Workbook

Sheet Curr
C1: NOK
B2: EUR | C2: 11
B3: SEK | C3: 1.02
B4: DKK | C4: 1.5
B5: ISK | C5: 0.075
B6: NOK | C6: 1
B7: USD | C7: 10.6

Sheet Kalk
B2: Dates: 24.09.2026
B3: Pax: 5
B4: Rooming: 2 x double, 1 x single
B6: ID | C6: Day | D6: Type | E6: From date | F6: To date | G6: From time | H6: To time | I6: Supplier | J6: Travel element | K6: Manual booking? | L6: Status | M6: Comments | N6: Non-refundable | O6: Refundable | P6: URL | Q6: Gross P per unit | R6: Units | S6: Gross P | T6: Supp Comm | U6: Net P | V6: Supp curr | W6: X-rate | X6: Net P NOK | Y6: Sales P per unit | Z6: Price | AA6: Sales curr | AB6: X-rate | AC6: Sales P NOK tot | AD6: GP NOK | AE6: GP % | AF6: VAT25 | AG6: VAT15 | AH6: VAT12 | AI6: VAT0-D | AJ6: VAT0-I
C7: Day 1 | D7: Arrival | E7: 24.09.2026 | J7: Oslo: Welcome to Norway | Q7: 0 | R7: 0 | S7: =+Q7*R7 -> 0 | T7: 0 | U7: =S7*(1-T7) -> 0 | V7: EUR | W7: =IFERROR(VLOOKUP(V7,Curr!$B$2:$C$13,2,FALSE),0) -> 11 | X7: =U7*W7 -> 0 | Y7: =Q7 -> 0 | Z7: =+Y7*R7 -> 0 | AA7: EUR | AB7: =IFERROR(VLOOKUP(AA7,Curr!$B$2:$C$13,2,FALSE),0) -> 11 | AC7: =+Y7*AB7*R7 -> 0 | AD7: =+AC7-X7 -> 0 | AE7: =IFERROR(AD7/AC7,0) -> 0
C8: Day 1 | D8: Transfer | E8: 24.09.2026 | J8: Oslo: Private transfer to your accommodation | Q8: 2500 | R8: 1 | S8: =+Q8*R8 -> 2500 | T8: 0 | U8: =S8*(1-T8) -> 2500 | V8: NOK | W8: =IFERROR(VLOOKUP(V8,Curr!$B$2:$C$13,2,FALSE),0) -> 1 | X8: =U8*W8 -> 2500 | Y8: =Q8/11/0.8 -> 284.09091 | Z8: =+Y8*R8 -> 284.09091 | AA8: EUR | AB8: =IFERROR(VLOOKUP(AA8,Curr!$B$2:$C$13,2,FALSE),0) -> 11 | AC8: =+Y8*AB8*R8 -> 3125 | AD8: =+AC8-X8 -> 625 | AE8: =IFERROR(AD8/AC8,0) -> 0.2
C9: Day 1 | D9: Hotel | E9: 24.09.2026 | F9: 26.09.2026 | J9: Oslo: Check in to your accommodation for a 2 night stay - Thon Opera - 2 x Standard Double Room, 1 x Standard Single Room - Breakfast included | P9: https://app.hotelbeds.com/factsheet/stay/87030?check_in=24-09-2026&check_out=26-09-2026&occupancy=2~0_2~0_1~0&packaging=true | Q9: =908+381 -> 1289 | R9: 1 | S9: =+Q9*R9 -> 1289 | T9: 0 | U9: =S9*(1-T9) -> 1289 | V9: EUR | W9: =IFERROR(VLOOKUP(V9,Curr!$B$2:$C$13,2,FALSE),0) -> 11 | X9: =U9*W9 -> 14179 | Y9: =Q9/0.8 -> 1611.25 | Z9: =+Y9*R9 -> 1611.25 | AA9: EUR | AB9: =IFERROR(VLOOKUP(AA9,Curr!$B$2:$C$13,2,FALSE),0) -> 11 | AC9: =+Y9*AB9*R9 -> 17723.75 | AD9: =+AC9-X9 -> 3544.75 | AE9: =IFERROR(AD9/AC9,0) -> 0.2
C10: Day 1 | D10: Leisure | E10: 24.09.2026 | J10: Oslo: Spend time at leisure | Q10: 0 | R10: 0 | S10: =+Q10*R10 -> 0 | T10: 0 | U10: =S10*(1-T10) -> 0 | V10: EUR | W10: =IFERROR(VLOOKUP(V10,Curr!$B$2:$C$13,2,FALSE),0) -> 11 | X10: =U10*W10 -> 0 | Y10: =Q10 -> 0 | Z10: =+Y10*R10 -> 0 | AA10: EUR | AB10: =IFERROR(VLOOKUP(AA10,Curr!$B$2:$C$13,2,FALSE),0) -> 11 | AC10: =+Y10*AB10*R10 -> 0 | AD10: =+AC10-X10 -> 0 | AE10: =IFERROR(AD10/AC10,0) -> 0
S11: =+Q11*R11 -> 0 | T11: 0 | U11: =S11*(1-T11) -> 0 | V11: EUR | W11: =IFERROR(VLOOKUP(V11,Curr!$B$2:$C$13,2,FALSE),0) -> 11 | X11: =U11*W11 -> 0 | Y11: =Q11 -> 0 | Z11: =+Y11*R11 -> 0 | AA11: EUR | AB11: =IFERROR(VLOOKUP(AA11,Curr!$B$2:$C$13,2,FALSE),0) -> 11 | AC11: =+Y11*AB11*R11 -> 0 | AD11: =+AC11-X11 -> 0 | AE11: =IFERROR(AD11/AC11,0) -> 0
C12: Day 2 | D12: Activity | E12: 25.09.2026 | J12: Oslo: Fjord Sightseeing Cruise onboard Electric Boat - Time: 11:00 am - 01:00 pm - Meeting point: Platform E, behind Fisketorget by ‘’TROLLCRUISE’’ sign - Includes: Electric fjord cruise with audio guidance, Access to outdoor deck and blankets, Charging ports and free Wi-FI, Comfortable seating, Panoramic windows, Accessibility features, Onboard toilets - Description: Embark on a 2-hr Oslofjord Sightseeing Cruise, where history, culture, and natural beauty intertwine. As you sail, discover fortresses, lighthouses, and coastal villages that echo with centuries-old tales. Audio guides available to enhance your experience. | O12: x | P12: https://booknordics.com/norway/eastern-norway/oslo/oslofjord-sightseeing-cruise | Q12: 498 | R12: 5 | S12: =+Q12*R12 -> 2490 | T12: 0.2 | U12: =S12*(1-T12) -> 1992 | V12: NOK | W12: =IFERROR(VLOOKUP(V12,Curr!$B$2:$C$13,2,FALSE),0) -> 1 | X12: =U12*W12 -> 1992 | Y12: =Q12/11/0.8 -> 56.590909 | Z12: =+Y12*R12 -> 282.95455 | AA12: EUR | AB12: =IFERROR(VLOOKUP(AA12,Curr!$B$2:$C$13,2,FALSE),0) -> 11 | AC12: =+Y12*AB12*R12 -> 3112.5 | AD12: =+AC12-X12 -> 1120.5 | AE12: =IFERROR(AD12/AC12,0) -> 0.36
C13: Day 2 | D13: Leisure | E13: 25.09.2026 | J13: Oslo: Spend time at leisure | Q13: 0 | R13: 0 | S13: =+Q13*R13 -> 0 | T13: 0 | U13: =S13*(1-T13) -> 0 | V13: EUR | W13: =IFERROR(VLOOKUP(V13,Curr!$B$2:$C$13,2,FALSE),0) -> 11 | X13: =U13*W13 -> 0 | Y13: =Q13 -> 0 | Z13: =+Y13*R13 -> 0 | AA13: EUR | AB13: =IFERROR(VLOOKUP(AA13,Curr!$B$2:$C$13,2,FALSE),0) -> 11 | AC13: =+Y13*AB13*R13 -> 0 | AD13: =+AC13-X13 -> 0 | AE13: =IFERROR(AD13/AC13,0) -> 0
S14: =+Q14*R14 -> 0 | T14: 0 | U14: =S14*(1-T14) -> 0 | V14: EUR | W14: =IFERROR(VLOOKUP(V14,Curr!$B$2:$C$13,2,FALSE),0) -> 11 | X14: =U14*W14 -> 0 | Y14: =Q14 -> 0 | Z14: =+Y14*R14 -> 0 | AA14: EUR | AB14: =IFERROR(VLOOKUP(AA14,Curr!$B$2:$C$13,2,FALSE),0) -> 11 | AC14: =+Y14*AB14*R14 -> 0 | AD14: =+AC14-X14 -> 0 | AE14: =IFERROR(AD14/AC14,0) -> 0
C15: Day 3 | D15: Transfer | E15: 26.09.2026 | J15: Oslo: Self transfer to Oslo Central Station - A short walk from your accommodation | Q15: 0 | R15: 0 | S15: =+Q15*R15 -> 0 | T15: 0 | U15: =S15*(1-T15) -> 0 | V15: EUR | W15: =IFERROR(VLOOKUP(V15,Curr!$B$2:$C$13,2,FALSE),0) -> 11 | X15: =U15*W15 -> 0 | Y15: =Q15 -> 0 | Z15: =+Y15*R15 -> 0 | AA15: EUR | AB15: =IFERROR(VLOOKUP(AA15,Curr!$B$2:$C$13,2,FALSE),0) -> 11 | AC15: =+Y15*AB15*R15 -> 0 | AD15: =+AC15-X15 -> 0 | AE15: =IFERROR(AD15/AC15,0) -> 0
C16: Day 3 | D16: Activity | E16: 26.09.2026 | J16: Oslo: Norway in a Nutshell to Flåm - Time: 06:25 am - 1:04 pm - Meeting point: Oslo Central Station - Includes: Train transfer Oslo to Myrdal (06:25 am - 11:15 am), Train tranfser Myrdal to Flåm (12:06 pm - 1:04 pm) | O16: x | P16: https://www.fjordtours.com/en | Q16: 3475 | R16: 5 | S16: =+Q16*R16 -> 17375 | T16: 0.08 | U16: =S16*(1-T16) -> 15985 | V16: NOK | W16: =IFERROR(VLOOKUP(V16,Curr!$B$2:$C$13,2,FALSE),0) -> 1 | X16: =U16*W16 -> 15985 | Y16: =Q16/11/0.85 -> 371.65775 | Z16: =+Y16*R16 -> 1858.2888 | AA16: EUR | AB16: =IFERROR(VLOOKUP(AA16,Curr!$B$2:$C$13,2,FALSE),0) -> 11 | AC16: =+Y16*AB16*R16 -> 20441.176 | AD16: =+AC16-X16 -> 4456.1765 | AE16: =IFERROR(AD16/AC16,0) -> 0.218
C17: Day 3 | D17: Transfer | E17: 26.09.2026 | J17: Flåm: Self transfer to your accommodation - A short walk from Flåm Station | Q17: 0 | R17: 0 | S17: =+Q17*R17 -> 0 | T17: 0 | U17: =S17*(1-T17) -> 0 | V17: EUR | W17: =IFERROR(VLOOKUP(V17,Curr!$B$2:$C$13,2,FALSE),0) -> 11 | X17: =U17*W17 -> 0 | Y17: =Q17 -> 0 | Z17: =+Y17*R17 -> 0 | AA17: EUR | AB17: =IFERROR(VLOOKUP(AA17,Curr!$B$2:$C$13,2,FALSE),0) -> 11 | AC17: =+Y17*AB17*R17 -> 0 | AD17: =+AC17-X17 -> 0 | AE17: =IFERROR(AD17/AC17,0) -> 0
C18: Day 3 | D18: Hotel | E18: 26.09.2026 | F18: 27.09.2026 | J18: Flåm: Check in to your accommodation for a 1 night stay - Fretheim Hotel - 3 x Historical Double Room - Breakfast included | P18: https://www.ratehawk.com/hotel/norway/aurland/mid7785115/fretheim_hotel/?q=6024041&dates=26.09.2026-27.09.2026&guests=2-2-1&meal_types=breakfast.halfBoard.fullBoard.allInclusive&price=one | Q18: 1403 | R18: 1 | S18: =+Q18*R18 -> 1403 | T18: 0 | U18: =S18*(1-T18) -> 1403 | V18: EUR | W18: =IFERROR(VLOOKUP(V18,Curr!$B$2:$C$13,2,FALSE),0) -> 11 | X18: =U18*W18 -> 15433 | Y18: =Q18/0.8 -> 1753.75 | Z18: =+Y18*R18 -> 1753.75 | AA18: EUR | AB18: =IFERROR(VLOOKUP(AA18,Curr!$B$2:$C$13,2,FALSE),0) -> 11 | AC18: =+Y18*AB18*R18 -> 19291.25 | AD18: =+AC18-X18 -> 3858.25 | AE18: =IFERROR(AD18/AC18,0) -> 0.2
C19: Day 3 | D19: Leisure | E19: 26.09.2026 | J19: Flåm: Spend time at leisure | Q19: 0 | R19: 0 | S19: =+Q19*R19 -> 0 | T19: 0 | U19: =S19*(1-T19) -> 0 | V19: EUR | W19: =IFERROR(VLOOKUP(V19,Curr!$B$2:$C$13,2,FALSE),0) -> 11 | X19: =U19*W19 -> 0 | Y19: =Q19 -> 0 | Z19: =+Y19*R19 -> 0 | AA19: EUR | AB19: =IFERROR(VLOOKUP(AA19,Curr!$B$2:$C$13,2,FALSE),0) -> 11 | AC19: =+Y19*AB19*R19 -> 0 | AD19: =+AC19-X19 -> 0 | AE19: =IFERROR(AD19/AC19,0) -> 0
S20: =+Q20*R20 -> 0 | T20: 0 | U20: =S20*(1-T20) -> 0 | V20: EUR | W20: =IFERROR(VLOOKUP(V20,Curr!$B$2:$C$13,2,FALSE),0) -> 11 | X20: =U20*W20 -> 0 | Y20: =Q20 -> 0 | Z20: =+Y20*R20 -> 0 | AA20: EUR | AB20: =IFERROR(VLOOKUP(AA20,Curr!$B$2:$C$13,2,FALSE),0) -> 11 | AC20: =+Y20*AB20*R20 -> 0 | AD20: =+AC20-X20 -> 0 | AE20: =IFERROR(AD20/AC20,0) -> 0
C21: Day 4 | D21: Transfer | E21: 27.09.2026 | J21: Flåm: Self transfer to Flåm Cruise Port - Short walk from your accommodation | Q21: 0 | R21: 0 | S21: =+Q21*R21 -> 0 | T21: 0 | U21: =S21*(1-T21) -> 0 | V21: EUR | W21: =IFERROR(VLOOKUP(V21,Curr!$B$2:$C$13,2,FALSE),0) -> 11 | X21: =U21*W21 -> 0 | Y21: =Q21 -> 0 | Z21: =+Y21*R21 -> 0 | AA21: EUR | AB21: =IFERROR(VLOOKUP(AA21,Curr!$B$2:$C$13,2,FALSE),0) -> 11 | AC21: =+Y21*AB21*R21 -> 0 | AD21: =+AC21-X21 -> 0 | AE21: =IFERROR(AD21/AC21,0) -> 0
C22: Day 4 | D22: Activity | E22: 27.09.2026 | J22: Flåm: Norway in a Nutshell to Bergen - Time: 12:00 pm - 6:17 pm - Meeting point: Flåm Harbor - Includes: Fjord Cruise Flåm to Gudvangen (12:00 pm - 2:00 pm), Coach Transfer Gudvangen to Voss (2:30 pm - 3:30 pm), Train transfer Voss to Bergen (4:57 pm - 6:17 pm) | O22: x | P22: https://www.fjordtours.com/en | Q22: 0 | R22: 0 | S22: =+Q22*R22 -> 0 | T22: 0.08 | U22: =S22*(1-T22) -> 0 | V22: NOK | W22: =IFERROR(VLOOKUP(V22,Curr!$B$2:$C$13,2,FALSE),0) -> 1 | X22: =U22*W22 -> 0 | Y22: =Q22 -> 0 | Z22: =+Y22*R22 -> 0 | AA22: EUR | AB22: =IFERROR(VLOOKUP(AA22,Curr!$B$2:$C$13,2,FALSE),0) -> 11 | AC22: =+Y22*AB22*R22 -> 0 | AD22: =+AC22-X22 -> 0 | AE22: =IFERROR(AD22/AC22,0) -> 0
C23: Day 4 | D23: Transfer | E23: 27.09.2026 | J23: Bergen: Private transfer to your accommodation | Q23: 1490 | R23: 1 | S23: =+Q23*R23 -> 1490 | T23: 0.15 | U23: =S23*(1-T23) -> 1266.5 | V23: NOK | W23: =IFERROR(VLOOKUP(V23,Curr!$B$2:$C$13,2,FALSE),0) -> 1 | X23: =U23*W23 -> 1266.5 | Y23: =Q23/11/0.9 -> 150.50505 | Z23: =+Y23*R23 -> 150.50505 | AA23: EUR | AB23: =IFERROR(VLOOKUP(AA23,Curr!$B$2:$C$13,2,FALSE),0) -> 11 | AC23: =+Y23*AB23*R23 -> 1655.5556 | AD23: =+AC23-X23 -> 389.05556 | AE23: =IFERROR(AD23/AC23,0) -> 0.235
C24: Day 4 | D24: Hotel | E24: 27.09.2026 | F24: 30.09.2026 | J24: Bergen: Check in to your accommodation for a 3 night stay - Thon Hotel Rosenkrantz Bergen - 2 x Standard Double Room, 1 x Standard Single Room - Breakfast included | P24: https://app.hotelbeds.com/factsheet/stay/9418?check_in=27-09-2026&check_out=30-09-2026&occupancy=2~0_2~0_1~0&packaging=true | Q24: =937+346 -> 1283 | R24: 1 | S24: =+Q24*R24 -> 1283 | T24: 0 | U24: =S24*(1-T24) -> 1283 | V24: EUR | W24: =IFERROR(VLOOKUP(V24,Curr!$B$2:$C$13,2,FALSE),0) -> 11 | X24: =U24*W24 -> 14113 | Y24: =Q24/0.8 -> 1603.75 | Z24: =+Y24*R24 -> 1603.75 | AA24: EUR | AB24: =IFERROR(VLOOKUP(AA24,Curr!$B$2:$C$13,2,FALSE),0) -> 11 | AC24: =+Y24*AB24*R24 -> 17641.25 | AD24: =+AC24-X24 -> 3528.25 | AE24: =IFERROR(AD24/AC24,0) -> 0.2
C25: Day 4 | D25: Leisure | E25: 27.09.2026 | J25: Bergen: Spend time at leisure | Q25: 0 | R25: 0 | S25: =+Q25*R25 -> 0 | T25: 0 | U25: =S25*(1-T25) -> 0 | V25: EUR | W25: =IFERROR(VLOOKUP(V25,Curr!$B$2:$C$13,2,FALSE),0) -> 11 | X25: =U25*W25 -> 0 | Y25: =Q25 -> 0 | Z25: =+Y25*R25 -> 0 | AA25: EUR | AB25: =IFERROR(VLOOKUP(AA25,Curr!$B$2:$C$13,2,FALSE),0) -> 11 | AC25: =+Y25*AB25*R25 -> 0 | AD25: =+AC25-X25 -> 0 | AE25: =IFERROR(AD25/AC25,0) -> 0
S26: =+Q26*R26 -> 0 | T26: 0 | U26: =S26*(1-T26) -> 0 | V26: EUR | W26: =IFERROR(VLOOKUP(V26,Curr!$B$2:$C$13,2,FALSE),0) -> 11 | X26: =U26*W26 -> 0 | Y26: =Q26 -> 0 | Z26: =+Y26*R26 -> 0 | AA26: EUR | AB26: =IFERROR(VLOOKUP(AA26,Curr!$B$2:$C$13,2,FALSE),0) -> 11 | AC26: =+Y26*AB26*R26 -> 0 | AD26: =+AC26-X26 -> 0 | AE26: =IFERROR(AD26/AC26,0) -> 0
C27: Day 5 | D27: Activity | E27: 28.09.2026 | J27: Bergen: Guided Walking Tour of Bergen Past & Present - Time: 10:00 am - 12:00 pm - Meeting point: Bradbenken 1 - Includes: Profesional Guide - Description: Discover the stories, landscapes and local life that shaped Bergen from the Middle Ages to today. This relaxed, friendly walk takes you through historic streets, colourful neighbourhoods and lesser-known spots that most visitors miss. | O27: x | P27: https://booknordics.com/norway/western-fjord-norway/bergen-and-hardanger/a-walk-through-bergen-past-present | Q27: 325 | R27: 5 | S27: =+Q27*R27 -> 1625 | T27: 0.2 | U27: =S27*(1-T27) -> 1300 | V27: NOK | W27: =IFERROR(VLOOKUP(V27,Curr!$B$2:$C$13,2,FALSE),0) -> 1 | X27: =U27*W27 -> 1300 | Y27: =Q27/11/0.8 -> 36.931818 | Z27: =+Y27*R27 -> 184.65909 | AA27: EUR | AB27: =IFERROR(VLOOKUP(AA27,Curr!$B$2:$C$13,2,FALSE),0) -> 11 | AC27: =+Y27*AB27*R27 -> 2031.25 | AD27: =+AC27-X27 -> 731.25 | AE27: =IFERROR(AD27/AC27,0) -> 0.36
C28: Day 5 | D28: Activity | E28: 28.09.2026 | J28: Bergen: Fløibanen Funicluar - Time: Flexible - Meeting point: Vetrlidsallmenningen 23A - Includes: Tickets - Description: Take the funicular Fløibanen to the top of Mount Fløyen and experience spectacular views of the city, the fjord and the surrounding mountains. | O28: x | P28: https://www.floyen.no/en/floibanen/buy-tickets/ | Q28: 200 | R28: 5 | S28: =+Q28*R28 -> 1000 | T28: 0 | U28: =S28*(1-T28) -> 1000 | V28: NOK | W28: =IFERROR(VLOOKUP(V28,Curr!$B$2:$C$13,2,FALSE),0) -> 1 | X28: =U28*W28 -> 1000 | Y28: =Q28/11/0.8 -> 22.727273 | Z28: =+Y28*R28 -> 113.63636 | AA28: EUR | AB28: =IFERROR(VLOOKUP(AA28,Curr!$B$2:$C$13,2,FALSE),0) -> 11 | AC28: =+Y28*AB28*R28 -> 1250 | AD28: =+AC28-X28 -> 250 | AE28: =IFERROR(AD28/AC28,0) -> 0.2
C29: Day 5 | D29: Leisure | E29: 28.09.2026 | J29: Bergen: Spend time at leisure | Q29: 0 | R29: 0 | S29: =+Q29*R29 -> 0 | T29: 0 | U29: =S29*(1-T29) -> 0 | V29: EUR | W29: =IFERROR(VLOOKUP(V29,Curr!$B$2:$C$13,2,FALSE),0) -> 11 | X29: =U29*W29 -> 0 | Y29: =Q29 -> 0 | Z29: =+Y29*R29 -> 0 | AA29: EUR | AB29: =IFERROR(VLOOKUP(AA29,Curr!$B$2:$C$13,2,FALSE),0) -> 11 | AC29: =+Y29*AB29*R29 -> 0 | AD29: =+AC29-X29 -> 0 | AE29: =IFERROR(AD29/AC29,0) -> 0
S30: =+Q30*R30 -> 0 | T30: 0 | U30: =S30*(1-T30) -> 0 | V30: EUR | W30: =IFERROR(VLOOKUP(V30,Curr!$B$2:$C$13,2,FALSE),0) -> 11 | X30: =U30*W30 -> 0 | Y30: =Q30 -> 0 | Z30: =+Y30*R30 -> 0 | AA30: EUR | AB30: =IFERROR(VLOOKUP(AA30,Curr!$B$2:$C$13,2,FALSE),0) -> 11 | AC30: =+Y30*AB30*R30 -> 0 | AD30: =+AC30-X30 -> 0 | AE30: =IFERROR(AD30/AC30,0) -> 0
C31: Day 6 | D31: Activity | E31: 29.09.2026 | J31: Bergen: Private Day Tour to Hardanger Fjords & Waterfalls - Time: 09:00 am - 04:00 pm - Meeting point: Hotel pick up - Includes: Pick-up from your Bergen hotel or cruise port, Knowledgeable, English-speaking guide, Full-day tour to the Hardanger fjord and back, Flexible itinerary and personalized route, Stops at waterfalls and fjord viewpoints, Luxury private vehicle, 100% electric - Description: This private day trip begins in Bergen and takes you deep into the beauty of the Hardangerfjord region. Along the way, we make scenic stops to visit waterfalls, enjoy panoramic viewpoints, and capture photos of the fjord and landscapes. | P31: https://booknordics.com/norway/western-fjord-norway/bergen-and-hardanger/private-tour-in-fjords-waterfalls-of-hardanger-norway-our-absolute-bestseller | Q31: 802 | R31: 1 | S31: =+Q31*R31 -> 802 | T31: 0.15 | U31: =S31*(1-T31) -> 681.7 | V31: EUR | W31: =IFERROR(VLOOKUP(V31,Curr!$B$2:$C$13,2,FALSE),0) -> 11 | X31: =U31*W31 -> 7498.7 | Y31: =Q31/0.95 -> 844.21053 | Z31: =+Y31*R31 -> 844.21053 | AA31: EUR | AB31: =IFERROR(VLOOKUP(AA31,Curr!$B$2:$C$13,2,FALSE),0) -> 11 | AC31: =+Y31*AB31*R31 -> 9286.3158 | AD31: =+AC31-X31 -> 1787.6158 | AE31: =IFERROR(AD31/AC31,0) -> 0.1925
C32: Day 6 | D32: Leisure | E32: 29.09.2026 | J32: Bergen: Spend time at leisure | Q32: 0 | R32: 0 | S32: =+Q32*R32 -> 0 | T32: 0 | U32: =S32*(1-T32) -> 0 | V32: EUR | W32: =IFERROR(VLOOKUP(V32,Curr!$B$2:$C$13,2,FALSE),0) -> 11 | X32: =U32*W32 -> 0 | Y32: =Q32 -> 0 | Z32: =+Y32*R32 -> 0 | AA32: EUR | AB32: =IFERROR(VLOOKUP(AA32,Curr!$B$2:$C$13,2,FALSE),0) -> 11 | AC32: =+Y32*AB32*R32 -> 0 | AD32: =+AC32-X32 -> 0 | AE32: =IFERROR(AD32/AC32,0) -> 0
S33: =+Q33*R33 -> 0 | T33: 0 | U33: =S33*(1-T33) -> 0 | V33: EUR | W33: =IFERROR(VLOOKUP(V33,Curr!$B$2:$C$13,2,FALSE),0) -> 11 | X33: =U33*W33 -> 0 | Y33: =Q33 -> 0 | Z33: =+Y33*R33 -> 0 | AA33: EUR | AB33: =IFERROR(VLOOKUP(AA33,Curr!$B$2:$C$13,2,FALSE),0) -> 11 | AC33: =+Y33*AB33*R33 -> 0 | AD33: =+AC33-X33 -> 0 | AE33: =IFERROR(AD33/AC33,0) -> 0
C34: Day 7 | D34: Transfer | E34: 30.09.2026 | J34: Bergen: Private transfer to Bergen Airport | Q34: 1990 | R34: 1 | S34: =+Q34*R34 -> 1990 | T34: 0.15 | U34: =S34*(1-T34) -> 1691.5 | V34: NOK | W34: =IFERROR(VLOOKUP(V34,Curr!$B$2:$C$13,2,FALSE),0) -> 1 | X34: =U34*W34 -> 1691.5 | Y34: =Q34/11/0.9 -> 201.0101 | Z34: =+Y34*R34 -> 201.0101 | AA34: EUR | AB34: =IFERROR(VLOOKUP(AA34,Curr!$B$2:$C$13,2,FALSE),0) -> 11 | AC34: =+Y34*AB34*R34 -> 2211.1111 | AD34: =+AC34-X34 -> 519.61111 | AE34: =IFERROR(AD34/AC34,0) -> 0.235
C35: Day 7 | D35: Flight | E35: 30.09.2026 | J35: Bergen: Flight to Tromsø - Time: 2:45 pm - 4:30 pm - Includes: Tickets, Luggage (1 x 23 kg check in and 1 x 8 kg carry on per person) | P35: https://www.wideroe.no/booking/booking#/select-flight | Q35: 1529 | R35: 5 | S35: =+Q35*R35 -> 7645 | T35: 0 | U35: =S35*(1-T35) -> 7645 | V35: NOK | W35: =IFERROR(VLOOKUP(V35,Curr!$B$2:$C$13,2,FALSE),0) -> 1 | X35: =U35*W35 -> 7645 | Y35: =Q35/11/0.8 -> 173.75 | Z35: =+Y35*R35 -> 868.75 | AA35: EUR | AB35: =IFERROR(VLOOKUP(AA35,Curr!$B$2:$C$13,2,FALSE),0) -> 11 | AC35: =+Y35*AB35*R35 -> 9556.25 | AD35: =+AC35-X35 -> 1911.25 | AE35: =IFERROR(AD35/AC35,0) -> 0.2
C36: Day 7 | D36: Transfer | E36: 30.09.2026 | J36: Tromsø: Private transfer to your accommodation | Q36: 2500 | R36: 1 | S36: =+Q36*R36 -> 2500 | T36: 0 | U36: =S36*(1-T36) -> 2500 | V36: NOK | W36: =IFERROR(VLOOKUP(V36,Curr!$B$2:$C$13,2,FALSE),0) -> 1 | X36: =U36*W36 -> 2500 | Y36: =Q36/11/0.8 -> 284.09091 | Z36: =+Y36*R36 -> 284.09091 | AA36: EUR | AB36: =IFERROR(VLOOKUP(AA36,Curr!$B$2:$C$13,2,FALSE),0) -> 11 | AC36: =+Y36*AB36*R36 -> 3125 | AD36: =+AC36-X36 -> 625 | AE36: =IFERROR(AD36/AC36,0) -> 0.2
C37: Day 7 | D37: Hotel | E37: 30.09.2026 | F37: 04.10.2026 | J37: Tromsø: Check in to your accommodation for a 4 night stay - Quality Hotel Saga - 2 x Standard Double Room, 1 x Standard Twin - Breakfast included | P37: https://app.hotelbeds.com/factsheet/stay/70273?check_in=30-09-2026&check_out=04-10-2026&occupancy=2~0_2~0_1~0&packaging=true | Q37: =1255+529 -> 1784 | R37: 1 | S37: =+Q37*R37 -> 1784 | T37: 0 | U37: =S37*(1-T37) -> 1784 | V37: EUR | W37: =IFERROR(VLOOKUP(V37,Curr!$B$2:$C$13,2,FALSE),0) -> 11 | X37: =U37*W37 -> 19624 | Y37: =Q37/0.8 -> 2230 | Z37: =+Y37*R37 -> 2230 | AA37: EUR | AB37: =IFERROR(VLOOKUP(AA37,Curr!$B$2:$C$13,2,FALSE),0) -> 11 | AC37: =+Y37*AB37*R37 -> 24530 | AD37: =+AC37-X37 -> 4906 | AE37: =IFERROR(AD37/AC37,0) -> 0.2
C38: Day 7 | D38: Leisure | E38: 30.09.2026 | J38: Tromsø: Spend time at leisure | Q38: 0 | R38: 0 | S38: =+Q38*R38 -> 0 | T38: 0 | U38: =S38*(1-T38) -> 0 | V38: EUR | W38: =IFERROR(VLOOKUP(V38,Curr!$B$2:$C$13,2,FALSE),0) -> 11 | X38: =U38*W38 -> 0 | Y38: =Q38 -> 0 | Z38: =+Y38*R38 -> 0 | AA38: EUR | AB38: =IFERROR(VLOOKUP(AA38,Curr!$B$2:$C$13,2,FALSE),0) -> 11 | AC38: =+Y38*AB38*R38 -> 0 | AD38: =+AC38-X38 -> 0 | AE38: =IFERROR(AD38/AC38,0) -> 0
S39: =+Q39*R39 -> 0 | T39: 0 | U39: =S39*(1-T39) -> 0 | V39: EUR | W39: =IFERROR(VLOOKUP(V39,Curr!$B$2:$C$13,2,FALSE),0) -> 11 | X39: =U39*W39 -> 0 | Y39: =Q39 -> 0 | Z39: =+Y39*R39 -> 0 | AA39: EUR | AB39: =IFERROR(VLOOKUP(AA39,Curr!$B$2:$C$13,2,FALSE),0) -> 11 | AC39: =+Y39*AB39*R39 -> 0 | AD39: =+AC39-X39 -> 0 | AE39: =IFERROR(AD39/AC39,0) -> 0
C40: Day 8 | D40: Activity | E40: 01.10.2026 | J40: Tromsø: Fjord Tour of Kvaløya & Sommarøy - Time: 10:00 am - 3:00 pm - Meeting point: Hotel pick up - Includes: Pick-up/drop-off in central Tromsø, Knowledgeable, multilingual guide, Free photographs from the trip, 2-course meal with coffee or tea - Description: On this tour you will travel in our minibus around the fjords of the island of Kvaløya, nearby Tromsø, and enjoy a nice lunch on Sommarøy island. | O40: x | P40: https://book.fjellheisen.no/en/to-do/2043246/return-ticket/showdetails | Q40: 125 | R40: 5 | S40: =+Q40*R40 -> 625 | T40: 0.2 | U40: =S40*(1-T40) -> 500 | V40: EUR | W40: =IFERROR(VLOOKUP(V40,Curr!$B$2:$C$13,2,FALSE),0) -> 11 | X40: =U40*W40 -> 5500 | Y40: =Q40 -> 125 | Z40: =+Y40*R40 -> 625 | AA40: EUR | AB40: =IFERROR(VLOOKUP(AA40,Curr!$B$2:$C$13,2,FALSE),0) -> 11 | AC40: =+Y40*AB40*R40 -> 6875 | AD40: =+AC40-X40 -> 1375 | AE40: =IFERROR(AD40/AC40,0) -> 0.2
C41: Day 8 | D41: Leisure | E41: 01.10.2026 | J41: Tromsø: Spend time at leisure | Q41: 0 | R41: 0 | S41: =+Q41*R41 -> 0 | T41: 0 | U41: =S41*(1-T41) -> 0 | V41: EUR | W41: =IFERROR(VLOOKUP(V41,Curr!$B$2:$C$13,2,FALSE),0) -> 11 | X41: =U41*W41 -> 0 | Y41: =Q41 -> 0 | Z41: =+Y41*R41 -> 0 | AA41: EUR | AB41: =IFERROR(VLOOKUP(AA41,Curr!$B$2:$C$13,2,FALSE),0) -> 11 | AC41: =+Y41*AB41*R41 -> 0 | AD41: =+AC41-X41 -> 0 | AE41: =IFERROR(AD41/AC41,0) -> 0
C42: Day 8 | D42: Activity | E42: 01.10.2026 | J42: Tromsø: All-Evening Northern Lights Hunt by Minibus - Time: 7:00 pm - 12:00 am - Meeting point: Magic Ice Bar Tromsø, Kaigata 4 - Includes: Knowledgeable, English-speaking guide, Photos shared with you after the tour, Light snacks and warm/cold beverages - Description: Join our intimate minibus tour, limited to just 16 participants, for an unforgettable journey to witness the Aurora Borealis. | P42: https://booknordics.com/norway/northern-norway/tromso-region/full-day-magic-of-the-arctic-lights-in-tromso | Q42: 107 | R42: 5 | S42: =+Q42*R42 -> 535 | T42: 0.2 | U42: =S42*(1-T42) -> 428 | V42: EUR | W42: =IFERROR(VLOOKUP(V42,Curr!$B$2:$C$13,2,FALSE),0) -> 11 | X42: =U42*W42 -> 4708 | Y42: =Q42 -> 107 | Z42: =+Y42*R42 -> 535 | AA42: EUR | AB42: =IFERROR(VLOOKUP(AA42,Curr!$B$2:$C$13,2,FALSE),0) -> 11 | AC42: =+Y42*AB42*R42 -> 5885 | AD42: =+AC42-X42 -> 1177 | AE42: =IFERROR(AD42/AC42,0) -> 0.2
...

Sheet Self Transfer
B2: Dates:
B3: Pax:
B4: Rooming:
B6: ID | C6: Day | D6: Type | E6: From date | F6: To date | G6: From time | H6: To time | I6: Supplier | J6: Travel element | K6: Manual booking? | L6: Status | M6: Comments | N6: Non-refundable | O6: Refundable | P6: URL | Q6: Gross P per unit | R6: Units | S6: Gross P | T6: Supp Comm | U6: Net P | V6: Supp curr | W6: X-rate | X6: Net P NOK | Y6: Sales P per unit | Z6: Price | AA6: Sales curr | AB6: X-rate | AC6: Sales P NOK tot | AD6: GP NOK | AE6: GP % | AF6: VAT25 | AG6: VAT15 | AH6: VAT12 | AI6: VAT0-D | AJ6: VAT0-I
C7: Day 1 | D7: Arrival | E7: 24.09.2026 | J7: Oslo: Welcome to Norway | Q7: 0 | R7: 0 | S7: =+Q7*R7 -> 0 | T7: 0 | U7: =S7*(1-T7) -> 0 | V7: EUR | W7: =IFERROR(VLOOKUP(V7,Curr!$B$2:$C$13,2,FALSE),0) -> 11 | X7: =U7*W7 -> 0 | Y7: =Q7 -> 0 | Z7: =+Y7*R7 -> 0 | AA7: EUR | AB7: =IFERROR(VLOOKUP(AA7,Curr!$B$2:$C$13,2,FALSE),0) -> 11 | AC7: =+Y7*AB7*R7 -> 0 | AD7: =+AC7-X7 -> 0 | AE7: =IFERROR(AD7/AC7,0) -> 0
C8: Day 1 | D8: Transfer | E8: 24.09.2026 | J8: Oslo: Self transfer to your accommodation | Q8: 2500 | R8: 0 | S8: =+Q8*R8 -> 0 | T8: 0 | U8: =S8*(1-T8) -> 0 | V8: NOK | W8: =IFERROR(VLOOKUP(V8,Curr!$B$2:$C$13,2,FALSE),0) -> 1 | X8: =U8*W8 -> 0 | Y8: =Q8/11/0.8 -> 284.09091 | Z8: =+Y8*R8 -> 0 | AA8: EUR | AB8: =IFERROR(VLOOKUP(AA8,Curr!$B$2:$C$13,2,FALSE),0) -> 11 | AC8: =+Y8*AB8*R8 -> 0 | AD8: =+AC8-X8 -> 0 | AE8: =IFERROR(AD8/AC8,0) -> 0
C9: Day 1 | D9: Hotel | E9: 24.09.2026 | F9: 26.09.2026 | J9: Oslo: Check in to your accommodation for a 2 night stay - Thon Opera - 2 x Standard Double Room, 1 x Standard Single Room - Breakfast included | P9: https://app.hotelbeds.com/factsheet/stay/87030?check_in=24-09-2026&check_out=26-09-2026&occupancy=2~0_2~0_1~0&packaging=true | Q9: =908+381 -> 1289 | R9: 1 | S9: =+Q9*R9 -> 1289 | T9: 0 | U9: =S9*(1-T9) -> 1289 | V9: EUR | W9: =IFERROR(VLOOKUP(V9,Curr!$B$2:$C$13,2,FALSE),0) -> 11 | X9: =U9*W9 -> 14179 | Y9: =Q9/0.8 -> 1611.25 | Z9: =+Y9*R9 -> 1611.25 | AA9: EUR | AB9: =IFERROR(VLOOKUP(AA9,Curr!$B$2:$C$13,2,FALSE),0) -> 11 | AC9: =+Y9*AB9*R9 -> 17723.75 | AD9: =+AC9-X9 -> 3544.75 | AE9: =IFERROR(AD9/AC9,0) -> 0.2
C10: Day 1 | D10: Leisure | E10: 24.09.2026 | J10: Oslo: Spend time at leisure | Q10: 0 | R10: 0 | S10: =+Q10*R10 -> 0 | T10: 0 | U10: =S10*(1-T10) -> 0 | V10: EUR | W10: =IFERROR(VLOOKUP(V10,Curr!$B$2:$C$13,2,FALSE),0) -> 11 | X10: =U10*W10 -> 0 | Y10: =Q10 -> 0 | Z10: =+Y10*R10 -> 0 | AA10: EUR | AB10: =IFERROR(VLOOKUP(AA10,Curr!$B$2:$C$13,2,FALSE),0) -> 11 | AC10: =+Y10*AB10*R10 -> 0 | AD10: =+AC10-X10 -> 0 | AE10: =IFERROR(AD10/AC10,0) -> 0
S11: =+Q11*R11 -> 0 | T11: 0 | U11: =S11*(1-T11) -> 0 | V11: EUR | W11: =IFERROR(VLOOKUP(V11,Curr!$B$2:$C$13,2,FALSE),0) -> 11 | X11: =U11*W11 -> 0 | Y11: =Q11 -> 0 | Z11: =+Y11*R11 -> 0 | AA11: EUR | AB11: =IFERROR(VLOOKUP(AA11,Curr!$B$2:$C$13,2,FALSE),0) -> 11 | AC11: =+Y11*AB11*R11 -> 0 | AD11: =+AC11-X11 -> 0 | AE11: =IFERROR(AD11/AC11,0) -> 0
C12: Day 2 | D12: Activity | E12: 25.09.2026 | J12: Oslo: Fjord Sightseeing Cruise onboard Electric Boat - Time: 11:00 am - 01:00 pm - Meeting point: Platform E, behind Fisketorget by ‘’TROLLCRUISE’’ sign - Includes: Electric fjord cruise with audio guidance, Access to outdoor deck and blankets, Charging ports and free Wi-FI, Comfortable seating, Panoramic windows, Accessibility features, Onboard toilets - Description: Embark on a 2-hr Oslofjord Sightseeing Cruise, where history, culture, and natural beauty intertwine. As you sail, discover fortresses, lighthouses, and coastal villages that echo with centuries-old tales. Audio guides available to enhance your experience. | O12: x | P12: https://booknordics.com/norway/eastern-norway/oslo/oslofjord-sightseeing-cruise | Q12: 498 | R12: 5 | S12: =+Q12*R12 -> 2490 | T12: 0.2 | U12: =S12*(1-T12) -> 1992 | V12: NOK | W12: =IFERROR(VLOOKUP(V12,Curr!$B$2:$C$13,2,FALSE),0) -> 1 | X12: =U12*W12 -> 1992 | Y12: =Q12/11/0.8 -> 56.590909 | Z12: =+Y12*R12 -> 282.95455 | AA12: EUR | AB12: =IFERROR(VLOOKUP(AA12,Curr!$B$2:$C$13,2,FALSE),0) -> 11 | AC12: =+Y12*AB12*R12 -> 3112.5 | AD12: =+AC12-X12 -> 1120.5 | AE12: =IFERROR(AD12/AC12,0) -> 0.36
C13: Day 2 | D13: Leisure | E13: 25.09.2026 | J13: Oslo: Spend time at leisure | Q13: 0 | R13: 0 | S13: =+Q13*R13 -> 0 | T13: 0 | U13: =S13*(1-T13) -> 0 | V13: EUR | W13: =IFERROR(VLOOKUP(V13,Curr!$B$2:$C$13,2,FALSE),0) -> 11 | X13: =U13*W13 -> 0 | Y13: =Q13 -> 0 | Z13: =+Y13*R13 -> 0 | AA13: EUR | AB13: =IFERROR(VLOOKUP(AA13,Curr!$B$2:$C$13,2,FALSE),0) -> 11 | AC13: =+Y13*AB13*R13 -> 0 | AD13: =+AC13-X13 -> 0 | AE13: =IFERROR(AD13/AC13,0) -> 0
S14: =+Q14*R14 -> 0 | T14: 0 | U14: =S14*(1-T14) -> 0 | V14: EUR | W14: =IFERROR(VLOOKUP(V14,Curr!$B$2:$C$13,2,FALSE),0) -> 11 | X14: =U14*W14 -> 0 | Y14: =Q14 -> 0 | Z14: =+Y14*R14 -> 0 | AA14: EUR | AB14: =IFERROR(VLOOKUP(AA14,Curr!$B$2:$C$13,2,FALSE),0) -> 11 | AC14: =+Y14*AB14*R14 -> 0 | AD14: =+AC14-X14 -> 0 | AE14: =IFERROR(AD14/AC14,0) -> 0
C15: Day 3 | D15: Transfer | E15: 26.09.2026 | J15: Oslo: Self transfer to Oslo Central Station - A short walk from your accommodation | Q15: 0 | R15: 0 | S15: =+Q15*R15 -> 0 | T15: 0 | U15: =S15*(1-T15) -> 0 | V15: EUR | W15: =IFERROR(VLOOKUP(V15,Curr!$B$2:$C$13,2,FALSE),0) -> 11 | X15: =U15*W15 -> 0 | Y15: =Q15 -> 0 | Z15: =+Y15*R15 -> 0 | AA15: EUR | AB15: =IFERROR(VLOOKUP(AA15,Curr!$B$2:$C$13,2,FALSE),0) -> 11 | AC15: =+Y15*AB15*R15 -> 0 | AD15: =+AC15-X15 -> 0 | AE15: =IFERROR(AD15/AC15,0) -> 0
C16: Day 3 | D16: Activity | E16: 26.09.2026 | J16: Oslo: Norway in a Nutshell to Flåm - Time: 06:25 am - 1:04 pm - Meeting point: Oslo Central Station - Includes: Train transfer Oslo to Myrdal (06:25 am - 11:15 am), Train tranfser Myrdal to Flåm (12:06 pm - 1:04 pm) | O16: x | P16: https://www.fjordtours.com/en | Q16: 3475 | R16: 5 | S16: =+Q16*R16 -> 17375 | T16: 0.08 | U16: =S16*(1-T16) -> 15985 | V16: NOK | W16: =IFERROR(VLOOKUP(V16,Curr!$B$2:$C$13,2,FALSE),0) -> 1 | X16: =U16*W16 -> 15985 | Y16: =Q16/11/0.85 -> 371.65775 | Z16: =+Y16*R16 -> 1858.2888 | AA16: EUR | AB16: =IFERROR(VLOOKUP(AA16,Curr!$B$2:$C$13,2,FALSE),0) -> 11 | AC16: =+Y16*AB16*R16 -> 20441.176 | AD16: =+AC16-X16 -> 4456.1765 | AE16: =IFERROR(AD16/AC16,0) -> 0.218
C17: Day 3 | D17: Transfer | E17: 26.09.2026 | J17: Flåm: Self transfer to your accommodation - A short walk from Flåm Station | Q17: 0 | R17: 0 | S17: =+Q17*R17 -> 0 | T17: 0 | U17: =S17*(1-T17) -> 0 | V17: EUR | W17: =IFERROR(VLOOKUP(V17,Curr!$B$2:$C$13,2,FALSE),0) -> 11 | X17: =U17*W17 -> 0 | Y17: =Q17 -> 0 | Z17: =+Y17*R17 -> 0 | AA17: EUR | AB17: =IFERROR(VLOOKUP(AA17,Curr!$B$2:$C$13,2,FALSE),0) -> 11 | AC17: =+Y17*AB17*R17 -> 0 | AD17: =+AC17-X17 -> 0 | AE17: =IFERROR(AD17/AC17,0) -> 0
C18: Day 3 | D18: Hotel | E18: 26.09.2026 | F18: 27.09.2026 | J18: Flåm: Check in to your accommodation for a 1 night stay - Fretheim Hotel - 3 × Historical Double Room - Breakfast included | P18: https://www.ratehawk.com/hotel/norway/aurland/mid7785115/fretheim_hotel/?q=6024041&dates=26.09.2026-27.09.2026&guests=2-2-1&meal_types=breakfast.halfBoard.fullBoard.allInclusive&price=one | Q18: 1403 | R18: 1 | S18: =+Q18*R18 -> 1403 | T18: 0 | U18: =S18*(1-T18) -> 1403 | V18: EUR | W18: =IFERROR(VLOOKUP(V18,Curr!$B$2:$C$13,2,FALSE),0) -> 11 | X18: =U18*W18 -> 15433 | Y18: =Q18/0.8 -> 1753.75 | Z18: =+Y18*R18 -> 1753.75 | AA18: EUR | AB18: =IFERROR(VLOOKUP(AA18,Curr!$B$2:$C$13,2,FALSE),0) -> 11 | AC18: =+Y18*AB18*R18 -> 19291.25 | AD18: =+AC18-X18 -> 3858.25 | AE18: =IFERROR(AD18/AC18,0) -> 0.2
C19: Day 3 | D19: Leisure | E19: 26.09.2026 | J19: Flåm: Spend time at leisure | Q19: 0 | R19: 0 | S19: =+Q19*R19 -> 0 | T19: 0 | U19: =S19*(1-T19) -> 0 | V19: EUR | W19: =IFERROR(VLOOKUP(V19,Curr!$B$2:$C$13,2,FALSE),0) -> 11 | X19: =U19*W19 -> 0 | Y19: =Q19 -> 0 | Z19: =+Y19*R19 -> 0 | AA19: EUR | AB19: =IFERROR(VLOOKUP(AA19,Curr!$B$2:$C$13,2,FALSE),0) -> 11 | AC19: =+Y19*AB19*R19 -> 0 | AD19: =+AC19-X19 -> 0 | AE19: =IFERROR(AD19/AC19,0) -> 0
S20: =+Q20*R20 -> 0 | T20: 0 | U20: =S20*(1-T20) -> 0 | V20: EUR | W20: =IFERROR(VLOOKUP(V20,Curr!$B$2:$C$13,2,FALSE),0) -> 11 | X20: =U20*W20 -> 0 | Y20: =Q20 -> 0 | Z20: =+Y20*R20 -> 0 | AA20: EUR | AB20: =IFERROR(VLOOKUP(AA20,Curr!$B$2:$C$13,2,FALSE),0) -> 11 | AC20: =+Y20*AB20*R20 -> 0 | AD20: =+AC20-X20 -> 0 | AE20: =IFERROR(AD20/AC20,0) -> 0
C21: Day 4 | D21: Transfer | E21: 27.09.2026 | J21: Flåm: Self transfer to Flåm Cruise Port - Short walk from your accommodation | Q21: 0 | R21: 0 | S21: =+Q21*R21 -> 0 | T21: 0 | U21: =S21*(1-T21) -> 0 | V21: EUR | W21: =IFERROR(VLOOKUP(V21,Curr!$B$2:$C$13,2,FALSE),0) -> 11 | X21: =U21*W21 -> 0 | Y21: =Q21 -> 0 | Z21: =+Y21*R21 -> 0 | AA21: EUR | AB21: =IFERROR(VLOOKUP(AA21,Curr!$B$2:$C$13,2,FALSE),0) -> 11 | AC21: =+Y21*AB21*R21 -> 0 | AD21: =+AC21-X21 -> 0 | AE21: =IFERROR(AD21/AC21,0) -> 0
C22: Day 4 | D22: Activity | E22: 27.09.2026 | J22: Flåm: Norway in a Nutshell to Bergen - Time: 12:00 pm - 6:17 pm - Meeting point: Flåm Harbor - Includes: Fjord Cruise Flåm to Gudvangen (12:00 pm - 2:00 pm), Coach Transfer Gudvangen to Voss (2:30 pm - 3:30 pm), Train transfer Voss to Bergen (4:57 pm - 6:17 pm) | O22: x | P22: https://www.fjordtours.com/en | Q22: 0 | R22: 0 | S22: =+Q22*R22 -> 0 | T22: 0.08 | U22: =S22*(1-T22) -> 0 | V22: NOK | W22: =IFERROR(VLOOKUP(V22,Curr!$B$2:$C$13,2,FALSE),0) -> 1 | X22: =U22*W22 -> 0 | Y22: =Q22 -> 0 | Z22: =+Y22*R22 -> 0 | AA22: EUR | AB22: =IFERROR(VLOOKUP(AA22,Curr!$B$2:$C$13,2,FALSE),0) -> 11 | AC22: =+Y22*AB22*R22 -> 0 | AD22: =+AC22-X22 -> 0 | AE22: =IFERROR(AD22/AC22,0) -> 0
C23: Day 4 | D23: Transfer | E23: 27.09.2026 | J23: Bergen: Self transfer to your accommodation | Q23: 1490 | R23: 0 | S23: =+Q23*R23 -> 0 | T23: 0.15 | U23: =S23*(1-T23) -> 0 | V23: NOK | W23: =IFERROR(VLOOKUP(V23,Curr!$B$2:$C$13,2,FALSE),0) -> 1 | X23: =U23*W23 -> 0 | Y23: =Q23/11/0.9 -> 150.50505 | Z23: =+Y23*R23 -> 0 | AA23: EUR | AB23: =IFERROR(VLOOKUP(AA23,Curr!$B$2:$C$13,2,FALSE),0) -> 11 | AC23: =+Y23*AB23*R23 -> 0 | AD23: =+AC23-X23 -> 0 | AE23: =IFERROR(AD23/AC23,0) -> 0
C24: Day 4 | D24: Hotel | E24: 27.09.2026 | F24: 30.09.2026 | J24: Bergen: Check in to your accommodation for a 3 night stay - Thon Hotel Rosenkrantz Bergen - 2 x Standard Double Room, 1 x Standard Single Room - Breakfast included | P24: https://app.hotelbeds.com/factsheet/stay/9418?check_in=27-09-2026&check_out=30-09-2026&occupancy=2~0_2~0_1~0&packaging=true | Q24: =937+346 -> 1283 | R24: 1 | S24: =+Q24*R24 -> 1283 | T24: 0 | U24: =S24*(1-T24) -> 1283 | V24: EUR | W24: =IFERROR(VLOOKUP(V24,Curr!$B$2:$C$13,2,FALSE),0) -> 11 | X24: =U24*W24 -> 14113 | Y24: =Q24/0.8 -> 1603.75 | Z24: =+Y24*R24 -> 1603.75 | AA24: EUR | AB24: =IFERROR(VLOOKUP(AA24,Curr!$B$2:$C$13,2,FALSE),0) -> 11 | AC24: =+Y24*AB24*R24 -> 17641.25 | AD24: =+AC24-X24 -> 3528.25 | AE24: =IFERROR(AD24/AC24,0) -> 0.2
C25: Day 4 | D25: Leisure | E25: 27.09.2026 | J25: Bergen: Spend time at leisure | Q25: 0 | R25: 0 | S25: =+Q25*R25 -> 0 | T25: 0 | U25: =S25*(1-T25) -> 0 | V25: EUR | W25: =IFERROR(VLOOKUP(V25,Curr!$B$2:$C$13,2,FALSE),0) -> 11 | X25: =U25*W25 -> 0 | Y25: =Q25 -> 0 | Z25: =+Y25*R25 -> 0 | AA25: EUR | AB25: =IFERROR(VLOOKUP(AA25,Curr!$B$2:$C$13,2,FALSE),0) -> 11 | AC25: =+Y25*AB25*R25 -> 0 | AD25: =+AC25-X25 -> 0 | AE25: =IFERROR(AD25/AC25,0) -> 0
S26: =+Q26*R26 -> 0 | T26: 0 | U26: =S26*(1-T26) -> 0 | V26: EUR | W26: =IFERROR(VLOOKUP(V26,Curr!$B$2:$C$13,2,FALSE),0) -> 11 | X26: =U26*W26 -> 0 | Y26: =Q26 -> 0 | Z26: =+Y26*R26 -> 0 | AA26: EUR | AB26: =IFERROR(VLOOKUP(AA26,Curr!$B$2:$C$13,2,FALSE),0) -> 11 | AC26: =+Y26*AB26*R26 -> 0 | AD26: =+AC26-X26 -> 0 | AE26: =IFERROR(AD26/AC26,0) -> 0
C27: Day 5 | D27: Activity | E27: 28.09.2026 | J27: Bergen: Guided Walking Tour of Bergen Past & Present - Time: 10:00 am - 12:00 pm - Meeting point: Bradbenken 1 - Includes: Profesional Guide - Description: Discover the stories, landscapes and local life that shaped Bergen from the Middle Ages to today. This relaxed, friendly walk takes you through historic streets, colourful neighbourhoods and lesser-known spots that most visitors miss. | O27: x | P27: https://booknordics.com/norway/western-fjord-norway/bergen-and-hardanger/a-walk-through-bergen-past-present | Q27: 325 | R27: 5 | S27: =+Q27*R27 -> 1625 | T27: 0.2 | U27: =S27*(1-T27) -> 1300 | V27: NOK | W27: =IFERROR(VLOOKUP(V27,Curr!$B$2:$C$13,2,FALSE),0) -> 1 | X27: =U27*W27 -> 1300 | Y27: =Q27/11/0.8 -> 36.931818 | Z27: =+Y27*R27 -> 184.65909 | AA27: EUR | AB27: =IFERROR(VLOOKUP(AA27,Curr!$B$2:$C$13,2,FALSE),0) -> 11 | AC27: =+Y27*AB27*R27 -> 2031.25 | AD27: =+AC27-X27 -> 731.25 | AE27: =IFERROR(AD27/AC27,0) -> 0.36
C28: Day 5 | D28: Activity | E28: 28.09.2026 | J28: Bergen: Fløibanen Funicluar - Time: Flexible - Meeting point: Vetrlidsallmenningen 23A - Includes: Tickets - Description: Take the funicular Fløibanen to the top of Mount Fløyen and experience spectacular views of the city, the fjord and the surrounding mountains. | O28: x | P28: https://www.floyen.no/en/floibanen/buy-tickets/ | Q28: 200 | R28: 5 | S28: =+Q28*R28 -> 1000 | T28: 0 | U28: =S28*(1-T28) -> 1000 | V28: NOK | W28: =IFERROR(VLOOKUP(V28,Curr!$B$2:$C$13,2,FALSE),0) -> 1 | X28: =U28*W28 -> 1000 | Y28: =Q28/11/0.8 -> 22.727273 | Z28: =+Y28*R28 -> 113.63636 | AA28: EUR | AB28: =IFERROR(VLOOKUP(AA28,Curr!$B$2:$C$13,2,FALSE),0) -> 11 | AC28: =+Y28*AB28*R28 -> 1250 | AD28: =+AC28-X28 -> 250 | AE28: =IFERROR(AD28/AC28,0) -> 0.2
C29: Day 5 | D29: Leisure | E29: 28.09.2026 | J29: Bergen: Spend time at leisure | Q29: 0 | R29: 0 | S29: =+Q29*R29 -> 0 | T29: 0 | U29: =S29*(1-T29) -> 0 | V29: EUR | W29: =IFERROR(VLOOKUP(V29,Curr!$B$2:$C$13,2,FALSE),0) -> 11 | X29: =U29*W29 -> 0 | Y29: =Q29 -> 0 | Z29: =+Y29*R29 -> 0 | AA29: EUR | AB29: =IFERROR(VLOOKUP(AA29,Curr!$B$2:$C$13,2,FALSE),0) -> 11 | AC29: =+Y29*AB29*R29 -> 0 | AD29: =+AC29-X29 -> 0 | AE29: =IFERROR(AD29/AC29,0) -> 0
S30: =+Q30*R30 -> 0 | T30: 0 | U30: =S30*(1-T30) -> 0 | V30: EUR | W30: =IFERROR(VLOOKUP(V30,Curr!$B$2:$C$13,2,FALSE),0) -> 11 | X30: =U30*W30 -> 0 | Y30: =Q30 -> 0 | Z30: =+Y30*R30 -> 0 | AA30: EUR | AB30: =IFERROR(VLOOKUP(AA30,Curr!$B$2:$C$13,2,FALSE),0) -> 11 | AC30: =+Y30*AB30*R30 -> 0 | AD30: =+AC30-X30 -> 0 | AE30: =IFERROR(AD30/AC30,0) -> 0
C31: Day 6 | D31: Activity | E31: 29.09.2026 | J31: Bergen: Private Day Tour to Hardanger Fjords & Waterfalls - Time: 09:00 am - 04:00 pm - Meeting point: Hotel pick up - Includes: Pick-up from your Bergen hotel or cruise port, Knowledgeable, English-speaking guide, Full-day tour to the Hardanger fjord and back, Flexible itinerary and personalized route, Stops at waterfalls and fjord viewpoints, Luxury private vehicle, 100% electric - Description: This private day trip begins in Bergen and takes you deep into the beauty of the Hardangerfjord region. Along the way, we make scenic stops to visit waterfalls, enjoy panoramic viewpoints, and capture photos of the fjord and landscapes. | P31: https://booknordics.com/norway/western-fjord-norway/bergen-and-hardanger/private-tour-in-fjords-waterfalls-of-hardanger-norway-our-absolute-bestseller | Q31: 802 | R31: 1 | S31: =+Q31*R31 -> 802 | T31: 0.15 | U31: =S31*(1-T31) -> 681.7 | V31: EUR | W31: =IFERROR(VLOOKUP(V31,Curr!$B$2:$C$13,2,FALSE),0) -> 11 | X31: =U31*W31 -> 7498.7 | Y31: =Q31/0.95 -> 844.21053 | Z31: =+Y31*R31 -> 844.21053 | AA31: EUR | AB31: =IFERROR(VLOOKUP(AA31,Curr!$B$2:$C$13,2,FALSE),0) -> 11 | AC31: =+Y31*AB31*R31 -> 9286.3158 | AD31: =+AC31-X31 -> 1787.6158 | AE31: =IFERROR(AD31/AC31,0) -> 0.1925
C32: Day 6 | D32: Leisure | E32: 29.09.2026 | J32: Bergen: Spend time at leisure | Q32: 0 | R32: 0 | S32: =+Q32*R32 -> 0 | T32: 0 | U32: =S32*(1-T32) -> 0 | V32: EUR | W32: =IFERROR(VLOOKUP(V32,Curr!$B$2:$C$13,2,FALSE),0) -> 11 | X32: =U32*W32 -> 0 | Y32: =Q32 -> 0 | Z32: =+Y32*R32 -> 0 | AA32: EUR | AB32: =IFERROR(VLOOKUP(AA32,Curr!$B$2:$C$13,2,FALSE),0) -> 11 | AC32: =+Y32*AB32*R32 -> 0 | AD32: =+AC32-X32 -> 0 | AE32: =IFERROR(AD32/AC32,0) -> 0
S33: =+Q33*R33 -> 0 | T33: 0 | U33: =S33*(1-T33) -> 0 | V33: EUR | W33: =IFERROR(VLOOKUP(V33,Curr!$B$2:$C$13,2,FALSE),0) -> 11 | X33: =U33*W33 -> 0 | Y33: =Q33 -> 0 | Z33: =+Y33*R33 -> 0 | AA33: EUR | AB33: =IFERROR(VLOOKUP(AA33,Curr!$B$2:$C$13,2,FALSE),0) -> 11 | AC33: =+Y33*AB33*R33 -> 0 | AD33: =+AC33-X33 -> 0 | AE33: =IFERROR(AD33/AC33,0) -> 0
C34: Day 7 | D34: Transfer | E34: 30.09.2026 | J34: Bergen: Self transfer to Bergen Airport | Q34: 1990 | R34: 0 | S34: =+Q34*R34 -> 0 | T34: 0.15 | U34: =S34*(1-T34) -> 0 | V34: NOK | W34: =IFERROR(VLOOKUP(V34,Curr!$B$2:$C$13,2,FALSE),0) -> 1 | X34: =U34*W34 -> 0 | Y34: =Q34/11/0.9 -> 201.0101 | Z34: =+Y34*R34 -> 0 | AA34: EUR | AB34: =IFERROR(VLOOKUP(AA34,Curr!$B$2:$C$13,2,FALSE),0) -> 11 | AC34: =+Y34*AB34*R34 -> 0 | AD34: =+AC34-X34 -> 0 | AE34: =IFERROR(AD34/AC34,0) -> 0
C35: Day 7 | D35: Flight | E35: 30.09.2026 | J35: Bergen: Flight to Tromsø - Time: 2:45 pm - 4:30 pm - Includes: Tickets, Luggage (1 x 23 kg check in and 1 x 8 kg carry on per person) | P35: https://www.wideroe.no/booking/booking#/select-flight | Q35: 1529 | R35: 5 | S35: =+Q35*R35 -> 7645 | T35: 0 | U35: =S35*(1-T35) -> 7645 | V35: NOK | W35: =IFERROR(VLOOKUP(V35,Curr!$B$2:$C$13,2,FALSE),0) -> 1 | X35: =U35*W35 -> 7645 | Y35: =Q35/11/0.8 -> 173.75 | Z35: =+Y35*R35 -> 868.75 | AA35: EUR | AB35: =IFERROR(VLOOKUP(AA35,Curr!$B$2:$C$13,2,FALSE),0) -> 11 | AC35: =+Y35*AB35*R35 -> 9556.25 | AD35: =+AC35-X35 -> 1911.25 | AE35: =IFERROR(AD35/AC35,0) -> 0.2
C36: Day 7 | D36: Transfer | E36: 30.09.2026 | J36: Tromsø: Self transfer to your accommodation | Q36: 2500 | R36: 0 | S36: =+Q36*R36 -> 0 | T36: 0 | U36: =S36*(1-T36) -> 0 | V36: NOK | W36: =IFERROR(VLOOKUP(V36,Curr!$B$2:$C$13,2,FALSE),0) -> 1 | X36: =U36*W36 -> 0 | Y36: =Q36/11/0.8 -> 284.09091 | Z36: =+Y36*R36 -> 0 | AA36: EUR | AB36: =IFERROR(VLOOKUP(AA36,Curr!$B$2:$C$13,2,FALSE),0) -> 11 | AC36: =+Y36*AB36*R36 -> 0 | AD36: =+AC36-X36 -> 0 | AE36: =IFERROR(AD36/AC36,0) -> 0
C37: Day 7 | D37: Hotel | E37: 30.09.2026 | F37: 04.10.2026 | J37: Tromsø: Check in to your accommodation for a 4 night stay - Quality Hotel Saga - 2 x Standard Double Room, 1 x Standard Twin - Breakfast included | P37: https://app.hotelbeds.com/factsheet/stay/70273?check_in=30-09-2026&check_out=04-10-2026&occupancy=2~0_2~0_1~0&packaging=true | Q37: =1255+529 -> 1784 | R37: 1 | S37: =+Q37*R37 -> 1784 | T37: 0 | U37: =S37*(1-T37) -> 1784 | V37: EUR | W37: =IFERROR(VLOOKUP(V37,Curr!$B$2:$C$13,2,FALSE),0) -> 11 | X37: =U37*W37 -> 19624 | Y37: =Q37/0.8 -> 2230 | Z37: =+Y37*R37 -> 2230 | AA37: EUR | AB37: =IFERROR(VLOOKUP(AA37,Curr!$B$2:$C$13,2,FALSE),0) -> 11 | AC37: =+Y37*AB37*R37 -> 24530 | AD37: =+AC37-X37 -> 4906 | AE37: =IFERROR(AD37/AC37,0) -> 0.2
C38: Day 7 | D38: Leisure | E38: 30.09.2026 | J38: Tromsø: Spend time at leisure | Q38: 0 | R38: 0 | S38: =+Q38*R38 -> 0 | T38: 0 | U38: =S38*(1-T38) -> 0 | V38: EUR | W38: =IFERROR(VLOOKUP(V38,Curr!$B$2:$C$13,2,FALSE),0) -> 11 | X38: =U38*W38 -> 0 | Y38: =Q38 -> 0 | Z38: =+Y38*R38 -> 0 | AA38: EUR | AB38: =IFERROR(VLOOKUP(AA38,Curr!$B$2:$C$13,2,FALSE),0) -> 11 | AC38: =+Y38*AB38*R38 -> 0 | AD38: =+AC38-X38 -> 0 | AE38: =IFERROR(AD38/AC38,0) -> 0
S39: =+Q39*R39 -> 0 | T39: 0 | U39: =S39*(1-T39) -> 0 | V39: EUR | W39: =IFERROR(VLOOKUP(V39,Curr!$B$2:$C$13,2,FALSE),0) -> 11 | X39: =U39*W39 -> 0 | Y39: =Q39 -> 0 | Z39: =+Y39*R39 -> 0 | AA39: EUR | AB39: =IFERROR(VLOOKUP(AA39,Curr!$B$2:$C$13,2,FALSE),0) -> 11 | AC39: =+Y39*AB39*R39 -> 0 | AD39: =+AC39-X39 -> 0 | AE39: =IFERROR(AD39/AC39,0) -> 0
C40: Day 8 | D40: Activity | E40: 01.10.2026 | J40: Tromsø: Fjord Tour of Kvaløya & Sommarøy - Time: 10:00 am - 3:00 pm - Meeting point: Hotel pick up - Includes: Pick-up/drop-off in central Tromsø, Knowledgeable, multilingual guide, Free photographs from the trip, 2-course meal with coffee or tea - Description: On this tour you will travel in our minibus around the fjords of the island of Kvaløya, nearby Tromsø, and enjoy a nice lunch on Sommarøy island. | O40: x | P40: https://book.fjellheisen.no/en/to-do/2043246/return-ticket/showdetails | Q40: 125 | R40: 5 | S40: =+Q40*R40 -> 625 | T40: 0.2 | U40: =S40*(1-T40) -> 500 | V40: EUR | W40: =IFERROR(VLOOKUP(V40,Curr!$B$2:$C$13,2,FALSE),0) -> 11 | X40: =U40*W40 -> 5500 | Y40: =Q40 -> 125 | Z40: =+Y40*R40 -> 625 | AA40: EUR | AB40: =IFERROR(VLOOKUP(AA40,Curr!$B$2:$C$13,2,FALSE),0) -> 11 | AC40: =+Y40*AB40*R40 -> 6875 | AD40: =+AC40-X40 -> 1375 | AE40: =IFERROR(AD40/AC40,0) -> 0.2
C41: Day 8 | D41: Leisure | E41: 01.10.2026 | J41: Tromsø: Spend time at leisure | Q41: 0 | R41: 0 | S41: =+Q41*R41 -> 0 | T41: 0 | U41: =S41*(1-T41) -> 0 | V41: EUR | W41: =IFERROR(VLOOKUP(V41,Curr!$B$2:$C$13,2,FALSE),0) -> 11 | X41: =U41*W41 -> 0 | Y41: =Q41 -> 0 | Z41: =+Y41*R41 -> 0 | AA41: EUR | AB41: =IFERROR(VLOOKUP(AA41,Curr!$B$2:$C$13,2,FALSE),0) -> 11 | AC41: =+Y41*AB41*R41 -> 0 | AD41: =+AC41-X41 -> 0 | AE41: =IFERROR(AD41/AC41,0) -> 0
C42: Day 8 | D42: Activity | E42: 01.10.2026 | J42: Tromsø: All-Evening Northern Lights Hunt by Minibus - Time: 7:00 pm - 12:00 am - Meeting point: Magic Ice Bar Tromsø, Kaigata 4 - Includes: Knowledgeable, English-speaking guide, Photos shared with you after the tour, Light snacks and warm/cold beverages - Description: Join our intimate minibus tour, limited to just 16 participants, for an unforgettable journey to witness the Aurora Borealis. | P42: https://booknordics.com/norway/northern-norway/tromso-region/full-day-magic-of-the-arctic-lights-in-tromso | Q42: 107 | R42: 5 | S42: =+Q42*R42 -> 535 | T42: 0.2 | U42: =S42*(1-T42) -> 428 | V42: EUR | W42: =IFERROR(VLOOKUP(V42,Curr!$B$2:$C$13,2,FALSE),0) -> 11 | X42: =U42*W42 -> 4708 | Y42: =Q42 -> 107 | Z42: =+Y42*R42 -> 535 | AA42: EUR | AB42: =IFERROR(VLOOKUP(AA42,Curr!$B$2:$C$13,2,FALSE),0) -> 11 | AC42: =+Y42*AB42*R42 -> 5885 | AD42: =+AC42-X42 -> 1177 | AE42: =IFERROR(AD42/AC42,0) -> 0.2
...
