Workbook

Sheet Curr
C1: NOK
B2: EUR | C2: 10.8
B3: SEK | C3: 1.02
B4: DKK | C4: 1.5
B5: ISK | C5: 0.075
B6: NOK | C6: 1
B7: USD | C7: 10.6

Sheet Kalk
B2: Dates: 27.06.2026
B3: Pax: 4
B4: Rooming: 2 x double
B6: ID | C6: Day | D6: Type | E6: From date | F6: To date | G6: From time | H6: To time | I6: Supplier | J6: Travel element | K6: Manual booking? | L6: Status | M6: Comments | N6: Non-refundable | O6: Refundable | P6: URL | Q6: Gross P per unit | R6: Units | S6: Gross P | T6: Supp Comm | U6: Net P | V6: Supp curr | W6: X-rate | X6: Net P NOK | Y6: Sales P per unit | Z6: Price | AA6: Sales curr | AB6: X-rate | AC6: Sales P NOK tot | AD6: GP NOK | AE6: GP % | AF6: VAT25 | AG6: VAT15 | AH6: VAT12 | AI6: VAT0-D | AJ6: VAT0-I
C7: Day 1 | D7: Arrival | E7: 27.06.2026 | J7: Keflavik: Welcome to Iceland | Q7: 0 | R7: 0 | S7: =+Q7*R7 -> 0 | T7: 0 | U7: =S7*(1-T7) -> 0 | V7: EUR | W7: =IFERROR(VLOOKUP(V7,Curr!$B$2:$C$13,2,FALSE),0) -> 10.8 | X7: =U7*W7 -> 0 | Y7: =Q7 -> 0 | Z7: =+Y7*R7 -> 0 | AA7: EUR | AB7: =IFERROR(VLOOKUP(AA7,Curr!$B$2:$C$13,2,FALSE),0) -> 10.8 | AC7: =+Y7*AB7*R7 -> 0 | AD7: =+AC7-X7 -> 0 | AE7: =IFERROR(AD7/AC7,0) -> 0
C8: Day 1 | D8: Car | E8: 27.06.2026 | J8: Keflavik: Pick up your rental car at Keflavik Airport Car rental office | Q8: 0 | R8: 0 | S8: =+Q8*R8 -> 0 | T8: 0 | U8: =S8*(1-T8) -> 0 | V8: EUR | W8: =IFERROR(VLOOKUP(V8,Curr!$B$2:$C$13,2,FALSE),0) -> 10.8 | X8: =U8*W8 -> 0 | Y8: =Q8 -> 0 | Z8: =+Y8*R8 -> 0 | AA8: EUR | AB8: =IFERROR(VLOOKUP(AA8,Curr!$B$2:$C$13,2,FALSE),0) -> 10.8 | AC8: =+Y8*AB8*R8 -> 0 | AD8: =+AC8-X8 -> 0 | AE8: =IFERROR(AD8/AC8,0) -> 0
C9: Day 1 | D9: Drive | E9: 27.06.2026 | J9: Keflavik: Drive to your accommodaiton | Q9: 0 | R9: 0 | S9: =+Q9*R9 -> 0 | T9: 0 | U9: =S9*(1-T9) -> 0 | V9: EUR | W9: =IFERROR(VLOOKUP(V9,Curr!$B$2:$C$13,2,FALSE),0) -> 10.8 | X9: =U9*W9 -> 0 | Y9: =Q9 -> 0 | Z9: =+Y9*R9 -> 0 | AA9: EUR | AB9: =IFERROR(VLOOKUP(AA9,Curr!$B$2:$C$13,2,FALSE),0) -> 10.8 | AC9: =+Y9*AB9*R9 -> 0 | AD9: =+AC9-X9 -> 0 | AE9: =IFERROR(AD9/AC9,0) -> 0
C10: Day 1 | D10: Hotel | E10: 27.06.2026 | F10: 29.06.2026 | J10: Vik: Check in to your accommodation for a 2 night stay - - 2 x double room - breakfast included | Q10: 0 | R10: 0 | S10: =+Q10*R10 -> 0 | T10: 0 | U10: =S10*(1-T10) -> 0 | V10: EUR | W10: =IFERROR(VLOOKUP(V10,Curr!$B$2:$C$13,2,FALSE),0) -> 10.8 | X10: =U10*W10 -> 0 | Y10: =Q10 -> 0 | Z10: =+Y10*R10 -> 0 | AA10: EUR | AB10: =IFERROR(VLOOKUP(AA10,Curr!$B$2:$C$13,2,FALSE),0) -> 10.8 | AC10: =+Y10*AB10*R10 -> 0 | AD10: =+AC10-X10 -> 0 | AE10: =IFERROR(AD10/AC10,0) -> 0
C11: Day 1 | D11: Leisure | E11: 27.06.2026 | J11: Vik: Spend time at leisure | Q11: 0 | R11: 0 | S11: =+Q11*R11 -> 0 | T11: 0 | U11: =S11*(1-T11) -> 0 | V11: EUR | W11: =IFERROR(VLOOKUP(V11,Curr!$B$2:$C$13,2,FALSE),0) -> 10.8 | X11: =U11*W11 -> 0 | Y11: =Q11 -> 0 | Z11: =+Y11*R11 -> 0 | AA11: EUR | AB11: =IFERROR(VLOOKUP(AA11,Curr!$B$2:$C$13,2,FALSE),0) -> 10.8 | AC11: =+Y11*AB11*R11 -> 0 | AD11: =+AC11-X11 -> 0 | AE11: =IFERROR(AD11/AC11,0) -> 0
S12: =+Q12*R12 -> 0 | T12: 0 | U12: =S12*(1-T12) -> 0 | V12: EUR | W12: =IFERROR(VLOOKUP(V12,Curr!$B$2:$C$13,2,FALSE),0) -> 10.8 | X12: =U12*W12 -> 0 | Y12: =Q12 -> 0 | Z12: =+Y12*R12 -> 0 | AA12: EUR | AB12: =IFERROR(VLOOKUP(AA12,Curr!$B$2:$C$13,2,FALSE),0) -> 10.8 | AC12: =+Y12*AB12*R12 -> 0 | AD12: =+AC12-X12 -> 0 | AE12: =IFERROR(AD12/AC12,0) -> 0
C13: Day 2 | D13: Activity | E13: 28.06.2026 | J13: Lava | Q13: 0 | R13: 0 | S13: =+Q13*R13 -> 0 | T13: 0 | U13: =S13*(1-T13) -> 0 | V13: EUR | W13: =IFERROR(VLOOKUP(V13,Curr!$B$2:$C$13,2,FALSE),0) -> 10.8 | X13: =U13*W13 -> 0 | Y13: =Q13 -> 0 | Z13: =+Y13*R13 -> 0 | AA13: EUR | AB13: =IFERROR(VLOOKUP(AA13,Curr!$B$2:$C$13,2,FALSE),0) -> 10.8 | AC13: =+Y13*AB13*R13 -> 0 | AD13: =+AC13-X13 -> 0 | AE13: =IFERROR(AD13/AC13,0) -> 0
C14: Day 2 | D14: Leisure | E14: 28.06.2026 | J14: Vik: Spend time at leisure | Q14: 0 | R14: 0 | S14: =+Q14*R14 -> 0 | T14: 0 | U14: =S14*(1-T14) -> 0 | V14: EUR | W14: =IFERROR(VLOOKUP(V14,Curr!$B$2:$C$13,2,FALSE),0) -> 10.8 | X14: =U14*W14 -> 0 | Y14: =Q14 -> 0 | Z14: =+Y14*R14 -> 0 | AA14: EUR | AB14: =IFERROR(VLOOKUP(AA14,Curr!$B$2:$C$13,2,FALSE),0) -> 10.8 | AC14: =+Y14*AB14*R14 -> 0 | AD14: =+AC14-X14 -> 0 | AE14: =IFERROR(AD14/AC14,0) -> 0
C15: Day 2 | D15: Activity | E15: 28.06.2026 | J15: Ice Cave | Q15: 0 | R15: 0 | S15: =+Q15*R15 -> 0 | T15: 0 | U15: =S15*(1-T15) -> 0 | V15: EUR | W15: =IFERROR(VLOOKUP(V15,Curr!$B$2:$C$13,2,FALSE),0) -> 10.8 | X15: =U15*W15 -> 0 | Y15: =Q15 -> 0 | Z15: =+Y15*R15 -> 0 | AA15: EUR | AB15: =IFERROR(VLOOKUP(AA15,Curr!$B$2:$C$13,2,FALSE),0) -> 10.8 | AC15: =+Y15*AB15*R15 -> 0 | AD15: =+AC15-X15 -> 0 | AE15: =IFERROR(AD15/AC15,0) -> 0
S16: =+Q16*R16 -> 0 | T16: 0 | U16: =S16*(1-T16) -> 0 | V16: EUR | W16: =IFERROR(VLOOKUP(V16,Curr!$B$2:$C$13,2,FALSE),0) -> 10.8 | X16: =U16*W16 -> 0 | Y16: =Q16 -> 0 | Z16: =+Y16*R16 -> 0 | AA16: EUR | AB16: =IFERROR(VLOOKUP(AA16,Curr!$B$2:$C$13,2,FALSE),0) -> 10.8 | AC16: =+Y16*AB16*R16 -> 0 | AD16: =+AC16-X16 -> 0 | AE16: =IFERROR(AD16/AC16,0) -> 0
C17: Day 3 | D17: Drive | E17: 29.06.2026 | J17: Vik: Drive to Selfoss, then embark on the Golden Circle - Driving time: 4hrs 40 minutes (without stops) - Things to see: Kerið Crater Lake, Fridheimar Tomato Farm, Gullfoss Waterfall, Geysir Hot Spring, Efstidalur Dairy Farm, Öxarárfoss Waterfall, Thingvellir National Park | P17: https://www.google.no/maps/dir/V%C3%ADk+%C3%AD+M%C3%BDrdal,+870,+Island/Keri%C3%B0,+805+Klausturholar,+Island/Fri%C3%B0heimar,+5HH4%2B225,+Fri%C3%B0heimar,+806+Reykholt,+Island/Gullfoss+Waterfall+Lookout,+above,+Gullfoss+Parking,+Island/Geysir+Hot+Springs,+333,+806,+Island/%C3%96xar%C3%A1rfoss,+7V8J%2B8RH,+806+Thingvellir,+Island/Reykjav%C3%ADk,+Island/@64.0776152,-20.5649188,170091m/data=!3m1!1e3!4m44!4m43!1m5!1m1!1s0x48d74a424936b0d1:0xbe83531b006d778d!2m2!1d-18.9974396!2d63.4176505!1m5!1m1!1s0x48d68bb755f6f257:0x515a44e0c12ed907!2m2!1d-20.8851466!2d64.0412785!1m5!1m1!1s0x48d696fbe383f7bb:0xdee6f1f7177295af!2m2!1d-20.4448859!2d64.177503!1m5!1m1!1s0x48d6a5f34f4c88b1:0xd3558f2a84b426ba!2m2!1d-20.1244323!2d64.326181!1m5!1m1!1s0x48d6a3ec33d9dc1f:0xda8b28dafde977e5!2m2!1d-20.299508!2d64.3137795!1m5!1m1!1s0x48d6811eadf0fd95:0x48dd72aa97e36e57!2m2!1d-21.117885!2d64.2658062!1m5!1m1!1s0x48d674b9eedcedc3:0xec912ca230d26071!2m2!1d-21.9407552!2d64.1469868!3e0?entry=ttu&g_ep=EgoyMDI2MDQwNy4wIKXMDSoASAFQAw%3D%3D | Q17: 0 | R17: 0 | S17: =+Q17*R17 -> 0 | T17: 0 | U17: =S17*(1-T17) -> 0 | V17: EUR | W17: =IFERROR(VLOOKUP(V17,Curr!$B$2:$C$13,2,FALSE),0) -> 10.8 | X17: =U17*W17 -> 0 | Y17: =Q17 -> 0 | Z17: =+Y17*R17 -> 0 | AA17: EUR | AB17: =IFERROR(VLOOKUP(AA17,Curr!$B$2:$C$13,2,FALSE),0) -> 10.8 | AC17: =+Y17*AB17*R17 -> 0 | AD17: =+AC17-X17 -> 0 | AE17: =IFERROR(AD17/AC17,0) -> 0
C18: Day 3 | D18: Hotel | E18: 29.06.2026 | F18: 03.07.2026 | J18: Reykjavik: Check in to your accommodation for a 4 night stay - - 2 x double room - breakfast included | Q18: 0 | R18: 0 | S18: =+Q18*R18 -> 0 | T18: 0 | U18: =S18*(1-T18) -> 0 | V18: EUR | W18: =IFERROR(VLOOKUP(V18,Curr!$B$2:$C$13,2,FALSE),0) -> 10.8 | X18: =U18*W18 -> 0 | Y18: =Q18 -> 0 | Z18: =+Y18*R18 -> 0 | AA18: EUR | AB18: =IFERROR(VLOOKUP(AA18,Curr!$B$2:$C$13,2,FALSE),0) -> 10.8 | AC18: =+Y18*AB18*R18 -> 0 | AD18: =+AC18-X18 -> 0 | AE18: =IFERROR(AD18/AC18,0) -> 0
C19: Day 3 | D19: Leisure | E19: 29.06.2026 | J19: Reykjavik: Spend time at leisure | Q19: 0 | R19: 0 | S19: =+Q19*R19 -> 0 | T19: 0 | U19: =S19*(1-T19) -> 0 | V19: EUR | W19: =IFERROR(VLOOKUP(V19,Curr!$B$2:$C$13,2,FALSE),0) -> 10.8 | X19: =U19*W19 -> 0 | Y19: =Q19 -> 0 | Z19: =+Y19*R19 -> 0 | AA19: EUR | AB19: =IFERROR(VLOOKUP(AA19,Curr!$B$2:$C$13,2,FALSE),0) -> 10.8 | AC19: =+Y19*AB19*R19 -> 0 | AD19: =+AC19-X19 -> 0 | AE19: =IFERROR(AD19/AC19,0) -> 0
S20: =+Q20*R20 -> 0 | T20: 0 | U20: =S20*(1-T20) -> 0 | V20: EUR | W20: =IFERROR(VLOOKUP(V20,Curr!$B$2:$C$13,2,FALSE),0) -> 10.8 | X20: =U20*W20 -> 0 | Y20: =Q20 -> 0 | Z20: =+Y20*R20 -> 0 | AA20: EUR | AB20: =IFERROR(VLOOKUP(AA20,Curr!$B$2:$C$13,2,FALSE),0) -> 10.8 | AC20: =+Y20*AB20*R20 -> 0 | AD20: =+AC20-X20 -> 0 | AE20: =IFERROR(AD20/AC20,0) -> 0
C21: Day 4 | D21: Activity | E21: 30.06.2026 | J21: Fly oVer | Q21: 0 | R21: 0 | S21: =+Q21*R21 -> 0 | T21: 0 | U21: =S21*(1-T21) -> 0 | V21: EUR | W21: =IFERROR(VLOOKUP(V21,Curr!$B$2:$C$13,2,FALSE),0) -> 10.8 | X21: =U21*W21 -> 0 | Y21: =Q21 -> 0 | Z21: =+Y21*R21 -> 0 | AA21: EUR | AB21: =IFERROR(VLOOKUP(AA21,Curr!$B$2:$C$13,2,FALSE),0) -> 10.8 | AC21: =+Y21*AB21*R21 -> 0 | AD21: =+AC21-X21 -> 0 | AE21: =IFERROR(AD21/AC21,0) -> 0
C22: Day 4 | D22: Leisure | E22: 30.06.2026 | J22: Reykjavik: Spend time at leisure | Q22: 0 | R22: 0 | S22: =+Q22*R22 -> 0 | T22: 0 | U22: =S22*(1-T22) -> 0 | V22: EUR | W22: =IFERROR(VLOOKUP(V22,Curr!$B$2:$C$13,2,FALSE),0) -> 10.8 | X22: =U22*W22 -> 0 | Y22: =Q22 -> 0 | Z22: =+Y22*R22 -> 0 | AA22: EUR | AB22: =IFERROR(VLOOKUP(AA22,Curr!$B$2:$C$13,2,FALSE),0) -> 10.8 | AC22: =+Y22*AB22*R22 -> 0 | AD22: =+AC22-X22 -> 0 | AE22: =IFERROR(AD22/AC22,0) -> 0
C23: Day 4 | D23: Activity | E23: 30.06.2026 | J23: Whale MidNightsun | Q23: 0 | R23: 0 | S23: =+Q23*R23 -> 0 | T23: 0 | U23: =S23*(1-T23) -> 0 | V23: EUR | W23: =IFERROR(VLOOKUP(V23,Curr!$B$2:$C$13,2,FALSE),0) -> 10.8 | X23: =U23*W23 -> 0 | Y23: =Q23 -> 0 | Z23: =+Y23*R23 -> 0 | AA23: EUR | AB23: =IFERROR(VLOOKUP(AA23,Curr!$B$2:$C$13,2,FALSE),0) -> 10.8 | AC23: =+Y23*AB23*R23 -> 0 | AD23: =+AC23-X23 -> 0 | AE23: =IFERROR(AD23/AC23,0) -> 0
S24: =+Q24*R24 -> 0 | T24: 0 | U24: =S24*(1-T24) -> 0 | V24: EUR | W24: =IFERROR(VLOOKUP(V24,Curr!$B$2:$C$13,2,FALSE),0) -> 10.8 | X24: =U24*W24 -> 0 | Y24: =Q24 -> 0 | Z24: =+Y24*R24 -> 0 | AA24: EUR | AB24: =IFERROR(VLOOKUP(AA24,Curr!$B$2:$C$13,2,FALSE),0) -> 10.8 | AC24: =+Y24*AB24*R24 -> 0 | AD24: =+AC24-X24 -> 0 | AE24: =IFERROR(AD24/AC24,0) -> 0
C25: Day 5 | D25: Optional | E25: 01.07.2026 | J25: Reykjavik: Self guided roadtrip to Snæfellnes - | Q25: 0 | R25: 0 | S25: =+Q25*R25 -> 0 | T25: 0 | U25: =S25*(1-T25) -> 0 | V25: EUR | W25: =IFERROR(VLOOKUP(V25,Curr!$B$2:$C$13,2,FALSE),0) -> 10.8 | X25: =U25*W25 -> 0 | Y25: =Q25 -> 0 | Z25: =+Y25*R25 -> 0 | AA25: EUR | AB25: =IFERROR(VLOOKUP(AA25,Curr!$B$2:$C$13,2,FALSE),0) -> 10.8 | AC25: =+Y25*AB25*R25 -> 0 | AD25: =+AC25-X25 -> 0 | AE25: =IFERROR(AD25/AC25,0) -> 0
C26: Day 5 | D26: Leisure | E26: 01.07.2026 | J26: Reykjavik: Spend time at leisure | Q26: 0 | R26: 0 | S26: =+Q26*R26 -> 0 | T26: 0 | U26: =S26*(1-T26) -> 0 | V26: EUR | W26: =IFERROR(VLOOKUP(V26,Curr!$B$2:$C$13,2,FALSE),0) -> 10.8 | X26: =U26*W26 -> 0 | Y26: =Q26 -> 0 | Z26: =+Y26*R26 -> 0 | AA26: EUR | AB26: =IFERROR(VLOOKUP(AA26,Curr!$B$2:$C$13,2,FALSE),0) -> 10.8 | AC26: =+Y26*AB26*R26 -> 0 | AD26: =+AC26-X26 -> 0 | AE26: =IFERROR(AD26/AC26,0) -> 0
S27: =+Q27*R27 -> 0 | T27: 0 | U27: =S27*(1-T27) -> 0 | V27: EUR | W27: =IFERROR(VLOOKUP(V27,Curr!$B$2:$C$13,2,FALSE),0) -> 10.8 | X27: =U27*W27 -> 0 | Y27: =Q27 -> 0 | Z27: =+Y27*R27 -> 0 | AA27: EUR | AB27: =IFERROR(VLOOKUP(AA27,Curr!$B$2:$C$13,2,FALSE),0) -> 10.8 | AC27: =+Y27*AB27*R27 -> 0 | AD27: =+AC27-X27 -> 0 | AE27: =IFERROR(AD27/AC27,0) -> 0
C28: Day 6 | D28: Activity | E28: 02.07.2026 | J28: Sky Lagoon | Q28: 0 | R28: 0 | S28: =+Q28*R28 -> 0 | T28: 0 | U28: =S28*(1-T28) -> 0 | V28: EUR | W28: =IFERROR(VLOOKUP(V28,Curr!$B$2:$C$13,2,FALSE),0) -> 10.8 | X28: =U28*W28 -> 0 | Y28: =Q28 -> 0 | Z28: =+Y28*R28 -> 0 | AA28: EUR | AB28: =IFERROR(VLOOKUP(AA28,Curr!$B$2:$C$13,2,FALSE),0) -> 10.8 | AC28: =+Y28*AB28*R28 -> 0 | AD28: =+AC28-X28 -> 0 | AE28: =IFERROR(AD28/AC28,0) -> 0
C29: Day 6 | D29: Leisure | E29: 02.07.2026 | J29: Reykjavik: Spend time at leisure | Q29: 0 | R29: 0 | S29: =+Q29*R29 -> 0 | T29: 0 | U29: =S29*(1-T29) -> 0 | V29: EUR | W29: =IFERROR(VLOOKUP(V29,Curr!$B$2:$C$13,2,FALSE),0) -> 10.8 | X29: =U29*W29 -> 0 | Y29: =Q29 -> 0 | Z29: =+Y29*R29 -> 0 | AA29: EUR | AB29: =IFERROR(VLOOKUP(AA29,Curr!$B$2:$C$13,2,FALSE),0) -> 10.8 | AC29: =+Y29*AB29*R29 -> 0 | AD29: =+AC29-X29 -> 0 | AE29: =IFERROR(AD29/AC29,0) -> 0
S30: =+Q30*R30 -> 0 | T30: 0 | U30: =S30*(1-T30) -> 0 | V30: EUR | W30: =IFERROR(VLOOKUP(V30,Curr!$B$2:$C$13,2,FALSE),0) -> 10.8 | X30: =U30*W30 -> 0 | Y30: =Q30 -> 0 | Z30: =+Y30*R30 -> 0 | AA30: EUR | AB30: =IFERROR(VLOOKUP(AA30,Curr!$B$2:$C$13,2,FALSE),0) -> 10.8 | AC30: =+Y30*AB30*R30 -> 0 | AD30: =+AC30-X30 -> 0 | AE30: =IFERROR(AD30/AC30,0) -> 0
C31: Day 7 | D31: Drive | E31: 03.07.2026 | J31: Reykjavik: Drive to Keflavik Airport | Q31: 0 | R31: 0 | S31: =+Q31*R31 -> 0 | T31: 0 | U31: =S31*(1-T31) -> 0 | V31: EUR | W31: =IFERROR(VLOOKUP(V31,Curr!$B$2:$C$13,2,FALSE),0) -> 10.8 | X31: =U31*W31 -> 0 | Y31: =Q31 -> 0 | Z31: =+Y31*R31 -> 0 | AA31: EUR | AB31: =IFERROR(VLOOKUP(AA31,Curr!$B$2:$C$13,2,FALSE),0) -> 10.8 | AC31: =+Y31*AB31*R31 -> 0 | AD31: =+AC31-X31 -> 0 | AE31: =IFERROR(AD31/AC31,0) -> 0
C32: Day 7 | D32: Car | E32: 03.07.2026 | J32: Keflavik: Deliver your rental car at the airport car rental office | Q32: 0 | R32: 0 | S32: =+Q32*R32 -> 0 | T32: 0 | U32: =S32*(1-T32) -> 0 | V32: EUR | W32: =IFERROR(VLOOKUP(V32,Curr!$B$2:$C$13,2,FALSE),0) -> 10.8 | X32: =U32*W32 -> 0 | Y32: =Q32 -> 0 | Z32: =+Y32*R32 -> 0 | AA32: EUR | AB32: =IFERROR(VLOOKUP(AA32,Curr!$B$2:$C$13,2,FALSE),0) -> 10.8 | AC32: =+Y32*AB32*R32 -> 0 | AD32: =+AC32-X32 -> 0 | AE32: =IFERROR(AD32/AC32,0) -> 0
C33: Day 7 | D33: Flight | E33: 03.07.2026 | J33: Keflavik: Flight to Oslo - Time: - Luggage included: 1 x 23 kg check in and 1 x 8 kg carry on per person | Q33: 0 | R33: 0 | S33: =+Q33*R33 -> 0 | T33: 0 | U33: =S33*(1-T33) -> 0 | V33: EUR | W33: =IFERROR(VLOOKUP(V33,Curr!$B$2:$C$13,2,FALSE),0) -> 10.8 | X33: =U33*W33 -> 0 | Y33: =Q33 -> 0 | Z33: =+Y33*R33 -> 0 | AA33: EUR | AB33: =IFERROR(VLOOKUP(AA33,Curr!$B$2:$C$13,2,FALSE),0) -> 10.8 | AC33: =+Y33*AB33*R33 -> 0 | AD33: =+AC33-X33 -> 0 | AE33: =IFERROR(AD33/AC33,0) -> 0
C34: Day 7 | D34: Transfer | E34: 03.07.2026 | J34: Oslo: Private transfer to your accommodation | Q34: 0 | R34: 0 | S34: =+Q34*R34 -> 0 | T34: 0 | U34: =S34*(1-T34) -> 0 | V34: EUR | W34: =IFERROR(VLOOKUP(V34,Curr!$B$2:$C$13,2,FALSE),0) -> 10.8 | X34: =U34*W34 -> 0 | Y34: =Q34 -> 0 | Z34: =+Y34*R34 -> 0 | AA34: EUR | AB34: =IFERROR(VLOOKUP(AA34,Curr!$B$2:$C$13,2,FALSE),0) -> 10.8 | AC34: =+Y34*AB34*R34 -> 0 | AD34: =+AC34-X34 -> 0 | AE34: =IFERROR(AD34/AC34,0) -> 0
C35: Day 7 | D35: Hotel | E35: 03.07.2026 | F35: 05.07.2026 | J35: Oslo: Check in to your accommodation for a X night stay - 2 x double room - breakfast included | Q35: 0 | R35: 0 | S35: =+Q35*R35 -> 0 | T35: 0 | U35: =S35*(1-T35) -> 0 | V35: EUR | W35: =IFERROR(VLOOKUP(V35,Curr!$B$2:$C$13,2,FALSE),0) -> 10.8 | X35: =U35*W35 -> 0 | Y35: =Q35 -> 0 | Z35: =+Y35*R35 -> 0 | AA35: EUR | AB35: =IFERROR(VLOOKUP(AA35,Curr!$B$2:$C$13,2,FALSE),0) -> 10.8 | AC35: =+Y35*AB35*R35 -> 0 | AD35: =+AC35-X35 -> 0 | AE35: =IFERROR(AD35/AC35,0) -> 0
C36: Day 7 | D36: Leisure | E36: 03.07.2026 | J36: Oslo: Spend time at leisure | Q36: 0 | R36: 0 | S36: =+Q36*R36 -> 0 | T36: 0 | U36: =S36*(1-T36) -> 0 | V36: EUR | W36: =IFERROR(VLOOKUP(V36,Curr!$B$2:$C$13,2,FALSE),0) -> 10.8 | X36: =U36*W36 -> 0 | Y36: =Q36 -> 0 | Z36: =+Y36*R36 -> 0 | AA36: EUR | AB36: =IFERROR(VLOOKUP(AA36,Curr!$B$2:$C$13,2,FALSE),0) -> 10.8 | AC36: =+Y36*AB36*R36 -> 0 | AD36: =+AC36-X36 -> 0 | AE36: =IFERROR(AD36/AC36,0) -> 0
S37: =+Q37*R37 -> 0 | T37: 0 | U37: =S37*(1-T37) -> 0 | V37: EUR | W37: =IFERROR(VLOOKUP(V37,Curr!$B$2:$C$13,2,FALSE),0) -> 10.8 | X37: =U37*W37 -> 0 | Y37: =Q37 -> 0 | Z37: =+Y37*R37 -> 0 | AA37: EUR | AB37: =IFERROR(VLOOKUP(AA37,Curr!$B$2:$C$13,2,FALSE),0) -> 10.8 | AC37: =+Y37*AB37*R37 -> 0 | AD37: =+AC37-X37 -> 0 | AE37: =IFERROR(AD37/AC37,0) -> 0
C38: Day 8 | D38: Activity | E38: 04.07.2026 | Q38: 0 | R38: 0 | S38: =+Q38*R38 -> 0 | T38: 0 | U38: =S38*(1-T38) -> 0 | V38: EUR | W38: =IFERROR(VLOOKUP(V38,Curr!$B$2:$C$13,2,FALSE),0) -> 10.8 | X38: =U38*W38 -> 0 | Y38: =Q38 -> 0 | Z38: =+Y38*R38 -> 0 | AA38: EUR | AB38: =IFERROR(VLOOKUP(AA38,Curr!$B$2:$C$13,2,FALSE),0) -> 10.8 | AC38: =+Y38*AB38*R38 -> 0 | AD38: =+AC38-X38 -> 0 | AE38: =IFERROR(AD38/AC38,0) -> 0
C39: Day 8 | D39: Leisure | E39: 04.07.2026 | J39: Oslo: Spend time at leisure | Q39: 0 | R39: 0 | S39: =+Q39*R39 -> 0 | T39: 0 | U39: =S39*(1-T39) -> 0 | V39: EUR | W39: =IFERROR(VLOOKUP(V39,Curr!$B$2:$C$13,2,FALSE),0) -> 10.8 | X39: =U39*W39 -> 0 | Y39: =Q39 -> 0 | Z39: =+Y39*R39 -> 0 | AA39: EUR | AB39: =IFERROR(VLOOKUP(AA39,Curr!$B$2:$C$13,2,FALSE),0) -> 10.8 | AC39: =+Y39*AB39*R39 -> 0 | AD39: =+AC39-X39 -> 0 | AE39: =IFERROR(AD39/AC39,0) -> 0
S40: =+Q40*R40 -> 0 | T40: 0 | U40: =S40*(1-T40) -> 0 | V40: EUR | W40: =IFERROR(VLOOKUP(V40,Curr!$B$2:$C$13,2,FALSE),0) -> 10.8 | X40: =U40*W40 -> 0 | Y40: =Q40 -> 0 | Z40: =+Y40*R40 -> 0 | AA40: EUR | AB40: =IFERROR(VLOOKUP(AA40,Curr!$B$2:$C$13,2,FALSE),0) -> 10.8 | AC40: =+Y40*AB40*R40 -> 0 | AD40: =+AC40-X40 -> 0 | AE40: =IFERROR(AD40/AC40,0) -> 0
C41: Day 9 | D41: Transfer | E41: 05.07.2026 | J41: Oslo: Self transfer to Oslo Central Station | Q41: 0 | R41: 0 | S41: =+Q41*R41 -> 0 | T41: 0 | U41: =S41*(1-T41) -> 0 | V41: EUR | W41: =IFERROR(VLOOKUP(V41,Curr!$B$2:$C$13,2,FALSE),0) -> 10.8 | X41: =U41*W41 -> 0 | Y41: =Q41 -> 0 | Z41: =+Y41*R41 -> 0 | AA41: EUR | AB41: =IFERROR(VLOOKUP(AA41,Curr!$B$2:$C$13,2,FALSE),0) -> 10.8 | AC41: =+Y41*AB41*R41 -> 0 | AD41: =+AC41-X41 -> 0 | AE41: =IFERROR(AD41/AC41,0) -> 0
C42: Day 9 | D42: Activity | E42: 05.07.2026 | J42: NIAN | Q42: 0 | R42: 0 | S42: =+Q42*R42 -> 0 | T42: 0 | U42: =S42*(1-T42) -> 0 | V42: EUR | W42: =IFERROR(VLOOKUP(V42,Curr!$B$2:$C$13,2,FALSE),0) -> 10.8 | X42: =U42*W42 -> 0 | Y42: =Q42 -> 0 | Z42: =+Y42*R42 -> 0 | AA42: EUR | AB42: =IFERROR(VLOOKUP(AA42,Curr!$B$2:$C$13,2,FALSE),0) -> 10.8 | AC42: =+Y42*AB42*R42 -> 0 | AD42: =+AC42-X42 -> 0 | AE42: =IFERROR(AD42/AC42,0) -> 0
...

Sheet Kalk 2
B2: Dates: 27.06.2026
B3: Pax: 4
B4: Rooming: 2 x double
B6: ID | C6: Day | D6: Type | E6: From date | F6: To date | G6: From time | H6: To time | I6: Supplier | J6: Travel element | K6: Manual booking? | L6: Status | M6: Comments | N6: Non-refundable | O6: Refundable | P6: URL | Q6: Gross P per unit | R6: Units | S6: Gross P | T6: Supp Comm | U6: Net P | V6: Supp curr | W6: X-rate | X6: Net P NOK | Y6: Sales P per unit | Z6: Price | AA6: Sales curr | AB6: X-rate | AC6: Sales P NOK tot | AD6: GP NOK | AE6: GP % | AF6: VAT25 | AG6: VAT15 | AH6: VAT12 | AI6: VAT0-D | AJ6: VAT0-I
C7: Day 1 | D7: Arrival | E7: 27.06.2026 | J7: Keflavik: Welcome to Iceland | Q7: 0 | R7: 0 | S7: =+Q7*R7 -> 0 | T7: 0 | U7: =S7*(1-T7) -> 0 | V7: EUR | W7: =IFERROR(VLOOKUP(V7,Curr!$B$2:$C$13,2,FALSE),0) -> 10.8 | X7: =U7*W7 -> 0 | Y7: =Q7 -> 0 | Z7: =+Y7*R7 -> 0 | AA7: EUR | AB7: =IFERROR(VLOOKUP(AA7,Curr!$B$2:$C$13,2,FALSE),0) -> 10.8 | AC7: =+Y7*AB7*R7 -> 0 | AD7: =+AC7-X7 -> 0 | AE7: =IFERROR(AD7/AC7,0) -> 0
C8: Day 1 | D8: Car | E8: 27.06.2026 | F8: 03.07.2026 | J8: Keflavik: Pick up your rental car at Keflavik Airport Car rental office - Car: Ford Kuga 4x4 - Automatic or similar - Includes: Unlimited milage, Airport service charge, Other taxes and service charges, Supplementary liability insurance, Collision damage waiver, Fuel information, Third party coverage, Theft protection, Vat | Q8: 535 | R8: 1 | S8: =+Q8*R8 -> 535 | T8: 0 | U8: =S8*(1-T8) -> 535 | V8: EUR | W8: =IFERROR(VLOOKUP(V8,Curr!$B$2:$C$13,2,FALSE),0) -> 10.8 | X8: =U8*W8 -> 5778 | Y8: =Q8/0.8 -> 668.75 | Z8: =+Y8*R8 -> 668.75 | AA8: EUR | AB8: =IFERROR(VLOOKUP(AA8,Curr!$B$2:$C$13,2,FALSE),0) -> 10.8 | AC8: =+Y8*AB8*R8 -> 7222.5 | AD8: =+AC8-X8 -> 1444.5 | AE8: =IFERROR(AD8/AC8,0) -> 0.2
C9: Day 1 | D9: Drive | E9: 27.06.2026 | J9: Keflavik: Drive to your accommodaiton | Q9: 0 | R9: 0 | S9: =+Q9*R9 -> 0 | T9: 0 | U9: =S9*(1-T9) -> 0 | V9: EUR | W9: =IFERROR(VLOOKUP(V9,Curr!$B$2:$C$13,2,FALSE),0) -> 10.8 | X9: =U9*W9 -> 0 | Y9: =Q9 -> 0 | Z9: =+Y9*R9 -> 0 | AA9: EUR | AB9: =IFERROR(VLOOKUP(AA9,Curr!$B$2:$C$13,2,FALSE),0) -> 10.8 | AC9: =+Y9*AB9*R9 -> 0 | AD9: =+AC9-X9 -> 0 | AE9: =IFERROR(AD9/AC9,0) -> 0
C10: Day 1 | D10: Hotel | E10: 27.06.2026 | F10: 28.07.2026 | J10: Reykjavik: Check in to your accommodation for a 1 night stay - Grandi by Center Hotels - 2 x Standard twin/double - breakfast included | P10: https://app.hotelbeds.com/factsheet/stay/749447?check_in=27-06-2026&check_out=28-06-2026&occupancy=2~0_2~0&packaging=true | Q10: 574 | R10: 1 | S10: =+Q10*R10 -> 574 | T10: 0 | U10: =S10*(1-T10) -> 574 | V10: EUR | W10: =IFERROR(VLOOKUP(V10,Curr!$B$2:$C$13,2,FALSE),0) -> 10.8 | X10: =U10*W10 -> 6199.2 | Y10: =Q10/0.85 -> 675.29412 | Z10: =+Y10*R10 -> 675.29412 | AA10: EUR | AB10: =IFERROR(VLOOKUP(AA10,Curr!$B$2:$C$13,2,FALSE),0) -> 10.8 | AC10: =+Y10*AB10*R10 -> 7293.1765 | AD10: =+AC10-X10 -> 1093.9765 | AE10: =IFERROR(AD10/AC10,0) -> 0.15
C11: Day 1 | D11: Leisure | E11: 27.06.2026 | J11: Vik: Spend time at leisure | Q11: 0 | R11: 0 | S11: =+Q11*R11 -> 0 | T11: 0 | U11: =S11*(1-T11) -> 0 | V11: EUR | W11: =IFERROR(VLOOKUP(V11,Curr!$B$2:$C$13,2,FALSE),0) -> 10.8 | X11: =U11*W11 -> 0 | Y11: =Q11 -> 0 | Z11: =+Y11*R11 -> 0 | AA11: EUR | AB11: =IFERROR(VLOOKUP(AA11,Curr!$B$2:$C$13,2,FALSE),0) -> 10.8 | AC11: =+Y11*AB11*R11 -> 0 | AD11: =+AC11-X11 -> 0 | AE11: =IFERROR(AD11/AC11,0) -> 0
S12: =+Q12*R12 -> 0 | T12: 0 | U12: =S12*(1-T12) -> 0 | V12: EUR | W12: =IFERROR(VLOOKUP(V12,Curr!$B$2:$C$13,2,FALSE),0) -> 10.8 | X12: =U12*W12 -> 0 | Y12: =Q12 -> 0 | Z12: =+Y12*R12 -> 0 | AA12: EUR | AB12: =IFERROR(VLOOKUP(AA12,Curr!$B$2:$C$13,2,FALSE),0) -> 10.8 | AC12: =+Y12*AB12*R12 -> 0 | AD12: =+AC12-X12 -> 0 | AE12: =IFERROR(AD12/AC12,0) -> 0
C13: Day 2 | D13: Drive | E13: 28.07.2026 | J13: Reykjavik: Drive to Vik - Drivign time: | Q13: 0 | R13: 0 | S13: =+Q13*R13 -> 0 | T13: 0 | U13: =S13*(1-T13) -> 0 | V13: EUR | W13: =IFERROR(VLOOKUP(V13,Curr!$B$2:$C$13,2,FALSE),0) -> 10.8 | X13: =U13*W13 -> 0 | Y13: =Q13 -> 0 | Z13: =+Y13*R13 -> 0 | AA13: EUR | AB13: =IFERROR(VLOOKUP(AA13,Curr!$B$2:$C$13,2,FALSE),0) -> 10.8 | AC13: =+Y13*AB13*R13 -> 0 | AD13: =+AC13-X13 -> 0 | AE13: =IFERROR(AD13/AC13,0) -> 0
C14: Day 2 | D14: Hotel | E14: 28.07.2026 | F14: 30.06.2026 | J14: Vik: Check in to your accommodation for a 2 night stay - Hotel Katla by Keahotels - 2 x Superior Double room - breakfast included | P14: https://www.ratehawk.com/hotel/iceland/vik_i_myrdal/mid7524341/hotel_hofdabrekka_country_hotel/?q=6130429&dates=28.06.2026-30.06.2026&guests=2-2&payment=freecancellation&price=one&sid=22ec769a-b117-452f-befc-9c97bff50e0a | Q14: 2130 | R14: 1 | S14: =+Q14*R14 -> 2130 | T14: 0 | U14: =S14*(1-T14) -> 2130 | V14: EUR | W14: =IFERROR(VLOOKUP(V14,Curr!$B$2:$C$13,2,FALSE),0) -> 10.8 | X14: =U14*W14 -> 23004 | Y14: =Q14/0.85 -> 2505.8824 | Z14: =+Y14*R14 -> 2505.8824 | AA14: EUR | AB14: =IFERROR(VLOOKUP(AA14,Curr!$B$2:$C$13,2,FALSE),0) -> 10.8 | AC14: =+Y14*AB14*R14 -> 27063.529 | AD14: =+AC14-X14 -> 4059.5294 | AE14: =IFERROR(AD14/AC14,0) -> 0.15
C15: Day 2 | D15: Leisure | E15: 28.07.2026 | J15: Vik: Spend time at leisure | Q15: 0 | R15: 0 | S15: =+Q15*R15 -> 0 | T15: 0 | U15: =S15*(1-T15) -> 0 | V15: EUR | W15: =IFERROR(VLOOKUP(V15,Curr!$B$2:$C$13,2,FALSE),0) -> 10.8 | X15: =U15*W15 -> 0 | Y15: =Q15 -> 0 | Z15: =+Y15*R15 -> 0 | AA15: EUR | AB15: =IFERROR(VLOOKUP(AA15,Curr!$B$2:$C$13,2,FALSE),0) -> 10.8 | AC15: =+Y15*AB15*R15 -> 0 | AD15: =+AC15-X15 -> 0 | AE15: =IFERROR(AD15/AC15,0) -> 0
S16: =+Q16*R16 -> 0 | T16: 0 | U16: =S16*(1-T16) -> 0 | V16: EUR | W16: =IFERROR(VLOOKUP(V16,Curr!$B$2:$C$13,2,FALSE),0) -> 10.8 | X16: =U16*W16 -> 0 | Y16: =Q16 -> 0 | Z16: =+Y16*R16 -> 0 | AA16: EUR | AB16: =IFERROR(VLOOKUP(AA16,Curr!$B$2:$C$13,2,FALSE),0) -> 10.8 | AC16: =+Y16*AB16*R16 -> 0 | AD16: =+AC16-X16 -> 0 | AE16: =IFERROR(AD16/AC16,0) -> 0
C17: Day 3 | D17: Activity | E17: 29.06.2026 | J17: Vik: Lava Show Vík - Time: 11:00 am - 12:00 pm - Meeeting point: Icelandic Lava Show, Víkurbraut 5 - Includes: A chance to get up close to real flowing lava, The only live lava show in the world, Security goggles, A live host makes the show fun and personal, A short educational video about Icelandic volcanism, A true story from the 1918 Katla eruption, A sensory loaded experience - you feel the heat from the lava, A Q&A session at the end of the show, A unique once-in-a-lifetime experience | P17: https://booknordics.com/iceland/southern-iceland/vik/lava-show-vik-the-original | Q17: 46 | R17: 4 | S17: =+Q17*R17 -> 184 | T17: 0.2 | U17: =S17*(1-T17) -> 147.2 | V17: EUR | W17: =IFERROR(VLOOKUP(V17,Curr!$B$2:$C$13,2,FALSE),0) -> 10.8 | X17: =U17*W17 -> 1589.76 | Y17: =Q17 -> 46 | Z17: =+Y17*R17 -> 184 | AA17: EUR | AB17: =IFERROR(VLOOKUP(AA17,Curr!$B$2:$C$13,2,FALSE),0) -> 10.8 | AC17: =+Y17*AB17*R17 -> 1987.2 | AD17: =+AC17-X17 -> 397.44 | AE17: =IFERROR(AD17/AC17,0) -> 0.2
C18: Day 3 | D18: Leisure | E18: 29.06.2026 | J18: Vik: Spend time at leisure | Q18: 0 | R18: 0 | S18: =+Q18*R18 -> 0 | T18: 0 | U18: =S18*(1-T18) -> 0 | V18: EUR | W18: =IFERROR(VLOOKUP(V18,Curr!$B$2:$C$13,2,FALSE),0) -> 10.8 | X18: =U18*W18 -> 0 | Y18: =Q18 -> 0 | Z18: =+Y18*R18 -> 0 | AA18: EUR | AB18: =IFERROR(VLOOKUP(AA18,Curr!$B$2:$C$13,2,FALSE),0) -> 10.8 | AC18: =+Y18*AB18*R18 -> 0 | AD18: =+AC18-X18 -> 0 | AE18: =IFERROR(AD18/AC18,0) -> 0
C19: Day 3 | D19: Activity | E19: 29.06.2026 | J19: Vik: Ice Cave Underneath Katla Volcano Super Jeep Tour - Time: 6:00 pm - 9:00 pm - Meeting point: Tröll Expeditions Katla Ice Cave, Víkubraut 26 - Includes: Stunning ride on a super jeep, Certified glacier guide, Visit to a natural ice cave, All safety ice cave equipment, Scenic landscapes viewing | P19: https://booknordics.com/iceland/southern-iceland/vik/katla-ice-cave-super-jeep-from-vik | Q19: 204 | R19: 4 | S19: =+Q19*R19 -> 816 | T19: 0.25 | U19: =S19*(1-T19) -> 612 | V19: EUR | W19: =IFERROR(VLOOKUP(V19,Curr!$B$2:$C$13,2,FALSE),0) -> 10.8 | X19: =U19*W19 -> 6609.6 | Y19: =Q19 -> 204 | Z19: =+Y19*R19 -> 816 | AA19: EUR | AB19: =IFERROR(VLOOKUP(AA19,Curr!$B$2:$C$13,2,FALSE),0) -> 10.8 | AC19: =+Y19*AB19*R19 -> 8812.8 | AD19: =+AC19-X19 -> 2203.2 | AE19: =IFERROR(AD19/AC19,0) -> 0.25
S20: =+Q20*R20 -> 0 | T20: 0 | U20: =S20*(1-T20) -> 0 | V20: EUR | W20: =IFERROR(VLOOKUP(V20,Curr!$B$2:$C$13,2,FALSE),0) -> 10.8 | X20: =U20*W20 -> 0 | Y20: =Q20 -> 0 | Z20: =+Y20*R20 -> 0 | AA20: EUR | AB20: =IFERROR(VLOOKUP(AA20,Curr!$B$2:$C$13,2,FALSE),0) -> 10.8 | AC20: =+Y20*AB20*R20 -> 0 | AD20: =+AC20-X20 -> 0 | AE20: =IFERROR(AD20/AC20,0) -> 0
C21: Day 4 | D21: Drive | E21: 30.06.2026 | J21: Vik: Drive to Selfoss, then embark on the Golden Circle - Driving time: 4hrs 40 minutes (without stops) - Things to see: Kerið Crater Lake, Fridheimar Tomato Farm, Gullfoss Waterfall, Geysir Hot Spring, Efstidalur Dairy Farm, Öxarárfoss Waterfall, Thingvellir National Park | Q21: 0 | R21: 0 | S21: =+Q21*R21 -> 0 | T21: 0 | U21: =S21*(1-T21) -> 0 | V21: EUR | W21: =IFERROR(VLOOKUP(V21,Curr!$B$2:$C$13,2,FALSE),0) -> 10.8 | X21: =U21*W21 -> 0 | Y21: =Q21 -> 0 | Z21: =+Y21*R21 -> 0 | AA21: EUR | AB21: =IFERROR(VLOOKUP(AA21,Curr!$B$2:$C$13,2,FALSE),0) -> 10.8 | AC21: =+Y21*AB21*R21 -> 0 | AD21: =+AC21-X21 -> 0 | AE21: =IFERROR(AD21/AC21,0) -> 0
C22: Day 4 | D22: Hotel | E22: 30.06.2026 | F22: 03.07.2026 | J22: Reykjavik: Check in to your accommodation for a 3 night stay - Grandi by Center Hotels - 2 x Standard twin/double - breakfast included | P22: https://app.hotelbeds.com/factsheet/stay/749447?check_in=30-06-2026&check_out=03-07-2026&occupancy=2~0_2~0&packaging=true | Q22: 1634 | R22: 1 | S22: =+Q22*R22 -> 1634 | T22: 0 | U22: =S22*(1-T22) -> 1634 | V22: EUR | W22: =IFERROR(VLOOKUP(V22,Curr!$B$2:$C$13,2,FALSE),0) -> 10.8 | X22: =U22*W22 -> 17647.2 | Y22: =Q22/0.85 -> 1922.3529 | Z22: =+Y22*R22 -> 1922.3529 | AA22: EUR | AB22: =IFERROR(VLOOKUP(AA22,Curr!$B$2:$C$13,2,FALSE),0) -> 10.8 | AC22: =+Y22*AB22*R22 -> 20761.412 | AD22: =+AC22-X22 -> 3114.2118 | AE22: =IFERROR(AD22/AC22,0) -> 0.15
C23: Day 4 | D23: Leisure | E23: 30.06.2026 | J23: Reykjavik: Spend time at leisure | Q23: 0 | R23: 0 | S23: =+Q23*R23 -> 0 | T23: 0 | U23: =S23*(1-T23) -> 0 | V23: EUR | W23: =IFERROR(VLOOKUP(V23,Curr!$B$2:$C$13,2,FALSE),0) -> 10.8 | X23: =U23*W23 -> 0 | Y23: =Q23 -> 0 | Z23: =+Y23*R23 -> 0 | AA23: EUR | AB23: =IFERROR(VLOOKUP(AA23,Curr!$B$2:$C$13,2,FALSE),0) -> 10.8 | AC23: =+Y23*AB23*R23 -> 0 | AD23: =+AC23-X23 -> 0 | AE23: =IFERROR(AD23/AC23,0) -> 0
S24: =+Q24*R24 -> 0 | T24: 0 | U24: =S24*(1-T24) -> 0 | V24: EUR | W24: =IFERROR(VLOOKUP(V24,Curr!$B$2:$C$13,2,FALSE),0) -> 10.8 | X24: =U24*W24 -> 0 | Y24: =Q24 -> 0 | Z24: =+Y24*R24 -> 0 | AA24: EUR | AB24: =IFERROR(VLOOKUP(AA24,Curr!$B$2:$C$13,2,FALSE),0) -> 10.8 | AC24: =+Y24*AB24*R24 -> 0 | AD24: =+AC24-X24 -> 0 | AE24: =IFERROR(AD24/AC24,0) -> 0
C25: Day 5 | D25: Activity | E25: 01.07.2026 | J25: Reykjavik: FlyOver Iceland - Time: 12:30 pm - 1:30 pm - Meeting point: Fiskislóð 43 - Includes: Entry or admission fee, FlyOver Iceland Pursuit | P25: https://booknordics.com/iceland/western-iceland/reykjavik/flyover-iceland | Q25: 35 | R25: 4 | S25: =+Q25*R25 -> 140 | T25: 0.2 | U25: =S25*(1-T25) -> 112 | V25: EUR | W25: =IFERROR(VLOOKUP(V25,Curr!$B$2:$C$13,2,FALSE),0) -> 10.8 | X25: =U25*W25 -> 1209.6 | Y25: =Q25 -> 35 | Z25: =+Y25*R25 -> 140 | AA25: EUR | AB25: =IFERROR(VLOOKUP(AA25,Curr!$B$2:$C$13,2,FALSE),0) -> 10.8 | AC25: =+Y25*AB25*R25 -> 1512 | AD25: =+AC25-X25 -> 302.4 | AE25: =IFERROR(AD25/AC25,0) -> 0.2
C26: Day 5 | D26: Leisure | E26: 01.07.2026 | J26: Reykjavik: Spend time at leisure | Q26: 0 | R26: 0 | S26: =+Q26*R26 -> 0 | T26: 0 | U26: =S26*(1-T26) -> 0 | V26: EUR | W26: =IFERROR(VLOOKUP(V26,Curr!$B$2:$C$13,2,FALSE),0) -> 10.8 | X26: =U26*W26 -> 0 | Y26: =Q26 -> 0 | Z26: =+Y26*R26 -> 0 | AA26: EUR | AB26: =IFERROR(VLOOKUP(AA26,Curr!$B$2:$C$13,2,FALSE),0) -> 10.8 | AC26: =+Y26*AB26*R26 -> 0 | AD26: =+AC26-X26 -> 0 | AE26: =IFERROR(AD26/AC26,0) -> 0
C27: Day 5 | D27: Activity | E27: 01.07.2026 | J27: Reykjavík: Classic Whale Watching under the Midnight Sun - Time: 8:30 pm - 11:30 pm - Meeting point: Elding ticket office, Ægisgarður 5c -Includes: 2-3,5 hours whale watching tour, Access to our Wildlife Exhibition, Excellent live commentary in English, Use of warm overalls & mellow music | P27: https://booknordics.com/iceland/western-iceland/reykjavik/reykjavik-classic-whales-in-the-midnight-sun | Q27: 127 | R27: 4 | S27: =+Q27*R27 -> 508 | T27: 0.25 | U27: =S27*(1-T27) -> 381 | V27: EUR | W27: =IFERROR(VLOOKUP(V27,Curr!$B$2:$C$13,2,FALSE),0) -> 10.8 | X27: =U27*W27 -> 4114.8 | Y27: =Q27 -> 127 | Z27: =+Y27*R27 -> 508 | AA27: EUR | AB27: =IFERROR(VLOOKUP(AA27,Curr!$B$2:$C$13,2,FALSE),0) -> 10.8 | AC27: =+Y27*AB27*R27 -> 5486.4 | AD27: =+AC27-X27 -> 1371.6 | AE27: =IFERROR(AD27/AC27,0) -> 0.25
S28: =+Q28*R28 -> 0 | T28: 0 | U28: =S28*(1-T28) -> 0 | V28: EUR | W28: =IFERROR(VLOOKUP(V28,Curr!$B$2:$C$13,2,FALSE),0) -> 10.8 | X28: =U28*W28 -> 0 | Y28: =Q28 -> 0 | Z28: =+Y28*R28 -> 0 | AA28: EUR | AB28: =IFERROR(VLOOKUP(AA28,Curr!$B$2:$C$13,2,FALSE),0) -> 10.8 | AC28: =+Y28*AB28*R28 -> 0 | AD28: =+AC28-X28 -> 0 | AE28: =IFERROR(AD28/AC28,0) -> 0
C29: Day 6 | D29: Activity | E29: 02.07.2026 | J29: Reykjavik: Sky Lagoon Sér Pass with Transfer - Time: 2:00 pm - 4:30 pm - Meeting point: Hotel Pick up - Includes: Bus fare, Sky Lagoon Sér Admission, Complete Seven-step Ritual, Private Changing Facilities, Towel | P29: https://booknordics.com/iceland/western-iceland/reykjavik/sky-lagoon-sky-pass-with-transfer | Q29: 167 | R29: 4 | S29: =+Q29*R29 -> 668 | T29: 0.2 | U29: =S29*(1-T29) -> 534.4 | V29: EUR | W29: =IFERROR(VLOOKUP(V29,Curr!$B$2:$C$13,2,FALSE),0) -> 10.8 | X29: =U29*W29 -> 5771.52 | Y29: =Q29 -> 167 | Z29: =+Y29*R29 -> 668 | AA29: EUR | AB29: =IFERROR(VLOOKUP(AA29,Curr!$B$2:$C$13,2,FALSE),0) -> 10.8 | AC29: =+Y29*AB29*R29 -> 7214.4 | AD29: =+AC29-X29 -> 1442.88 | AE29: =IFERROR(AD29/AC29,0) -> 0.2
C30: Day 6 | D30: Leisure | E30: 02.07.2026 | J30: Reykjavik: Spend time at leisure | Q30: 0 | R30: 0 | S30: =+Q30*R30 -> 0 | T30: 0 | U30: =S30*(1-T30) -> 0 | V30: EUR | W30: =IFERROR(VLOOKUP(V30,Curr!$B$2:$C$13,2,FALSE),0) -> 10.8 | X30: =U30*W30 -> 0 | Y30: =Q30 -> 0 | Z30: =+Y30*R30 -> 0 | AA30: EUR | AB30: =IFERROR(VLOOKUP(AA30,Curr!$B$2:$C$13,2,FALSE),0) -> 10.8 | AC30: =+Y30*AB30*R30 -> 0 | AD30: =+AC30-X30 -> 0 | AE30: =IFERROR(AD30/AC30,0) -> 0
S31: =+Q31*R31 -> 0 | T31: 0 | U31: =S31*(1-T31) -> 0 | V31: EUR | W31: =IFERROR(VLOOKUP(V31,Curr!$B$2:$C$13,2,FALSE),0) -> 10.8 | X31: =U31*W31 -> 0 | Y31: =Q31 -> 0 | Z31: =+Y31*R31 -> 0 | AA31: EUR | AB31: =IFERROR(VLOOKUP(AA31,Curr!$B$2:$C$13,2,FALSE),0) -> 10.8 | AC31: =+Y31*AB31*R31 -> 0 | AD31: =+AC31-X31 -> 0 | AE31: =IFERROR(AD31/AC31,0) -> 0
C32: Day 7 | D32: Drive | E32: 03.07.2026 | J32: Reykjavik: Drive to Keflavik Airport | Q32: 0 | R32: 0 | S32: =+Q32*R32 -> 0 | T32: 0 | U32: =S32*(1-T32) -> 0 | V32: EUR | W32: =IFERROR(VLOOKUP(V32,Curr!$B$2:$C$13,2,FALSE),0) -> 10.8 | X32: =U32*W32 -> 0 | Y32: =Q32 -> 0 | Z32: =+Y32*R32 -> 0 | AA32: EUR | AB32: =IFERROR(VLOOKUP(AA32,Curr!$B$2:$C$13,2,FALSE),0) -> 10.8 | AC32: =+Y32*AB32*R32 -> 0 | AD32: =+AC32-X32 -> 0 | AE32: =IFERROR(AD32/AC32,0) -> 0
C33: Day 7 | D33: Car | E33: 03.07.2026 | J33: Keflavik: Deliver your rental car at the airport car rental office | Q33: 0 | R33: 0 | S33: =+Q33*R33 -> 0 | T33: 0 | U33: =S33*(1-T33) -> 0 | V33: EUR | W33: =IFERROR(VLOOKUP(V33,Curr!$B$2:$C$13,2,FALSE),0) -> 10.8 | X33: =U33*W33 -> 0 | Y33: =Q33 -> 0 | Z33: =+Y33*R33 -> 0 | AA33: EUR | AB33: =IFERROR(VLOOKUP(AA33,Curr!$B$2:$C$13,2,FALSE),0) -> 10.8 | AC33: =+Y33*AB33*R33 -> 0 | AD33: =+AC33-X33 -> 0 | AE33: =IFERROR(AD33/AC33,0) -> 0
C34: Day 7 | D34: Flight | E34: 03.07.2026 | J34: Keflavik: Flight to Oslo - Time: 09:10 am - 1:50 pm - Luggage included: 1 x 23 kg check in and 1 x 8 kg carry on per person | P34: https://www.sas.no/book/flights/?search=OW_KEF-OSL-20260703_a4c0i0y0&view=upsell&bookingFlow=revenue&out_flight_number=SK4788&skyscanner_redirectid=RhZvBkUmTrSXl9DScsN5CA&utm_source=skyscanner&utm_medium=metasearch&utm_campaign=skyscanner_metasearch&sortBy=rec&out_class=ECONOMY&out_sub_class=FLEX | Q34: 3747 | R34: 4 | S34: =+Q34*R34 -> 14988 | T34: 0 | U34: =S34*(1-T34) -> 14988 | V34: NOK | W34: =IFERROR(VLOOKUP(V34,Curr!$B$2:$C$13,2,FALSE),0) -> 1 | X34: =U34*W34 -> 14988 | Y34: =Q34/11/0.8 -> 425.79545 | Z34: =+Y34*R34 -> 1703.1818 | AA34: EUR | AB34: =IFERROR(VLOOKUP(AA34,Curr!$B$2:$C$13,2,FALSE),0) -> 10.8 | AC34: =+Y34*AB34*R34 -> 18394.364 | AD34: =+AC34-X34 -> 3406.3636 | AE34: =IFERROR(AD34/AC34,0) -> 0.18518519
C35: Day 7 | D35: Transfer | E35: 03.07.2026 | J35: Oslo: Private transfer to your accommodation | Q35: 1900 | R35: 1 | S35: =+Q35*R35 -> 1900 | T35: 0 | U35: =S35*(1-T35) -> 1900 | V35: NOK | W35: =IFERROR(VLOOKUP(V35,Curr!$B$2:$C$13,2,FALSE),0) -> 1 | X35: =U35*W35 -> 1900 | Y35: =Q35/11/0.8 -> 215.90909 | Z35: =+Y35*R35 -> 215.90909 | AA35: EUR | AB35: =IFERROR(VLOOKUP(AA35,Curr!$B$2:$C$13,2,FALSE),0) -> 10.8 | AC35: =+Y35*AB35*R35 -> 2331.8182 | AD35: =+AC35-X35 -> 431.81818 | AE35: =IFERROR(AD35/AC35,0) -> 0.18518519
C36: Day 7 | D36: Hotel | E36: 03.07.2026 | F36: 05.07.2026 | J36: Oslo: Check in to your accommodation for a 2 night stay - Clarion Hotel The Hub - 2 x double room - breakfast included | P36: https://app.hotelbeds.com/factsheet/stay/7398?check_in=03-07-2026&check_out=05-07-2026&occupancy=2~0_2~0&packaging=true | Q36: 1336 | R36: 1 | S36: =+Q36*R36 -> 1336 | T36: 0 | U36: =S36*(1-T36) -> 1336 | V36: EUR | W36: =IFERROR(VLOOKUP(V36,Curr!$B$2:$C$13,2,FALSE),0) -> 10.8 | X36: =U36*W36 -> 14428.8 | Y36: =Q36/0.85 -> 1571.7647 | Z36: =+Y36*R36 -> 1571.7647 | AA36: EUR | AB36: =IFERROR(VLOOKUP(AA36,Curr!$B$2:$C$13,2,FALSE),0) -> 10.8 | AC36: =+Y36*AB36*R36 -> 16975.059 | AD36: =+AC36-X36 -> 2546.2588 | AE36: =IFERROR(AD36/AC36,0) -> 0.15
C37: Day 7 | D37: Leisure | E37: 03.07.2026 | J37: Oslo: Spend time at leisure | Q37: 0 | R37: 0 | S37: =+Q37*R37 -> 0 | T37: 0 | U37: =S37*(1-T37) -> 0 | V37: EUR | W37: =IFERROR(VLOOKUP(V37,Curr!$B$2:$C$13,2,FALSE),0) -> 10.8 | X37: =U37*W37 -> 0 | Y37: =Q37 -> 0 | Z37: =+Y37*R37 -> 0 | AA37: EUR | AB37: =IFERROR(VLOOKUP(AA37,Curr!$B$2:$C$13,2,FALSE),0) -> 10.8 | AC37: =+Y37*AB37*R37 -> 0 | AD37: =+AC37-X37 -> 0 | AE37: =IFERROR(AD37/AC37,0) -> 0
S38: =+Q38*R38 -> 0 | T38: 0 | U38: =S38*(1-T38) -> 0 | V38: EUR | W38: =IFERROR(VLOOKUP(V38,Curr!$B$2:$C$13,2,FALSE),0) -> 10.8 | X38: =U38*W38 -> 0 | Y38: =Q38 -> 0 | Z38: =+Y38*R38 -> 0 | AA38: EUR | AB38: =IFERROR(VLOOKUP(AA38,Curr!$B$2:$C$13,2,FALSE),0) -> 10.8 | AC38: =+Y38*AB38*R38 -> 0 | AD38: =+AC38-X38 -> 0 | AE38: =IFERROR(AD38/AC38,0) -> 0
C39: Day 8 | D39: Activity | E39: 04.07.2026 | J39: Oslo: Fjord Sightseeing Cruise by 100% Electric Boat - Time: 1:30 pm - 3:30 pm - Meeting point: Rådhusbrygge 4, Platform E - Includes: Oslo Fjord archipelago cruise by electric boat, Cafeteria with snacks and drinks for purchase, "Voice of Norway" Audio guide for download, Stop at the Bygdøy peninsula near to museums | P39: https://booknordics.com/norway/eastern-norway/oslo/oslofjord-sightseeing-cruise | Q39: 40 | R39: 4 | S39: =+Q39*R39 -> 160 | T39: 0.2 | U39: =S39*(1-T39) -> 128 | V39: EUR | W39: =IFERROR(VLOOKUP(V39,Curr!$B$2:$C$13,2,FALSE),0) -> 10.8 | X39: =U39*W39 -> 1382.4 | Y39: =Q39 -> 40 | Z39: =+Y39*R39 -> 160 | AA39: EUR | AB39: =IFERROR(VLOOKUP(AA39,Curr!$B$2:$C$13,2,FALSE),0) -> 10.8 | AC39: =+Y39*AB39*R39 -> 1728 | AD39: =+AC39-X39 -> 345.6 | AE39: =IFERROR(AD39/AC39,0) -> 0.2
C40: Day 8 | D40: Leisure | E40: 04.07.2026 | J40: Oslo: Spend time at leisure | Q40: 0 | R40: 0 | S40: =+Q40*R40 -> 0 | T40: 0 | U40: =S40*(1-T40) -> 0 | V40: EUR | W40: =IFERROR(VLOOKUP(V40,Curr!$B$2:$C$13,2,FALSE),0) -> 10.8 | X40: =U40*W40 -> 0 | Y40: =Q40 -> 0 | Z40: =+Y40*R40 -> 0 | AA40: EUR | AB40: =IFERROR(VLOOKUP(AA40,Curr!$B$2:$C$13,2,FALSE),0) -> 10.8 | AC40: =+Y40*AB40*R40 -> 0 | AD40: =+AC40-X40 -> 0 | AE40: =IFERROR(AD40/AC40,0) -> 0
S41: =+Q41*R41 -> 0 | T41: 0 | U41: =S41*(1-T41) -> 0 | V41: EUR | W41: =IFERROR(VLOOKUP(V41,Curr!$B$2:$C$13,2,FALSE),0) -> 10.8 | X41: =U41*W41 -> 0 | Y41: =Q41 -> 0 | Z41: =+Y41*R41 -> 0 | AA41: EUR | AB41: =IFERROR(VLOOKUP(AA41,Curr!$B$2:$C$13,2,FALSE),0) -> 10.8 | AC41: =+Y41*AB41*R41 -> 0 | AD41: =+AC41-X41 -> 0 | AE41: =IFERROR(AD41/AC41,0) -> 0
C42: Day 9 | D42: Transfer | E42: 05.07.2026 | J42: Oslo: Self transfer to Oslo Central Station | Q42: 0 | R42: 0 | S42: =+Q42*R42 -> 0 | T42: 0 | U42: =S42*(1-T42) -> 0 | V42: EUR | W42: =IFERROR(VLOOKUP(V42,Curr!$B$2:$C$13,2,FALSE),0) -> 10.8 | X42: =U42*W42 -> 0 | Y42: =Q42 -> 0 | Z42: =+Y42*R42 -> 0 | AA42: EUR | AB42: =IFERROR(VLOOKUP(AA42,Curr!$B$2:$C$13,2,FALSE),0) -> 10.8 | AC42: =+Y42*AB42*R42 -> 0 | AD42: =+AC42-X42 -> 0 | AE42: =IFERROR(AD42/AC42,0) -> 0
...

Sheet Kalk 3
B2: Dates: 27.06.2026
B3: Pax: 4
B4: Rooming: 2 x double
B6: ID | C6: Day | D6: Type | E6: From date | F6: To date | G6: From time | H6: To time | I6: Supplier | J6: Travel element | K6: Manual booking? | L6: Status | M6: Comments | N6: Non-refundable | O6: Refundable | P6: URL | Q6: Gross P per unit | R6: Units | S6: Gross P | T6: Supp Comm | U6: Net P | V6: Supp curr | W6: X-rate | X6: Net P NOK | Y6: Sales P per unit | Z6: Price | AA6: Sales curr | AB6: X-rate | AC6: Sales P NOK tot | AD6: GP NOK | AE6: GP % | AF6: VAT25 | AG6: VAT15 | AH6: VAT12 | AI6: VAT0-D | AJ6: VAT0-I
C7: Day 1 | D7: Arrival | E7: 27.06.2026 | J7: Keflavik: Welcome to Iceland | Q7: 0 | R7: 0 | S7: =+Q7*R7 -> 0 | T7: 0 | U7: =S7*(1-T7) -> 0 | V7: EUR | W7: =IFERROR(VLOOKUP(V7,Curr!$B$2:$C$13,2,FALSE),0) -> 10.8 | X7: =U7*W7 -> 0 | Y7: =Q7 -> 0 | Z7: =+Y7*R7 -> 0 | AA7: EUR | AB7: =IFERROR(VLOOKUP(AA7,Curr!$B$2:$C$13,2,FALSE),0) -> 10.8 | AC7: =+Y7*AB7*R7 -> 0 | AD7: =+AC7-X7 -> 0 | AE7: =IFERROR(AD7/AC7,0) -> 0
C8: Day 1 | D8: Tranfser | E8: 27.06.2026 | J8: Keflavik: Private transfer to your accommodation | Q8: 160 | R8: 1 | S8: =+Q8*R8 -> 160 | T8: 0.2 | U8: =S8*(1-T8) -> 128 | V8: EUR | W8: =IFERROR(VLOOKUP(V8,Curr!$B$2:$C$13,2,FALSE),0) -> 10.8 | X8: =U8*W8 -> 1382.4 | Y8: =Q8 -> 160 | Z8: =+Y8*R8 -> 160 | AA8: EUR | AB8: =IFERROR(VLOOKUP(AA8,Curr!$B$2:$C$13,2,FALSE),0) -> 10.8 | AC8: =+Y8*AB8*R8 -> 1728 | AD8: =+AC8-X8 -> 345.6 | AE8: =IFERROR(AD8/AC8,0) -> 0.2
C9: Day 1 | D9: Hotel | E9: 27.06.2026 | F9: 28.06.2026 | J9: Reykjavik: Check in to your accommodation for a 1 night stay - Grandi by Center Hotels - 2 x Double deluxe - breakfast included | P9: https://app.hotelbeds.com/factsheet/stay/749447?check_in=27-06-2026&check_out=28-06-2026&occupancy=2~0_2~0&packaging=true | Q9: 811 | R9: 1 | S9: =+Q9*R9 -> 811 | T9: 0 | U9: =S9*(1-T9) -> 811 | V9: EUR | W9: =IFERROR(VLOOKUP(V9,Curr!$B$2:$C$13,2,FALSE),0) -> 10.8 | X9: =U9*W9 -> 8758.8 | Y9: =Q9/0.8 -> 1013.75 | Z9: =+Y9*R9 -> 1013.75 | AA9: EUR | AB9: =IFERROR(VLOOKUP(AA9,Curr!$B$2:$C$13,2,FALSE),0) -> 10.8 | AC9: =+Y9*AB9*R9 -> 10948.5 | AD9: =+AC9-X9 -> 2189.7 | AE9: =IFERROR(AD9/AC9,0) -> 0.2
C10: Day 1 | D10: Leisure | E10: 27.06.2026 | J10: Reykjavik: Spend time at leisure | Q10: 0 | R10: 0 | S10: =+Q10*R10 -> 0 | T10: 0 | U10: =S10*(1-T10) -> 0 | V10: EUR | W10: =IFERROR(VLOOKUP(V10,Curr!$B$2:$C$13,2,FALSE),0) -> 10.8 | X10: =U10*W10 -> 0 | Y10: =Q10 -> 0 | Z10: =+Y10*R10 -> 0 | AA10: EUR | AB10: =IFERROR(VLOOKUP(AA10,Curr!$B$2:$C$13,2,FALSE),0) -> 10.8 | AC10: =+Y10*AB10*R10 -> 0 | AD10: =+AC10-X10 -> 0 | AE10: =IFERROR(AD10/AC10,0) -> 0
S11: =+Q11*R11 -> 0 | T11: 0 | U11: =S11*(1-T11) -> 0 | V11: EUR | W11: =IFERROR(VLOOKUP(V11,Curr!$B$2:$C$13,2,FALSE),0) -> 10.8 | X11: =U11*W11 -> 0 | Y11: =Q11 -> 0 | Z11: =+Y11*R11 -> 0 | AA11: EUR | AB11: =IFERROR(VLOOKUP(AA11,Curr!$B$2:$C$13,2,FALSE),0) -> 10.8 | AC11: =+Y11*AB11*R11 -> 0 | AD11: =+AC11-X11 -> 0 | AE11: =IFERROR(AD11/AC11,0) -> 0
C12: Day 2 | D12: Transfer | E12: 28.06.2026 | J12: Reykjavik: Self transfer by Uber to the car rental office | Q12: 0 | R12: 0 | S12: =+Q12*R12 -> 0 | T12: 0 | U12: =S12*(1-T12) -> 0 | V12: EUR | W12: =IFERROR(VLOOKUP(V12,Curr!$B$2:$C$13,2,FALSE),0) -> 10.8 | X12: =U12*W12 -> 0 | Y12: =Q12 -> 0 | Z12: =+Y12*R12 -> 0 | AA12: EUR | AB12: =IFERROR(VLOOKUP(AA12,Curr!$B$2:$C$13,2,FALSE),0) -> 10.8 | AC12: =+Y12*AB12*R12 -> 0 | AD12: =+AC12-X12 -> 0 | AE12: =IFERROR(AD12/AC12,0) -> 0
C13: Day 2 | D13: Car | E13: 28.06.2026 | J13: Reykjavik: Pick up your rental car at the car rental office - Car: TOYOTA RAV4 2.0 4WD AUTOMATIC or similar - Office Location: Njardargata Fluggardar - Includes: Collision damage waiver, Fuel information, Unlimited mileage, Theft protection, Vat, Personal accident insurance, Cancellation fee - Excludes: 1 way fee, road tax | Q13: 691 | R13: 1 | S13: =+Q13*R13 -> 691 | T13: 0 | U13: =S13*(1-T13) -> 691 | V13: EUR | W13: =IFERROR(VLOOKUP(V13,Curr!$B$2:$C$13,2,FALSE),0) -> 10.8 | X13: =U13*W13 -> 7462.8 | Y13: =Q13/0.8 -> 863.75 | Z13: =+Y13*R13 -> 863.75 | AA13: EUR | AB13: =IFERROR(VLOOKUP(AA13,Curr!$B$2:$C$13,2,FALSE),0) -> 10.8 | AC13: =+Y13*AB13*R13 -> 9328.5 | AD13: =+AC13-X13 -> 1865.7 | AE13: =IFERROR(AD13/AC13,0) -> 0.2
C14: Day 2 | D14: Drive | E14: 28.06.2026 | J14: Reykjavik: Drive to Vik - Driving time: 2hrs 40 minutes | Q14: 0 | R14: 0 | S14: =+Q14*R14 -> 0 | T14: 0 | U14: =S14*(1-T14) -> 0 | V14: EUR | W14: =IFERROR(VLOOKUP(V14,Curr!$B$2:$C$13,2,FALSE),0) -> 10.8 | X14: =U14*W14 -> 0 | Y14: =Q14 -> 0 | Z14: =+Y14*R14 -> 0 | AA14: EUR | AB14: =IFERROR(VLOOKUP(AA14,Curr!$B$2:$C$13,2,FALSE),0) -> 10.8 | AC14: =+Y14*AB14*R14 -> 0 | AD14: =+AC14-X14 -> 0 | AE14: =IFERROR(AD14/AC14,0) -> 0
C15: Day 2 | D15: Hotel | E15: 28.06.2026 | F15: 30.06.2026 | J15: Vik: Check in to your accommodation for a 2 night stay - Hotel Katla by Keahotels - 2 x Superior Double room - breakfast included | P15: https://www.ratehawk.com/hotel/iceland/vik_i_myrdal/mid7524341/hotel_hofdabrekka_country_hotel/?q=6130429&dates=28.06.2026-30.06.2026&guests=2-2&payment=freecancellation&price=one&sid=22ec769a-b117-452f-befc-9c97bff50e0a | Q15: 2232 | R15: 1 | S15: =+Q15*R15 -> 2232 | T15: 0 | U15: =S15*(1-T15) -> 2232 | V15: EUR | W15: =IFERROR(VLOOKUP(V15,Curr!$B$2:$C$13,2,FALSE),0) -> 10.8 | X15: =U15*W15 -> 24105.6 | Y15: =Q15/0.85 -> 2625.8824 | Z15: =+Y15*R15 -> 2625.8824 | AA15: EUR | AB15: =IFERROR(VLOOKUP(AA15,Curr!$B$2:$C$13,2,FALSE),0) -> 10.8 | AC15: =+Y15*AB15*R15 -> 28359.529 | AD15: =+AC15-X15 -> 4253.9294 | AE15: =IFERROR(AD15/AC15,0) -> 0.15
C16: Day 2 | D16: Leisure | E16: 28.06.2026 | J16: Vik: Spend time at leisure | Q16: 0 | R16: 0 | S16: =+Q16*R16 -> 0 | T16: 0 | U16: =S16*(1-T16) -> 0 | V16: EUR | W16: =IFERROR(VLOOKUP(V16,Curr!$B$2:$C$13,2,FALSE),0) -> 10.8 | X16: =U16*W16 -> 0 | Y16: =Q16 -> 0 | Z16: =+Y16*R16 -> 0 | AA16: EUR | AB16: =IFERROR(VLOOKUP(AA16,Curr!$B$2:$C$13,2,FALSE),0) -> 10.8 | AC16: =+Y16*AB16*R16 -> 0 | AD16: =+AC16-X16 -> 0 | AE16: =IFERROR(AD16/AC16,0) -> 0
S17: =+Q17*R17 -> 0 | T17: 0 | U17: =S17*(1-T17) -> 0 | V17: EUR | W17: =IFERROR(VLOOKUP(V17,Curr!$B$2:$C$13,2,FALSE),0) -> 10.8 | X17: =U17*W17 -> 0 | Y17: =Q17 -> 0 | Z17: =+Y17*R17 -> 0 | AA17: EUR | AB17: =IFERROR(VLOOKUP(AA17,Curr!$B$2:$C$13,2,FALSE),0) -> 10.8 | AC17: =+Y17*AB17*R17 -> 0 | AD17: =+AC17-X17 -> 0 | AE17: =IFERROR(AD17/AC17,0) -> 0
C18: Day 3 | D18: Activity | E18: 29.06.2026 | J18: Vik: Lava Show Vík - Time: 11:00 am - 12:00 pm - Meeeting point: Icelandic Lava Show, Víkurbraut 5 - Includes: A chance to get up close to real flowing lava, The only live lava show in the world, Security goggles, A live host makes the show fun and personal, A short educational video about Icelandic volcanism, A true story from the 1918 Katla eruption, A sensory loaded experience - you feel the heat from the lava, A Q&A session at the end of the show, A unique once-in-a-lifetime experience | P18: https://booknordics.com/iceland/southern-iceland/vik/lava-show-vik-the-original | Q18: 46 | R18: 4 | S18: =+Q18*R18 -> 184 | T18: 0.2 | U18: =S18*(1-T18) -> 147.2 | V18: EUR | W18: =IFERROR(VLOOKUP(V18,Curr!$B$2:$C$13,2,FALSE),0) -> 10.8 | X18: =U18*W18 -> 1589.76 | Y18: =Q18 -> 46 | Z18: =+Y18*R18 -> 184 | AA18: EUR | AB18: =IFERROR(VLOOKUP(AA18,Curr!$B$2:$C$13,2,FALSE),0) -> 10.8 | AC18: =+Y18*AB18*R18 -> 1987.2 | AD18: =+AC18-X18 -> 397.44 | AE18: =IFERROR(AD18/AC18,0) -> 0.2
C19: Day 3 | D19: Leisure | E19: 29.06.2026 | J19: Vik: Spend time at leisure | Q19: 0 | R19: 0 | S19: =+Q19*R19 -> 0 | T19: 0 | U19: =S19*(1-T19) -> 0 | V19: EUR | W19: =IFERROR(VLOOKUP(V19,Curr!$B$2:$C$13,2,FALSE),0) -> 10.8 | X19: =U19*W19 -> 0 | Y19: =Q19 -> 0 | Z19: =+Y19*R19 -> 0 | AA19: EUR | AB19: =IFERROR(VLOOKUP(AA19,Curr!$B$2:$C$13,2,FALSE),0) -> 10.8 | AC19: =+Y19*AB19*R19 -> 0 | AD19: =+AC19-X19 -> 0 | AE19: =IFERROR(AD19/AC19,0) -> 0
C20: Day 3 | D20: Activity | E20: 29.06.2026 | J20: Vik: Ice Cave Underneath Katla Volcano Super Jeep Tour - Time: 6:00 pm - 9:00 pm - Meeting point: Tröll Expeditions Katla Ice Cave, Víkubraut 26 - Includes: Stunning ride on a super jeep, Certified glacier guide, Visit to a natural ice cave, All safety ice cave equipment, Scenic landscapes viewing | P20: https://booknordics.com/iceland/southern-iceland/vik/katla-ice-cave-super-jeep-from-vik | Q20: 204 | R20: 4 | S20: =+Q20*R20 -> 816 | T20: 0.25 | U20: =S20*(1-T20) -> 612 | V20: EUR | W20: =IFERROR(VLOOKUP(V20,Curr!$B$2:$C$13,2,FALSE),0) -> 10.8 | X20: =U20*W20 -> 6609.6 | Y20: =Q20 -> 204 | Z20: =+Y20*R20 -> 816 | AA20: EUR | AB20: =IFERROR(VLOOKUP(AA20,Curr!$B$2:$C$13,2,FALSE),0) -> 10.8 | AC20: =+Y20*AB20*R20 -> 8812.8 | AD20: =+AC20-X20 -> 2203.2 | AE20: =IFERROR(AD20/AC20,0) -> 0.25
S21: =+Q21*R21 -> 0 | T21: 0 | U21: =S21*(1-T21) -> 0 | V21: EUR | W21: =IFERROR(VLOOKUP(V21,Curr!$B$2:$C$13,2,FALSE),0) -> 10.8 | X21: =U21*W21 -> 0 | Y21: =Q21 -> 0 | Z21: =+Y21*R21 -> 0 | AA21: EUR | AB21: =IFERROR(VLOOKUP(AA21,Curr!$B$2:$C$13,2,FALSE),0) -> 10.8 | AC21: =+Y21*AB21*R21 -> 0 | AD21: =+AC21-X21 -> 0 | AE21: =IFERROR(AD21/AC21,0) -> 0
C22: Day 4 | D22: Drive | E22: 30.06.2026 | J22: Vik: Drive to Asborgir - Things to see: Hella, Seashells beach, Black Sand Dunes, Selfoss | Q22: 0 | R22: 0 | S22: =+Q22*R22 -> 0 | T22: 0 | U22: =S22*(1-T22) -> 0 | V22: EUR | W22: =IFERROR(VLOOKUP(V22,Curr!$B$2:$C$13,2,FALSE),0) -> 10.8 | X22: =U22*W22 -> 0 | Y22: =Q22 -> 0 | Z22: =+Y22*R22 -> 0 | AA22: EUR | AB22: =IFERROR(VLOOKUP(AA22,Curr!$B$2:$C$13,2,FALSE),0) -> 10.8 | AC22: =+Y22*AB22*R22 -> 0 | AD22: =+AC22-X22 -> 0 | AE22: =IFERROR(AD22/AC22,0) -> 0
C23: Day 4 | D23: Hotel | E23: 30.06.2026 | F23: 01.07.2026 | J23: Asborgir: Check in to your accommodaiton for a 1 night stay - Hotel Grimsborgir by Keahotels - 2 x Double deluxe - Breakfast included | P23: https://app.hotelbeds.com/factsheet/stay/257043?check_in=30-06-2026&check_out=01-07-2026&occupancy=2~0_2~0&packaging=true | Q23: 694 | R23: 1 | S23: =+Q23*R23 -> 694 | T23: 0 | U23: =S23*(1-T23) -> 694 | V23: EUR | W23: =IFERROR(VLOOKUP(V23,Curr!$B$2:$C$13,2,FALSE),0) -> 10.8 | X23: =U23*W23 -> 7495.2 | Y23: =Q23/0.85 -> 816.47059 | Z23: =+Y23*R23 -> 816.47059 | AA23: EUR | AB23: =IFERROR(VLOOKUP(AA23,Curr!$B$2:$C$13,2,FALSE),0) -> 10.8 | AC23: =+Y23*AB23*R23 -> 8817.8824 | AD23: =+AC23-X23 -> 1322.6824 | AE23: =IFERROR(AD23/AC23,0) -> 0.15
C24: Day 4 | D24: Leisure | E24: 30.06.2026 | J24: Asborgir: Spend time at leisure | Q24: 0 | R24: 0 | S24: =+Q24*R24 -> 0 | T24: 0 | U24: =S24*(1-T24) -> 0 | V24: EUR | W24: =IFERROR(VLOOKUP(V24,Curr!$B$2:$C$13,2,FALSE),0) -> 10.8 | X24: =U24*W24 -> 0 | Y24: =Q24 -> 0 | Z24: =+Y24*R24 -> 0 | AA24: EUR | AB24: =IFERROR(VLOOKUP(AA24,Curr!$B$2:$C$13,2,FALSE),0) -> 10.8 | AC24: =+Y24*AB24*R24 -> 0 | AD24: =+AC24-X24 -> 0 | AE24: =IFERROR(AD24/AC24,0) -> 0
S25: =+Q25*R25 -> 0 | T25: 0 | U25: =S25*(1-T25) -> 0 | V25: EUR | W25: =IFERROR(VLOOKUP(V25,Curr!$B$2:$C$13,2,FALSE),0) -> 10.8 | X25: =U25*W25 -> 0 | Y25: =Q25 -> 0 | Z25: =+Y25*R25 -> 0 | AA25: EUR | AB25: =IFERROR(VLOOKUP(AA25,Curr!$B$2:$C$13,2,FALSE),0) -> 10.8 | AC25: =+Y25*AB25*R25 -> 0 | AD25: =+AC25-X25 -> 0 | AE25: =IFERROR(AD25/AC25,0) -> 0
C26: Day 5 | D26: Drive | E26: 01.07.2026 | J26: Asborgir: Drive to Reykjavik via the Golden Circle - Driving time: 3 hrs (without stops) - Things to see: Kerið Crater Lake, Fridheimar Tomato Farm (perfect stop for lunch), Gullfoss Waterfall, Geysir Hot Spring, Efstidalur Dairy Farm, Öxarárfoss Waterfall, Thingvellir National Park | P26: https://www.google.no/maps/dir/Gr%C3%ADmsborgir+-+Restaurant+and+Bar,+805+Selfoss,+Island/Keri%C3%B0,+805+Klausturholar,+Island/Fri%C3%B0heimar,+5HH4%2B225,+Fri%C3%B0heimar,+806+Reykholt,+Island/Gullfoss+Waterfall+Lookout,+above,+Gullfoss+Parking,+Island/Geysir+Hot+Springs,+333,+806,+Island/Efstidalur+II,+Bl%C3%A1sk%C3%B3gabygg%C3%B0,+801+Laugarvatn,+Island/%C3%96xar%C3%A1rfoss,+7V8J%2B8RH,+806+Thingvellir,+Island/Reykjav%C3%ADk,+Island/@64.1688511,-21.6918568,121628m/data=!3m1!1e3!4m50!4m49!1m5!1m1!1s0x48d68b942e2bd0e5:0x5a7a846e86721d79!2m2!1d-20.9667166!2d64.0521039!1m5!1m1!1s0x48d68bb755f6f257:0x515a44e0c12ed907!2m2!1d-20.8851466!2d64.0412785!1m5!1m1!1s0x48d696fbe383f7bb:0xdee6f1f7177295af!2m2!1d-20.4448859!2d64.177503!1m5!1m1!1s0x48d6a5f34f4c88b1:0xd3558f2a84b426ba!2m2!1d-20.1244323!2d64.326181!1m5!1m1!1s0x48d6a3ec33d9dc1f:0xda8b28dafde977e5!2m2!1d-20.299508!2d64.3137795!1m5!1m1!1s0x48d699ea8baff6ab:0x27379b3ab3273542!2m2!1d-20.5516435!2d64.2424477!1m5!1m1!1s0x48d6811eadf0fd95:0x48dd72aa97e36e57!2m2!1d-21.117885!2d64.2658062!1m5!1m1!1s0x48d674b9eedcedc3:0xec912ca230d26071!2m2!1d-21.9407552!2d64.1469868!3e0?entry=ttu&g_ep=EgoyMDI2MDQwOC4wIKXMDSoASAFQAw%3D%3D | Q26: 0 | R26: 0 | S26: =+Q26*R26 -> 0 | T26: 0 | U26: =S26*(1-T26) -> 0 | V26: EUR | W26: =IFERROR(VLOOKUP(V26,Curr!$B$2:$C$13,2,FALSE),0) -> 10.8 | X26: =U26*W26 -> 0 | Y26: =Q26 -> 0 | Z26: =+Y26*R26 -> 0 | AA26: EUR | AB26: =IFERROR(VLOOKUP(AA26,Curr!$B$2:$C$13,2,FALSE),0) -> 10.8 | AC26: =+Y26*AB26*R26 -> 0 | AD26: =+AC26-X26 -> 0 | AE26: =IFERROR(AD26/AC26,0) -> 0
C27: Day 5 | D27: Hotel | E27: 01.07.2026 | F27: 03.07.2026 | J27: Reykjavik: Check in to your accommodation for a 2 night stay - Borg by Keahotels - 2 x Deluxe room - breakfast included | P27: https://app.hotelbeds.com/factsheet/stay/90467?check_in=01-07-2026&check_out=03-07-2026&occupancy=2~0_2~0&packaging=true | Q27: 2170 | R27: 1 | S27: =+Q27*R27 -> 2170 | T27: 0 | U27: =S27*(1-T27) -> 2170 | V27: EUR | W27: =IFERROR(VLOOKUP(V27,Curr!$B$2:$C$13,2,FALSE),0) -> 10.8 | X27: =U27*W27 -> 23436 | Y27: =Q27/0.85 -> 2552.9412 | Z27: =+Y27*R27 -> 2552.9412 | AA27: EUR | AB27: =IFERROR(VLOOKUP(AA27,Curr!$B$2:$C$13,2,FALSE),0) -> 10.8 | AC27: =+Y27*AB27*R27 -> 27571.765 | AD27: =+AC27-X27 -> 4135.7647 | AE27: =IFERROR(AD27/AC27,0) -> 0.15
C28: Day 5 | D28: Leisure | E28: 01.07.2026 | J28: Reykjavik: Spend time at leisure | Q28: 0 | R28: 0 | S28: =+Q28*R28 -> 0 | T28: 0 | U28: =S28*(1-T28) -> 0 | V28: EUR | W28: =IFERROR(VLOOKUP(V28,Curr!$B$2:$C$13,2,FALSE),0) -> 10.8 | X28: =U28*W28 -> 0 | Y28: =Q28 -> 0 | Z28: =+Y28*R28 -> 0 | AA28: EUR | AB28: =IFERROR(VLOOKUP(AA28,Curr!$B$2:$C$13,2,FALSE),0) -> 10.8 | AC28: =+Y28*AB28*R28 -> 0 | AD28: =+AC28-X28 -> 0 | AE28: =IFERROR(AD28/AC28,0) -> 0
C29: Day 5 | D29: Activity | E29: 01.07.2026 | J29: Reykjavík: Classic Whale Watching under the Midnight Sun - Time: 8:30 pm - 11:30 pm - Meeting point: Elding ticket office, Ægisgarður 5c -Includes: 2-3,5 hours whale watching tour, Access to our Wildlife Exhibition, Excellent live commentary in English, Use of warm overalls & mellow music | P29: https://booknordics.com/iceland/western-iceland/reykjavik/reykjavik-classic-whales-in-the-midnight-sun | Q29: 127 | R29: 4 | S29: =+Q29*R29 -> 508 | T29: 0.25 | U29: =S29*(1-T29) -> 381 | V29: EUR | W29: =IFERROR(VLOOKUP(V29,Curr!$B$2:$C$13,2,FALSE),0) -> 10.8 | X29: =U29*W29 -> 4114.8 | Y29: =Q29 -> 127 | Z29: =+Y29*R29 -> 508 | AA29: EUR | AB29: =IFERROR(VLOOKUP(AA29,Curr!$B$2:$C$13,2,FALSE),0) -> 10.8 | AC29: =+Y29*AB29*R29 -> 5486.4 | AD29: =+AC29-X29 -> 1371.6 | AE29: =IFERROR(AD29/AC29,0) -> 0.25
S30: =+Q30*R30 -> 0 | T30: 0 | U30: =S30*(1-T30) -> 0 | V30: EUR | W30: =IFERROR(VLOOKUP(V30,Curr!$B$2:$C$13,2,FALSE),0) -> 10.8 | X30: =U30*W30 -> 0 | Y30: =Q30 -> 0 | Z30: =+Y30*R30 -> 0 | AA30: EUR | AB30: =IFERROR(VLOOKUP(AA30,Curr!$B$2:$C$13,2,FALSE),0) -> 10.8 | AC30: =+Y30*AB30*R30 -> 0 | AD30: =+AC30-X30 -> 0 | AE30: =IFERROR(AD30/AC30,0) -> 0
C31: Day 6 | D31: Activity | E31: 02.07.2026 | J31: Reykjavik: FlyOver Iceland - Time: 12:30 pm - 1:30 pm - Meeting point: Fiskislóð 43 - Includes: Entry or admission fee, FlyOver Iceland Pursuit | P31: https://booknordics.com/iceland/western-iceland/reykjavik/flyover-iceland | Q31: 35 | R31: 4 | S31: =+Q31*R31 -> 140 | T31: 0.2 | U31: =S31*(1-T31) -> 112 | V31: EUR | W31: =IFERROR(VLOOKUP(V31,Curr!$B$2:$C$13,2,FALSE),0) -> 10.8 | X31: =U31*W31 -> 1209.6 | Y31: =Q31 -> 35 | Z31: =+Y31*R31 -> 140 | AA31: EUR | AB31: =IFERROR(VLOOKUP(AA31,Curr!$B$2:$C$13,2,FALSE),0) -> 10.8 | AC31: =+Y31*AB31*R31 -> 1512 | AD31: =+AC31-X31 -> 302.4 | AE31: =IFERROR(AD31/AC31,0) -> 0.2
C32: Day 6 | D32: Leisure | E32: 02.07.2026 | J32: Reykjavik: Spend time at leisure | Q32: 0 | R32: 0 | S32: =+Q32*R32 -> 0 | T32: 0 | U32: =S32*(1-T32) -> 0 | V32: EUR | W32: =IFERROR(VLOOKUP(V32,Curr!$B$2:$C$13,2,FALSE),0) -> 10.8 | X32: =U32*W32 -> 0 | Y32: =Q32 -> 0 | Z32: =+Y32*R32 -> 0 | AA32: EUR | AB32: =IFERROR(VLOOKUP(AA32,Curr!$B$2:$C$13,2,FALSE),0) -> 10.8 | AC32: =+Y32*AB32*R32 -> 0 | AD32: =+AC32-X32 -> 0 | AE32: =IFERROR(AD32/AC32,0) -> 0
C33: Day 6 | D33: Activity | E33: 02.07.2026 | J33: Reykjavik: Sky Lagoon Sér Pass with Transfer - Time: 5:00 pm - 7:30 pm - Meeting point: Hotel Pick up - Includes: Bus fare, Sky Lagoon Sér Admission, Complete Seven-step Ritual, Private Changing Facilities, Towel | P33: https://booknordics.com/iceland/western-iceland/reykjavik/sky-lagoon-sky-pass-with-transfer | Q33: 167 | R33: 4 | S33: =+Q33*R33 -> 668 | T33: 0.2 | U33: =S33*(1-T33) -> 534.4 | V33: EUR | W33: =IFERROR(VLOOKUP(V33,Curr!$B$2:$C$13,2,FALSE),0) -> 10.8 | X33: =U33*W33 -> 5771.52 | Y33: =Q33 -> 167 | Z33: =+Y33*R33 -> 668 | AA33: EUR | AB33: =IFERROR(VLOOKUP(AA33,Curr!$B$2:$C$13,2,FALSE),0) -> 10.8 | AC33: =+Y33*AB33*R33 -> 7214.4 | AD33: =+AC33-X33 -> 1442.88 | AE33: =IFERROR(AD33/AC33,0) -> 0.2
S34: =+Q34*R34 -> 0 | T34: 0 | U34: =S34*(1-T34) -> 0 | V34: EUR | W34: =IFERROR(VLOOKUP(V34,Curr!$B$2:$C$13,2,FALSE),0) -> 10.8 | X34: =U34*W34 -> 0 | Y34: =Q34 -> 0 | Z34: =+Y34*R34 -> 0 | AA34: EUR | AB34: =IFERROR(VLOOKUP(AA34,Curr!$B$2:$C$13,2,FALSE),0) -> 10.8 | AC34: =+Y34*AB34*R34 -> 0 | AD34: =+AC34-X34 -> 0 | AE34: =IFERROR(AD34/AC34,0) -> 0
C35: Day 7 | D35: Drive | E35: 03.07.2026 | J35: Reykjavik: Drive to Keflavik Airport | Q35: 0 | R35: 0 | S35: =+Q35*R35 -> 0 | T35: 0 | U35: =S35*(1-T35) -> 0 | V35: EUR | W35: =IFERROR(VLOOKUP(V35,Curr!$B$2:$C$13,2,FALSE),0) -> 10.8 | X35: =U35*W35 -> 0 | Y35: =Q35 -> 0 | Z35: =+Y35*R35 -> 0 | AA35: EUR | AB35: =IFERROR(VLOOKUP(AA35,Curr!$B$2:$C$13,2,FALSE),0) -> 10.8 | AC35: =+Y35*AB35*R35 -> 0 | AD35: =+AC35-X35 -> 0 | AE35: =IFERROR(AD35/AC35,0) -> 0
C36: Day 7 | D36: Car | E36: 03.07.2026 | J36: Keflavik: Deliver your rental car at the airport car rental office | Q36: 0 | R36: 0 | S36: =+Q36*R36 -> 0 | T36: 0 | U36: =S36*(1-T36) -> 0 | V36: EUR | W36: =IFERROR(VLOOKUP(V36,Curr!$B$2:$C$13,2,FALSE),0) -> 10.8 | X36: =U36*W36 -> 0 | Y36: =Q36 -> 0 | Z36: =+Y36*R36 -> 0 | AA36: EUR | AB36: =IFERROR(VLOOKUP(AA36,Curr!$B$2:$C$13,2,FALSE),0) -> 10.8 | AC36: =+Y36*AB36*R36 -> 0 | AD36: =+AC36-X36 -> 0 | AE36: =IFERROR(AD36/AC36,0) -> 0
C37: Day 7 | D37: Flight | E37: 03.07.2026 | J37: Keflavik: Flight to Oslo - Time: 09:10 am - 1:50 pm - Luggage included: 1 x 23 kg check in and 1 x 8 kg carry on per person | P37: https://www.sas.no/book/flights/?search=OW_KEF-OSL-20260703_a4c0i0y0&view=upsell&bookingFlow=revenue&out_flight_number=SK4788&skyscanner_redirectid=RhZvBkUmTrSXl9DScsN5CA&utm_source=skyscanner&utm_medium=metasearch&utm_campaign=skyscanner_metasearch&sortBy=rec&out_class=ECONOMY&out_sub_class=FLEX | Q37: 3747 | R37: 4 | S37: =+Q37*R37 -> 14988 | T37: 0 | U37: =S37*(1-T37) -> 14988 | V37: NOK | W37: =IFERROR(VLOOKUP(V37,Curr!$B$2:$C$13,2,FALSE),0) -> 1 | X37: =U37*W37 -> 14988 | Y37: =Q37/11/0.8 -> 425.79545 | Z37: =+Y37*R37 -> 1703.1818 | AA37: EUR | AB37: =IFERROR(VLOOKUP(AA37,Curr!$B$2:$C$13,2,FALSE),0) -> 10.8 | AC37: =+Y37*AB37*R37 -> 18394.364 | AD37: =+AC37-X37 -> 3406.3636 | AE37: =IFERROR(AD37/AC37,0) -> 0.18518519
C38: Day 7 | D38: Transfer | E38: 03.07.2026 | J38: Oslo: Private transfer to your accommodation | Q38: 1900 | R38: 1 | S38: =+Q38*R38 -> 1900 | T38: 0 | U38: =S38*(1-T38) -> 1900 | V38: NOK | W38: =IFERROR(VLOOKUP(V38,Curr!$B$2:$C$13,2,FALSE),0) -> 1 | X38: =U38*W38 -> 1900 | Y38: =Q38/11/0.8 -> 215.90909 | Z38: =+Y38*R38 -> 215.90909 | AA38: EUR | AB38: =IFERROR(VLOOKUP(AA38,Curr!$B$2:$C$13,2,FALSE),0) -> 10.8 | AC38: =+Y38*AB38*R38 -> 2331.8182 | AD38: =+AC38-X38 -> 431.81818 | AE38: =IFERROR(AD38/AC38,0) -> 0.18518519
C39: Day 7 | D39: Hotel | E39: 03.07.2026 | F39: 05.07.2026 | J39: Oslo: Check in to your accommodation for a 2 night stay - Grand Hotel Oslo by Scandic - 2 x Superior king - Breakfast included | P39: https://app.hotelbeds.com/factsheet/stay/616601?check_in=03-07-2026&check_out=05-07-2026&occupancy=2~0_2~0&packaging=true | Q39: 2014 | R39: 1 | S39: =+Q39*R39 -> 2014 | T39: 0 | U39: =S39*(1-T39) -> 2014 | V39: EUR | W39: =IFERROR(VLOOKUP(V39,Curr!$B$2:$C$13,2,FALSE),0) -> 10.8 | X39: =U39*W39 -> 21751.2 | Y39: =Q39/0.85 -> 2369.4118 | Z39: =+Y39*R39 -> 2369.4118 | AA39: EUR | AB39: =IFERROR(VLOOKUP(AA39,Curr!$B$2:$C$13,2,FALSE),0) -> 10.8 | AC39: =+Y39*AB39*R39 -> 25589.647 | AD39: =+AC39-X39 -> 3838.4471 | AE39: =IFERROR(AD39/AC39,0) -> 0.15
C40: Day 7 | D40: Leisure | E40: 03.07.2026 | J40: Oslo: Spend time at leisure | Q40: 0 | R40: 0 | S40: =+Q40*R40 -> 0 | T40: 0 | U40: =S40*(1-T40) -> 0 | V40: EUR | W40: =IFERROR(VLOOKUP(V40,Curr!$B$2:$C$13,2,FALSE),0) -> 10.8 | X40: =U40*W40 -> 0 | Y40: =Q40 -> 0 | Z40: =+Y40*R40 -> 0 | AA40: EUR | AB40: =IFERROR(VLOOKUP(AA40,Curr!$B$2:$C$13,2,FALSE),0) -> 10.8 | AC40: =+Y40*AB40*R40 -> 0 | AD40: =+AC40-X40 -> 0 | AE40: =IFERROR(AD40/AC40,0) -> 0
