Workbook

Sheet Curr
C1: NOK
B2: EUR | C2: 11.3
B3: SEK | C3: 1.02
B4: DKK | C4: 1.5
B5: ISK | C5: 0.075
B6: NOK | C6: 1
B7: USD | C7: 10.6

Sheet Kalk
B2: Dates: 9 - 13 june
B3: Pax: 3 (2 adults, 1 adult kid)
B4: Rooming: 1 x doulbe 1 x single
B6: ID | C6: Day | D6: Type | E6: From date | F6: To date | G6: From time | H6: To time | I6: Supplier | J6: Travel element | K6: Manual booking? | L6: Status | M6: Comments | N6: Non-refundable | O6: Refundable | P6: URL | Q6: Gross P per unit | R6: Units | S6: Gross P | T6: Supp Comm | U6: Net P | V6: Supp curr | W6: X-rate | X6: Net P NOK | Y6: Sales P per unit | Z6: Price | AA6: Sales curr | AB6: X-rate | AC6: Sales P NOK tot | AD6: GP NOK | AE6: GP % | AF6: VAT25 | AG6: VAT15 | AH6: VAT12 | AI6: VAT0-D | AJ6: VAT0-I
C7: Day 1 | D7: Arrival | E7: 09.06.2026 | J7: Oslo: Welcome to Norway | Q7: 0 | R7: 0 | S7: =+Q7*R7 -> 0 | T7: 0 | U7: =S7*(1-T7) -> 0 | V7: EUR | W7: =IFERROR(VLOOKUP(V7,Curr!$B$2:$C$13,2,FALSE),0) -> 11.3 | X7: =U7*W7 -> 0 | Y7: =Q7 -> 0 | Z7: =+Y7*R7 -> 0 | AA7: EUR | AB7: =IFERROR(VLOOKUP(AA7,Curr!$B$2:$C$13,2,FALSE),0) -> 11.3 | AC7: =+Y7*AB7*R7 -> 0 | AD7: =+AC7-X7 -> 0 | AE7: =IFERROR(AD7/AC7,0) -> 0
C8: Day 1 | D8: Car | E8: 09.06.2026 | J8: Oslo: Pick up your rental car at the aiport car rental office - Suzuki S-Cross AWD (automatic) or similar - Includes: Airport service charge, Collision damage waiver, Fuel information, Unlimited mileage, Vehicle licence fee / road fund licence, Theft protection, Vat, Other taxes and service charges, Supplementary liability insurance, Cancellation fee | P8: https://app.hotelbeds.com/carhire/search?specialEquipment=AUTOMATIC&door=4&baggage=3,4&results=20&sortBy=LOWEST_PRICE_FIRST&field=PRICE&direction=ASCENDING&page=1&destinationTab=Oslo%20Airport%20(OSL)&officePickupControl=1758&pickupDate=09-06-2026&pickupTime=08:00&officeDropoffControl=1758&dropoffDate=13-06-2026&dropoffTime=08:00&sameOfficeCheckbox=true&typeDepartureCode=airport&typeArrivalCode=airport&_timestamp=1780149002935&departureTab= | Q8: 390 | R8: 1 | S8: =+Q8*R8 -> 390 | T8: 0 | U8: =S8*(1-T8) -> 390 | V8: EUR | W8: =IFERROR(VLOOKUP(V8,Curr!$B$2:$C$13,2,FALSE),0) -> 11.3 | X8: =U8*W8 -> 4407 | Y8: =Q8/0.75 -> 520 | Z8: =+Y8*R8 -> 520 | AA8: EUR | AB8: =IFERROR(VLOOKUP(AA8,Curr!$B$2:$C$13,2,FALSE),0) -> 11.3 | AC8: =+Y8*AB8*R8 -> 5876 | AD8: =+AC8-X8 -> 1469 | AE8: =IFERROR(AD8/AC8,0) -> 0.25
C9: Day 1 | D9: Drive | E9: 09.06.2026 | J9: Oslo: Drive to Voss - Time: 08:30 am - 2:30 pm (without stops) | Q9: 0 | R9: 0 | S9: =+Q9*R9 -> 0 | T9: 0 | U9: =S9*(1-T9) -> 0 | V9: EUR | W9: =IFERROR(VLOOKUP(V9,Curr!$B$2:$C$13,2,FALSE),0) -> 11.3 | X9: =U9*W9 -> 0 | Y9: =Q9 -> 0 | Z9: =+Y9*R9 -> 0 | AA9: EUR | AB9: =IFERROR(VLOOKUP(AA9,Curr!$B$2:$C$13,2,FALSE),0) -> 11.3 | AC9: =+Y9*AB9*R9 -> 0 | AD9: =+AC9-X9 -> 0 | AE9: =IFERROR(AD9/AC9,0) -> 0
C10: Day 1 | D10: Hotel | E10: 09.06.2026 | F10: 10.06.2026 | J10: Voss: Check in to your accommodation for a 1 night stay - Scandic Voss - 2 x Standard Room - Breakfast included | P10: https://app.hotelbeds.com/factsheet/stay/712885?check_in=09-06-2026&check_out=10-06-2026&occupancy=2~0_1~0&packaging=true | Q10: 461 | R10: 1 | S10: =+Q10*R10 -> 461 | T10: 0 | U10: =S10*(1-T10) -> 461 | V10: EUR | W10: =IFERROR(VLOOKUP(V10,Curr!$B$2:$C$13,2,FALSE),0) -> 11.3 | X10: =U10*W10 -> 5209.3 | Y10: =Q10/0.75 -> 614.66667 | Z10: =+Y10*R10 -> 614.66667 | AA10: EUR | AB10: =IFERROR(VLOOKUP(AA10,Curr!$B$2:$C$13,2,FALSE),0) -> 11.3 | AC10: =+Y10*AB10*R10 -> 6945.7333 | AD10: =+AC10-X10 -> 1736.4333 | AE10: =IFERROR(AD10/AC10,0) -> 0.25
C11: Day 1 | D11: Activity | E11: 09.06.2026 | J11: Voss: 1h E-Mountain Bike Full Suspension Rental - Time: 5:00 pm - 7:00 pm - Meeting point: Outdoor Norway office, Evangervegen 32, Voss - Includes: Top-quality equipment and helmet, High quality full-suspensions mountain bike - Description: Embark on a journey of awe-inspiring landscapes with the unparalleled E-MTB full-suspension bike, perfectly designed to elevate your adventure in the breathtaking beauty of Voss! | P11: https://booknordics.com/norway/western-fjord-norway/bergen-and-hardanger/rentals-e-mountain-bike-full-suspension | Q11: 78 | R11: 3 | S11: =+Q11*R11 -> 234 | T11: 0.2 | U11: =S11*(1-T11) -> 187.2 | V11: EUR | W11: =IFERROR(VLOOKUP(V11,Curr!$B$2:$C$13,2,FALSE),0) -> 11.3 | X11: =U11*W11 -> 2115.36 | Y11: =Q11 -> 78 | Z11: =+Y11*R11 -> 234 | AA11: EUR | AB11: =IFERROR(VLOOKUP(AA11,Curr!$B$2:$C$13,2,FALSE),0) -> 11.3 | AC11: =+Y11*AB11*R11 -> 2644.2 | AD11: =+AC11-X11 -> 528.84 | AE11: =IFERROR(AD11/AC11,0) -> 0.2
C12: Day 1 | D12: Leisure | E12: 09.06.2026 | J12: Voss: Spend time at leisure | Q12: 0 | R12: 0 | S12: =+Q12*R12 -> 0 | T12: 0 | U12: =S12*(1-T12) -> 0 | V12: EUR | W12: =IFERROR(VLOOKUP(V12,Curr!$B$2:$C$13,2,FALSE),0) -> 11.3 | X12: =U12*W12 -> 0 | Y12: =Q12 -> 0 | Z12: =+Y12*R12 -> 0 | AA12: EUR | AB12: =IFERROR(VLOOKUP(AA12,Curr!$B$2:$C$13,2,FALSE),0) -> 11.3 | AC12: =+Y12*AB12*R12 -> 0 | AD12: =+AC12-X12 -> 0 | AE12: =IFERROR(AD12/AC12,0) -> 0
S13: =+Q13*R13 -> 0 | T13: 0 | U13: =S13*(1-T13) -> 0 | V13: EUR | W13: =IFERROR(VLOOKUP(V13,Curr!$B$2:$C$13,2,FALSE),0) -> 11.3 | X13: =U13*W13 -> 0 | Y13: =Q13 -> 0 | Z13: =+Y13*R13 -> 0 | AA13: EUR | AB13: =IFERROR(VLOOKUP(AA13,Curr!$B$2:$C$13,2,FALSE),0) -> 11.3 | AC13: =+Y13*AB13*R13 -> 0 | AD13: =+AC13-X13 -> 0 | AE13: =IFERROR(AD13/AC13,0) -> 0
C14: Day 2 | D14: Activity | E14: 10.06.2026 | J14: Voss: Guided Sea Kayaking on the Nærøyfjord - Time: 08:30 am - 2:30 pm - Meeting point: Outdoor Norway, Evangervegen 32 - Includes: Professional sea kayaking guide, Transfers to and from the fjord, Sea kayak, paddle, PFD (life-jacket), Sprayskirt and splash jacket - Description: Explore the heart of the UNESCO World Heritage Park – Nærøyfjord in Norway. We take you to places only accessible by kayak. We explore historic areas of the Nærøyfjord, which for centuries, have been playing an important role in linking western and central Norway together. | P14: https://booknordics.com/norway/western-fjord-norway/bergen-and-hardanger/sea-kayaking-naeroyfjord-tour | Q14: 148 | R14: 3 | S14: =+Q14*R14 -> 444 | T14: 0.2 | U14: =S14*(1-T14) -> 355.2 | V14: EUR | W14: =IFERROR(VLOOKUP(V14,Curr!$B$2:$C$13,2,FALSE),0) -> 11.3 | X14: =U14*W14 -> 4013.76 | Y14: =Q14 -> 148 | Z14: =+Y14*R14 -> 444 | AA14: EUR | AB14: =IFERROR(VLOOKUP(AA14,Curr!$B$2:$C$13,2,FALSE),0) -> 11.3 | AC14: =+Y14*AB14*R14 -> 5017.2 | AD14: =+AC14-X14 -> 1003.44 | AE14: =IFERROR(AD14/AC14,0) -> 0.2
C15: Day 2 | D15: Drive | E15: 10.06.2026 | J15: Voss: Drive to Bergen - 3:00 pm - 5:30 pm (without stops) | Q15: 0 | R15: 0 | S15: =+Q15*R15 -> 0 | T15: 0 | U15: =S15*(1-T15) -> 0 | V15: EUR | W15: =IFERROR(VLOOKUP(V15,Curr!$B$2:$C$13,2,FALSE),0) -> 11.3 | X15: =U15*W15 -> 0 | Y15: =Q15 -> 0 | Z15: =+Y15*R15 -> 0 | AA15: EUR | AB15: =IFERROR(VLOOKUP(AA15,Curr!$B$2:$C$13,2,FALSE),0) -> 11.3 | AC15: =+Y15*AB15*R15 -> 0 | AD15: =+AC15-X15 -> 0 | AE15: =IFERROR(AD15/AC15,0) -> 0
C16: Day 2 | D16: Hotel | E16: 10.06.2026 | F16: 11.06.2026 | J16: Bergen: Check in to your accommodation for a 1 night stay - Radisson Blu Royal Bergen - 2 x Standard Room - Breakfast included | P16: https://app.hotelbeds.com/factsheet/stay/197867?check_in=10-06-2026&check_out=11-06-2026&occupancy=2~0_1~0&packaging=true | Q16: 847 | R16: 1 | S16: =+Q16*R16 -> 847 | T16: 0 | U16: =S16*(1-T16) -> 847 | V16: EUR | W16: =IFERROR(VLOOKUP(V16,Curr!$B$2:$C$13,2,FALSE),0) -> 11.3 | X16: =U16*W16 -> 9571.1 | Y16: =Q16/0.75 -> 1129.3333 | Z16: =+Y16*R16 -> 1129.3333 | AA16: EUR | AB16: =IFERROR(VLOOKUP(AA16,Curr!$B$2:$C$13,2,FALSE),0) -> 11.3 | AC16: =+Y16*AB16*R16 -> 12761.467 | AD16: =+AC16-X16 -> 3190.3667 | AE16: =IFERROR(AD16/AC16,0) -> 0.25
C17: Day 2 | D17: Leisure | E17: 10.06.2026 | J17: Bergen: Spend time at leisure | Q17: 0 | R17: 0 | S17: =+Q17*R17 -> 0 | T17: 0 | U17: =S17*(1-T17) -> 0 | V17: EUR | W17: =IFERROR(VLOOKUP(V17,Curr!$B$2:$C$13,2,FALSE),0) -> 11.3 | X17: =U17*W17 -> 0 | Y17: =Q17 -> 0 | Z17: =+Y17*R17 -> 0 | AA17: EUR | AB17: =IFERROR(VLOOKUP(AA17,Curr!$B$2:$C$13,2,FALSE),0) -> 11.3 | AC17: =+Y17*AB17*R17 -> 0 | AD17: =+AC17-X17 -> 0 | AE17: =IFERROR(AD17/AC17,0) -> 0
S18: =+Q18*R18 -> 0 | T18: 0 | U18: =S18*(1-T18) -> 0 | V18: EUR | W18: =IFERROR(VLOOKUP(V18,Curr!$B$2:$C$13,2,FALSE),0) -> 11.3 | X18: =U18*W18 -> 0 | Y18: =Q18 -> 0 | Z18: =+Y18*R18 -> 0 | AA18: EUR | AB18: =IFERROR(VLOOKUP(AA18,Curr!$B$2:$C$13,2,FALSE),0) -> 11.3 | AC18: =+Y18*AB18*R18 -> 0 | AD18: =+AC18-X18 -> 0 | AE18: =IFERROR(AD18/AC18,0) -> 0
C19: Day 3 | D19: Activity | E19: 11.06.2026 | J19: Bergen: Mostraumen Majestic Fjord & Waterfall Cruise - Time: 10:30 am - 2:30 pm - Meeting point: Börshopen Pier, Strandkaien 13 - Includes: Round-trip cruise Bergen - Mostraumen - Bergen - Description: Fjord Cruise from Bergen to Mostraumen strait and the Osterfjord. This round-trip cruise is available all year. | P19: https://booknordics.com/norway/western-fjord-norway/bergen-and-hardanger/mostraumen-fjord-waterfall-cruise | Q19: 78 | R19: 3 | S19: =+Q19*R19 -> 234 | T19: 0.2 | U19: =S19*(1-T19) -> 187.2 | V19: EUR | W19: =IFERROR(VLOOKUP(V19,Curr!$B$2:$C$13,2,FALSE),0) -> 11.3 | X19: =U19*W19 -> 2115.36 | Y19: =Q19 -> 78 | Z19: =+Y19*R19 -> 234 | AA19: EUR | AB19: =IFERROR(VLOOKUP(AA19,Curr!$B$2:$C$13,2,FALSE),0) -> 11.3 | AC19: =+Y19*AB19*R19 -> 2644.2 | AD19: =+AC19-X19 -> 528.84 | AE19: =IFERROR(AD19/AC19,0) -> 0.2
C20: Day 3 | D20: Drive | E20: 11.06.2026 | J20: Bergen: Drive to Stavanger - 3:00 pm - 7:30 pm (without stops) | Q20: 0 | R20: 0 | S20: =+Q20*R20 -> 0 | T20: 0 | U20: =S20*(1-T20) -> 0 | V20: EUR | W20: =IFERROR(VLOOKUP(V20,Curr!$B$2:$C$13,2,FALSE),0) -> 11.3 | X20: =U20*W20 -> 0 | Y20: =Q20 -> 0 | Z20: =+Y20*R20 -> 0 | AA20: EUR | AB20: =IFERROR(VLOOKUP(AA20,Curr!$B$2:$C$13,2,FALSE),0) -> 11.3 | AC20: =+Y20*AB20*R20 -> 0 | AD20: =+AC20-X20 -> 0 | AE20: =IFERROR(AD20/AC20,0) -> 0
C21: Day 3 | D21: Hotel | E21: 11.06.2026 | F21: 12.06.2026 | J21: Stavanger: Check in to your accommodation for a 1 night stay - Radisson Blu Atlantic Stavanger - 1 x Standard room, 1 x single room - Breakfast included | P21: https://app.hotelbeds.com/factsheet/stay/7407?check_in=11-06-2026&check_out=12-06-2026&occupancy=2~0_1~0&packaging=true | Q21: =245+186 -> 431 | R21: 1 | S21: =+Q21*R21 -> 431 | T21: 0 | U21: =S21*(1-T21) -> 431 | V21: EUR | W21: =IFERROR(VLOOKUP(V21,Curr!$B$2:$C$13,2,FALSE),0) -> 11.3 | X21: =U21*W21 -> 4870.3 | Y21: =Q21/0.75 -> 574.66667 | Z21: =+Y21*R21 -> 574.66667 | AA21: EUR | AB21: =IFERROR(VLOOKUP(AA21,Curr!$B$2:$C$13,2,FALSE),0) -> 11.3 | AC21: =+Y21*AB21*R21 -> 6493.7333 | AD21: =+AC21-X21 -> 1623.4333 | AE21: =IFERROR(AD21/AC21,0) -> 0.25
C22: Day 3 | D22: Leisure | E22: 11.06.2026 | J22: Stavanger: Spend time at leisure | Q22: 0 | R22: 0 | S22: =+Q22*R22 -> 0 | T22: 0 | U22: =S22*(1-T22) -> 0 | V22: EUR | W22: =IFERROR(VLOOKUP(V22,Curr!$B$2:$C$13,2,FALSE),0) -> 11.3 | X22: =U22*W22 -> 0 | Y22: =Q22 -> 0 | Z22: =+Y22*R22 -> 0 | AA22: EUR | AB22: =IFERROR(VLOOKUP(AA22,Curr!$B$2:$C$13,2,FALSE),0) -> 11.3 | AC22: =+Y22*AB22*R22 -> 0 | AD22: =+AC22-X22 -> 0 | AE22: =IFERROR(AD22/AC22,0) -> 0
S23: =+Q23*R23 -> 0 | T23: 0 | U23: =S23*(1-T23) -> 0 | V23: EUR | W23: =IFERROR(VLOOKUP(V23,Curr!$B$2:$C$13,2,FALSE),0) -> 11.3 | X23: =U23*W23 -> 0 | Y23: =Q23 -> 0 | Z23: =+Y23*R23 -> 0 | AA23: EUR | AB23: =IFERROR(VLOOKUP(AA23,Curr!$B$2:$C$13,2,FALSE),0) -> 11.3 | AC23: =+Y23*AB23*R23 -> 0 | AD23: =+AC23-X23 -> 0 | AE23: =IFERROR(AD23/AC23,0) -> 0
C24: Day 4 | D24: Activity | E24: 12.06.2026 | J24: Stavanger: Lysefjord & Preikestolen Fjord Cruise - Time: 10:00 am - 2:00 pm - Meeting point: Strandkaien, Stavanger - Includes: Sustainable, quiet & scenic fjord cruise, Boat tour aboard & luxurious catamaran, Spacious cabin with comfortable leather seats, Panoramic windows & large viewing decks, Audio guiding & free Wi-Fi on board, Licensed café serving snacks & drinks - Description: Discover magical Lysefjord - one of the most breathtaking fjords in Norway! Gaze up at spectacular Preikestolen (Pulpit Rock), majestic waterfalls and amazing mountains on our half-day fjord cruise! | Q24: 82 | R24: 3 | S24: =+Q24*R24 -> 246 | T24: 0.2 | U24: =S24*(1-T24) -> 196.8 | V24: EUR | W24: =IFERROR(VLOOKUP(V24,Curr!$B$2:$C$13,2,FALSE),0) -> 11.3 | X24: =U24*W24 -> 2223.84 | Y24: =Q24 -> 82 | Z24: =+Y24*R24 -> 246 | AA24: EUR | AB24: =IFERROR(VLOOKUP(AA24,Curr!$B$2:$C$13,2,FALSE),0) -> 11.3 | AC24: =+Y24*AB24*R24 -> 2779.8 | AD24: =+AC24-X24 -> 555.96 | AE24: =IFERROR(AD24/AC24,0) -> 0.2
C25: Day 4 | D25: Drive | E25: 12.06.2026 | J25: Stavanger: Drive to Oslo - 3:00 pm - 9:00 pm (without stops) | Q25: 0 | R25: 0 | S25: =+Q25*R25 -> 0 | T25: 0 | U25: =S25*(1-T25) -> 0 | V25: EUR | W25: =IFERROR(VLOOKUP(V25,Curr!$B$2:$C$13,2,FALSE),0) -> 11.3 | X25: =U25*W25 -> 0 | Y25: =Q25 -> 0 | Z25: =+Y25*R25 -> 0 | AA25: EUR | AB25: =IFERROR(VLOOKUP(AA25,Curr!$B$2:$C$13,2,FALSE),0) -> 11.3 | AC25: =+Y25*AB25*R25 -> 0 | AD25: =+AC25-X25 -> 0 | AE25: =IFERROR(AD25/AC25,0) -> 0
C26: Day 4 | D26: Hotel | E26: 12.06.2026 | F26: 13.06.2026 | J26: Oslo: Check in to your accommodation for a 1 night stay - Clarion Hotel The Hub - 2 x standard double - Breakfast included | P26: https://app.hotelbeds.com/factsheet/stay/7398?check_in=12-06-2026&check_out=13-06-2026&occupancy=2~0_1~0&packaging=true | Q26: =275*2 -> 550 | R26: 1 | S26: =+Q26*R26 -> 550 | T26: 0 | U26: =S26*(1-T26) -> 550 | V26: EUR | W26: =IFERROR(VLOOKUP(V26,Curr!$B$2:$C$13,2,FALSE),0) -> 11.3 | X26: =U26*W26 -> 6215 | Y26: =Q26/0.75 -> 733.33333 | Z26: =+Y26*R26 -> 733.33333 | AA26: EUR | AB26: =IFERROR(VLOOKUP(AA26,Curr!$B$2:$C$13,2,FALSE),0) -> 11.3 | AC26: =+Y26*AB26*R26 -> 8286.6667 | AD26: =+AC26-X26 -> 2071.6667 | AE26: =IFERROR(AD26/AC26,0) -> 0.25
C27: Day 4 | D27: Leisure | E27: 12.06.2026 | J27: Oslo: Spend time at leisure | Q27: 0 | R27: 0 | S27: =+Q27*R27 -> 0 | T27: 0 | U27: =S27*(1-T27) -> 0 | V27: EUR | W27: =IFERROR(VLOOKUP(V27,Curr!$B$2:$C$13,2,FALSE),0) -> 11.3 | X27: =U27*W27 -> 0 | Y27: =Q27 -> 0 | Z27: =+Y27*R27 -> 0 | AA27: EUR | AB27: =IFERROR(VLOOKUP(AA27,Curr!$B$2:$C$13,2,FALSE),0) -> 11.3 | AC27: =+Y27*AB27*R27 -> 0 | AD27: =+AC27-X27 -> 0 | AE27: =IFERROR(AD27/AC27,0) -> 0
S28: =+Q28*R28 -> 0 | T28: 0 | U28: =S28*(1-T28) -> 0 | V28: EUR | W28: =IFERROR(VLOOKUP(V28,Curr!$B$2:$C$13,2,FALSE),0) -> 11.3 | X28: =U28*W28 -> 0 | Y28: =Q28 -> 0 | Z28: =+Y28*R28 -> 0 | AA28: EUR | AB28: =IFERROR(VLOOKUP(AA28,Curr!$B$2:$C$13,2,FALSE),0) -> 11.3 | AC28: =+Y28*AB28*R28 -> 0 | AD28: =+AC28-X28 -> 0 | AE28: =IFERROR(AD28/AC28,0) -> 0
C29: Day 5 | D29: Drive | E29: 13.06.2026 | J29: Oslo: Drive to Oslo Airport - 40 minutes | Q29: 0 | R29: 0 | S29: =+Q29*R29 -> 0 | T29: 0 | U29: =S29*(1-T29) -> 0 | V29: EUR | W29: =IFERROR(VLOOKUP(V29,Curr!$B$2:$C$13,2,FALSE),0) -> 11.3 | X29: =U29*W29 -> 0 | Y29: =Q29 -> 0 | Z29: =+Y29*R29 -> 0 | AA29: EUR | AB29: =IFERROR(VLOOKUP(AA29,Curr!$B$2:$C$13,2,FALSE),0) -> 11.3 | AC29: =+Y29*AB29*R29 -> 0 | AD29: =+AC29-X29 -> 0 | AE29: =IFERROR(AD29/AC29,0) -> 0
C30: Day 5 | D30: Hotel | E30: 13.06.2026 | J30: Oslo: Deliver your rental car at the airport car rental office | Q30: 0 | R30: 0 | S30: =+Q30*R30 -> 0 | T30: 0 | U30: =S30*(1-T30) -> 0 | V30: EUR | W30: =IFERROR(VLOOKUP(V30,Curr!$B$2:$C$13,2,FALSE),0) -> 11.3 | X30: =U30*W30 -> 0 | Y30: =Q30 -> 0 | Z30: =+Y30*R30 -> 0 | AA30: EUR | AB30: =IFERROR(VLOOKUP(AA30,Curr!$B$2:$C$13,2,FALSE),0) -> 11.3 | AC30: =+Y30*AB30*R30 -> 0 | AD30: =+AC30-X30 -> 0 | AE30: =IFERROR(AD30/AC30,0) -> 0
C31: Day 5 | D31: Departure | E31: 13.06.2026 | J31: Oslo: Departure onwards | Q31: 0 | R31: 0 | S31: =+Q31*R31 -> 0 | T31: 0 | U31: =S31*(1-T31) -> 0 | V31: EUR | W31: =IFERROR(VLOOKUP(V31,Curr!$B$2:$C$13,2,FALSE),0) -> 11.3 | X31: =U31*W31 -> 0 | Y31: =Q31 -> 0 | Z31: =+Y31*R31 -> 0 | AA31: EUR | AB31: =IFERROR(VLOOKUP(AA31,Curr!$B$2:$C$13,2,FALSE),0) -> 11.3 | AC31: =+Y31*AB31*R31 -> 0 | AD31: =+AC31-X31 -> 0 | AE31: =IFERROR(AD31/AC31,0) -> 0
S32: =+Q32*R32 -> 0 | T32: 0 | U32: =S32*(1-T32) -> 0 | V32: EUR | W32: =IFERROR(VLOOKUP(V32,Curr!$B$2:$C$13,2,FALSE),0) -> 11.3 | X32: =U32*W32 -> 0 | Y32: =Q32 -> 0 | Z32: =+Y32*R32 -> 0 | AA32: EUR | AB32: =IFERROR(VLOOKUP(AA32,Curr!$B$2:$C$13,2,FALSE),0) -> 11.3 | AC32: =+Y32*AB32*R32 -> 0 | AD32: =+AC32-X32 -> 0 | AE32: =IFERROR(AD32/AC32,0) -> 0
S33: =+Q33*R33 -> 0 | T33: 0 | U33: =S33*(1-T33) -> 0 | V33: EUR | W33: =IFERROR(VLOOKUP(V33,Curr!$B$2:$C$13,2,FALSE),0) -> 11.3 | X33: =U33*W33 -> 0 | Y33: =Q33 -> 0 | Z33: =+Y33*R33 -> 0 | AA33: EUR | AB33: =IFERROR(VLOOKUP(AA33,Curr!$B$2:$C$13,2,FALSE),0) -> 11.3 | AC33: =+Y33*AB33*R33 -> 0 | AD33: =+AC33-X33 -> 0 | AE33: =IFERROR(AD33/AC33,0) -> 0
S34: =+Q34*R34 -> 0 | T34: 0 | U34: =S34*(1-T34) -> 0 | V34: EUR | W34: =IFERROR(VLOOKUP(V34,Curr!$B$2:$C$13,2,FALSE),0) -> 11.3 | X34: =U34*W34 -> 0 | Y34: =Q34 -> 0 | Z34: =+Y34*R34 -> 0 | AA34: EUR | AB34: =IFERROR(VLOOKUP(AA34,Curr!$B$2:$C$13,2,FALSE),0) -> 11.3 | AC34: =+Y34*AB34*R34 -> 0 | AD34: =+AC34-X34 -> 0 | AE34: =IFERROR(AD34/AC34,0) -> 0
S35: =+Q35*R35 -> 0 | T35: 0 | U35: =S35*(1-T35) -> 0 | V35: EUR | W35: =IFERROR(VLOOKUP(V35,Curr!$B$2:$C$13,2,FALSE),0) -> 11.3 | X35: =U35*W35 -> 0 | Y35: =Q35 -> 0 | Z35: =+Y35*R35 -> 0 | AA35: EUR | AB35: =IFERROR(VLOOKUP(AA35,Curr!$B$2:$C$13,2,FALSE),0) -> 11.3 | AC35: =+Y35*AB35*R35 -> 0 | AD35: =+AC35-X35 -> 0 | AE35: =IFERROR(AD35/AC35,0) -> 0
S36: =+Q36*R36 -> 0 | T36: 0 | U36: =S36*(1-T36) -> 0 | V36: EUR | W36: =IFERROR(VLOOKUP(V36,Curr!$B$2:$C$13,2,FALSE),0) -> 11.3 | X36: =U36*W36 -> 0 | Y36: =Q36 -> 0 | Z36: =+Y36*R36 -> 0 | AA36: EUR | AB36: =IFERROR(VLOOKUP(AA36,Curr!$B$2:$C$13,2,FALSE),0) -> 11.3 | AC36: =+Y36*AB36*R36 -> 0 | AD36: =+AC36-X36 -> 0 | AE36: =IFERROR(AD36/AC36,0) -> 0
S37: =+Q37*R37 -> 0 | T37: 0 | U37: =S37*(1-T37) -> 0 | V37: EUR | W37: =IFERROR(VLOOKUP(V37,Curr!$B$2:$C$13,2,FALSE),0) -> 11.3 | X37: =U37*W37 -> 0 | Y37: =Q37 -> 0 | Z37: =+Y37*R37 -> 0 | AA37: EUR | AB37: =IFERROR(VLOOKUP(AA37,Curr!$B$2:$C$13,2,FALSE),0) -> 11.3 | AC37: =+Y37*AB37*R37 -> 0 | AD37: =+AC37-X37 -> 0 | AE37: =IFERROR(AD37/AC37,0) -> 0
S38: =+Q38*R38 -> 0 | T38: 0 | U38: =S38*(1-T38) -> 0 | V38: EUR | W38: =IFERROR(VLOOKUP(V38,Curr!$B$2:$C$13,2,FALSE),0) -> 11.3 | X38: =U38*W38 -> 0 | Y38: =Q38 -> 0 | Z38: =+Y38*R38 -> 0 | AA38: EUR | AB38: =IFERROR(VLOOKUP(AA38,Curr!$B$2:$C$13,2,FALSE),0) -> 11.3 | AC38: =+Y38*AB38*R38 -> 0 | AD38: =+AC38-X38 -> 0 | AE38: =IFERROR(AD38/AC38,0) -> 0
B40: Totals | D40: x | E40: x | F40: x | G40: x | H40: x | I40: x | J40: x | K40: x | L40: x | M40: x | N40: x | O40: x | P40: x | Q40: x | R40: x | S40: x | T40: x | U40: x | V40: x | W40: x | X40: x | Y40: x | Z40: =SUM(Z7:Z38) -> 4730 | AC40: =SUM(AC7:AC38) -> 53449 | AD40: =SUM(AD7:AD38) -> 12707.98 | AE40: =IFERROR(AD40/AC40,0) -> 0.23775899 | AF40: =SUM(AF8:AF39) -> 0 | AG40: =SUM(AG8:AG39) -> 0 | AH40: =SUM(AH8:AH39) -> 0 | AI40: =SUM(AI8:AI39) -> 0 | AJ40: =SUM(AJ8:AJ39) -> 0
Y42: Quote | Z42: 4730 | AA42: =1860*3 -> 5580
Y43: PP | Z43: =Z42/3 -> 1576.6667 | AA43: =AA42/3 -> 1860

Sheet Kalk 2
B2: Dates: 9 - 13 june
B3: Pax: 3 (2 adults, 1 adult kid)
B4: Rooming: 1 x doulbe 1 x single
B6: ID | C6: Day | D6: Type | E6: From date | F6: To date | G6: From time | H6: To time | I6: Supplier | J6: Travel element | K6: Manual booking? | L6: Status | M6: Comments | N6: Non-refundable | O6: Refundable | P6: URL | Q6: Gross P per unit | R6: Units | S6: Gross P | T6: Supp Comm | U6: Net P | V6: Supp curr | W6: X-rate | X6: Net P NOK | Y6: Sales P per unit | Z6: Price | AA6: Sales curr | AB6: X-rate | AC6: Sales P NOK tot | AD6: GP NOK | AE6: GP % | AF6: VAT25 | AG6: VAT15 | AH6: VAT12 | AI6: VAT0-D | AJ6: VAT0-I
C7: Day 1 | D7: Arrival | E7: 09.06.2026 | J7: Oslo: Welcome to Norway | Q7: 0 | R7: 0 | S7: =+Q7*R7 -> 0 | T7: 0 | U7: =S7*(1-T7) -> 0 | V7: EUR | W7: =IFERROR(VLOOKUP(V7,Curr!$B$2:$C$13,2,FALSE),0) -> 11.3 | X7: =U7*W7 -> 0 | Y7: =Q7 -> 0 | Z7: =+Y7*R7 -> 0 | AA7: EUR | AB7: =IFERROR(VLOOKUP(AA7,Curr!$B$2:$C$13,2,FALSE),0) -> 11.3 | AC7: =+Y7*AB7*R7 -> 0 | AD7: =+AC7-X7 -> 0 | AE7: =IFERROR(AD7/AC7,0) -> 0
C8: Day 1 | D8: Car | E8: 09.06.2026 | J8: Oslo: Pick up your rental car at the aiport car rental office - G5 POLESTAR 2 LONG RANGE or similar - Includes: Airport service charge, Collision damage waiver, Fuel information, Unlimited mileage, Vehicle licence fee / road fund licence, Theft protection, Vat, Other taxes and service charges, Supplementary liability insurance, Cancellation fee | P8: https://app.hotelbeds.com/carhire/search?specialEquipment=AUTOMATIC&baggage=3,4&results=20&sortBy=LOWEST_PRICE_FIRST&field=PRICE&direction=ASCENDING&page=1&destinationTab=Oslo%20Airport%20(OSL)&pickupDate=09-06-2026&pickupTime=08:00&dropoffDate=13-06-2026&dropoffTime=08:00&sameOfficeCheckbox=true&officePickupControl=1758&officeDropoffControl=1758&typeDepartureCode=airport&_timestamp=1780558935093&typeArrivalCode=airport&departureTab= | Q8: 358 | R8: 1 | S8: =+Q8*R8 -> 358 | T8: 0 | U8: =S8*(1-T8) -> 358 | V8: EUR | W8: =IFERROR(VLOOKUP(V8,Curr!$B$2:$C$13,2,FALSE),0) -> 11.3 | X8: =U8*W8 -> 4045.4 | Y8: =Q8/0.75 -> 477.33333 | Z8: =+Y8*R8 -> 477.33333 | AA8: EUR | AB8: =IFERROR(VLOOKUP(AA8,Curr!$B$2:$C$13,2,FALSE),0) -> 11.3 | AC8: =+Y8*AB8*R8 -> 5393.8667 | AD8: =+AC8-X8 -> 1348.4667 | AE8: =IFERROR(AD8/AC8,0) -> 0.25
C9: Day 1 | D9: Drive | E9: 09.06.2026 | J9: Oslo: Drive to Voss - Time: 08:30 am - 2:30 pm (without stops) | Q9: 0 | R9: 0 | S9: =+Q9*R9 -> 0 | T9: 0 | U9: =S9*(1-T9) -> 0 | V9: EUR | W9: =IFERROR(VLOOKUP(V9,Curr!$B$2:$C$13,2,FALSE),0) -> 11.3 | X9: =U9*W9 -> 0 | Y9: =Q9 -> 0 | Z9: =+Y9*R9 -> 0 | AA9: EUR | AB9: =IFERROR(VLOOKUP(AA9,Curr!$B$2:$C$13,2,FALSE),0) -> 11.3 | AC9: =+Y9*AB9*R9 -> 0 | AD9: =+AC9-X9 -> 0 | AE9: =IFERROR(AD9/AC9,0) -> 0
C10: Day 1 | D10: Hotel | E10: 09.06.2026 | F10: 10.06.2026 | J10: Voss: Check in to your accommodation for a 1 night stay - Scandic Voss - 2 x Standard Room - Breakfast included | P10: https://app.hotelbeds.com/factsheet/stay/712885?check_in=09-06-2026&check_out=10-06-2026&occupancy=2~0_1~0&packaging=true | Q10: 500 | R10: 1 | S10: =+Q10*R10 -> 500 | T10: 0 | U10: =S10*(1-T10) -> 500 | V10: EUR | W10: =IFERROR(VLOOKUP(V10,Curr!$B$2:$C$13,2,FALSE),0) -> 11.3 | X10: =U10*W10 -> 5650 | Y10: =Q10/0.75 -> 666.66667 | Z10: =+Y10*R10 -> 666.66667 | AA10: EUR | AB10: =IFERROR(VLOOKUP(AA10,Curr!$B$2:$C$13,2,FALSE),0) -> 11.3 | AC10: =+Y10*AB10*R10 -> 7533.3333 | AD10: =+AC10-X10 -> 1883.3333 | AE10: =IFERROR(AD10/AC10,0) -> 0.25
C11: Day 1 | D11: Activity | E11: 09.06.2026 | J11: Voss: 1h E-Mountain Bike Full Suspension Rental - Time: 5:00 pm - 7:00 pm - Meeting point: Outdoor Norway office, Evangervegen 32, Voss - Includes: Top-quality equipment and helmet, High quality full-suspensions mountain bike - Description: Embark on a journey of awe-inspiring landscapes with the unparalleled E-MTB full-suspension bike, perfectly designed to elevate your adventure in the breathtaking beauty of Voss! | P11: https://booknordics.com/norway/western-fjord-norway/bergen-and-hardanger/rentals-e-mountain-bike-full-suspension | Q11: 78 | R11: 3 | S11: =+Q11*R11 -> 234 | T11: 0.2 | U11: =S11*(1-T11) -> 187.2 | V11: EUR | W11: =IFERROR(VLOOKUP(V11,Curr!$B$2:$C$13,2,FALSE),0) -> 11.3 | X11: =U11*W11 -> 2115.36 | Y11: =Q11 -> 78 | Z11: =+Y11*R11 -> 234 | AA11: EUR | AB11: =IFERROR(VLOOKUP(AA11,Curr!$B$2:$C$13,2,FALSE),0) -> 11.3 | AC11: =+Y11*AB11*R11 -> 2644.2 | AD11: =+AC11-X11 -> 528.84 | AE11: =IFERROR(AD11/AC11,0) -> 0.2
C12: Day 1 | D12: Leisure | E12: 09.06.2026 | J12: Voss: Spend time at leisure | Q12: 0 | R12: 0 | S12: =+Q12*R12 -> 0 | T12: 0 | U12: =S12*(1-T12) -> 0 | V12: EUR | W12: =IFERROR(VLOOKUP(V12,Curr!$B$2:$C$13,2,FALSE),0) -> 11.3 | X12: =U12*W12 -> 0 | Y12: =Q12 -> 0 | Z12: =+Y12*R12 -> 0 | AA12: EUR | AB12: =IFERROR(VLOOKUP(AA12,Curr!$B$2:$C$13,2,FALSE),0) -> 11.3 | AC12: =+Y12*AB12*R12 -> 0 | AD12: =+AC12-X12 -> 0 | AE12: =IFERROR(AD12/AC12,0) -> 0
S13: =+Q13*R13 -> 0 | T13: 0 | U13: =S13*(1-T13) -> 0 | V13: EUR | W13: =IFERROR(VLOOKUP(V13,Curr!$B$2:$C$13,2,FALSE),0) -> 11.3 | X13: =U13*W13 -> 0 | Y13: =Q13 -> 0 | Z13: =+Y13*R13 -> 0 | AA13: EUR | AB13: =IFERROR(VLOOKUP(AA13,Curr!$B$2:$C$13,2,FALSE),0) -> 11.3 | AC13: =+Y13*AB13*R13 -> 0 | AD13: =+AC13-X13 -> 0 | AE13: =IFERROR(AD13/AC13,0) -> 0
C14: Day 2 | D14: Activity | E14: 10.06.2026 | J14: Voss: Guided Sea Kayaking on the Nærøyfjord - Time: 08:30 am - 2:30 pm - Meeting point: Outdoor Norway, Evangervegen 32 - Includes: Professional sea kayaking guide, Transfers to and from the fjord, Sea kayak, paddle, PFD (life-jacket), Sprayskirt and splash jacket - Description: Explore the heart of the UNESCO World Heritage Park – Nærøyfjord in Norway. We take you to places only accessible by kayak. We explore historic areas of the Nærøyfjord, which for centuries, have been playing an important role in linking western and central Norway together. | P14: https://booknordics.com/norway/western-fjord-norway/bergen-and-hardanger/sea-kayaking-naeroyfjord-tour | Q14: 148 | R14: 3 | S14: =+Q14*R14 -> 444 | T14: 0.2 | U14: =S14*(1-T14) -> 355.2 | V14: EUR | W14: =IFERROR(VLOOKUP(V14,Curr!$B$2:$C$13,2,FALSE),0) -> 11.3 | X14: =U14*W14 -> 4013.76 | Y14: =Q14 -> 148 | Z14: =+Y14*R14 -> 444 | AA14: EUR | AB14: =IFERROR(VLOOKUP(AA14,Curr!$B$2:$C$13,2,FALSE),0) -> 11.3 | AC14: =+Y14*AB14*R14 -> 5017.2 | AD14: =+AC14-X14 -> 1003.44 | AE14: =IFERROR(AD14/AC14,0) -> 0.2
C15: Day 2 | D15: Drive | E15: 10.06.2026 | J15: Voss: Drive to Bergen - 3:00 pm - 5:30 pm (without stops) | Q15: 0 | R15: 0 | S15: =+Q15*R15 -> 0 | T15: 0 | U15: =S15*(1-T15) -> 0 | V15: EUR | W15: =IFERROR(VLOOKUP(V15,Curr!$B$2:$C$13,2,FALSE),0) -> 11.3 | X15: =U15*W15 -> 0 | Y15: =Q15 -> 0 | Z15: =+Y15*R15 -> 0 | AA15: EUR | AB15: =IFERROR(VLOOKUP(AA15,Curr!$B$2:$C$13,2,FALSE),0) -> 11.3 | AC15: =+Y15*AB15*R15 -> 0 | AD15: =+AC15-X15 -> 0 | AE15: =IFERROR(AD15/AC15,0) -> 0
C16: Day 2 | D16: Hotel | E16: 10.06.2026 | F16: 11.06.2026 | J16: Bergen: Check in to your accommodation for a 1 night stay - Scandic Neptun - 2 x Superior Room - Breakfast included | P16: https://app.hotelbeds.com/factsheet/stay/6678?check_in=10-06-2026&check_out=11-06-2026&occupancy=2~0_1~0&packaging=true | Q16: 696 | R16: 1 | S16: =+Q16*R16 -> 696 | T16: 0 | U16: =S16*(1-T16) -> 696 | V16: EUR | W16: =IFERROR(VLOOKUP(V16,Curr!$B$2:$C$13,2,FALSE),0) -> 11.3 | X16: =U16*W16 -> 7864.8 | Y16: =Q16/0.75 -> 928 | Z16: =+Y16*R16 -> 928 | AA16: EUR | AB16: =IFERROR(VLOOKUP(AA16,Curr!$B$2:$C$13,2,FALSE),0) -> 11.3 | AC16: =+Y16*AB16*R16 -> 10486.4 | AD16: =+AC16-X16 -> 2621.6 | AE16: =IFERROR(AD16/AC16,0) -> 0.25
C17: Day 2 | D17: Leisure | E17: 10.06.2026 | J17: Bergen: Spend time at leisure | Q17: 0 | R17: 0 | S17: =+Q17*R17 -> 0 | T17: 0 | U17: =S17*(1-T17) -> 0 | V17: EUR | W17: =IFERROR(VLOOKUP(V17,Curr!$B$2:$C$13,2,FALSE),0) -> 11.3 | X17: =U17*W17 -> 0 | Y17: =Q17 -> 0 | Z17: =+Y17*R17 -> 0 | AA17: EUR | AB17: =IFERROR(VLOOKUP(AA17,Curr!$B$2:$C$13,2,FALSE),0) -> 11.3 | AC17: =+Y17*AB17*R17 -> 0 | AD17: =+AC17-X17 -> 0 | AE17: =IFERROR(AD17/AC17,0) -> 0
S18: =+Q18*R18 -> 0 | T18: 0 | U18: =S18*(1-T18) -> 0 | V18: EUR | W18: =IFERROR(VLOOKUP(V18,Curr!$B$2:$C$13,2,FALSE),0) -> 11.3 | X18: =U18*W18 -> 0 | Y18: =Q18 -> 0 | Z18: =+Y18*R18 -> 0 | AA18: EUR | AB18: =IFERROR(VLOOKUP(AA18,Curr!$B$2:$C$13,2,FALSE),0) -> 11.3 | AC18: =+Y18*AB18*R18 -> 0 | AD18: =+AC18-X18 -> 0 | AE18: =IFERROR(AD18/AC18,0) -> 0
C19: Day 3 | D19: Activity | E19: 11.06.2026 | J19: Bergen: Mostraumen Majestic Fjord & Waterfall Cruise - Time: 10:30 am - 2:30 pm - Meeting point: Börshopen Pier, Strandkaien 13 - Includes: Round-trip cruise Bergen - Mostraumen - Bergen - Description: Fjord Cruise from Bergen to Mostraumen strait and the Osterfjord. This round-trip cruise is available all year. | P19: https://booknordics.com/norway/western-fjord-norway/bergen-and-hardanger/mostraumen-fjord-waterfall-cruise | Q19: 78 | R19: 3 | S19: =+Q19*R19 -> 234 | T19: 0.2 | U19: =S19*(1-T19) -> 187.2 | V19: EUR | W19: =IFERROR(VLOOKUP(V19,Curr!$B$2:$C$13,2,FALSE),0) -> 11.3 | X19: =U19*W19 -> 2115.36 | Y19: =Q19 -> 78 | Z19: =+Y19*R19 -> 234 | AA19: EUR | AB19: =IFERROR(VLOOKUP(AA19,Curr!$B$2:$C$13,2,FALSE),0) -> 11.3 | AC19: =+Y19*AB19*R19 -> 2644.2 | AD19: =+AC19-X19 -> 528.84 | AE19: =IFERROR(AD19/AC19,0) -> 0.2
C20: Day 3 | D20: Drive | E20: 11.06.2026 | J20: Bergen: Drive to Stavanger - 3:00 pm - 7:30 pm (without stops) | Q20: 0 | R20: 0 | S20: =+Q20*R20 -> 0 | T20: 0 | U20: =S20*(1-T20) -> 0 | V20: EUR | W20: =IFERROR(VLOOKUP(V20,Curr!$B$2:$C$13,2,FALSE),0) -> 11.3 | X20: =U20*W20 -> 0 | Y20: =Q20 -> 0 | Z20: =+Y20*R20 -> 0 | AA20: EUR | AB20: =IFERROR(VLOOKUP(AA20,Curr!$B$2:$C$13,2,FALSE),0) -> 11.3 | AC20: =+Y20*AB20*R20 -> 0 | AD20: =+AC20-X20 -> 0 | AE20: =IFERROR(AD20/AC20,0) -> 0
C21: Day 3 | D21: Hotel | E21: 11.06.2026 | F21: 12.06.2026 | J21: Stavanger: Check in to your accommodation for a 1 night stay - Radisson Blu Atlantic Stavanger - 1 x Standard room, 1 x single room - Breakfast included | P21: https://app.hotelbeds.com/factsheet/stay/7407?check_in=11-06-2026&check_out=12-06-2026&occupancy=2~0_1~0&packaging=true | Q21: 400 | R21: 1 | S21: =+Q21*R21 -> 400 | T21: 0 | U21: =S21*(1-T21) -> 400 | V21: EUR | W21: =IFERROR(VLOOKUP(V21,Curr!$B$2:$C$13,2,FALSE),0) -> 11.3 | X21: =U21*W21 -> 4520 | Y21: =Q21/0.75 -> 533.33333 | Z21: =+Y21*R21 -> 533.33333 | AA21: EUR | AB21: =IFERROR(VLOOKUP(AA21,Curr!$B$2:$C$13,2,FALSE),0) -> 11.3 | AC21: =+Y21*AB21*R21 -> 6026.6667 | AD21: =+AC21-X21 -> 1506.6667 | AE21: =IFERROR(AD21/AC21,0) -> 0.25
C22: Day 3 | D22: Leisure | E22: 11.06.2026 | J22: Stavanger: Spend time at leisure | Q22: 0 | R22: 0 | S22: =+Q22*R22 -> 0 | T22: 0 | U22: =S22*(1-T22) -> 0 | V22: EUR | W22: =IFERROR(VLOOKUP(V22,Curr!$B$2:$C$13,2,FALSE),0) -> 11.3 | X22: =U22*W22 -> 0 | Y22: =Q22 -> 0 | Z22: =+Y22*R22 -> 0 | AA22: EUR | AB22: =IFERROR(VLOOKUP(AA22,Curr!$B$2:$C$13,2,FALSE),0) -> 11.3 | AC22: =+Y22*AB22*R22 -> 0 | AD22: =+AC22-X22 -> 0 | AE22: =IFERROR(AD22/AC22,0) -> 0
S23: =+Q23*R23 -> 0 | T23: 0 | U23: =S23*(1-T23) -> 0 | V23: EUR | W23: =IFERROR(VLOOKUP(V23,Curr!$B$2:$C$13,2,FALSE),0) -> 11.3 | X23: =U23*W23 -> 0 | Y23: =Q23 -> 0 | Z23: =+Y23*R23 -> 0 | AA23: EUR | AB23: =IFERROR(VLOOKUP(AA23,Curr!$B$2:$C$13,2,FALSE),0) -> 11.3 | AC23: =+Y23*AB23*R23 -> 0 | AD23: =+AC23-X23 -> 0 | AE23: =IFERROR(AD23/AC23,0) -> 0
C24: Day 4 | D24: Activity | E24: 12.06.2026 | J24: Stavanger: Lysefjord & Preikestolen Fjord Cruise - Time: 10:00 am - 2:00 pm - Meeting point: Strandkaien, Stavanger - Includes: Sustainable, quiet & scenic fjord cruise, Boat tour aboard & luxurious catamaran, Spacious cabin with comfortable leather seats, Panoramic windows & large viewing decks, Audio guiding & free Wi-Fi on board, Licensed café serving snacks & drinks - Description: Discover magical Lysefjord - one of the most breathtaking fjords in Norway! Gaze up at spectacular Preikestolen (Pulpit Rock), majestic waterfalls and amazing mountains on our half-day fjord cruise! | Q24: 82 | R24: 3 | S24: =+Q24*R24 -> 246 | T24: 0.2 | U24: =S24*(1-T24) -> 196.8 | V24: EUR | W24: =IFERROR(VLOOKUP(V24,Curr!$B$2:$C$13,2,FALSE),0) -> 11.3 | X24: =U24*W24 -> 2223.84 | Y24: =Q24 -> 82 | Z24: =+Y24*R24 -> 246 | AA24: EUR | AB24: =IFERROR(VLOOKUP(AA24,Curr!$B$2:$C$13,2,FALSE),0) -> 11.3 | AC24: =+Y24*AB24*R24 -> 2779.8 | AD24: =+AC24-X24 -> 555.96 | AE24: =IFERROR(AD24/AC24,0) -> 0.2
C25: Day 4 | D25: Drive | E25: 12.06.2026 | J25: Stavanger: Drive to Oslo - 3:00 pm - 9:00 pm (without stops) | Q25: 0 | R25: 0 | S25: =+Q25*R25 -> 0 | T25: 0 | U25: =S25*(1-T25) -> 0 | V25: EUR | W25: =IFERROR(VLOOKUP(V25,Curr!$B$2:$C$13,2,FALSE),0) -> 11.3 | X25: =U25*W25 -> 0 | Y25: =Q25 -> 0 | Z25: =+Y25*R25 -> 0 | AA25: EUR | AB25: =IFERROR(VLOOKUP(AA25,Curr!$B$2:$C$13,2,FALSE),0) -> 11.3 | AC25: =+Y25*AB25*R25 -> 0 | AD25: =+AC25-X25 -> 0 | AE25: =IFERROR(AD25/AC25,0) -> 0
C26: Day 4 | D26: Hotel | E26: 12.06.2026 | F26: 13.06.2026 | J26: Oslo: Check in to your accommodation for a 1 night stay - Clarion Hotel The Hub - 2 x standard double - Breakfast included | P26: https://app.hotelbeds.com/factsheet/stay/7398?check_in=12-06-2026&check_out=13-06-2026&occupancy=2~0_1~0&packaging=true | Q26: =281*2 -> 562 | R26: 1 | S26: =+Q26*R26 -> 562 | T26: 0 | U26: =S26*(1-T26) -> 562 | V26: EUR | W26: =IFERROR(VLOOKUP(V26,Curr!$B$2:$C$13,2,FALSE),0) -> 11.3 | X26: =U26*W26 -> 6350.6 | Y26: =Q26/0.75 -> 749.33333 | Z26: =+Y26*R26 -> 749.33333 | AA26: EUR | AB26: =IFERROR(VLOOKUP(AA26,Curr!$B$2:$C$13,2,FALSE),0) -> 11.3 | AC26: =+Y26*AB26*R26 -> 8467.4667 | AD26: =+AC26-X26 -> 2116.8667 | AE26: =IFERROR(AD26/AC26,0) -> 0.25
C27: Day 4 | D27: Leisure | E27: 12.06.2026 | J27: Oslo: Spend time at leisure | Q27: 0 | R27: 0 | S27: =+Q27*R27 -> 0 | T27: 0 | U27: =S27*(1-T27) -> 0 | V27: EUR | W27: =IFERROR(VLOOKUP(V27,Curr!$B$2:$C$13,2,FALSE),0) -> 11.3 | X27: =U27*W27 -> 0 | Y27: =Q27 -> 0 | Z27: =+Y27*R27 -> 0 | AA27: EUR | AB27: =IFERROR(VLOOKUP(AA27,Curr!$B$2:$C$13,2,FALSE),0) -> 11.3 | AC27: =+Y27*AB27*R27 -> 0 | AD27: =+AC27-X27 -> 0 | AE27: =IFERROR(AD27/AC27,0) -> 0
S28: =+Q28*R28 -> 0 | T28: 0 | U28: =S28*(1-T28) -> 0 | V28: EUR | W28: =IFERROR(VLOOKUP(V28,Curr!$B$2:$C$13,2,FALSE),0) -> 11.3 | X28: =U28*W28 -> 0 | Y28: =Q28 -> 0 | Z28: =+Y28*R28 -> 0 | AA28: EUR | AB28: =IFERROR(VLOOKUP(AA28,Curr!$B$2:$C$13,2,FALSE),0) -> 11.3 | AC28: =+Y28*AB28*R28 -> 0 | AD28: =+AC28-X28 -> 0 | AE28: =IFERROR(AD28/AC28,0) -> 0
C29: Day 5 | D29: Drive | E29: 13.06.2026 | J29: Oslo: Drive to Oslo Airport - 40 minutes | Q29: 0 | R29: 0 | S29: =+Q29*R29 -> 0 | T29: 0 | U29: =S29*(1-T29) -> 0 | V29: EUR | W29: =IFERROR(VLOOKUP(V29,Curr!$B$2:$C$13,2,FALSE),0) -> 11.3 | X29: =U29*W29 -> 0 | Y29: =Q29 -> 0 | Z29: =+Y29*R29 -> 0 | AA29: EUR | AB29: =IFERROR(VLOOKUP(AA29,Curr!$B$2:$C$13,2,FALSE),0) -> 11.3 | AC29: =+Y29*AB29*R29 -> 0 | AD29: =+AC29-X29 -> 0 | AE29: =IFERROR(AD29/AC29,0) -> 0
C30: Day 5 | D30: Hotel | E30: 13.06.2026 | J30: Oslo: Deliver your rental car at the airport car rental office | Q30: 0 | R30: 0 | S30: =+Q30*R30 -> 0 | T30: 0 | U30: =S30*(1-T30) -> 0 | V30: EUR | W30: =IFERROR(VLOOKUP(V30,Curr!$B$2:$C$13,2,FALSE),0) -> 11.3 | X30: =U30*W30 -> 0 | Y30: =Q30 -> 0 | Z30: =+Y30*R30 -> 0 | AA30: EUR | AB30: =IFERROR(VLOOKUP(AA30,Curr!$B$2:$C$13,2,FALSE),0) -> 11.3 | AC30: =+Y30*AB30*R30 -> 0 | AD30: =+AC30-X30 -> 0 | AE30: =IFERROR(AD30/AC30,0) -> 0
C31: Day 5 | D31: Departure | E31: 13.06.2026 | J31: Oslo: Departure onwards | Q31: 0 | R31: 0 | S31: =+Q31*R31 -> 0 | T31: 0 | U31: =S31*(1-T31) -> 0 | V31: EUR | W31: =IFERROR(VLOOKUP(V31,Curr!$B$2:$C$13,2,FALSE),0) -> 11.3 | X31: =U31*W31 -> 0 | Y31: =Q31 -> 0 | Z31: =+Y31*R31 -> 0 | AA31: EUR | AB31: =IFERROR(VLOOKUP(AA31,Curr!$B$2:$C$13,2,FALSE),0) -> 11.3 | AC31: =+Y31*AB31*R31 -> 0 | AD31: =+AC31-X31 -> 0 | AE31: =IFERROR(AD31/AC31,0) -> 0
S32: =+Q32*R32 -> 0 | T32: 0 | U32: =S32*(1-T32) -> 0 | V32: EUR | W32: =IFERROR(VLOOKUP(V32,Curr!$B$2:$C$13,2,FALSE),0) -> 11.3 | X32: =U32*W32 -> 0 | Y32: =Q32 -> 0 | Z32: =+Y32*R32 -> 0 | AA32: EUR | AB32: =IFERROR(VLOOKUP(AA32,Curr!$B$2:$C$13,2,FALSE),0) -> 11.3 | AC32: =+Y32*AB32*R32 -> 0 | AD32: =+AC32-X32 -> 0 | AE32: =IFERROR(AD32/AC32,0) -> 0
S33: =+Q33*R33 -> 0 | T33: 0 | U33: =S33*(1-T33) -> 0 | V33: EUR | W33: =IFERROR(VLOOKUP(V33,Curr!$B$2:$C$13,2,FALSE),0) -> 11.3 | X33: =U33*W33 -> 0 | Y33: =Q33 -> 0 | Z33: =+Y33*R33 -> 0 | AA33: EUR | AB33: =IFERROR(VLOOKUP(AA33,Curr!$B$2:$C$13,2,FALSE),0) -> 11.3 | AC33: =+Y33*AB33*R33 -> 0 | AD33: =+AC33-X33 -> 0 | AE33: =IFERROR(AD33/AC33,0) -> 0
S34: =+Q34*R34 -> 0 | T34: 0 | U34: =S34*(1-T34) -> 0 | V34: EUR | W34: =IFERROR(VLOOKUP(V34,Curr!$B$2:$C$13,2,FALSE),0) -> 11.3 | X34: =U34*W34 -> 0 | Y34: =Q34 -> 0 | Z34: =+Y34*R34 -> 0 | AA34: EUR | AB34: =IFERROR(VLOOKUP(AA34,Curr!$B$2:$C$13,2,FALSE),0) -> 11.3 | AC34: =+Y34*AB34*R34 -> 0 | AD34: =+AC34-X34 -> 0 | AE34: =IFERROR(AD34/AC34,0) -> 0
S35: =+Q35*R35 -> 0 | T35: 0 | U35: =S35*(1-T35) -> 0 | V35: EUR | W35: =IFERROR(VLOOKUP(V35,Curr!$B$2:$C$13,2,FALSE),0) -> 11.3 | X35: =U35*W35 -> 0 | Y35: =Q35 -> 0 | Z35: =+Y35*R35 -> 0 | AA35: EUR | AB35: =IFERROR(VLOOKUP(AA35,Curr!$B$2:$C$13,2,FALSE),0) -> 11.3 | AC35: =+Y35*AB35*R35 -> 0 | AD35: =+AC35-X35 -> 0 | AE35: =IFERROR(AD35/AC35,0) -> 0
S36: =+Q36*R36 -> 0 | T36: 0 | U36: =S36*(1-T36) -> 0 | V36: EUR | W36: =IFERROR(VLOOKUP(V36,Curr!$B$2:$C$13,2,FALSE),0) -> 11.3 | X36: =U36*W36 -> 0 | Y36: =Q36 -> 0 | Z36: =+Y36*R36 -> 0 | AA36: EUR | AB36: =IFERROR(VLOOKUP(AA36,Curr!$B$2:$C$13,2,FALSE),0) -> 11.3 | AC36: =+Y36*AB36*R36 -> 0 | AD36: =+AC36-X36 -> 0 | AE36: =IFERROR(AD36/AC36,0) -> 0
S37: =+Q37*R37 -> 0 | T37: 0 | U37: =S37*(1-T37) -> 0 | V37: EUR | W37: =IFERROR(VLOOKUP(V37,Curr!$B$2:$C$13,2,FALSE),0) -> 11.3 | X37: =U37*W37 -> 0 | Y37: =Q37 -> 0 | Z37: =+Y37*R37 -> 0 | AA37: EUR | AB37: =IFERROR(VLOOKUP(AA37,Curr!$B$2:$C$13,2,FALSE),0) -> 11.3 | AC37: =+Y37*AB37*R37 -> 0 | AD37: =+AC37-X37 -> 0 | AE37: =IFERROR(AD37/AC37,0) -> 0
S38: =+Q38*R38 -> 0 | T38: 0 | U38: =S38*(1-T38) -> 0 | V38: EUR | W38: =IFERROR(VLOOKUP(V38,Curr!$B$2:$C$13,2,FALSE),0) -> 11.3 | X38: =U38*W38 -> 0 | Y38: =Q38 -> 0 | Z38: =+Y38*R38 -> 0 | AA38: EUR | AB38: =IFERROR(VLOOKUP(AA38,Curr!$B$2:$C$13,2,FALSE),0) -> 11.3 | AC38: =+Y38*AB38*R38 -> 0 | AD38: =+AC38-X38 -> 0 | AE38: =IFERROR(AD38/AC38,0) -> 0
B40: Totals | D40: x | E40: x | F40: x | G40: x | H40: x | I40: x | J40: x | K40: x | L40: x | M40: x | N40: x | O40: x | P40: x | Q40: x | R40: x | S40: x | T40: x | U40: x | V40: x | W40: x | X40: x | Y40: x | Z40: =SUM(Z7:Z38) -> 4512.6667 | AC40: =SUM(AC7:AC38) -> 50993.133 | AD40: =SUM(AD7:AD38) -> 12094.013 | AE40: =IFERROR(AD40/AC40,0) -> 0.23716945 | AF40: =SUM(AF8:AF39) -> 0 | AG40: =SUM(AG8:AG39) -> 0 | AH40: =SUM(AH8:AH39) -> 0 | AI40: =SUM(AI8:AI39) -> 0 | AJ40: =SUM(AJ8:AJ39) -> 0
Y42: Quote | Z42: 4530 | AA42: 5250
Y43: PP | Z43: =Z42/3 -> 1510 | AA43: =AA42/3 -> 1750
Y45: Car | Z45: 490 | AA45: 570
...
