Workbook

Sheet Curr
C1: NOK
B2: EUR | C2: 11.2
B3: SEK | C3: 1.02
B4: DKK | C4: 1.5
B5: ISK | C5: 0.075
B6: NOK | C6: 1
B7: USD | C7: 10.6

Sheet Overview
A2: ITIN | B2: Destinations | C2: Cost | D2: Margin | E2: Transfer Package | F2: TOT
A3: 101 | B3: Helsinki 1N - Santa Express 1N - Rovaniemi 3N - Kakslauttanen 1N | C3: ='101'!Z56 -> 4120 | D3: ='101'!AE52 -> 0.20120112 | E3: 300 | F3: =C3+E3 -> 4420
A4: 102 | B4: Helsinki 1N - Santa Express 1N - Rovaniemi 3N - Saariselkä 1N | C4: ='102'!Z62 -> 3460 | D4: ='102'!AE58 -> 0.20522946 | E4: 460 | F4: =C4+E4 -> 3920
A5: 103 | B5: Helsinki 1N - Santa Express 1N - Kemi 1N - Rovaniemi 3N | C5: ='103'!Z57 -> 3320 | D5: ='103'!AE53 -> 0.20864039 | E5: 300 | F5: =C5+E5 -> 3620
A6: 104 | B6: Helsinki 1N - Santa Express 1N - Kemi 1N - Rovaniemi 2N - Saariselkä 1N | C6: ='104'!Z66 -> 3460 | D6: ='104'!AE62 -> 0.21300931 | E6: 460 | F6: =C6+E6 -> 3920
A7: 105 | B7: Helsinki 1N - Santa Express 1N - Kemi 1N - Rovaniemi 2N - Kakslauttanen 1N | C7: ='105'!Z63 -> 4120 | D7: ='105'!AE59 -> 0.20647144 | E7: 300 | F7: =C7+E7 -> 4420
A8: 106 | B8: Helsinki 1N - Santa Express 1N - Rovaenimi 1N - Luosto 2N - Pyhä 1N | C8: ='106'!Z61 -> 3580 | D8: ='106'!AE57 -> 0.20858814 | E8: 300 | F8: =C8+E8 -> 3880
A9: 107 | B9: Helsinki 1N - Santa Express 1N - Rovaniemi 1N - Levi 3N | C9: ='107'!Z62 -> 3860 | D9: ='107'!AE58 -> 0.20638857 | E9: 300 | F9: =C9+E9 -> 4160
A10: 108 | B10: Helsinki 1N - Santa Express 1N - Rovaniemi 2N - Saariselkä 2N | C10: ='108'!Z60 -> 3120 | D10: ='108'!AE56 -> 0.23634851 | E10: 460 | F10: =C10+E10 -> 3580
A11: 109 | B11: Helsinki 1N - Santa Express 1N - Rovaniemi 3N - Kakslauttanen 1N | C11: ='109'!Z41 -> 5255.6969 | D11: ='109'!AE41 -> 0.20581417 | E11: 0 | F11: =C11+E11 -> 5255.6969
A12: 110 | B12: Helsinki 1N - Santa Express 1N -

Sheet MAL
B2: Places:
B3: Pax: 2
B4: Rooming: Double
B6: ID | C6: Day | D6: Type | E6: From date | F6: To date | G6: From time | H6: To time | I6: Supplier | J6: Travel element | K6: Manual booking? | L6: Status | M6: Comments | N6: Non-refundable | O6: Refundable | P6: URL | Q6: Gross P per unit | R6: Units | S6: Gross P | T6: Supp Comm | U6: Net P | V6: Supp curr | W6: X-rate | X6: Net P NOK | Y6: Sales P per unit | Z6: Price | AA6: Sales curr | AB6: X-rate | AC6: Sales P NOK tot | AD6: GP NOK | AE6: GP % | AF6: VAT25 | AG6: VAT15 | AH6: VAT12 | AI6: VAT0-D | AJ6: VAT0-I
Q7: 0 | R7: 0 | S7: =+Q7*R7 -> 0 | T7: 0 | U7: =S7*(1-T7) -> 0 | V7: EUR | W7: =IFERROR(VLOOKUP(V7,Curr!$B$2:$C$13,2,FALSE),0) -> 11.2 | X7: =U7*W7 -> 0 | Y7: =Q7 -> 0 | Z7: =+Y7*R7 -> 0 | AA7: EUR | AB7: =IFERROR(VLOOKUP(AA7,Curr!$B$2:$C$13,2,FALSE),0) -> 11.2 | AC7: =+Y7*AB7*R7 -> 0 | AD7: =+AC7-X7 -> 0 | AE7: =IFERROR(AD7/AC7,0) -> 0
Q8: 0 | R8: 0 | S8: =+Q8*R8 -> 0 | T8: 0 | U8: =S8*(1-T8) -> 0 | V8: EUR | W8: =IFERROR(VLOOKUP(V8,Curr!$B$2:$C$13,2,FALSE),0) -> 11.2 | X8: =U8*W8 -> 0 | Y8: =Q8 -> 0 | Z8: =+Y8*R8 -> 0 | AA8: EUR | AB8: =IFERROR(VLOOKUP(AA8,Curr!$B$2:$C$13,2,FALSE),0) -> 11.2 | AC8: =+Y8*AB8*R8 -> 0 | AD8: =+AC8-X8 -> 0 | AE8: =IFERROR(AD8/AC8,0) -> 0
Q9: 0 | R9: 0 | S9: =+Q9*R9 -> 0 | T9: 0 | U9: =S9*(1-T9) -> 0 | V9: EUR | W9: =IFERROR(VLOOKUP(V9,Curr!$B$2:$C$13,2,FALSE),0) -> 11.2 | X9: =U9*W9 -> 0 | Y9: =Q9 -> 0 | Z9: =+Y9*R9 -> 0 | AA9: EUR | AB9: =IFERROR(VLOOKUP(AA9,Curr!$B$2:$C$13,2,FALSE),0) -> 11.2 | AC9: =+Y9*AB9*R9 -> 0 | AD9: =+AC9-X9 -> 0 | AE9: =IFERROR(AD9/AC9,0) -> 0
Q10: 0 | R10: 0 | S10: =+Q10*R10 -> 0 | T10: 0 | U10: =S10*(1-T10) -> 0 | V10: EUR | W10: =IFERROR(VLOOKUP(V10,Curr!$B$2:$C$13,2,FALSE),0) -> 11.2 | X10: =U10*W10 -> 0 | Y10: =Q10 -> 0 | Z10: =+Y10*R10 -> 0 | AA10: EUR | AB10: =IFERROR(VLOOKUP(AA10,Curr!$B$2:$C$13,2,FALSE),0) -> 11.2 | AC10: =+Y10*AB10*R10 -> 0 | AD10: =+AC10-X10 -> 0 | AE10: =IFERROR(AD10/AC10,0) -> 0
Q11: 0 | R11: 0 | S11: =+Q11*R11 -> 0 | T11: 0 | U11: =S11*(1-T11) -> 0 | V11: EUR | W11: =IFERROR(VLOOKUP(V11,Curr!$B$2:$C$13,2,FALSE),0) -> 11.2 | X11: =U11*W11 -> 0 | Y11: =Q11 -> 0 | Z11: =+Y11*R11 -> 0 | AA11: EUR | AB11: =IFERROR(VLOOKUP(AA11,Curr!$B$2:$C$13,2,FALSE),0) -> 11.2 | AC11: =+Y11*AB11*R11 -> 0 | AD11: =+AC11-X11 -> 0 | AE11: =IFERROR(AD11/AC11,0) -> 0
Q12: 0 | R12: 0 | S12: =+Q12*R12 -> 0 | T12: 0 | U12: =S12*(1-T12) -> 0 | V12: EUR | W12: =IFERROR(VLOOKUP(V12,Curr!$B$2:$C$13,2,FALSE),0) -> 11.2 | X12: =U12*W12 -> 0 | Y12: =Q12 -> 0 | Z12: =+Y12*R12 -> 0 | AA12: EUR | AB12: =IFERROR(VLOOKUP(AA12,Curr!$B$2:$C$13,2,FALSE),0) -> 11.2 | AC12: =+Y12*AB12*R12 -> 0 | AD12: =+AC12-X12 -> 0 | AE12: =IFERROR(AD12/AC12,0) -> 0
Q13: 0 | R13: 0 | S13: =+Q13*R13 -> 0 | T13: 0 | U13: =S13*(1-T13) -> 0 | V13: EUR | W13: =IFERROR(VLOOKUP(V13,Curr!$B$2:$C$13,2,FALSE),0) -> 11.2 | X13: =U13*W13 -> 0 | Y13: =Q13 -> 0 | Z13: =+Y13*R13 -> 0 | AA13: EUR | AB13: =IFERROR(VLOOKUP(AA13,Curr!$B$2:$C$13,2,FALSE),0) -> 11.2 | AC13: =+Y13*AB13*R13 -> 0 | AD13: =+AC13-X13 -> 0 | AE13: =IFERROR(AD13/AC13,0) -> 0
Q14: 0 | R14: 0 | S14: =+Q14*R14 -> 0 | T14: 0 | U14: =S14*(1-T14) -> 0 | V14: EUR | W14: =IFERROR(VLOOKUP(V14,Curr!$B$2:$C$13,2,FALSE),0) -> 11.2 | X14: =U14*W14 -> 0 | Y14: =Q14 -> 0 | Z14: =+Y14*R14 -> 0 | AA14: EUR | AB14: =IFERROR(VLOOKUP(AA14,Curr!$B$2:$C$13,2,FALSE),0) -> 11.2 | AC14: =+Y14*AB14*R14 -> 0 | AD14: =+AC14-X14 -> 0 | AE14: =IFERROR(AD14/AC14,0) -> 0
Q15: 0 | R15: 0 | S15: =+Q15*R15 -> 0 | T15: 0 | U15: =S15*(1-T15) -> 0 | V15: EUR | W15: =IFERROR(VLOOKUP(V15,Curr!$B$2:$C$13,2,FALSE),0) -> 11.2 | X15: =U15*W15 -> 0 | Y15: =Q15 -> 0 | Z15: =+Y15*R15 -> 0 | AA15: EUR | AB15: =IFERROR(VLOOKUP(AA15,Curr!$B$2:$C$13,2,FALSE),0) -> 11.2 | AC15: =+Y15*AB15*R15 -> 0 | AD15: =+AC15-X15 -> 0 | AE15: =IFERROR(AD15/AC15,0) -> 0
Q16: 0 | R16: 0 | S16: =+Q16*R16 -> 0 | T16: 0 | U16: =S16*(1-T16) -> 0 | V16: EUR | W16: =IFERROR(VLOOKUP(V16,Curr!$B$2:$C$13,2,FALSE),0) -> 11.2 | X16: =U16*W16 -> 0 | Y16: =Q16 -> 0 | Z16: =+Y16*R16 -> 0 | AA16: EUR | AB16: =IFERROR(VLOOKUP(AA16,Curr!$B$2:$C$13,2,FALSE),0) -> 11.2 | AC16: =+Y16*AB16*R16 -> 0 | AD16: =+AC16-X16 -> 0 | AE16: =IFERROR(AD16/AC16,0) -> 0
Q17: 0 | R17: 0 | S17: =+Q17*R17 -> 0 | T17: 0 | U17: =S17*(1-T17) -> 0 | V17: EUR | W17: =IFERROR(VLOOKUP(V17,Curr!$B$2:$C$13,2,FALSE),0) -> 11.2 | X17: =U17*W17 -> 0 | Y17: =Q17 -> 0 | Z17: =+Y17*R17 -> 0 | AA17: EUR | AB17: =IFERROR(VLOOKUP(AA17,Curr!$B$2:$C$13,2,FALSE),0) -> 11.2 | AC17: =+Y17*AB17*R17 -> 0 | AD17: =+AC17-X17 -> 0 | AE17: =IFERROR(AD17/AC17,0) -> 0
Q18: 0 | R18: 0 | S18: =+Q18*R18 -> 0 | T18: 0 | U18: =S18*(1-T18) -> 0 | V18: EUR | W18: =IFERROR(VLOOKUP(V18,Curr!$B$2:$C$13,2,FALSE),0) -> 11.2 | X18: =U18*W18 -> 0 | Y18: =Q18 -> 0 | Z18: =+Y18*R18 -> 0 | AA18: EUR | AB18: =IFERROR(VLOOKUP(AA18,Curr!$B$2:$C$13,2,FALSE),0) -> 11.2 | AC18: =+Y18*AB18*R18 -> 0 | AD18: =+AC18-X18 -> 0 | AE18: =IFERROR(AD18/AC18,0) -> 0
... Q62: 0 | R62: 0 | S62: =+Q62*R62 -> 0 | T62: 0 | U62: =S62*(1-T62) -> 0 | V62: EUR | W62: =IFERROR(VLOOKUP(V62,Curr!$B$2:$C$13,2,FALSE),0) -> 11.2 | X62: =U62*W62 -> 0 | Y62: =Q62 -> 0 | Z62: =+Y62*R62 -> 0 | AA62: EUR | AB62: =IFERROR(VLOOKUP(AA62,Curr!$B$2:$C$13,2,FALSE),0) -> 11.2 | AC62: =+Y62*AB62*R62 -> 0 | AD62: =+AC62-X62 -> 0 | AE62: =IFERROR(AD62/AC62,0) -> 0
B64: Totals | D64: x | E64: x | F64: x | G64: x | H64: x | I64: x | J64: x | K64: x | L64: x | M64: x | N64: x | O64: x | P64: x | Q64: x | R64: x | S64: x | T64: x | U64: x | V64: x | W64: x | X64: x | Y64: x | Z64: =SUM(Z7:Z62) -> 0 | AC64: =SUM(AC7:AC62) -> 0 | AD64: =SUM(AD7:AD62) -> 0 | AE64: =IFERROR(AD64/AC64,0) -> 0 | AF64: =SUM(AF8:AF63) -> 0 | AG64: =SUM(AG8:AG63) -> 0 | AH64: =SUM(AH8:AH63) -> 0 | AI64: =SUM(AI8:AI63) -> 0 | AJ64: =SUM(AJ8:AJ63) -> 0
Y66: Fixed | Z66: =Z12+Z19+Z21+Z23+Z25+Z29+Z30+Z31+Z33 -> 0
Y67: Variable | Z67: =Y9+Y14+Y17 -> 0
Y68: Total | Z68: 4120
Y69: PP | Z69: =Z68/2 -> 2060
Y71: Ref | Z71: =Z68-Z72 -> 1760
Y72: NoRef | Z72: 2360
Y74: Deposit | Z74: 2360
Y75: Rest | Z75: =Z68-Z74 -> 1760
Y77: Shoulder | Z77: 3640
Y78: High | Z78: =Z77*1.15 -> 4186
Y79: Chirstmas | Z79: =Z77*1.2 -> 4368
Y80: Low | Z80: =Z77*0.84 -> 3057.6

Sheet 101
B2: Places: Helsinki - Santa Express - Rovaniemi - Kakslauttanen
B3: Pax: 2
B4: Rooming: Double
B6: ID | C6: Day | D6: Type | E6: From date | F6: To date | G6: From time | H6: To time | I6: Supplier | J6: Travel element | K6: Manual booking? | L6: Status | M6: Comments | N6: Non-refundable | O6: Refundable | P6: URL | Q6: Gross P per unit | R6: Units | S6: Gross P | T6: Supp Comm | U6: Net P | V6: Supp curr | W6: X-rate | X6: Net P NOK | Y6: Sales P per unit | Z6: Price | AA6: Sales curr | AB6: X-rate | AC6: Sales P NOK tot | AD6: GP NOK | AE6: GP % | AF6: VAT25 | AG6: VAT15 | AH6: VAT12 | AI6: VAT0-D | AJ6: VAT0-I
C7: Day 1 | D7: Arrival | J7: Helsinki: Welcome to Finland | Q7: 0 | R7: 0 | S7: =+Q7*R7 -> 0 | T7: 0 | U7: =S7*(1-T7) -> 0 | V7: EUR | W7: =IFERROR(VLOOKUP(V7,Curr!$B$2:$C$13,2,FALSE),0) -> 11.2 | X7: =U7*W7 -> 0 | Y7: =Q7 -> 0 | Z7: =+Y7*R7 -> 0 | AA7: EUR | AB7: =IFERROR(VLOOKUP(AA7,Curr!$B$2:$C$13,2,FALSE),0) -> 11.2 | AC7: =+Y7*AB7*R7 -> 0 | AD7: =+AC7-X7 -> 0 | AE7: =IFERROR(AD7/AC7,0) -> 0
C8: Day 1 | D8: Transfer | J8: Helsinki: Self transfer to your accommodation | Q8: 0 | R8: 0 | S8: =+Q8*R8 -> 0 | T8: 0 | U8: =S8*(1-T8) -> 0 | V8: EUR | W8: =IFERROR(VLOOKUP(V8,Curr!$B$2:$C$13,2,FALSE),0) -> 11.2 | X8: =U8*W8 -> 0 | Y8: =Q8/0.8 -> 0 | Z8: =+Y8*R8 -> 0 | AA8: EUR | AB8: =IFERROR(VLOOKUP(AA8,Curr!$B$2:$C$13,2,FALSE),0) -> 11.2 | AC8: =+Y8*AB8*R8 -> 0 | AD8: =+AC8-X8 -> 0 | AE8: =IFERROR(AD8/AC8,0) -> 0
C9: Day 1 | D9: Hotel | J9: Helsinki: Check in to your accommodation for a 1 night stay - Centraly Located 4-star hotel - Standard Room - Breakfast included | O9: x | Q9: 150 | R9: 1 | S9: =+Q9*R9 -> 150 | T9: 0 | U9: =S9*(1-T9) -> 150 | V9: EUR | W9: =IFERROR(VLOOKUP(V9,Curr!$B$2:$C$13,2,FALSE),0) -> 11.2 | X9: =U9*W9 -> 1680 | Y9: =Q9/0.8 -> 187.5 | Z9: =+Y9*R9 -> 187.5 | AA9: EUR | AB9: =IFERROR(VLOOKUP(AA9,Curr!$B$2:$C$13,2,FALSE),0) -> 11.2 | AC9: =+Y9*AB9*R9 -> 2100 | AD9: =+AC9-X9 -> 420 | AE9: =IFERROR(AD9/AC9,0) -> 0.2
C10: Day 1 | D10: Leisure | J10: Helsinki: Spend time at leisure | Q10: 0 | R10: 0 | S10: =+Q10*R10 -> 0 | T10: 0 | U10: =S10*(1-T10) -> 0 | V10: EUR | W10: =IFERROR(VLOOKUP(V10,Curr!$B$2:$C$13,2,FALSE),0) -> 11.2 | X10: =U10*W10 -> 0 | Y10: =Q10 -> 0 | Z10: =+Y10*R10 -> 0 | AA10: EUR | AB10: =IFERROR(VLOOKUP(AA10,Curr!$B$2:$C$13,2,FALSE),0) -> 11.2 | AC10: =+Y10*AB10*R10 -> 0 | AD10: =+AC10-X10 -> 0 | AE10: =IFERROR(AD10/AC10,0) -> 0
S11: =+Q11*R11 -> 0 | T11: 0 | U11: =S11*(1-T11) -> 0 | V11: EUR | W11: =IFERROR(VLOOKUP(V11,Curr!$B$2:$C$13,2,FALSE),0) -> 11.2 | X11: =U11*W11 -> 0 | Y11: =Q11 -> 0 | Z11: =+Y11*R11 -> 0 | AA11: EUR | AB11: =IFERROR(VLOOKUP(AA11,Curr!$B$2:$C$13,2,FALSE),0) -> 11.2 | AC11: =+Y11*AB11*R11 -> 0 | AD11: =+AC11-X11 -> 0 | AE11: =IFERROR(AD11/AC11,0) -> 0
C12: Day 2 | D12: Activity | J12: Helsinki: A Finntastic Walking Tour - Time: 10:30 am / 1:30 pm - 12:45 pm / 3:45 pm - Meeting point: Senate Square (Look for a blue and white umbrella) - End point: Helsinki Central Library Oodi - Notable Sights: Senate Square, Helsinki Cathedral, Kauppatori, Uspenski Cathedral, Esplanadi Park and more - Includes: Professional authorised Helsinki Guide, Liability Insurance | O12: x | P12: https://www.finntastictours.fi/# | Q12: 20 | R12: 2 | S12: =+Q12*R12 -> 40 | T12: 0 | U12: =S12*(1-T12) -> 40 | V12: EUR | W12: =IFERROR(VLOOKUP(V12,Curr!$B$2:$C$13,2,FALSE),0) -> 11.2 | X12: =U12*W12 -> 448 | Y12: =Q12/0.57 -> 35.087719 | Z12: =+Y12*R12 -> 70.175439 | AA12: EUR | AB12: =IFERROR(VLOOKUP(AA12,Curr!$B$2:$C$13,2,FALSE),0) -> 11.2 | AC12: =+Y12*AB12*R12 -> 785.96491 | AD12: =+AC12-X12 -> 337.96491 | AE12: =IFERROR(AD12/AC12,0) -> 0.43
C13: Day 2 | D13: Transfer | J13: Helsinki: Self transfer to Helsinki Central Station | Q13: 0 | R13: 0 | S13: =+Q13*R13 -> 0 | T13: 0 | U13: =S13*(1-T13) -> 0 | V13: EUR | W13: =IFERROR(VLOOKUP(V13,Curr!$B$2:$C$13,2,FALSE),0) -> 11.2 | X13: =U13*W13 -> 0 | Y13: =Q13 -> 0 | Z13: =+Y13*R13 -> 0 | AA13: EUR | AB13: =IFERROR(VLOOKUP(AA13,Curr!$B$2:$C$13,2,FALSE),0) -> 11.2 | AC13: =+Y13*AB13*R13 -> 0 | AD13: =+AC13-X13 -> 0 | AE13: =IFERROR(AD13/AC13,0) -> 0
C14: Day 2 | D14: Train | J14: Helsinki: Overnight Santa Claus Express Train to Rovaniemi - Time: 11:13 pm - 10:59 am - Includes: Upstairs Sleeper Cabin with Private Bathroom | N14: x | P14: https://www.vr.fi/en/santa-claus-express | Q14: 200 | R14: 1 | S14: =+Q14*R14 -> 200 | T14: 0 | U14: =S14*(1-T14) -> 200 | V14: EUR | W14: =IFERROR(VLOOKUP(V14,Curr!$B$2:$C$13,2,FALSE),0) -> 11.2 | X14: =U14*W14 -> 2240 | Y14: =Q14/0.85 -> 235.29412 | Z14: =+Y14*R14 -> 235.29412 | AA14: EUR | AB14: =IFERROR(VLOOKUP(AA14,Curr!$B$2:$C$13,2,FALSE),0) -> 11.2 | AC14: =+Y14*AB14*R14 -> 2635.2941 | AD14: =+AC14-X14 -> 395.29412 | AE14: =IFERROR(AD14/AC14,0) -> 0.15
S15: =+Q15*R15 -> 0 | T15: 0 | U15: =S15*(1-T15) -> 0 | V15: EUR | W15: =IFERROR(VLOOKUP(V15,Curr!$B$2:$C$13,2,FALSE),0) -> 11.2 | X15: =U15*W15 -> 0 | Y15: =Q15 -> 0 | Z15: =+Y15*R15 -> 0 | AA15: EUR | AB15: =IFERROR(VLOOKUP(AA15,Curr!$B$2:$C$13,2,FALSE),0) -> 11.2 | AC15: =+Y15*AB15*R15 -> 0 | AD15: =+AC15-X15 -> 0 | AE15: =IFERROR(AD15/AC15,0) -> 0
C16: Day 3 | D16: Transfer | J16: Rovaniemi: Self transfer to your accommodation | Q16: 0 | R16: 0 | S16: =+Q16*R16 -> 0 | T16: 0 | U16: =S16*(1-T16) -> 0 | V16: EUR | W16: =IFERROR(VLOOKUP(V16,Curr!$B$2:$C$13,2,FALSE),0) -> 11.2 | X16: =U16*W16 -> 0 | Y16: =Q16/0.8 -> 0 | Z16: =+Y16*R16 -> 0 | AA16: EUR | AB16: =IFERROR(VLOOKUP(AA16,Curr!$B$2:$C$13,2,FALSE),0) -> 11.2 | AC16: =+Y16*AB16*R16 -> 0 | AD16: =+AC16-X16 -> 0 | AE16: =IFERROR(AD16/AC16,0) -> 0
C17: Day 3 | D17: Hotel | J17: Rovaniemi: Check in to your accommodation for a 3 night stay - Centrally Located 3/4-star Hotel - Standard Room - Breakfast included | N17: x | Q17: =109*2*3 -> 654 | R17: 1 | S17: =+Q17*R17 -> 654 | T17: 0 | U17: =S17*(1-T17) -> 654 | V17: EUR | W17: =IFERROR(VLOOKUP(V17,Curr!$B$2:$C$13,2,FALSE),0) -> 11.2 | X17: =U17*W17 -> 7324.8 | Y17: =Q17/0.8 -> 817.5 | Z17: =+Y17*R17 -> 817.5 | AA17: EUR | AB17: =IFERROR(VLOOKUP(AA17,Curr!$B$2:$C$13,2,FALSE),0) -> 11.2 | AC17: =+Y17*AB17*R17 -> 9156 | AD17: =+AC17-X17 -> 1831.2 | AE17: =IFERROR(AD17/AC17,0) -> 0.2
C18: Day 3 | D18: Leisure | J18: Rovaniemi: Spend time at leisure | Q18: 0 | R18: 0 | S18: =+Q18*R18 -> 0 | T18: 0 | U18: =S18*(1-T18) -> 0 | V18: EUR | W18: =IFERROR(VLOOKUP(V18,Curr!$B$2:$C$13,2,FALSE),0) -> 11.2 | X18: =U18*W18 -> 0 | Y18: =Q18 -> 0 | Z18: =+Y18*R18 -> 0 | AA18: EUR | AB18: =IFERROR(VLOOKUP(AA18,Curr!$B$2:$C$13,2,FALSE),0) -> 11.2 | AC18: =+Y18*AB18*R18 -> 0 | AD18: =+AC18-X18 -> 0 | AE18: =IFERROR(AD18/AC18,0) -> 0
C19: Day 3 | D19: Activity | J19: Rovaniemi: Northern Lights Unlimited Mileage Photo Tour - Time: 08:00 pm - 01:00 am - Meeting point: Book Lapland Office - Includes: Pick-up/drop-off in central Rovaniemi, Knowledgeable, English-speaking guides, Professional DSLR photography (unlimited), Meteorological observations, Thermal winter clothing, Hot drinks & snacks or cookies | O19: x | P19: https://booknordics.com/finland/western-lapland/rovaniemi/rovaniemi-northern-lights-family-tour-by-bus-with-photos | Q19: 109 | R19: 2 | S19: =+Q19*R19 -> 218 | T19: 0.2 | U19: =S19*(1-T19) -> 174.4 | V19: EUR | W19: =IFERROR(VLOOKUP(V19,Curr!$B$2:$C$13,2,FALSE),0) -> 11.2 | X19: =U19*W19 -> 1953.28 | Y19: =Q19 -> 109 | Z19: =+Y19*R19 -> 218 | AA19: EUR | AB19: =IFERROR(VLOOKUP(AA19,Curr!$B$2:$C$13,2,FALSE),0) -> 11.2 | AC19: =+Y19*AB19*R19 -> 2441.6 | AD19: =+AC19-X19 -> 488.32 | AE19: =IFERROR(AD19/AC19,0) -> 0.2
S20: =+Q20*R20 -> 0 | T20: 0 | U20: =S20*(1-T20) -> 0 | V20: EUR | W20: =IFERROR(VLOOKUP(V20,Curr!$B$2:$C$13,2,FALSE),0) -> 11.2 | X20: =U20*W20 -> 0 | Y20: =Q20 -> 0 | Z20: =+Y20*R20 -> 0 | AA20: EUR | AB20: =IFERROR(VLOOKUP(AA20,Curr!$B$2:$C$13,2,FALSE),0) -> 11.2 | AC20: =+Y20*AB20*R20 -> 0 | AD20: =+AC20-X20 -> 0 | AE20: =IFERROR(AD20/AC20,0) -> 0
C21: Day 4 | D21: Activity | J21: Rovaniemi: Arctic Circle Highlights Adventure Day - Time: 08:45 am - 2:45 pm - Meeting point: Arctic Circle Snowmobile Park office - Includes: Pick-up/drop-off in central Rovaniemi, Reindeer Farm visit with sleigh ride (2-3 pers), Reindeer sledge driver’s license reward, Alaskan Husky visit with sleigh ride (4 pers), Approx. 2 hours free time in Santa Claus Village, Winter clothes (overalls, boots and gloves), Traditional salmon soup or vegetarian option | O21: x | P21: https://booknordics.com/finland/western-lapland/rovaniemi/arctic-circle-highlights-family-day-by-minibus | Q21: 188 | R21: 2 | S21: =+Q21*R21 -> 376 | T21: 0.2 | U21: =S21*(1-T21) -> 300.8 | V21: EUR | W21: =IFERROR(VLOOKUP(V21,Curr!$B$2:$C$13,2,FALSE),0) -> 11.2 | X21: =U21*W21 -> 3368.96 | Y21: =Q21 -> 188 | Z21: =+Y21*R21 -> 376 | AA21: EUR | AB21: =IFERROR(VLOOKUP(AA21,Curr!$B$2:$C$13,2,FALSE),0) -> 11.2 | AC21: =+Y21*AB21*R21 -> 4211.2 | AD21: =+AC21-X21 -> 842.24 | AE21: =IFERROR(AD21/AC21,0) -> 0.2
C22: Day 4 | D22: Leisure | J22: Rovaniemi: Spend time at leisure | Q22: 0 | R22: 0 | S22: =+Q22*R22 -> 0 | T22: 0 | U22: =S22*(1-T22) -> 0 | V22: EUR | W22: =IFERROR(VLOOKUP(V22,Curr!$B$2:$C$13,2,FALSE),0) -> 11.2 | X22: =U22*W22 -> 0 | Y22: =Q22 -> 0 | Z22: =+Y22*R22 -> 0 | AA22: EUR | AB22: =IFERROR(VLOOKUP(AA22,Curr!$B$2:$C$13,2,FALSE),0) -> 11.2 | AC22: =+Y22*AB22*R22 -> 0 | AD22: =+AC22-X22 -> 0 | AE22: =IFERROR(AD22/AC22,0) -> 0
C23: Day 4 | D23: Activity | J23: Rovaniemi: Small-Group Aurora Hunt by Minibus - Time: 7:00 pm - 10:00 pm - Meeting point: Lapland Royal Adventures Office - Includes: Pick-up/drop-off from central Rovaniemi, Knowledgeable, English-speaking guide, Dedicated Northern Lights chase by minibus, Cozy blankets, hot drinks and a snack | O23: x | P23: https://booknordics.com/finland/western-lapland/rovaniemi/aurora-quest-by-minibus | Q23: 89 | R23: 2 | S23: =+Q23*R23 -> 178 | T23: 0.2 | U23: =S23*(1-T23) -> 142.4 | V23: EUR | W23: =IFERROR(VLOOKUP(V23,Curr!$B$2:$C$13,2,FALSE),0) -> 11.2 | X23: =U23*W23 -> 1594.88 | Y23: =Q23 -> 89 | Z23: =+Y23*R23 -> 178 | AA23: EUR | AB23: =IFERROR(VLOOKUP(AA23,Curr!$B$2:$C$13,2,FALSE),0) -> 11.2 | AC23: =+Y23*AB23*R23 -> 1993.6 | AD23: =+AC23-X23 -> 398.72 | AE23: =IFERROR(AD23/AC23,0) -> 0.2
S24: =+Q24*R24 -> 0 | T24: 0 | U24: =S24*(1-T24) -> 0 | V24: EUR | W24: =IFERROR(VLOOKUP(V24,Curr!$B$2:$C$13,2,FALSE),0) -> 11.2 | X24: =U24*W24 -> 0 | Y24: =Q24 -> 0 | Z24: =+Y24*R24 -> 0 | AA24: EUR | AB24: =IFERROR(VLOOKUP(AA24,Curr!$B$2:$C$13,2,FALSE),0) -> 11.2 | AC24: =+Y24*AB24*R24 -> 0 | AD24: =+AC24-X24 -> 0 | AE24: =IFERROR(AD24/AC24,0) -> 0
C25: Day 5 | D25: Activity | J25: Rovaniemi: Arctic Wildlife Adventure to Ranua Park - Time: 10:00 am - 4:00 pm - Meeting point: Lapland Royal Adventures office - Includes: Pick-up/drop-off in central Rovaniemi, Tickets to Ranua Wildlife Park, Drinks and BBQ sausages by fire | O25: x | P25: https://booknordics.com/finland/western-lapland/rovaniemi/arctic-wildlife-adventure-ranua-wildlife-park-trip | Q25: 109 | R25: 2 | S25: =+Q25*R25 -> 218 | T25: 0.2 | U25: =S25*(1-T25) -> 174.4 | V25: EUR | W25: =IFERROR(VLOOKUP(V25,Curr!$B$2:$C$13,2,FALSE),0) -> 11.2 | X25: =U25*W25 -> 1953.28 | Y25: =Q25 -> 109 | Z25: =+Y25*R25 -> 218 | AA25: EUR | AB25: =IFERROR(VLOOKUP(AA25,Curr!$B$2:$C$13,2,FALSE),0) -> 11.2 | AC25: =+Y25*AB25*R25 -> 2441.6 | AD25: =+AC25-X25 -> 488.32 | AE25: =IFERROR(AD25/AC25,0) -> 0.2
C26: Day 5 | D26: Leisure | J26: Rovaniemi: Spend time at leisure | Q26: 0 | R26: 0 | S26: =+Q26*R26 -> 0 | T26: 0 | U26: =S26*(1-T26) -> 0 | V26: EUR | W26: =IFERROR(VLOOKUP(V26,Curr!$B$2:$C$13,2,FALSE),0) -> 11.2 | X26: =U26*W26 -> 0 | Y26: =Q26 -> 0 | Z26: =+Y26*R26 -> 0 | AA26: EUR | AB26: =IFERROR(VLOOKUP(AA26,Curr!$B$2:$C$13,2,FALSE),0) -> 11.2 | AC26: =+Y26*AB26*R26 -> 0 | AD26: =+AC26-X26 -> 0 | AE26: =IFERROR(AD26/AC26,0) -> 0
S27: =+Q27*R27 -> 0 | T27: 0 | U27: =S27*(1-T27) -> 0 | V27: EUR | W27: =IFERROR(VLOOKUP(V27,Curr!$B$2:$C$13,2,FALSE),0) -> 11.2 | X27: =U27*W27 -> 0 | Y27: =Q27 -> 0 | Z27: =+Y27*R27 -> 0 | AA27: EUR | AB27: =IFERROR(VLOOKUP(AA27,Curr!$B$2:$C$13,2,FALSE),0) -> 11.2 | AC27: =+Y27*AB27*R27 -> 0 | AD27: =+AC27-X27 -> 0 | AE27: =IFERROR(AD27/AC27,0) -> 0
C28: Day 6 | D28: Transfer | J28: Rovaniemi: Self transfer to Rovaniemi Bus Station | Q28: 0 | R28: 0 | S28: =+Q28*R28 -> 0 | T28: 0 | U28: =S28*(1-T28) -> 0 | V28: EUR | W28: =IFERROR(VLOOKUP(V28,Curr!$B$2:$C$13,2,FALSE),0) -> 11.2 | X28: =U28*W28 -> 0 | Y28: =Q28 -> 0 | Z28: =+Y28*R28 -> 0 | AA28: EUR | AB28: =IFERROR(VLOOKUP(AA28,Curr!$B$2:$C$13,2,FALSE),0) -> 11.2 | AC28: =+Y28*AB28*R28 -> 0 | AD28: =+AC28-X28 -> 0 | AE28: =IFERROR(AD28/AC28,0) -> 0
C29: Day 6 | D29: Coach | J29: Rovaniemi: Panorama Coach Transfer to Kakslauttanen - Time: 11:45 am - 3:02 pm - Includes: tickets | N29: x | P29: https://www.matkahuolto.fi/en | Q29: 50 | R29: 2 | S29: =+Q29*R29 -> 100 | T29: 0 | U29: =S29*(1-T29) -> 100 | V29: EUR | W29: =IFERROR(VLOOKUP(V29,Curr!$B$2:$C$13,2,FALSE),0) -> 11.2 | X29: =U29*W29 -> 1120 | Y29: =Q29/0.8 -> 62.5 | Z29: =+Y29*R29 -> 125 | AA29: EUR | AB29: =IFERROR(VLOOKUP(AA29,Curr!$B$2:$C$13,2,FALSE),0) -> 11.2 | AC29: =+Y29*AB29*R29 -> 1400 | AD29: =+AC29-X29 -> 280 | AE29: =IFERROR(AD29/AC29,0) -> 0.2
C30: Day 6 | D30: Hotel | J30: Kakslauttanen: Check in to your accommodation for a 1 night stay - Kakslauttanen Arctic Resort - Small Glass Igloo with Sauna and Shower East or West Village - dinner and breakfast included | N30: x | Q30: =58+58+538 -> 654 | R30: 1 | S30: =+Q30*R30 -> 654 | T30: 0 | U30: =S30*(1-T30) -> 654 | V30: EUR | W30: =IFERROR(VLOOKUP(V30,Curr!$B$2:$C$13,2,FALSE),0) -> 11.2 | X30: =U30*W30 -> 7324.8 | Y30: =Q30/0.8 -> 817.5 | Z30: =+Y30*R30 -> 817.5 | AA30: EUR | AB30: =IFERROR(VLOOKUP(AA30,Curr!$B$2:$C$13,2,FALSE),0) -> 11.2 | AC30: =+Y30*AB30*R30 -> 9156 | AD30: =+AC30-X30 -> 1831.2 | AE30: =IFERROR(AD30/AC30,0) -> 0.2
C31: Day 6 | D31: Activity | J31: Kakslauttanen: Aurora Hunting with Reindeers - Time: To be determined - Meeting point: Resort Reception - Includes: Transfers, Thermal clothing, winter boots and gloves | N31: x | Q31: 111 | R31: 2 | S31: =+Q31*R31 -> 222 | T31: 0 | U31: =S31*(1-T31) -> 222 | V31: EUR | W31: =IFERROR(VLOOKUP(V31,Curr!$B$2:$C$13,2,FALSE),0) -> 11.2 | X31: =U31*W31 -> 2486.4 | Y31: =Q31/0.8 -> 138.75 | Z31: =+Y31*R31 -> 277.5 | AA31: EUR | AB31: =IFERROR(VLOOKUP(AA31,Curr!$B$2:$C$13,2,FALSE),0) -> 11.2 | AC31: =+Y31*AB31*R31 -> 3108 | AD31: =+AC31-X31 -> 621.6 | AE31: =IFERROR(AD31/AC31,0) -> 0.2
S32: =+Q32*R32 -> 0 | T32: 0 | U32: =S32*(1-T32) -> 0 | V32: EUR | W32: =IFERROR(VLOOKUP(V32,Curr!$B$2:$C$13,2,FALSE),0) -> 11.2 | X32: =U32*W32 -> 0 | Y32: =Q32 -> 0 | Z32: =+Y32*R32 -> 0 | AA32: EUR | AB32: =IFERROR(VLOOKUP(AA32,Curr!$B$2:$C$13,2,FALSE),0) -> 11.2 | AC32: =+Y32*AB32*R32 -> 0 | AD32: =+AC32-X32 -> 0 | AE32: =IFERROR(AD32/AC32,0) -> 0
C33: Day 7 | D33: Transfer | J33: Kakslauttanen: Shuttle transfer to Ivalo Airport | N33: x | Q33: 49 | R33: 2 | S33: =+Q33*R33 -> 98 | T33: 0 | U33: =S33*(1-T33) -> 98 | V33: EUR | W33: =IFERROR(VLOOKUP(V33,Curr!$B$2:$C$13,2,FALSE),0) -> 11.2 | X33: =U33*W33 -> 1097.6 | Y33: =Q33/0.8 -> 61.25 | Z33: =+Y33*R33 -> 122.5 | AA33: EUR | AB33: =IFERROR(VLOOKUP(AA33,Curr!$B$2:$C$13,2,FALSE),0) -> 11.2 | AC33: =+Y33*AB33*R33 -> 1372 | AD33: =+AC33-X33 -> 274.4 | AE33: =IFERROR(AD33/AC33,0) -> 0.2
C34: Day 7 | D34: Departure | J34: Ivalo: Departure home | Q34: 0 | R34: 0 | S34: =+Q34*R34 -> 0 | T34: 0 | U34: =S34*(1-T34) -> 0 | V34: EUR | W34: =IFERROR(VLOOKUP(V34,Curr!$B$2:$C$13,2,FALSE),0) -> 11.2 | X34: =U34*W34 -> 0 | Y34: =Q34 -> 0 | Z34: =+Y34*R34 -> 0 | AA34: EUR | AB34: =IFERROR(VLOOKUP(AA34,Curr!$B$2:$C$13,2,FALSE),0) -> 11.2 | AC34: =+Y34*AB34*R34 -> 0 | AD34: =+AC34-X34 -> 0 | AE34: =IFERROR(AD34/AC34,0) -> 0
S35: =+Q35*R35 -> 0 | T35: 0 | U35: =S35*(1-T35) -> 0 | V35: EUR | W35: =IFERROR(VLOOKUP(V35,Curr!$B$2:$C$13,2,FALSE),0) -> 11.2 | X35: =U35*W35 -> 0 | Y35: =Q35 -> 0 | Z35: =+Y35*R35 -> 0 | AA35: EUR | AB35: =IFERROR(VLOOKUP(AA35,Curr!$B$2:$C$13,2,FALSE),0) -> 11.2 | AC35: =+Y35*AB35*R35 -> 0 | AD35: =+AC35-X35 -> 0 | AE35: =IFERROR(AD35/AC35,0) -> 0
S36: =+Q36*R36 -> 0 | T36: 0 | U36: =S36*(1-T36) -> 0 | V36: EUR | W36: =IFERROR(VLOOKUP(V36,Curr!$B$2:$C$13,2,FALSE),0) -> 11.2 | X36: =U36*W36 -> 0 | Y36: =Q36 -> 0 | Z36: =+Y36*R36 -> 0 | AA36: EUR | AB36: =IFERROR(VLOOKUP(AA36,Curr!$B$2:$C$13,2,FALSE),0) -> 11.2 | AC36: =+Y36*AB36*R36 -> 0 | AD36: =+AC36-X36 -> 0 | AE36: =IFERROR(AD36/AC36,0) -> 0
C37: Day 1 | D37: Transfer Package | J37: Helsinki: Private transfer to your accommodation | O37: x | Q37: 80 | R37: 0 | S37: =+Q37*R37 -> 0 | T37: 0 | U37: =S37*(1-T37) -> 0 | V37: EUR | W37: =IFERROR(VLOOKUP(V37,Curr!$B$2:$C$13,2,FALSE),0) -> 11.2 | X37: =U37*W37 -> 0 | Y37: =Q37/0.8 -> 100 | Z37: =+Y37*R37 -> 0 | AA37: EUR | AB37: =IFERROR(VLOOKUP(AA37,Curr!$B$2:$C$13,2,FALSE),0) -> 11.2 | AC37: =+Y37*AB37*R37 -> 0 | AD37: =+AC37-X37 -> 0 | AE37: =IFERROR(AD37/AC37,0) -> 0
C38: Day 2 | D38: Transfer Package | J38: Helsinki: Private transfer to Helsinki Central Station | O38: x | Q38: 60 | R38: 0 | S38: =+Q38*R38 -> 0 | T38: 0 | U38: =S38*(1-T38) -> 0 | V38: EUR | W38: =IFERROR(VLOOKUP(V38,Curr!$B$2:$C$13,2,FALSE),0) -> 11.2 | X38: =U38*W38 -> 0 | Y38: =Q38/0.75 -> 80 | Z38: =+Y38*R38 -> 0 | AA38: EUR | AB38: =IFERROR(VLOOKUP(AA38,Curr!$B$2:$C$13,2,FALSE),0) -> 11.2 | AC38: =+Y38*AB38*R38 -> 0 | AD38: =+AC38-X38 -> 0 | AE38: =IFERROR(AD38/AC38,0) -> 0
C39: Day 3 | D39: Transfer Package | J39: Rovaniemi: Private transfer to your accommodation | O39: x | Q39: 40 | R39: 0 | S39: =+Q39*R39 -> 0 | T39: 0 | U39: =S39*(1-T39) -> 0 | V39: EUR | W39: =IFERROR(VLOOKUP(V39,Curr!$B$2:$C$13,2,FALSE),0) -> 11.2 | X39: =U39*W39 -> 0 | Y39: =Q39/0.665 -> 60.150376 | Z39: =+Y39*R39 -> 0 | AA39: EUR | AB39: =IFERROR(VLOOKUP(AA39,Curr!$B$2:$C$13,2,FALSE),0) -> 11.2 | AC39: =+Y39*AB39*R39 -> 0 | AD39: =+AC39-X39 -> 0 | AE39: =IFERROR(AD39/AC39,0) -> 0
C40: Day 6 | D40: Transfer Package | J40: Rovaniemi: Private transfer to Rovaniemi Bus Station | O40: x | Q40: 40 | R40: 0 | S40: =+Q40*R40 -> 0 | T40: 0 | U40: =S40*(1-T40) -> 0 | V40: EUR | W40: =IFERROR(VLOOKUP(V40,Curr!$B$2:$C$13,2,FALSE),0) -> 11.2 | X40: =U40*W40 -> 0 | Y40: =Q40/0.665 -> 60.150376 | Z40: =+Y40*R40 -> 0 | AA40: EUR | AB40: =IFERROR(VLOOKUP(AA40,Curr!$B$2:$C$13,2,FALSE),0) -> 11.2 | AC40: =+Y40*AB40*R40 -> 0 | AD40: =+AC40-X40 -> 0 | AE40: =IFERROR(AD40/AC40,0) -> 0
S41: =+Q41*R41 -> 0 | T41: 0 | U41: =S41*(1-T41) -> 0 | V41: EUR | W41: =IFERROR(VLOOKUP(V41,Curr!$B$2:$C$13,2,FALSE),0) -> 11.2 | X41: =U41*W41 -> 0 | Y41: =Q41/0.665 -> 0 | Z41: =+Y41*R41 -> 0 | AA41: EUR | AB41: =IFERROR(VLOOKUP(AA41,Curr!$B$2:$C$13,2,FALSE),0) -> 11.2 | AC41: =+Y41*AB41*R41 -> 0 | AD41: =+AC41-X41 -> 0 | AE41: =IFERROR(AD41/AC41,0) -> 0
S42: =+Q42*R42 -> 0 | T42: 0 | U42: =S42*(1-T42) -> 0 | V42: EUR | W42: =IFERROR(VLOOKUP(V42,Curr!$B$2:$C$13,2,FALSE),0) -> 11.2 | X42: =U42*W42 -> 0 | Y42: =Q42 -> 0 | Z42: =+Y42*R42 -> 0 | AA42: EUR | AB42: =IFERROR(VLOOKUP(AA42,Curr!$B$2:$C$13,2,FALSE),0) -> 11.2 | AC42: =+Y42*AB42*R42 -> 0 | AD42: =+AC42-X42 -> 0 | AE42: =IFERROR(AD42/AC42,0) -> 0
...

Sheet 102
B2: Places: Helsinki - Santa Express - Rovaniemi - Saariselka
B3: Pax: 2
B4: Rooming: Double
B6: ID | C6: Day | D6: Type | E6: From date | F6: To date | G6: From time | H6: To time | I6: Supplier | J6: Travel element | K6: Manual booking? | L6: Status | M6: Comments | N6: Non-refundable | O6: Refundable | P6: URL | Q6: Gross P per unit | R6: Units | S6: Gross P | T6: Supp Comm | U6: Net P | V6: Supp curr | W6: X-rate | X6: Net P NOK | Y6: Sales P per unit | Z6: Price | AA6: Sales curr | AB6: X-rate | AC6: Sales P NOK tot | AD6: GP NOK | AE6: GP % | AF6: VAT25 | AG6: VAT15 | AH6: VAT12 | AI6: VAT0-D | AJ6: VAT0-I
C7: Day 1 | D7: Arrival | J7: Helsinki: Welcome to Finland | Q7: 0 | R7: 0 | S7: =+Q7*R7 -> 0 | T7: 0 | U7: =S7*(1-T7) -> 0 | V7: EUR | W7: =IFERROR(VLOOKUP(V7,Curr!$B$2:$C$13,2,FALSE),0) -> 11.2 | X7: =U7*W7 -> 0 | Y7: =Q7 -> 0 | Z7: =+Y7*R7 -> 0 | AA7: EUR | AB7: =IFERROR(VLOOKUP(AA7,Curr!$B$2:$C$13,2,FALSE),0) -> 11.2 | AC7: =+Y7*AB7*R7 -> 0 | AD7: =+AC7-X7 -> 0 | AE7: =IFERROR(AD7/AC7,0) -> 0
C8: Day 1 | D8: Transfer | J8: Helsinki: Self transfer to your accommodation | Q8: 0 | R8: 0 | S8: =+Q8*R8 -> 0 | T8: 0 | U8: =S8*(1-T8) -> 0 | V8: EUR | W8: =IFERROR(VLOOKUP(V8,Curr!$B$2:$C$13,2,FALSE),0) -> 11.2 | X8: =U8*W8 -> 0 | Y8: =Q8/0.8 -> 0 | Z8: =+Y8*R8 -> 0 | AA8: EUR | AB8: =IFERROR(VLOOKUP(AA8,Curr!$B$2:$C$13,2,FALSE),0) -> 11.2 | AC8: =+Y8*AB8*R8 -> 0 | AD8: =+AC8-X8 -> 0 | AE8: =IFERROR(AD8/AC8,0) -> 0
C9: Day 1 | D9: Hotel | J9: Helsinki: Check in to your accommodation for a 1 night stay - Centraly Located 4-star hotel - Standard Room - Breakfast included | O9: x | Q9: 150 | R9: 1 | S9: =+Q9*R9 -> 150 | T9: 0 | U9: =S9*(1-T9) -> 150 | V9: EUR | W9: =IFERROR(VLOOKUP(V9,Curr!$B$2:$C$13,2,FALSE),0) -> 11.2 | X9: =U9*W9 -> 1680 | Y9: =Q9/0.8 -> 187.5 | Z9: =+Y9*R9 -> 187.5 | AA9: EUR | AB9: =IFERROR(VLOOKUP(AA9,Curr!$B$2:$C$13,2,FALSE),0) -> 11.2 | AC9: =+Y9*AB9*R9 -> 2100 | AD9: =+AC9-X9 -> 420 | AE9: =IFERROR(AD9/AC9,0) -> 0.2
C10: Day 1 | D10: Leisure | J10: Helsinki: Spend time at leisure | Q10: 0 | R10: 0 | S10: =+Q10*R10 -> 0 | T10: 0 | U10: =S10*(1-T10) -> 0 | V10: EUR | W10: =IFERROR(VLOOKUP(V10,Curr!$B$2:$C$13,2,FALSE),0) -> 11.2 | X10: =U10*W10 -> 0 | Y10: =Q10 -> 0 | Z10: =+Y10*R10 -> 0 | AA10: EUR | AB10: =IFERROR(VLOOKUP(AA10,Curr!$B$2:$C$13,2,FALSE),0) -> 11.2 | AC10: =+Y10*AB10*R10 -> 0 | AD10: =+AC10-X10 -> 0 | AE10: =IFERROR(AD10/AC10,0) -> 0
S11: =+Q11*R11 -> 0 | T11: 0 | U11: =S11*(1-T11) -> 0 | V11: EUR | W11: =IFERROR(VLOOKUP(V11,Curr!$B$2:$C$13,2,FALSE),0) -> 11.2 | X11: =U11*W11 -> 0 | Y11: =Q11 -> 0 | Z11: =+Y11*R11 -> 0 | AA11: EUR | AB11: =IFERROR(VLOOKUP(AA11,Curr!$B$2:$C$13,2,FALSE),0) -> 11.2 | AC11: =+Y11*AB11*R11 -> 0 | AD11: =+AC11-X11 -> 0 | AE11: =IFERROR(AD11/AC11,0) -> 0
C12: Day 2 | D12: Activity | J12: Helsinki: A Finntastic Walking Tour - Time: 10:30 am / 1:30 pm - 12:45 pm / 3:45 pm - Meeting point: Senate Square (Look for a blue and white umbrella) - End point: Helsinki Central Library Oodi - Notable Sights: Senate Square, Helsinki Cathedral, Kauppatori, Uspenski Cathedral, Esplanadi Park and more - Includes: Professional authorised Helsinki Guide, Liability Insurance | O12: x | P12: https://www.finntastictours.fi/# | Q12: 20 | R12: 2 | S12: =+Q12*R12 -> 40 | T12: 0 | U12: =S12*(1-T12) -> 40 | V12: EUR | W12: =IFERROR(VLOOKUP(V12,Curr!$B$2:$C$13,2,FALSE),0) -> 11.2 | X12: =U12*W12 -> 448 | Y12: =Q12/0.57 -> 35.087719 | Z12: =+Y12*R12 -> 70.175439 | AA12: EUR | AB12: =IFERROR(VLOOKUP(AA12,Curr!$B$2:$C$13,2,FALSE),0) -> 11.2 | AC12: =+Y12*AB12*R12 -> 785.96491 | AD12: =+AC12-X12 -> 337.96491 | AE12: =IFERROR(AD12/AC12,0) -> 0.43
C13: Day 2 | D13: Transfer | J13: Helsinki: Self transfer to Helsinki Central Station | Q13: 0 | R13: 0 | S13: =+Q13*R13 -> 0 | T13: 0 | U13: =S13*(1-T13) -> 0 | V13: EUR | W13: =IFERROR(VLOOKUP(V13,Curr!$B$2:$C$13,2,FALSE),0) -> 11.2 | X13: =U13*W13 -> 0 | Y13: =Q13 -> 0 | Z13: =+Y13*R13 -> 0 | AA13: EUR | AB13: =IFERROR(VLOOKUP(AA13,Curr!$B$2:$C$13,2,FALSE),0) -> 11.2 | AC13: =+Y13*AB13*R13 -> 0 | AD13: =+AC13-X13 -> 0 | AE13: =IFERROR(AD13/AC13,0) -> 0
C14: Day 2 | D14: Train | J14: Helsinki: Overnight Santa Claus Express Train to Rovaniemi - Time: 11:13 pm - 10:59 am - Includes: Upstairs Sleeper Cabin with Private Bathroom | N14: x | P14: https://www.vr.fi/en/santa-claus-express | Q14: 200 | R14: 1 | S14: =+Q14*R14 -> 200 | T14: 0 | U14: =S14*(1-T14) -> 200 | V14: EUR | W14: =IFERROR(VLOOKUP(V14,Curr!$B$2:$C$13,2,FALSE),0) -> 11.2 | X14: =U14*W14 -> 2240 | Y14: =Q14/0.8 -> 250 | Z14: =+Y14*R14 -> 250 | AA14: EUR | AB14: =IFERROR(VLOOKUP(AA14,Curr!$B$2:$C$13,2,FALSE),0) -> 11.2 | AC14: =+Y14*AB14*R14 -> 2800 | AD14: =+AC14-X14 -> 560 | AE14: =IFERROR(AD14/AC14,0) -> 0.2
S15: =+Q15*R15 -> 0 | T15: 0 | U15: =S15*(1-T15) -> 0 | V15: EUR | W15: =IFERROR(VLOOKUP(V15,Curr!$B$2:$C$13,2,FALSE),0) -> 11.2 | X15: =U15*W15 -> 0 | Y15: =Q15 -> 0 | Z15: =+Y15*R15 -> 0 | AA15: EUR | AB15: =IFERROR(VLOOKUP(AA15,Curr!$B$2:$C$13,2,FALSE),0) -> 11.2 | AC15: =+Y15*AB15*R15 -> 0 | AD15: =+AC15-X15 -> 0 | AE15: =IFERROR(AD15/AC15,0) -> 0
C16: Day 3 | D16: Transfer | J16: Rovaniemi: Self transfer to your accommodation | Q16: 0 | R16: 0 | S16: =+Q16*R16 -> 0 | T16: 0 | U16: =S16*(1-T16) -> 0 | V16: EUR | W16: =IFERROR(VLOOKUP(V16,Curr!$B$2:$C$13,2,FALSE),0) -> 11.2 | X16: =U16*W16 -> 0 | Y16: =Q16/0.8 -> 0 | Z16: =+Y16*R16 -> 0 | AA16: EUR | AB16: =IFERROR(VLOOKUP(AA16,Curr!$B$2:$C$13,2,FALSE),0) -> 11.2 | AC16: =+Y16*AB16*R16 -> 0 | AD16: =+AC16-X16 -> 0 | AE16: =IFERROR(AD16/AC16,0) -> 0
C17: Day 3 | D17: Hotel | J17: Rovaniemi: Check in to your accommodation for a 3 night stay - Centrally Located 3/4-star Hotel - Standard Room - Breakfast included | N17: x | Q17: =109*2*3 -> 654 | R17: 1 | S17: =+Q17*R17 -> 654 | T17: 0 | U17: =S17*(1-T17) -> 654 | V17: EUR | W17: =IFERROR(VLOOKUP(V17,Curr!$B$2:$C$13,2,FALSE),0) -> 11.2 | X17: =U17*W17 -> 7324.8 | Y17: =Q17/0.8 -> 817.5 | Z17: =+Y17*R17 -> 817.5 | AA17: EUR | AB17: =IFERROR(VLOOKUP(AA17,Curr!$B$2:$C$13,2,FALSE),0) -> 11.2 | AC17: =+Y17*AB17*R17 -> 9156 | AD17: =+AC17-X17 -> 1831.2 | AE17: =IFERROR(AD17/AC17,0) -> 0.2
C18: Day 3 | D18: Leisure | J18: Rovaniemi: Spend time at leisure | Q18: 0 | R18: 0 | S18: =+Q18*R18 -> 0 | T18: 0 | U18: =S18*(1-T18) -> 0 | V18: EUR | W18: =IFERROR(VLOOKUP(V18,Curr!$B$2:$C$13,2,FALSE),0) -> 11.2 | X18: =U18*W18 -> 0 | Y18: =Q18 -> 0 | Z18: =+Y18*R18 -> 0 | AA18: EUR | AB18: =IFERROR(VLOOKUP(AA18,Curr!$B$2:$C$13,2,FALSE),0) -> 11.2 | AC18: =+Y18*AB18*R18 -> 0 | AD18: =+AC18-X18 -> 0 | AE18: =IFERROR(AD18/AC18,0) -> 0
C19: Day 3 | D19: Activity | J19: Rovaniemi: Northern Lights Unlimited Mileage Photo Tour - Time: 08:00 pm - 01:00 am - Meeting point: Book Lapland Office - Includes: Pick-up/drop-off in central Rovaniemi, Knowledgeable, English-speaking guides, Professional DSLR photography (unlimited), Meteorological observations, Thermal winter clothing, Hot drinks & snacks or cookies | O19: x | P19: https://booknordics.com/finland/western-lapland/rovaniemi/rovaniemi-northern-lights-family-tour-by-bus-with-photos | Q19: 109 | R19: 2 | S19: =+Q19*R19 -> 218 | T19: 0.2 | U19: =S19*(1-T19) -> 174.4 | V19: EUR | W19: =IFERROR(VLOOKUP(V19,Curr!$B$2:$C$13,2,FALSE),0) -> 11.2 | X19: =U19*W19 -> 1953.28 | Y19: =Q19 -> 109 | Z19: =+Y19*R19 -> 218 | AA19: EUR | AB19: =IFERROR(VLOOKUP(AA19,Curr!$B$2:$C$13,2,FALSE),0) -> 11.2 | AC19: =+Y19*AB19*R19 -> 2441.6 | AD19: =+AC19-X19 -> 488.32 | AE19: =IFERROR(AD19/AC19,0) -> 0.2
S20: =+Q20*R20 -> 0 | T20: 0 | U20: =S20*(1-T20) -> 0 | V20: EUR | W20: =IFERROR(VLOOKUP(V20,Curr!$B$2:$C$13,2,FALSE),0) -> 11.2 | X20: =U20*W20 -> 0 | Y20: =Q20 -> 0 | Z20: =+Y20*R20 -> 0 | AA20: EUR | AB20: =IFERROR(VLOOKUP(AA20,Curr!$B$2:$C$13,2,FALSE),0) -> 11.2 | AC20: =+Y20*AB20*R20 -> 0 | AD20: =+AC20-X20 -> 0 | AE20: =IFERROR(AD20/AC20,0) -> 0
C21: Day 4 | D21: Activity | J21: Rovaniemi: Arctic Circle Highlights Adventure Day - Time: 08:45 am - 2:45 pm - Meeting point: Arctic Circle Snowmobile Park office - Includes: Pick-up/drop-off in central Rovaniemi, Reindeer Farm visit with sleigh ride (2-3 pers), Reindeer sledge driver’s license reward, Alaskan Husky visit with sleigh ride (4 pers), Approx. 2 hours free time in Santa Claus Village, Winter clothes (overalls, boots and gloves), Traditional salmon soup or vegetarian option | O21: x | P21: https://booknordics.com/finland/western-lapland/rovaniemi/arctic-circle-highlights-family-day-by-minibus | Q21: 188 | R21: 2 | S21: =+Q21*R21 -> 376 | T21: 0.2 | U21: =S21*(1-T21) -> 300.8 | V21: EUR | W21: =IFERROR(VLOOKUP(V21,Curr!$B$2:$C$13,2,FALSE),0) -> 11.2 | X21: =U21*W21 -> 3368.96 | Y21: =Q21 -> 188 | Z21: =+Y21*R21 -> 376 | AA21: EUR | AB21: =IFERROR(VLOOKUP(AA21,Curr!$B$2:$C$13,2,FALSE),0) -> 11.2 | AC21: =+Y21*AB21*R21 -> 4211.2 | AD21: =+AC21-X21 -> 842.24 | AE21: =IFERROR(AD21/AC21,0) -> 0.2
C22: Day 4 | D22: Leisure | J22: Rovaniemi: Spend time at leisure | Q22: 0 | R22: 0 | S22: =+Q22*R22 -> 0 | T22: 0 | U22: =S22*(1-T22) -> 0 | V22: EUR | W22: =IFERROR(VLOOKUP(V22,Curr!$B$2:$C$13,2,FALSE),0) -> 11.2 | X22: =U22*W22 -> 0 | Y22: =Q22 -> 0 | Z22: =+Y22*R22 -> 0 | AA22: EUR | AB22: =IFERROR(VLOOKUP(AA22,Curr!$B$2:$C$13,2,FALSE),0) -> 11.2 | AC22: =+Y22*AB22*R22 -> 0 | AD22: =+AC22-X22 -> 0 | AE22: =IFERROR(AD22/AC22,0) -> 0
C23: Day 4 | D23: Activity | J23: Rovaniemi: Small-Group Aurora Hunt by Minibus - Time: 7:00 pm - 10:00 pm - Meeting point: Lapland Royal Adventures Office - Includes: Pick-up/drop-off from central Rovaniemi, Knowledgeable, English-speaking guide, Dedicated Northern Lights chase by minibus, Cozy blankets, hot drinks and a snack | O23: x | P23: https://booknordics.com/finland/western-lapland/rovaniemi/aurora-quest-by-minibus | Q23: 89 | R23: 2 | S23: =+Q23*R23 -> 178 | T23: 0.2 | U23: =S23*(1-T23) -> 142.4 | V23: EUR | W23: =IFERROR(VLOOKUP(V23,Curr!$B$2:$C$13,2,FALSE),0) -> 11.2 | X23: =U23*W23 -> 1594.88 | Y23: =Q23 -> 89 | Z23: =+Y23*R23 -> 178 | AA23: EUR | AB23: =IFERROR(VLOOKUP(AA23,Curr!$B$2:$C$13,2,FALSE),0) -> 11.2 | AC23: =+Y23*AB23*R23 -> 1993.6 | AD23: =+AC23-X23 -> 398.72 | AE23: =IFERROR(AD23/AC23,0) -> 0.2
S24: =+Q24*R24 -> 0 | T24: 0 | U24: =S24*(1-T24) -> 0 | V24: EUR | W24: =IFERROR(VLOOKUP(V24,Curr!$B$2:$C$13,2,FALSE),0) -> 11.2 | X24: =U24*W24 -> 0 | Y24: =Q24 -> 0 | Z24: =+Y24*R24 -> 0 | AA24: EUR | AB24: =IFERROR(VLOOKUP(AA24,Curr!$B$2:$C$13,2,FALSE),0) -> 11.2 | AC24: =+Y24*AB24*R24 -> 0 | AD24: =+AC24-X24 -> 0 | AE24: =IFERROR(AD24/AC24,0) -> 0
C25: Day 5 | D25: Activity | J25: Rovaniemi: Arctic Wildlife Adventure to Ranua Park - Time: 10:00 am - 4:00 pm - Meeting point: Lapland Royal Adventures office - Includes: Pick-up/drop-off in central Rovaniemi, Tickets to Ranua Wildlife Park, Drinks and BBQ sausages by fire | O25: x | P25: https://booknordics.com/finland/western-lapland/rovaniemi/arctic-wildlife-adventure-ranua-wildlife-park-trip | Q25: 109 | R25: 2 | S25: =+Q25*R25 -> 218 | T25: 0.2 | U25: =S25*(1-T25) -> 174.4 | V25: EUR | W25: =IFERROR(VLOOKUP(V25,Curr!$B$2:$C$13,2,FALSE),0) -> 11.2 | X25: =U25*W25 -> 1953.28 | Y25: =Q25 -> 109 | Z25: =+Y25*R25 -> 218 | AA25: EUR | AB25: =IFERROR(VLOOKUP(AA25,Curr!$B$2:$C$13,2,FALSE),0) -> 11.2 | AC25: =+Y25*AB25*R25 -> 2441.6 | AD25: =+AC25-X25 -> 488.32 | AE25: =IFERROR(AD25/AC25,0) -> 0.2
C26: Day 5 | D26: Leisure | J26: Rovaniemi: Spend time at leisure | Q26: 0 | R26: 0 | S26: =+Q26*R26 -> 0 | T26: 0 | U26: =S26*(1-T26) -> 0 | V26: EUR | W26: =IFERROR(VLOOKUP(V26,Curr!$B$2:$C$13,2,FALSE),0) -> 11.2 | X26: =U26*W26 -> 0 | Y26: =Q26 -> 0 | Z26: =+Y26*R26 -> 0 | AA26: EUR | AB26: =IFERROR(VLOOKUP(AA26,Curr!$B$2:$C$13,2,FALSE),0) -> 11.2 | AC26: =+Y26*AB26*R26 -> 0 | AD26: =+AC26-X26 -> 0 | AE26: =IFERROR(AD26/AC26,0) -> 0
S27: =+Q27*R27 -> 0 | T27: 0 | U27: =S27*(1-T27) -> 0 | V27: EUR | W27: =IFERROR(VLOOKUP(V27,Curr!$B$2:$C$13,2,FALSE),0) -> 11.2 | X27: =U27*W27 -> 0 | Y27: =Q27 -> 0 | Z27: =+Y27*R27 -> 0 | AA27: EUR | AB27: =IFERROR(VLOOKUP(AA27,Curr!$B$2:$C$13,2,FALSE),0) -> 11.2 | AC27: =+Y27*AB27*R27 -> 0 | AD27: =+AC27-X27 -> 0 | AE27: =IFERROR(AD27/AC27,0) -> 0
C28: Day 6 | D28: Transfer | J28: Rovaniemi: Self transfer to Rovaniemi Bus Station | Q28: 0 | R28: 0 | S28: =+Q28*R28 -> 0 | T28: 0 | U28: =S28*(1-T28) -> 0 | V28: EUR | W28: =IFERROR(VLOOKUP(V28,Curr!$B$2:$C$13,2,FALSE),0) -> 11.2 | X28: =U28*W28 -> 0 | Y28: =Q28 -> 0 | Z28: =+Y28*R28 -> 0 | AA28: EUR | AB28: =IFERROR(VLOOKUP(AA28,Curr!$B$2:$C$13,2,FALSE),0) -> 11.2 | AC28: =+Y28*AB28*R28 -> 0 | AD28: =+AC28-X28 -> 0 | AE28: =IFERROR(AD28/AC28,0) -> 0
C29: Day 6 | D29: Coach | J29: Rovaniemi: Panorama Coach Transfer to Saariselkä - Time: 11:45 am - 3:30 pm - Includes: tickets | N29: x | P29: https://www.matkahuolto.fi/en | Q29: 50 | R29: 2 | S29: =+Q29*R29 -> 100 | T29: 0 | U29: =S29*(1-T29) -> 100 | V29: EUR | W29: =IFERROR(VLOOKUP(V29,Curr!$B$2:$C$13,2,FALSE),0) -> 11.2 | X29: =U29*W29 -> 1120 | Y29: =Q29/0.8 -> 62.5 | Z29: =+Y29*R29 -> 125 | AA29: EUR | AB29: =IFERROR(VLOOKUP(AA29,Curr!$B$2:$C$13,2,FALSE),0) -> 11.2 | AC29: =+Y29*AB29*R29 -> 1400 | AD29: =+AC29-X29 -> 280 | AE29: =IFERROR(AD29/AC29,0) -> 0.2
C30: Day 6 | D30: Transfer | J30: Saariselkä: Self transfer to Saariselkä Northern Lights Village | Q30: 0 | R30: 0 | S30: =+Q30*R30 -> 0 | T30: 0 | U30: =S30*(1-T30) -> 0 | V30: EUR | W30: =IFERROR(VLOOKUP(V30,Curr!$B$2:$C$13,2,FALSE),0) -> 11.2 | X30: =U30*W30 -> 0 | Y30: =Q30 -> 0 | Z30: =+Y30*R30 -> 0 | AA30: EUR | AB30: =IFERROR(VLOOKUP(AA30,Curr!$B$2:$C$13,2,FALSE),0) -> 11.2 | AC30: =+Y30*AB30*R30 -> 0 | AD30: =+AC30-X30 -> 0 | AE30: =IFERROR(AD30/AC30,0) -> 0
C31: Day 6 | D31: Hotel | J31: Saariselkä: Check in to your accommodation for a 1 night stay - Saariselkä Northern Lights Village - Aurora Cabin - breakfast included | N31: x | Q31: 517 | R31: 1 | S31: =+Q31*R31 -> 517 | T31: 0 | U31: =S31*(1-T31) -> 517 | V31: EUR | W31: =IFERROR(VLOOKUP(V31,Curr!$B$2:$C$13,2,FALSE),0) -> 11.2 | X31: =U31*W31 -> 5790.4 | Y31: =Q31/0.8 -> 646.25 | Z31: =+Y31*R31 -> 646.25 | AA31: EUR | AB31: =IFERROR(VLOOKUP(AA31,Curr!$B$2:$C$13,2,FALSE),0) -> 11.2 | AC31: =+Y31*AB31*R31 -> 7238 | AD31: =+AC31-X31 -> 1447.6 | AE31: =IFERROR(AD31/AC31,0) -> 0.2
C32: Day 6 | D32: Leisure | J32: Saariselkä: Spend time at leisure | Q32: 0 | R32: 0 | S32: =+Q32*R32 -> 0 | T32: 0 | U32: =S32*(1-T32) -> 0 | V32: EUR | W32: =IFERROR(VLOOKUP(V32,Curr!$B$2:$C$13,2,FALSE),0) -> 11.2 | X32: =U32*W32 -> 0 | Y32: =Q32 -> 0 | Z32: =+Y32*R32 -> 0 | AA32: EUR | AB32: =IFERROR(VLOOKUP(AA32,Curr!$B$2:$C$13,2,FALSE),0) -> 11.2 | AC32: =+Y32*AB32*R32 -> 0 | AD32: =+AC32-X32 -> 0 | AE32: =IFERROR(AD32/AC32,0) -> 0
S33: =+Q33*R33 -> 0 | T33: 0 | U33: =S33*(1-T33) -> 0 | V33: EUR | W33: =IFERROR(VLOOKUP(V33,Curr!$B$2:$C$13,2,FALSE),0) -> 11.2 | X33: =U33*W33 -> 0 | Y33: =Q33 -> 0 | Z33: =+Y33*R33 -> 0 | AA33: EUR | AB33: =IFERROR(VLOOKUP(AA33,Curr!$B$2:$C$13,2,FALSE),0) -> 11.2 | AC33: =+Y33*AB33*R33 -> 0 | AD33: =+AC33-X33 -> 0 | AE33: =IFERROR(AD33/AC33,0) -> 0
C34: Day 7 | D34: Transfer | J34: Saariselkä: Self transfer to Ivalo Airport | Q34: 0 | R34: 0 | S34: =+Q34*R34 -> 0 | T34: 0 | U34: =S34*(1-T34) -> 0 | V34: EUR | W34: =IFERROR(VLOOKUP(V34,Curr!$B$2:$C$13,2,FALSE),0) -> 11.2 | X34: =U34*W34 -> 0 | Y34: =Q34/0.8 -> 0 | Z34: =+Y34*R34 -> 0 | AA34: EUR | AB34: =IFERROR(VLOOKUP(AA34,Curr!$B$2:$C$13,2,FALSE),0) -> 11.2 | AC34: =+Y34*AB34*R34 -> 0 | AD34: =+AC34-X34 -> 0 | AE34: =IFERROR(AD34/AC34,0) -> 0
C35: Day 7 | D35: Departure | J35: Ivalo: Departure home | Q35: 0 | R35: 0 | S35: =+Q35*R35 -> 0 | T35: 0 | U35: =S35*(1-T35) -> 0 | V35: EUR | W35: =IFERROR(VLOOKUP(V35,Curr!$B$2:$C$13,2,FALSE),0) -> 11.2 | X35: =U35*W35 -> 0 | Y35: =Q35 -> 0 | Z35: =+Y35*R35 -> 0 | AA35: EUR | AB35: =IFERROR(VLOOKUP(AA35,Curr!$B$2:$C$13,2,FALSE),0) -> 11.2 | AC35: =+Y35*AB35*R35 -> 0 | AD35: =+AC35-X35 -> 0 | AE35: =IFERROR(AD35/AC35,0) -> 0
S36: =+Q36*R36 -> 0 | T36: 0 | U36: =S36*(1-T36) -> 0 | V36: EUR | W36: =IFERROR(VLOOKUP(V36,Curr!$B$2:$C$13,2,FALSE),0) -> 11.2 | X36: =U36*W36 -> 0 | Y36: =Q36 -> 0 | Z36: =+Y36*R36 -> 0 | AA36: EUR | AB36: =IFERROR(VLOOKUP(AA36,Curr!$B$2:$C$13,2,FALSE),0) -> 11.2 | AC36: =+Y36*AB36*R36 -> 0 | AD36: =+AC36-X36 -> 0 | AE36: =IFERROR(AD36/AC36,0) -> 0
S37: =+Q37*R37 -> 0 | T37: 0 | U37: =S37*(1-T37) -> 0 | V37: EUR | W37: =IFERROR(VLOOKUP(V37,Curr!$B$2:$C$13,2,FALSE),0) -> 11.2 | X37: =U37*W37 -> 0 | Y37: =Q37 -> 0 | Z37: =+Y37*R37 -> 0 | AA37: EUR | AB37: =IFERROR(VLOOKUP(AA37,Curr!$B$2:$C$13,2,FALSE),0) -> 11.2 | AC37: =+Y37*AB37*R37 -> 0 | AD37: =+AC37-X37 -> 0 | AE37: =IFERROR(AD37/AC37,0) -> 0
C38: Day 1 | D38: Transfer Package | J38: Helsinki: Private transfer to your accommodation | O38: x | Q38: 80 | R38: 0 | S38: =+Q38*R38 -> 0 | T38: 0 | U38: =S38*(1-T38) -> 0 | V38: EUR | W38: =IFERROR(VLOOKUP(V38,Curr!$B$2:$C$13,2,FALSE),0) -> 11.2 | X38: =U38*W38 -> 0 | Y38: =Q38/0.8 -> 100 | Z38: =+Y38*R38 -> 0 | AA38: EUR | AB38: =IFERROR(VLOOKUP(AA38,Curr!$B$2:$C$13,2,FALSE),0) -> 11.2 | AC38: =+Y38*AB38*R38 -> 0 | AD38: =+AC38-X38 -> 0 | AE38: =IFERROR(AD38/AC38,0) -> 0
C39: Day 2 | D39: Transfer Package | J39: Helsinki: Private transfer to Helsinki Central Station | O39: x | Q39: 60 | R39: 0 | S39: =+Q39*R39 -> 0 | T39: 0 | U39: =S39*(1-T39) -> 0 | V39: EUR | W39: =IFERROR(VLOOKUP(V39,Curr!$B$2:$C$13,2,FALSE),0) -> 11.2 | X39: =U39*W39 -> 0 | Y39: =Q39/0.75 -> 80 | Z39: =+Y39*R39 -> 0 | AA39: EUR | AB39: =IFERROR(VLOOKUP(AA39,Curr!$B$2:$C$13,2,FALSE),0) -> 11.2 | AC39: =+Y39*AB39*R39 -> 0 | AD39: =+AC39-X39 -> 0 | AE39: =IFERROR(AD39/AC39,0) -> 0
C40: Day 3 | D40: Transfer Package | J40: Rovaniemi: Private transfer to your accommodation | O40: x | Q40: 40 | R40: 0 | S40: =+Q40*R40 -> 0 | T40: 0 | U40: =S40*(1-T40) -> 0 | V40: EUR | W40: =IFERROR(VLOOKUP(V40,Curr!$B$2:$C$13,2,FALSE),0) -> 11.2 | X40: =U40*W40 -> 0 | Y40: =Q40/0.665 -> 60.150376 | Z40: =+Y40*R40 -> 0 | AA40: EUR | AB40: =IFERROR(VLOOKUP(AA40,Curr!$B$2:$C$13,2,FALSE),0) -> 11.2 | AC40: =+Y40*AB40*R40 -> 0 | AD40: =+AC40-X40 -> 0 | AE40: =IFERROR(AD40/AC40,0) -> 0
C41: Day 6 | D41: Transfer Package | J41: Rovaniemi: Private transfer to Rovaniemi Bus Station | O41: x | Q41: 40 | R41: 0 | S41: =+Q41*R41 -> 0 | T41: 0 | U41: =S41*(1-T41) -> 0 | V41: EUR | W41: =IFERROR(VLOOKUP(V41,Curr!$B$2:$C$13,2,FALSE),0) -> 11.2 | X41: =U41*W41 -> 0 | Y41: =Q41/0.665 -> 60.150376 | Z41: =+Y41*R41 -> 0 | AA41: EUR | AB41: =IFERROR(VLOOKUP(AA41,Curr!$B$2:$C$13,2,FALSE),0) -> 11.2 | AC41: =+Y41*AB41*R41 -> 0 | AD41: =+AC41-X41 -> 0 | AE41: =IFERROR(AD41/AC41,0) -> 0
C42: Day 6 | D42: Transfer Package | J42: Saariselkä: Private transfer to Saariselkä Northern Lights Village | P42: https://www.arctictours.fi/saariselkataxi | Q42: 35 | R42: 0 | S42: =+Q42*R42 -> 0 | T42: 0 | U42: =S42*(1-T42) -> 0 | V42: EUR | W42: =IFERROR(VLOOKUP(V42,Curr!$B$2:$C$13,2,FALSE),0) -> 11.2 | X42: =U42*W42 -> 0 | Y42: =Q42/0.785 -> 44.585987 | Z42: =+Y42*R42 -> 0 | AA42: EUR | AB42: =IFERROR(VLOOKUP(AA42,Curr!$B$2:$C$13,2,FALSE),0) -> 11.2 | AC42: =+Y42*AB42*R42 -> 0 | AD42: =+AC42-X42 -> 0 | AE42: =IFERROR(AD42/AC42,0) -> 0
...

Sheet 103
B2: Places: Helsinki - Santa Express - Kemi - Rovaniemi
B3: Pax: 2
B4: Rooming: Double
B6: ID | C6: Day | D6: Type | E6: From date | F6: To date | G6: From time | H6: To time | I6: Supplier | J6: Travel element | K6: Manual booking? | L6: Status | M6: Comments | N6: Non-refundable | O6: Refundable | P6: URL | Q6: Gross P per unit | R6: Units | S6: Gross P | T6: Supp Comm | U6: Net P | V6: Supp curr | W6: X-rate | X6: Net P NOK | Y6: Sales P per unit | Z6: Price | AA6: Sales curr | AB6: X-rate | AC6: Sales P NOK tot | AD6: GP NOK | AE6: GP % | AF6: VAT25 | AG6: VAT15 | AH6: VAT12 | AI6: VAT0-D | AJ6: VAT0-I
C7: Day 1 | D7: Arrival | J7: Helsinki: Welcome to Finland | Q7: 0 | R7: 0 | S7: =+Q7*R7 -> 0 | T7: 0 | U7: =S7*(1-T7) -> 0 | V7: EUR | W7: =IFERROR(VLOOKUP(V7,Curr!$B$2:$C$13,2,FALSE),0) -> 11.2 | X7: =U7*W7 -> 0 | Y7: =Q7 -> 0 | Z7: =+Y7*R7 -> 0 | AA7: EUR | AB7: =IFERROR(VLOOKUP(AA7,Curr!$B$2:$C$13,2,FALSE),0) -> 11.2 | AC7: =+Y7*AB7*R7 -> 0 | AD7: =+AC7-X7 -> 0 | AE7: =IFERROR(AD7/AC7,0) -> 0
C8: Day 1 | D8: Transfer | J8: Helsinki: Self transfer to your accommodation | Q8: 0 | R8: 0 | S8: =+Q8*R8 -> 0 | T8: 0 | U8: =S8*(1-T8) -> 0 | V8: EUR | W8: =IFERROR(VLOOKUP(V8,Curr!$B$2:$C$13,2,FALSE),0) -> 11.2 | X8: =U8*W8 -> 0 | Y8: =Q8/0.8 -> 0 | Z8: =+Y8*R8 -> 0 | AA8: EUR | AB8: =IFERROR(VLOOKUP(AA8,Curr!$B$2:$C$13,2,FALSE),0) -> 11.2 | AC8: =+Y8*AB8*R8 -> 0 | AD8: =+AC8-X8 -> 0 | AE8: =IFERROR(AD8/AC8,0) -> 0
C9: Day 1 | D9: Hotel | J9: Helsinki: Check in to your accommodation for a 1 night stay - Centraly Located 4-star hotel - Standard Room - Breakfast included | O9: x | Q9: 150 | R9: 1 | S9: =+Q9*R9 -> 150 | T9: 0 | U9: =S9*(1-T9) -> 150 | V9: EUR | W9: =IFERROR(VLOOKUP(V9,Curr!$B$2:$C$13,2,FALSE),0) -> 11.2 | X9: =U9*W9 -> 1680 | Y9: =Q9/0.8 -> 187.5 | Z9: =+Y9*R9 -> 187.5 | AA9: EUR | AB9: =IFERROR(VLOOKUP(AA9,Curr!$B$2:$C$13,2,FALSE),0) -> 11.2 | AC9: =+Y9*AB9*R9 -> 2100 | AD9: =+AC9-X9 -> 420 | AE9: =IFERROR(AD9/AC9,0) -> 0.2
C10: Day 1 | D10: Leisure | J10: Helsinki: Spend time at leisure | Q10: 0 | R10: 0 | S10: =+Q10*R10 -> 0 | T10: 0 | U10: =S10*(1-T10) -> 0 | V10: EUR | W10: =IFERROR(VLOOKUP(V10,Curr!$B$2:$C$13,2,FALSE),0) -> 11.2 | X10: =U10*W10 -> 0 | Y10: =Q10 -> 0 | Z10: =+Y10*R10 -> 0 | AA10: EUR | AB10: =IFERROR(VLOOKUP(AA10,Curr!$B$2:$C$13,2,FALSE),0) -> 11.2 | AC10: =+Y10*AB10*R10 -> 0 | AD10: =+AC10-X10 -> 0 | AE10: =IFERROR(AD10/AC10,0) -> 0
S11: =+Q11*R11 -> 0 | T11: 0 | U11: =S11*(1-T11) -> 0 | V11: EUR | W11: =IFERROR(VLOOKUP(V11,Curr!$B$2:$C$13,2,FALSE),0) -> 11.2 | X11: =U11*W11 -> 0 | Y11: =Q11 -> 0 | Z11: =+Y11*R11 -> 0 | AA11: EUR | AB11: =IFERROR(VLOOKUP(AA11,Curr!$B$2:$C$13,2,FALSE),0) -> 11.2 | AC11: =+Y11*AB11*R11 -> 0 | AD11: =+AC11-X11 -> 0 | AE11: =IFERROR(AD11/AC11,0) -> 0
C12: Day 2 | D12: Activity | J12: Helsinki: A Finntastic Walking Tour - Time: 10:30 am / 1:30 pm - 12:45 pm / 3:45 pm - Meeting point: Senate Square (Look for a blue and white umbrella) - End point: Helsinki Central Library Oodi - Notable Sights: Senate Square, Helsinki Cathedral, Kauppatori, Uspenski Cathedral, Esplanadi Park and more - Includes: Professional authorised Helsinki Guide, Liability Insurance | O12: x | P12: https://www.finntastictours.fi/# | Q12: 20 | R12: 2 | S12: =+Q12*R12 -> 40 | T12: 0 | U12: =S12*(1-T12) -> 40 | V12: EUR | W12: =IFERROR(VLOOKUP(V12,Curr!$B$2:$C$13,2,FALSE),0) -> 11.2 | X12: =U12*W12 -> 448 | Y12: =Q12/0.57 -> 35.087719 | Z12: =+Y12*R12 -> 70.175439 | AA12: EUR | AB12: =IFERROR(VLOOKUP(AA12,Curr!$B$2:$C$13,2,FALSE),0) -> 11.2 | AC12: =+Y12*AB12*R12 -> 785.96491 | AD12: =+AC12-X12 -> 337.96491 | AE12: =IFERROR(AD12/AC12,0) -> 0.43
C13: Day 2 | D13: Transfer | J13: Helsinki: Self transfer to Helsinki Central Station | Q13: 0 | R13: 0 | S13: =+Q13*R13 -> 0 | T13: 0 | U13: =S13*(1-T13) -> 0 | V13: EUR | W13: =IFERROR(VLOOKUP(V13,Curr!$B$2:$C$13,2,FALSE),0) -> 11.2 | X13: =U13*W13 -> 0 | Y13: =Q13 -> 0 | Z13: =+Y13*R13 -> 0 | AA13: EUR | AB13: =IFERROR(VLOOKUP(AA13,Curr!$B$2:$C$13,2,FALSE),0) -> 11.2 | AC13: =+Y13*AB13*R13 -> 0 | AD13: =+AC13-X13 -> 0 | AE13: =IFERROR(AD13/AC13,0) -> 0
C14: Day 2 | D14: Train | J14: Helsinki: Overnight Santa Claus Express Train to Kemi - Time: 11:13 pm - 09:32 am - Includes: Upstairs Sleeper Cabin with Private Bathroom | N14: x | P14: https://www.vr.fi/en/santa-claus-express | Q14: 200 | R14: 1 | S14: =+Q14*R14 -> 200 | T14: 0 | U14: =S14*(1-T14) -> 200 | V14: EUR | W14: =IFERROR(VLOOKUP(V14,Curr!$B$2:$C$13,2,FALSE),0) -> 11.2 | X14: =U14*W14 -> 2240 | Y14: =Q14/0.8 -> 250 | Z14: =+Y14*R14 -> 250 | AA14: EUR | AB14: =IFERROR(VLOOKUP(AA14,Curr!$B$2:$C$13,2,FALSE),0) -> 11.2 | AC14: =+Y14*AB14*R14 -> 2800 | AD14: =+AC14-X14 -> 560 | AE14: =IFERROR(AD14/AC14,0) -> 0.2
S15: =+Q15*R15 -> 0 | T15: 0 | U15: =S15*(1-T15) -> 0 | V15: EUR | W15: =IFERROR(VLOOKUP(V15,Curr!$B$2:$C$13,2,FALSE),0) -> 11.2 | X15: =U15*W15 -> 0 | Y15: =Q15 -> 0 | Z15: =+Y15*R15 -> 0 | AA15: EUR | AB15: =IFERROR(VLOOKUP(AA15,Curr!$B$2:$C$13,2,FALSE),0) -> 11.2 | AC15: =+Y15*AB15*R15 -> 0 | AD15: =+AC15-X15 -> 0 | AE15: =IFERROR(AD15/AC15,0) -> 0
C16: Day 3 | D16: Transfer | J16: Kemi: Self transfer to your accommodation | Q16: 0 | R16: 0 | S16: =+Q16*R16 -> 0 | T16: 0 | U16: =S16*(1-T16) -> 0 | V16: EUR | W16: =IFERROR(VLOOKUP(V16,Curr!$B$2:$C$13,2,FALSE),0) -> 11.2 | X16: =U16*W16 -> 0 | Y16: =Q16 -> 0 | Z16: =+Y16*R16 -> 0 | AA16: EUR | AB16: =IFERROR(VLOOKUP(AA16,Curr!$B$2:$C$13,2,FALSE),0) -> 11.2 | AC16: =+Y16*AB16*R16 -> 0 | AD16: =+AC16-X16 -> 0 | AE16: =IFERROR(AD16/AC16,0) -> 0
C17: Day 3 | D17: Hotel | J17: Kemi: Check in to your accommodation for a 1 night stay - Kemi Seaside Villas - Superior Villa - breakfast included | N17: x | Q17: 319 | R17: 1 | S17: =+Q17*R17 -> 319 | T17: 0 | U17: =S17*(1-T17) -> 319 | V17: EUR | W17: =IFERROR(VLOOKUP(V17,Curr!$B$2:$C$13,2,FALSE),0) -> 11.2 | X17: =U17*W17 -> 3572.8 | Y17: =Q17/0.8 -> 398.75 | Z17: =+Y17*R17 -> 398.75 | AA17: EUR | AB17: =IFERROR(VLOOKUP(AA17,Curr!$B$2:$C$13,2,FALSE),0) -> 11.2 | AC17: =+Y17*AB17*R17 -> 4466 | AD17: =+AC17-X17 -> 893.2 | AE17: =IFERROR(AD17/AC17,0) -> 0.2
C18: Day 3 | D18: Activity | J18: Kemi: Snowcastle Area - Entrance fee package - Time: Flexible - Meeting point: Kemi Snowcastle - Includes: entrance fees to exhibitions in SnowCastle area such as Gemstone gallery and SnowExperience365 | O18: x | Q18: 20 | R18: 2 | S18: =+Q18*R18 -> 40 | T18: 0 | U18: =S18*(1-T18) -> 40 | V18: EUR | W18: =IFERROR(VLOOKUP(V18,Curr!$B$2:$C$13,2,FALSE),0) -> 11.2 | X18: =U18*W18 -> 448 | Y18: =Q18/0.67 -> 29.850746 | Z18: =+Y18*R18 -> 59.701493 | AA18: EUR | AB18: =IFERROR(VLOOKUP(AA18,Curr!$B$2:$C$13,2,FALSE),0) -> 11.2 | AC18: =+Y18*AB18*R18 -> 668.65672 | AD18: =+AC18-X18 -> 220.65672 | AE18: =IFERROR(AD18/AC18,0) -> 0.33
C19: Day 3 | D19: Leisure | J19: Kemi: Spend time at leisure | Q19: 0 | R19: 0 | S19: =+Q19*R19 -> 0 | T19: 0 | U19: =S19*(1-T19) -> 0 | V19: EUR | W19: =IFERROR(VLOOKUP(V19,Curr!$B$2:$C$13,2,FALSE),0) -> 11.2 | X19: =U19*W19 -> 0 | Y19: =Q19 -> 0 | Z19: =+Y19*R19 -> 0 | AA19: EUR | AB19: =IFERROR(VLOOKUP(AA19,Curr!$B$2:$C$13,2,FALSE),0) -> 11.2 | AC19: =+Y19*AB19*R19 -> 0 | AD19: =+AC19-X19 -> 0 | AE19: =IFERROR(AD19/AC19,0) -> 0
S20: =+Q20*R20 -> 0 | T20: 0 | U20: =S20*(1-T20) -> 0 | V20: EUR | W20: =IFERROR(VLOOKUP(V20,Curr!$B$2:$C$13,2,FALSE),0) -> 11.2 | X20: =U20*W20 -> 0 | Y20: =Q20 -> 0 | Z20: =+Y20*R20 -> 0 | AA20: EUR | AB20: =IFERROR(VLOOKUP(AA20,Curr!$B$2:$C$13,2,FALSE),0) -> 11.2 | AC20: =+Y20*AB20*R20 -> 0 | AD20: =+AC20-X20 -> 0 | AE20: =IFERROR(AD20/AC20,0) -> 0
C21: Day 4 | D21: Transfer | J21: Kemi: Self transfer to Kemi Train Station | Q21: 0 | R21: 0 | S21: =+Q21*R21 -> 0 | T21: 0 | U21: =S21*(1-T21) -> 0 | V21: EUR | W21: =IFERROR(VLOOKUP(V21,Curr!$B$2:$C$13,2,FALSE),0) -> 11.2 | X21: =U21*W21 -> 0 | Y21: =Q21 -> 0 | Z21: =+Y21*R21 -> 0 | AA21: EUR | AB21: =IFERROR(VLOOKUP(AA21,Curr!$B$2:$C$13,2,FALSE),0) -> 11.2 | AC21: =+Y21*AB21*R21 -> 0 | AD21: =+AC21-X21 -> 0 | AE21: =IFERROR(AD21/AC21,0) -> 0
C22: Day 4 | D22: Train | J22: Kemi: Santa Claus Express Train to Rovaniemi - Time: 1:36 pm - 2:41 pm - Includes: Eko Class Ticket | N22: x | P22: https://www.vr.fi/en/santa-claus-express | Q22: 37 | R22: 1 | S22: =+Q22*R22 -> 37 | T22: 0 | U22: =S22*(1-T22) -> 37 | V22: EUR | W22: =IFERROR(VLOOKUP(V22,Curr!$B$2:$C$13,2,FALSE),0) -> 11.2 | X22: =U22*W22 -> 414.4 | Y22: =Q22/0.79 -> 46.835443 | Z22: =+Y22*R22 -> 46.835443 | AA22: EUR | AB22: =IFERROR(VLOOKUP(AA22,Curr!$B$2:$C$13,2,FALSE),0) -> 11.2 | AC22: =+Y22*AB22*R22 -> 524.55696 | AD22: =+AC22-X22 -> 110.15696 | AE22: =IFERROR(AD22/AC22,0) -> 0.21
C23: Day 4 | D23: Transfer | J23: Rovaniemi: Self transfer to your accommodation | Q23: 0 | R23: 0 | S23: =+Q23*R23 -> 0 | T23: 0 | U23: =S23*(1-T23) -> 0 | V23: EUR | W23: =IFERROR(VLOOKUP(V23,Curr!$B$2:$C$13,2,FALSE),0) -> 11.2 | X23: =U23*W23 -> 0 | Y23: =Q23/0.8 -> 0 | Z23: =+Y23*R23 -> 0 | AA23: EUR | AB23: =IFERROR(VLOOKUP(AA23,Curr!$B$2:$C$13,2,FALSE),0) -> 11.2 | AC23: =+Y23*AB23*R23 -> 0 | AD23: =+AC23-X23 -> 0 | AE23: =IFERROR(AD23/AC23,0) -> 0
C24: Day 4 | D24: Hotel | J24: Rovaniemi: Check in to your accommodation for a 3 night stay - Centrally Located 3/4-star Hotel - Standard Room - Breakfast included | N24: x | Q24: =109*2*3 -> 654 | R24: 1 | S24: =+Q24*R24 -> 654 | T24: 0 | U24: =S24*(1-T24) -> 654 | V24: EUR | W24: =IFERROR(VLOOKUP(V24,Curr!$B$2:$C$13,2,FALSE),0) -> 11.2 | X24: =U24*W24 -> 7324.8 | Y24: =Q24/0.8 -> 817.5 | Z24: =+Y24*R24 -> 817.5 | AA24: EUR | AB24: =IFERROR(VLOOKUP(AA24,Curr!$B$2:$C$13,2,FALSE),0) -> 11.2 | AC24: =+Y24*AB24*R24 -> 9156 | AD24: =+AC24-X24 -> 1831.2 | AE24: =IFERROR(AD24/AC24,0) -> 0.2
C25: Day 4 | D25: Leisure | J25: Rovaniemi: Spend time at leisure | Q25: 0 | R25: 0 | S25: =+Q25*R25 -> 0 | T25: 0 | U25: =S25*(1-T25) -> 0 | V25: EUR | W25: =IFERROR(VLOOKUP(V25,Curr!$B$2:$C$13,2,FALSE),0) -> 11.2 | X25: =U25*W25 -> 0 | Y25: =Q25 -> 0 | Z25: =+Y25*R25 -> 0 | AA25: EUR | AB25: =IFERROR(VLOOKUP(AA25,Curr!$B$2:$C$13,2,FALSE),0) -> 11.2 | AC25: =+Y25*AB25*R25 -> 0 | AD25: =+AC25-X25 -> 0 | AE25: =IFERROR(AD25/AC25,0) -> 0
C26: Day 4 | D26: Activity | J26: Rovaniemi: Northern Lights Unlimited Mileage Photo Tour - Time: 08:00 pm - 01:00 am - Meeting point: Book Lapland Office - Includes: Pick-up/drop-off in central Rovaniemi, Knowledgeable, English-speaking guides, Professional DSLR photography (unlimited), Meteorological observations, Thermal winter clothing, Hot drinks & snacks or cookies | O26: x | P26: https://booknordics.com/finland/western-lapland/rovaniemi/rovaniemi-northern-lights-family-tour-by-bus-with-photos | Q26: 109 | R26: 2 | S26: =+Q26*R26 -> 218 | T26: 0.2 | U26: =S26*(1-T26) -> 174.4 | V26: EUR | W26: =IFERROR(VLOOKUP(V26,Curr!$B$2:$C$13,2,FALSE),0) -> 11.2 | X26: =U26*W26 -> 1953.28 | Y26: =Q26 -> 109 | Z26: =+Y26*R26 -> 218 | AA26: EUR | AB26: =IFERROR(VLOOKUP(AA26,Curr!$B$2:$C$13,2,FALSE),0) -> 11.2 | AC26: =+Y26*AB26*R26 -> 2441.6 | AD26: =+AC26-X26 -> 488.32 | AE26: =IFERROR(AD26/AC26,0) -> 0.2
S27: =+Q27*R27 -> 0 | T27: 0 | U27: =S27*(1-T27) -> 0 | V27: EUR | W27: =IFERROR(VLOOKUP(V27,Curr!$B$2:$C$13,2,FALSE),0) -> 11.2 | X27: =U27*W27 -> 0 | Y27: =Q27 -> 0 | Z27: =+Y27*R27 -> 0 | AA27: EUR | AB27: =IFERROR(VLOOKUP(AA27,Curr!$B$2:$C$13,2,FALSE),0) -> 11.2 | AC27: =+Y27*AB27*R27 -> 0 | AD27: =+AC27-X27 -> 0 | AE27: =IFERROR(AD27/AC27,0) -> 0
C28: Day 5 | D28: Activity | J28: Rovaniemi: Arctic Circle Highlights Adventure Day - Time: 08:45 am - 2:45 pm - Meeting point: Arctic Circle Snowmobile Park office - Includes: Pick-up/drop-off in central Rovaniemi, Reindeer Farm visit with sleigh ride (2-3 pers), Reindeer sledge driver’s license reward, Alaskan Husky visit with sleigh ride (4 pers), Approx. 2 hours free time in Santa Claus Village, Winter clothes (overalls, boots and gloves), Traditional salmon soup or vegetarian option | O28: x | P28: https://booknordics.com/finland/western-lapland/rovaniemi/arctic-circle-highlights-family-day-by-minibus | Q28: 188 | R28: 2 | S28: =+Q28*R28 -> 376 | T28: 0.2 | U28: =S28*(1-T28) -> 300.8 | V28: EUR | W28: =IFERROR(VLOOKUP(V28,Curr!$B$2:$C$13,2,FALSE),0) -> 11.2 | X28: =U28*W28 -> 3368.96 | Y28: =Q28 -> 188 | Z28: =+Y28*R28 -> 376 | AA28: EUR | AB28: =IFERROR(VLOOKUP(AA28,Curr!$B$2:$C$13,2,FALSE),0) -> 11.2 | AC28: =+Y28*AB28*R28 -> 4211.2 | AD28: =+AC28-X28 -> 842.24 | AE28: =IFERROR(AD28/AC28,0) -> 0.2
C29: Day 5 | D29: Leisure | J29: Rovaniemi: Spend time at leisure | Q29: 0 | R29: 0 | S29: =+Q29*R29 -> 0 | T29: 0 | U29: =S29*(1-T29) -> 0 | V29: EUR | W29: =IFERROR(VLOOKUP(V29,Curr!$B$2:$C$13,2,FALSE),0) -> 11.2 | X29: =U29*W29 -> 0 | Y29: =Q29 -> 0 | Z29: =+Y29*R29 -> 0 | AA29: EUR | AB29: =IFERROR(VLOOKUP(AA29,Curr!$B$2:$C$13,2,FALSE),0) -> 11.2 | AC29: =+Y29*AB29*R29 -> 0 | AD29: =+AC29-X29 -> 0 | AE29: =IFERROR(AD29/AC29,0) -> 0
C30: Day 5 | D30: Activity | J30: Rovaniemi: Small-Group Aurora Hunt by Minibus - Time: 7:00 pm - 10:00 pm - Meeting point: Lapland Royal Adventures Office - Includes: Pick-up/drop-off from central Rovaniemi, Knowledgeable, English-speaking guide, Dedicated Northern Lights chase by minibus, Cozy blankets, hot drinks and a snack | O30: x | P30: https://booknordics.com/finland/western-lapland/rovaniemi/aurora-quest-by-minibus | Q30: 89 | R30: 2 | S30: =+Q30*R30 -> 178 | T30: 0.2 | U30: =S30*(1-T30) -> 142.4 | V30: EUR | W30: =IFERROR(VLOOKUP(V30,Curr!$B$2:$C$13,2,FALSE),0) -> 11.2 | X30: =U30*W30 -> 1594.88 | Y30: =Q30 -> 89 | Z30: =+Y30*R30 -> 178 | AA30: EUR | AB30: =IFERROR(VLOOKUP(AA30,Curr!$B$2:$C$13,2,FALSE),0) -> 11.2 | AC30: =+Y30*AB30*R30 -> 1993.6 | AD30: =+AC30-X30 -> 398.72 | AE30: =IFERROR(AD30/AC30,0) -> 0.2
