Workbook

Sheet Curr
C1: NOK
B2: EUR | C2: 11.2
B3: SEK | C3: 1.02
B4: DKK | C4: 1.5
B5: ISK | C5: 0.075
B6: NOK | C6: 1
B7: USD | C7: 10.6

Sheet Mal
B1: Season: Summer
B2: Places: Trondheim - Sandnessjøen - Svolvær
B3: Pax: 2
B4: Rooming: Double
B6: ID | C6: Day | D6: Type | E6: From date | F6: To date | G6: From time | H6: To time | I6: Supplier | J6: Travel element | K6: Manual booking? | L6: Status | M6: Comments | N6: Non-refundable | O6: Refundable | P6: URL | Q6: Gross P per unit | R6: Units | S6: Gross P | T6: Supp Comm | U6: Net P | V6: Supp curr | W6: X-rate | X6: Net P NOK | Y6: Sales P per unit | Z6: Price | AA6: Sales curr | AB6: X-rate | AC6: Sales P NOK tot | AD6: GP NOK | AE6: GP % | AF6: VAT25 | AG6: VAT15 | AH6: VAT12 | AI6: VAT0-D | AJ6: VAT0-I
Q7: 0 | R7: 0 | S7: =+Q7*R7 -> 0 | T7: 0 | U7: =S7*(1-T7) -> 0 | V7: EUR | W7: =IFERROR(VLOOKUP(V7,Curr!$B$2:$C$13,2,FALSE),0) -> 11.2 | X7: =U7*W7 -> 0 | Y7: =Q7 -> 0 | Z7: =+Y7*R7 -> 0 | AA7: EUR | AB7: =IFERROR(VLOOKUP(AA7,Curr!$B$2:$C$13,2,FALSE),0) -> 11.2 | AC7: =+Y7*AB7*R7 -> 0 | AD7: =+AC7-X7 -> 0 | AE7: =IFERROR(AD7/AC7,0) -> 0
Q8: 0 | R8: 0 | S8: =+Q8*R8 -> 0 | T8: 0 | U8: =S8*(1-T8) -> 0 | V8: EUR | W8: =IFERROR(VLOOKUP(V8,Curr!$B$2:$C$13,2,FALSE),0) -> 11.2 | X8: =U8*W8 -> 0 | Y8: =Q8 -> 0 | Z8: =+Y8*R8 -> 0 | AA8: EUR | AB8: =IFERROR(VLOOKUP(AA8,Curr!$B$2:$C$13,2,FALSE),0) -> 11.2 | AC8: =+Y8*AB8*R8 -> 0 | AD8: =+AC8-X8 -> 0 | AE8: =IFERROR(AD8/AC8,0) -> 0
Q9: 0 | R9: 0 | S9: =+Q9*R9 -> 0 | T9: 0 | U9: =S9*(1-T9) -> 0 | V9: EUR | W9: =IFERROR(VLOOKUP(V9,Curr!$B$2:$C$13,2,FALSE),0) -> 11.2 | X9: =U9*W9 -> 0 | Y9: =Q9 -> 0 | Z9: =+Y9*R9 -> 0 | AA9: EUR | AB9: =IFERROR(VLOOKUP(AA9,Curr!$B$2:$C$13,2,FALSE),0) -> 11.2 | AC9: =+Y9*AB9*R9 -> 0 | AD9: =+AC9-X9 -> 0 | AE9: =IFERROR(AD9/AC9,0) -> 0
Q10: 0 | R10: 0 | S10: =+Q10*R10 -> 0 | T10: 0 | U10: =S10*(1-T10) -> 0 | V10: EUR | W10: =IFERROR(VLOOKUP(V10,Curr!$B$2:$C$13,2,FALSE),0) -> 11.2 | X10: =U10*W10 -> 0 | Y10: =Q10 -> 0 | Z10: =+Y10*R10 -> 0 | AA10: EUR | AB10: =IFERROR(VLOOKUP(AA10,Curr!$B$2:$C$13,2,FALSE),0) -> 11.2 | AC10: =+Y10*AB10*R10 -> 0 | AD10: =+AC10-X10 -> 0 | AE10: =IFERROR(AD10/AC10,0) -> 0
Q11: 0 | R11: 0 | S11: =+Q11*R11 -> 0 | T11: 0 | U11: =S11*(1-T11) -> 0 | V11: EUR | W11: =IFERROR(VLOOKUP(V11,Curr!$B$2:$C$13,2,FALSE),0) -> 11.2 | X11: =U11*W11 -> 0 | Y11: =Q11 -> 0 | Z11: =+Y11*R11 -> 0 | AA11: EUR | AB11: =IFERROR(VLOOKUP(AA11,Curr!$B$2:$C$13,2,FALSE),0) -> 11.2 | AC11: =+Y11*AB11*R11 -> 0 | AD11: =+AC11-X11 -> 0 | AE11: =IFERROR(AD11/AC11,0) -> 0
Q12: 0 | R12: 0 | S12: =+Q12*R12 -> 0 | T12: 0 | U12: =S12*(1-T12) -> 0 | V12: EUR | W12: =IFERROR(VLOOKUP(V12,Curr!$B$2:$C$13,2,FALSE),0) -> 11.2 | X12: =U12*W12 -> 0 | Y12: =Q12 -> 0 | Z12: =+Y12*R12 -> 0 | AA12: EUR | AB12: =IFERROR(VLOOKUP(AA12,Curr!$B$2:$C$13,2,FALSE),0) -> 11.2 | AC12: =+Y12*AB12*R12 -> 0 | AD12: =+AC12-X12 -> 0 | AE12: =IFERROR(AD12/AC12,0) -> 0
Q13: 0 | R13: 0 | S13: =+Q13*R13 -> 0 | T13: 0 | U13: =S13*(1-T13) -> 0 | V13: EUR | W13: =IFERROR(VLOOKUP(V13,Curr!$B$2:$C$13,2,FALSE),0) -> 11.2 | X13: =U13*W13 -> 0 | Y13: =Q13 -> 0 | Z13: =+Y13*R13 -> 0 | AA13: EUR | AB13: =IFERROR(VLOOKUP(AA13,Curr!$B$2:$C$13,2,FALSE),0) -> 11.2 | AC13: =+Y13*AB13*R13 -> 0 | AD13: =+AC13-X13 -> 0 | AE13: =IFERROR(AD13/AC13,0) -> 0
Q14: 0 | R14: 0 | S14: =+Q14*R14 -> 0 | T14: 0 | U14: =S14*(1-T14) -> 0 | V14: EUR | W14: =IFERROR(VLOOKUP(V14,Curr!$B$2:$C$13,2,FALSE),0) -> 11.2 | X14: =U14*W14 -> 0 | Y14: =Q14 -> 0 | Z14: =+Y14*R14 -> 0 | AA14: EUR | AB14: =IFERROR(VLOOKUP(AA14,Curr!$B$2:$C$13,2,FALSE),0) -> 11.2 | AC14: =+Y14*AB14*R14 -> 0 | AD14: =+AC14-X14 -> 0 | AE14: =IFERROR(AD14/AC14,0) -> 0
Q15: 0 | R15: 0 | S15: =+Q15*R15 -> 0 | T15: 0 | U15: =S15*(1-T15) -> 0 | V15: EUR | W15: =IFERROR(VLOOKUP(V15,Curr!$B$2:$C$13,2,FALSE),0) -> 11.2 | X15: =U15*W15 -> 0 | Y15: =Q15 -> 0 | Z15: =+Y15*R15 -> 0 | AA15: EUR | AB15: =IFERROR(VLOOKUP(AA15,Curr!$B$2:$C$13,2,FALSE),0) -> 11.2 | AC15: =+Y15*AB15*R15 -> 0 | AD15: =+AC15-X15 -> 0 | AE15: =IFERROR(AD15/AC15,0) -> 0
Q16: 0 | R16: 0 | S16: =+Q16*R16 -> 0 | T16: 0 | U16: =S16*(1-T16) -> 0 | V16: EUR | W16: =IFERROR(VLOOKUP(V16,Curr!$B$2:$C$13,2,FALSE),0) -> 11.2 | X16: =U16*W16 -> 0 | Y16: =Q16 -> 0 | Z16: =+Y16*R16 -> 0 | AA16: EUR | AB16: =IFERROR(VLOOKUP(AA16,Curr!$B$2:$C$13,2,FALSE),0) -> 11.2 | AC16: =+Y16*AB16*R16 -> 0 | AD16: =+AC16-X16 -> 0 | AE16: =IFERROR(AD16/AC16,0) -> 0
Q17: 0 | R17: 0 | S17: =+Q17*R17 -> 0 | T17: 0 | U17: =S17*(1-T17) -> 0 | V17: EUR | W17: =IFERROR(VLOOKUP(V17,Curr!$B$2:$C$13,2,FALSE),0) -> 11.2 | X17: =U17*W17 -> 0 | Y17: =Q17 -> 0 | Z17: =+Y17*R17 -> 0 | AA17: EUR | AB17: =IFERROR(VLOOKUP(AA17,Curr!$B$2:$C$13,2,FALSE),0) -> 11.2 | AC17: =+Y17*AB17*R17 -> 0 | AD17: =+AC17-X17 -> 0 | AE17: =IFERROR(AD17/AC17,0) -> 0
Q18: 0 | R18: 0 | S18: =+Q18*R18 -> 0 | T18: 0 | U18: =S18*(1-T18) -> 0 | V18: EUR | W18: =IFERROR(VLOOKUP(V18,Curr!$B$2:$C$13,2,FALSE),0) -> 11.2 | X18: =U18*W18 -> 0 | Y18: =Q18 -> 0 | Z18: =+Y18*R18 -> 0 | AA18: EUR | AB18: =IFERROR(VLOOKUP(AA18,Curr!$B$2:$C$13,2,FALSE),0) -> 11.2 | AC18: =+Y18*AB18*R18 -> 0 | AD18: =+AC18-X18 -> 0 | AE18: =IFERROR(AD18/AC18,0) -> 0
... Q98: 0 | R98: 0 | S98: =+Q98*R98 -> 0 | T98: 0 | U98: =S98*(1-T98) -> 0 | V98: EUR | W98: =IFERROR(VLOOKUP(V98,Curr!$B$2:$C$13,2,FALSE),0) -> 11.2 | X98: =U98*W98 -> 0 | Y98: =Q98 -> 0 | Z98: =+Y98*R98 -> 0 | AA98: EUR | AB98: =IFERROR(VLOOKUP(AA98,Curr!$B$2:$C$13,2,FALSE),0) -> 11.2 | AC98: =+Y98*AB98*R98 -> 0 | AD98: =+AC98-X98 -> 0 | AE98: =IFERROR(AD98/AC98,0) -> 0
B100: Totals | D100: x | E100: x | F100: x | G100: x | H100: x | I100: x | J100: x | K100: x | L100: x | M100: x | N100: x | O100: x | P100: x | Q100: x | R100: x | S100: x | T100: x | U100: x | V100: x | W100: x | X100: x | Y100: x | Z100: =SUM(Z7:Z98) -> 0 | AC100: =SUM(AC7:AC98) -> 0 | AD100: =SUM(AD7:AD98) -> 0 | AE100: =IFERROR(AD100/AC100,0) -> 0 | AF100: =SUM(AF8:AF99) -> 0 | AG100: =SUM(AG8:AG99) -> 0 | AH100: =SUM(AH8:AH99) -> 0 | AI100: =SUM(AI8:AI99) -> 0 | AJ100: =SUM(AJ8:AJ99) -> 0
Y102: Fixed | Z102: 1290
Y103: Variable | Z103: =Z54+Z60+Z68+Z70 -> 0
Y104: Total | Z104: 2920
Y105: PP | Z105: =Z104/2 -> 1460
Y107: Ref | Z107: 2920
Y108: NoRef | Z108: 0
Y110: Deposit | Z110: 850
Y111: Rest | Z111: 1760

Sheet 201
B1: Season: Winter
B2: Places: Oslo 1N - Bergen 2N - Tromsø 2N
B3: Pax: 2
B4: Rooming: Double
B6: ID | C6: Day | D6: Type | E6: From date | F6: To date | G6: From time | H6: To time | I6: Supplier | J6: Travel element | K6: Manual booking? | L6: Status | M6: Comments | N6: Non-refundable | O6: Refundable | P6: URL | Q6: Gross P per unit | R6: Units | S6: Gross P | T6: Supp Comm | U6: Net P | V6: Supp curr | W6: X-rate | X6: Net P NOK | Y6: Sales P per unit | Z6: Price | AA6: Sales curr | AB6: X-rate | AC6: Sales P NOK tot | AD6: GP NOK | AE6: GP % | AF6: VAT25 | AG6: VAT15 | AH6: VAT12 | AI6: VAT0-D | AJ6: VAT0-I
C7: Day 1 | D7: Arrival | J7: Oslo: Welcome to Norway | Q7: 0 | R7: 0 | S7: =+Q7*R7 -> 0 | T7: 0 | U7: =S7*(1-T7) -> 0 | V7: EUR | W7: =IFERROR(VLOOKUP(V7,Curr!$B$2:$C$13,2,FALSE),0) -> 11.2 | X7: =U7*W7 -> 0 | Y7: =Q7 -> 0 | Z7: =+Y7*R7 -> 0 | AA7: EUR | AB7: =IFERROR(VLOOKUP(AA7,Curr!$B$2:$C$13,2,FALSE),0) -> 11.2 | AC7: =+Y7*AB7*R7 -> 0 | AD7: =+AC7-X7 -> 0 | AE7: =IFERROR(AD7/AC7,0) -> 0
C8: Day 1 | D8: Transfer | J8: Oslo: Self transfer to your accommodation | Q8: 0 | R8: 0 | S8: =+Q8*R8 -> 0 | T8: 0 | U8: =S8*(1-T8) -> 0 | V8: NOK | W8: =IFERROR(VLOOKUP(V8,Curr!$B$2:$C$13,2,FALSE),0) -> 1 | X8: =U8*W8 -> 0 | Y8: =Q8/11.3/0.8 -> 0 | Z8: =+Y8*R8 -> 0 | AA8: EUR | AB8: =IFERROR(VLOOKUP(AA8,Curr!$B$2:$C$13,2,FALSE),0) -> 11.2 | AC8: =+Y8*AB8*R8 -> 0 | AD8: =+AC8-X8 -> 0 | AE8: =IFERROR(AD8/AC8,0) -> 0
C9: Day 1 | D9: Hotel | J9: Oslo: Check in to your accommodation for a 1 night stay - Centrally located 3/4-star hotel - Standard Room - Breakfast included | Q9: 150 | R9: 1 | S9: =+Q9*R9 -> 150 | T9: 0 | U9: =S9*(1-T9) -> 150 | V9: EUR | W9: =IFERROR(VLOOKUP(V9,Curr!$B$2:$C$13,2,FALSE),0) -> 11.2 | X9: =U9*W9 -> 1680 | Y9: =Q9/0.85 -> 176.47059 | Z9: =+Y9*R9 -> 176.47059 | AA9: EUR | AB9: =IFERROR(VLOOKUP(AA9,Curr!$B$2:$C$13,2,FALSE),0) -> 11.2 | AC9: =+Y9*AB9*R9 -> 1976.4706 | AD9: =+AC9-X9 -> 296.47059 | AE9: =IFERROR(AD9/AC9,0) -> 0.15
C10: Day 1 | D10: Leisure | J10: Oslo: Spend time at leisure | Q10: 0 | R10: 0 | S10: =+Q10*R10 -> 0 | T10: 0 | U10: =S10*(1-T10) -> 0 | V10: EUR | W10: =IFERROR(VLOOKUP(V10,Curr!$B$2:$C$13,2,FALSE),0) -> 11.2 | X10: =U10*W10 -> 0 | Y10: =Q10 -> 0 | Z10: =+Y10*R10 -> 0 | AA10: EUR | AB10: =IFERROR(VLOOKUP(AA10,Curr!$B$2:$C$13,2,FALSE),0) -> 11.2 | AC10: =+Y10*AB10*R10 -> 0 | AD10: =+AC10-X10 -> 0 | AE10: =IFERROR(AD10/AC10,0) -> 0
S11: =+Q11*R11 -> 0 | T11: 0 | U11: =S11*(1-T11) -> 0 | V11: EUR | W11: =IFERROR(VLOOKUP(V11,Curr!$B$2:$C$13,2,FALSE),0) -> 11.2 | X11: =U11*W11 -> 0 | Y11: =Q11 -> 0 | Z11: =+Y11*R11 -> 0 | AA11: EUR | AB11: =IFERROR(VLOOKUP(AA11,Curr!$B$2:$C$13,2,FALSE),0) -> 11.2 | AC11: =+Y11*AB11*R11 -> 0 | AD11: =+AC11-X11 -> 0 | AE11: =IFERROR(AD11/AC11,0) -> 0
C12: Day 2 | D12: Transfer | J12: Oslo: Self transfer to Oslo Central Station | Q12: 0 | R12: 0 | S12: =+Q12*R12 -> 0 | T12: 0 | U12: =S12*(1-T12) -> 0 | V12: EUR | W12: =IFERROR(VLOOKUP(V12,Curr!$B$2:$C$13,2,FALSE),0) -> 11.2 | X12: =U12*W12 -> 0 | Y12: =Q12 -> 0 | Z12: =+Y12*R12 -> 0 | AA12: EUR | AB12: =IFERROR(VLOOKUP(AA12,Curr!$B$2:$C$13,2,FALSE),0) -> 11.2 | AC12: =+Y12*AB12*R12 -> 0 | AD12: =+AC12-X12 -> 0 | AE12: =IFERROR(AD12/AC12,0) -> 0
C13: Day 2 | D13: Train | J13: Oslo: Scenic Long Distance Train transfer to Bergen - Time: 08:25 am - 3:00 pm - Includes: Tickets | O13: x | P13: https://www.vy.no/#reisesok | Q13: 2400 | R13: 1 | S13: =+Q13*R13 -> 2400 | T13: 0 | U13: =S13*(1-T13) -> 2400 | V13: NOK | W13: =IFERROR(VLOOKUP(V13,Curr!$B$2:$C$13,2,FALSE),0) -> 1 | X13: =U13*W13 -> 2400 | Y13: =Q13/11.3/0.8 -> 265.48673 | Z13: =+Y13*R13 -> 265.48673 | AA13: EUR | AB13: =IFERROR(VLOOKUP(AA13,Curr!$B$2:$C$13,2,FALSE),0) -> 11.2 | AC13: =+Y13*AB13*R13 -> 2973.4513 | AD13: =+AC13-X13 -> 573.45133 | AE13: =IFERROR(AD13/AC13,0) -> 0.19285714
C14: Day 2 | D14: Transfer | J14: Bergen: Self transfer to your accommodation | Q14: 0 | R14: 0 | S14: =+Q14*R14 -> 0 | T14: 0 | U14: =S14*(1-T14) -> 0 | V14: EUR | W14: =IFERROR(VLOOKUP(V14,Curr!$B$2:$C$13,2,FALSE),0) -> 11.2 | X14: =U14*W14 -> 0 | Y14: =Q14 -> 0 | Z14: =+Y14*R14 -> 0 | AA14: EUR | AB14: =IFERROR(VLOOKUP(AA14,Curr!$B$2:$C$13,2,FALSE),0) -> 11.2 | AC14: =+Y14*AB14*R14 -> 0 | AD14: =+AC14-X14 -> 0 | AE14: =IFERROR(AD14/AC14,0) -> 0
C15: Day 2 | D15: Hotel | J15: Bergen: Check in to your accommodation for a 2 night stay - Centrally located 3/4-star hotel - Standard Room - Breakfast included | Q15: 280 | R15: 1 | S15: =+Q15*R15 -> 280 | T15: 0 | U15: =S15*(1-T15) -> 280 | V15: EUR | W15: =IFERROR(VLOOKUP(V15,Curr!$B$2:$C$13,2,FALSE),0) -> 11.2 | X15: =U15*W15 -> 3136 | Y15: =Q15/0.85 -> 329.41176 | Z15: =+Y15*R15 -> 329.41176 | AA15: EUR | AB15: =IFERROR(VLOOKUP(AA15,Curr!$B$2:$C$13,2,FALSE),0) -> 11.2 | AC15: =+Y15*AB15*R15 -> 3689.4118 | AD15: =+AC15-X15 -> 553.41176 | AE15: =IFERROR(AD15/AC15,0) -> 0.15
C16: Day 2 | D16: Leisure | J16: Bergen: Spend time at leisure | Q16: 0 | R16: 0 | S16: =+Q16*R16 -> 0 | T16: 0 | U16: =S16*(1-T16) -> 0 | V16: EUR | W16: =IFERROR(VLOOKUP(V16,Curr!$B$2:$C$13,2,FALSE),0) -> 11.2 | X16: =U16*W16 -> 0 | Y16: =Q16 -> 0 | Z16: =+Y16*R16 -> 0 | AA16: EUR | AB16: =IFERROR(VLOOKUP(AA16,Curr!$B$2:$C$13,2,FALSE),0) -> 11.2 | AC16: =+Y16*AB16*R16 -> 0 | AD16: =+AC16-X16 -> 0 | AE16: =IFERROR(AD16/AC16,0) -> 0
S17: =+Q17*R17 -> 0 | T17: 0 | U17: =S17*(1-T17) -> 0 | V17: EUR | W17: =IFERROR(VLOOKUP(V17,Curr!$B$2:$C$13,2,FALSE),0) -> 11.2 | X17: =U17*W17 -> 0 | Y17: =Q17 -> 0 | Z17: =+Y17*R17 -> 0 | AA17: EUR | AB17: =IFERROR(VLOOKUP(AA17,Curr!$B$2:$C$13,2,FALSE),0) -> 11.2 | AC17: =+Y17*AB17*R17 -> 0 | AD17: =+AC17-X17 -> 0 | AE17: =IFERROR(AD17/AC17,0) -> 0
C18: Day 3 | D18: Activity | J18: Bergen: 2 hr walk Through Bergen Past & Present - Time: 10:00 am - 12:00 pm - Meeting point: Bradbenken 1 - Includes: Profesional Guide | O18: x | P18: https://www.ilovebergen.net/tour/a-walk-through-bergen-past-present/ | Q18: 290 | R18: 2 | S18: =+Q18*R18 -> 580 | T18: 0.2 | U18: =S18*(1-T18) -> 464 | V18: NOK | W18: =IFERROR(VLOOKUP(V18,Curr!$B$2:$C$13,2,FALSE),0) -> 1 | X18: =U18*W18 -> 464 | Y18: =Q18/11.3/0.64 -> 40.099558 | Z18: =+Y18*R18 -> 80.199115 | AA18: EUR | AB18: =IFERROR(VLOOKUP(AA18,Curr!$B$2:$C$13,2,FALSE),0) -> 11.2 | AC18: =+Y18*AB18*R18 -> 898.23009 | AD18: =+AC18-X18 -> 434.23009 | AE18: =IFERROR(AD18/AC18,0) -> 0.48342857
C19: Day 3 | D19: Activity | J19: Bergen: Fløibanen Funicual - Time: Flexible - Meeting point: Vetrlidsallmenningen 23A - Includes: Tickets | O19: x | P19: https://www.floyen.no/en/floibanen/buy-tickets/ | Q19: 175 | R19: 2 | S19: =+Q19*R19 -> 350 | T19: 0 | U19: =S19*(1-T19) -> 350 | V19: NOK | W19: =IFERROR(VLOOKUP(V19,Curr!$B$2:$C$13,2,FALSE),0) -> 1 | X19: =U19*W19 -> 350 | Y19: =Q19/11.3/0.5 -> 30.973451 | Z19: =+Y19*R19 -> 61.946903 | AA19: EUR | AB19: =IFERROR(VLOOKUP(AA19,Curr!$B$2:$C$13,2,FALSE),0) -> 11.2 | AC19: =+Y19*AB19*R19 -> 693.80531 | AD19: =+AC19-X19 -> 343.80531 | AE19: =IFERROR(AD19/AC19,0) -> 0.49553571
C20: Day 3 | D20: Leisure | J20: Bergen: Spend time at leisure | Q20: 0 | R20: 0 | S20: =+Q20*R20 -> 0 | T20: 0 | U20: =S20*(1-T20) -> 0 | V20: EUR | W20: =IFERROR(VLOOKUP(V20,Curr!$B$2:$C$13,2,FALSE),0) -> 11.2 | X20: =U20*W20 -> 0 | Y20: =Q20 -> 0 | Z20: =+Y20*R20 -> 0 | AA20: EUR | AB20: =IFERROR(VLOOKUP(AA20,Curr!$B$2:$C$13,2,FALSE),0) -> 11.2 | AC20: =+Y20*AB20*R20 -> 0 | AD20: =+AC20-X20 -> 0 | AE20: =IFERROR(AD20/AC20,0) -> 0
S21: =+Q21*R21 -> 0 | T21: 0 | U21: =S21*(1-T21) -> 0 | V21: EUR | W21: =IFERROR(VLOOKUP(V21,Curr!$B$2:$C$13,2,FALSE),0) -> 11.2 | X21: =U21*W21 -> 0 | Y21: =Q21 -> 0 | Z21: =+Y21*R21 -> 0 | AA21: EUR | AB21: =IFERROR(VLOOKUP(AA21,Curr!$B$2:$C$13,2,FALSE),0) -> 11.2 | AC21: =+Y21*AB21*R21 -> 0 | AD21: =+AC21-X21 -> 0 | AE21: =IFERROR(AD21/AC21,0) -> 0
C22: Day 4 | D22: Transfer | J22: Bergen: Self transfer to Bergen Airport | Q22: 0 | R22: 0 | S22: =+Q22*R22 -> 0 | T22: 0 | U22: =S22*(1-T22) -> 0 | V22: EUR | W22: =IFERROR(VLOOKUP(V22,Curr!$B$2:$C$13,2,FALSE),0) -> 11.2 | X22: =U22*W22 -> 0 | Y22: =Q22 -> 0 | Z22: =+Y22*R22 -> 0 | AA22: EUR | AB22: =IFERROR(VLOOKUP(AA22,Curr!$B$2:$C$13,2,FALSE),0) -> 11.2 | AC22: =+Y22*AB22*R22 -> 0 | AD22: =+AC22-X22 -> 0 | AE22: =IFERROR(AD22/AC22,0) -> 0
C23: Day 4 | D23: Flight | J23: Bergen: Flight to Tromsø - Time: Date dependant - Luggage included: 1 x 23 kg check in and 1 x 8 kg carry on per person | O23: x | Q23: 1800 | R23: 2 | S23: =+Q23*R23 -> 3600 | T23: 0 | U23: =S23*(1-T23) -> 3600 | V23: NOK | W23: =IFERROR(VLOOKUP(V23,Curr!$B$2:$C$13,2,FALSE),0) -> 1 | X23: =U23*W23 -> 3600 | Y23: =Q23/11.3/0.8 -> 199.11504 | Z23: =+Y23*R23 -> 398.23009 | AA23: EUR | AB23: =IFERROR(VLOOKUP(AA23,Curr!$B$2:$C$13,2,FALSE),0) -> 11.2 | AC23: =+Y23*AB23*R23 -> 4460.177 | AD23: =+AC23-X23 -> 860.17699 | AE23: =IFERROR(AD23/AC23,0) -> 0.19285714
C24: Day 4 | D24: Transfer | J24: Tromsø: Self transfer to your accommodation | Q24: 0 | R24: 0 | S24: =+Q24*R24 -> 0 | T24: 0 | U24: =S24*(1-T24) -> 0 | V24: NOK | W24: =IFERROR(VLOOKUP(V24,Curr!$B$2:$C$13,2,FALSE),0) -> 1 | X24: =U24*W24 -> 0 | Y24: =Q24/11.3/0.8 -> 0 | Z24: =+Y24*R24 -> 0 | AA24: EUR | AB24: =IFERROR(VLOOKUP(AA24,Curr!$B$2:$C$13,2,FALSE),0) -> 11.2 | AC24: =+Y24*AB24*R24 -> 0 | AD24: =+AC24-X24 -> 0 | AE24: =IFERROR(AD24/AC24,0) -> 0
C25: Day 4 | D25: Hotel | J25: Tromsø: Check in to your accommodation for a 2 night stay - Centrally located 3/4-star hotel - Standard Room - Breakfast included | Q25: 500 | R25: 1 | S25: =+Q25*R25 -> 500 | T25: 0 | U25: =S25*(1-T25) -> 500 | V25: EUR | W25: =IFERROR(VLOOKUP(V25,Curr!$B$2:$C$13,2,FALSE),0) -> 11.2 | X25: =U25*W25 -> 5600 | Y25: =Q25/0.85 -> 588.23529 | Z25: =+Y25*R25 -> 588.23529 | AA25: EUR | AB25: =IFERROR(VLOOKUP(AA25,Curr!$B$2:$C$13,2,FALSE),0) -> 11.2 | AC25: =+Y25*AB25*R25 -> 6588.2353 | AD25: =+AC25-X25 -> 988.23529 | AE25: =IFERROR(AD25/AC25,0) -> 0.15
C26: Day 4 | D26: Leisure | J26: Tromsø: Spend time at leisure | Q26: 0 | R26: 0 | S26: =+Q26*R26 -> 0 | T26: 0 | U26: =S26*(1-T26) -> 0 | V26: EUR | W26: =IFERROR(VLOOKUP(V26,Curr!$B$2:$C$13,2,FALSE),0) -> 11.2 | X26: =U26*W26 -> 0 | Y26: =Q26 -> 0 | Z26: =+Y26*R26 -> 0 | AA26: EUR | AB26: =IFERROR(VLOOKUP(AA26,Curr!$B$2:$C$13,2,FALSE),0) -> 11.2 | AC26: =+Y26*AB26*R26 -> 0 | AD26: =+AC26-X26 -> 0 | AE26: =IFERROR(AD26/AC26,0) -> 0
C27: Day 4 | D27: Activity | J27: Tromsø: Northern Lights Cruise with Silent Electric Ship - Time: 7:00 pm - 10:00 pm - Meeting point: Kaigata 6 - Includes: Departure from central Tromsø, 3-hour fjord cruise, Light meal (soup and bread) and water, English speaking guides, Warm indoor saloons, Free wifi, Toilets | O27: x | P27: https://booknordics.com/norway/northern-norway/tromso-region/northern-lights-cruise-electric-ship | Q27: 105 | R27: 2 | S27: =+Q27*R27 -> 210 | T27: 0.2 | U27: =S27*(1-T27) -> 168 | V27: EUR | W27: =IFERROR(VLOOKUP(V27,Curr!$B$2:$C$13,2,FALSE),0) -> 11.2 | X27: =U27*W27 -> 1881.6 | Y27: =Q27 -> 105 | Z27: =+Y27*R27 -> 210 | AA27: EUR | AB27: =IFERROR(VLOOKUP(AA27,Curr!$B$2:$C$13,2,FALSE),0) -> 11.2 | AC27: =+Y27*AB27*R27 -> 2352 | AD27: =+AC27-X27 -> 470.4 | AE27: =IFERROR(AD27/AC27,0) -> 0.2
S28: =+Q28*R28 -> 0 | T28: 0 | U28: =S28*(1-T28) -> 0 | V28: EUR | W28: =IFERROR(VLOOKUP(V28,Curr!$B$2:$C$13,2,FALSE),0) -> 11.2 | X28: =U28*W28 -> 0 | Y28: =Q28 -> 0 | Z28: =+Y28*R28 -> 0 | AA28: EUR | AB28: =IFERROR(VLOOKUP(AA28,Curr!$B$2:$C$13,2,FALSE),0) -> 11.2 | AC28: =+Y28*AB28*R28 -> 0 | AD28: =+AC28-X28 -> 0 | AE28: =IFERROR(AD28/AC28,0) -> 0
C29: Day 5 | D29: Activity | J29: Tromsø: Reindeer Feeding and Sámi Culture - Time: 09:45 am - 2:30 pm - Meeting point: Radisson Blu Hotel's main entrance (Sjøgata 7) - Includes: Scenic transfers (45 min each way), Knowledgeable English and Norwegian speaking guide, Feeding the herd at our camp, Hot beverages and hot meal (traditional Sámi stew or vegetable/lentil soup), Cultural introduction about Sámi history and daily life, A chance to see the northern lights from our camp, Thermal suit and warm snow boots | O29: x | P29: https://www.tromsolapland.no/activities/reindeer-feeding-and-sami-culture | Q29: 1695 | R29: 2 | S29: =+Q29*R29 -> 3390 | T29: 0.2 | U29: =S29*(1-T29) -> 2712 | V29: NOK | W29: =IFERROR(VLOOKUP(V29,Curr!$B$2:$C$13,2,FALSE),0) -> 1 | X29: =U29*W29 -> 2712 | Y29: =Q29/11.3 -> 150 | Z29: =+Y29*R29 -> 300 | AA29: EUR | AB29: =IFERROR(VLOOKUP(AA29,Curr!$B$2:$C$13,2,FALSE),0) -> 11.2 | AC29: =+Y29*AB29*R29 -> 3360 | AD29: =+AC29-X29 -> 648 | AE29: =IFERROR(AD29/AC29,0) -> 0.19285714
C30: Day 5 | D30: Leisure | J30: Tromsø: Spend time at leisure | Q30: 0 | R30: 0 | S30: =+Q30*R30 -> 0 | T30: 0 | U30: =S30*(1-T30) -> 0 | V30: EUR | W30: =IFERROR(VLOOKUP(V30,Curr!$B$2:$C$13,2,FALSE),0) -> 11.2 | X30: =U30*W30 -> 0 | Y30: =Q30 -> 0 | Z30: =+Y30*R30 -> 0 | AA30: EUR | AB30: =IFERROR(VLOOKUP(AA30,Curr!$B$2:$C$13,2,FALSE),0) -> 11.2 | AC30: =+Y30*AB30*R30 -> 0 | AD30: =+AC30-X30 -> 0 | AE30: =IFERROR(AD30/AC30,0) -> 0
C31: Day 5 | D31: Activity | J31: Tromsø: All-Evening Northern Lights Hunt by Minibus or Bus - Time: 7:00 pm - 12:00 am - Meeting point: Kaigata 4 - Includes: Knowledgeable, English-speaking guides, Photos shared with you after the tour, Thermo clothing and warm gear, Light snacks and warm/cold beverages, Drop-off at hotel, up to 5 km from Tromsø | O31: x | P31: https://booknordics.com/norway/northern-norway/tromso-region/full-day-magic-of-the-arctic-lights-in-tromso | Q31: 120 | R31: 2 | S31: =+Q31*R31 -> 240 | T31: 0.2 | U31: =S31*(1-T31) -> 192 | V31: EUR | W31: =IFERROR(VLOOKUP(V31,Curr!$B$2:$C$13,2,FALSE),0) -> 11.2 | X31: =U31*W31 -> 2150.4 | Y31: =Q31 -> 120 | Z31: =+Y31*R31 -> 240 | AA31: EUR | AB31: =IFERROR(VLOOKUP(AA31,Curr!$B$2:$C$13,2,FALSE),0) -> 11.2 | AC31: =+Y31*AB31*R31 -> 2688 | AD31: =+AC31-X31 -> 537.6 | AE31: =IFERROR(AD31/AC31,0) -> 0.2
S32: =+Q32*R32 -> 0 | T32: 0 | U32: =S32*(1-T32) -> 0 | V32: EUR | W32: =IFERROR(VLOOKUP(V32,Curr!$B$2:$C$13,2,FALSE),0) -> 11.2 | X32: =U32*W32 -> 0 | Y32: =Q32 -> 0 | Z32: =+Y32*R32 -> 0 | AA32: EUR | AB32: =IFERROR(VLOOKUP(AA32,Curr!$B$2:$C$13,2,FALSE),0) -> 11.2 | AC32: =+Y32*AB32*R32 -> 0 | AD32: =+AC32-X32 -> 0 | AE32: =IFERROR(AD32/AC32,0) -> 0
C33: Day 6 | D33: Transfer | J33: Tromsø: Self transfer to Tromsø Airport | Q33: 0 | R33: 0 | S33: =+Q33*R33 -> 0 | T33: 0 | U33: =S33*(1-T33) -> 0 | V33: NOK | W33: =IFERROR(VLOOKUP(V33,Curr!$B$2:$C$13,2,FALSE),0) -> 1 | X33: =U33*W33 -> 0 | Y33: =Q33/11.3/0.8 -> 0 | Z33: =+Y33*R33 -> 0 | AA33: EUR | AB33: =IFERROR(VLOOKUP(AA33,Curr!$B$2:$C$13,2,FALSE),0) -> 11.2 | AC33: =+Y33*AB33*R33 -> 0 | AD33: =+AC33-X33 -> 0 | AE33: =IFERROR(AD33/AC33,0) -> 0
C34: Day 6 | D34: Departure | J34: Tromsø: Departure home | Q34: 0 | R34: 0 | S34: =+Q34*R34 -> 0 | T34: 0 | U34: =S34*(1-T34) -> 0 | V34: EUR | W34: =IFERROR(VLOOKUP(V34,Curr!$B$2:$C$13,2,FALSE),0) -> 11.2 | X34: =U34*W34 -> 0 | Y34: =Q34 -> 0 | Z34: =+Y34*R34 -> 0 | AA34: EUR | AB34: =IFERROR(VLOOKUP(AA34,Curr!$B$2:$C$13,2,FALSE),0) -> 11.2 | AC34: =+Y34*AB34*R34 -> 0 | AD34: =+AC34-X34 -> 0 | AE34: =IFERROR(AD34/AC34,0) -> 0
S35: =+Q35*R35 -> 0 | T35: 0 | U35: =S35*(1-T35) -> 0 | V35: EUR | W35: =IFERROR(VLOOKUP(V35,Curr!$B$2:$C$13,2,FALSE),0) -> 11.2 | X35: =U35*W35 -> 0 | Y35: =Q35 -> 0 | Z35: =+Y35*R35 -> 0 | AA35: EUR | AB35: =IFERROR(VLOOKUP(AA35,Curr!$B$2:$C$13,2,FALSE),0) -> 11.2 | AC35: =+Y35*AB35*R35 -> 0 | AD35: =+AC35-X35 -> 0 | AE35: =IFERROR(AD35/AC35,0) -> 0
S36: =+Q36*R36 -> 0 | T36: 0 | U36: =S36*(1-T36) -> 0 | V36: EUR | W36: =IFERROR(VLOOKUP(V36,Curr!$B$2:$C$13,2,FALSE),0) -> 11.2 | X36: =U36*W36 -> 0 | Y36: =Q36 -> 0 | Z36: =+Y36*R36 -> 0 | AA36: EUR | AB36: =IFERROR(VLOOKUP(AA36,Curr!$B$2:$C$13,2,FALSE),0) -> 11.2 | AC36: =+Y36*AB36*R36 -> 0 | AD36: =+AC36-X36 -> 0 | AE36: =IFERROR(AD36/AC36,0) -> 0
C37: Day 1 | D37: Transfer Package | J37: Oslo: Private transfer to your accommodation | Q37: 1750 | R37: 0 | S37: =+Q37*R37 -> 0 | T37: 0 | U37: =S37*(1-T37) -> 0 | V37: NOK | W37: =IFERROR(VLOOKUP(V37,Curr!$B$2:$C$13,2,FALSE),0) -> 1 | X37: =U37*W37 -> 0 | Y37: =Q37/11.3/0.8 -> 193.58407 | Z37: =+Y37*R37 -> 0 | AA37: EUR | AB37: =IFERROR(VLOOKUP(AA37,Curr!$B$2:$C$13,2,FALSE),0) -> 11.2 | AC37: =+Y37*AB37*R37 -> 0 | AD37: =+AC37-X37 -> 0 | AE37: =IFERROR(AD37/AC37,0) -> 0
C38: Day 2 | D38: Transfer Package | J38: Bergen: Private transfer to your accommodation | Q38: 1290 | R38: 0 | S38: =+Q38*R38 -> 0 | T38: 0.15 | U38: =S38*(1-T38) -> 0 | V38: NOK | W38: =IFERROR(VLOOKUP(V38,Curr!$B$2:$C$13,2,FALSE),0) -> 1 | X38: =U38*W38 -> 0 | Y38: =Q38/11.3/0.98 -> 116.48907 | Z38: =+Y38*R38 -> 0 | AA38: EUR | AB38: =IFERROR(VLOOKUP(AA38,Curr!$B$2:$C$13,2,FALSE),0) -> 11.2 | AC38: =+Y38*AB38*R38 -> 0 | AD38: =+AC38-X38 -> 0 | AE38: =IFERROR(AD38/AC38,0) -> 0
C39: Day 4 | D39: Transfer Package | J39: Bergen: Private transfer to Bergen Airport | Q39: 1690 | R39: 0 | S39: =+Q39*R39 -> 0 | T39: 0.15 | U39: =S39*(1-T39) -> 0 | V39: NOK | W39: =IFERROR(VLOOKUP(V39,Curr!$B$2:$C$13,2,FALSE),0) -> 1 | X39: =U39*W39 -> 0 | Y39: =Q39/11.3/0.98 -> 152.60972 | Z39: =+Y39*R39 -> 0 | AA39: EUR | AB39: =IFERROR(VLOOKUP(AA39,Curr!$B$2:$C$13,2,FALSE),0) -> 11.2 | AC39: =+Y39*AB39*R39 -> 0 | AD39: =+AC39-X39 -> 0 | AE39: =IFERROR(AD39/AC39,0) -> 0
C40: Day 4 | D40: Transfer Package | J40: Tromsø: Private transfer to your accommodation | Q40: 900 | R40: 0 | S40: =+Q40*R40 -> 0 | T40: 0 | U40: =S40*(1-T40) -> 0 | V40: NOK | W40: =IFERROR(VLOOKUP(V40,Curr!$B$2:$C$13,2,FALSE),0) -> 1 | X40: =U40*W40 -> 0 | Y40: =Q40/11.3/0.8 -> 99.557522 | Z40: =+Y40*R40 -> 0 | AA40: EUR | AB40: =IFERROR(VLOOKUP(AA40,Curr!$B$2:$C$13,2,FALSE),0) -> 11.2 | AC40: =+Y40*AB40*R40 -> 0 | AD40: =+AC40-X40 -> 0 | AE40: =IFERROR(AD40/AC40,0) -> 0
C41: Day 6 | D41: Transfer Package | J41: Tromsø: Private transfer to Tromsø Airport | Q41: 900 | R41: 0 | S41: =+Q41*R41 -> 0 | T41: 0 | U41: =S41*(1-T41) -> 0 | V41: NOK | W41: =IFERROR(VLOOKUP(V41,Curr!$B$2:$C$13,2,FALSE),0) -> 1 | X41: =U41*W41 -> 0 | Y41: =Q41/11.3/0.8 -> 99.557522 | Z41: =+Y41*R41 -> 0 | AA41: EUR | AB41: =IFERROR(VLOOKUP(AA41,Curr!$B$2:$C$13,2,FALSE),0) -> 11.2 | AC41: =+Y41*AB41*R41 -> 0 | AD41: =+AC41-X41 -> 0 | AE41: =IFERROR(AD41/AC41,0) -> 0
...

Sheet 202
B1: Season: Winter
B2: Places: Oslo 1N - Flåm 1N - Bergen 2N - Tromsø 3N
B3: Pax: 2
B4: Rooming: Double
B6: ID | C6: Day | D6: Type | E6: From date | F6: To date | G6: From time | H6: To time | I6: Supplier | J6: Travel element | K6: Manual booking? | L6: Status | M6: Comments | N6: Non-refundable | O6: Refundable | P6: URL | Q6: Gross P per unit | R6: Units | S6: Gross P | T6: Supp Comm | U6: Net P | V6: Supp curr | W6: X-rate | X6: Net P NOK | Y6: Sales P per unit | Z6: Price | AA6: Sales curr | AB6: X-rate | AC6: Sales P NOK tot | AD6: GP NOK | AE6: GP % | AF6: VAT25 | AG6: VAT15 | AH6: VAT12 | AI6: VAT0-D | AJ6: VAT0-I
C7: Day 1 | D7: Arrival | J7: Oslo: Welcome to Norway | Q7: 0 | R7: 0 | S7: =+Q7*R7 -> 0 | T7: 0 | U7: =S7*(1-T7) -> 0 | V7: EUR | W7: =IFERROR(VLOOKUP(V7,Curr!$B$2:$C$13,2,FALSE),0) -> 11.2 | X7: =U7*W7 -> 0 | Y7: =Q7 -> 0 | Z7: =+Y7*R7 -> 0 | AA7: EUR | AB7: =IFERROR(VLOOKUP(AA7,Curr!$B$2:$C$13,2,FALSE),0) -> 11.2 | AC7: =+Y7*AB7*R7 -> 0 | AD7: =+AC7-X7 -> 0 | AE7: =IFERROR(AD7/AC7,0) -> 0
C8: Day 1 | D8: Transfer | J8: Oslo: Self transfer to your accommodation | Q8: 0 | R8: 0 | S8: =+Q8*R8 -> 0 | T8: 0 | U8: =S8*(1-T8) -> 0 | V8: NOK | W8: =IFERROR(VLOOKUP(V8,Curr!$B$2:$C$13,2,FALSE),0) -> 1 | X8: =U8*W8 -> 0 | Y8: =Q8/11.3/0.8 -> 0 | Z8: =+Y8*R8 -> 0 | AA8: EUR | AB8: =IFERROR(VLOOKUP(AA8,Curr!$B$2:$C$13,2,FALSE),0) -> 11.2 | AC8: =+Y8*AB8*R8 -> 0 | AD8: =+AC8-X8 -> 0 | AE8: =IFERROR(AD8/AC8,0) -> 0
C9: Day 1 | D9: Hotel | J9: Oslo: Check in to your accommodation for a 1 night stay - Centrally located 3/4-star hotel - Standard Room - Breakfast included | Q9: 150 | R9: 1 | S9: =+Q9*R9 -> 150 | T9: 0 | U9: =S9*(1-T9) -> 150 | V9: EUR | W9: =IFERROR(VLOOKUP(V9,Curr!$B$2:$C$13,2,FALSE),0) -> 11.2 | X9: =U9*W9 -> 1680 | Y9: =Q9/0.85 -> 176.47059 | Z9: =+Y9*R9 -> 176.47059 | AA9: EUR | AB9: =IFERROR(VLOOKUP(AA9,Curr!$B$2:$C$13,2,FALSE),0) -> 11.2 | AC9: =+Y9*AB9*R9 -> 1976.4706 | AD9: =+AC9-X9 -> 296.47059 | AE9: =IFERROR(AD9/AC9,0) -> 0.15
C10: Day 1 | D10: Leisure | J10: Oslo: Spend time at leisure | Q10: 0 | R10: 0 | S10: =+Q10*R10 -> 0 | T10: 0 | U10: =S10*(1-T10) -> 0 | V10: EUR | W10: =IFERROR(VLOOKUP(V10,Curr!$B$2:$C$13,2,FALSE),0) -> 11.2 | X10: =U10*W10 -> 0 | Y10: =Q10 -> 0 | Z10: =+Y10*R10 -> 0 | AA10: EUR | AB10: =IFERROR(VLOOKUP(AA10,Curr!$B$2:$C$13,2,FALSE),0) -> 11.2 | AC10: =+Y10*AB10*R10 -> 0 | AD10: =+AC10-X10 -> 0 | AE10: =IFERROR(AD10/AC10,0) -> 0
S11: =+Q11*R11 -> 0 | T11: 0 | U11: =S11*(1-T11) -> 0 | V11: EUR | W11: =IFERROR(VLOOKUP(V11,Curr!$B$2:$C$13,2,FALSE),0) -> 11.2 | X11: =U11*W11 -> 0 | Y11: =Q11 -> 0 | Z11: =+Y11*R11 -> 0 | AA11: EUR | AB11: =IFERROR(VLOOKUP(AA11,Curr!$B$2:$C$13,2,FALSE),0) -> 11.2 | AC11: =+Y11*AB11*R11 -> 0 | AD11: =+AC11-X11 -> 0 | AE11: =IFERROR(AD11/AC11,0) -> 0
C12: Day 2 | D12: Transfer | J12: Oslo: Self transfer to Oslo Central Station | Q12: 0 | R12: 0 | S12: =+Q12*R12 -> 0 | T12: 0 | U12: =S12*(1-T12) -> 0 | V12: EUR | W12: =IFERROR(VLOOKUP(V12,Curr!$B$2:$C$13,2,FALSE),0) -> 11.2 | X12: =U12*W12 -> 0 | Y12: =Q12 -> 0 | Z12: =+Y12*R12 -> 0 | AA12: EUR | AB12: =IFERROR(VLOOKUP(AA12,Curr!$B$2:$C$13,2,FALSE),0) -> 11.2 | AC12: =+Y12*AB12*R12 -> 0 | AD12: =+AC12-X12 -> 0 | AE12: =IFERROR(AD12/AC12,0) -> 0
C13: Day 2 | D13: Activity | J13: Oslo: Norway in a Nutshell to Flåm - Time: 08:00 am - 2:00 pm - Meeting point: Oslo Central Station - Includes: Train transfer Oslo to Myrdal, Train tranfser Myrdal to Flåm | O13: x | P13: https://www.fjordtours.com/en | Q13: 3280 | R13: 2 | S13: =+Q13*R13 -> 6560 | T13: 0.08 | U13: =S13*(1-T13) -> 6035.2 | V13: NOK | W13: =IFERROR(VLOOKUP(V13,Curr!$B$2:$C$13,2,FALSE),0) -> 1 | X13: =U13*W13 -> 6035.2 | Y13: =Q13/11.3/0.9 -> 322.51721 | Z13: =+Y13*R13 -> 645.03441 | AA13: EUR | AB13: =IFERROR(VLOOKUP(AA13,Curr!$B$2:$C$13,2,FALSE),0) -> 11.2 | AC13: =+Y13*AB13*R13 -> 7224.3854 | AD13: =+AC13-X13 -> 1189.1854 | AE13: =IFERROR(AD13/AC13,0) -> 0.16460714
C14: Day 2 | D14: Transfer | J14: Flåm: Self transfer to your accommodation | Q14: 0 | R14: 0 | S14: =+Q14*R14 -> 0 | T14: 0 | U14: =S14*(1-T14) -> 0 | V14: EUR | W14: =IFERROR(VLOOKUP(V14,Curr!$B$2:$C$13,2,FALSE),0) -> 11.2 | X14: =U14*W14 -> 0 | Y14: =Q14 -> 0 | Z14: =+Y14*R14 -> 0 | AA14: EUR | AB14: =IFERROR(VLOOKUP(AA14,Curr!$B$2:$C$13,2,FALSE),0) -> 11.2 | AC14: =+Y14*AB14*R14 -> 0 | AD14: =+AC14-X14 -> 0 | AE14: =IFERROR(AD14/AC14,0) -> 0
C15: Day 2 | D15: Hotel | J15: Flåm: Check in to your accommodation for a 1 night stay - Centrally located 3/4-star hotel - Standard Room - Breakfast included | Q15: 225 | R15: 1 | S15: =+Q15*R15 -> 225 | T15: 0 | U15: =S15*(1-T15) -> 225 | V15: EUR | W15: =IFERROR(VLOOKUP(V15,Curr!$B$2:$C$13,2,FALSE),0) -> 11.2 | X15: =U15*W15 -> 2520 | Y15: =Q15/0.85 -> 264.70588 | Z15: =+Y15*R15 -> 264.70588 | AA15: EUR | AB15: =IFERROR(VLOOKUP(AA15,Curr!$B$2:$C$13,2,FALSE),0) -> 11.2 | AC15: =+Y15*AB15*R15 -> 2964.7059 | AD15: =+AC15-X15 -> 444.70588 | AE15: =IFERROR(AD15/AC15,0) -> 0.15
C16: Day 2 | D16: Leisure | J16: Flåm: Spend time at leisure | Q16: 0 | R16: 0 | S16: =+Q16*R16 -> 0 | T16: 0 | U16: =S16*(1-T16) -> 0 | V16: EUR | W16: =IFERROR(VLOOKUP(V16,Curr!$B$2:$C$13,2,FALSE),0) -> 11.2 | X16: =U16*W16 -> 0 | Y16: =Q16 -> 0 | Z16: =+Y16*R16 -> 0 | AA16: EUR | AB16: =IFERROR(VLOOKUP(AA16,Curr!$B$2:$C$13,2,FALSE),0) -> 11.2 | AC16: =+Y16*AB16*R16 -> 0 | AD16: =+AC16-X16 -> 0 | AE16: =IFERROR(AD16/AC16,0) -> 0
S17: =+Q17*R17 -> 0 | T17: 0 | U17: =S17*(1-T17) -> 0 | V17: EUR | W17: =IFERROR(VLOOKUP(V17,Curr!$B$2:$C$13,2,FALSE),0) -> 11.2 | X17: =U17*W17 -> 0 | Y17: =Q17 -> 0 | Z17: =+Y17*R17 -> 0 | AA17: EUR | AB17: =IFERROR(VLOOKUP(AA17,Curr!$B$2:$C$13,2,FALSE),0) -> 11.2 | AC17: =+Y17*AB17*R17 -> 0 | AD17: =+AC17-X17 -> 0 | AE17: =IFERROR(AD17/AC17,0) -> 0
C18: Day 3 | D18: Transfer | J18: Flåm: Self transfer to Flåm Harbor | Q18: 0 | R18: 0 | S18: =+Q18*R18 -> 0 | T18: 0 | U18: =S18*(1-T18) -> 0 | V18: EUR | W18: =IFERROR(VLOOKUP(V18,Curr!$B$2:$C$13,2,FALSE),0) -> 11.2 | X18: =U18*W18 -> 0 | Y18: =Q18 -> 0 | Z18: =+Y18*R18 -> 0 | AA18: EUR | AB18: =IFERROR(VLOOKUP(AA18,Curr!$B$2:$C$13,2,FALSE),0) -> 11.2 | AC18: =+Y18*AB18*R18 -> 0 | AD18: =+AC18-X18 -> 0 | AE18: =IFERROR(AD18/AC18,0) -> 0
C19: Day 3 | D19: Activity | J19: Flåm: Norway in a Nutshell to Bergen - Time: - Meeting point: Flåm Harbor - Includes: Fjord Cruise Flåm to Gudvangen, Coach Transfer Gudvangen to Voss, Train transfer Voss to Bergen | O19: x | P19: https://www.fjordtours.com/en | Q19: 0 | R19: 0 | S19: =+Q19*R19 -> 0 | T19: 0.08 | U19: =S19*(1-T19) -> 0 | V19: NOK | W19: =IFERROR(VLOOKUP(V19,Curr!$B$2:$C$13,2,FALSE),0) -> 1 | X19: =U19*W19 -> 0 | Y19: =Q19/11.3/0.9 -> 0 | Z19: =+Y19*R19 -> 0 | AA19: EUR | AB19: =IFERROR(VLOOKUP(AA19,Curr!$B$2:$C$13,2,FALSE),0) -> 11.2 | AC19: =+Y19*AB19*R19 -> 0 | AD19: =+AC19-X19 -> 0 | AE19: =IFERROR(AD19/AC19,0) -> 0
C20: Day 3 | D20: Transfer | J20: Bergen: Self transfer to your accommodation | Q20: 0 | R20: 0 | S20: =+Q20*R20 -> 0 | T20: 0 | U20: =S20*(1-T20) -> 0 | V20: EUR | W20: =IFERROR(VLOOKUP(V20,Curr!$B$2:$C$13,2,FALSE),0) -> 11.2 | X20: =U20*W20 -> 0 | Y20: =Q20 -> 0 | Z20: =+Y20*R20 -> 0 | AA20: EUR | AB20: =IFERROR(VLOOKUP(AA20,Curr!$B$2:$C$13,2,FALSE),0) -> 11.2 | AC20: =+Y20*AB20*R20 -> 0 | AD20: =+AC20-X20 -> 0 | AE20: =IFERROR(AD20/AC20,0) -> 0
C21: Day 3 | D21: Hotel | J21: Bergen: Check in to your accommodation for a 2 night stay - Centrally located 3/4-star hotel - Standard Room - Breakfast included | Q21: 290 | R21: 1 | S21: =+Q21*R21 -> 290 | T21: 0 | U21: =S21*(1-T21) -> 290 | V21: EUR | W21: =IFERROR(VLOOKUP(V21,Curr!$B$2:$C$13,2,FALSE),0) -> 11.2 | X21: =U21*W21 -> 3248 | Y21: =Q21/0.85 -> 341.17647 | Z21: =+Y21*R21 -> 341.17647 | AA21: EUR | AB21: =IFERROR(VLOOKUP(AA21,Curr!$B$2:$C$13,2,FALSE),0) -> 11.2 | AC21: =+Y21*AB21*R21 -> 3821.1765 | AD21: =+AC21-X21 -> 573.17647 | AE21: =IFERROR(AD21/AC21,0) -> 0.15
C22: Day 3 | D22: Leisure | J22: Bergen: Spend time at leisure | Q22: 0 | R22: 0 | S22: =+Q22*R22 -> 0 | T22: 0 | U22: =S22*(1-T22) -> 0 | V22: EUR | W22: =IFERROR(VLOOKUP(V22,Curr!$B$2:$C$13,2,FALSE),0) -> 11.2 | X22: =U22*W22 -> 0 | Y22: =Q22 -> 0 | Z22: =+Y22*R22 -> 0 | AA22: EUR | AB22: =IFERROR(VLOOKUP(AA22,Curr!$B$2:$C$13,2,FALSE),0) -> 11.2 | AC22: =+Y22*AB22*R22 -> 0 | AD22: =+AC22-X22 -> 0 | AE22: =IFERROR(AD22/AC22,0) -> 0
S23: =+Q23*R23 -> 0 | T23: 0 | U23: =S23*(1-T23) -> 0 | V23: EUR | W23: =IFERROR(VLOOKUP(V23,Curr!$B$2:$C$13,2,FALSE),0) -> 11.2 | X23: =U23*W23 -> 0 | Y23: =Q23 -> 0 | Z23: =+Y23*R23 -> 0 | AA23: EUR | AB23: =IFERROR(VLOOKUP(AA23,Curr!$B$2:$C$13,2,FALSE),0) -> 11.2 | AC23: =+Y23*AB23*R23 -> 0 | AD23: =+AC23-X23 -> 0 | AE23: =IFERROR(AD23/AC23,0) -> 0
C24: Day 4 | D24: Activity | J24: Bergen: 2 hr walk Through Bergen Past & Present - Time: 10:00 am - 12:00 pm - Meeting point: Bradbenken 1 - Includes: Profesional Guide | O24: x | P24: https://www.ilovebergen.net/tour/a-walk-through-bergen-past-present/ | Q24: 290 | R24: 2 | S24: =+Q24*R24 -> 580 | T24: 0.2 | U24: =S24*(1-T24) -> 464 | V24: NOK | W24: =IFERROR(VLOOKUP(V24,Curr!$B$2:$C$13,2,FALSE),0) -> 1 | X24: =U24*W24 -> 464 | Y24: =Q24/11.3/0.64 -> 40.099558 | Z24: =+Y24*R24 -> 80.199115 | AA24: EUR | AB24: =IFERROR(VLOOKUP(AA24,Curr!$B$2:$C$13,2,FALSE),0) -> 11.2 | AC24: =+Y24*AB24*R24 -> 898.23009 | AD24: =+AC24-X24 -> 434.23009 | AE24: =IFERROR(AD24/AC24,0) -> 0.48342857
C25: Day 4 | D25: Activity | J25: Bergen: Fløibanen Funicual - Time: Flexible - Meeting point: Vetrlidsallmenningen 23A - Includes: Tickets | O25: x | P25: https://www.floyen.no/en/floibanen/buy-tickets/ | Q25: 175 | R25: 2 | S25: =+Q25*R25 -> 350 | T25: 0 | U25: =S25*(1-T25) -> 350 | V25: NOK | W25: =IFERROR(VLOOKUP(V25,Curr!$B$2:$C$13,2,FALSE),0) -> 1 | X25: =U25*W25 -> 350 | Y25: =Q25/11.3/0.5 -> 30.973451 | Z25: =+Y25*R25 -> 61.946903 | AA25: EUR | AB25: =IFERROR(VLOOKUP(AA25,Curr!$B$2:$C$13,2,FALSE),0) -> 11.2 | AC25: =+Y25*AB25*R25 -> 693.80531 | AD25: =+AC25-X25 -> 343.80531 | AE25: =IFERROR(AD25/AC25,0) -> 0.49553571
C26: Day 4 | D26: Leisure | J26: Bergen: Spend time at leisure | Q26: 0 | R26: 0 | S26: =+Q26*R26 -> 0 | T26: 0 | U26: =S26*(1-T26) -> 0 | V26: EUR | W26: =IFERROR(VLOOKUP(V26,Curr!$B$2:$C$13,2,FALSE),0) -> 11.2 | X26: =U26*W26 -> 0 | Y26: =Q26 -> 0 | Z26: =+Y26*R26 -> 0 | AA26: EUR | AB26: =IFERROR(VLOOKUP(AA26,Curr!$B$2:$C$13,2,FALSE),0) -> 11.2 | AC26: =+Y26*AB26*R26 -> 0 | AD26: =+AC26-X26 -> 0 | AE26: =IFERROR(AD26/AC26,0) -> 0
S27: =+Q27*R27 -> 0 | T27: 0 | U27: =S27*(1-T27) -> 0 | V27: EUR | W27: =IFERROR(VLOOKUP(V27,Curr!$B$2:$C$13,2,FALSE),0) -> 11.2 | X27: =U27*W27 -> 0 | Y27: =Q27 -> 0 | Z27: =+Y27*R27 -> 0 | AA27: EUR | AB27: =IFERROR(VLOOKUP(AA27,Curr!$B$2:$C$13,2,FALSE),0) -> 11.2 | AC27: =+Y27*AB27*R27 -> 0 | AD27: =+AC27-X27 -> 0 | AE27: =IFERROR(AD27/AC27,0) -> 0
C28: Day 5 | D28: Transfer | J28: Bergen: Self transfer to Bergen Airport | Q28: 0 | R28: 0 | S28: =+Q28*R28 -> 0 | T28: 0 | U28: =S28*(1-T28) -> 0 | V28: EUR | W28: =IFERROR(VLOOKUP(V28,Curr!$B$2:$C$13,2,FALSE),0) -> 11.2 | X28: =U28*W28 -> 0 | Y28: =Q28 -> 0 | Z28: =+Y28*R28 -> 0 | AA28: EUR | AB28: =IFERROR(VLOOKUP(AA28,Curr!$B$2:$C$13,2,FALSE),0) -> 11.2 | AC28: =+Y28*AB28*R28 -> 0 | AD28: =+AC28-X28 -> 0 | AE28: =IFERROR(AD28/AC28,0) -> 0
C29: Day 5 | D29: Flight | J29: Bergen: Flight to Tromsø - Time: Date dependant - Luggage included: 1 x 23 kg check in and 1 x 8 kg carry on per person | O29: x | Q29: 1800 | R29: 2 | S29: =+Q29*R29 -> 3600 | T29: 0 | U29: =S29*(1-T29) -> 3600 | V29: NOK | W29: =IFERROR(VLOOKUP(V29,Curr!$B$2:$C$13,2,FALSE),0) -> 1 | X29: =U29*W29 -> 3600 | Y29: =Q29/11.3/0.8 -> 199.11504 | Z29: =+Y29*R29 -> 398.23009 | AA29: EUR | AB29: =IFERROR(VLOOKUP(AA29,Curr!$B$2:$C$13,2,FALSE),0) -> 11.2 | AC29: =+Y29*AB29*R29 -> 4460.177 | AD29: =+AC29-X29 -> 860.17699 | AE29: =IFERROR(AD29/AC29,0) -> 0.19285714
C30: Day 5 | D30: Transfer | J30: Tromsø: Self transfer to your accommodation | Q30: 0 | R30: 0 | S30: =+Q30*R30 -> 0 | T30: 0 | U30: =S30*(1-T30) -> 0 | V30: NOK | W30: =IFERROR(VLOOKUP(V30,Curr!$B$2:$C$13,2,FALSE),0) -> 1 | X30: =U30*W30 -> 0 | Y30: =Q30/11.3/0.8 -> 0 | Z30: =+Y30*R30 -> 0 | AA30: EUR | AB30: =IFERROR(VLOOKUP(AA30,Curr!$B$2:$C$13,2,FALSE),0) -> 11.2 | AC30: =+Y30*AB30*R30 -> 0 | AD30: =+AC30-X30 -> 0 | AE30: =IFERROR(AD30/AC30,0) -> 0
C31: Day 5 | D31: Hotel | J31: Tromsø: Check in to your accommodation for a 3 night stay - Centrally located 3/4-star hotel - Standard Room - Breakfast included | Q31: 700 | R31: 1 | S31: =+Q31*R31 -> 700 | T31: 0 | U31: =S31*(1-T31) -> 700 | V31: EUR | W31: =IFERROR(VLOOKUP(V31,Curr!$B$2:$C$13,2,FALSE),0) -> 11.2 | X31: =U31*W31 -> 7840 | Y31: =Q31/0.85 -> 823.52941 | Z31: =+Y31*R31 -> 823.52941 | AA31: EUR | AB31: =IFERROR(VLOOKUP(AA31,Curr!$B$2:$C$13,2,FALSE),0) -> 11.2 | AC31: =+Y31*AB31*R31 -> 9223.5294 | AD31: =+AC31-X31 -> 1383.5294 | AE31: =IFERROR(AD31/AC31,0) -> 0.15
C32: Day 5 | D32: Leisure | J32: Tromsø: Spend time at leisure | Q32: 0 | R32: 0 | S32: =+Q32*R32 -> 0 | T32: 0 | U32: =S32*(1-T32) -> 0 | V32: EUR | W32: =IFERROR(VLOOKUP(V32,Curr!$B$2:$C$13,2,FALSE),0) -> 11.2 | X32: =U32*W32 -> 0 | Y32: =Q32 -> 0 | Z32: =+Y32*R32 -> 0 | AA32: EUR | AB32: =IFERROR(VLOOKUP(AA32,Curr!$B$2:$C$13,2,FALSE),0) -> 11.2 | AC32: =+Y32*AB32*R32 -> 0 | AD32: =+AC32-X32 -> 0 | AE32: =IFERROR(AD32/AC32,0) -> 0
C33: Day 5 | D33: Activity | J33: Tromsø: Northern Lights Cruise with Silent Electric Ship - Time: 7:00 pm - 10:00 pm - Meeting point: Kaigata 6 - Includes: Departure from central Tromsø, 3-hour fjord cruise, Light meal (soup and bread) and water, English speaking guides, Warm indoor saloons, Free wifi, Toilets | O33: x | P33: https://booknordics.com/norway/northern-norway/tromso-region/northern-lights-cruise-electric-ship | Q33: 105 | R33: 2 | S33: =+Q33*R33 -> 210 | T33: 0.2 | U33: =S33*(1-T33) -> 168 | V33: EUR | W33: =IFERROR(VLOOKUP(V33,Curr!$B$2:$C$13,2,FALSE),0) -> 11.2 | X33: =U33*W33 -> 1881.6 | Y33: =Q33 -> 105 | Z33: =+Y33*R33 -> 210 | AA33: EUR | AB33: =IFERROR(VLOOKUP(AA33,Curr!$B$2:$C$13,2,FALSE),0) -> 11.2 | AC33: =+Y33*AB33*R33 -> 2352 | AD33: =+AC33-X33 -> 470.4 | AE33: =IFERROR(AD33/AC33,0) -> 0.2
S34: =+Q34*R34 -> 0 | T34: 0 | U34: =S34*(1-T34) -> 0 | V34: EUR | W34: =IFERROR(VLOOKUP(V34,Curr!$B$2:$C$13,2,FALSE),0) -> 11.2 | X34: =U34*W34 -> 0 | Y34: =Q34 -> 0 | Z34: =+Y34*R34 -> 0 | AA34: EUR | AB34: =IFERROR(VLOOKUP(AA34,Curr!$B$2:$C$13,2,FALSE),0) -> 11.2 | AC34: =+Y34*AB34*R34 -> 0 | AD34: =+AC34-X34 -> 0 | AE34: =IFERROR(AD34/AC34,0) -> 0
C35: Day 6 | D35: Activity | J35: Tromsø: Reindeer Feeding and Sámi Culture - Time: 09:45 am - 2:30 pm - Meeting point: Radisson Blu Hotel's main entrance (Sjøgata 7) - Includes: Scenic transfers (45 min each way), Knowledgeable English and Norwegian speaking guide, Feeding the herd at our camp, Hot beverages and hot meal (traditional Sámi stew or vegetable/lentil soup), Cultural introduction about Sámi history and daily life, A chance to see the northern lights from our camp, Thermal suit and warm snow boots | O35: x | P35: https://www.tromsolapland.no/activities/reindeer-feeding-and-sami-culture | Q35: 1695 | R35: 2 | S35: =+Q35*R35 -> 3390 | T35: 0.2 | U35: =S35*(1-T35) -> 2712 | V35: NOK | W35: =IFERROR(VLOOKUP(V35,Curr!$B$2:$C$13,2,FALSE),0) -> 1 | X35: =U35*W35 -> 2712 | Y35: =Q35/11.3 -> 150 | Z35: =+Y35*R35 -> 300 | AA35: EUR | AB35: =IFERROR(VLOOKUP(AA35,Curr!$B$2:$C$13,2,FALSE),0) -> 11.2 | AC35: =+Y35*AB35*R35 -> 3360 | AD35: =+AC35-X35 -> 648 | AE35: =IFERROR(AD35/AC35,0) -> 0.19285714
C36: Day 6 | D36: Leisure | J36: Tromsø: Spend time at leisure | Q36: 0 | R36: 0 | S36: =+Q36*R36 -> 0 | T36: 0 | U36: =S36*(1-T36) -> 0 | V36: EUR | W36: =IFERROR(VLOOKUP(V36,Curr!$B$2:$C$13,2,FALSE),0) -> 11.2 | X36: =U36*W36 -> 0 | Y36: =Q36 -> 0 | Z36: =+Y36*R36 -> 0 | AA36: EUR | AB36: =IFERROR(VLOOKUP(AA36,Curr!$B$2:$C$13,2,FALSE),0) -> 11.2 | AC36: =+Y36*AB36*R36 -> 0 | AD36: =+AC36-X36 -> 0 | AE36: =IFERROR(AD36/AC36,0) -> 0
C37: Day 6 | D37: Activity | J37: Tromsø: All-Evening Northern Lights Hunt by Minibus or Bus - Time: 7:00 pm - 12:00 am - Meeting point: Kaigata 4 - Includes: Knowledgeable, English-speaking guides, Photos shared with you after the tour, Thermo clothing and warm gear, Light snacks and warm/cold beverages, Drop-off at hotel, up to 5 km from Tromsø | O37: x | P37: https://booknordics.com/norway/northern-norway/tromso-region/full-day-magic-of-the-arctic-lights-in-tromso | Q37: 120 | R37: 2 | S37: =+Q37*R37 -> 240 | T37: 0.2 | U37: =S37*(1-T37) -> 192 | V37: EUR | W37: =IFERROR(VLOOKUP(V37,Curr!$B$2:$C$13,2,FALSE),0) -> 11.2 | X37: =U37*W37 -> 2150.4 | Y37: =Q37 -> 120 | Z37: =+Y37*R37 -> 240 | AA37: EUR | AB37: =IFERROR(VLOOKUP(AA37,Curr!$B$2:$C$13,2,FALSE),0) -> 11.2 | AC37: =+Y37*AB37*R37 -> 2688 | AD37: =+AC37-X37 -> 537.6 | AE37: =IFERROR(AD37/AC37,0) -> 0.2
S38: =+Q38*R38 -> 0 | T38: 0 | U38: =S38*(1-T38) -> 0 | V38: EUR | W38: =IFERROR(VLOOKUP(V38,Curr!$B$2:$C$13,2,FALSE),0) -> 11.2 | X38: =U38*W38 -> 0 | Y38: =Q38 -> 0 | Z38: =+Y38*R38 -> 0 | AA38: EUR | AB38: =IFERROR(VLOOKUP(AA38,Curr!$B$2:$C$13,2,FALSE),0) -> 11.2 | AC38: =+Y38*AB38*R38 -> 0 | AD38: =+AC38-X38 -> 0 | AE38: =IFERROR(AD38/AC38,0) -> 0
C39: Day 7 | D39: Activity | J39: Tromsø: Photo Tour to Arctic Landscapes and Fjords - Time: 10:00 am - 3:00 pm - Meeting point: Roald Amundsens plass 1A - Includes: Departure from central Tromsø. Drop-off to your hotel, Professional, English-speaking photo guides, Scenic fjord safari by comfortable minivan vehicle, Help with camera settings and nature photography, Usually a small-group experience with 4-8 guests, Soup or expedition food, coffee and waffles/cookies | O39: x | P39: https://booknordics.com/norway/northern-norway/tromso-region/tromso-fjord-photo-tour | Q39: 145 | R39: 2 | S39: =+Q39*R39 -> 290 | T39: 0.2 | U39: =S39*(1-T39) -> 232 | V39: EUR | W39: =IFERROR(VLOOKUP(V39,Curr!$B$2:$C$13,2,FALSE),0) -> 11.2 | X39: =U39*W39 -> 2598.4 | Y39: =Q39 -> 145 | Z39: =+Y39*R39 -> 290 | AA39: EUR | AB39: =IFERROR(VLOOKUP(AA39,Curr!$B$2:$C$13,2,FALSE),0) -> 11.2 | AC39: =+Y39*AB39*R39 -> 3248 | AD39: =+AC39-X39 -> 649.6 | AE39: =IFERROR(AD39/AC39,0) -> 0.2
C40: Day 7 | D40: Leisure | J40: Tromsø: Spend time at leisure | Q40: 0 | R40: 0 | S40: =+Q40*R40 -> 0 | T40: 0 | U40: =S40*(1-T40) -> 0 | V40: EUR | W40: =IFERROR(VLOOKUP(V40,Curr!$B$2:$C$13,2,FALSE),0) -> 11.2 | X40: =U40*W40 -> 0 | Y40: =Q40 -> 0 | Z40: =+Y40*R40 -> 0 | AA40: EUR | AB40: =IFERROR(VLOOKUP(AA40,Curr!$B$2:$C$13,2,FALSE),0) -> 11.2 | AC40: =+Y40*AB40*R40 -> 0 | AD40: =+AC40-X40 -> 0 | AE40: =IFERROR(AD40/AC40,0) -> 0
S41: =+Q41*R41 -> 0 | T41: 0 | U41: =S41*(1-T41) -> 0 | V41: EUR | W41: =IFERROR(VLOOKUP(V41,Curr!$B$2:$C$13,2,FALSE),0) -> 11.2 | X41: =U41*W41 -> 0 | Y41: =Q41 -> 0 | Z41: =+Y41*R41 -> 0 | AA41: EUR | AB41: =IFERROR(VLOOKUP(AA41,Curr!$B$2:$C$13,2,FALSE),0) -> 11.2 | AC41: =+Y41*AB41*R41 -> 0 | AD41: =+AC41-X41 -> 0 | AE41: =IFERROR(AD41/AC41,0) -> 0
...

Sheet 203
B1: Season: Winter
B2: Places: Oslo 1N - Bergen 2N - Tromsø 2N - Lyngen 1N - Tromsø 1N
B3: Pax: 2
B4: Rooming: Double
B6: ID | C6: Day | D6: Type | E6: From date | F6: To date | G6: From time | H6: To time | I6: Supplier | J6: Travel element | K6: Manual booking? | L6: Status | M6: Comments | N6: Non-refundable | O6: Refundable | P6: URL | Q6: Gross P per unit | R6: Units | S6: Gross P | T6: Supp Comm | U6: Net P | V6: Supp curr | W6: X-rate | X6: Net P NOK | Y6: Sales P per unit | Z6: Price | AA6: Sales curr | AB6: X-rate | AC6: Sales P NOK tot | AD6: GP NOK | AE6: GP % | AF6: VAT25 | AG6: VAT15 | AH6: VAT12 | AI6: VAT0-D | AJ6: VAT0-I
C7: Day 1 | D7: Arrival | J7: Oslo: Welcome to Norway | Q7: 0 | R7: 0 | S7: =+Q7*R7 -> 0 | T7: 0 | U7: =S7*(1-T7) -> 0 | V7: EUR | W7: =IFERROR(VLOOKUP(V7,Curr!$B$2:$C$13,2,FALSE),0) -> 11.2 | X7: =U7*W7 -> 0 | Y7: =Q7 -> 0 | Z7: =+Y7*R7 -> 0 | AA7: EUR | AB7: =IFERROR(VLOOKUP(AA7,Curr!$B$2:$C$13,2,FALSE),0) -> 11.2 | AC7: =+Y7*AB7*R7 -> 0 | AD7: =+AC7-X7 -> 0 | AE7: =IFERROR(AD7/AC7,0) -> 0
C8: Day 1 | D8: Transfer | J8: Oslo: Self transfer to your accommodation | Q8: 0 | R8: 0 | S8: =+Q8*R8 -> 0 | T8: 0 | U8: =S8*(1-T8) -> 0 | V8: NOK | W8: =IFERROR(VLOOKUP(V8,Curr!$B$2:$C$13,2,FALSE),0) -> 1 | X8: =U8*W8 -> 0 | Y8: =Q8/11.3/0.8 -> 0 | Z8: =+Y8*R8 -> 0 | AA8: EUR | AB8: =IFERROR(VLOOKUP(AA8,Curr!$B$2:$C$13,2,FALSE),0) -> 11.2 | AC8: =+Y8*AB8*R8 -> 0 | AD8: =+AC8-X8 -> 0 | AE8: =IFERROR(AD8/AC8,0) -> 0
C9: Day 1 | D9: Hotel | J9: Oslo: Check in to your accommodation for a 1 night stay - Centrally located 3/4-star hotel - Standard Room - Breakfast included | Q9: 150 | R9: 1 | S9: =+Q9*R9 -> 150 | T9: 0 | U9: =S9*(1-T9) -> 150 | V9: EUR | W9: =IFERROR(VLOOKUP(V9,Curr!$B$2:$C$13,2,FALSE),0) -> 11.2 | X9: =U9*W9 -> 1680 | Y9: =Q9/0.85 -> 176.47059 | Z9: =+Y9*R9 -> 176.47059 | AA9: EUR | AB9: =IFERROR(VLOOKUP(AA9,Curr!$B$2:$C$13,2,FALSE),0) -> 11.2 | AC9: =+Y9*AB9*R9 -> 1976.4706 | AD9: =+AC9-X9 -> 296.47059 | AE9: =IFERROR(AD9/AC9,0) -> 0.15
C10: Day 1 | D10: Leisure | J10: Oslo: Spend time at leisure | Q10: 0 | R10: 0 | S10: =+Q10*R10 -> 0 | T10: 0 | U10: =S10*(1-T10) -> 0 | V10: EUR | W10: =IFERROR(VLOOKUP(V10,Curr!$B$2:$C$13,2,FALSE),0) -> 11.2 | X10: =U10*W10 -> 0 | Y10: =Q10 -> 0 | Z10: =+Y10*R10 -> 0 | AA10: EUR | AB10: =IFERROR(VLOOKUP(AA10,Curr!$B$2:$C$13,2,FALSE),0) -> 11.2 | AC10: =+Y10*AB10*R10 -> 0 | AD10: =+AC10-X10 -> 0 | AE10: =IFERROR(AD10/AC10,0) -> 0
S11: =+Q11*R11 -> 0 | T11: 0 | U11: =S11*(1-T11) -> 0 | V11: EUR | W11: =IFERROR(VLOOKUP(V11,Curr!$B$2:$C$13,2,FALSE),0) -> 11.2 | X11: =U11*W11 -> 0 | Y11: =Q11 -> 0 | Z11: =+Y11*R11 -> 0 | AA11: EUR | AB11: =IFERROR(VLOOKUP(AA11,Curr!$B$2:$C$13,2,FALSE),0) -> 11.2 | AC11: =+Y11*AB11*R11 -> 0 | AD11: =+AC11-X11 -> 0 | AE11: =IFERROR(AD11/AC11,0) -> 0
C12: Day 2 | D12: Transfer | J12: Oslo: Self transfer to Oslo Central Station | Q12: 0 | R12: 0 | S12: =+Q12*R12 -> 0 | T12: 0 | U12: =S12*(1-T12) -> 0 | V12: EUR | W12: =IFERROR(VLOOKUP(V12,Curr!$B$2:$C$13,2,FALSE),0) -> 11.2 | X12: =U12*W12 -> 0 | Y12: =Q12 -> 0 | Z12: =+Y12*R12 -> 0 | AA12: EUR | AB12: =IFERROR(VLOOKUP(AA12,Curr!$B$2:$C$13,2,FALSE),0) -> 11.2 | AC12: =+Y12*AB12*R12 -> 0 | AD12: =+AC12-X12 -> 0 | AE12: =IFERROR(AD12/AC12,0) -> 0
C13: Day 2 | D13: Train | J13: Oslo: Scenic Long Distance Train transfer to Bergen - Time: 08:25 am - 3:00 pm - Includes: Tickets | O13: x | P13: https://www.vy.no/#reisesok | Q13: 2400 | R13: 1 | S13: =+Q13*R13 -> 2400 | T13: 0 | U13: =S13*(1-T13) -> 2400 | V13: NOK | W13: =IFERROR(VLOOKUP(V13,Curr!$B$2:$C$13,2,FALSE),0) -> 1 | X13: =U13*W13 -> 2400 | Y13: =Q13/11.3/0.8 -> 265.48673 | Z13: =+Y13*R13 -> 265.48673 | AA13: EUR | AB13: =IFERROR(VLOOKUP(AA13,Curr!$B$2:$C$13,2,FALSE),0) -> 11.2 | AC13: =+Y13*AB13*R13 -> 2973.4513 | AD13: =+AC13-X13 -> 573.45133 | AE13: =IFERROR(AD13/AC13,0) -> 0.19285714
C14: Day 2 | D14: Transfer | J14: Bergen: Self transfer to your accommodation | Q14: 0 | R14: 0 | S14: =+Q14*R14 -> 0 | T14: 0 | U14: =S14*(1-T14) -> 0 | V14: EUR | W14: =IFERROR(VLOOKUP(V14,Curr!$B$2:$C$13,2,FALSE),0) -> 11.2 | X14: =U14*W14 -> 0 | Y14: =Q14 -> 0 | Z14: =+Y14*R14 -> 0 | AA14: EUR | AB14: =IFERROR(VLOOKUP(AA14,Curr!$B$2:$C$13,2,FALSE),0) -> 11.2 | AC14: =+Y14*AB14*R14 -> 0 | AD14: =+AC14-X14 -> 0 | AE14: =IFERROR(AD14/AC14,0) -> 0
C15: Day 2 | D15: Hotel | J15: Bergen: Check in to your accommodation for a 2 night stay - Centrally located 3/4-star hotel - Standard Room - Breakfast included | Q15: 280 | R15: 1 | S15: =+Q15*R15 -> 280 | T15: 0 | U15: =S15*(1-T15) -> 280 | V15: EUR | W15: =IFERROR(VLOOKUP(V15,Curr!$B$2:$C$13,2,FALSE),0) -> 11.2 | X15: =U15*W15 -> 3136 | Y15: =Q15/0.85 -> 329.41176 | Z15: =+Y15*R15 -> 329.41176 | AA15: EUR | AB15: =IFERROR(VLOOKUP(AA15,Curr!$B$2:$C$13,2,FALSE),0) -> 11.2 | AC15: =+Y15*AB15*R15 -> 3689.4118 | AD15: =+AC15-X15 -> 553.41176 | AE15: =IFERROR(AD15/AC15,0) -> 0.15
C16: Day 2 | D16: Leisure | J16: Bergen: Spend time at leisure | Q16: 0 | R16: 0 | S16: =+Q16*R16 -> 0 | T16: 0 | U16: =S16*(1-T16) -> 0 | V16: EUR | W16: =IFERROR(VLOOKUP(V16,Curr!$B$2:$C$13,2,FALSE),0) -> 11.2 | X16: =U16*W16 -> 0 | Y16: =Q16 -> 0 | Z16: =+Y16*R16 -> 0 | AA16: EUR | AB16: =IFERROR(VLOOKUP(AA16,Curr!$B$2:$C$13,2,FALSE),0) -> 11.2 | AC16: =+Y16*AB16*R16 -> 0 | AD16: =+AC16-X16 -> 0 | AE16: =IFERROR(AD16/AC16,0) -> 0
S17: =+Q17*R17 -> 0 | T17: 0 | U17: =S17*(1-T17) -> 0 | V17: EUR | W17: =IFERROR(VLOOKUP(V17,Curr!$B$2:$C$13,2,FALSE),0) -> 11.2 | X17: =U17*W17 -> 0 | Y17: =Q17 -> 0 | Z17: =+Y17*R17 -> 0 | AA17: EUR | AB17: =IFERROR(VLOOKUP(AA17,Curr!$B$2:$C$13,2,FALSE),0) -> 11.2 | AC17: =+Y17*AB17*R17 -> 0 | AD17: =+AC17-X17 -> 0 | AE17: =IFERROR(AD17/AC17,0) -> 0
C18: Day 3 | D18: Activity | J18: Bergen: 2 hr walk Through Bergen Past & Present - Time: 10:00 am - 12:00 pm - Meeting point: Bradbenken 1 - Includes: Profesional Guide | O18: x | P18: https://www.ilovebergen.net/tour/a-walk-through-bergen-past-present/ | Q18: 290 | R18: 2 | S18: =+Q18*R18 -> 580 | T18: 0.2 | U18: =S18*(1-T18) -> 464 | V18: NOK | W18: =IFERROR(VLOOKUP(V18,Curr!$B$2:$C$13,2,FALSE),0) -> 1 | X18: =U18*W18 -> 464 | Y18: =Q18/11.3/0.64 -> 40.099558 | Z18: =+Y18*R18 -> 80.199115 | AA18: EUR | AB18: =IFERROR(VLOOKUP(AA18,Curr!$B$2:$C$13,2,FALSE),0) -> 11.2 | AC18: =+Y18*AB18*R18 -> 898.23009 | AD18: =+AC18-X18 -> 434.23009 | AE18: =IFERROR(AD18/AC18,0) -> 0.48342857
C19: Day 3 | D19: Activity | J19: Bergen: Fløibanen Funicual - Time: Flexible - Meeting point: Vetrlidsallmenningen 23A - Includes: Tickets | O19: x | P19: https://www.floyen.no/en/floibanen/buy-tickets/ | Q19: 175 | R19: 2 | S19: =+Q19*R19 -> 350 | T19: 0 | U19: =S19*(1-T19) -> 350 | V19: NOK | W19: =IFERROR(VLOOKUP(V19,Curr!$B$2:$C$13,2,FALSE),0) -> 1 | X19: =U19*W19 -> 350 | Y19: =Q19/11.3/0.5 -> 30.973451 | Z19: =+Y19*R19 -> 61.946903 | AA19: EUR | AB19: =IFERROR(VLOOKUP(AA19,Curr!$B$2:$C$13,2,FALSE),0) -> 11.2 | AC19: =+Y19*AB19*R19 -> 693.80531 | AD19: =+AC19-X19 -> 343.80531 | AE19: =IFERROR(AD19/AC19,0) -> 0.49553571
C20: Day 3 | D20: Leisure | J20: Bergen: Spend time at leisure | Q20: 0 | R20: 0 | S20: =+Q20*R20 -> 0 | T20: 0 | U20: =S20*(1-T20) -> 0 | V20: EUR | W20: =IFERROR(VLOOKUP(V20,Curr!$B$2:$C$13,2,FALSE),0) -> 11.2 | X20: =U20*W20 -> 0 | Y20: =Q20 -> 0 | Z20: =+Y20*R20 -> 0 | AA20: EUR | AB20: =IFERROR(VLOOKUP(AA20,Curr!$B$2:$C$13,2,FALSE),0) -> 11.2 | AC20: =+Y20*AB20*R20 -> 0 | AD20: =+AC20-X20 -> 0 | AE20: =IFERROR(AD20/AC20,0) -> 0
S21: =+Q21*R21 -> 0 | T21: 0 | U21: =S21*(1-T21) -> 0 | V21: EUR | W21: =IFERROR(VLOOKUP(V21,Curr!$B$2:$C$13,2,FALSE),0) -> 11.2 | X21: =U21*W21 -> 0 | Y21: =Q21 -> 0 | Z21: =+Y21*R21 -> 0 | AA21: EUR | AB21: =IFERROR(VLOOKUP(AA21,Curr!$B$2:$C$13,2,FALSE),0) -> 11.2 | AC21: =+Y21*AB21*R21 -> 0 | AD21: =+AC21-X21 -> 0 | AE21: =IFERROR(AD21/AC21,0) -> 0
C22: Day 4 | D22: Transfer | J22: Bergen: Self transfer to Bergen Airport | Q22: 0 | R22: 0 | S22: =+Q22*R22 -> 0 | T22: 0 | U22: =S22*(1-T22) -> 0 | V22: EUR | W22: =IFERROR(VLOOKUP(V22,Curr!$B$2:$C$13,2,FALSE),0) -> 11.2 | X22: =U22*W22 -> 0 | Y22: =Q22 -> 0 | Z22: =+Y22*R22 -> 0 | AA22: EUR | AB22: =IFERROR(VLOOKUP(AA22,Curr!$B$2:$C$13,2,FALSE),0) -> 11.2 | AC22: =+Y22*AB22*R22 -> 0 | AD22: =+AC22-X22 -> 0 | AE22: =IFERROR(AD22/AC22,0) -> 0
C23: Day 4 | D23: Flight | J23: Bergen: Flight to Tromsø - Time: Date dependant - Luggage included: 1 x 23 kg check in and 1 x 8 kg carry on per person | O23: x | Q23: 1800 | R23: 2 | S23: =+Q23*R23 -> 3600 | T23: 0 | U23: =S23*(1-T23) -> 3600 | V23: NOK | W23: =IFERROR(VLOOKUP(V23,Curr!$B$2:$C$13,2,FALSE),0) -> 1 | X23: =U23*W23 -> 3600 | Y23: =Q23/11.3/0.8 -> 199.11504 | Z23: =+Y23*R23 -> 398.23009 | AA23: EUR | AB23: =IFERROR(VLOOKUP(AA23,Curr!$B$2:$C$13,2,FALSE),0) -> 11.2 | AC23: =+Y23*AB23*R23 -> 4460.177 | AD23: =+AC23-X23 -> 860.17699 | AE23: =IFERROR(AD23/AC23,0) -> 0.19285714
C24: Day 4 | D24: Transfer | J24: Tromsø: Self transfer to your accommodation | Q24: 0 | R24: 0 | S24: =+Q24*R24 -> 0 | T24: 0 | U24: =S24*(1-T24) -> 0 | V24: NOK | W24: =IFERROR(VLOOKUP(V24,Curr!$B$2:$C$13,2,FALSE),0) -> 1 | X24: =U24*W24 -> 0 | Y24: =Q24/11.3/0.8 -> 0 | Z24: =+Y24*R24 -> 0 | AA24: EUR | AB24: =IFERROR(VLOOKUP(AA24,Curr!$B$2:$C$13,2,FALSE),0) -> 11.2 | AC24: =+Y24*AB24*R24 -> 0 | AD24: =+AC24-X24 -> 0 | AE24: =IFERROR(AD24/AC24,0) -> 0
C25: Day 4 | D25: Hotel | J25: Tromsø: Check in to your accommodation for a 2 night stay - Centrally located 3/4-star hotel - Standard Room - Breakfast included | Q25: 500 | R25: 1 | S25: =+Q25*R25 -> 500 | T25: 0 | U25: =S25*(1-T25) -> 500 | V25: EUR | W25: =IFERROR(VLOOKUP(V25,Curr!$B$2:$C$13,2,FALSE),0) -> 11.2 | X25: =U25*W25 -> 5600 | Y25: =Q25/0.85 -> 588.23529 | Z25: =+Y25*R25 -> 588.23529 | AA25: EUR | AB25: =IFERROR(VLOOKUP(AA25,Curr!$B$2:$C$13,2,FALSE),0) -> 11.2 | AC25: =+Y25*AB25*R25 -> 6588.2353 | AD25: =+AC25-X25 -> 988.23529 | AE25: =IFERROR(AD25/AC25,0) -> 0.15
C26: Day 4 | D26: Leisure | J26: Tromsø: Spend time at leisure | Q26: 0 | R26: 0 | S26: =+Q26*R26 -> 0 | T26: 0 | U26: =S26*(1-T26) -> 0 | V26: EUR | W26: =IFERROR(VLOOKUP(V26,Curr!$B$2:$C$13,2,FALSE),0) -> 11.2 | X26: =U26*W26 -> 0 | Y26: =Q26 -> 0 | Z26: =+Y26*R26 -> 0 | AA26: EUR | AB26: =IFERROR(VLOOKUP(AA26,Curr!$B$2:$C$13,2,FALSE),0) -> 11.2 | AC26: =+Y26*AB26*R26 -> 0 | AD26: =+AC26-X26 -> 0 | AE26: =IFERROR(AD26/AC26,0) -> 0
C27: Day 4 | D27: Activity | J27: Tromsø: Northern Lights Cruise with Silent Electric Ship - Time: 7:00 pm - 10:00 pm - Meeting point: Kaigata 6 - Includes: Departure from central Tromsø, 3-hour fjord cruise, Light meal (soup and bread) and water, English speaking guides, Warm indoor saloons, Free wifi, Toilets | O27: x | P27: https://booknordics.com/norway/northern-norway/tromso-region/northern-lights-cruise-electric-ship | Q27: 105 | R27: 2 | S27: =+Q27*R27 -> 210 | T27: 0.2 | U27: =S27*(1-T27) -> 168 | V27: EUR | W27: =IFERROR(VLOOKUP(V27,Curr!$B$2:$C$13,2,FALSE),0) -> 11.2 | X27: =U27*W27 -> 1881.6 | Y27: =Q27 -> 105 | Z27: =+Y27*R27 -> 210 | AA27: EUR | AB27: =IFERROR(VLOOKUP(AA27,Curr!$B$2:$C$13,2,FALSE),0) -> 11.2 | AC27: =+Y27*AB27*R27 -> 2352 | AD27: =+AC27-X27 -> 470.4 | AE27: =IFERROR(AD27/AC27,0) -> 0.2
S28: =+Q28*R28 -> 0 | T28: 0 | U28: =S28*(1-T28) -> 0 | V28: EUR | W28: =IFERROR(VLOOKUP(V28,Curr!$B$2:$C$13,2,FALSE),0) -> 11.2 | X28: =U28*W28 -> 0 | Y28: =Q28 -> 0 | Z28: =+Y28*R28 -> 0 | AA28: EUR | AB28: =IFERROR(VLOOKUP(AA28,Curr!$B$2:$C$13,2,FALSE),0) -> 11.2 | AC28: =+Y28*AB28*R28 -> 0 | AD28: =+AC28-X28 -> 0 | AE28: =IFERROR(AD28/AC28,0) -> 0
C29: Day 5 | D29: Activity | J29: Tromsø: Reindeer Feeding and Sámi Culture - Time: 09:45 am - 2:30 pm - Meeting point: Radisson Blu Hotel's main entrance (Sjøgata 7) - Includes: Scenic transfers (45 min each way), Knowledgeable English and Norwegian speaking guide, Feeding the herd at our camp, Hot beverages and hot meal (traditional Sámi stew or vegetable/lentil soup), Cultural introduction about Sámi history and daily life, A chance to see the northern lights from our camp, Thermal suit and warm snow boots | O29: x | P29: https://www.tromsolapland.no/activities/reindeer-feeding-and-sami-culture | Q29: 1695 | R29: 2 | S29: =+Q29*R29 -> 3390 | T29: 0.2 | U29: =S29*(1-T29) -> 2712 | V29: NOK | W29: =IFERROR(VLOOKUP(V29,Curr!$B$2:$C$13,2,FALSE),0) -> 1 | X29: =U29*W29 -> 2712 | Y29: =Q29/11.3 -> 150 | Z29: =+Y29*R29 -> 300 | AA29: EUR | AB29: =IFERROR(VLOOKUP(AA29,Curr!$B$2:$C$13,2,FALSE),0) -> 11.2 | AC29: =+Y29*AB29*R29 -> 3360 | AD29: =+AC29-X29 -> 648 | AE29: =IFERROR(AD29/AC29,0) -> 0.19285714
C30: Day 5 | D30: Leisure | J30: Tromsø: Spend time at leisure | Q30: 0 | R30: 0 | S30: =+Q30*R30 -> 0 | T30: 0 | U30: =S30*(1-T30) -> 0 | V30: EUR | W30: =IFERROR(VLOOKUP(V30,Curr!$B$2:$C$13,2,FALSE),0) -> 11.2 | X30: =U30*W30 -> 0 | Y30: =Q30 -> 0 | Z30: =+Y30*R30 -> 0 | AA30: EUR | AB30: =IFERROR(VLOOKUP(AA30,Curr!$B$2:$C$13,2,FALSE),0) -> 11.2 | AC30: =+Y30*AB30*R30 -> 0 | AD30: =+AC30-X30 -> 0 | AE30: =IFERROR(AD30/AC30,0) -> 0
C31: Day 5 | D31: Activity | J31: Tromsø: All-Evening Northern Lights Hunt by Minibus or Bus - Time: 7:00 pm - 12:00 am - Meeting point: Kaigata 4 - Includes: Knowledgeable, English-speaking guides, Photos shared with you after the tour, Thermo clothing and warm gear, Light snacks and warm/cold beverages, Drop-off at hotel, up to 5 km from Tromsø | O31: x | P31: https://booknordics.com/norway/northern-norway/tromso-region/full-day-magic-of-the-arctic-lights-in-tromso | Q31: 120 | R31: 2 | S31: =+Q31*R31 -> 240 | T31: 0.2 | U31: =S31*(1-T31) -> 192 | V31: EUR | W31: =IFERROR(VLOOKUP(V31,Curr!$B$2:$C$13,2,FALSE),0) -> 11.2 | X31: =U31*W31 -> 2150.4 | Y31: =Q31 -> 120 | Z31: =+Y31*R31 -> 240 | AA31: EUR | AB31: =IFERROR(VLOOKUP(AA31,Curr!$B$2:$C$13,2,FALSE),0) -> 11.2 | AC31: =+Y31*AB31*R31 -> 2688 | AD31: =+AC31-X31 -> 537.6 | AE31: =IFERROR(AD31/AC31,0) -> 0.2
S32: =+Q32*R32 -> 0 | T32: 0 | U32: =S32*(1-T32) -> 0 | V32: EUR | W32: =IFERROR(VLOOKUP(V32,Curr!$B$2:$C$13,2,FALSE),0) -> 11.2 | X32: =U32*W32 -> 0 | Y32: =Q32 -> 0 | Z32: =+Y32*R32 -> 0 | AA32: EUR | AB32: =IFERROR(VLOOKUP(AA32,Curr!$B$2:$C$13,2,FALSE),0) -> 11.2 | AC32: =+Y32*AB32*R32 -> 0 | AD32: =+AC32-X32 -> 0 | AE32: =IFERROR(AD32/AC32,0) -> 0
C33: Day 6 | D33: Transfer | J33: Tromsø: Self transfer to Scandic Ishavs Hotel | Q33: 0 | R33: 0 | S33: =+Q33*R33 -> 0 | T33: 0 | U33: =S33*(1-T33) -> 0 | V33: EUR | W33: =IFERROR(VLOOKUP(V33,Curr!$B$2:$C$13,2,FALSE),0) -> 11.2 | X33: =U33*W33 -> 0 | Y33: =Q33 -> 0 | Z33: =+Y33*R33 -> 0 | AA33: EUR | AB33: =IFERROR(VLOOKUP(AA33,Curr!$B$2:$C$13,2,FALSE),0) -> 11.2 | AC33: =+Y33*AB33*R33 -> 0 | AD33: =+AC33-X33 -> 0 | AE33: =IFERROR(AD33/AC33,0) -> 0
C34: Day 6 | D34: Activity | J34: Tromsø: Crystal Lavvo Stay with Auroras, Meals & Activities - Time: 11:30 am - 10: 50 am (the next day) - Meeting point: Samuel Arnesens gate 5 - Includes: Pick-up/drop-off in Tromsø with scenic transfers, Comfortable overnight stay in crystal lavvo, Fireplace heating with unlimited firewood, Northern Lights hunt with photo workshop, Snowshoeing experience nearby, Lunch and dinner included on day 1, Bathroom/toilet facilities in the main house, Breakfast and return transfer included on day 2 | O34: x | P34: https://booknordics.com/norway/northern-norway/tromso-region/crystal-lavvy-stay-northern-lights-snowshoeing | Q34: 375 | R34: 2 | S34: =+Q34*R34 -> 750 | T34: 0.2 | U34: =S34*(1-T34) -> 600 | V34: EUR | W34: =IFERROR(VLOOKUP(V34,Curr!$B$2:$C$13,2,FALSE),0) -> 11.2 | X34: =U34*W34 -> 6720 | Y34: =Q34 -> 375 | Z34: =+Y34*R34 -> 750 | AA34: EUR | AB34: =IFERROR(VLOOKUP(AA34,Curr!$B$2:$C$13,2,FALSE),0) -> 11.2 | AC34: =+Y34*AB34*R34 -> 8400 | AD34: =+AC34-X34 -> 1680 | AE34: =IFERROR(AD34/AC34,0) -> 0.2
S35: =+Q35*R35 -> 0 | T35: 0 | U35: =S35*(1-T35) -> 0 | V35: EUR | W35: =IFERROR(VLOOKUP(V35,Curr!$B$2:$C$13,2,FALSE),0) -> 11.2 | X35: =U35*W35 -> 0 | Y35: =Q35 -> 0 | Z35: =+Y35*R35 -> 0 | AA35: EUR | AB35: =IFERROR(VLOOKUP(AA35,Curr!$B$2:$C$13,2,FALSE),0) -> 11.2 | AC35: =+Y35*AB35*R35 -> 0 | AD35: =+AC35-X35 -> 0 | AE35: =IFERROR(AD35/AC35,0) -> 0
C36: Day 7 | D36: Transfer | J36: Lyngen: Included transfer back to Central Tromsø | Q36: 0 | R36: 0 | S36: =+Q36*R36 -> 0 | T36: 0 | U36: =S36*(1-T36) -> 0 | V36: EUR | W36: =IFERROR(VLOOKUP(V36,Curr!$B$2:$C$13,2,FALSE),0) -> 11.2 | X36: =U36*W36 -> 0 | Y36: =Q36 -> 0 | Z36: =+Y36*R36 -> 0 | AA36: EUR | AB36: =IFERROR(VLOOKUP(AA36,Curr!$B$2:$C$13,2,FALSE),0) -> 11.2 | AC36: =+Y36*AB36*R36 -> 0 | AD36: =+AC36-X36 -> 0 | AE36: =IFERROR(AD36/AC36,0) -> 0
