Workbook

Sheet Curr
C1: NOK
B2: EUR | C2: 11
B3: SEK | C3: 1.02
B4: DKK | C4: 1.5
B5: ISK | C5: 0.075
B6: NOK | C6: 1
B7: USD | C7: 10.6

Sheet Oversikt
B3: D | C3: Day | F3: ITIN | G3: Page | H3: Cost | I3: Margin
B4: SD | C4: Self Drive | F4: 301 | G4: 5D SD | H4: ='5D SD'!Z51 -> 1468.75 | I4: ='5D SD'!AE51 -> 0.2
B5: GTS | C5: Group Tour Summer | F5: 302 | G5: 6D SD | H5: ='6D SD'!Z51 -> 1875 | I5: ='6D SD'!AE51 -> 0.2
B6: GTW | C6: Group Tour Winter | F6: 303 | G6: 7D SD | H6: ='7D SD'!Z51 -> 2312.5 | I6: ='7D SD'!AE51 -> 0.2
B7: RS | C7: Reykjavik Summer | F7: 304 | G7: 8D SD | H7: ='8D SD'!Z58 -> 2812.5 | I7: ='8D SD'!AE58 -> 0.2
B8: RW | C8: Reykjavik Winter | F8: 305 | G8: 10D SD | H8: ='10D SD'!Z66 -> 3500 | I8: ='10D SD'!AE66 -> 0.2
F9: 306 | G9: 5D GTS | H9: ='5D GTS'!Z43 -> 2190.0882 | I9: ='5D GTS'!AE43 -> 0.15619838
F10: 307 | G10: 6D GTS | H10: ='6D GTS'!Z52 -> 2798.0882 | I10: ='6D GTS'!AE52 -> 0.15656698
F11: 308 | G11: 7D GTS | H11: ='7D GTS'!Z57 -> 3339.5882 | I11: ='7D GTS'!AE57 -> 0.15678227
F12: 309 | G12: 8D GTS | H12: ='8D GTS'!Z59 -> 4223.0882 | I12: ='8D GTS'!AE59 -> 0.15701501
F13: 310 | G13: 10D GTS | H13: ='10D GTS'!Z62 -> 5159.7882 | I13: ='10D GTS'!AE62 -> 0.15717471
F14: 311 | G14: 5D GTW | H14: ='5D GTW'!Z47 -> 2133.0882 | I14: ='5D GTW'!AE47 -> 0.15615305
F15: 312 | G15: 6D GTW | H15: ='6D GTW'!Z50 -> 2581.4882 | I15: ='6D GTW'!AE50 -> 0.15645558
F16: 313 | G16: 7D GTW | H16: ='7D GTW'!Z51 -> 3339.5882 | I16: ='7D GTW'!AE51 -> 0.15678227
F17: 314 | G17: 8D GTW | H17: ='8D GTW'!Z58 -> 4213.5882 | I17: ='8D GTW'!AE58 -> 0.15701303
F18: 315 | G18: 10D GTW | H18: ='10D GTW'!Z62 -> 4878.5882 | I18: ='10D GTW'!AE62 -> 0.15713321
F19: 316 | G19: 5D RS | H19: ='5D RS'!Z45 -> 2130.4706 | I19: ='5D RS'!AE45 -> 0.18712795
F20: 317 | G20: 6D RS | H20: ='6D RS'!Z48 -> 2461.7647 | I20: ='6D RS'!AE48 -> 0.18448746
F21: 318 | G21: 7D RS | H21: ='7D RS'!Z53 -> 2937.0588 | I21: ='7D RS'!AE53 -> 0.18707791
F22: 319 | G22: 8D RS | H22: ='8D RS'!Z53 -> 3376.3529 | I22: ='8D RS'!AE53 -> 0.18829576
F23: 320 | G23: 5D RW | H23: ='5D RW'!Z44 -> 1797.5294 | I23: ='5D RW'!AE44 -> 0.19511748
F24: 321 | G24: 6D RW | H24: ='6D RW'!Z52 -> 2108.8235 | I24: ='6D RW'!AE52 -> 0.19025941
F25: 322 | G25: 7D RW | H25: ='7D RW'!Z55 -> 2584.1176 | I25: ='7D RW'!AE55 -> 0.19214204
F26: 323 | G26: 8D RW | H26: ='8D RW'!Z52 -> 3023.4118 | I26: ='8D RW'!AE52 -> 0.19276626

Sheet 5D SD
B1: Season: All
B2: Places: Reykjavik 1N - Vik I Myrdal 1N - Hofn 1N - Selfoss 1N
B3: Pax: 2
B4: Rooming: Double
B6: ID | C6: Day | D6: Type | E6: From date | F6: To date | G6: From time | H6: To time | I6: Supplier | J6: Travel element | K6: Manual booking? | L6: Status | M6: Comments | N6: Non-refundable | O6: Refundable | P6: URL | Q6: Gross P per unit | R6: Units | S6: Gross P | T6: Supp Comm | U6: Net P | V6: Supp curr | W6: X-rate | X6: Net P NOK | Y6: Sales P per unit | Z6: Price | AA6: Sales curr | AB6: X-rate | AC6: Sales P NOK tot | AD6: GP NOK | AE6: GP % | AF6: VAT25 | AG6: VAT15 | AH6: VAT12 | AI6: VAT0-D | AJ6: VAT0-I
C7: Day 1 | D7: Arrival | J7: Keflavik: Welcome to Iceland | Q7: 0 | R7: 0 | S7: =+Q7*R7 -> 0 | T7: 0 | U7: =S7*(1-T7) -> 0 | V7: EUR | W7: =IFERROR(VLOOKUP(V7,Curr!$B$2:$C$13,2,FALSE),0) -> 11 | X7: =U7*W7 -> 0 | Y7: =Q7 -> 0 | Z7: =+Y7*R7 -> 0 | AA7: EUR | AB7: =IFERROR(VLOOKUP(AA7,Curr!$B$2:$C$13,2,FALSE),0) -> 11 | AC7: =+Y7*AB7*R7 -> 0 | AD7: =+AC7-X7 -> 0 | AE7: =IFERROR(AD7/AC7,0) -> 0
C8: Day 1 | D8: Car | J8: Keflavik: Pick up your rental car at the car rental office - A 4x4 will with room for 4 luggages will be provided - Includes: Basic Insuarance - Excludes: Deposit | P8: https://www.ratehawk.com/cars/?route=965846080%2C965846080&date=2026-06-14T09%3A00%2C2026-06-18T18%3A00&age=26%2C69&sid=c2238b01-0af9-4e1e-b966-e14d15ef26da | Q8: 300 | R8: 1 | S8: =+Q8*R8 -> 300 | T8: 0 | U8: =S8*(1-T8) -> 300 | V8: EUR | W8: =IFERROR(VLOOKUP(V8,Curr!$B$2:$C$13,2,FALSE),0) -> 11 | X8: =U8*W8 -> 3300 | Y8: =Q8/0.8 -> 375 | Z8: =+Y8*R8 -> 375 | AA8: EUR | AB8: =IFERROR(VLOOKUP(AA8,Curr!$B$2:$C$13,2,FALSE),0) -> 11 | AC8: =+Y8*AB8*R8 -> 4125 | AD8: =+AC8-X8 -> 825 | AE8: =IFERROR(AD8/AC8,0) -> 0.2
C9: Day 1 | D9: Drive | J9: Keflavik: Drive to Reykjavik - Driving time: 45 min - 1 hr - Optional Stops: Reykjanes lava fields, Coastal views along Route 41, Faxaflói Bay viewpoints (weather permitting) - Hidden Gems: Small roadside lava formations, Quiet pull-offs with ocean views, Reykjanes Peninsula backroad detours (only if not rushing) | Q9: 0 | R9: 0 | S9: =+Q9*R9 -> 0 | T9: 0 | U9: =S9*(1-T9) -> 0 | V9: EUR | W9: =IFERROR(VLOOKUP(V9,Curr!$B$2:$C$13,2,FALSE),0) -> 11 | X9: =U9*W9 -> 0 | Y9: =Q9 -> 0 | Z9: =+Y9*R9 -> 0 | AA9: EUR | AB9: =IFERROR(VLOOKUP(AA9,Curr!$B$2:$C$13,2,FALSE),0) -> 11 | AC9: =+Y9*AB9*R9 -> 0 | AD9: =+AC9-X9 -> 0 | AE9: =IFERROR(AD9/AC9,0) -> 0
C10: Day 1 | D10: Hotel | J10: Reykjavik: Check in to your accommodation for a 1 night stay - Cenrally located 3/4-star hotel - Standard room - breakfast included | P10: https://www.ratehawk.com/?sid=5c11424c-1694-4e32-9a64-786852f88adb | Q10: 200 | R10: 1 | S10: =+Q10*R10 -> 200 | T10: 0 | U10: =S10*(1-T10) -> 200 | V10: EUR | W10: =IFERROR(VLOOKUP(V10,Curr!$B$2:$C$13,2,FALSE),0) -> 11 | X10: =U10*W10 -> 2200 | Y10: =Q10/0.8 -> 250 | Z10: =+Y10*R10 -> 250 | AA10: EUR | AB10: =IFERROR(VLOOKUP(AA10,Curr!$B$2:$C$13,2,FALSE),0) -> 11 | AC10: =+Y10*AB10*R10 -> 2750 | AD10: =+AC10-X10 -> 550 | AE10: =IFERROR(AD10/AC10,0) -> 0.2
C11: Day 1 | D11: Leisure | J11: Reykjavik: Spend time at leisure | Q11: 0 | R11: 0 | S11: =+Q11*R11 -> 0 | T11: 0 | U11: =S11*(1-T11) -> 0 | V11: EUR | W11: =IFERROR(VLOOKUP(V11,Curr!$B$2:$C$13,2,FALSE),0) -> 11 | X11: =U11*W11 -> 0 | Y11: =Q11 -> 0 | Z11: =+Y11*R11 -> 0 | AA11: EUR | AB11: =IFERROR(VLOOKUP(AA11,Curr!$B$2:$C$13,2,FALSE),0) -> 11 | AC11: =+Y11*AB11*R11 -> 0 | AD11: =+AC11-X11 -> 0 | AE11: =IFERROR(AD11/AC11,0) -> 0
S12: =+Q12*R12 -> 0 | T12: 0 | U12: =S12*(1-T12) -> 0 | V12: EUR | W12: =IFERROR(VLOOKUP(V12,Curr!$B$2:$C$13,2,FALSE),0) -> 11 | X12: =U12*W12 -> 0 | Y12: =Q12 -> 0 | Z12: =+Y12*R12 -> 0 | AA12: EUR | AB12: =IFERROR(VLOOKUP(AA12,Curr!$B$2:$C$13,2,FALSE),0) -> 11 | AC12: =+Y12*AB12*R12 -> 0 | AD12: =+AC12-X12 -> 0 | AE12: =IFERROR(AD12/AC12,0) -> 0
C13: Day 2 | D13: Drive | J13: Reykjavik: Drive to Vik I Myrdal via the Golden Circle - Driving time: 5.5hrs - 6.5hrs - Highlights: Þingvellir National Park, Geysir (Strokkur), Gullfoss, Seljalandsfoss, Skógafoss, Reynisfjara - Hidden Gems: Kerið, Gljúfrabúi, Dyrhólaey coastal viewpoints (weather permitting) | Q13: 0 | R13: 0 | S13: =+Q13*R13 -> 0 | T13: 0 | U13: =S13*(1-T13) -> 0 | V13: EUR | W13: =IFERROR(VLOOKUP(V13,Curr!$B$2:$C$13,2,FALSE),0) -> 11 | X13: =U13*W13 -> 0 | Y13: =Q13 -> 0 | Z13: =+Y13*R13 -> 0 | AA13: EUR | AB13: =IFERROR(VLOOKUP(AA13,Curr!$B$2:$C$13,2,FALSE),0) -> 11 | AC13: =+Y13*AB13*R13 -> 0 | AD13: =+AC13-X13 -> 0 | AE13: =IFERROR(AD13/AC13,0) -> 0
C14: Day 2 | D14: Hotel | J14: Vik i Myrdal: Check in to your accommodation for a 1 night stay - Cenrally located 3/4-star hotel - Standard room - breakfast included | Q14: 250 | R14: 1 | S14: =+Q14*R14 -> 250 | T14: 0 | U14: =S14*(1-T14) -> 250 | V14: EUR | W14: =IFERROR(VLOOKUP(V14,Curr!$B$2:$C$13,2,FALSE),0) -> 11 | X14: =U14*W14 -> 2750 | Y14: =Q14/0.8 -> 312.5 | Z14: =+Y14*R14 -> 312.5 | AA14: EUR | AB14: =IFERROR(VLOOKUP(AA14,Curr!$B$2:$C$13,2,FALSE),0) -> 11 | AC14: =+Y14*AB14*R14 -> 3437.5 | AD14: =+AC14-X14 -> 687.5 | AE14: =IFERROR(AD14/AC14,0) -> 0.2
C15: Day 2 | D15: Leisure | J15: Vik i Myrdal: Spend time at leisure | Q15: 0 | R15: 0 | S15: =+Q15*R15 -> 0 | T15: 0 | U15: =S15*(1-T15) -> 0 | V15: EUR | W15: =IFERROR(VLOOKUP(V15,Curr!$B$2:$C$13,2,FALSE),0) -> 11 | X15: =U15*W15 -> 0 | Y15: =Q15 -> 0 | Z15: =+Y15*R15 -> 0 | AA15: EUR | AB15: =IFERROR(VLOOKUP(AA15,Curr!$B$2:$C$13,2,FALSE),0) -> 11 | AC15: =+Y15*AB15*R15 -> 0 | AD15: =+AC15-X15 -> 0 | AE15: =IFERROR(AD15/AC15,0) -> 0
S16: =+Q16*R16 -> 0 | T16: 0 | U16: =S16*(1-T16) -> 0 | V16: EUR | W16: =IFERROR(VLOOKUP(V16,Curr!$B$2:$C$13,2,FALSE),0) -> 11 | X16: =U16*W16 -> 0 | Y16: =Q16 -> 0 | Z16: =+Y16*R16 -> 0 | AA16: EUR | AB16: =IFERROR(VLOOKUP(AA16,Curr!$B$2:$C$13,2,FALSE),0) -> 11 | AC16: =+Y16*AB16*R16 -> 0 | AD16: =+AC16-X16 -> 0 | AE16: =IFERROR(AD16/AC16,0) -> 0
C17: Day 3 | D17: Drive | J17: Vik i Myrdal: Drive to Höfn - Driving time: 4.5hrs - 5.5 hrs - Highlights: Fjaðrárgljúfur, Skaftafell, Svartifoss, Jökulsárlón, Diamond Beach - Hidden Gems: Moss-covered lava fields of Eldhraun, Svínafellsjökull, Quiet pull-offs along Skeiðarársandur outwash plain | Q17: 0 | R17: 0 | S17: =+Q17*R17 -> 0 | T17: 0 | U17: =S17*(1-T17) -> 0 | V17: EUR | W17: =IFERROR(VLOOKUP(V17,Curr!$B$2:$C$13,2,FALSE),0) -> 11 | X17: =U17*W17 -> 0 | Y17: =Q17 -> 0 | Z17: =+Y17*R17 -> 0 | AA17: EUR | AB17: =IFERROR(VLOOKUP(AA17,Curr!$B$2:$C$13,2,FALSE),0) -> 11 | AC17: =+Y17*AB17*R17 -> 0 | AD17: =+AC17-X17 -> 0 | AE17: =IFERROR(AD17/AC17,0) -> 0
C18: Day 3 | D18: Hotel | J18: Höfn: Check in to your accommodation for a 1 night stay - Cenrally located 3/4-star hotel - Standard room - breakfast included | Q18: 200 | R18: 1 | S18: =+Q18*R18 -> 200 | T18: 0 | U18: =S18*(1-T18) -> 200 | V18: EUR | W18: =IFERROR(VLOOKUP(V18,Curr!$B$2:$C$13,2,FALSE),0) -> 11 | X18: =U18*W18 -> 2200 | Y18: =Q18/0.8 -> 250 | Z18: =+Y18*R18 -> 250 | AA18: EUR | AB18: =IFERROR(VLOOKUP(AA18,Curr!$B$2:$C$13,2,FALSE),0) -> 11 | AC18: =+Y18*AB18*R18 -> 2750 | AD18: =+AC18-X18 -> 550 | AE18: =IFERROR(AD18/AC18,0) -> 0.2
C19: Day 3 | D19: Leisure | J19: Höfn: Spend time at leisure | Q19: 0 | R19: 0 | S19: =+Q19*R19 -> 0 | T19: 0 | U19: =S19*(1-T19) -> 0 | V19: EUR | W19: =IFERROR(VLOOKUP(V19,Curr!$B$2:$C$13,2,FALSE),0) -> 11 | X19: =U19*W19 -> 0 | Y19: =Q19 -> 0 | Z19: =+Y19*R19 -> 0 | AA19: EUR | AB19: =IFERROR(VLOOKUP(AA19,Curr!$B$2:$C$13,2,FALSE),0) -> 11 | AC19: =+Y19*AB19*R19 -> 0 | AD19: =+AC19-X19 -> 0 | AE19: =IFERROR(AD19/AC19,0) -> 0
S20: =+Q20*R20 -> 0 | T20: 0 | U20: =S20*(1-T20) -> 0 | V20: EUR | W20: =IFERROR(VLOOKUP(V20,Curr!$B$2:$C$13,2,FALSE),0) -> 11 | X20: =U20*W20 -> 0 | Y20: =Q20 -> 0 | Z20: =+Y20*R20 -> 0 | AA20: EUR | AB20: =IFERROR(VLOOKUP(AA20,Curr!$B$2:$C$13,2,FALSE),0) -> 11 | AC20: =+Y20*AB20*R20 -> 0 | AD20: =+AC20-X20 -> 0 | AE20: =IFERROR(AD20/AC20,0) -> 0
C21: Day 4 | D21: Drive | J21: Höfn: Drive to Selfoss - Driving time: 6hrs - 7hrs - Highlights: Vatnajökull views, Skaftafell, Eldhraun, Skógafoss, Seljalandsfoss - Hidden Gems: Svínafellsjökull, Gljúfrabúi, Quiet stretches of Skeiðarársandur outwash plains | Q21: 0 | R21: 0 | S21: =+Q21*R21 -> 0 | T21: 0 | U21: =S21*(1-T21) -> 0 | V21: EUR | W21: =IFERROR(VLOOKUP(V21,Curr!$B$2:$C$13,2,FALSE),0) -> 11 | X21: =U21*W21 -> 0 | Y21: =Q21 -> 0 | Z21: =+Y21*R21 -> 0 | AA21: EUR | AB21: =IFERROR(VLOOKUP(AA21,Curr!$B$2:$C$13,2,FALSE),0) -> 11 | AC21: =+Y21*AB21*R21 -> 0 | AD21: =+AC21-X21 -> 0 | AE21: =IFERROR(AD21/AC21,0) -> 0
C22: Day 4 | D22: Hotel | J22: Selfoss: Check in to your accommodation for a 1 night stay - Cenrally located 3/4-star hotel - Standard room - breakfast included | Q22: 225 | R22: 1 | S22: =+Q22*R22 -> 225 | T22: 0 | U22: =S22*(1-T22) -> 225 | V22: EUR | W22: =IFERROR(VLOOKUP(V22,Curr!$B$2:$C$13,2,FALSE),0) -> 11 | X22: =U22*W22 -> 2475 | Y22: =Q22/0.8 -> 281.25 | Z22: =+Y22*R22 -> 281.25 | AA22: EUR | AB22: =IFERROR(VLOOKUP(AA22,Curr!$B$2:$C$13,2,FALSE),0) -> 11 | AC22: =+Y22*AB22*R22 -> 3093.75 | AD22: =+AC22-X22 -> 618.75 | AE22: =IFERROR(AD22/AC22,0) -> 0.2
C23: Day 4 | D23: Leisure | J23: Selfoss: Spend time at leisure | Q23: 0 | R23: 0 | S23: =+Q23*R23 -> 0 | T23: 0 | U23: =S23*(1-T23) -> 0 | V23: EUR | W23: =IFERROR(VLOOKUP(V23,Curr!$B$2:$C$13,2,FALSE),0) -> 11 | X23: =U23*W23 -> 0 | Y23: =Q23 -> 0 | Z23: =+Y23*R23 -> 0 | AA23: EUR | AB23: =IFERROR(VLOOKUP(AA23,Curr!$B$2:$C$13,2,FALSE),0) -> 11 | AC23: =+Y23*AB23*R23 -> 0 | AD23: =+AC23-X23 -> 0 | AE23: =IFERROR(AD23/AC23,0) -> 0
S24: =+Q24*R24 -> 0 | T24: 0 | U24: =S24*(1-T24) -> 0 | V24: EUR | W24: =IFERROR(VLOOKUP(V24,Curr!$B$2:$C$13,2,FALSE),0) -> 11 | X24: =U24*W24 -> 0 | Y24: =Q24 -> 0 | Z24: =+Y24*R24 -> 0 | AA24: EUR | AB24: =IFERROR(VLOOKUP(AA24,Curr!$B$2:$C$13,2,FALSE),0) -> 11 | AC24: =+Y24*AB24*R24 -> 0 | AD24: =+AC24-X24 -> 0 | AE24: =IFERROR(AD24/AC24,0) -> 0
C25: Day 5 | D25: Drive | J25: Selfoss: Drive to Keflavik Airport - Driving time: 1.5hrs - 2hrs - Highlights: Reykjanes lava landscapes, Reykjanes Peninsula scenery, Coastal views approaching Keflavík - Hidden Gems: Bridge Between Continents, Gunnuhver, Reykjanesviti | Q25: 0 | R25: 0 | S25: =+Q25*R25 -> 0 | T25: 0 | U25: =S25*(1-T25) -> 0 | V25: EUR | W25: =IFERROR(VLOOKUP(V25,Curr!$B$2:$C$13,2,FALSE),0) -> 11 | X25: =U25*W25 -> 0 | Y25: =Q25 -> 0 | Z25: =+Y25*R25 -> 0 | AA25: EUR | AB25: =IFERROR(VLOOKUP(AA25,Curr!$B$2:$C$13,2,FALSE),0) -> 11 | AC25: =+Y25*AB25*R25 -> 0 | AD25: =+AC25-X25 -> 0 | AE25: =IFERROR(AD25/AC25,0) -> 0
C26: Day 5 | D26: Car | J26: Keflavik: Deliver your car at the car rental office | Q26: 0 | R26: 0 | S26: =+Q26*R26 -> 0 | T26: 0 | U26: =S26*(1-T26) -> 0 | V26: EUR | W26: =IFERROR(VLOOKUP(V26,Curr!$B$2:$C$13,2,FALSE),0) -> 11 | X26: =U26*W26 -> 0 | Y26: =Q26 -> 0 | Z26: =+Y26*R26 -> 0 | AA26: EUR | AB26: =IFERROR(VLOOKUP(AA26,Curr!$B$2:$C$13,2,FALSE),0) -> 11 | AC26: =+Y26*AB26*R26 -> 0 | AD26: =+AC26-X26 -> 0 | AE26: =IFERROR(AD26/AC26,0) -> 0
C27: Day 5 | D27: Departure | J27: Keflavik: Departure home | Q27: 0 | R27: 0 | S27: =+Q27*R27 -> 0 | T27: 0 | U27: =S27*(1-T27) -> 0 | V27: EUR | W27: =IFERROR(VLOOKUP(V27,Curr!$B$2:$C$13,2,FALSE),0) -> 11 | X27: =U27*W27 -> 0 | Y27: =Q27 -> 0 | Z27: =+Y27*R27 -> 0 | AA27: EUR | AB27: =IFERROR(VLOOKUP(AA27,Curr!$B$2:$C$13,2,FALSE),0) -> 11 | AC27: =+Y27*AB27*R27 -> 0 | AD27: =+AC27-X27 -> 0 | AE27: =IFERROR(AD27/AC27,0) -> 0
S28: =+Q28*R28 -> 0 | T28: 0 | U28: =S28*(1-T28) -> 0 | V28: EUR | W28: =IFERROR(VLOOKUP(V28,Curr!$B$2:$C$13,2,FALSE),0) -> 11 | X28: =U28*W28 -> 0 | Y28: =Q28 -> 0 | Z28: =+Y28*R28 -> 0 | AA28: EUR | AB28: =IFERROR(VLOOKUP(AA28,Curr!$B$2:$C$13,2,FALSE),0) -> 11 | AC28: =+Y28*AB28*R28 -> 0 | AD28: =+AC28-X28 -> 0 | AE28: =IFERROR(AD28/AC28,0) -> 0
S29: =+Q29*R29 -> 0 | T29: 0 | U29: =S29*(1-T29) -> 0 | V29: EUR | W29: =IFERROR(VLOOKUP(V29,Curr!$B$2:$C$13,2,FALSE),0) -> 11 | X29: =U29*W29 -> 0 | Y29: =Q29 -> 0 | Z29: =+Y29*R29 -> 0 | AA29: EUR | AB29: =IFERROR(VLOOKUP(AA29,Curr!$B$2:$C$13,2,FALSE),0) -> 11 | AC29: =+Y29*AB29*R29 -> 0 | AD29: =+AC29-X29 -> 0 | AE29: =IFERROR(AD29/AC29,0) -> 0
C30: Day 1 | D30: Activity Upgrade | J30: Reykjavík: City Walking Tour - Time: 2:00 pm - 5:00 pm - Meeting point: Hallgrímskirkja, Hallgrimstorgi 1 - Includes: Professional, English-speaking guide - Highlights: Hallgrímskirkja, All the major landmarks, Hidden street art & local corners, Iceland in a nutshell | P30: https://booknordics.com/iceland/western-iceland/reykjavik/reykjavik-walking-tour-small-group-citywalk | Q30: 37 | R30: 0 | S30: =+Q30*R30 -> 0 | T30: 0.2 | U30: =S30*(1-T30) -> 0 | V30: EUR | W30: =IFERROR(VLOOKUP(V30,Curr!$B$2:$C$13,2,FALSE),0) -> 11 | X30: =U30*W30 -> 0 | Y30: =Q30 -> 37 | Z30: =+Y30*R30 -> 0 | AA30: EUR | AB30: =IFERROR(VLOOKUP(AA30,Curr!$B$2:$C$13,2,FALSE),0) -> 11 | AC30: =+Y30*AB30*R30 -> 0 | AD30: =+AC30-X30 -> 0 | AE30: =IFERROR(AD30/AC30,0) -> 0
C31: Day 1 | D31: Activity Upgrade | J31: Reykjavík: Northern Lights Minibus Tour - Small Group - Time: 8:30 pm - 12:30 am - Meeting point: Hotel pick up - Includes: Pick-up/drop-off in central Reykjavik, Professional, English-speaking guide, Northern lights tour in a small group, Ticket to Aurora Museum Reykjavik, Free Wi-Fi onboard the vehicle, Hot chocolate and refreshments | P31: https://booknordics.com/iceland/western-iceland/reykjavik/northern-lights-small-group-minibus-tour | Q31: 89 | R31: 0 | S31: =+Q31*R31 -> 0 | T31: 0.25 | U31: =S31*(1-T31) -> 0 | V31: EUR | W31: =IFERROR(VLOOKUP(V31,Curr!$B$2:$C$13,2,FALSE),0) -> 11 | X31: =U31*W31 -> 0 | Y31: =Q31 -> 89 | Z31: =+Y31*R31 -> 0 | AA31: EUR | AB31: =IFERROR(VLOOKUP(AA31,Curr!$B$2:$C$13,2,FALSE),0) -> 11 | AC31: =+Y31*AB31*R31 -> 0 | AD31: =+AC31-X31 -> 0 | AE31: =IFERROR(AD31/AC31,0) -> 0
C32: Day 3 | D32: Activity Upgrade | J32: Vik: Katla Ice Cave Super Jeep Tour - Time: 09:30 am - 12:30 pm - Meeting point: Tröll Expeditions Katla Ice Cave - Includes: Super Jeep excursion to Katla Ice Cave, Certified glacier guide and glacier hike, Experienced off-road driver, Ice cave gear: crampons, and helmet | P32: https://booknordics.com/iceland/southern-iceland/vik/katla-ice-cave-super-jeep-from-vik | Q32: 205 | R32: 0 | S32: =+Q32*R32 -> 0 | T32: 0 | U32: =S32*(1-T32) -> 0 | V32: EUR | W32: =IFERROR(VLOOKUP(V32,Curr!$B$2:$C$13,2,FALSE),0) -> 11 | X32: =U32*W32 -> 0 | Y32: =Q32 -> 205 | Z32: =+Y32*R32 -> 0 | AA32: EUR | AB32: =IFERROR(VLOOKUP(AA32,Curr!$B$2:$C$13,2,FALSE),0) -> 11 | AC32: =+Y32*AB32*R32 -> 0 | AD32: =+AC32-X32 -> 0 | AE32: =IFERROR(AD32/AC32,0) -> 0
C33: Day 5 | D33: Activity Upgrade | J33: Reykjavik: Blue Lagoon Comfort Package - Time: 09:00 am - 1:00 pm - Meeting point: Hotel Pick up - Includes: Return transfer, Entrance to the Blue Lagoon, Silica mud mask at the Mask Bar, Use of towel, shampoo, conditioner, and moisturizer, Private locker, Non-alcoholic drink at the in-water bar | P33: https://booknordics.com/iceland/western-iceland/reykjavik/reykjavik-blue-lagoon-comfort-including-admission | Q33: 163 | R33: 0 | S33: =+Q33*R33 -> 0 | T33: 0.2 | U33: =S33*(1-T33) -> 0 | V33: EUR | W33: =IFERROR(VLOOKUP(V33,Curr!$B$2:$C$13,2,FALSE),0) -> 11 | X33: =U33*W33 -> 0 | Y33: =Q33 -> 163 | Z33: =+Y33*R33 -> 0 | AA33: EUR | AB33: =IFERROR(VLOOKUP(AA33,Curr!$B$2:$C$13,2,FALSE),0) -> 11 | AC33: =+Y33*AB33*R33 -> 0 | AD33: =+AC33-X33 -> 0 | AE33: =IFERROR(AD33/AC33,0) -> 0
S34: =+Q34*R34 -> 0 | T34: 0 | U34: =S34*(1-T34) -> 0 | V34: EUR | W34: =IFERROR(VLOOKUP(V34,Curr!$B$2:$C$13,2,FALSE),0) -> 11 | X34: =U34*W34 -> 0 | Y34: =Q34 -> 0 | Z34: =+Y34*R34 -> 0 | AA34: EUR | AB34: =IFERROR(VLOOKUP(AA34,Curr!$B$2:$C$13,2,FALSE),0) -> 11 | AC34: =+Y34*AB34*R34 -> 0 | AD34: =+AC34-X34 -> 0 | AE34: =IFERROR(AD34/AC34,0) -> 0
S35: =+Q35*R35 -> 0 | T35: 0 | U35: =S35*(1-T35) -> 0 | V35: EUR | W35: =IFERROR(VLOOKUP(V35,Curr!$B$2:$C$13,2,FALSE),0) -> 11 | X35: =U35*W35 -> 0 | Y35: =Q35 -> 0 | Z35: =+Y35*R35 -> 0 | AA35: EUR | AB35: =IFERROR(VLOOKUP(AA35,Curr!$B$2:$C$13,2,FALSE),0) -> 11 | AC35: =+Y35*AB35*R35 -> 0 | AD35: =+AC35-X35 -> 0 | AE35: =IFERROR(AD35/AC35,0) -> 0
C36: Day 1 | D36: Extra Hotel Night | J36: Reykjavik: Add on an extra night in Reykjavik | Q36: 225 | R36: 0 | S36: =+Q36*R36 -> 0 | T36: 0 | U36: =S36*(1-T36) -> 0 | V36: EUR | W36: =IFERROR(VLOOKUP(V36,Curr!$B$2:$C$13,2,FALSE),0) -> 11 | X36: =U36*W36 -> 0 | Y36: =Q36/0.85 -> 264.70588 | Z36: =+Y36*R36 -> 0 | AA36: EUR | AB36: =IFERROR(VLOOKUP(AA36,Curr!$B$2:$C$13,2,FALSE),0) -> 11 | AC36: =+Y36*AB36*R36 -> 0 | AD36: =+AC36-X36 -> 0 | AE36: =IFERROR(AD36/AC36,0) -> 0
C37: Day 5 | D37: Extra Hotel Night | J37: Reykjavik: Add on an extra night in Reykjavik | Q37: 225 | R37: 0 | S37: =+Q37*R37 -> 0 | T37: 0 | U37: =S37*(1-T37) -> 0 | V37: EUR | W37: =IFERROR(VLOOKUP(V37,Curr!$B$2:$C$13,2,FALSE),0) -> 11 | X37: =U37*W37 -> 0 | Y37: =Q37/0.85 -> 264.70588 | Z37: =+Y37*R37 -> 0 | AA37: EUR | AB37: =IFERROR(VLOOKUP(AA37,Curr!$B$2:$C$13,2,FALSE),0) -> 11 | AC37: =+Y37*AB37*R37 -> 0 | AD37: =+AC37-X37 -> 0 | AE37: =IFERROR(AD37/AC37,0) -> 0
S38: =+Q38*R38 -> 0 | T38: 0 | U38: =S38*(1-T38) -> 0 | V38: EUR | W38: =IFERROR(VLOOKUP(V38,Curr!$B$2:$C$13,2,FALSE),0) -> 11 | X38: =U38*W38 -> 0 | Y38: =Q38 -> 0 | Z38: =+Y38*R38 -> 0 | AA38: EUR | AB38: =IFERROR(VLOOKUP(AA38,Curr!$B$2:$C$13,2,FALSE),0) -> 11 | AC38: =+Y38*AB38*R38 -> 0 | AD38: =+AC38-X38 -> 0 | AE38: =IFERROR(AD38/AC38,0) -> 0
S39: =+Q39*R39 -> 0 | T39: 0 | U39: =S39*(1-T39) -> 0 | V39: EUR | W39: =IFERROR(VLOOKUP(V39,Curr!$B$2:$C$13,2,FALSE),0) -> 11 | X39: =U39*W39 -> 0 | Y39: =Q39 -> 0 | Z39: =+Y39*R39 -> 0 | AA39: EUR | AB39: =IFERROR(VLOOKUP(AA39,Curr!$B$2:$C$13,2,FALSE),0) -> 11 | AC39: =+Y39*AB39*R39 -> 0 | AD39: =+AC39-X39 -> 0 | AE39: =IFERROR(AD39/AC39,0) -> 0
S40: =+Q40*R40 -> 0 | T40: 0 | U40: =S40*(1-T40) -> 0 | V40: EUR | W40: =IFERROR(VLOOKUP(V40,Curr!$B$2:$C$13,2,FALSE),0) -> 11 | X40: =U40*W40 -> 0 | Y40: =Q40 -> 0 | Z40: =+Y40*R40 -> 0 | AA40: EUR | AB40: =IFERROR(VLOOKUP(AA40,Curr!$B$2:$C$13,2,FALSE),0) -> 11 | AC40: =+Y40*AB40*R40 -> 0 | AD40: =+AC40-X40 -> 0 | AE40: =IFERROR(AD40/AC40,0) -> 0
S41: =+Q41*R41 -> 0 | T41: 0 | U41: =S41*(1-T41) -> 0 | V41: EUR | W41: =IFERROR(VLOOKUP(V41,Curr!$B$2:$C$13,2,FALSE),0) -> 11 | X41: =U41*W41 -> 0 | Y41: =Q41 -> 0 | Z41: =+Y41*R41 -> 0 | AA41: EUR | AB41: =IFERROR(VLOOKUP(AA41,Curr!$B$2:$C$13,2,FALSE),0) -> 11 | AC41: =+Y41*AB41*R41 -> 0 | AD41: =+AC41-X41 -> 0 | AE41: =IFERROR(AD41/AC41,0) -> 0
...

Sheet 6D SD
B1: Season: All
B2: Places: Reykjavik 1N - Vik I Myrdal 1N - Hofn 1N - Myvatn 1N - Borgarnes 1N
B3: Pax: 2
B4: Rooming: Double
B6: ID | C6: Day | D6: Type | E6: From date | F6: To date | G6: From time | H6: To time | I6: Supplier | J6: Travel element | K6: Manual booking? | L6: Status | M6: Comments | N6: Non-refundable | O6: Refundable | P6: URL | Q6: Gross P per unit | R6: Units | S6: Gross P | T6: Supp Comm | U6: Net P | V6: Supp curr | W6: X-rate | X6: Net P NOK | Y6: Sales P per unit | Z6: Price | AA6: Sales curr | AB6: X-rate | AC6: Sales P NOK tot | AD6: GP NOK | AE6: GP % | AF6: VAT25 | AG6: VAT15 | AH6: VAT12 | AI6: VAT0-D | AJ6: VAT0-I
C7: Day 1 | D7: Arrival | J7: Keflavik: Welcome to Iceland | Q7: 0 | R7: 0 | S7: =+Q7*R7 -> 0 | T7: 0 | U7: =S7*(1-T7) -> 0 | V7: EUR | W7: =IFERROR(VLOOKUP(V7,Curr!$B$2:$C$13,2,FALSE),0) -> 11 | X7: =U7*W7 -> 0 | Y7: =Q7 -> 0 | Z7: =+Y7*R7 -> 0 | AA7: EUR | AB7: =IFERROR(VLOOKUP(AA7,Curr!$B$2:$C$13,2,FALSE),0) -> 11 | AC7: =+Y7*AB7*R7 -> 0 | AD7: =+AC7-X7 -> 0 | AE7: =IFERROR(AD7/AC7,0) -> 0
C8: Day 1 | D8: Car | J8: Keflavik: Pick up your rental car at the car rental office - A 4x4 will with room for 4 luggages will be provided - Includes: Basic Insuarance - Excludes: Deposit | Q8: 450 | R8: 1 | S8: =+Q8*R8 -> 450 | T8: 0 | U8: =S8*(1-T8) -> 450 | V8: EUR | W8: =IFERROR(VLOOKUP(V8,Curr!$B$2:$C$13,2,FALSE),0) -> 11 | X8: =U8*W8 -> 4950 | Y8: =Q8/0.8 -> 562.5 | Z8: =+Y8*R8 -> 562.5 | AA8: EUR | AB8: =IFERROR(VLOOKUP(AA8,Curr!$B$2:$C$13,2,FALSE),0) -> 11 | AC8: =+Y8*AB8*R8 -> 6187.5 | AD8: =+AC8-X8 -> 1237.5 | AE8: =IFERROR(AD8/AC8,0) -> 0.2
C9: Day 1 | D9: Drive | J9: Keflavik: Drive to Reykjavik - Driving time: 45 min - 1 hr - Optional Stops: Reykjanes lava fields, Coastal views along Route 41, Faxaflói Bay viewpoints (weather permitting) - Hidden Gems: Small roadside lava formations, Quiet pull-offs with ocean views, Reykjanes Peninsula backroad detours (only if not rushing) | Q9: 0 | R9: 0 | S9: =+Q9*R9 -> 0 | T9: 0 | U9: =S9*(1-T9) -> 0 | V9: EUR | W9: =IFERROR(VLOOKUP(V9,Curr!$B$2:$C$13,2,FALSE),0) -> 11 | X9: =U9*W9 -> 0 | Y9: =Q9 -> 0 | Z9: =+Y9*R9 -> 0 | AA9: EUR | AB9: =IFERROR(VLOOKUP(AA9,Curr!$B$2:$C$13,2,FALSE),0) -> 11 | AC9: =+Y9*AB9*R9 -> 0 | AD9: =+AC9-X9 -> 0 | AE9: =IFERROR(AD9/AC9,0) -> 0
C10: Day 1 | D10: Hotel | J10: Reykjavik: Check in to your accommodation for a 1 night stay - Cenrally located 3/4-star hotel - Standard room - breakfast included | P10: https://www.ratehawk.com/?sid=5c11424c-1694-4e32-9a64-786852f88adb | Q10: 200 | R10: 1 | S10: =+Q10*R10 -> 200 | T10: 0 | U10: =S10*(1-T10) -> 200 | V10: EUR | W10: =IFERROR(VLOOKUP(V10,Curr!$B$2:$C$13,2,FALSE),0) -> 11 | X10: =U10*W10 -> 2200 | Y10: =Q10/0.8 -> 250 | Z10: =+Y10*R10 -> 250 | AA10: EUR | AB10: =IFERROR(VLOOKUP(AA10,Curr!$B$2:$C$13,2,FALSE),0) -> 11 | AC10: =+Y10*AB10*R10 -> 2750 | AD10: =+AC10-X10 -> 550 | AE10: =IFERROR(AD10/AC10,0) -> 0.2
C11: Day 1 | D11: Leisure | J11: Reykjavik: Spend time at leisure | Q11: 0 | R11: 0 | S11: =+Q11*R11 -> 0 | T11: 0 | U11: =S11*(1-T11) -> 0 | V11: EUR | W11: =IFERROR(VLOOKUP(V11,Curr!$B$2:$C$13,2,FALSE),0) -> 11 | X11: =U11*W11 -> 0 | Y11: =Q11 -> 0 | Z11: =+Y11*R11 -> 0 | AA11: EUR | AB11: =IFERROR(VLOOKUP(AA11,Curr!$B$2:$C$13,2,FALSE),0) -> 11 | AC11: =+Y11*AB11*R11 -> 0 | AD11: =+AC11-X11 -> 0 | AE11: =IFERROR(AD11/AC11,0) -> 0
S12: =+Q12*R12 -> 0 | T12: 0 | U12: =S12*(1-T12) -> 0 | V12: EUR | W12: =IFERROR(VLOOKUP(V12,Curr!$B$2:$C$13,2,FALSE),0) -> 11 | X12: =U12*W12 -> 0 | Y12: =Q12 -> 0 | Z12: =+Y12*R12 -> 0 | AA12: EUR | AB12: =IFERROR(VLOOKUP(AA12,Curr!$B$2:$C$13,2,FALSE),0) -> 11 | AC12: =+Y12*AB12*R12 -> 0 | AD12: =+AC12-X12 -> 0 | AE12: =IFERROR(AD12/AC12,0) -> 0
C13: Day 2 | D13: Drive | J13: Reykjavik: Drive to Vik I Myrdal via the Golden Circle - Driving time: 5.5hrs - 6.5hrs - Highlights: Þingvellir National Park, Geysir (Strokkur), Gullfoss, Seljalandsfoss, Skógafoss, Reynisfjara - Hidden Gems: Kerið, Gljúfrabúi, Dyrhólaey coastal viewpoints (weather permitting) | Q13: 0 | R13: 0 | S13: =+Q13*R13 -> 0 | T13: 0 | U13: =S13*(1-T13) -> 0 | V13: EUR | W13: =IFERROR(VLOOKUP(V13,Curr!$B$2:$C$13,2,FALSE),0) -> 11 | X13: =U13*W13 -> 0 | Y13: =Q13 -> 0 | Z13: =+Y13*R13 -> 0 | AA13: EUR | AB13: =IFERROR(VLOOKUP(AA13,Curr!$B$2:$C$13,2,FALSE),0) -> 11 | AC13: =+Y13*AB13*R13 -> 0 | AD13: =+AC13-X13 -> 0 | AE13: =IFERROR(AD13/AC13,0) -> 0
C14: Day 2 | D14: Hotel | J14: Vik i Myrdal: Check in to your accommodation for a 1 night stay - Cenrally located 3/4-star hotel - Standard room - breakfast included | Q14: 250 | R14: 1 | S14: =+Q14*R14 -> 250 | T14: 0 | U14: =S14*(1-T14) -> 250 | V14: EUR | W14: =IFERROR(VLOOKUP(V14,Curr!$B$2:$C$13,2,FALSE),0) -> 11 | X14: =U14*W14 -> 2750 | Y14: =Q14/0.8 -> 312.5 | Z14: =+Y14*R14 -> 312.5 | AA14: EUR | AB14: =IFERROR(VLOOKUP(AA14,Curr!$B$2:$C$13,2,FALSE),0) -> 11 | AC14: =+Y14*AB14*R14 -> 3437.5 | AD14: =+AC14-X14 -> 687.5 | AE14: =IFERROR(AD14/AC14,0) -> 0.2
C15: Day 2 | D15: Leisure | J15: Vik i Myrdal: Spend time at leisure | Q15: 0 | R15: 0 | S15: =+Q15*R15 -> 0 | T15: 0 | U15: =S15*(1-T15) -> 0 | V15: EUR | W15: =IFERROR(VLOOKUP(V15,Curr!$B$2:$C$13,2,FALSE),0) -> 11 | X15: =U15*W15 -> 0 | Y15: =Q15 -> 0 | Z15: =+Y15*R15 -> 0 | AA15: EUR | AB15: =IFERROR(VLOOKUP(AA15,Curr!$B$2:$C$13,2,FALSE),0) -> 11 | AC15: =+Y15*AB15*R15 -> 0 | AD15: =+AC15-X15 -> 0 | AE15: =IFERROR(AD15/AC15,0) -> 0
S16: =+Q16*R16 -> 0 | T16: 0 | U16: =S16*(1-T16) -> 0 | V16: EUR | W16: =IFERROR(VLOOKUP(V16,Curr!$B$2:$C$13,2,FALSE),0) -> 11 | X16: =U16*W16 -> 0 | Y16: =Q16 -> 0 | Z16: =+Y16*R16 -> 0 | AA16: EUR | AB16: =IFERROR(VLOOKUP(AA16,Curr!$B$2:$C$13,2,FALSE),0) -> 11 | AC16: =+Y16*AB16*R16 -> 0 | AD16: =+AC16-X16 -> 0 | AE16: =IFERROR(AD16/AC16,0) -> 0
C17: Day 3 | D17: Drive | J17: Vik i Myrdal: Drive to Höfn - Driving time: 4.5hrs - 5.5 hrs - Highlights: Fjaðrárgljúfur, Skaftafell, Svartifoss, Jökulsárlón, Diamond Beach - Hidden Gems: Moss-covered lava fields of Eldhraun, Svínafellsjökull, Quiet pull-offs along Skeiðarársandur outwash plain | Q17: 0 | R17: 0 | S17: =+Q17*R17 -> 0 | T17: 0 | U17: =S17*(1-T17) -> 0 | V17: EUR | W17: =IFERROR(VLOOKUP(V17,Curr!$B$2:$C$13,2,FALSE),0) -> 11 | X17: =U17*W17 -> 0 | Y17: =Q17 -> 0 | Z17: =+Y17*R17 -> 0 | AA17: EUR | AB17: =IFERROR(VLOOKUP(AA17,Curr!$B$2:$C$13,2,FALSE),0) -> 11 | AC17: =+Y17*AB17*R17 -> 0 | AD17: =+AC17-X17 -> 0 | AE17: =IFERROR(AD17/AC17,0) -> 0
C18: Day 3 | D18: Hotel | J18: Höfn: Check in to your accommodation for a 1 night stay - Cenrally located 3/4-star hotel - Standard room - breakfast included | Q18: 200 | R18: 1 | S18: =+Q18*R18 -> 200 | T18: 0 | U18: =S18*(1-T18) -> 200 | V18: EUR | W18: =IFERROR(VLOOKUP(V18,Curr!$B$2:$C$13,2,FALSE),0) -> 11 | X18: =U18*W18 -> 2200 | Y18: =Q18/0.8 -> 250 | Z18: =+Y18*R18 -> 250 | AA18: EUR | AB18: =IFERROR(VLOOKUP(AA18,Curr!$B$2:$C$13,2,FALSE),0) -> 11 | AC18: =+Y18*AB18*R18 -> 2750 | AD18: =+AC18-X18 -> 550 | AE18: =IFERROR(AD18/AC18,0) -> 0.2
C19: Day 3 | D19: Leisure | J19: Höfn: Spend time at leisure | Q19: 0 | R19: 0 | S19: =+Q19*R19 -> 0 | T19: 0 | U19: =S19*(1-T19) -> 0 | V19: EUR | W19: =IFERROR(VLOOKUP(V19,Curr!$B$2:$C$13,2,FALSE),0) -> 11 | X19: =U19*W19 -> 0 | Y19: =Q19 -> 0 | Z19: =+Y19*R19 -> 0 | AA19: EUR | AB19: =IFERROR(VLOOKUP(AA19,Curr!$B$2:$C$13,2,FALSE),0) -> 11 | AC19: =+Y19*AB19*R19 -> 0 | AD19: =+AC19-X19 -> 0 | AE19: =IFERROR(AD19/AC19,0) -> 0
S20: =+Q20*R20 -> 0 | T20: 0 | U20: =S20*(1-T20) -> 0 | V20: EUR | W20: =IFERROR(VLOOKUP(V20,Curr!$B$2:$C$13,2,FALSE),0) -> 11 | X20: =U20*W20 -> 0 | Y20: =Q20 -> 0 | Z20: =+Y20*R20 -> 0 | AA20: EUR | AB20: =IFERROR(VLOOKUP(AA20,Curr!$B$2:$C$13,2,FALSE),0) -> 11 | AC20: =+Y20*AB20*R20 -> 0 | AD20: =+AC20-X20 -> 0 | AE20: =IFERROR(AD20/AC20,0) -> 0
C21: Day 4 | D21: Drive | J21: Höfn: Drive to Myvatn - Driving time: 6.5hrs - 7.5hrs - Highlights: Djúpivogur coastal scenery, Eastfjords mountain passes & fjords, Dettifoss, Lake Mývatn area - Hidden Gems: Eggin í Gleðivík, Stuðlagil Canyon, Hverir | Q21: 0 | R21: 0 | S21: =+Q21*R21 -> 0 | T21: 0 | U21: =S21*(1-T21) -> 0 | V21: EUR | W21: =IFERROR(VLOOKUP(V21,Curr!$B$2:$C$13,2,FALSE),0) -> 11 | X21: =U21*W21 -> 0 | Y21: =Q21 -> 0 | Z21: =+Y21*R21 -> 0 | AA21: EUR | AB21: =IFERROR(VLOOKUP(AA21,Curr!$B$2:$C$13,2,FALSE),0) -> 11 | AC21: =+Y21*AB21*R21 -> 0 | AD21: =+AC21-X21 -> 0 | AE21: =IFERROR(AD21/AC21,0) -> 0
C22: Day 4 | D22: Hotel | J22: Myvatn: Check in to your accommodation for a 1 night stay - Cenrally located 3/4-star hotel - Standard room - breakfast included | Q22: 225 | R22: 1 | S22: =+Q22*R22 -> 225 | T22: 0 | U22: =S22*(1-T22) -> 225 | V22: EUR | W22: =IFERROR(VLOOKUP(V22,Curr!$B$2:$C$13,2,FALSE),0) -> 11 | X22: =U22*W22 -> 2475 | Y22: =Q22/0.8 -> 281.25 | Z22: =+Y22*R22 -> 281.25 | AA22: EUR | AB22: =IFERROR(VLOOKUP(AA22,Curr!$B$2:$C$13,2,FALSE),0) -> 11 | AC22: =+Y22*AB22*R22 -> 3093.75 | AD22: =+AC22-X22 -> 618.75 | AE22: =IFERROR(AD22/AC22,0) -> 0.2
C23: Day 4 | D23: Leisure | J23: Myvatn: Spend time at leisure | Q23: 0 | R23: 0 | S23: =+Q23*R23 -> 0 | T23: 0 | U23: =S23*(1-T23) -> 0 | V23: EUR | W23: =IFERROR(VLOOKUP(V23,Curr!$B$2:$C$13,2,FALSE),0) -> 11 | X23: =U23*W23 -> 0 | Y23: =Q23 -> 0 | Z23: =+Y23*R23 -> 0 | AA23: EUR | AB23: =IFERROR(VLOOKUP(AA23,Curr!$B$2:$C$13,2,FALSE),0) -> 11 | AC23: =+Y23*AB23*R23 -> 0 | AD23: =+AC23-X23 -> 0 | AE23: =IFERROR(AD23/AC23,0) -> 0
S24: =+Q24*R24 -> 0 | T24: 0 | U24: =S24*(1-T24) -> 0 | V24: EUR | W24: =IFERROR(VLOOKUP(V24,Curr!$B$2:$C$13,2,FALSE),0) -> 11 | X24: =U24*W24 -> 0 | Y24: =Q24 -> 0 | Z24: =+Y24*R24 -> 0 | AA24: EUR | AB24: =IFERROR(VLOOKUP(AA24,Curr!$B$2:$C$13,2,FALSE),0) -> 11 | AC24: =+Y24*AB24*R24 -> 0 | AD24: =+AC24-X24 -> 0 | AE24: =IFERROR(AD24/AC24,0) -> 0
C25: Day 5 | D25: Drive | J25: Myvatn: Drive to Borgarnes via the Diamond Circle - Driving time: 3.5hrs - 4.5hrs - Highlights: Dettifoss, Ásbyrgi, Húsavík, Goðafoss, Hraunfossar, Barnafoss - Hidden Gems: Grjótagjá, Hljóðaklettar, Quiet stretches along Skagafjörður farmland | Q25: 0 | R25: 0 | S25: =+Q25*R25 -> 0 | T25: 0 | U25: =S25*(1-T25) -> 0 | V25: EUR | W25: =IFERROR(VLOOKUP(V25,Curr!$B$2:$C$13,2,FALSE),0) -> 11 | X25: =U25*W25 -> 0 | Y25: =Q25 -> 0 | Z25: =+Y25*R25 -> 0 | AA25: EUR | AB25: =IFERROR(VLOOKUP(AA25,Curr!$B$2:$C$13,2,FALSE),0) -> 11 | AC25: =+Y25*AB25*R25 -> 0 | AD25: =+AC25-X25 -> 0 | AE25: =IFERROR(AD25/AC25,0) -> 0
C26: Day 5 | D26: Hotel | J26: Borgarnes: Check in to your accommodation for a 1 night stay - Cenrally located 3/4-star hotel - Standard room - breakfast included | Q26: 175 | R26: 1 | S26: =+Q26*R26 -> 175 | T26: 0 | U26: =S26*(1-T26) -> 175 | V26: EUR | W26: =IFERROR(VLOOKUP(V26,Curr!$B$2:$C$13,2,FALSE),0) -> 11 | X26: =U26*W26 -> 1925 | Y26: =Q26/0.8 -> 218.75 | Z26: =+Y26*R26 -> 218.75 | AA26: EUR | AB26: =IFERROR(VLOOKUP(AA26,Curr!$B$2:$C$13,2,FALSE),0) -> 11 | AC26: =+Y26*AB26*R26 -> 2406.25 | AD26: =+AC26-X26 -> 481.25 | AE26: =IFERROR(AD26/AC26,0) -> 0.2
C27: Day 5 | D27: Leisure | J27: Borgarnes: Spend time at leisure | Q27: 0 | R27: 0 | S27: =+Q27*R27 -> 0 | T27: 0 | U27: =S27*(1-T27) -> 0 | V27: EUR | W27: =IFERROR(VLOOKUP(V27,Curr!$B$2:$C$13,2,FALSE),0) -> 11 | X27: =U27*W27 -> 0 | Y27: =Q27 -> 0 | Z27: =+Y27*R27 -> 0 | AA27: EUR | AB27: =IFERROR(VLOOKUP(AA27,Curr!$B$2:$C$13,2,FALSE),0) -> 11 | AC27: =+Y27*AB27*R27 -> 0 | AD27: =+AC27-X27 -> 0 | AE27: =IFERROR(AD27/AC27,0) -> 0
S28: =+Q28*R28 -> 0 | T28: 0 | U28: =S28*(1-T28) -> 0 | V28: EUR | W28: =IFERROR(VLOOKUP(V28,Curr!$B$2:$C$13,2,FALSE),0) -> 11 | X28: =U28*W28 -> 0 | Y28: =Q28 -> 0 | Z28: =+Y28*R28 -> 0 | AA28: EUR | AB28: =IFERROR(VLOOKUP(AA28,Curr!$B$2:$C$13,2,FALSE),0) -> 11 | AC28: =+Y28*AB28*R28 -> 0 | AD28: =+AC28-X28 -> 0 | AE28: =IFERROR(AD28/AC28,0) -> 0
C29: Day 6 | D29: Drive | J29: Borgarnes: Drive to Keflavik Airport - Driving time: 1.5hrs - 2hrs - Highlights: Hvalfjörður coastal drive (Route 47), Mountain and fjord scenery in West Iceland, Reykjanes lava landscapes near Keflavík - Hidden Gems: Glymur (short hike), Quiet pull-offs along Hvalfjörður, Small geothermal areas on the Reykjanes Peninsula | Q29: 0 | R29: 0 | S29: =+Q29*R29 -> 0 | T29: 0 | U29: =S29*(1-T29) -> 0 | V29: EUR | W29: =IFERROR(VLOOKUP(V29,Curr!$B$2:$C$13,2,FALSE),0) -> 11 | X29: =U29*W29 -> 0 | Y29: =Q29 -> 0 | Z29: =+Y29*R29 -> 0 | AA29: EUR | AB29: =IFERROR(VLOOKUP(AA29,Curr!$B$2:$C$13,2,FALSE),0) -> 11 | AC29: =+Y29*AB29*R29 -> 0 | AD29: =+AC29-X29 -> 0 | AE29: =IFERROR(AD29/AC29,0) -> 0
C30: Day 6 | D30: Car | J30: Keflavik: Deliver your car at the car rental office | Q30: 0 | R30: 0 | S30: =+Q30*R30 -> 0 | T30: 0 | U30: =S30*(1-T30) -> 0 | V30: EUR | W30: =IFERROR(VLOOKUP(V30,Curr!$B$2:$C$13,2,FALSE),0) -> 11 | X30: =U30*W30 -> 0 | Y30: =Q30 -> 0 | Z30: =+Y30*R30 -> 0 | AA30: EUR | AB30: =IFERROR(VLOOKUP(AA30,Curr!$B$2:$C$13,2,FALSE),0) -> 11 | AC30: =+Y30*AB30*R30 -> 0 | AD30: =+AC30-X30 -> 0 | AE30: =IFERROR(AD30/AC30,0) -> 0
C31: Day 6 | D31: Departure | J31: Keflavik: Departure home | Q31: 0 | R31: 0 | S31: =+Q31*R31 -> 0 | T31: 0 | U31: =S31*(1-T31) -> 0 | V31: EUR | W31: =IFERROR(VLOOKUP(V31,Curr!$B$2:$C$13,2,FALSE),0) -> 11 | X31: =U31*W31 -> 0 | Y31: =Q31 -> 0 | Z31: =+Y31*R31 -> 0 | AA31: EUR | AB31: =IFERROR(VLOOKUP(AA31,Curr!$B$2:$C$13,2,FALSE),0) -> 11 | AC31: =+Y31*AB31*R31 -> 0 | AD31: =+AC31-X31 -> 0 | AE31: =IFERROR(AD31/AC31,0) -> 0
S32: =+Q32*R32 -> 0 | T32: 0 | U32: =S32*(1-T32) -> 0 | V32: EUR | W32: =IFERROR(VLOOKUP(V32,Curr!$B$2:$C$13,2,FALSE),0) -> 11 | X32: =U32*W32 -> 0 | Y32: =Q32 -> 0 | Z32: =+Y32*R32 -> 0 | AA32: EUR | AB32: =IFERROR(VLOOKUP(AA32,Curr!$B$2:$C$13,2,FALSE),0) -> 11 | AC32: =+Y32*AB32*R32 -> 0 | AD32: =+AC32-X32 -> 0 | AE32: =IFERROR(AD32/AC32,0) -> 0
S33: =+Q33*R33 -> 0 | T33: 0 | U33: =S33*(1-T33) -> 0 | V33: EUR | W33: =IFERROR(VLOOKUP(V33,Curr!$B$2:$C$13,2,FALSE),0) -> 11 | X33: =U33*W33 -> 0 | Y33: =Q33 -> 0 | Z33: =+Y33*R33 -> 0 | AA33: EUR | AB33: =IFERROR(VLOOKUP(AA33,Curr!$B$2:$C$13,2,FALSE),0) -> 11 | AC33: =+Y33*AB33*R33 -> 0 | AD33: =+AC33-X33 -> 0 | AE33: =IFERROR(AD33/AC33,0) -> 0
C34: Day 1 | D34: Activity Upgrade | J34: Reykjavík: City Walking Tour - Time: 2:00 pm - 5:00 pm - Meeting point: Hallgrímskirkja, Hallgrimstorgi 1 - Includes: Professional, English-speaking guide - Highlights: Hallgrímskirkja, All the major landmarks, Hidden street art & local corners, Iceland in a nutshell | P34: https://booknordics.com/iceland/western-iceland/reykjavik/reykjavik-walking-tour-small-group-citywalk | Q34: 37 | R34: 0 | S34: =+Q34*R34 -> 0 | T34: 0.2 | U34: =S34*(1-T34) -> 0 | V34: EUR | W34: =IFERROR(VLOOKUP(V34,Curr!$B$2:$C$13,2,FALSE),0) -> 11 | X34: =U34*W34 -> 0 | Y34: =Q34 -> 37 | Z34: =+Y34*R34 -> 0 | AA34: EUR | AB34: =IFERROR(VLOOKUP(AA34,Curr!$B$2:$C$13,2,FALSE),0) -> 11 | AC34: =+Y34*AB34*R34 -> 0 | AD34: =+AC34-X34 -> 0 | AE34: =IFERROR(AD34/AC34,0) -> 0
C35: Day 1 | D35: Activity Upgrade | J35: Reykjavík: Northern Lights Minibus Tour - Small Group - Time: 8:30 pm - 12:30 am - Meeting point: Hotel pick up - Includes: Pick-up/drop-off in central Reykjavik, Professional, English-speaking guide, Northern lights tour in a small group, Ticket to Aurora Museum Reykjavik, Free Wi-Fi onboard the vehicle, Hot chocolate and refreshments | P35: https://booknordics.com/iceland/western-iceland/reykjavik/northern-lights-small-group-minibus-tour | Q35: 89 | R35: 0 | S35: =+Q35*R35 -> 0 | T35: 0.25 | U35: =S35*(1-T35) -> 0 | V35: EUR | W35: =IFERROR(VLOOKUP(V35,Curr!$B$2:$C$13,2,FALSE),0) -> 11 | X35: =U35*W35 -> 0 | Y35: =Q35 -> 89 | Z35: =+Y35*R35 -> 0 | AA35: EUR | AB35: =IFERROR(VLOOKUP(AA35,Curr!$B$2:$C$13,2,FALSE),0) -> 11 | AC35: =+Y35*AB35*R35 -> 0 | AD35: =+AC35-X35 -> 0 | AE35: =IFERROR(AD35/AC35,0) -> 0
C36: Day 3 | D36: Activity Upgrade | J36: Vik: Katla Ice Cave Super Jeep Tour - Time: 09:30 am - 12:30 pm - Meeting point: Tröll Expeditions Katla Ice Cave - Includes: Super Jeep excursion to Katla Ice Cave, Certified glacier guide and glacier hike, Experienced off-road driver, Ice cave gear: crampons, and helmet | P36: https://booknordics.com/iceland/southern-iceland/vik/katla-ice-cave-super-jeep-from-vik | Q36: 205 | R36: 0 | S36: =+Q36*R36 -> 0 | T36: 0 | U36: =S36*(1-T36) -> 0 | V36: EUR | W36: =IFERROR(VLOOKUP(V36,Curr!$B$2:$C$13,2,FALSE),0) -> 11 | X36: =U36*W36 -> 0 | Y36: =Q36 -> 205 | Z36: =+Y36*R36 -> 0 | AA36: EUR | AB36: =IFERROR(VLOOKUP(AA36,Curr!$B$2:$C$13,2,FALSE),0) -> 11 | AC36: =+Y36*AB36*R36 -> 0 | AD36: =+AC36-X36 -> 0 | AE36: =IFERROR(AD36/AC36,0) -> 0
C37: Day 5 | D37: Activity Upgrade | J37: Akureyri: Whale Watching Tour - Time: 11:00 am - 1:30 pm - Meeting point: Oddeyrarbót 2, next to the cultural centre HOF in Akureyri - Includes: Whale watching tour approx. 2,5-3 hrs, Knowledgeable, English-speaking guides, Use of warm overalls and blankets, Warm indoor saloom and Free WiFi, Panoramic viewing windows | P37: https://booknordics.com/iceland/northern-iceland/akureyri/akureyri-classic-whale-watching | Q37: 99 | R37: 0 | S37: =+Q37*R37 -> 0 | T37: 0.25 | U37: =S37*(1-T37) -> 0 | V37: EUR | W37: =IFERROR(VLOOKUP(V37,Curr!$B$2:$C$13,2,FALSE),0) -> 11 | X37: =U37*W37 -> 0 | Y37: =Q37 -> 99 | Z37: =+Y37*R37 -> 0 | AA37: EUR | AB37: =IFERROR(VLOOKUP(AA37,Curr!$B$2:$C$13,2,FALSE),0) -> 11 | AC37: =+Y37*AB37*R37 -> 0 | AD37: =+AC37-X37 -> 0 | AE37: =IFERROR(AD37/AC37,0) -> 0
C38: Day 6 | D38: Activity Upgrade | J38: Reykjavik: Blue Lagoon Comfort Package - Time: 09:00 am - 1:00 pm - Meeting point: Hotel Pick up - Includes: Return transfer, Entrance to the Blue Lagoon, Silica mud mask at the Mask Bar, Use of towel, shampoo, conditioner, and moisturizer, Private locker, Non-alcoholic drink at the in-water bar | P38: https://booknordics.com/iceland/western-iceland/reykjavik/reykjavik-blue-lagoon-comfort-including-admission | Q38: 163 | R38: 0 | S38: =+Q38*R38 -> 0 | T38: 0.2 | U38: =S38*(1-T38) -> 0 | V38: EUR | W38: =IFERROR(VLOOKUP(V38,Curr!$B$2:$C$13,2,FALSE),0) -> 11 | X38: =U38*W38 -> 0 | Y38: =Q38 -> 163 | Z38: =+Y38*R38 -> 0 | AA38: EUR | AB38: =IFERROR(VLOOKUP(AA38,Curr!$B$2:$C$13,2,FALSE),0) -> 11 | AC38: =+Y38*AB38*R38 -> 0 | AD38: =+AC38-X38 -> 0 | AE38: =IFERROR(AD38/AC38,0) -> 0
S39: =+Q39*R39 -> 0 | T39: 0 | U39: =S39*(1-T39) -> 0 | V39: EUR | W39: =IFERROR(VLOOKUP(V39,Curr!$B$2:$C$13,2,FALSE),0) -> 11 | X39: =U39*W39 -> 0 | Y39: =Q39 -> 0 | Z39: =+Y39*R39 -> 0 | AA39: EUR | AB39: =IFERROR(VLOOKUP(AA39,Curr!$B$2:$C$13,2,FALSE),0) -> 11 | AC39: =+Y39*AB39*R39 -> 0 | AD39: =+AC39-X39 -> 0 | AE39: =IFERROR(AD39/AC39,0) -> 0
S40: =+Q40*R40 -> 0 | T40: 0 | U40: =S40*(1-T40) -> 0 | V40: EUR | W40: =IFERROR(VLOOKUP(V40,Curr!$B$2:$C$13,2,FALSE),0) -> 11 | X40: =U40*W40 -> 0 | Y40: =Q40 -> 0 | Z40: =+Y40*R40 -> 0 | AA40: EUR | AB40: =IFERROR(VLOOKUP(AA40,Curr!$B$2:$C$13,2,FALSE),0) -> 11 | AC40: =+Y40*AB40*R40 -> 0 | AD40: =+AC40-X40 -> 0 | AE40: =IFERROR(AD40/AC40,0) -> 0
C41: Day 1 | D41: Extra Hotel Night | J41: Reykjavik: Add on an extra night in Reykjavik | Q41: 225 | R41: 0 | S41: =+Q41*R41 -> 0 | T41: 0 | U41: =S41*(1-T41) -> 0 | V41: EUR | W41: =IFERROR(VLOOKUP(V41,Curr!$B$2:$C$13,2,FALSE),0) -> 11 | X41: =U41*W41 -> 0 | Y41: =Q41/0.85 -> 264.70588 | Z41: =+Y41*R41 -> 0 | AA41: EUR | AB41: =IFERROR(VLOOKUP(AA41,Curr!$B$2:$C$13,2,FALSE),0) -> 11 | AC41: =+Y41*AB41*R41 -> 0 | AD41: =+AC41-X41 -> 0 | AE41: =IFERROR(AD41/AC41,0) -> 0
...

Sheet 7D SD
B1: Season: All
B2: Places: Reykjavik 1N - Vik I Myrdal 1N - Hofn 1N - Egilsstadir 1N - Akureyri 1N - Reykjavik 1N
B3: Pax: 2
B4: Rooming: Double
B6: ID | C6: Day | D6: Type | E6: From date | F6: To date | G6: From time | H6: To time | I6: Supplier | J6: Travel element | K6: Manual booking? | L6: Status | M6: Comments | N6: Non-refundable | O6: Refundable | P6: URL | Q6: Gross P per unit | R6: Units | S6: Gross P | T6: Supp Comm | U6: Net P | V6: Supp curr | W6: X-rate | X6: Net P NOK | Y6: Sales P per unit | Z6: Price | AA6: Sales curr | AB6: X-rate | AC6: Sales P NOK tot | AD6: GP NOK | AE6: GP % | AF6: VAT25 | AG6: VAT15 | AH6: VAT12 | AI6: VAT0-D | AJ6: VAT0-I
C7: Day 1 | D7: Arrival | J7: Keflavik: Welcome to Iceland | Q7: 0 | R7: 0 | S7: =+Q7*R7 -> 0 | T7: 0 | U7: =S7*(1-T7) -> 0 | V7: EUR | W7: =IFERROR(VLOOKUP(V7,Curr!$B$2:$C$13,2,FALSE),0) -> 11 | X7: =U7*W7 -> 0 | Y7: =Q7 -> 0 | Z7: =+Y7*R7 -> 0 | AA7: EUR | AB7: =IFERROR(VLOOKUP(AA7,Curr!$B$2:$C$13,2,FALSE),0) -> 11 | AC7: =+Y7*AB7*R7 -> 0 | AD7: =+AC7-X7 -> 0 | AE7: =IFERROR(AD7/AC7,0) -> 0
C8: Day 1 | D8: Car | J8: Keflavik: Pick up your rental car at the car rental office - A 4x4 will with room for 4 luggages will be provided - Includes: Basic Insuarance - Excludes: Deposit | Q8: 550 | R8: 1 | S8: =+Q8*R8 -> 550 | T8: 0 | U8: =S8*(1-T8) -> 550 | V8: EUR | W8: =IFERROR(VLOOKUP(V8,Curr!$B$2:$C$13,2,FALSE),0) -> 11 | X8: =U8*W8 -> 6050 | Y8: =Q8/0.8 -> 687.5 | Z8: =+Y8*R8 -> 687.5 | AA8: EUR | AB8: =IFERROR(VLOOKUP(AA8,Curr!$B$2:$C$13,2,FALSE),0) -> 11 | AC8: =+Y8*AB8*R8 -> 7562.5 | AD8: =+AC8-X8 -> 1512.5 | AE8: =IFERROR(AD8/AC8,0) -> 0.2
C9: Day 1 | D9: Drive | J9: Keflavik: Drive to Reykjavik - Driving time: 45 min - 1 hr - Optional Stops: Reykjanes lava fields, Coastal views along Route 41, Faxaflói Bay viewpoints (weather permitting) - Hidden Gems: Small roadside lava formations, Quiet pull-offs with ocean views, Reykjanes Peninsula backroad detours (only if not rushing) | Q9: 0 | R9: 0 | S9: =+Q9*R9 -> 0 | T9: 0 | U9: =S9*(1-T9) -> 0 | V9: EUR | W9: =IFERROR(VLOOKUP(V9,Curr!$B$2:$C$13,2,FALSE),0) -> 11 | X9: =U9*W9 -> 0 | Y9: =Q9 -> 0 | Z9: =+Y9*R9 -> 0 | AA9: EUR | AB9: =IFERROR(VLOOKUP(AA9,Curr!$B$2:$C$13,2,FALSE),0) -> 11 | AC9: =+Y9*AB9*R9 -> 0 | AD9: =+AC9-X9 -> 0 | AE9: =IFERROR(AD9/AC9,0) -> 0
C10: Day 1 | D10: Hotel | J10: Reykjavik: Check in to your accommodation for a 1 night stay - Cenrally located 3/4-star hotel - Standard room - breakfast included | P10: https://www.ratehawk.com/?sid=5c11424c-1694-4e32-9a64-786852f88adb | Q10: 200 | R10: 1 | S10: =+Q10*R10 -> 200 | T10: 0 | U10: =S10*(1-T10) -> 200 | V10: EUR | W10: =IFERROR(VLOOKUP(V10,Curr!$B$2:$C$13,2,FALSE),0) -> 11 | X10: =U10*W10 -> 2200 | Y10: =Q10/0.8 -> 250 | Z10: =+Y10*R10 -> 250 | AA10: EUR | AB10: =IFERROR(VLOOKUP(AA10,Curr!$B$2:$C$13,2,FALSE),0) -> 11 | AC10: =+Y10*AB10*R10 -> 2750 | AD10: =+AC10-X10 -> 550 | AE10: =IFERROR(AD10/AC10,0) -> 0.2
C11: Day 1 | D11: Leisure | J11: Reykjavik: Spend time at leisure | Q11: 0 | R11: 0 | S11: =+Q11*R11 -> 0 | T11: 0 | U11: =S11*(1-T11) -> 0 | V11: EUR | W11: =IFERROR(VLOOKUP(V11,Curr!$B$2:$C$13,2,FALSE),0) -> 11 | X11: =U11*W11 -> 0 | Y11: =Q11 -> 0 | Z11: =+Y11*R11 -> 0 | AA11: EUR | AB11: =IFERROR(VLOOKUP(AA11,Curr!$B$2:$C$13,2,FALSE),0) -> 11 | AC11: =+Y11*AB11*R11 -> 0 | AD11: =+AC11-X11 -> 0 | AE11: =IFERROR(AD11/AC11,0) -> 0
S12: =+Q12*R12 -> 0 | T12: 0 | U12: =S12*(1-T12) -> 0 | V12: EUR | W12: =IFERROR(VLOOKUP(V12,Curr!$B$2:$C$13,2,FALSE),0) -> 11 | X12: =U12*W12 -> 0 | Y12: =Q12 -> 0 | Z12: =+Y12*R12 -> 0 | AA12: EUR | AB12: =IFERROR(VLOOKUP(AA12,Curr!$B$2:$C$13,2,FALSE),0) -> 11 | AC12: =+Y12*AB12*R12 -> 0 | AD12: =+AC12-X12 -> 0 | AE12: =IFERROR(AD12/AC12,0) -> 0
C13: Day 2 | D13: Drive | J13: Reykjavik: Drive to Vik I Myrdal via the Golden Circle - Driving time: 5.5hrs - 6.5hrs - Highlights: Þingvellir National Park, Geysir (Strokkur), Gullfoss, Seljalandsfoss, Skógafoss, Reynisfjara - Hidden Gems: Kerið, Gljúfrabúi, Dyrhólaey coastal viewpoints (weather permitting) | Q13: 0 | R13: 0 | S13: =+Q13*R13 -> 0 | T13: 0 | U13: =S13*(1-T13) -> 0 | V13: EUR | W13: =IFERROR(VLOOKUP(V13,Curr!$B$2:$C$13,2,FALSE),0) -> 11 | X13: =U13*W13 -> 0 | Y13: =Q13 -> 0 | Z13: =+Y13*R13 -> 0 | AA13: EUR | AB13: =IFERROR(VLOOKUP(AA13,Curr!$B$2:$C$13,2,FALSE),0) -> 11 | AC13: =+Y13*AB13*R13 -> 0 | AD13: =+AC13-X13 -> 0 | AE13: =IFERROR(AD13/AC13,0) -> 0
C14: Day 2 | D14: Hotel | J14: Vik i Myrdal: Check in to your accommodation for a 1 night stay - Cenrally located 3/4-star hotel - Standard room - breakfast included | Q14: 250 | R14: 1 | S14: =+Q14*R14 -> 250 | T14: 0 | U14: =S14*(1-T14) -> 250 | V14: EUR | W14: =IFERROR(VLOOKUP(V14,Curr!$B$2:$C$13,2,FALSE),0) -> 11 | X14: =U14*W14 -> 2750 | Y14: =Q14/0.8 -> 312.5 | Z14: =+Y14*R14 -> 312.5 | AA14: EUR | AB14: =IFERROR(VLOOKUP(AA14,Curr!$B$2:$C$13,2,FALSE),0) -> 11 | AC14: =+Y14*AB14*R14 -> 3437.5 | AD14: =+AC14-X14 -> 687.5 | AE14: =IFERROR(AD14/AC14,0) -> 0.2
C15: Day 2 | D15: Leisure | J15: Vik i Myrdal: Spend time at leisure | Q15: 0 | R15: 0 | S15: =+Q15*R15 -> 0 | T15: 0 | U15: =S15*(1-T15) -> 0 | V15: EUR | W15: =IFERROR(VLOOKUP(V15,Curr!$B$2:$C$13,2,FALSE),0) -> 11 | X15: =U15*W15 -> 0 | Y15: =Q15 -> 0 | Z15: =+Y15*R15 -> 0 | AA15: EUR | AB15: =IFERROR(VLOOKUP(AA15,Curr!$B$2:$C$13,2,FALSE),0) -> 11 | AC15: =+Y15*AB15*R15 -> 0 | AD15: =+AC15-X15 -> 0 | AE15: =IFERROR(AD15/AC15,0) -> 0
S16: =+Q16*R16 -> 0 | T16: 0 | U16: =S16*(1-T16) -> 0 | V16: EUR | W16: =IFERROR(VLOOKUP(V16,Curr!$B$2:$C$13,2,FALSE),0) -> 11 | X16: =U16*W16 -> 0 | Y16: =Q16 -> 0 | Z16: =+Y16*R16 -> 0 | AA16: EUR | AB16: =IFERROR(VLOOKUP(AA16,Curr!$B$2:$C$13,2,FALSE),0) -> 11 | AC16: =+Y16*AB16*R16 -> 0 | AD16: =+AC16-X16 -> 0 | AE16: =IFERROR(AD16/AC16,0) -> 0
C17: Day 3 | D17: Drive | J17: Vik i Myrdal: Drive to Höfn - Driving time: 4.5hrs - 5.5 hrs - Highlights: Fjaðrárgljúfur, Skaftafell, Svartifoss, Jökulsárlón, Diamond Beach - Hidden Gems: Moss-covered lava fields of Eldhraun, Svínafellsjökull, Quiet pull-offs along Skeiðarársandur outwash plain | Q17: 0 | R17: 0 | S17: =+Q17*R17 -> 0 | T17: 0 | U17: =S17*(1-T17) -> 0 | V17: EUR | W17: =IFERROR(VLOOKUP(V17,Curr!$B$2:$C$13,2,FALSE),0) -> 11 | X17: =U17*W17 -> 0 | Y17: =Q17 -> 0 | Z17: =+Y17*R17 -> 0 | AA17: EUR | AB17: =IFERROR(VLOOKUP(AA17,Curr!$B$2:$C$13,2,FALSE),0) -> 11 | AC17: =+Y17*AB17*R17 -> 0 | AD17: =+AC17-X17 -> 0 | AE17: =IFERROR(AD17/AC17,0) -> 0
C18: Day 3 | D18: Hotel | J18: Höfn: Check in to your accommodation for a 1 night stay - Cenrally located 3/4-star hotel - Standard room - breakfast included | Q18: 200 | R18: 1 | S18: =+Q18*R18 -> 200 | T18: 0 | U18: =S18*(1-T18) -> 200 | V18: EUR | W18: =IFERROR(VLOOKUP(V18,Curr!$B$2:$C$13,2,FALSE),0) -> 11 | X18: =U18*W18 -> 2200 | Y18: =Q18/0.8 -> 250 | Z18: =+Y18*R18 -> 250 | AA18: EUR | AB18: =IFERROR(VLOOKUP(AA18,Curr!$B$2:$C$13,2,FALSE),0) -> 11 | AC18: =+Y18*AB18*R18 -> 2750 | AD18: =+AC18-X18 -> 550 | AE18: =IFERROR(AD18/AC18,0) -> 0.2
C19: Day 3 | D19: Leisure | J19: Höfn: Spend time at leisure | Q19: 0 | R19: 0 | S19: =+Q19*R19 -> 0 | T19: 0 | U19: =S19*(1-T19) -> 0 | V19: EUR | W19: =IFERROR(VLOOKUP(V19,Curr!$B$2:$C$13,2,FALSE),0) -> 11 | X19: =U19*W19 -> 0 | Y19: =Q19 -> 0 | Z19: =+Y19*R19 -> 0 | AA19: EUR | AB19: =IFERROR(VLOOKUP(AA19,Curr!$B$2:$C$13,2,FALSE),0) -> 11 | AC19: =+Y19*AB19*R19 -> 0 | AD19: =+AC19-X19 -> 0 | AE19: =IFERROR(AD19/AC19,0) -> 0
S20: =+Q20*R20 -> 0 | T20: 0 | U20: =S20*(1-T20) -> 0 | V20: EUR | W20: =IFERROR(VLOOKUP(V20,Curr!$B$2:$C$13,2,FALSE),0) -> 11 | X20: =U20*W20 -> 0 | Y20: =Q20 -> 0 | Z20: =+Y20*R20 -> 0 | AA20: EUR | AB20: =IFERROR(VLOOKUP(AA20,Curr!$B$2:$C$13,2,FALSE),0) -> 11 | AC20: =+Y20*AB20*R20 -> 0 | AD20: =+AC20-X20 -> 0 | AE20: =IFERROR(AD20/AC20,0) -> 0
C21: Day 4 | D21: Drive | J21: Höfn: Drive to Egilsstaðir - Driving time: 3.5hrs - 4-5hrs - Highlights: Eastfjords coastal & mountain scenery, Djúpivogur, Fjord crossings and dramatic mountain passes, Lagarfljót - Hidden Gems: Eggin í Gleðivík, Remote Eastfjords viewpoints, Small roadside waterfalls along Route 1 | Q21: 0 | R21: 0 | S21: =+Q21*R21 -> 0 | T21: 0 | U21: =S21*(1-T21) -> 0 | V21: EUR | W21: =IFERROR(VLOOKUP(V21,Curr!$B$2:$C$13,2,FALSE),0) -> 11 | X21: =U21*W21 -> 0 | Y21: =Q21 -> 0 | Z21: =+Y21*R21 -> 0 | AA21: EUR | AB21: =IFERROR(VLOOKUP(AA21,Curr!$B$2:$C$13,2,FALSE),0) -> 11 | AC21: =+Y21*AB21*R21 -> 0 | AD21: =+AC21-X21 -> 0 | AE21: =IFERROR(AD21/AC21,0) -> 0
C22: Day 4 | D22: Hotel | J22: Egilsstaðir: Check in to your accommodation for a 1 night stay - Cenrally located 3/4-star hotel - Standard room - breakfast included | Q22: 250 | R22: 1 | S22: =+Q22*R22 -> 250 | T22: 0 | U22: =S22*(1-T22) -> 250 | V22: EUR | W22: =IFERROR(VLOOKUP(V22,Curr!$B$2:$C$13,2,FALSE),0) -> 11 | X22: =U22*W22 -> 2750 | Y22: =Q22/0.8 -> 312.5 | Z22: =+Y22*R22 -> 312.5 | AA22: EUR | AB22: =IFERROR(VLOOKUP(AA22,Curr!$B$2:$C$13,2,FALSE),0) -> 11 | AC22: =+Y22*AB22*R22 -> 3437.5 | AD22: =+AC22-X22 -> 687.5 | AE22: =IFERROR(AD22/AC22,0) -> 0.2
C23: Day 4 | D23: Leisure | J23: Egilsstaðir: Spend time at leisure | Q23: 0 | R23: 0 | S23: =+Q23*R23 -> 0 | T23: 0 | U23: =S23*(1-T23) -> 0 | V23: EUR | W23: =IFERROR(VLOOKUP(V23,Curr!$B$2:$C$13,2,FALSE),0) -> 11 | X23: =U23*W23 -> 0 | Y23: =Q23 -> 0 | Z23: =+Y23*R23 -> 0 | AA23: EUR | AB23: =IFERROR(VLOOKUP(AA23,Curr!$B$2:$C$13,2,FALSE),0) -> 11 | AC23: =+Y23*AB23*R23 -> 0 | AD23: =+AC23-X23 -> 0 | AE23: =IFERROR(AD23/AC23,0) -> 0
S24: =+Q24*R24 -> 0 | T24: 0 | U24: =S24*(1-T24) -> 0 | V24: EUR | W24: =IFERROR(VLOOKUP(V24,Curr!$B$2:$C$13,2,FALSE),0) -> 11 | X24: =U24*W24 -> 0 | Y24: =Q24 -> 0 | Z24: =+Y24*R24 -> 0 | AA24: EUR | AB24: =IFERROR(VLOOKUP(AA24,Curr!$B$2:$C$13,2,FALSE),0) -> 11 | AC24: =+Y24*AB24*R24 -> 0 | AD24: =+AC24-X24 -> 0 | AE24: =IFERROR(AD24/AC24,0) -> 0
C25: Day 5 | D25: Drive | J25: Egilsstaðir: Drive to Akureyri, via the Diamond Circle - Driving time: 4.5hrs - 5.5hrs - Highlights: Stuðlagil Canyon, Dettifoss, Ásbyrgi, Goðafoss - Hidden Gems: Hljóðaklettar, Jökulsárgljúfur canyon viewpoints, Quiet stretches near Lake Mývatn | Q25: 0 | R25: 0 | S25: =+Q25*R25 -> 0 | T25: 0 | U25: =S25*(1-T25) -> 0 | V25: EUR | W25: =IFERROR(VLOOKUP(V25,Curr!$B$2:$C$13,2,FALSE),0) -> 11 | X25: =U25*W25 -> 0 | Y25: =Q25 -> 0 | Z25: =+Y25*R25 -> 0 | AA25: EUR | AB25: =IFERROR(VLOOKUP(AA25,Curr!$B$2:$C$13,2,FALSE),0) -> 11 | AC25: =+Y25*AB25*R25 -> 0 | AD25: =+AC25-X25 -> 0 | AE25: =IFERROR(AD25/AC25,0) -> 0
C26: Day 5 | D26: Hotel | J26: Akureyri: Check in to your accommodation for a 1 night stay - Cenrally located 3/4-star hotel - Standard room - breakfast included | Q26: 200 | R26: 1 | S26: =+Q26*R26 -> 200 | T26: 0 | U26: =S26*(1-T26) -> 200 | V26: EUR | W26: =IFERROR(VLOOKUP(V26,Curr!$B$2:$C$13,2,FALSE),0) -> 11 | X26: =U26*W26 -> 2200 | Y26: =Q26/0.8 -> 250 | Z26: =+Y26*R26 -> 250 | AA26: EUR | AB26: =IFERROR(VLOOKUP(AA26,Curr!$B$2:$C$13,2,FALSE),0) -> 11 | AC26: =+Y26*AB26*R26 -> 2750 | AD26: =+AC26-X26 -> 550 | AE26: =IFERROR(AD26/AC26,0) -> 0.2
C27: Day 5 | D27: Leisure | J27: Akureyri: Spend time at leisure | Q27: 0 | R27: 0 | S27: =+Q27*R27 -> 0 | T27: 0 | U27: =S27*(1-T27) -> 0 | V27: EUR | W27: =IFERROR(VLOOKUP(V27,Curr!$B$2:$C$13,2,FALSE),0) -> 11 | X27: =U27*W27 -> 0 | Y27: =Q27 -> 0 | Z27: =+Y27*R27 -> 0 | AA27: EUR | AB27: =IFERROR(VLOOKUP(AA27,Curr!$B$2:$C$13,2,FALSE),0) -> 11 | AC27: =+Y27*AB27*R27 -> 0 | AD27: =+AC27-X27 -> 0 | AE27: =IFERROR(AD27/AC27,0) -> 0
S28: =+Q28*R28 -> 0 | T28: 0 | U28: =S28*(1-T28) -> 0 | V28: EUR | W28: =IFERROR(VLOOKUP(V28,Curr!$B$2:$C$13,2,FALSE),0) -> 11 | X28: =U28*W28 -> 0 | Y28: =Q28 -> 0 | Z28: =+Y28*R28 -> 0 | AA28: EUR | AB28: =IFERROR(VLOOKUP(AA28,Curr!$B$2:$C$13,2,FALSE),0) -> 11 | AC28: =+Y28*AB28*R28 -> 0 | AD28: =+AC28-X28 -> 0 | AE28: =IFERROR(AD28/AC28,0) -> 0
C29: Day 6 | D29: Drive | J29: Akureyri: Drive to Reykjavik - Driving time: 4.5hrs - 5.5hrs - Highlights: Goðafoss, Skagafjörður valley scenery, Borgarnes, Reykjavík arrival - Hidden Gems: Hraunfossar, Barnafoss, Hvalfjörður scenic coastal route (Route 47) | Q29: 0 | R29: 0 | S29: =+Q29*R29 -> 0 | T29: 0 | U29: =S29*(1-T29) -> 0 | V29: EUR | W29: =IFERROR(VLOOKUP(V29,Curr!$B$2:$C$13,2,FALSE),0) -> 11 | X29: =U29*W29 -> 0 | Y29: =Q29 -> 0 | Z29: =+Y29*R29 -> 0 | AA29: EUR | AB29: =IFERROR(VLOOKUP(AA29,Curr!$B$2:$C$13,2,FALSE),0) -> 11 | AC29: =+Y29*AB29*R29 -> 0 | AD29: =+AC29-X29 -> 0 | AE29: =IFERROR(AD29/AC29,0) -> 0
C30: Day 6 | D30: Hotel | J30: Reykjavik: Check in to your accommodation for a 1 night stay - Cenrally located 3/4-star hotel - Standard room - breakfast included | Q30: 200 | R30: 1 | S30: =+Q30*R30 -> 200 | T30: 0 | U30: =S30*(1-T30) -> 200 | V30: EUR | W30: =IFERROR(VLOOKUP(V30,Curr!$B$2:$C$13,2,FALSE),0) -> 11 | X30: =U30*W30 -> 2200 | Y30: =Q30/0.8 -> 250 | Z30: =+Y30*R30 -> 250 | AA30: EUR | AB30: =IFERROR(VLOOKUP(AA30,Curr!$B$2:$C$13,2,FALSE),0) -> 11 | AC30: =+Y30*AB30*R30 -> 2750 | AD30: =+AC30-X30 -> 550 | AE30: =IFERROR(AD30/AC30,0) -> 0.2
C31: Day 6 | D31: Leisure | J31: Reykjavik: Spend time at leisure | Q31: 0 | R31: 0 | S31: =+Q31*R31 -> 0 | T31: 0 | U31: =S31*(1-T31) -> 0 | V31: EUR | W31: =IFERROR(VLOOKUP(V31,Curr!$B$2:$C$13,2,FALSE),0) -> 11 | X31: =U31*W31 -> 0 | Y31: =Q31 -> 0 | Z31: =+Y31*R31 -> 0 | AA31: EUR | AB31: =IFERROR(VLOOKUP(AA31,Curr!$B$2:$C$13,2,FALSE),0) -> 11 | AC31: =+Y31*AB31*R31 -> 0 | AD31: =+AC31-X31 -> 0 | AE31: =IFERROR(AD31/AC31,0) -> 0
S32: =+Q32*R32 -> 0 | T32: 0 | U32: =S32*(1-T32) -> 0 | V32: EUR | W32: =IFERROR(VLOOKUP(V32,Curr!$B$2:$C$13,2,FALSE),0) -> 11 | X32: =U32*W32 -> 0 | Y32: =Q32 -> 0 | Z32: =+Y32*R32 -> 0 | AA32: EUR | AB32: =IFERROR(VLOOKUP(AA32,Curr!$B$2:$C$13,2,FALSE),0) -> 11 | AC32: =+Y32*AB32*R32 -> 0 | AD32: =+AC32-X32 -> 0 | AE32: =IFERROR(AD32/AC32,0) -> 0
C33: Day 7 | D33: Drive | J33: Reykjavik: Drive to Keflavik Airport - Driving time: 45min - 1hrs - Highlights: Reykjanes lava fields, Coastal views toward Faxaflói Bay - Hidden Gems: Small pull-offs with ocean views, Short detours on the Reykjanes Peninsula | Q33: 0 | R33: 0 | S33: =+Q33*R33 -> 0 | T33: 0 | U33: =S33*(1-T33) -> 0 | V33: EUR | W33: =IFERROR(VLOOKUP(V33,Curr!$B$2:$C$13,2,FALSE),0) -> 11 | X33: =U33*W33 -> 0 | Y33: =Q33 -> 0 | Z33: =+Y33*R33 -> 0 | AA33: EUR | AB33: =IFERROR(VLOOKUP(AA33,Curr!$B$2:$C$13,2,FALSE),0) -> 11 | AC33: =+Y33*AB33*R33 -> 0 | AD33: =+AC33-X33 -> 0 | AE33: =IFERROR(AD33/AC33,0) -> 0
C34: Day 7 | D34: Car | J34: Keflavik: Deliver your car at the car rental office | Q34: 0 | R34: 0 | S34: =+Q34*R34 -> 0 | T34: 0 | U34: =S34*(1-T34) -> 0 | V34: EUR | W34: =IFERROR(VLOOKUP(V34,Curr!$B$2:$C$13,2,FALSE),0) -> 11 | X34: =U34*W34 -> 0 | Y34: =Q34 -> 0 | Z34: =+Y34*R34 -> 0 | AA34: EUR | AB34: =IFERROR(VLOOKUP(AA34,Curr!$B$2:$C$13,2,FALSE),0) -> 11 | AC34: =+Y34*AB34*R34 -> 0 | AD34: =+AC34-X34 -> 0 | AE34: =IFERROR(AD34/AC34,0) -> 0
C35: Day 7 | D35: Departure | J35: Keflavik: Departure home | Q35: 0 | R35: 0 | S35: =+Q35*R35 -> 0 | T35: 0 | U35: =S35*(1-T35) -> 0 | V35: EUR | W35: =IFERROR(VLOOKUP(V35,Curr!$B$2:$C$13,2,FALSE),0) -> 11 | X35: =U35*W35 -> 0 | Y35: =Q35 -> 0 | Z35: =+Y35*R35 -> 0 | AA35: EUR | AB35: =IFERROR(VLOOKUP(AA35,Curr!$B$2:$C$13,2,FALSE),0) -> 11 | AC35: =+Y35*AB35*R35 -> 0 | AD35: =+AC35-X35 -> 0 | AE35: =IFERROR(AD35/AC35,0) -> 0
S36: =+Q36*R36 -> 0 | T36: 0 | U36: =S36*(1-T36) -> 0 | V36: EUR | W36: =IFERROR(VLOOKUP(V36,Curr!$B$2:$C$13,2,FALSE),0) -> 11 | X36: =U36*W36 -> 0 | Y36: =Q36 -> 0 | Z36: =+Y36*R36 -> 0 | AA36: EUR | AB36: =IFERROR(VLOOKUP(AA36,Curr!$B$2:$C$13,2,FALSE),0) -> 11 | AC36: =+Y36*AB36*R36 -> 0 | AD36: =+AC36-X36 -> 0 | AE36: =IFERROR(AD36/AC36,0) -> 0
S37: =+Q37*R37 -> 0 | T37: 0 | U37: =S37*(1-T37) -> 0 | V37: EUR | W37: =IFERROR(VLOOKUP(V37,Curr!$B$2:$C$13,2,FALSE),0) -> 11 | X37: =U37*W37 -> 0 | Y37: =Q37 -> 0 | Z37: =+Y37*R37 -> 0 | AA37: EUR | AB37: =IFERROR(VLOOKUP(AA37,Curr!$B$2:$C$13,2,FALSE),0) -> 11 | AC37: =+Y37*AB37*R37 -> 0 | AD37: =+AC37-X37 -> 0 | AE37: =IFERROR(AD37/AC37,0) -> 0
C38: Day 1 | D38: Activity Upgrade | J38: Reykjavík: City Walking Tour - Time: 2:00 pm - 5:00 pm - Meeting point: Hallgrímskirkja, Hallgrimstorgi 1 - Includes: Professional, English-speaking guide - Highlights: Hallgrímskirkja, All the major landmarks, Hidden street art & local corners, Iceland in a nutshell | P38: https://booknordics.com/iceland/western-iceland/reykjavik/reykjavik-walking-tour-small-group-citywalk | Q38: 37 | R38: 0 | S38: =+Q38*R38 -> 0 | T38: 0.2 | U38: =S38*(1-T38) -> 0 | V38: EUR | W38: =IFERROR(VLOOKUP(V38,Curr!$B$2:$C$13,2,FALSE),0) -> 11 | X38: =U38*W38 -> 0 | Y38: =Q38 -> 37 | Z38: =+Y38*R38 -> 0 | AA38: EUR | AB38: =IFERROR(VLOOKUP(AA38,Curr!$B$2:$C$13,2,FALSE),0) -> 11 | AC38: =+Y38*AB38*R38 -> 0 | AD38: =+AC38-X38 -> 0 | AE38: =IFERROR(AD38/AC38,0) -> 0
C39: Day 1 | D39: Activity Upgrade | J39: Reykjavík: Northern Lights Minibus Tour - Small Group - Time: 8:30 pm - 12:30 am - Meeting point: Hotel pick up - Includes: Pick-up/drop-off in central Reykjavik, Professional, English-speaking guide, Northern lights tour in a small group, Ticket to Aurora Museum Reykjavik, Free Wi-Fi onboard the vehicle, Hot chocolate and refreshments | P39: https://booknordics.com/iceland/western-iceland/reykjavik/northern-lights-small-group-minibus-tour | Q39: 89 | R39: 0 | S39: =+Q39*R39 -> 0 | T39: 0.25 | U39: =S39*(1-T39) -> 0 | V39: EUR | W39: =IFERROR(VLOOKUP(V39,Curr!$B$2:$C$13,2,FALSE),0) -> 11 | X39: =U39*W39 -> 0 | Y39: =Q39 -> 89 | Z39: =+Y39*R39 -> 0 | AA39: EUR | AB39: =IFERROR(VLOOKUP(AA39,Curr!$B$2:$C$13,2,FALSE),0) -> 11 | AC39: =+Y39*AB39*R39 -> 0 | AD39: =+AC39-X39 -> 0 | AE39: =IFERROR(AD39/AC39,0) -> 0
C40: Day 3 | D40: Activity Upgrade | J40: Vik: Katla Ice Cave Super Jeep Tour - Time: 09:30 am - 12:30 pm - Meeting point: Tröll Expeditions Katla Ice Cave - Includes: Super Jeep excursion to Katla Ice Cave, Certified glacier guide and glacier hike, Experienced off-road driver, Ice cave gear: crampons, and helmet | P40: https://booknordics.com/iceland/southern-iceland/vik/katla-ice-cave-super-jeep-from-vik | Q40: 205 | R40: 0 | S40: =+Q40*R40 -> 0 | T40: 0 | U40: =S40*(1-T40) -> 0 | V40: EUR | W40: =IFERROR(VLOOKUP(V40,Curr!$B$2:$C$13,2,FALSE),0) -> 11 | X40: =U40*W40 -> 0 | Y40: =Q40 -> 205 | Z40: =+Y40*R40 -> 0 | AA40: EUR | AB40: =IFERROR(VLOOKUP(AA40,Curr!$B$2:$C$13,2,FALSE),0) -> 11 | AC40: =+Y40*AB40*R40 -> 0 | AD40: =+AC40-X40 -> 0 | AE40: =IFERROR(AD40/AC40,0) -> 0
C41: Day 6 | D41: Activity Upgrade | J41: Akureyri: Whale Watching Tour - Time: 11:00 am - 1:30 pm - Meeting point: Oddeyrarbót 2, next to the cultural centre HOF in Akureyri - Includes: Whale watching tour approx. 2,5-3 hrs, Knowledgeable, English-speaking guides, Use of warm overalls and blankets, Warm indoor saloom and Free WiFi, Panoramic viewing windows | P41: https://booknordics.com/iceland/northern-iceland/akureyri/akureyri-classic-whale-watching | Q41: 99 | R41: 0 | S41: =+Q41*R41 -> 0 | T41: 0.25 | U41: =S41*(1-T41) -> 0 | V41: EUR | W41: =IFERROR(VLOOKUP(V41,Curr!$B$2:$C$13,2,FALSE),0) -> 11 | X41: =U41*W41 -> 0 | Y41: =Q41 -> 99 | Z41: =+Y41*R41 -> 0 | AA41: EUR | AB41: =IFERROR(VLOOKUP(AA41,Curr!$B$2:$C$13,2,FALSE),0) -> 11 | AC41: =+Y41*AB41*R41 -> 0 | AD41: =+AC41-X41 -> 0 | AE41: =IFERROR(AD41/AC41,0) -> 0
...

Sheet 8D SD
B1: Season: All
B2: Places: Reykjavik 1N - Vik I Myrdal 1N - Hofn 1N - Egilsstadir 1N - Akureyri 1N - Snæfellsnes Pininsula 1N - Reykjavik 1N
B3: Pax: 2
B4: Rooming: Double
