Workbook

Sheet Curr
C1: NOK
B2: EUR | C2: 11.3
B3: SEK | C3: 1.02
B4: DKK | C4: 1.5
B5: ISK | C5: 0.075
B6: NOK | C6: 1
B7: USD | C7: 10.6

Sheet Mal
B2: Dates:
B3: Pax:
B4: Rooming:
B6: ID | C6: Day | D6: Type | E6: From date | F6: To date | G6: From time | H6: To time | I6: Supplier | J6: Travel element | K6: Manual booking? | L6: Status | M6: Comments | N6: Non-refundable | O6: Refundable | P6: URL | Q6: Gross P per unit | R6: Units | S6: Gross P | T6: Supp Comm | U6: Net P | V6: Supp curr | W6: X-rate | X6: Net P NOK | Y6: Sales P per unit | Z6: Price | AA6: Sales curr | AB6: X-rate | AC6: Sales P NOK tot | AD6: GP NOK | AE6: GP % | AF6: VAT25 | AG6: VAT15 | AH6: VAT12 | AI6: VAT0-D | AJ6: VAT0-I
Q7: 0 | R7: 0 | S7: =+Q7*R7 -> 0 | T7: 0 | U7: =S7*(1-T7) -> 0 | V7: EUR | W7: =IFERROR(VLOOKUP(V7,[1]Curr!$B$2:$C$13,2,FALSE),0) -> 11.3 | X7: =U7*W7 -> 0 | Y7: =Q7 -> 0 | Z7: =+Y7*R7 -> 0 | AA7: EUR | AB7: =IFERROR(VLOOKUP(AA7,Curr!$B$2:$C$13,2,FALSE),0) -> 11.3 | AC7: =+Y7*AB7*R7 -> 0 | AD7: =+AC7-X7 -> 0 | AE7: =IFERROR(AD7/AC7,0) -> 0
Q8: 0 | R8: 0 | S8: =+Q8*R8 -> 0 | T8: 0 | U8: =S8*(1-T8) -> 0 | V8: EUR | W8: =IFERROR(VLOOKUP(V8,[1]Curr!$B$2:$C$13,2,FALSE),0) -> 11.3 | X8: =U8*W8 -> 0 | Y8: =Q8 -> 0 | Z8: =+Y8*R8 -> 0 | AA8: EUR | AB8: =IFERROR(VLOOKUP(AA8,Curr!$B$2:$C$13,2,FALSE),0) -> 11.3 | AC8: =+Y8*AB8*R8 -> 0 | AD8: =+AC8-X8 -> 0 | AE8: =IFERROR(AD8/AC8,0) -> 0
Q9: 0 | R9: 0 | S9: =+Q9*R9 -> 0 | T9: 0 | U9: =S9*(1-T9) -> 0 | V9: EUR | W9: =IFERROR(VLOOKUP(V9,[1]Curr!$B$2:$C$13,2,FALSE),0) -> 11.3 | X9: =U9*W9 -> 0 | Y9: =Q9 -> 0 | Z9: =+Y9*R9 -> 0 | AA9: EUR | AB9: =IFERROR(VLOOKUP(AA9,Curr!$B$2:$C$13,2,FALSE),0) -> 11.3 | AC9: =+Y9*AB9*R9 -> 0 | AD9: =+AC9-X9 -> 0 | AE9: =IFERROR(AD9/AC9,0) -> 0
Q10: 0 | R10: 0 | S10: =+Q10*R10 -> 0 | T10: 0 | U10: =S10*(1-T10) -> 0 | V10: EUR | W10: =IFERROR(VLOOKUP(V10,[1]Curr!$B$2:$C$13,2,FALSE),0) -> 11.3 | X10: =U10*W10 -> 0 | Y10: =Q10 -> 0 | Z10: =+Y10*R10 -> 0 | AA10: EUR | AB10: =IFERROR(VLOOKUP(AA10,Curr!$B$2:$C$13,2,FALSE),0) -> 11.3 | AC10: =+Y10*AB10*R10 -> 0 | AD10: =+AC10-X10 -> 0 | AE10: =IFERROR(AD10/AC10,0) -> 0
Q11: 0 | R11: 0 | S11: =+Q11*R11 -> 0 | T11: 0 | U11: =S11*(1-T11) -> 0 | V11: EUR | W11: =IFERROR(VLOOKUP(V11,[1]Curr!$B$2:$C$13,2,FALSE),0) -> 11.3 | X11: =U11*W11 -> 0 | Y11: =Q11 -> 0 | Z11: =+Y11*R11 -> 0 | AA11: EUR | AB11: =IFERROR(VLOOKUP(AA11,Curr!$B$2:$C$13,2,FALSE),0) -> 11.3 | AC11: =+Y11*AB11*R11 -> 0 | AD11: =+AC11-X11 -> 0 | AE11: =IFERROR(AD11/AC11,0) -> 0
Q12: 0 | R12: 0 | S12: =+Q12*R12 -> 0 | T12: 0 | U12: =S12*(1-T12) -> 0 | V12: EUR | W12: =IFERROR(VLOOKUP(V12,[1]Curr!$B$2:$C$13,2,FALSE),0) -> 11.3 | X12: =U12*W12 -> 0 | Y12: =Q12 -> 0 | Z12: =+Y12*R12 -> 0 | AA12: EUR | AB12: =IFERROR(VLOOKUP(AA12,Curr!$B$2:$C$13,2,FALSE),0) -> 11.3 | AC12: =+Y12*AB12*R12 -> 0 | AD12: =+AC12-X12 -> 0 | AE12: =IFERROR(AD12/AC12,0) -> 0
Q13: 0 | R13: 0 | S13: =+Q13*R13 -> 0 | T13: 0 | U13: =S13*(1-T13) -> 0 | V13: EUR | W13: =IFERROR(VLOOKUP(V13,[1]Curr!$B$2:$C$13,2,FALSE),0) -> 11.3 | X13: =U13*W13 -> 0 | Y13: =Q13 -> 0 | Z13: =+Y13*R13 -> 0 | AA13: EUR | AB13: =IFERROR(VLOOKUP(AA13,Curr!$B$2:$C$13,2,FALSE),0) -> 11.3 | AC13: =+Y13*AB13*R13 -> 0 | AD13: =+AC13-X13 -> 0 | AE13: =IFERROR(AD13/AC13,0) -> 0
Q14: 0 | R14: 0 | S14: =+Q14*R14 -> 0 | T14: 0 | U14: =S14*(1-T14) -> 0 | V14: EUR | W14: =IFERROR(VLOOKUP(V14,[1]Curr!$B$2:$C$13,2,FALSE),0) -> 11.3 | X14: =U14*W14 -> 0 | Y14: =Q14 -> 0 | Z14: =+Y14*R14 -> 0 | AA14: EUR | AB14: =IFERROR(VLOOKUP(AA14,Curr!$B$2:$C$13,2,FALSE),0) -> 11.3 | AC14: =+Y14*AB14*R14 -> 0 | AD14: =+AC14-X14 -> 0 | AE14: =IFERROR(AD14/AC14,0) -> 0
Q15: 0 | R15: 0 | S15: =+Q15*R15 -> 0 | T15: 0 | U15: =S15*(1-T15) -> 0 | V15: EUR | W15: =IFERROR(VLOOKUP(V15,[1]Curr!$B$2:$C$13,2,FALSE),0) -> 11.3 | X15: =U15*W15 -> 0 | Y15: =Q15 -> 0 | Z15: =+Y15*R15 -> 0 | AA15: EUR | AB15: =IFERROR(VLOOKUP(AA15,Curr!$B$2:$C$13,2,FALSE),0) -> 11.3 | AC15: =+Y15*AB15*R15 -> 0 | AD15: =+AC15-X15 -> 0 | AE15: =IFERROR(AD15/AC15,0) -> 0
Q16: 0 | R16: 0 | S16: =+Q16*R16 -> 0 | T16: 0 | U16: =S16*(1-T16) -> 0 | V16: EUR | W16: =IFERROR(VLOOKUP(V16,[1]Curr!$B$2:$C$13,2,FALSE),0) -> 11.3 | X16: =U16*W16 -> 0 | Y16: =Q16 -> 0 | Z16: =+Y16*R16 -> 0 | AA16: EUR | AB16: =IFERROR(VLOOKUP(AA16,Curr!$B$2:$C$13,2,FALSE),0) -> 11.3 | AC16: =+Y16*AB16*R16 -> 0 | AD16: =+AC16-X16 -> 0 | AE16: =IFERROR(AD16/AC16,0) -> 0
Q17: 0 | R17: 0 | S17: =+Q17*R17 -> 0 | T17: 0 | U17: =S17*(1-T17) -> 0 | V17: EUR | W17: =IFERROR(VLOOKUP(V17,[1]Curr!$B$2:$C$13,2,FALSE),0) -> 11.3 | X17: =U17*W17 -> 0 | Y17: =Q17 -> 0 | Z17: =+Y17*R17 -> 0 | AA17: EUR | AB17: =IFERROR(VLOOKUP(AA17,Curr!$B$2:$C$13,2,FALSE),0) -> 11.3 | AC17: =+Y17*AB17*R17 -> 0 | AD17: =+AC17-X17 -> 0 | AE17: =IFERROR(AD17/AC17,0) -> 0
Q18: 0 | R18: 0 | S18: =+Q18*R18 -> 0 | T18: 0 | U18: =S18*(1-T18) -> 0 | V18: EUR | W18: =IFERROR(VLOOKUP(V18,[1]Curr!$B$2:$C$13,2,FALSE),0) -> 11.3 | X18: =U18*W18 -> 0 | Y18: =Q18 -> 0 | Z18: =+Y18*R18 -> 0 | AA18: EUR | AB18: =IFERROR(VLOOKUP(AA18,Curr!$B$2:$C$13,2,FALSE),0) -> 11.3 | AC18: =+Y18*AB18*R18 -> 0 | AD18: =+AC18-X18 -> 0 | AE18: =IFERROR(AD18/AC18,0) -> 0
... Q99: 0 | R99: 0 | S99: =+Q99*R99 -> 0 | T99: 0 | U99: =S99*(1-T99) -> 0 | V99: EUR | W99: =IFERROR(VLOOKUP(V99,[1]Curr!$B$2:$C$13,2,FALSE),0) -> 11.3 | X99: =U99*W99 -> 0 | Y99: =Q99 -> 0 | Z99: =+Y99*R99 -> 0 | AA99: EUR | AB99: =IFERROR(VLOOKUP(AA99,Curr!$B$2:$C$13,2,FALSE),0) -> 11.3 | AC99: =+Y99*AB99*R99 -> 0 | AD99: =+AC99-X99 -> 0 | AE99: =IFERROR(AD99/AC99,0) -> 0
B101: Totals | D101: x | E101: x | F101: x | G101: x | H101: x | I101: x | J101: x | K101: x | L101: x | M101: x | N101: x | O101: x | P101: x | Q101: x | R101: x | S101: x | T101: x | U101: x | V101: x | W101: x | X101: x | Y101: x | Z101: =SUM(Z7:Z99) -> 0 | AC101: =SUM(AC7:AC99) -> 0 | AD101: =SUM(AD7:AD99) -> 0 | AE101: =IFERROR(AD101/AC101,0) -> 0 | AF101: =SUM(AF8:AF100) -> 0 | AG101: =SUM(AG8:AG100) -> 0 | AH101: =SUM(AH8:AH100) -> 0 | AI101: =SUM(AI8:AI100) -> 0 | AJ101: =SUM(AJ8:AJ100) -> 0
Y103: Quote
Y104: PP | Z104: =Z103/2 -> 0
Y106: Ref | Z106: =Z103-Z107 -> 0
Y107: NoRef
Y109: Deposit | Z109: =Z103*0.3 -> 0
Y110: Second | Z110: =Z107-Z109 -> 0
Y111: Rest | Z111: =Z103-Z109-Z110 -> 0

Sheet 401
B2: Dates: Winter
B3: Pax: 2
B4: Rooming: Double
B6: ID | C6: Day | D6: Type | E6: From date | F6: To date | G6: From time | H6: To time | I6: Supplier | J6: Travel element | K6: Manual booking? | L6: Status | M6: Comments | N6: Non-refundable | O6: Refundable | P6: URL | Q6: Gross P per unit | R6: Units | S6: Gross P | T6: Supp Comm | U6: Net P | V6: Supp curr | W6: X-rate | X6: Net P NOK | Y6: Sales P per unit | Z6: Price | AA6: Sales curr | AB6: X-rate | AC6: Sales P NOK tot | AD6: GP NOK | AE6: GP % | AF6: VAT25 | AG6: VAT15 | AH6: VAT12 | AI6: VAT0-D | AJ6: VAT0-I
C7: Day 1 | D7: Arrival | J7: Stockholm: Welcome to Sweden | Q7: 0 | R7: 0 | S7: =+Q7*R7 -> 0 | T7: 0 | U7: =S7*(1-T7) -> 0 | V7: EUR | W7: =IFERROR(VLOOKUP(V7,[1]Curr!$B$2:$C$13,2,FALSE),0) -> 11.3 | X7: =U7*W7 -> 0 | Y7: =Q7 -> 0 | Z7: =+Y7*R7 -> 0 | AA7: EUR | AB7: =IFERROR(VLOOKUP(AA7,Curr!$B$2:$C$13,2,FALSE),0) -> 11.3 | AC7: =+Y7*AB7*R7 -> 0 | AD7: =+AC7-X7 -> 0 | AE7: =IFERROR(AD7/AC7,0) -> 0
C8: Day 1 | D8: Transfer | J8: Stockholm: Self transfer to your accommodation | Q8: 0 | R8: 0 | S8: =+Q8*R8 -> 0 | T8: 0 | U8: =S8*(1-T8) -> 0 | V8: EUR | W8: =IFERROR(VLOOKUP(V8,[1]Curr!$B$2:$C$13,2,FALSE),0) -> 11.3 | X8: =U8*W8 -> 0 | Y8: =Q8 -> 0 | Z8: =+Y8*R8 -> 0 | AA8: EUR | AB8: =IFERROR(VLOOKUP(AA8,Curr!$B$2:$C$13,2,FALSE),0) -> 11.3 | AC8: =+Y8*AB8*R8 -> 0 | AD8: =+AC8-X8 -> 0 | AE8: =IFERROR(AD8/AC8,0) -> 0
C9: Day 1 | D9: Hotel | J9: Stockholm: Check in to your accommodation for a 1 night stay - Centrally located 4 star hotel - Standard Room - Breakfast included | Q9: 200 | R9: 1 | S9: =+Q9*R9 -> 200 | T9: 0 | U9: =S9*(1-T9) -> 200 | V9: EUR | W9: =IFERROR(VLOOKUP(V9,[1]Curr!$B$2:$C$13,2,FALSE),0) -> 11.3 | X9: =U9*W9 -> 2260 | Y9: =Q9/0.8 -> 250 | Z9: =+Y9*R9 -> 250 | AA9: EUR | AB9: =IFERROR(VLOOKUP(AA9,Curr!$B$2:$C$13,2,FALSE),0) -> 11.3 | AC9: =+Y9*AB9*R9 -> 2825 | AD9: =+AC9-X9 -> 565 | AE9: =IFERROR(AD9/AC9,0) -> 0.2
C10: Day 1 | D10: Leisure | J10: Stockholm: Spend time at leisure | Q10: 0 | R10: 0 | S10: =+Q10*R10 -> 0 | T10: 0 | U10: =S10*(1-T10) -> 0 | V10: EUR | W10: =IFERROR(VLOOKUP(V10,[1]Curr!$B$2:$C$13,2,FALSE),0) -> 11.3 | X10: =U10*W10 -> 0 | Y10: =Q10 -> 0 | Z10: =+Y10*R10 -> 0 | AA10: EUR | AB10: =IFERROR(VLOOKUP(AA10,Curr!$B$2:$C$13,2,FALSE),0) -> 11.3 | AC10: =+Y10*AB10*R10 -> 0 | AD10: =+AC10-X10 -> 0 | AE10: =IFERROR(AD10/AC10,0) -> 0
S11: =+Q11*R11 -> 0 | T11: 0 | U11: =S11*(1-T11) -> 0 | V11: EUR | W11: =IFERROR(VLOOKUP(V11,[1]Curr!$B$2:$C$13,2,FALSE),0) -> 11.3 | X11: =U11*W11 -> 0 | Y11: =Q11 -> 0 | Z11: =+Y11*R11 -> 0 | AA11: EUR | AB11: =IFERROR(VLOOKUP(AA11,Curr!$B$2:$C$13,2,FALSE),0) -> 11.3 | AC11: =+Y11*AB11*R11 -> 0 | AD11: =+AC11-X11 -> 0 | AE11: =IFERROR(AD11/AC11,0) -> 0
C12: Day 2 | D12: Transfer | J12: Stockholm: Self transfer to Stockholm Airport | Q12: 0 | R12: 0 | S12: =+Q12*R12 -> 0 | T12: 0 | U12: =S12*(1-T12) -> 0 | V12: EUR | W12: =IFERROR(VLOOKUP(V12,[1]Curr!$B$2:$C$13,2,FALSE),0) -> 11.3 | X12: =U12*W12 -> 0 | Y12: =Q12 -> 0 | Z12: =+Y12*R12 -> 0 | AA12: EUR | AB12: =IFERROR(VLOOKUP(AA12,Curr!$B$2:$C$13,2,FALSE),0) -> 11.3 | AC12: =+Y12*AB12*R12 -> 0 | AD12: =+AC12-X12 -> 0 | AE12: =IFERROR(AD12/AC12,0) -> 0
C13: Day 2 | D13: Flight | J13: Stockholm: Flight to Kiruna - Time: Date dependant - Luggage included: 1 x 23 kg check in and 1 x 8 kg carry on per person | Q13: 2700 | R13: 2 | S13: =+Q13*R13 -> 5400 | T13: 0 | U13: =S13*(1-T13) -> 5400 | V13: NOK | W13: =IFERROR(VLOOKUP(V13,[1]Curr!$B$2:$C$13,2,FALSE),0) -> 1 | X13: =U13*W13 -> 5400 | Y13: =Q13/11.3/0.8 -> 298.67257 | Z13: =+Y13*R13 -> 597.34513 | AA13: EUR | AB13: =IFERROR(VLOOKUP(AA13,Curr!$B$2:$C$13,2,FALSE),0) -> 11.3 | AC13: =+Y13*AB13*R13 -> 6750 | AD13: =+AC13-X13 -> 1350 | AE13: =IFERROR(AD13/AC13,0) -> 0.2
C14: Day 2 | D14: Transfer | J14: Kiruna: Self transfer to your accommodaiton | Q14: 0 | R14: 0 | S14: =+Q14*R14 -> 0 | T14: 0 | U14: =S14*(1-T14) -> 0 | V14: EUR | W14: =IFERROR(VLOOKUP(V14,[1]Curr!$B$2:$C$13,2,FALSE),0) -> 11.3 | X14: =U14*W14 -> 0 | Y14: =Q14 -> 0 | Z14: =+Y14*R14 -> 0 | AA14: EUR | AB14: =IFERROR(VLOOKUP(AA14,Curr!$B$2:$C$13,2,FALSE),0) -> 11.3 | AC14: =+Y14*AB14*R14 -> 0 | AD14: =+AC14-X14 -> 0 | AE14: =IFERROR(AD14/AC14,0) -> 0
C15: Day 2 | D15: Hotel | J15: Kiruna: Check in to your accommodation for a 3 night stay - - Standard Room - Breakfast included | Q15: 600 | R15: 1 | S15: =+Q15*R15 -> 600 | T15: 0 | U15: =S15*(1-T15) -> 600 | V15: EUR | W15: =IFERROR(VLOOKUP(V15,[1]Curr!$B$2:$C$13,2,FALSE),0) -> 11.3 | X15: =U15*W15 -> 6780 | Y15: =Q15/0.85 -> 705.88235 | Z15: =+Y15*R15 -> 705.88235 | AA15: EUR | AB15: =IFERROR(VLOOKUP(AA15,Curr!$B$2:$C$13,2,FALSE),0) -> 11.3 | AC15: =+Y15*AB15*R15 -> 7976.4706 | AD15: =+AC15-X15 -> 1196.4706 | AE15: =IFERROR(AD15/AC15,0) -> 0.15
C16: Day 2 | D16: Leisure | J16: Kiruna: Spend time at leisure | Q16: 0 | R16: 0 | S16: =+Q16*R16 -> 0 | T16: 0 | U16: =S16*(1-T16) -> 0 | V16: EUR | W16: =IFERROR(VLOOKUP(V16,[1]Curr!$B$2:$C$13,2,FALSE),0) -> 11.3 | X16: =U16*W16 -> 0 | Y16: =Q16 -> 0 | Z16: =+Y16*R16 -> 0 | AA16: EUR | AB16: =IFERROR(VLOOKUP(AA16,Curr!$B$2:$C$13,2,FALSE),0) -> 11.3 | AC16: =+Y16*AB16*R16 -> 0 | AD16: =+AC16-X16 -> 0 | AE16: =IFERROR(AD16/AC16,0) -> 0
C17: Day 2 | D17: Activity | J17: Kiruna: Northern Lights Hunt with Pro Photographer - Time: 7:00 pm - 12:00 am - Meeting point: Hotel Pick up - Includes: Pick-up/drop-off in central Kiruna, Knowledgeable guide & photographer, Coffee and/or tea with snacks | P17: https://booknordics.com/sweden/swedish-lapland/kiruna-and-abisko/kiruna-northern-lights-tour-with-photographer | Q17: 155 | R17: 2 | S17: =+Q17*R17 -> 310 | T17: 0.2 | U17: =S17*(1-T17) -> 248 | V17: EUR | W17: =IFERROR(VLOOKUP(V17,[1]Curr!$B$2:$C$13,2,FALSE),0) -> 11.3 | X17: =U17*W17 -> 2802.4 | Y17: =Q17 -> 155 | Z17: =+Y17*R17 -> 310 | AA17: EUR | AB17: =IFERROR(VLOOKUP(AA17,Curr!$B$2:$C$13,2,FALSE),0) -> 11.3 | AC17: =+Y17*AB17*R17 -> 3503 | AD17: =+AC17-X17 -> 700.6 | AE17: =IFERROR(AD17/AC17,0) -> 0.2
S18: =+Q18*R18 -> 0 | T18: 0 | U18: =S18*(1-T18) -> 0 | V18: EUR | W18: =IFERROR(VLOOKUP(V18,[1]Curr!$B$2:$C$13,2,FALSE),0) -> 11.3 | X18: =U18*W18 -> 0 | Y18: =Q18 -> 0 | Z18: =+Y18*R18 -> 0 | AA18: EUR | AB18: =IFERROR(VLOOKUP(AA18,Curr!$B$2:$C$13,2,FALSE),0) -> 11.3 | AC18: =+Y18*AB18*R18 -> 0 | AD18: =+AC18-X18 -> 0 | AE18: =IFERROR(AD18/AC18,0) -> 0
C19: Day 3 | D19: Activity | J19: Kiruna: Snowmobiling Day Tour into the Arctic Wilderness - Time: 10:30 am - 2:00 pm - Meeting point: Hotel Pick up Includes: Pick-up from selected locations, Guided snowmobile tour experience, High-quality Arctic snowmobile gear, Overalls, helmets, shoes and gloves, Swedish fika with warm lingonberry juice | P19: https://booknordics.com/sweden/swedish-lapland/kiruna-and-abisko/day-tour-with-snowmobile-in-kiruna-1030-am | Q19: 141 | R19: 2 | S19: =+Q19*R19 -> 282 | T19: 0.2 | U19: =S19*(1-T19) -> 225.6 | V19: EUR | W19: =IFERROR(VLOOKUP(V19,[1]Curr!$B$2:$C$13,2,FALSE),0) -> 11.3 | X19: =U19*W19 -> 2549.28 | Y19: =Q19 -> 141 | Z19: =+Y19*R19 -> 282 | AA19: EUR | AB19: =IFERROR(VLOOKUP(AA19,Curr!$B$2:$C$13,2,FALSE),0) -> 11.3 | AC19: =+Y19*AB19*R19 -> 3186.6 | AD19: =+AC19-X19 -> 637.32 | AE19: =IFERROR(AD19/AC19,0) -> 0.2
C20: Day 3 | D20: Leisure | J20: Kiruna: Spend time at leisure | Q20: 0 | R20: 0 | S20: =+Q20*R20 -> 0 | T20: 0 | U20: =S20*(1-T20) -> 0 | V20: EUR | W20: =IFERROR(VLOOKUP(V20,[1]Curr!$B$2:$C$13,2,FALSE),0) -> 11.3 | X20: =U20*W20 -> 0 | Y20: =Q20 -> 0 | Z20: =+Y20*R20 -> 0 | AA20: EUR | AB20: =IFERROR(VLOOKUP(AA20,Curr!$B$2:$C$13,2,FALSE),0) -> 11.3 | AC20: =+Y20*AB20*R20 -> 0 | AD20: =+AC20-X20 -> 0 | AE20: =IFERROR(AD20/AC20,0) -> 0
C21: Day 3 | D21: Activity | J21: Kiruna: Northern Light Minibus Hunt to Abisko National Park - Time: 7:30 pm - 12:30 am - Meeting point: Hotel Pick up - Includes: Pick-up from selected locations, Transfer with heated minibus, Professional, English-speaking guide, Help with taking pictures, Swedish fika with warm juice | P21: https://booknordics.com/sweden/swedish-lapland/kiruna-and-abisko/northern-light-minibus-hunt-to-abisko-national-park-730-pm | Q21: 179 | R21: 2 | S21: =+Q21*R21 -> 358 | T21: 0.2 | U21: =S21*(1-T21) -> 286.4 | V21: EUR | W21: =IFERROR(VLOOKUP(V21,[1]Curr!$B$2:$C$13,2,FALSE),0) -> 11.3 | X21: =U21*W21 -> 3236.32 | Y21: =Q21 -> 179 | Z21: =+Y21*R21 -> 358 | AA21: EUR | AB21: =IFERROR(VLOOKUP(AA21,Curr!$B$2:$C$13,2,FALSE),0) -> 11.3 | AC21: =+Y21*AB21*R21 -> 4045.4 | AD21: =+AC21-X21 -> 809.08 | AE21: =IFERROR(AD21/AC21,0) -> 0.2
S22: =+Q22*R22 -> 0 | T22: 0 | U22: =S22*(1-T22) -> 0 | V22: EUR | W22: =IFERROR(VLOOKUP(V22,[1]Curr!$B$2:$C$13,2,FALSE),0) -> 11.3 | X22: =U22*W22 -> 0 | Y22: =Q22 -> 0 | Z22: =+Y22*R22 -> 0 | AA22: EUR | AB22: =IFERROR(VLOOKUP(AA22,Curr!$B$2:$C$13,2,FALSE),0) -> 11.3 | AC22: =+Y22*AB22*R22 -> 0 | AD22: =+AC22-X22 -> 0 | AE22: =IFERROR(AD22/AC22,0) -> 0
C23: Day 4 | D23: Activity | J23: Kiruna: Moose Safari - Time: 09:00 am - 2:00 pm - Meeting point: Hotel pick up - Includes: Transfer to/from your accommodation, Moose safari chase, Professional, English-speaking guide | Q23: 151 | R23: 2 | S23: =+Q23*R23 -> 302 | T23: 0.2 | U23: =S23*(1-T23) -> 241.6 | V23: EUR | W23: =IFERROR(VLOOKUP(V23,[1]Curr!$B$2:$C$13,2,FALSE),0) -> 11.3 | X23: =U23*W23 -> 2730.08 | Y23: =Q23 -> 151 | Z23: =+Y23*R23 -> 302 | AA23: EUR | AB23: =IFERROR(VLOOKUP(AA23,Curr!$B$2:$C$13,2,FALSE),0) -> 11.3 | AC23: =+Y23*AB23*R23 -> 3412.6 | AD23: =+AC23-X23 -> 682.52 | AE23: =IFERROR(AD23/AC23,0) -> 0.2
C24: Day 4 | D24: Leisure | J24: Kiruna: Spend time at leisure | Q24: 0 | R24: 0 | S24: =+Q24*R24 -> 0 | T24: 0 | U24: =S24*(1-T24) -> 0 | V24: EUR | W24: =IFERROR(VLOOKUP(V24,[1]Curr!$B$2:$C$13,2,FALSE),0) -> 11.3 | X24: =U24*W24 -> 0 | Y24: =Q24 -> 0 | Z24: =+Y24*R24 -> 0 | AA24: EUR | AB24: =IFERROR(VLOOKUP(AA24,Curr!$B$2:$C$13,2,FALSE),0) -> 11.3 | AC24: =+Y24*AB24*R24 -> 0 | AD24: =+AC24-X24 -> 0 | AE24: =IFERROR(AD24/AC24,0) -> 0
S25: =+Q25*R25 -> 0 | T25: 0 | U25: =S25*(1-T25) -> 0 | V25: EUR | W25: =IFERROR(VLOOKUP(V25,[1]Curr!$B$2:$C$13,2,FALSE),0) -> 11.3 | X25: =U25*W25 -> 0 | Y25: =Q25 -> 0 | Z25: =+Y25*R25 -> 0 | AA25: EUR | AB25: =IFERROR(VLOOKUP(AA25,Curr!$B$2:$C$13,2,FALSE),0) -> 11.3 | AC25: =+Y25*AB25*R25 -> 0 | AD25: =+AC25-X25 -> 0 | AE25: =IFERROR(AD25/AC25,0) -> 0
C26: Day 5 | D26: Transfer | J26: Kiruna: Self transfer to Kiruna Airport | Q26: 0 | R26: 0 | S26: =+Q26*R26 -> 0 | T26: 0 | U26: =S26*(1-T26) -> 0 | V26: EUR | W26: =IFERROR(VLOOKUP(V26,[1]Curr!$B$2:$C$13,2,FALSE),0) -> 11.3 | X26: =U26*W26 -> 0 | Y26: =Q26 -> 0 | Z26: =+Y26*R26 -> 0 | AA26: EUR | AB26: =IFERROR(VLOOKUP(AA26,Curr!$B$2:$C$13,2,FALSE),0) -> 11.3 | AC26: =+Y26*AB26*R26 -> 0 | AD26: =+AC26-X26 -> 0 | AE26: =IFERROR(AD26/AC26,0) -> 0
C27: Day 5 | D27: Departure | J27: Kiruna: Departure home | Q27: 0 | R27: 0 | S27: =+Q27*R27 -> 0 | T27: 0 | U27: =S27*(1-T27) -> 0 | V27: EUR | W27: =IFERROR(VLOOKUP(V27,[1]Curr!$B$2:$C$13,2,FALSE),0) -> 11.3 | X27: =U27*W27 -> 0 | Y27: =Q27 -> 0 | Z27: =+Y27*R27 -> 0 | AA27: EUR | AB27: =IFERROR(VLOOKUP(AA27,Curr!$B$2:$C$13,2,FALSE),0) -> 11.3 | AC27: =+Y27*AB27*R27 -> 0 | AD27: =+AC27-X27 -> 0 | AE27: =IFERROR(AD27/AC27,0) -> 0
S28: =+Q28*R28 -> 0 | T28: 0 | U28: =S28*(1-T28) -> 0 | V28: EUR | W28: =IFERROR(VLOOKUP(V28,[1]Curr!$B$2:$C$13,2,FALSE),0) -> 11.3 | X28: =U28*W28 -> 0 | Y28: =Q28 -> 0 | Z28: =+Y28*R28 -> 0 | AA28: EUR | AB28: =IFERROR(VLOOKUP(AA28,Curr!$B$2:$C$13,2,FALSE),0) -> 11.3 | AC28: =+Y28*AB28*R28 -> 0 | AD28: =+AC28-X28 -> 0 | AE28: =IFERROR(AD28/AC28,0) -> 0
S29: =+Q29*R29 -> 0 | T29: 0 | U29: =S29*(1-T29) -> 0 | V29: EUR | W29: =IFERROR(VLOOKUP(V29,[1]Curr!$B$2:$C$13,2,FALSE),0) -> 11.3 | X29: =U29*W29 -> 0 | Y29: =Q29 -> 0 | Z29: =+Y29*R29 -> 0 | AA29: EUR | AB29: =IFERROR(VLOOKUP(AA29,Curr!$B$2:$C$13,2,FALSE),0) -> 11.3 | AC29: =+Y29*AB29*R29 -> 0 | AD29: =+AC29-X29 -> 0 | AE29: =IFERROR(AD29/AC29,0) -> 0
C30: Day 1 | D30: Transfer Package | J30: Stockholm: Private transfer to your accommodation | Q30: 150 | R30: 0 | S30: =+Q30*R30 -> 0 | T30: 0 | U30: =S30*(1-T30) -> 0 | V30: EUR | W30: =IFERROR(VLOOKUP(V30,[1]Curr!$B$2:$C$13,2,FALSE),0) -> 11.3 | X30: =U30*W30 -> 0 | Y30: =Q30/0.8 -> 187.5 | Z30: =+Y30*R30 -> 0 | AA30: EUR | AB30: =IFERROR(VLOOKUP(AA30,Curr!$B$2:$C$13,2,FALSE),0) -> 11.3 | AC30: =+Y30*AB30*R30 -> 0 | AD30: =+AC30-X30 -> 0 | AE30: =IFERROR(AD30/AC30,0) -> 0
C31: Day 2 | D31: Transfer Package | J31: Stockholm: Private transfer to Stockholm Airport | Q31: 150 | R31: 0 | S31: =+Q31*R31 -> 0 | T31: 0 | U31: =S31*(1-T31) -> 0 | V31: EUR | W31: =IFERROR(VLOOKUP(V31,[1]Curr!$B$2:$C$13,2,FALSE),0) -> 11.3 | X31: =U31*W31 -> 0 | Y31: =Q31/0.8 -> 187.5 | Z31: =+Y31*R31 -> 0 | AA31: EUR | AB31: =IFERROR(VLOOKUP(AA31,Curr!$B$2:$C$13,2,FALSE),0) -> 11.3 | AC31: =+Y31*AB31*R31 -> 0 | AD31: =+AC31-X31 -> 0 | AE31: =IFERROR(AD31/AC31,0) -> 0
C32: Day 2 | D32: Transfer Package | J32: Kiruna: Private transfer to your accommodaiton | Q32: 750 | R32: 0 | S32: =+Q32*R32 -> 0 | T32: 0 | U32: =S32*(1-T32) -> 0 | V32: EUR | W32: =IFERROR(VLOOKUP(V32,[1]Curr!$B$2:$C$13,2,FALSE),0) -> 11.3 | X32: =U32*W32 -> 0 | Y32: =Q32/11.3/0.8 -> 82.964602 | Z32: =+Y32*R32 -> 0 | AA32: EUR | AB32: =IFERROR(VLOOKUP(AA32,Curr!$B$2:$C$13,2,FALSE),0) -> 11.3 | AC32: =+Y32*AB32*R32 -> 0 | AD32: =+AC32-X32 -> 0 | AE32: =IFERROR(AD32/AC32,0) -> 0
C33: Day 5 | D33: Transfer Package | J33: Kiruna: Private transfer to Kiruna Airport | Q33: 750 | R33: 0 | S33: =+Q33*R33 -> 0 | T33: 0 | U33: =S33*(1-T33) -> 0 | V33: EUR | W33: =IFERROR(VLOOKUP(V33,[1]Curr!$B$2:$C$13,2,FALSE),0) -> 11.3 | X33: =U33*W33 -> 0 | Y33: =Q33/11.3/0.8 -> 82.964602 | Z33: =+Y33*R33 -> 0 | AA33: EUR | AB33: =IFERROR(VLOOKUP(AA33,Curr!$B$2:$C$13,2,FALSE),0) -> 11.3 | AC33: =+Y33*AB33*R33 -> 0 | AD33: =+AC33-X33 -> 0 | AE33: =IFERROR(AD33/AC33,0) -> 0
S34: =+Q34*R34 -> 0 | T34: 0 | U34: =S34*(1-T34) -> 0 | V34: EUR | W34: =IFERROR(VLOOKUP(V34,[1]Curr!$B$2:$C$13,2,FALSE),0) -> 11.3 | X34: =U34*W34 -> 0 | Y34: =Q34 -> 0 | Z34: =+Y34*R34 -> 0 | AA34: EUR | AB34: =IFERROR(VLOOKUP(AA34,Curr!$B$2:$C$13,2,FALSE),0) -> 11.3 | AC34: =+Y34*AB34*R34 -> 0 | AD34: =+AC34-X34 -> 0 | AE34: =IFERROR(AD34/AC34,0) -> 0
S35: =+Q35*R35 -> 0 | T35: 0 | U35: =S35*(1-T35) -> 0 | V35: EUR | W35: =IFERROR(VLOOKUP(V35,[1]Curr!$B$2:$C$13,2,FALSE),0) -> 11.3 | X35: =U35*W35 -> 0 | Y35: =Q35 -> 0 | Z35: =+Y35*R35 -> 0 | AA35: EUR | AB35: =IFERROR(VLOOKUP(AA35,Curr!$B$2:$C$13,2,FALSE),0) -> 11.3 | AC35: =+Y35*AB35*R35 -> 0 | AD35: =+AC35-X35 -> 0 | AE35: =IFERROR(AD35/AC35,0) -> 0
C36: Day 4 | D36: Hotel upgrade | J36: Kiruna: Upgrade to Kiruna Ice Hotel for a 1 night stay in a Ice Room - Breakfast included - Avaliable December - April | Q36: 660 | R36: 0 | S36: =+Q36*R36 -> 0 | T36: 0 | U36: =S36*(1-T36) -> 0 | V36: EUR | W36: =IFERROR(VLOOKUP(V36,[1]Curr!$B$2:$C$13,2,FALSE),0) -> 11.3 | X36: =U36*W36 -> 0 | Y36: =Q36/0.85 -> 776.47059 | Z36: =+Y36*R36 -> 0 | AA36: EUR | AB36: =IFERROR(VLOOKUP(AA36,Curr!$B$2:$C$13,2,FALSE),0) -> 11.3 | AC36: =+Y36*AB36*R36 -> 0 | AD36: =+AC36-X36 -> 0 | AE36: =IFERROR(AD36/AC36,0) -> 0
S37: =+Q37*R37 -> 0 | T37: 0 | U37: =S37*(1-T37) -> 0 | V37: EUR | W37: =IFERROR(VLOOKUP(V37,[1]Curr!$B$2:$C$13,2,FALSE),0) -> 11.3 | X37: =U37*W37 -> 0 | Y37: =Q37 -> 0 | Z37: =+Y37*R37 -> 0 | AA37: EUR | AB37: =IFERROR(VLOOKUP(AA37,Curr!$B$2:$C$13,2,FALSE),0) -> 11.3 | AC37: =+Y37*AB37*R37 -> 0 | AD37: =+AC37-X37 -> 0 | AE37: =IFERROR(AD37/AC37,0) -> 0
S38: =+Q38*R38 -> 0 | T38: 0 | U38: =S38*(1-T38) -> 0 | V38: EUR | W38: =IFERROR(VLOOKUP(V38,[1]Curr!$B$2:$C$13,2,FALSE),0) -> 11.3 | X38: =U38*W38 -> 0 | Y38: =Q38 -> 0 | Z38: =+Y38*R38 -> 0 | AA38: EUR | AB38: =IFERROR(VLOOKUP(AA38,Curr!$B$2:$C$13,2,FALSE),0) -> 11.3 | AC38: =+Y38*AB38*R38 -> 0 | AD38: =+AC38-X38 -> 0 | AE38: =IFERROR(AD38/AC38,0) -> 0
S39: =+Q39*R39 -> 0 | T39: 0 | U39: =S39*(1-T39) -> 0 | V39: EUR | W39: =IFERROR(VLOOKUP(V39,[1]Curr!$B$2:$C$13,2,FALSE),0) -> 11.3 | X39: =U39*W39 -> 0 | Y39: =Q39 -> 0 | Z39: =+Y39*R39 -> 0 | AA39: EUR | AB39: =IFERROR(VLOOKUP(AA39,Curr!$B$2:$C$13,2,FALSE),0) -> 11.3 | AC39: =+Y39*AB39*R39 -> 0 | AD39: =+AC39-X39 -> 0 | AE39: =IFERROR(AD39/AC39,0) -> 0
S40: =+Q40*R40 -> 0 | T40: 0 | U40: =S40*(1-T40) -> 0 | V40: EUR | W40: =IFERROR(VLOOKUP(V40,[1]Curr!$B$2:$C$13,2,FALSE),0) -> 11.3 | X40: =U40*W40 -> 0 | Y40: =Q40 -> 0 | Z40: =+Y40*R40 -> 0 | AA40: EUR | AB40: =IFERROR(VLOOKUP(AA40,Curr!$B$2:$C$13,2,FALSE),0) -> 11.3 | AC40: =+Y40*AB40*R40 -> 0 | AD40: =+AC40-X40 -> 0 | AE40: =IFERROR(AD40/AC40,0) -> 0
B42: Totals | D42: x | E42: x | F42: x | G42: x | H42: x | I42: x | J42: x | K42: x | L42: x | M42: x | N42: x | O42: x | P42: x | Q42: x | R42: x | S42: x | T42: x | U42: x | V42: x | W42: x | X42: x | Y42: x | Z42: =SUM(Z7:Z40) -> 2805.2275 | AC42: =SUM(AC7:AC40) -> 31699.071 | AD42: =SUM(AD7:AD40) -> 5940.9906 | AE42: =IFERROR(AD42/AC42,0) -> 0.18741845 | AF42: =SUM(AF8:AF41) -> 0 | AG42: =SUM(AG8:AG41) -> 0 | AH42: =SUM(AH8:AH41) -> 0 | AI42: =SUM(AI8:AI41) -> 0 | AJ42: =SUM(AJ8:AJ41) -> 0
Y44: Quote | Z44: 2820
...

Sheet 402
B1: Self drive: Stockholm - Karlstad - Gothenburg - Helsingborg - Karlskrona - Vastervik - Stockholm
B2: Dates: Summer
B3: Pax: 2
B4: Rooming: Double
B6: ID | C6: Day | D6: Type | E6: From date | F6: To date | G6: From time | H6: To time | I6: Supplier | J6: Travel element | K6: Manual booking? | L6: Status | M6: Comments | N6: Non-refundable | O6: Refundable | P6: URL | Q6: Gross P per unit | R6: Units | S6: Gross P | T6: Supp Comm | U6: Net P | V6: Supp curr | W6: X-rate | X6: Net P NOK | Y6: Sales P per unit | Z6: Price | AA6: Sales curr | AB6: X-rate | AC6: Sales P NOK tot | AD6: GP NOK | AE6: GP % | AF6: VAT25 | AG6: VAT15 | AH6: VAT12 | AI6: VAT0-D | AJ6: VAT0-I
C7: Day 1 | D7: Arrival | J7: Stockholm: Welcome to Sweden | Q7: 0 | R7: 0 | S7: =+Q7*R7 -> 0 | T7: 0 | U7: =S7*(1-T7) -> 0 | V7: EUR | W7: =IFERROR(VLOOKUP(V7,[1]Curr!$B$2:$C$13,2,FALSE),0) -> 11.3 | X7: =U7*W7 -> 0 | Y7: =Q7 -> 0 | Z7: =+Y7*R7 -> 0 | AA7: EUR | AB7: =IFERROR(VLOOKUP(AA7,Curr!$B$2:$C$13,2,FALSE),0) -> 11.3 | AC7: =+Y7*AB7*R7 -> 0 | AD7: =+AC7-X7 -> 0 | AE7: =IFERROR(AD7/AC7,0) -> 0
C8: Day 1 | D8: Car | J8: Stockholm: Pick up your car at the airport car rental office - Automatic Sedan - Includes: Airport service charge, Collision damage waiver, VAT, Vehicle licence fee / road fund licence, Theft protection, Cancellation fee, Unlimited mileage | Q8: 400 | R8: 1 | S8: =+Q8*R8 -> 400 | T8: 0 | U8: =S8*(1-T8) -> 400 | V8: EUR | W8: =IFERROR(VLOOKUP(V8,[1]Curr!$B$2:$C$13,2,FALSE),0) -> 11.3 | X8: =U8*W8 -> 4520 | Y8: =Q8/0.8 -> 500 | Z8: =+Y8*R8 -> 500 | AA8: EUR | AB8: =IFERROR(VLOOKUP(AA8,Curr!$B$2:$C$13,2,FALSE),0) -> 11.3 | AC8: =+Y8*AB8*R8 -> 5650 | AD8: =+AC8-X8 -> 1130 | AE8: =IFERROR(AD8/AC8,0) -> 0.2
C9: Day 1 | D9: Drive | J9: Stockholm: Drive to your accommodation | Q9: 0 | R9: 0 | S9: =+Q9*R9 -> 0 | T9: 0 | U9: =S9*(1-T9) -> 0 | V9: EUR | W9: =IFERROR(VLOOKUP(V9,[1]Curr!$B$2:$C$13,2,FALSE),0) -> 11.3 | X9: =U9*W9 -> 0 | Y9: =Q9 -> 0 | Z9: =+Y9*R9 -> 0 | AA9: EUR | AB9: =IFERROR(VLOOKUP(AA9,Curr!$B$2:$C$13,2,FALSE),0) -> 11.3 | AC9: =+Y9*AB9*R9 -> 0 | AD9: =+AC9-X9 -> 0 | AE9: =IFERROR(AD9/AC9,0) -> 0
C10: Day 1 | D10: Hotel | J10: Stockholm: Check in to your accommodation for a 1 night stay - Central 4-star hotel - Standard Room - Breakfast included | Q10: 200 | R10: 1 | S10: =+Q10*R10 -> 200 | T10: 0 | U10: =S10*(1-T10) -> 200 | V10: EUR | W10: =IFERROR(VLOOKUP(V10,[1]Curr!$B$2:$C$13,2,FALSE),0) -> 11.3 | X10: =U10*W10 -> 2260 | Y10: =Q10/0.8 -> 250 | Z10: =+Y10*R10 -> 250 | AA10: EUR | AB10: =IFERROR(VLOOKUP(AA10,Curr!$B$2:$C$13,2,FALSE),0) -> 11.3 | AC10: =+Y10*AB10*R10 -> 2825 | AD10: =+AC10-X10 -> 565 | AE10: =IFERROR(AD10/AC10,0) -> 0.2
C11: Day 1 | D11: Leisure | J11: Stockholm: Spend time at leisure | Q11: 0 | R11: 0 | S11: =+Q11*R11 -> 0 | T11: 0 | U11: =S11*(1-T11) -> 0 | V11: EUR | W11: =IFERROR(VLOOKUP(V11,[1]Curr!$B$2:$C$13,2,FALSE),0) -> 11.3 | X11: =U11*W11 -> 0 | Y11: =Q11 -> 0 | Z11: =+Y11*R11 -> 0 | AA11: EUR | AB11: =IFERROR(VLOOKUP(AA11,Curr!$B$2:$C$13,2,FALSE),0) -> 11.3 | AC11: =+Y11*AB11*R11 -> 0 | AD11: =+AC11-X11 -> 0 | AE11: =IFERROR(AD11/AC11,0) -> 0
S12: =+Q12*R12 -> 0 | T12: 0 | U12: =S12*(1-T12) -> 0 | V12: EUR | W12: =IFERROR(VLOOKUP(V12,[1]Curr!$B$2:$C$13,2,FALSE),0) -> 11.3 | X12: =U12*W12 -> 0 | Y12: =Q12 -> 0 | Z12: =+Y12*R12 -> 0 | AA12: EUR | AB12: =IFERROR(VLOOKUP(AA12,Curr!$B$2:$C$13,2,FALSE),0) -> 11.3 | AC12: =+Y12*AB12*R12 -> 0 | AD12: =+AC12-X12 -> 0 | AE12: =IFERROR(AD12/AC12,0) -> 0
C13: Day 2 | D13: Drive | J13: Stockholm: Drive to Karlstad - Time: 4hrs - Highlights: Gripsholm Castle, Strängnäs Cathedral, Arboga Medieval Town, Björskog Snökälla Runestone, Örebro Castle, Picasso Sculpture | Q13: 0 | R13: 0 | S13: =+Q13*R13 -> 0 | T13: 0 | U13: =S13*(1-T13) -> 0 | V13: EUR | W13: =IFERROR(VLOOKUP(V13,[1]Curr!$B$2:$C$13,2,FALSE),0) -> 11.3 | X13: =U13*W13 -> 0 | Y13: =Q13 -> 0 | Z13: =+Y13*R13 -> 0 | AA13: EUR | AB13: =IFERROR(VLOOKUP(AA13,Curr!$B$2:$C$13,2,FALSE),0) -> 11.3 | AC13: =+Y13*AB13*R13 -> 0 | AD13: =+AC13-X13 -> 0 | AE13: =IFERROR(AD13/AC13,0) -> 0
C14: Day 2 | D14: Hotel | J14: Karlstad: Check in to your accommodation for a 1 night stay - Central 4-star hotel - Standard Room - Breakfast included | Q14: 150 | R14: 1 | S14: =+Q14*R14 -> 150 | T14: 0 | U14: =S14*(1-T14) -> 150 | V14: EUR | W14: =IFERROR(VLOOKUP(V14,[1]Curr!$B$2:$C$13,2,FALSE),0) -> 11.3 | X14: =U14*W14 -> 1695 | Y14: =Q14/0.83 -> 180.72289 | Z14: =+Y14*R14 -> 180.72289 | AA14: EUR | AB14: =IFERROR(VLOOKUP(AA14,Curr!$B$2:$C$13,2,FALSE),0) -> 11.3 | AC14: =+Y14*AB14*R14 -> 2042.1687 | AD14: =+AC14-X14 -> 347.16867 | AE14: =IFERROR(AD14/AC14,0) -> 0.17
C15: Day 2 | D15: Leisure | J15: Karlstad: Spend time at leisure | Q15: 0 | R15: 0 | S15: =+Q15*R15 -> 0 | T15: 0 | U15: =S15*(1-T15) -> 0 | V15: EUR | W15: =IFERROR(VLOOKUP(V15,[1]Curr!$B$2:$C$13,2,FALSE),0) -> 11.3 | X15: =U15*W15 -> 0 | Y15: =Q15 -> 0 | Z15: =+Y15*R15 -> 0 | AA15: EUR | AB15: =IFERROR(VLOOKUP(AA15,Curr!$B$2:$C$13,2,FALSE),0) -> 11.3 | AC15: =+Y15*AB15*R15 -> 0 | AD15: =+AC15-X15 -> 0 | AE15: =IFERROR(AD15/AC15,0) -> 0
S16: =+Q16*R16 -> 0 | T16: 0 | U16: =S16*(1-T16) -> 0 | V16: EUR | W16: =IFERROR(VLOOKUP(V16,[1]Curr!$B$2:$C$13,2,FALSE),0) -> 11.3 | X16: =U16*W16 -> 0 | Y16: =Q16 -> 0 | Z16: =+Y16*R16 -> 0 | AA16: EUR | AB16: =IFERROR(VLOOKUP(AA16,Curr!$B$2:$C$13,2,FALSE),0) -> 11.3 | AC16: =+Y16*AB16*R16 -> 0 | AD16: =+AC16-X16 -> 0 | AE16: =IFERROR(AD16/AC16,0) -> 0
C17: Day 3 | D17: Drive | J17: Karlstad: Drive to Gothenburg - Time: 3hrs 30 min - Highlights: Borgvik Manor, Läckö Castle, Kinneulle, Husaby Church, Skara Cathedral, Varnhem Abbey, Äskekärr Viking Village, Skansen Kronan, Skansen Lejonet | Q17: 0 | R17: 0 | S17: =+Q17*R17 -> 0 | T17: 0 | U17: =S17*(1-T17) -> 0 | V17: EUR | W17: =IFERROR(VLOOKUP(V17,[1]Curr!$B$2:$C$13,2,FALSE),0) -> 11.3 | X17: =U17*W17 -> 0 | Y17: =Q17 -> 0 | Z17: =+Y17*R17 -> 0 | AA17: EUR | AB17: =IFERROR(VLOOKUP(AA17,Curr!$B$2:$C$13,2,FALSE),0) -> 11.3 | AC17: =+Y17*AB17*R17 -> 0 | AD17: =+AC17-X17 -> 0 | AE17: =IFERROR(AD17/AC17,0) -> 0
C18: Day 3 | D18: Hotel | J18: Gothenburg: Check in to your accommodation for a 1 night stay - Central 4-star hotel - Standard Room - Breakfast included | Q18: 300 | R18: 1 | S18: =+Q18*R18 -> 300 | T18: 0 | U18: =S18*(1-T18) -> 300 | V18: EUR | W18: =IFERROR(VLOOKUP(V18,[1]Curr!$B$2:$C$13,2,FALSE),0) -> 11.3 | X18: =U18*W18 -> 3390 | Y18: =Q18/0.83 -> 361.44578 | Z18: =+Y18*R18 -> 361.44578 | AA18: EUR | AB18: =IFERROR(VLOOKUP(AA18,Curr!$B$2:$C$13,2,FALSE),0) -> 11.3 | AC18: =+Y18*AB18*R18 -> 4084.3373 | AD18: =+AC18-X18 -> 694.33735 | AE18: =IFERROR(AD18/AC18,0) -> 0.17
C19: Day 3 | D19: Leisure | J19: Gothenburg: Spend time at leisure | Q19: 0 | R19: 0 | S19: =+Q19*R19 -> 0 | T19: 0 | U19: =S19*(1-T19) -> 0 | V19: EUR | W19: =IFERROR(VLOOKUP(V19,[1]Curr!$B$2:$C$13,2,FALSE),0) -> 11.3 | X19: =U19*W19 -> 0 | Y19: =Q19 -> 0 | Z19: =+Y19*R19 -> 0 | AA19: EUR | AB19: =IFERROR(VLOOKUP(AA19,Curr!$B$2:$C$13,2,FALSE),0) -> 11.3 | AC19: =+Y19*AB19*R19 -> 0 | AD19: =+AC19-X19 -> 0 | AE19: =IFERROR(AD19/AC19,0) -> 0
S20: =+Q20*R20 -> 0 | T20: 0 | U20: =S20*(1-T20) -> 0 | V20: EUR | W20: =IFERROR(VLOOKUP(V20,[1]Curr!$B$2:$C$13,2,FALSE),0) -> 11.3 | X20: =U20*W20 -> 0 | Y20: =Q20 -> 0 | Z20: =+Y20*R20 -> 0 | AA20: EUR | AB20: =IFERROR(VLOOKUP(AA20,Curr!$B$2:$C$13,2,FALSE),0) -> 11.3 | AC20: =+Y20*AB20*R20 -> 0 | AD20: =+AC20-X20 -> 0 | AE20: =IFERROR(AD20/AC20,0) -> 0
C21: Day 4 | D21: Drive | J21: Gothenburg: Drive to Helsingborg - Time: 2hrs 30 min - Highlights: Älvsborg Fortress, Tjolöholm Castle, Varberg Fortress, Grimeton Radio Station, Halmstad Castle, Båstad Old Railway Station, Sofiero Palace, Kärnan Tower | Q21: 0 | R21: 0 | S21: =+Q21*R21 -> 0 | T21: 0 | U21: =S21*(1-T21) -> 0 | V21: EUR | W21: =IFERROR(VLOOKUP(V21,[1]Curr!$B$2:$C$13,2,FALSE),0) -> 11.3 | X21: =U21*W21 -> 0 | Y21: =Q21 -> 0 | Z21: =+Y21*R21 -> 0 | AA21: EUR | AB21: =IFERROR(VLOOKUP(AA21,Curr!$B$2:$C$13,2,FALSE),0) -> 11.3 | AC21: =+Y21*AB21*R21 -> 0 | AD21: =+AC21-X21 -> 0 | AE21: =IFERROR(AD21/AC21,0) -> 0
C22: Day 4 | D22: Hotel | J22: Helsingborg: Check in to your accommodation for a 1 night stay - Central 4-star hotel - Standard Room - Breakfast included | Q22: 200 | R22: 1 | S22: =+Q22*R22 -> 200 | T22: 0 | U22: =S22*(1-T22) -> 200 | V22: EUR | W22: =IFERROR(VLOOKUP(V22,[1]Curr!$B$2:$C$13,2,FALSE),0) -> 11.3 | X22: =U22*W22 -> 2260 | Y22: =Q22/0.8 -> 250 | Z22: =+Y22*R22 -> 250 | AA22: EUR | AB22: =IFERROR(VLOOKUP(AA22,Curr!$B$2:$C$13,2,FALSE),0) -> 11.3 | AC22: =+Y22*AB22*R22 -> 2825 | AD22: =+AC22-X22 -> 565 | AE22: =IFERROR(AD22/AC22,0) -> 0.2
C23: Day 4 | D23: Leisure | J23: Helsingborg: Spend time at leisure | Q23: 0 | R23: 0 | S23: =+Q23*R23 -> 0 | T23: 0 | U23: =S23*(1-T23) -> 0 | V23: EUR | W23: =IFERROR(VLOOKUP(V23,[1]Curr!$B$2:$C$13,2,FALSE),0) -> 11.3 | X23: =U23*W23 -> 0 | Y23: =Q23 -> 0 | Z23: =+Y23*R23 -> 0 | AA23: EUR | AB23: =IFERROR(VLOOKUP(AA23,Curr!$B$2:$C$13,2,FALSE),0) -> 11.3 | AC23: =+Y23*AB23*R23 -> 0 | AD23: =+AC23-X23 -> 0 | AE23: =IFERROR(AD23/AC23,0) -> 0
S24: =+Q24*R24 -> 0 | T24: 0 | U24: =S24*(1-T24) -> 0 | V24: EUR | W24: =IFERROR(VLOOKUP(V24,[1]Curr!$B$2:$C$13,2,FALSE),0) -> 11.3 | X24: =U24*W24 -> 0 | Y24: =Q24 -> 0 | Z24: =+Y24*R24 -> 0 | AA24: EUR | AB24: =IFERROR(VLOOKUP(AA24,Curr!$B$2:$C$13,2,FALSE),0) -> 11.3 | AC24: =+Y24*AB24*R24 -> 0 | AD24: =+AC24-X24 -> 0 | AE24: =IFERROR(AD24/AC24,0) -> 0
C25: Day 5 | D25: Drive | J25: Helsingborg: Drive to Karlskrona - Time: 3hrs - Highlights: Glimmingehus, Ale's Stones, Svaneholm Castle, Christinehof Castle, Stenshuvud National Park, Naval Port of Karlskrona, Fredrikskyrkan | Q25: 0 | R25: 0 | S25: =+Q25*R25 -> 0 | T25: 0 | U25: =S25*(1-T25) -> 0 | V25: EUR | W25: =IFERROR(VLOOKUP(V25,[1]Curr!$B$2:$C$13,2,FALSE),0) -> 11.3 | X25: =U25*W25 -> 0 | Y25: =Q25 -> 0 | Z25: =+Y25*R25 -> 0 | AA25: EUR | AB25: =IFERROR(VLOOKUP(AA25,Curr!$B$2:$C$13,2,FALSE),0) -> 11.3 | AC25: =+Y25*AB25*R25 -> 0 | AD25: =+AC25-X25 -> 0 | AE25: =IFERROR(AD25/AC25,0) -> 0
C26: Day 5 | D26: Hotel | J26: Karlskrona: Check in to your accommodation for a 1 night stay - Central 4-star hotel - Standard Room - Breakfast included | Q26: 200 | R26: 1 | S26: =+Q26*R26 -> 200 | T26: 0 | U26: =S26*(1-T26) -> 200 | V26: EUR | W26: =IFERROR(VLOOKUP(V26,[1]Curr!$B$2:$C$13,2,FALSE),0) -> 11.3 | X26: =U26*W26 -> 2260 | Y26: =Q26/0.8 -> 250 | Z26: =+Y26*R26 -> 250 | AA26: EUR | AB26: =IFERROR(VLOOKUP(AA26,Curr!$B$2:$C$13,2,FALSE),0) -> 11.3 | AC26: =+Y26*AB26*R26 -> 2825 | AD26: =+AC26-X26 -> 565 | AE26: =IFERROR(AD26/AC26,0) -> 0.2
C27: Day 5 | D27: Leisure | J27: Karlskrona: Spend time at leisure | Q27: 0 | R27: 0 | S27: =+Q27*R27 -> 0 | T27: 0 | U27: =S27*(1-T27) -> 0 | V27: EUR | W27: =IFERROR(VLOOKUP(V27,[1]Curr!$B$2:$C$13,2,FALSE),0) -> 11.3 | X27: =U27*W27 -> 0 | Y27: =Q27 -> 0 | Z27: =+Y27*R27 -> 0 | AA27: EUR | AB27: =IFERROR(VLOOKUP(AA27,Curr!$B$2:$C$13,2,FALSE),0) -> 11.3 | AC27: =+Y27*AB27*R27 -> 0 | AD27: =+AC27-X27 -> 0 | AE27: =IFERROR(AD27/AC27,0) -> 0
S28: =+Q28*R28 -> 0 | T28: 0 | U28: =S28*(1-T28) -> 0 | V28: EUR | W28: =IFERROR(VLOOKUP(V28,[1]Curr!$B$2:$C$13,2,FALSE),0) -> 11.3 | X28: =U28*W28 -> 0 | Y28: =Q28 -> 0 | Z28: =+Y28*R28 -> 0 | AA28: EUR | AB28: =IFERROR(VLOOKUP(AA28,Curr!$B$2:$C$13,2,FALSE),0) -> 11.3 | AC28: =+Y28*AB28*R28 -> 0 | AD28: =+AC28-X28 -> 0 | AE28: =IFERROR(AD28/AC28,0) -> 0
C29: Day 6 | D29: Drive | J29: Karlskrona: Drive to Västervik - Time: 3hrs - Highlights: Kungsholms Fort, Brömsebro Treaty Stone, Kalmar Castle, Kalmar Cathedral, Borgholm Castle, Eketorp Fort, Virum Moose Park, Västervik Castle Ruins | Q29: 0 | R29: 0 | S29: =+Q29*R29 -> 0 | T29: 0 | U29: =S29*(1-T29) -> 0 | V29: EUR | W29: =IFERROR(VLOOKUP(V29,[1]Curr!$B$2:$C$13,2,FALSE),0) -> 11.3 | X29: =U29*W29 -> 0 | Y29: =Q29 -> 0 | Z29: =+Y29*R29 -> 0 | AA29: EUR | AB29: =IFERROR(VLOOKUP(AA29,Curr!$B$2:$C$13,2,FALSE),0) -> 11.3 | AC29: =+Y29*AB29*R29 -> 0 | AD29: =+AC29-X29 -> 0 | AE29: =IFERROR(AD29/AC29,0) -> 0
C30: Day 6 | D30: Hotel | J30: Västervik: Check in to your accommodation for a 1 night stay - Central 4-star hotel - Standard Room - Breakfast included | Q30: 220 | R30: 1 | S30: =+Q30*R30 -> 220 | T30: 0 | U30: =S30*(1-T30) -> 220 | V30: EUR | W30: =IFERROR(VLOOKUP(V30,[1]Curr!$B$2:$C$13,2,FALSE),0) -> 11.3 | X30: =U30*W30 -> 2486 | Y30: =Q30/0.8 -> 275 | Z30: =+Y30*R30 -> 275 | AA30: EUR | AB30: =IFERROR(VLOOKUP(AA30,Curr!$B$2:$C$13,2,FALSE),0) -> 11.3 | AC30: =+Y30*AB30*R30 -> 3107.5 | AD30: =+AC30-X30 -> 621.5 | AE30: =IFERROR(AD30/AC30,0) -> 0.2
C31: Day 6 | D31: Leisure | J31: Västervik: Spend tim at leisure | Q31: 0 | R31: 0 | S31: =+Q31*R31 -> 0 | T31: 0 | U31: =S31*(1-T31) -> 0 | V31: EUR | W31: =IFERROR(VLOOKUP(V31,[1]Curr!$B$2:$C$13,2,FALSE),0) -> 11.3 | X31: =U31*W31 -> 0 | Y31: =Q31 -> 0 | Z31: =+Y31*R31 -> 0 | AA31: EUR | AB31: =IFERROR(VLOOKUP(AA31,Curr!$B$2:$C$13,2,FALSE),0) -> 11.3 | AC31: =+Y31*AB31*R31 -> 0 | AD31: =+AC31-X31 -> 0 | AE31: =IFERROR(AD31/AC31,0) -> 0
S32: =+Q32*R32 -> 0 | T32: 0 | U32: =S32*(1-T32) -> 0 | V32: EUR | W32: =IFERROR(VLOOKUP(V32,[1]Curr!$B$2:$C$13,2,FALSE),0) -> 11.3 | X32: =U32*W32 -> 0 | Y32: =Q32 -> 0 | Z32: =+Y32*R32 -> 0 | AA32: EUR | AB32: =IFERROR(VLOOKUP(AA32,Curr!$B$2:$C$13,2,FALSE),0) -> 11.3 | AC32: =+Y32*AB32*R32 -> 0 | AD32: =+AC32-X32 -> 0 | AE32: =IFERROR(AD32/AC32,0) -> 0
C33: Day 7 | D33: Drive | J33: Västervik: Drive to Stockholm - Time: 3hrs 30 min - Highlights: Stegeholm Castle Ruins, Gamleby Church Ruins, Stjärnorps Castle Ruins, Linköping Cathedral, Vadstena Castle, Drottningholm Palace | Q33: 0 | R33: 0 | S33: =+Q33*R33 -> 0 | T33: 0 | U33: =S33*(1-T33) -> 0 | V33: EUR | W33: =IFERROR(VLOOKUP(V33,[1]Curr!$B$2:$C$13,2,FALSE),0) -> 11.3 | X33: =U33*W33 -> 0 | Y33: =Q33 -> 0 | Z33: =+Y33*R33 -> 0 | AA33: EUR | AB33: =IFERROR(VLOOKUP(AA33,Curr!$B$2:$C$13,2,FALSE),0) -> 11.3 | AC33: =+Y33*AB33*R33 -> 0 | AD33: =+AC33-X33 -> 0 | AE33: =IFERROR(AD33/AC33,0) -> 0
C34: Day 7 | D34: Hotel | J34: Stockholm: Check in to your accommodation for a 1 night stay - Central 4-star hotel - Standard Room - Breakfast included | Q34: 200 | R34: 1 | S34: =+Q34*R34 -> 200 | T34: 0 | U34: =S34*(1-T34) -> 200 | V34: EUR | W34: =IFERROR(VLOOKUP(V34,[1]Curr!$B$2:$C$13,2,FALSE),0) -> 11.3 | X34: =U34*W34 -> 2260 | Y34: =Q34/0.8 -> 250 | Z34: =+Y34*R34 -> 250 | AA34: EUR | AB34: =IFERROR(VLOOKUP(AA34,Curr!$B$2:$C$13,2,FALSE),0) -> 11.3 | AC34: =+Y34*AB34*R34 -> 2825 | AD34: =+AC34-X34 -> 565 | AE34: =IFERROR(AD34/AC34,0) -> 0.2
C35: Day 7 | D35: Leisure | J35: Stockholm: Spend time at leisure | Q35: 0 | R35: 0 | S35: =+Q35*R35 -> 0 | T35: 0 | U35: =S35*(1-T35) -> 0 | V35: EUR | W35: =IFERROR(VLOOKUP(V35,[1]Curr!$B$2:$C$13,2,FALSE),0) -> 11.3 | X35: =U35*W35 -> 0 | Y35: =Q35 -> 0 | Z35: =+Y35*R35 -> 0 | AA35: EUR | AB35: =IFERROR(VLOOKUP(AA35,Curr!$B$2:$C$13,2,FALSE),0) -> 11.3 | AC35: =+Y35*AB35*R35 -> 0 | AD35: =+AC35-X35 -> 0 | AE35: =IFERROR(AD35/AC35,0) -> 0
S36: =+Q36*R36 -> 0 | T36: 0 | U36: =S36*(1-T36) -> 0 | V36: EUR | W36: =IFERROR(VLOOKUP(V36,[1]Curr!$B$2:$C$13,2,FALSE),0) -> 11.3 | X36: =U36*W36 -> 0 | Y36: =Q36 -> 0 | Z36: =+Y36*R36 -> 0 | AA36: EUR | AB36: =IFERROR(VLOOKUP(AA36,Curr!$B$2:$C$13,2,FALSE),0) -> 11.3 | AC36: =+Y36*AB36*R36 -> 0 | AD36: =+AC36-X36 -> 0 | AE36: =IFERROR(AD36/AC36,0) -> 0
C37: Day 8 | D37: Drive | J37: Stockholm: Drive to Stockholm Airport | Q37: 0 | R37: 0 | S37: =+Q37*R37 -> 0 | T37: 0 | U37: =S37*(1-T37) -> 0 | V37: EUR | W37: =IFERROR(VLOOKUP(V37,[1]Curr!$B$2:$C$13,2,FALSE),0) -> 11.3 | X37: =U37*W37 -> 0 | Y37: =Q37 -> 0 | Z37: =+Y37*R37 -> 0 | AA37: EUR | AB37: =IFERROR(VLOOKUP(AA37,Curr!$B$2:$C$13,2,FALSE),0) -> 11.3 | AC37: =+Y37*AB37*R37 -> 0 | AD37: =+AC37-X37 -> 0 | AE37: =IFERROR(AD37/AC37,0) -> 0
C38: Day 8 | D38: Car | J38: Stockholm: Deliver your rental car | Q38: 0 | R38: 0 | S38: =+Q38*R38 -> 0 | T38: 0 | U38: =S38*(1-T38) -> 0 | V38: EUR | W38: =IFERROR(VLOOKUP(V38,[1]Curr!$B$2:$C$13,2,FALSE),0) -> 11.3 | X38: =U38*W38 -> 0 | Y38: =Q38 -> 0 | Z38: =+Y38*R38 -> 0 | AA38: EUR | AB38: =IFERROR(VLOOKUP(AA38,Curr!$B$2:$C$13,2,FALSE),0) -> 11.3 | AC38: =+Y38*AB38*R38 -> 0 | AD38: =+AC38-X38 -> 0 | AE38: =IFERROR(AD38/AC38,0) -> 0
C39: Day 8 | D39: Departure | J39: Stockholm: Departure home | Q39: 0 | R39: 0 | S39: =+Q39*R39 -> 0 | T39: 0 | U39: =S39*(1-T39) -> 0 | V39: EUR | W39: =IFERROR(VLOOKUP(V39,[1]Curr!$B$2:$C$13,2,FALSE),0) -> 11.3 | X39: =U39*W39 -> 0 | Y39: =Q39 -> 0 | Z39: =+Y39*R39 -> 0 | AA39: EUR | AB39: =IFERROR(VLOOKUP(AA39,Curr!$B$2:$C$13,2,FALSE),0) -> 11.3 | AC39: =+Y39*AB39*R39 -> 0 | AD39: =+AC39-X39 -> 0 | AE39: =IFERROR(AD39/AC39,0) -> 0
S40: =+Q40*R40 -> 0 | T40: 0 | U40: =S40*(1-T40) -> 0 | V40: EUR | W40: =IFERROR(VLOOKUP(V40,[1]Curr!$B$2:$C$13,2,FALSE),0) -> 11.3 | X40: =U40*W40 -> 0 | Y40: =Q40 -> 0 | Z40: =+Y40*R40 -> 0 | AA40: EUR | AB40: =IFERROR(VLOOKUP(AA40,Curr!$B$2:$C$13,2,FALSE),0) -> 11.3 | AC40: =+Y40*AB40*R40 -> 0 | AD40: =+AC40-X40 -> 0 | AE40: =IFERROR(AD40/AC40,0) -> 0
S41: =+Q41*R41 -> 0 | T41: 0 | U41: =S41*(1-T41) -> 0 | V41: EUR | W41: =IFERROR(VLOOKUP(V41,[1]Curr!$B$2:$C$13,2,FALSE),0) -> 11.3 | X41: =U41*W41 -> 0 | Y41: =Q41 -> 0 | Z41: =+Y41*R41 -> 0 | AA41: EUR | AB41: =IFERROR(VLOOKUP(AA41,Curr!$B$2:$C$13,2,FALSE),0) -> 11.3 | AC41: =+Y41*AB41*R41 -> 0 | AD41: =+AC41-X41 -> 0 | AE41: =IFERROR(AD41/AC41,0) -> 0
...

Sheet 403
B1: Stockholm - Gothenburg - Malmø
B2: Dates: Summer
B3: Pax: 2 pax
B4: Rooming: Double
B6: ID | C6: Day | D6: Type | E6: From date | F6: To date | G6: From time | H6: To time | I6: Supplier | J6: Travel element | K6: Manual booking? | L6: Status | M6: Comments | N6: Non-refundable | O6: Refundable | P6: URL | Q6: Gross P per unit | R6: Units | S6: Gross P | T6: Supp Comm | U6: Net P | V6: Supp curr | W6: X-rate | X6: Net P NOK | Y6: Sales P per unit | Z6: Price | AA6: Sales curr | AB6: X-rate | AC6: Sales P NOK tot | AD6: GP NOK | AE6: GP % | AF6: VAT25 | AG6: VAT15 | AH6: VAT12 | AI6: VAT0-D | AJ6: VAT0-I
C7: Day 1 | D7: Arrival | J7: Stockholm: Welcome to Sweden | Q7: 0 | R7: 0 | S7: =+Q7*R7 -> 0 | T7: 0 | U7: =S7*(1-T7) -> 0 | V7: EUR | W7: =IFERROR(VLOOKUP(V7,[1]Curr!$B$2:$C$13,2,FALSE),0) -> 11.3 | X7: =U7*W7 -> 0 | Y7: =Q7 -> 0 | Z7: =+Y7*R7 -> 0 | AA7: EUR | AB7: =IFERROR(VLOOKUP(AA7,Curr!$B$2:$C$13,2,FALSE),0) -> 11.3 | AC7: =+Y7*AB7*R7 -> 0 | AD7: =+AC7-X7 -> 0 | AE7: =IFERROR(AD7/AC7,0) -> 0
C8: Day 1 | D8: Transfer | J8: Stockholm: Self transfer to your accommodation | Q8: 0 | R8: 0 | S8: =+Q8*R8 -> 0 | T8: 0 | U8: =S8*(1-T8) -> 0 | V8: EUR | W8: =IFERROR(VLOOKUP(V8,[1]Curr!$B$2:$C$13,2,FALSE),0) -> 11.3 | X8: =U8*W8 -> 0 | Y8: =Q8 -> 0 | Z8: =+Y8*R8 -> 0 | AA8: EUR | AB8: =IFERROR(VLOOKUP(AA8,Curr!$B$2:$C$13,2,FALSE),0) -> 11.3 | AC8: =+Y8*AB8*R8 -> 0 | AD8: =+AC8-X8 -> 0 | AE8: =IFERROR(AD8/AC8,0) -> 0
C9: Day 1 | D9: Hotel | J9: Stockholm: Check in to your accommodation for a X night stay - - Standard Room - Breakfast included | Q9: 0 | R9: 0 | S9: =+Q9*R9 -> 0 | T9: 0 | U9: =S9*(1-T9) -> 0 | V9: EUR | W9: =IFERROR(VLOOKUP(V9,[1]Curr!$B$2:$C$13,2,FALSE),0) -> 11.3 | X9: =U9*W9 -> 0 | Y9: =Q9/0.85 -> 0 | Z9: =+Y9*R9 -> 0 | AA9: EUR | AB9: =IFERROR(VLOOKUP(AA9,Curr!$B$2:$C$13,2,FALSE),0) -> 11.3 | AC9: =+Y9*AB9*R9 -> 0 | AD9: =+AC9-X9 -> 0 | AE9: =IFERROR(AD9/AC9,0) -> 0
C10: Day 1 | D10: Leisure | J10: Stockholm: Spend time at leisure | Q10: 0 | R10: 0 | S10: =+Q10*R10 -> 0 | T10: 0 | U10: =S10*(1-T10) -> 0 | V10: EUR | W10: =IFERROR(VLOOKUP(V10,[1]Curr!$B$2:$C$13,2,FALSE),0) -> 11.3 | X10: =U10*W10 -> 0 | Y10: =Q10 -> 0 | Z10: =+Y10*R10 -> 0 | AA10: EUR | AB10: =IFERROR(VLOOKUP(AA10,Curr!$B$2:$C$13,2,FALSE),0) -> 11.3 | AC10: =+Y10*AB10*R10 -> 0 | AD10: =+AC10-X10 -> 0 | AE10: =IFERROR(AD10/AC10,0) -> 0
S11: =+Q11*R11 -> 0 | T11: 0 | U11: =S11*(1-T11) -> 0 | V11: EUR | W11: =IFERROR(VLOOKUP(V11,[1]Curr!$B$2:$C$13,2,FALSE),0) -> 11.3 | X11: =U11*W11 -> 0 | Y11: =Q11 -> 0 | Z11: =+Y11*R11 -> 0 | AA11: EUR | AB11: =IFERROR(VLOOKUP(AA11,Curr!$B$2:$C$13,2,FALSE),0) -> 11.3 | AC11: =+Y11*AB11*R11 -> 0 | AD11: =+AC11-X11 -> 0 | AE11: =IFERROR(AD11/AC11,0) -> 0
C12: Day 2 | D12: Transfer | J12: Stockholm: Self transfer to Stockholm Central Station | Q12: 0 | R12: 0 | S12: =+Q12*R12 -> 0 | T12: 0 | U12: =S12*(1-T12) -> 0 | V12: EUR | W12: =IFERROR(VLOOKUP(V12,[1]Curr!$B$2:$C$13,2,FALSE),0) -> 11.3 | X12: =U12*W12 -> 0 | Y12: =Q12 -> 0 | Z12: =+Y12*R12 -> 0 | AA12: EUR | AB12: =IFERROR(VLOOKUP(AA12,Curr!$B$2:$C$13,2,FALSE),0) -> 11.3 | AC12: =+Y12*AB12*R12 -> 0 | AD12: =+AC12-X12 -> 0 | AE12: =IFERROR(AD12/AC12,0) -> 0
C13: Day 2 | D13: Train | J13: Stockholm: Scenic Train Transfer to Karlstad - Time: xxx - Includes: Tickets | Q13: 0 | R13: 0 | S13: =+Q13*R13 -> 0 | T13: 0 | U13: =S13*(1-T13) -> 0 | V13: EUR | W13: =IFERROR(VLOOKUP(V13,[1]Curr!$B$2:$C$13,2,FALSE),0) -> 11.3 | X13: =U13*W13 -> 0 | Y13: =Q13 -> 0 | Z13: =+Y13*R13 -> 0 | AA13: EUR | AB13: =IFERROR(VLOOKUP(AA13,Curr!$B$2:$C$13,2,FALSE),0) -> 11.3 | AC13: =+Y13*AB13*R13 -> 0 | AD13: =+AC13-X13 -> 0 | AE13: =IFERROR(AD13/AC13,0) -> 0
C14: Day 2 | D14: Transfer | J14: Karlstad: Self transfer to your accommodation | Q14: 0 | R14: 0 | S14: =+Q14*R14 -> 0 | T14: 0 | U14: =S14*(1-T14) -> 0 | V14: EUR | W14: =IFERROR(VLOOKUP(V14,[1]Curr!$B$2:$C$13,2,FALSE),0) -> 11.3 | X14: =U14*W14 -> 0 | Y14: =Q14 -> 0 | Z14: =+Y14*R14 -> 0 | AA14: EUR | AB14: =IFERROR(VLOOKUP(AA14,Curr!$B$2:$C$13,2,FALSE),0) -> 11.3 | AC14: =+Y14*AB14*R14 -> 0 | AD14: =+AC14-X14 -> 0 | AE14: =IFERROR(AD14/AC14,0) -> 0
C15: Day 2 | D15: Hotel | J15: Karlstad: Check in to your accommodation for a 1 night stay - Central 4-star hotel - Standard Room - Breakfast included | Q15: 150 | R15: 1 | S15: =+Q15*R15 -> 150 | T15: 0 | U15: =S15*(1-T15) -> 150 | V15: EUR | W15: =IFERROR(VLOOKUP(V15,[1]Curr!$B$2:$C$13,2,FALSE),0) -> 11.3 | X15: =U15*W15 -> 1695 | Y15: =Q15/0.83 -> 180.72289 | Z15: =+Y15*R15 -> 180.72289 | AA15: EUR | AB15: =IFERROR(VLOOKUP(AA15,Curr!$B$2:$C$13,2,FALSE),0) -> 11.3 | AC15: =+Y15*AB15*R15 -> 2042.1687 | AD15: =+AC15-X15 -> 347.16867 | AE15: =IFERROR(AD15/AC15,0) -> 0.17
C16: Day 2 | D16: Leisure | J16: Karlstad: Spend time at leisure | Q16: 0 | R16: 0 | S16: =+Q16*R16 -> 0 | T16: 0 | U16: =S16*(1-T16) -> 0 | V16: EUR | W16: =IFERROR(VLOOKUP(V16,[1]Curr!$B$2:$C$13,2,FALSE),0) -> 11.3 | X16: =U16*W16 -> 0 | Y16: =Q16 -> 0 | Z16: =+Y16*R16 -> 0 | AA16: EUR | AB16: =IFERROR(VLOOKUP(AA16,Curr!$B$2:$C$13,2,FALSE),0) -> 11.3 | AC16: =+Y16*AB16*R16 -> 0 | AD16: =+AC16-X16 -> 0 | AE16: =IFERROR(AD16/AC16,0) -> 0
S17: =+Q17*R17 -> 0 | T17: 0 | U17: =S17*(1-T17) -> 0 | V17: EUR | W17: =IFERROR(VLOOKUP(V17,[1]Curr!$B$2:$C$13,2,FALSE),0) -> 11.3 | X17: =U17*W17 -> 0 | Y17: =Q17 -> 0 | Z17: =+Y17*R17 -> 0 | AA17: EUR | AB17: =IFERROR(VLOOKUP(AA17,Curr!$B$2:$C$13,2,FALSE),0) -> 11.3 | AC17: =+Y17*AB17*R17 -> 0 | AD17: =+AC17-X17 -> 0 | AE17: =IFERROR(AD17/AC17,0) -> 0
C18: Day 3 | D18: Transfer | J18: Karlstad: Self transfer to Karlstad Central Station | Q18: 0 | R18: 0 | S18: =+Q18*R18 -> 0 | T18: 0 | U18: =S18*(1-T18) -> 0 | V18: EUR | W18: =IFERROR(VLOOKUP(V18,[1]Curr!$B$2:$C$13,2,FALSE),0) -> 11.3 | X18: =U18*W18 -> 0 | Y18: =Q18 -> 0 | Z18: =+Y18*R18 -> 0 | AA18: EUR | AB18: =IFERROR(VLOOKUP(AA18,Curr!$B$2:$C$13,2,FALSE),0) -> 11.3 | AC18: =+Y18*AB18*R18 -> 0 | AD18: =+AC18-X18 -> 0 | AE18: =IFERROR(AD18/AC18,0) -> 0
C19: Day 3 | D19: Train | J19: Karlstad: Scenic Train Transfer to Gothenburg - Time: xxx - Includes: Tickets | Q19: 0 | R19: 0 | S19: =+Q19*R19 -> 0 | T19: 0 | U19: =S19*(1-T19) -> 0 | V19: EUR | W19: =IFERROR(VLOOKUP(V19,[1]Curr!$B$2:$C$13,2,FALSE),0) -> 11.3 | X19: =U19*W19 -> 0 | Y19: =Q19 -> 0 | Z19: =+Y19*R19 -> 0 | AA19: EUR | AB19: =IFERROR(VLOOKUP(AA19,Curr!$B$2:$C$13,2,FALSE),0) -> 11.3 | AC19: =+Y19*AB19*R19 -> 0 | AD19: =+AC19-X19 -> 0 | AE19: =IFERROR(AD19/AC19,0) -> 0
C20: Day 3 | D20: Transfer | J20: Gothenburg: Self transfer to your accommodation | Q20: 0 | R20: 0 | S20: =+Q20*R20 -> 0 | T20: 0 | U20: =S20*(1-T20) -> 0 | V20: EUR | W20: =IFERROR(VLOOKUP(V20,[1]Curr!$B$2:$C$13,2,FALSE),0) -> 11.3 | X20: =U20*W20 -> 0 | Y20: =Q20 -> 0 | Z20: =+Y20*R20 -> 0 | AA20: EUR | AB20: =IFERROR(VLOOKUP(AA20,Curr!$B$2:$C$13,2,FALSE),0) -> 11.3 | AC20: =+Y20*AB20*R20 -> 0 | AD20: =+AC20-X20 -> 0 | AE20: =IFERROR(AD20/AC20,0) -> 0
C21: Day 3 | D21: Hotel | J21: Gothenburg: Check in to your accommodation for a 1 night stay - Central 4-star hotel - Standard Room - Breakfast included | Q21: 300 | R21: 1 | S21: =+Q21*R21 -> 300 | T21: 0 | U21: =S21*(1-T21) -> 300 | V21: EUR | W21: =IFERROR(VLOOKUP(V21,[1]Curr!$B$2:$C$13,2,FALSE),0) -> 11.3 | X21: =U21*W21 -> 3390 | Y21: =Q21/0.83 -> 361.44578 | Z21: =+Y21*R21 -> 361.44578 | AA21: EUR | AB21: =IFERROR(VLOOKUP(AA21,Curr!$B$2:$C$13,2,FALSE),0) -> 11.3 | AC21: =+Y21*AB21*R21 -> 4084.3373 | AD21: =+AC21-X21 -> 694.33735 | AE21: =IFERROR(AD21/AC21,0) -> 0.17
C22: Day 3 | D22: Leisure | J22: Gothenburg: Spend time at leisure | Q22: 0 | R22: 0 | S22: =+Q22*R22 -> 0 | T22: 0 | U22: =S22*(1-T22) -> 0 | V22: EUR | W22: =IFERROR(VLOOKUP(V22,[1]Curr!$B$2:$C$13,2,FALSE),0) -> 11.3 | X22: =U22*W22 -> 0 | Y22: =Q22 -> 0 | Z22: =+Y22*R22 -> 0 | AA22: EUR | AB22: =IFERROR(VLOOKUP(AA22,Curr!$B$2:$C$13,2,FALSE),0) -> 11.3 | AC22: =+Y22*AB22*R22 -> 0 | AD22: =+AC22-X22 -> 0 | AE22: =IFERROR(AD22/AC22,0) -> 0
S23: =+Q23*R23 -> 0 | T23: 0 | U23: =S23*(1-T23) -> 0 | V23: EUR | W23: =IFERROR(VLOOKUP(V23,[1]Curr!$B$2:$C$13,2,FALSE),0) -> 11.3 | X23: =U23*W23 -> 0 | Y23: =Q23 -> 0 | Z23: =+Y23*R23 -> 0 | AA23: EUR | AB23: =IFERROR(VLOOKUP(AA23,Curr!$B$2:$C$13,2,FALSE),0) -> 11.3 | AC23: =+Y23*AB23*R23 -> 0 | AD23: =+AC23-X23 -> 0 | AE23: =IFERROR(AD23/AC23,0) -> 0
C24: Day 4 | D24: Transfer | J24: Gothenburg: Self transfer to Gothenburg Central Station | Q24: 0 | R24: 0 | S24: =+Q24*R24 -> 0 | T24: 0 | U24: =S24*(1-T24) -> 0 | V24: EUR | W24: =IFERROR(VLOOKUP(V24,[1]Curr!$B$2:$C$13,2,FALSE),0) -> 11.3 | X24: =U24*W24 -> 0 | Y24: =Q24 -> 0 | Z24: =+Y24*R24 -> 0 | AA24: EUR | AB24: =IFERROR(VLOOKUP(AA24,Curr!$B$2:$C$13,2,FALSE),0) -> 11.3 | AC24: =+Y24*AB24*R24 -> 0 | AD24: =+AC24-X24 -> 0 | AE24: =IFERROR(AD24/AC24,0) -> 0
C25: Day 4 | D25: Train | J25: Gothenburg: Scenic Train Transfer to Helsingborg - Time: xxx - Includes: Tickets | Q25: 0 | R25: 0 | S25: =+Q25*R25 -> 0 | T25: 0 | U25: =S25*(1-T25) -> 0 | V25: EUR | W25: =IFERROR(VLOOKUP(V25,[1]Curr!$B$2:$C$13,2,FALSE),0) -> 11.3 | X25: =U25*W25 -> 0 | Y25: =Q25 -> 0 | Z25: =+Y25*R25 -> 0 | AA25: EUR | AB25: =IFERROR(VLOOKUP(AA25,Curr!$B$2:$C$13,2,FALSE),0) -> 11.3 | AC25: =+Y25*AB25*R25 -> 0 | AD25: =+AC25-X25 -> 0 | AE25: =IFERROR(AD25/AC25,0) -> 0
C26: Day 4 | D26: Transfer | J26: Helsingborg: Self transfer to your accommodation | Q26: 0 | R26: 0 | S26: =+Q26*R26 -> 0 | T26: 0 | U26: =S26*(1-T26) -> 0 | V26: EUR | W26: =IFERROR(VLOOKUP(V26,[1]Curr!$B$2:$C$13,2,FALSE),0) -> 11.3 | X26: =U26*W26 -> 0 | Y26: =Q26 -> 0 | Z26: =+Y26*R26 -> 0 | AA26: EUR | AB26: =IFERROR(VLOOKUP(AA26,Curr!$B$2:$C$13,2,FALSE),0) -> 11.3 | AC26: =+Y26*AB26*R26 -> 0 | AD26: =+AC26-X26 -> 0 | AE26: =IFERROR(AD26/AC26,0) -> 0
C27: Day 4 | D27: Hotel | J27: Helsingborg: Check in to your accommodation for a 1 night stay - Central 4-star hotel - Standard Room - Breakfast included | Q27: 200 | R27: 1 | S27: =+Q27*R27 -> 200 | T27: 0 | U27: =S27*(1-T27) -> 200 | V27: EUR | W27: =IFERROR(VLOOKUP(V27,[1]Curr!$B$2:$C$13,2,FALSE),0) -> 11.3 | X27: =U27*W27 -> 2260 | Y27: =Q27/0.8 -> 250 | Z27: =+Y27*R27 -> 250 | AA27: EUR | AB27: =IFERROR(VLOOKUP(AA27,Curr!$B$2:$C$13,2,FALSE),0) -> 11.3 | AC27: =+Y27*AB27*R27 -> 2825 | AD27: =+AC27-X27 -> 565 | AE27: =IFERROR(AD27/AC27,0) -> 0.2
C28: Day 4 | D28: Leisure | J28: Helsingborg: Spend time at leisure | Q28: 0 | R28: 0 | S28: =+Q28*R28 -> 0 | T28: 0 | U28: =S28*(1-T28) -> 0 | V28: EUR | W28: =IFERROR(VLOOKUP(V28,[1]Curr!$B$2:$C$13,2,FALSE),0) -> 11.3 | X28: =U28*W28 -> 0 | Y28: =Q28 -> 0 | Z28: =+Y28*R28 -> 0 | AA28: EUR | AB28: =IFERROR(VLOOKUP(AA28,Curr!$B$2:$C$13,2,FALSE),0) -> 11.3 | AC28: =+Y28*AB28*R28 -> 0 | AD28: =+AC28-X28 -> 0 | AE28: =IFERROR(AD28/AC28,0) -> 0
S29: =+Q29*R29 -> 0 | T29: 0 | U29: =S29*(1-T29) -> 0 | V29: EUR | W29: =IFERROR(VLOOKUP(V29,[1]Curr!$B$2:$C$13,2,FALSE),0) -> 11.3 | X29: =U29*W29 -> 0 | Y29: =Q29 -> 0 | Z29: =+Y29*R29 -> 0 | AA29: EUR | AB29: =IFERROR(VLOOKUP(AA29,Curr!$B$2:$C$13,2,FALSE),0) -> 11.3 | AC29: =+Y29*AB29*R29 -> 0 | AD29: =+AC29-X29 -> 0 | AE29: =IFERROR(AD29/AC29,0) -> 0
C30: Day 5 | D30: Transfer | J30: Helsingborg: Self transfer to Helsingborg Central Station | Q30: 0 | R30: 0 | S30: =+Q30*R30 -> 0 | T30: 0 | U30: =S30*(1-T30) -> 0 | V30: EUR | W30: =IFERROR(VLOOKUP(V30,[1]Curr!$B$2:$C$13,2,FALSE),0) -> 11.3 | X30: =U30*W30 -> 0 | Y30: =Q30 -> 0 | Z30: =+Y30*R30 -> 0 | AA30: EUR | AB30: =IFERROR(VLOOKUP(AA30,Curr!$B$2:$C$13,2,FALSE),0) -> 11.3 | AC30: =+Y30*AB30*R30 -> 0 | AD30: =+AC30-X30 -> 0 | AE30: =IFERROR(AD30/AC30,0) -> 0
C31: Day 5 | D31: Train | J31: Helsingborg: Scenic Train Transfer to Karlskrona - Time: xxx - Includes: Tickets | Q31: 0 | R31: 0 | S31: =+Q31*R31 -> 0 | T31: 0 | U31: =S31*(1-T31) -> 0 | V31: EUR | W31: =IFERROR(VLOOKUP(V31,[1]Curr!$B$2:$C$13,2,FALSE),0) -> 11.3 | X31: =U31*W31 -> 0 | Y31: =Q31 -> 0 | Z31: =+Y31*R31 -> 0 | AA31: EUR | AB31: =IFERROR(VLOOKUP(AA31,Curr!$B$2:$C$13,2,FALSE),0) -> 11.3 | AC31: =+Y31*AB31*R31 -> 0 | AD31: =+AC31-X31 -> 0 | AE31: =IFERROR(AD31/AC31,0) -> 0
C32: Day 5 | D32: Transfer | J32: Karlskrona: Self transfer to your accommodation | Q32: 0 | R32: 0 | S32: =+Q32*R32 -> 0 | T32: 0 | U32: =S32*(1-T32) -> 0 | V32: EUR | W32: =IFERROR(VLOOKUP(V32,[1]Curr!$B$2:$C$13,2,FALSE),0) -> 11.3 | X32: =U32*W32 -> 0 | Y32: =Q32 -> 0 | Z32: =+Y32*R32 -> 0 | AA32: EUR | AB32: =IFERROR(VLOOKUP(AA32,Curr!$B$2:$C$13,2,FALSE),0) -> 11.3 | AC32: =+Y32*AB32*R32 -> 0 | AD32: =+AC32-X32 -> 0 | AE32: =IFERROR(AD32/AC32,0) -> 0
C33: Day 5 | D33: Hotel | J33: Karlskrona: Check in to your accommodation for a 1 night stay - Central 4-star hotel - Standard Room - Breakfast included | Q33: 200 | R33: 1 | S33: =+Q33*R33 -> 200 | T33: 0 | U33: =S33*(1-T33) -> 200 | V33: EUR | W33: =IFERROR(VLOOKUP(V33,[1]Curr!$B$2:$C$13,2,FALSE),0) -> 11.3 | X33: =U33*W33 -> 2260 | Y33: =Q33/0.8 -> 250 | Z33: =+Y33*R33 -> 250 | AA33: EUR | AB33: =IFERROR(VLOOKUP(AA33,Curr!$B$2:$C$13,2,FALSE),0) -> 11.3 | AC33: =+Y33*AB33*R33 -> 2825 | AD33: =+AC33-X33 -> 565 | AE33: =IFERROR(AD33/AC33,0) -> 0.2
C34: Day 5 | D34: Leisure | J34: Karlskrona: Spend time at leisure | Q34: 0 | R34: 0 | S34: =+Q34*R34 -> 0 | T34: 0 | U34: =S34*(1-T34) -> 0 | V34: EUR | W34: =IFERROR(VLOOKUP(V34,[1]Curr!$B$2:$C$13,2,FALSE),0) -> 11.3 | X34: =U34*W34 -> 0 | Y34: =Q34 -> 0 | Z34: =+Y34*R34 -> 0 | AA34: EUR | AB34: =IFERROR(VLOOKUP(AA34,Curr!$B$2:$C$13,2,FALSE),0) -> 11.3 | AC34: =+Y34*AB34*R34 -> 0 | AD34: =+AC34-X34 -> 0 | AE34: =IFERROR(AD34/AC34,0) -> 0
S35: =+Q35*R35 -> 0 | T35: 0 | U35: =S35*(1-T35) -> 0 | V35: EUR | W35: =IFERROR(VLOOKUP(V35,[1]Curr!$B$2:$C$13,2,FALSE),0) -> 11.3 | X35: =U35*W35 -> 0 | Y35: =Q35 -> 0 | Z35: =+Y35*R35 -> 0 | AA35: EUR | AB35: =IFERROR(VLOOKUP(AA35,Curr!$B$2:$C$13,2,FALSE),0) -> 11.3 | AC35: =+Y35*AB35*R35 -> 0 | AD35: =+AC35-X35 -> 0 | AE35: =IFERROR(AD35/AC35,0) -> 0
C36: Day 6 | D36: Transfer | J36: Karlskrona: Self transfer to Karlskrona Central Station | Q36: 0 | R36: 0 | S36: =+Q36*R36 -> 0 | T36: 0 | U36: =S36*(1-T36) -> 0 | V36: EUR | W36: =IFERROR(VLOOKUP(V36,[1]Curr!$B$2:$C$13,2,FALSE),0) -> 11.3 | X36: =U36*W36 -> 0 | Y36: =Q36 -> 0 | Z36: =+Y36*R36 -> 0 | AA36: EUR | AB36: =IFERROR(VLOOKUP(AA36,Curr!$B$2:$C$13,2,FALSE),0) -> 11.3 | AC36: =+Y36*AB36*R36 -> 0 | AD36: =+AC36-X36 -> 0 | AE36: =IFERROR(AD36/AC36,0) -> 0
C37: Day 6 | D37: Train | J37: Karlskrona: Scenic Train Transfer to Västervik - Time: xxx - Includes: Tickets | Q37: 0 | R37: 0 | S37: =+Q37*R37 -> 0 | T37: 0 | U37: =S37*(1-T37) -> 0 | V37: EUR | W37: =IFERROR(VLOOKUP(V37,[1]Curr!$B$2:$C$13,2,FALSE),0) -> 11.3 | X37: =U37*W37 -> 0 | Y37: =Q37 -> 0 | Z37: =+Y37*R37 -> 0 | AA37: EUR | AB37: =IFERROR(VLOOKUP(AA37,Curr!$B$2:$C$13,2,FALSE),0) -> 11.3 | AC37: =+Y37*AB37*R37 -> 0 | AD37: =+AC37-X37 -> 0 | AE37: =IFERROR(AD37/AC37,0) -> 0
C38: Day 6 | D38: Transfer | J38: Västervik: Self transfer to your accommodation | Q38: 0 | R38: 0 | S38: =+Q38*R38 -> 0 | T38: 0 | U38: =S38*(1-T38) -> 0 | V38: EUR | W38: =IFERROR(VLOOKUP(V38,[1]Curr!$B$2:$C$13,2,FALSE),0) -> 11.3 | X38: =U38*W38 -> 0 | Y38: =Q38 -> 0 | Z38: =+Y38*R38 -> 0 | AA38: EUR | AB38: =IFERROR(VLOOKUP(AA38,Curr!$B$2:$C$13,2,FALSE),0) -> 11.3 | AC38: =+Y38*AB38*R38 -> 0 | AD38: =+AC38-X38 -> 0 | AE38: =IFERROR(AD38/AC38,0) -> 0
C39: Day 6 | D39: Hotel | J39: Västervik: Check in to your accommodation for a 1 night stay - Central 4-star hotel - Standard Room - Breakfast included | Q39: 220 | R39: 1 | S39: =+Q39*R39 -> 220 | T39: 0 | U39: =S39*(1-T39) -> 220 | V39: EUR | W39: =IFERROR(VLOOKUP(V39,[1]Curr!$B$2:$C$13,2,FALSE),0) -> 11.3 | X39: =U39*W39 -> 2486 | Y39: =Q39/0.8 -> 275 | Z39: =+Y39*R39 -> 275 | AA39: EUR | AB39: =IFERROR(VLOOKUP(AA39,Curr!$B$2:$C$13,2,FALSE),0) -> 11.3 | AC39: =+Y39*AB39*R39 -> 3107.5 | AD39: =+AC39-X39 -> 621.5 | AE39: =IFERROR(AD39/AC39,0) -> 0.2
C40: Day 6 | D40: Leisure | J40: Västervik: Spend tim at leisure | Q40: 0 | R40: 0 | S40: =+Q40*R40 -> 0 | T40: 0 | U40: =S40*(1-T40) -> 0 | V40: EUR | W40: =IFERROR(VLOOKUP(V40,[1]Curr!$B$2:$C$13,2,FALSE),0) -> 11.3 | X40: =U40*W40 -> 0 | Y40: =Q40 -> 0 | Z40: =+Y40*R40 -> 0 | AA40: EUR | AB40: =IFERROR(VLOOKUP(AA40,Curr!$B$2:$C$13,2,FALSE),0) -> 11.3 | AC40: =+Y40*AB40*R40 -> 0 | AD40: =+AC40-X40 -> 0 | AE40: =IFERROR(AD40/AC40,0) -> 0
S41: =+Q41*R41 -> 0 | T41: 0 | U41: =S41*(1-T41) -> 0 | V41: EUR | W41: =IFERROR(VLOOKUP(V41,[1]Curr!$B$2:$C$13,2,FALSE),0) -> 11.3 | X41: =U41*W41 -> 0 | Y41: =Q41 -> 0 | Z41: =+Y41*R41 -> 0 | AA41: EUR | AB41: =IFERROR(VLOOKUP(AA41,Curr!$B$2:$C$13,2,FALSE),0) -> 11.3 | AC41: =+Y41*AB41*R41 -> 0 | AD41: =+AC41-X41 -> 0 | AE41: =IFERROR(AD41/AC41,0) -> 0
...
