Workbook

Sheet Curr
C1: NOK
B2: EUR | C2: 11.3
B3: SEK | C3: 1.02
B4: DKK | C4: 1.5
B5: ISK | C5: 0.075
B6: NOK | C6: 1
B7: USD | C7: 10.6

Sheet Overview
A2: ITIN | B2: Cost
A3: 1201 | B3: ='1201'!Z60 -> 4380
A4: 1202 | B4: ='1202'!Z63 -> 3420
A5: 1203 | B5: ='1203'!Z72 -> 4340
A6: 1204 | B6: ='1204'!Z64 -> 4940
A7: 1205 | B7: ='1205'!Z74 -> 4560
A8: 1206 | B8: ='1206'!Z67 -> 4640
A9: 1207 | B9: ='1207'!Z65 -> 4560
A10: 1208 | B10: ='1208'!Z82 -> 5140
A11: 1209 | B11: ='1209'!Z84 -> 5160
A12: 1210 | B12: ='1210'!Z85 -> 4920
A13: 1211 | B13: ='1211'!Z71 -> 4080
A14: 1212 | B14: ='1212'!Z77 -> 5240
A15: 1213 | B15: ='1213'!Z82 -> 4760
A16: 1214 | B16: ='1214'!Z88 -> 5920
A17: 1215
A18: 1216

Sheet 1201
B1: Places: 3N Rovaniemi - 3N Tromsø
B2: Dates: Winter
B3: Pax: 2
B4: Rooming: Double
B6: ID | C6: Day | D6: Type | E6: From date | F6: To date | G6: From time | H6: To time | I6: Supplier | J6: Travel element | K6: Manual booking? | L6: Status | M6: Comments | N6: Non-refundable | O6: Refundable | P6: URL | Q6: Gross P per unit | R6: Units | S6: Gross P | T6: Supp Comm | U6: Net P | V6: Supp curr | W6: X-rate | X6: Net P NOK | Y6: Sales P per unit | Z6: Price | AA6: Sales curr | AB6: X-rate | AC6: Sales P NOK tot | AD6: GP NOK | AE6: GP % | AF6: VAT25 | AG6: VAT15 | AH6: VAT12 | AI6: VAT0-D | AJ6: VAT0-I
C7: Day 1 | D7: Arrival | J7: Rovaniemi: Welcome to Finland | Q7: 0 | R7: 0 | S7: =+Q7*R7 -> 0 | T7: 0 | U7: =S7*(1-T7) -> 0 | V7: EUR | W7: =IFERROR(VLOOKUP(V7,[1]Curr!$B$2:$C$13,2,FALSE),0) -> 11.3 | X7: =U7*W7 -> 0 | Y7: =Q7 -> 0 | Z7: =+Y7*R7 -> 0 | AA7: EUR | AB7: =IFERROR(VLOOKUP(AA7,Curr!$B$2:$C$13,2,FALSE),0) -> 11.3 | AC7: =+Y7*AB7*R7 -> 0 | AD7: =+AC7-X7 -> 0 | AE7: =IFERROR(AD7/AC7,0) -> 0
C8: Day 1 | D8: Transfer | J8: Rovaniemi: Self transfer to your accommodation | Q8: 0 | R8: 0 | S8: =+Q8*R8 -> 0 | T8: 0 | U8: =S8*(1-T8) -> 0 | V8: EUR | W8: =IFERROR(VLOOKUP(V8,[1]Curr!$B$2:$C$13,2,FALSE),0) -> 11.3 | X8: =U8*W8 -> 0 | Y8: =Q8/0.8 -> 0 | Z8: =+Y8*R8 -> 0 | AA8: EUR | AB8: =IFERROR(VLOOKUP(AA8,Curr!$B$2:$C$13,2,FALSE),0) -> 11.3 | AC8: =+Y8*AB8*R8 -> 0 | AD8: =+AC8-X8 -> 0 | AE8: =IFERROR(AD8/AC8,0) -> 0
C9: Day 1 | D9: Hotel | J9: Rovaniemi: Check in to your accommodation for a 3 night stay - Centrally Located 3/4-star Hotel - Standard Room - Breakfast included | N9: x | Q9: 850 | R9: 1 | S9: =+Q9*R9 -> 850 | T9: 0 | U9: =S9*(1-T9) -> 850 | V9: EUR | W9: =IFERROR(VLOOKUP(V9,[1]Curr!$B$2:$C$13,2,FALSE),0) -> 11.3 | X9: =U9*W9 -> 9605 | Y9: =Q9/0.8 -> 1062.5 | Z9: =+Y9*R9 -> 1062.5 | AA9: EUR | AB9: =IFERROR(VLOOKUP(AA9,Curr!$B$2:$C$13,2,FALSE),0) -> 11.3 | AC9: =+Y9*AB9*R9 -> 12006.25 | AD9: =+AC9-X9 -> 2401.25 | AE9: =IFERROR(AD9/AC9,0) -> 0.2
C10: Day 1 | D10: Leisure | J10: Rovaniemi: Spend time at leisure | Q10: 0 | R10: 0 | S10: =+Q10*R10 -> 0 | T10: 0 | U10: =S10*(1-T10) -> 0 | V10: EUR | W10: =IFERROR(VLOOKUP(V10,[1]Curr!$B$2:$C$13,2,FALSE),0) -> 11.3 | X10: =U10*W10 -> 0 | Y10: =Q10 -> 0 | Z10: =+Y10*R10 -> 0 | AA10: EUR | AB10: =IFERROR(VLOOKUP(AA10,Curr!$B$2:$C$13,2,FALSE),0) -> 11.3 | AC10: =+Y10*AB10*R10 -> 0 | AD10: =+AC10-X10 -> 0 | AE10: =IFERROR(AD10/AC10,0) -> 0
S11: =+Q11*R11 -> 0 | T11: 0 | U11: =S11*(1-T11) -> 0 | V11: EUR | W11: =IFERROR(VLOOKUP(V11,[1]Curr!$B$2:$C$13,2,FALSE),0) -> 11.3 | X11: =U11*W11 -> 0 | Y11: =Q11 -> 0 | Z11: =+Y11*R11 -> 0 | AA11: EUR | AB11: =IFERROR(VLOOKUP(AA11,Curr!$B$2:$C$13,2,FALSE),0) -> 11.3 | AC11: =+Y11*AB11*R11 -> 0 | AD11: =+AC11-X11 -> 0 | AE11: =IFERROR(AD11/AC11,0) -> 0
C12: Day 2 | D12: Activity | J12: Rovaniemi: Arctic Circle Highlights Adventure Day - Time: 08:45 am - 2:45 pm - Meeting point: Arctic Circle Snowmobile Park office - Includes: Pick-up/drop-off in central Rovaniemi, Reindeer Farm visit with sleigh ride (2-3 pers), Reindeer sledge driver’s license reward, Alaskan Husky visit with sleigh ride (4 pers), Approx. 2 hours free time in Santa Claus Village, Winter clothes (overalls, boots and gloves), Traditional salmon soup or vegetarian option | O12: x | P12: https://booknordics.com/finland/western-lapland/rovaniemi/arctic-circle-highlights-family-day-by-minibus | Q12: 188 | R12: 2 | S12: 376 | T12: 0.2 | U12: 300.8 | V12: EUR | W12: 11.3 | X12: 3399.04 | Y12: 188 | Z12: =+Y12*R12 -> 376 | AA12: EUR | AB12: =IFERROR(VLOOKUP(AA12,Curr!$B$2:$C$13,2,FALSE),0) -> 11.3 | AC12: =+Y12*AB12*R12 -> 4248.8 | AD12: =+AC12-X12 -> 849.76 | AE12: =IFERROR(AD12/AC12,0) -> 0.2
C13: Day 2 | D13: Leisure | J13: Rovaniemi: Spend time at leisure | Q13: 0 | R13: 0 | S13: =+Q13*R13 -> 0 | T13: 0 | U13: =S13*(1-T13) -> 0 | V13: EUR | W13: =IFERROR(VLOOKUP(V13,[1]Curr!$B$2:$C$13,2,FALSE),0) -> 11.3 | X13: =U13*W13 -> 0 | Y13: =Q13 -> 0 | Z13: =+Y13*R13 -> 0 | AA13: EUR | AB13: =IFERROR(VLOOKUP(AA13,Curr!$B$2:$C$13,2,FALSE),0) -> 11.3 | AC13: =+Y13*AB13*R13 -> 0 | AD13: =+AC13-X13 -> 0 | AE13: =IFERROR(AD13/AC13,0) -> 0
C14: Day 2 | D14: Activity | J14: Rovaniemi: Northern Lights Unlimited Mileage Photo Tour - Time: 08:00 pm - 01:00 am - Meeting point: Book Lapland Office - Includes: Pick-up/drop-off in central Rovaniemi, Knowledgeable, English-speaking guides, Professional DSLR photography (unlimited), Meteorological observations, Thermal winter clothing, Hot drinks & snacks or cookies | O14: x | P14: https://booknordics.com/finland/western-lapland/rovaniemi/rovaniemi-northern-lights-family-tour-by-bus-with-photos | Q14: 109 | R14: 2 | S14: =+Q14*R14 -> 218 | T14: 0.2 | U14: =S14*(1-T14) -> 174.4 | V14: EUR | W14: =IFERROR(VLOOKUP(V14,[1]Curr!$B$2:$C$13,2,FALSE),0) -> 11.3 | X14: =U14*W14 -> 1970.72 | Y14: =Q14 -> 109 | Z14: =+Y14*R14 -> 218 | AA14: EUR | AB14: =IFERROR(VLOOKUP(AA14,Curr!$B$2:$C$13,2,FALSE),0) -> 11.3 | AC14: =+Y14*AB14*R14 -> 2463.4 | AD14: =+AC14-X14 -> 492.68 | AE14: =IFERROR(AD14/AC14,0) -> 0.2
S15: =+Q15*R15 -> 0 | T15: 0 | U15: =S15*(1-T15) -> 0 | V15: EUR | W15: =IFERROR(VLOOKUP(V15,[1]Curr!$B$2:$C$13,2,FALSE),0) -> 11.3 | X15: =U15*W15 -> 0 | Y15: =Q15 -> 0 | Z15: =+Y15*R15 -> 0 | AA15: EUR | AB15: =IFERROR(VLOOKUP(AA15,Curr!$B$2:$C$13,2,FALSE),0) -> 11.3 | AC15: =+Y15*AB15*R15 -> 0 | AD15: =+AC15-X15 -> 0 | AE15: =IFERROR(AD15/AC15,0) -> 0
C16: Day 3 | D16: Activity | J16: Rovaniemi: Arctic Wildlife Adventure to Ranua Park - Time: 10:00 am - 4:00 pm - Meeting point: Lapland Royal Adventures office - Includes: Pick-up/drop-off in central Rovaniemi, Tickets to Ranua Wildlife Park, Drinks and BBQ sausages by fire | O16: x | P16: https://booknordics.com/finland/western-lapland/rovaniemi/arctic-wildlife-adventure-ranua-wildlife-park-trip | Q16: 109 | R16: 2 | S16: =+Q16*R16 -> 218 | T16: 0.2 | U16: =S16*(1-T16) -> 174.4 | V16: EUR | W16: =IFERROR(VLOOKUP(V16,[1]Curr!$B$2:$C$13,2,FALSE),0) -> 11.3 | X16: =U16*W16 -> 1970.72 | Y16: =Q16 -> 109 | Z16: =+Y16*R16 -> 218 | AA16: EUR | AB16: =IFERROR(VLOOKUP(AA16,Curr!$B$2:$C$13,2,FALSE),0) -> 11.3 | AC16: =+Y16*AB16*R16 -> 2463.4 | AD16: =+AC16-X16 -> 492.68 | AE16: =IFERROR(AD16/AC16,0) -> 0.2
C17: Day 3 | D17: Leisure | J17: Rovaniemi: Spend time at leisure | Q17: 0 | R17: 0 | S17: =+Q17*R17 -> 0 | T17: 0 | U17: =S17*(1-T17) -> 0 | V17: EUR | W17: =IFERROR(VLOOKUP(V17,[1]Curr!$B$2:$C$13,2,FALSE),0) -> 11.3 | X17: =U17*W17 -> 0 | Y17: =Q17 -> 0 | Z17: =+Y17*R17 -> 0 | AA17: EUR | AB17: =IFERROR(VLOOKUP(AA17,Curr!$B$2:$C$13,2,FALSE),0) -> 11.3 | AC17: =+Y17*AB17*R17 -> 0 | AD17: =+AC17-X17 -> 0 | AE17: =IFERROR(AD17/AC17,0) -> 0
C18: Day 3 | D18: Activity | J18: Rovaniemi: Small-Group Aurora Hunt by Minibus - Time: 7:00 pm - 10:00 pm - Meeting point: Lapland Royal Adventures Office - Includes: Pick-up/drop-off from central Rovaniemi, Knowledgeable, English-speaking guide, Dedicated Northern Lights chase by minibus, Cozy blankets, hot drinks and a snack | O18: x | P18: https://booknordics.com/finland/western-lapland/rovaniemi/aurora-quest-by-minibus | Q18: 89 | R18: 2 | S18: 178 | T18: 0.2 | U18: 142.4 | V18: EUR | W18: 11.3 | X18: 1609.12 | Y18: 89 | Z18: =+Y18*R18 -> 178 | AA18: EUR | AB18: =IFERROR(VLOOKUP(AA18,Curr!$B$2:$C$13,2,FALSE),0) -> 11.3 | AC18: =+Y18*AB18*R18 -> 2011.4 | AD18: =+AC18-X18 -> 402.28 | AE18: =IFERROR(AD18/AC18,0) -> 0.2
S19: =+Q19*R19 -> 0 | T19: 0 | U19: =S19*(1-T19) -> 0 | V19: EUR | W19: =IFERROR(VLOOKUP(V19,[1]Curr!$B$2:$C$13,2,FALSE),0) -> 11.3 | X19: =U19*W19 -> 0 | Y19: =Q19 -> 0 | Z19: =+Y19*R19 -> 0 | AA19: EUR | AB19: =IFERROR(VLOOKUP(AA19,Curr!$B$2:$C$13,2,FALSE),0) -> 11.3 | AC19: =+Y19*AB19*R19 -> 0 | AD19: =+AC19-X19 -> 0 | AE19: =IFERROR(AD19/AC19,0) -> 0
C20: Day 4 | D20: Transfer | J20: Rovaniemi: Self transfer to Rovaniemi Bus Station | Q20: 0 | R20: 0 | S20: =+Q20*R20 -> 0 | T20: 0 | U20: =S20*(1-T20) -> 0 | V20: EUR | W20: =IFERROR(VLOOKUP(V20,[1]Curr!$B$2:$C$13,2,FALSE),0) -> 11.3 | X20: =U20*W20 -> 0 | Y20: =Q20 -> 0 | Z20: =+Y20*R20 -> 0 | AA20: EUR | AB20: =IFERROR(VLOOKUP(AA20,Curr!$B$2:$C$13,2,FALSE),0) -> 11.3 | AC20: =+Y20*AB20*R20 -> 0 | AD20: =+AC20-X20 -> 0 | AE20: =IFERROR(AD20/AC20,0) -> 0
C21: Day 4 | D21: Activity | J21: Rovaniemi: Arctic Route Coach Transfer to Tromsø - Time: 11:40 am - 7:30 pm - Includes: Tickets | O21: x | P21: https://bestarctic.com/the-arctic-route/arctic-winter-routes-explore-norway-sweden-and-finland/bus-between-tromso-norway-and-rovaniemi-finland/ | Q21: 1830 | R21: 2 | S21: =+Q21*R21 -> 3660 | T21: 0.2 | U21: =S21*(1-T21) -> 2928 | V21: NOK | W21: =IFERROR(VLOOKUP(V21,[1]Curr!$B$2:$C$13,2,FALSE),0) -> 1 | X21: =U21*W21 -> 2928 | Y21: =Q21/11.3/0.9 -> 179.941 | Z21: =+Y21*R21 -> 359.88201 | AA21: EUR | AB21: =IFERROR(VLOOKUP(AA21,Curr!$B$2:$C$13,2,FALSE),0) -> 11.3 | AC21: =+Y21*AB21*R21 -> 4066.6667 | AD21: =+AC21-X21 -> 1138.6667 | AE21: =IFERROR(AD21/AC21,0) -> 0.28
C22: Day 4 | D22: Transfer | J22: Tromsø: Self transfer to your accommodation | Q22: 0 | R22: 0 | S22: =+Q22*R22 -> 0 | T22: 0 | U22: =S22*(1-T22) -> 0 | V22: EUR | W22: =IFERROR(VLOOKUP(V22,[1]Curr!$B$2:$C$13,2,FALSE),0) -> 11.3 | X22: =U22*W22 -> 0 | Y22: =Q22 -> 0 | Z22: =+Y22*R22 -> 0 | AA22: EUR | AB22: =IFERROR(VLOOKUP(AA22,Curr!$B$2:$C$13,2,FALSE),0) -> 11.3 | AC22: =+Y22*AB22*R22 -> 0 | AD22: =+AC22-X22 -> 0 | AE22: =IFERROR(AD22/AC22,0) -> 0
C23: Day 4 | D23: Hotel | J23: Tromsø: Check in to your accommodation for a 3 night stay - Centrally Located 3/4-star Hotel - Standard Room - Breakfast included | O23: x | Q23: 800 | R23: 1 | S23: =+Q23*R23 -> 800 | T23: 0 | U23: =S23*(1-T23) -> 800 | V23: EUR | W23: =IFERROR(VLOOKUP(V23,[1]Curr!$B$2:$C$13,2,FALSE),0) -> 11.3 | X23: =U23*W23 -> 9040 | Y23: =Q23/0.85 -> 941.17647 | Z23: =+Y23*R23 -> 941.17647 | AA23: EUR | AB23: =IFERROR(VLOOKUP(AA23,Curr!$B$2:$C$13,2,FALSE),0) -> 11.3 | AC23: =+Y23*AB23*R23 -> 10635.294 | AD23: =+AC23-X23 -> 1595.2941 | AE23: =IFERROR(AD23/AC23,0) -> 0.15
C24: Day 4 | D24: Leisure | J24: Tromsø: Spend time at leisure | Q24: 0 | R24: 0 | S24: =+Q24*R24 -> 0 | T24: 0 | U24: =S24*(1-T24) -> 0 | V24: EUR | W24: =IFERROR(VLOOKUP(V24,[1]Curr!$B$2:$C$13,2,FALSE),0) -> 11.3 | X24: =U24*W24 -> 0 | Y24: =Q24 -> 0 | Z24: =+Y24*R24 -> 0 | AA24: EUR | AB24: =IFERROR(VLOOKUP(AA24,Curr!$B$2:$C$13,2,FALSE),0) -> 11.3 | AC24: =+Y24*AB24*R24 -> 0 | AD24: =+AC24-X24 -> 0 | AE24: =IFERROR(AD24/AC24,0) -> 0
S25: =+Q25*R25 -> 0 | T25: 0 | U25: =S25*(1-T25) -> 0 | V25: EUR | W25: =IFERROR(VLOOKUP(V25,[1]Curr!$B$2:$C$13,2,FALSE),0) -> 11.3 | X25: =U25*W25 -> 0 | Y25: =Q25 -> 0 | Z25: =+Y25*R25 -> 0 | AA25: EUR | AB25: =IFERROR(VLOOKUP(AA25,Curr!$B$2:$C$13,2,FALSE),0) -> 11.3 | AC25: =+Y25*AB25*R25 -> 0 | AD25: =+AC25-X25 -> 0 | AE25: =IFERROR(AD25/AC25,0) -> 0
C26: Day 5 | D26: Activity | J26: Tromsø: Reindeer Feeding and Sámi Culture - Time: 09:45 am - 2:30 pm - Meeting point: Radisson Blu Hotel's main entrance (Sjøgata 7) - Includes: Scenic transfers (45 min each way), Knowledgeable English and Norwegian speaking guide, Feeding the herd at our camp, Hot beverages and hot meal (traditional Sámi stew or vegetable/lentil soup), Cultural introduction about Sámi history and daily life, A chance to see the northern lights from our camp, Thermal suit and warm snow boots | O26: x | P26: https://www.tromsolapland.no/activities/reindeer-feeding-and-sami-culture | Q26: 1695 | R26: 2 | S26: =+Q26*R26 -> 3390 | T26: 0.2 | U26: =S26*(1-T26) -> 2712 | V26: NOK | W26: =IFERROR(VLOOKUP(V26,[1]Curr!$B$2:$C$13,2,FALSE),0) -> 1 | X26: =U26*W26 -> 2712 | Y26: =Q26/11.3 -> 150 | Z26: =+Y26*R26 -> 300 | AA26: EUR | AB26: =IFERROR(VLOOKUP(AA26,Curr!$B$2:$C$13,2,FALSE),0) -> 11.3 | AC26: =+Y26*AB26*R26 -> 3390 | AD26: =+AC26-X26 -> 678 | AE26: =IFERROR(AD26/AC26,0) -> 0.2
C27: Day 5 | D27: Leisure | J27: Tromsø: Spend time at leisure | Q27: 0 | R27: 0 | S27: =+Q27*R27 -> 0 | T27: 0 | U27: =S27*(1-T27) -> 0 | V27: EUR | W27: =IFERROR(VLOOKUP(V27,[1]Curr!$B$2:$C$13,2,FALSE),0) -> 11.3 | X27: =U27*W27 -> 0 | Y27: =Q27 -> 0 | Z27: =+Y27*R27 -> 0 | AA27: EUR | AB27: =IFERROR(VLOOKUP(AA27,Curr!$B$2:$C$13,2,FALSE),0) -> 11.3 | AC27: =+Y27*AB27*R27 -> 0 | AD27: =+AC27-X27 -> 0 | AE27: =IFERROR(AD27/AC27,0) -> 0
C28: Day 5 | D28: Activity | J28: Tromsø: Northern Lights Chase with Pro Photographer - Time: 6:00 pm - 12:00 am - Meeting point: Roald Amundsens plass 1A - Includes: Professional, English-speaking Aurora photographer guides, Transportation by comfortable minibus, van or coach, Help with camera settings and Aurora Borealis photography, Hot drinks and cookies | O28: x | P28: https://booknordics.com/norway/northern-norway/tromso-region/aurora-chase-with-professional-photographers | Q28: 120 | R28: 2 | S28: =+Q28*R28 -> 240 | T28: 0.2 | U28: =S28*(1-T28) -> 192 | V28: EUR | W28: =IFERROR(VLOOKUP(V28,[2]Curr!$B$2:$C$13,2,FALSE),0) -> 11.3 | X28: =U28*W28 -> 2169.6 | Y28: =Q28 -> 120 | Z28: =+Y28*R28 -> 240 | AA28: EUR | AB28: =IFERROR(VLOOKUP(AA28,Curr!$B$2:$C$13,2,FALSE),0) -> 11.3 | AC28: =+Y28*AB28*R28 -> 2712 | AD28: =+AC28-X28 -> 542.4 | AE28: =IFERROR(AD28/AC28,0) -> 0.2
S29: =+Q29*R29 -> 0 | T29: 0 | U29: =S29*(1-T29) -> 0 | V29: EUR | W29: =IFERROR(VLOOKUP(V29,[1]Curr!$B$2:$C$13,2,FALSE),0) -> 11.3 | X29: =U29*W29 -> 0 | Y29: =Q29 -> 0 | Z29: =+Y29*R29 -> 0 | AA29: EUR | AB29: =IFERROR(VLOOKUP(AA29,Curr!$B$2:$C$13,2,FALSE),0) -> 11.3 | AC29: =+Y29*AB29*R29 -> 0 | AD29: =+AC29-X29 -> 0 | AE29: =IFERROR(AD29/AC29,0) -> 0
C30: Day 6 | D30: Activity | J30: Tromsø: Photo Tour to Arctic Landscapes and Fjords - Time: 10:00 am - 3:00 pm - Meeting point: Roald Amundsens plass 1A - Includes: Departure from central Tromsø. Drop-off to your hotel, Professional, English-speaking photo guides, Scenic fjord safari by comfortable minivan vehicle, Help with camera settings and nature photography, Usually a small-group experience with 4-8 guests, Soup or expedition food, coffee and waffles/cookies | O30: x | P30: https://booknordics.com/norway/northern-norway/tromso-region/tromso-fjord-photo-tour | Q30: 145 | R30: 2 | S30: =+Q30*R30 -> 290 | T30: 0.2 | U30: =S30*(1-T30) -> 232 | V30: EUR | W30: =IFERROR(VLOOKUP(V30,[1]Curr!$B$2:$C$13,2,FALSE),0) -> 11.3 | X30: =U30*W30 -> 2621.6 | Y30: =Q30 -> 145 | Z30: =+Y30*R30 -> 290 | AA30: EUR | AB30: =IFERROR(VLOOKUP(AA30,Curr!$B$2:$C$13,2,FALSE),0) -> 11.3 | AC30: =+Y30*AB30*R30 -> 3277 | AD30: =+AC30-X30 -> 655.4 | AE30: =IFERROR(AD30/AC30,0) -> 0.2
C31: Day 6 | D31: Leisure | J31: Tromsø: Spend time at leisure | Q31: 0 | R31: 0 | S31: =+Q31*R31 -> 0 | T31: 0 | U31: =S31*(1-T31) -> 0 | V31: EUR | W31: =IFERROR(VLOOKUP(V31,[1]Curr!$B$2:$C$13,2,FALSE),0) -> 11.3 | X31: =U31*W31 -> 0 | Y31: =Q31 -> 0 | Z31: =+Y31*R31 -> 0 | AA31: EUR | AB31: =IFERROR(VLOOKUP(AA31,Curr!$B$2:$C$13,2,FALSE),0) -> 11.3 | AC31: =+Y31*AB31*R31 -> 0 | AD31: =+AC31-X31 -> 0 | AE31: =IFERROR(AD31/AC31,0) -> 0
C32: Day 6 | D32: Activity | J32: Tromsø: Northern Lights Cruise with Silent Electric Ship - Time: 7:00 pm - 10:00 pm - Meeting point: Kaigata 6 - Includes: Departure from central Tromsø, 3-hour fjord cruise, Light meal (soup and bread) and water, English speaking guides, Warm indoor saloons, Free wifi, Toilets | O32: x | P32: https://booknordics.com/norway/northern-norway/tromso-region/northern-lights-cruise-electric-ship | Q32: 105 | R32: 2 | S32: =+Q32*R32 -> 210 | T32: 0.2 | U32: =S32*(1-T32) -> 168 | V32: EUR | W32: =IFERROR(VLOOKUP(V32,[1]Curr!$B$2:$C$13,2,FALSE),0) -> 11.3 | X32: =U32*W32 -> 1898.4 | Y32: =Q32 -> 105 | Z32: =+Y32*R32 -> 210 | AA32: EUR | AB32: =IFERROR(VLOOKUP(AA32,Curr!$B$2:$C$13,2,FALSE),0) -> 11.3 | AC32: =+Y32*AB32*R32 -> 2373 | AD32: =+AC32-X32 -> 474.6 | AE32: =IFERROR(AD32/AC32,0) -> 0.2
S33: =+Q33*R33 -> 0 | T33: 0 | U33: =S33*(1-T33) -> 0 | V33: EUR | W33: =IFERROR(VLOOKUP(V33,[1]Curr!$B$2:$C$13,2,FALSE),0) -> 11.3 | X33: =U33*W33 -> 0 | Y33: =Q33 -> 0 | Z33: =+Y33*R33 -> 0 | AA33: EUR | AB33: =IFERROR(VLOOKUP(AA33,Curr!$B$2:$C$13,2,FALSE),0) -> 11.3 | AC33: =+Y33*AB33*R33 -> 0 | AD33: =+AC33-X33 -> 0 | AE33: =IFERROR(AD33/AC33,0) -> 0
C34: Day 7 | D34: Transfer | J34: Tromsø: Self transfer to Tromsø Airport | Q34: 0 | R34: 0 | S34: =+Q34*R34 -> 0 | T34: 0 | U34: =S34*(1-T34) -> 0 | V34: EUR | W34: =IFERROR(VLOOKUP(V34,[1]Curr!$B$2:$C$13,2,FALSE),0) -> 11.3 | X34: =U34*W34 -> 0 | Y34: =Q34 -> 0 | Z34: =+Y34*R34 -> 0 | AA34: EUR | AB34: =IFERROR(VLOOKUP(AA34,Curr!$B$2:$C$13,2,FALSE),0) -> 11.3 | AC34: =+Y34*AB34*R34 -> 0 | AD34: =+AC34-X34 -> 0 | AE34: =IFERROR(AD34/AC34,0) -> 0
C35: Day 7 | D35: Departure | J35: Tromsø: Departure home | Q35: 0 | R35: 0 | S35: =+Q35*R35 -> 0 | T35: 0 | U35: =S35*(1-T35) -> 0 | V35: EUR | W35: =IFERROR(VLOOKUP(V35,[1]Curr!$B$2:$C$13,2,FALSE),0) -> 11.3 | X35: =U35*W35 -> 0 | Y35: =Q35 -> 0 | Z35: =+Y35*R35 -> 0 | AA35: EUR | AB35: =IFERROR(VLOOKUP(AA35,Curr!$B$2:$C$13,2,FALSE),0) -> 11.3 | AC35: =+Y35*AB35*R35 -> 0 | AD35: =+AC35-X35 -> 0 | AE35: =IFERROR(AD35/AC35,0) -> 0
S36: =+Q36*R36 -> 0 | T36: 0 | U36: =S36*(1-T36) -> 0 | V36: EUR | W36: =IFERROR(VLOOKUP(V36,[1]Curr!$B$2:$C$13,2,FALSE),0) -> 11.3 | X36: =U36*W36 -> 0 | Y36: =Q36 -> 0 | Z36: =+Y36*R36 -> 0 | AA36: EUR | AB36: =IFERROR(VLOOKUP(AA36,Curr!$B$2:$C$13,2,FALSE),0) -> 11.3 | AC36: =+Y36*AB36*R36 -> 0 | AD36: =+AC36-X36 -> 0 | AE36: =IFERROR(AD36/AC36,0) -> 0
S37: =+Q37*R37 -> 0 | T37: 0 | U37: =S37*(1-T37) -> 0 | V37: EUR | W37: =IFERROR(VLOOKUP(V37,[1]Curr!$B$2:$C$13,2,FALSE),0) -> 11.3 | X37: =U37*W37 -> 0 | Y37: =Q37 -> 0 | Z37: =+Y37*R37 -> 0 | AA37: EUR | AB37: =IFERROR(VLOOKUP(AA37,Curr!$B$2:$C$13,2,FALSE),0) -> 11.3 | AC37: =+Y37*AB37*R37 -> 0 | AD37: =+AC37-X37 -> 0 | AE37: =IFERROR(AD37/AC37,0) -> 0
C38: Day 1 | D38: Transfer package | J38: Rovaniemi: Private transfer to your accommodation | Q38: 40 | R38: 0 | S38: =+Q38*R38 -> 0 | T38: 0 | U38: =S38*(1-T38) -> 0 | V38: EUR | W38: =IFERROR(VLOOKUP(V38,[1]Curr!$B$2:$C$13,2,FALSE),0) -> 11.3 | X38: =U38*W38 -> 0 | Y38: =Q38/0.67 -> 59.701493 | Z38: =+Y38*R38 -> 0 | AA38: EUR | AB38: =IFERROR(VLOOKUP(AA38,Curr!$B$2:$C$13,2,FALSE),0) -> 11.3 | AC38: =+Y38*AB38*R38 -> 0 | AD38: =+AC38-X38 -> 0 | AE38: =IFERROR(AD38/AC38,0) -> 0
C39: Day 4 | D39: Transfer package | J39: Rovaniemi: Private transfer to Rovaniemi Bus Station | Q39: 40 | R39: 0 | S39: =+Q39*R39 -> 0 | T39: 0 | U39: =S39*(1-T39) -> 0 | V39: EUR | W39: =IFERROR(VLOOKUP(V39,[1]Curr!$B$2:$C$13,2,FALSE),0) -> 11.3 | X39: =U39*W39 -> 0 | Y39: =Q39/0.67 -> 59.701493 | Z39: =+Y39*R39 -> 0 | AA39: EUR | AB39: =IFERROR(VLOOKUP(AA39,Curr!$B$2:$C$13,2,FALSE),0) -> 11.3 | AC39: =+Y39*AB39*R39 -> 0 | AD39: =+AC39-X39 -> 0 | AE39: =IFERROR(AD39/AC39,0) -> 0
C40: Day 7 | D40: Transfer package | J40: Tromsø: Private transfer to Tromsø Airport | Q40: 900 | R40: 0 | S40: =+Q40*R40 -> 0 | T40: 0 | U40: =S40*(1-T40) -> 0 | V40: NOK | W40: =IFERROR(VLOOKUP(V40,[1]Curr!$B$2:$C$13,2,FALSE),0) -> 1 | X40: =U40*W40 -> 0 | Y40: =Q40/11.3/0.8 -> 99.557522 | Z40: =+Y40*R40 -> 0 | AA40: EUR | AB40: =IFERROR(VLOOKUP(AA40,Curr!$B$2:$C$13,2,FALSE),0) -> 11.3 | AC40: =+Y40*AB40*R40 -> 0 | AD40: =+AC40-X40 -> 0 | AE40: =IFERROR(AD40/AC40,0) -> 0
S41: =+Q41*R41 -> 0 | T41: 0 | U41: =S41*(1-T41) -> 0 | V41: EUR | W41: =IFERROR(VLOOKUP(V41,[1]Curr!$B$2:$C$13,2,FALSE),0) -> 11.3 | X41: =U41*W41 -> 0 | Y41: =Q41 -> 0 | Z41: =+Y41*R41 -> 0 | AA41: EUR | AB41: =IFERROR(VLOOKUP(AA41,Curr!$B$2:$C$13,2,FALSE),0) -> 11.3 | AC41: =+Y41*AB41*R41 -> 0 | AD41: =+AC41-X41 -> 0 | AE41: =IFERROR(AD41/AC41,0) -> 0
...

Sheet 1202
B1: Places: 1N Helsinki - 1N Santa Express - 2N Rovaniemi - 2N Tromsø
B2: Dates: Winter
B3: Pax: 2
B4: Rooming: Double
B6: ID | C6: Day | D6: Type | E6: From date | F6: To date | G6: From time | H6: To time | I6: Supplier | J6: Travel element | K6: Manual booking? | L6: Status | M6: Comments | N6: Non-refundable | O6: Refundable | P6: URL | Q6: Gross P per unit | R6: Units | S6: Gross P | T6: Supp Comm | U6: Net P | V6: Supp curr | W6: X-rate | X6: Net P NOK | Y6: Sales P per unit | Z6: Price | AA6: Sales curr | AB6: X-rate | AC6: Sales P NOK tot | AD6: GP NOK | AE6: GP % | AF6: VAT25 | AG6: VAT15 | AH6: VAT12 | AI6: VAT0-D | AJ6: VAT0-I
C7: Day 1 | D7: Arrival | J7: Helsinki: Welcome to Finland | Q7: 0 | R7: 0 | S7: =+Q7*R7 -> 0 | T7: 0 | U7: =S7*(1-T7) -> 0 | V7: EUR | W7: =IFERROR(VLOOKUP(V7,[1]Curr!$B$2:$C$13,2,FALSE),0) -> 11.3 | X7: =U7*W7 -> 0 | Y7: =Q7 -> 0 | Z7: =+Y7*R7 -> 0 | AA7: EUR | AB7: =IFERROR(VLOOKUP(AA7,Curr!$B$2:$C$13,2,FALSE),0) -> 11.3 | AC7: =+Y7*AB7*R7 -> 0 | AD7: =+AC7-X7 -> 0 | AE7: =IFERROR(AD7/AC7,0) -> 0
C8: Day 1 | D8: Transfer | J8: Helsinki: Self transfer to your accommodation | Q8: 0 | R8: 0 | S8: =+Q8*R8 -> 0 | T8: 0 | U8: =S8*(1-T8) -> 0 | V8: EUR | W8: =IFERROR(VLOOKUP(V8,[1]Curr!$B$2:$C$13,2,FALSE),0) -> 11.3 | X8: =U8*W8 -> 0 | Y8: =Q8/0.8 -> 0 | Z8: =+Y8*R8 -> 0 | AA8: EUR | AB8: =IFERROR(VLOOKUP(AA8,Curr!$B$2:$C$13,2,FALSE),0) -> 11.3 | AC8: =+Y8*AB8*R8 -> 0 | AD8: =+AC8-X8 -> 0 | AE8: =IFERROR(AD8/AC8,0) -> 0
C9: Day 1 | D9: Hotel | J9: Helsinki: Check in to your accommodation for a 1 night stay - Centrally Located 3/4-star Hotel - Standard Room - Breakfast included | Q9: 150 | R9: 1 | S9: =+Q9*R9 -> 150 | T9: 0 | U9: =S9*(1-T9) -> 150 | V9: EUR | W9: =IFERROR(VLOOKUP(V9,[1]Curr!$B$2:$C$13,2,FALSE),0) -> 11.3 | X9: =U9*W9 -> 1695 | Y9: =Q9/0.85 -> 176.47059 | Z9: =+Y9*R9 -> 176.47059 | AA9: EUR | AB9: =IFERROR(VLOOKUP(AA9,Curr!$B$2:$C$13,2,FALSE),0) -> 11.3 | AC9: =+Y9*AB9*R9 -> 1994.1176 | AD9: =+AC9-X9 -> 299.11765 | AE9: =IFERROR(AD9/AC9,0) -> 0.15
C10: Day 1 | D10: Leisure | J10: Helsinki: Spend time at leisure | Q10: 0 | R10: 0 | S10: =+Q10*R10 -> 0 | T10: 0 | U10: =S10*(1-T10) -> 0 | V10: EUR | W10: =IFERROR(VLOOKUP(V10,[1]Curr!$B$2:$C$13,2,FALSE),0) -> 11.3 | X10: =U10*W10 -> 0 | Y10: =Q10 -> 0 | Z10: =+Y10*R10 -> 0 | AA10: EUR | AB10: =IFERROR(VLOOKUP(AA10,Curr!$B$2:$C$13,2,FALSE),0) -> 11.3 | AC10: =+Y10*AB10*R10 -> 0 | AD10: =+AC10-X10 -> 0 | AE10: =IFERROR(AD10/AC10,0) -> 0
S11: =+Q11*R11 -> 0 | T11: 0 | U11: =S11*(1-T11) -> 0 | V11: EUR | W11: =IFERROR(VLOOKUP(V11,[1]Curr!$B$2:$C$13,2,FALSE),0) -> 11.3 | X11: =U11*W11 -> 0 | Y11: =Q11 -> 0 | Z11: =+Y11*R11 -> 0 | AA11: EUR | AB11: =IFERROR(VLOOKUP(AA11,Curr!$B$2:$C$13,2,FALSE),0) -> 11.3 | AC11: =+Y11*AB11*R11 -> 0 | AD11: =+AC11-X11 -> 0 | AE11: =IFERROR(AD11/AC11,0) -> 0
C12: Day 2 | D12: Activity | J12: Helsinki: A Finntastic Walking Tour - Time: 10:30 am / 1:30 pm - 12:45 pm / 3:45 pm - Meeting point: Senate Square (Look for a blue and white umbrella) - End point: Helsinki Central Library Oodi - Notable Sights: Senate Square, Helsinki Cathedral, Kauppatori, Uspenski Cathedral, Esplanadi Park and more - Includes: Professional authorised Helsinki Guide, Liability Insurance | O12: x | P12: https://www.finntastictours.fi/# | Q12: 20 | R12: 2 | S12: =+Q12*R12 -> 40 | T12: 0 | U12: =S12*(1-T12) -> 40 | V12: EUR | W12: 11.3 | X12: =U12*W12 -> 452 | Y12: 35.087719 | Z12: =+Y12*R12 -> 70.175439 | AA12: EUR | AB12: =IFERROR(VLOOKUP(AA12,Curr!$B$2:$C$13,2,FALSE),0) -> 11.3 | AC12: =+Y12*AB12*R12 -> 792.98246 | AD12: =+AC12-X12 -> 340.98246 | AE12: =IFERROR(AD12/AC12,0) -> 0.43
C13: Day 2 | D13: Transfer | J13: Helsinki: Self transfer to Helsinki Central Station | Q13: 0 | R13: 0 | S13: =+Q13*R13 -> 0 | T13: 0 | U13: =S13*(1-T13) -> 0 | V13: EUR | W13: 11.3 | X13: =U13*W13 -> 0 | Y13: 0 | Z13: =+Y13*R13 -> 0 | AA13: EUR | AB13: =IFERROR(VLOOKUP(AA13,Curr!$B$2:$C$13,2,FALSE),0) -> 11.3 | AC13: =+Y13*AB13*R13 -> 0 | AD13: =+AC13-X13 -> 0 | AE13: =IFERROR(AD13/AC13,0) -> 0
C14: Day 2 | D14: Train | J14: Helsinki: Overnight Santa Claus Express Train to Rovaniemi - Time: 11:13 pm - 10:59 am - Includes: Upstairs Sleeper Cabin with Private Bathroom | N14: x | P14: https://www.vr.fi/en/santa-claus-express | Q14: 200 | R14: 1 | S14: =+Q14*R14 -> 200 | T14: 0 | U14: =S14*(1-T14) -> 200 | V14: EUR | W14: 11.3 | X14: =U14*W14 -> 2260 | Y14: =Q14/0.8 -> 250 | Z14: =+Y14*R14 -> 250 | AA14: EUR | AB14: =IFERROR(VLOOKUP(AA14,Curr!$B$2:$C$13,2,FALSE),0) -> 11.3 | AC14: =+Y14*AB14*R14 -> 2825 | AD14: =+AC14-X14 -> 565 | AE14: =IFERROR(AD14/AC14,0) -> 0.2
S15: =+Q15*R15 -> 0 | T15: 0 | U15: =S15*(1-T15) -> 0 | V15: EUR | W15: =IFERROR(VLOOKUP(V15,[1]Curr!$B$2:$C$13,2,FALSE),0) -> 11.3 | X15: =U15*W15 -> 0 | Y15: =Q15 -> 0 | Z15: =+Y15*R15 -> 0 | AA15: EUR | AB15: =IFERROR(VLOOKUP(AA15,Curr!$B$2:$C$13,2,FALSE),0) -> 11.3 | AC15: =+Y15*AB15*R15 -> 0 | AD15: =+AC15-X15 -> 0 | AE15: =IFERROR(AD15/AC15,0) -> 0
C16: Day 3 | D16: Transfer | J16: Rovaniemi: Self transfer to your accommodation | Q16: 0 | R16: 0 | S16: =+Q16*R16 -> 0 | T16: 0 | U16: =S16*(1-T16) -> 0 | V16: EUR | W16: =IFERROR(VLOOKUP(V16,[1]Curr!$B$2:$C$13,2,FALSE),0) -> 11.3 | X16: =U16*W16 -> 0 | Y16: =Q16/0.8 -> 0 | Z16: =+Y16*R16 -> 0 | AA16: EUR | AB16: =IFERROR(VLOOKUP(AA16,Curr!$B$2:$C$13,2,FALSE),0) -> 11.3 | AC16: =+Y16*AB16*R16 -> 0 | AD16: =+AC16-X16 -> 0 | AE16: =IFERROR(AD16/AC16,0) -> 0
C17: Day 3 | D17: Hotel | J17: Rovaniemi: Check in to your accommodation for a 2 night stay - Centrally Located 3/4-star Hotel - Standard Room - Breakfast included | Q17: 600 | R17: 1 | S17: =+Q17*R17 -> 600 | T17: 0 | U17: =S17*(1-T17) -> 600 | V17: EUR | W17: =IFERROR(VLOOKUP(V17,[1]Curr!$B$2:$C$13,2,FALSE),0) -> 11.3 | X17: =U17*W17 -> 6780 | Y17: =Q17/0.85 -> 705.88235 | Z17: =+Y17*R17 -> 705.88235 | AA17: EUR | AB17: =IFERROR(VLOOKUP(AA17,Curr!$B$2:$C$13,2,FALSE),0) -> 11.3 | AC17: =+Y17*AB17*R17 -> 7976.4706 | AD17: =+AC17-X17 -> 1196.4706 | AE17: =IFERROR(AD17/AC17,0) -> 0.15
C18: Day 3 | D18: Leisure | J18: Rovaniemi: Spend time at leisure | Q18: 0 | R18: 0 | S18: =+Q18*R18 -> 0 | T18: 0 | U18: =S18*(1-T18) -> 0 | V18: EUR | W18: =IFERROR(VLOOKUP(V18,[1]Curr!$B$2:$C$13,2,FALSE),0) -> 11.3 | X18: =U18*W18 -> 0 | Y18: =Q18 -> 0 | Z18: =+Y18*R18 -> 0 | AA18: EUR | AB18: =IFERROR(VLOOKUP(AA18,Curr!$B$2:$C$13,2,FALSE),0) -> 11.3 | AC18: =+Y18*AB18*R18 -> 0 | AD18: =+AC18-X18 -> 0 | AE18: =IFERROR(AD18/AC18,0) -> 0
C19: Day 3 | D19: Activity | J19: Rovaniemi: Northern Lights Unlimited Mileage Photo Tour - Time: 08:00 pm - 01:00 am - Meeting point: Book Lapland Office - Includes: Pick-up/drop-off in central Rovaniemi, Knowledgeable, English-speaking guides, Professional DSLR photography (unlimited), Meteorological observations, Thermal winter clothing, Hot drinks & snacks or cookies | O19: x | P19: https://booknordics.com/finland/western-lapland/rovaniemi/rovaniemi-northern-lights-family-tour-by-bus-with-photos | Q19: 109 | R19: 2 | S19: =+Q19*R19 -> 218 | T19: 0.2 | U19: =S19*(1-T19) -> 174.4 | V19: EUR | W19: =IFERROR(VLOOKUP(V19,[1]Curr!$B$2:$C$13,2,FALSE),0) -> 11.3 | X19: =U19*W19 -> 1970.72 | Y19: =Q19 -> 109 | Z19: =+Y19*R19 -> 218 | AA19: EUR | AB19: =IFERROR(VLOOKUP(AA19,Curr!$B$2:$C$13,2,FALSE),0) -> 11.3 | AC19: =+Y19*AB19*R19 -> 2463.4 | AD19: =+AC19-X19 -> 492.68 | AE19: =IFERROR(AD19/AC19,0) -> 0.2
S20: =+Q20*R20 -> 0 | T20: 0 | U20: =S20*(1-T20) -> 0 | V20: EUR | W20: =IFERROR(VLOOKUP(V20,[1]Curr!$B$2:$C$13,2,FALSE),0) -> 11.3 | X20: =U20*W20 -> 0 | Y20: =Q20 -> 0 | Z20: =+Y20*R20 -> 0 | AA20: EUR | AB20: =IFERROR(VLOOKUP(AA20,Curr!$B$2:$C$13,2,FALSE),0) -> 11.3 | AC20: =+Y20*AB20*R20 -> 0 | AD20: =+AC20-X20 -> 0 | AE20: =IFERROR(AD20/AC20,0) -> 0
C21: Day 4 | D21: Activity | J21: Rovaniemi: Arctic Circle Highlights Adventure Day - Time: 08:45 am - 2:45 pm - Meeting point: Arctic Circle Snowmobile Park office - Includes: Pick-up/drop-off in central Rovaniemi, Reindeer Farm visit with sleigh ride (2-3 pers), Reindeer sledge driver’s license reward, Alaskan Husky visit with sleigh ride (4 pers), Approx. 2 hours free time in Santa Claus Village, Winter clothes (overalls, boots and gloves), Traditional salmon soup or vegetarian option | O21: x | P21: https://booknordics.com/finland/western-lapland/rovaniemi/arctic-circle-highlights-family-day-by-minibus | Q21: 188 | R21: 2 | S21: =+Q21*R21 -> 376 | T21: 0.2 | U21: =S21*(1-T21) -> 300.8 | V21: EUR | W21: 11.3 | X21: =U21*W21 -> 3399.04 | Y21: =Q21 -> 188 | Z21: =+Y21*R21 -> 376 | AA21: EUR | AB21: =IFERROR(VLOOKUP(AA21,Curr!$B$2:$C$13,2,FALSE),0) -> 11.3 | AC21: =+Y21*AB21*R21 -> 4248.8 | AD21: =+AC21-X21 -> 849.76 | AE21: =IFERROR(AD21/AC21,0) -> 0.2
C22: Day 4 | D22: Leisure | J22: Rovaniemi: Spend time at leisure | Q22: 0 | R22: 0 | S22: =+Q22*R22 -> 0 | T22: 0 | U22: =S22*(1-T22) -> 0 | V22: EUR | W22: 11.3 | X22: =U22*W22 -> 0 | Y22: =Q22 -> 0 | Z22: =+Y22*R22 -> 0 | AA22: EUR | AB22: =IFERROR(VLOOKUP(AA22,Curr!$B$2:$C$13,2,FALSE),0) -> 11.3 | AC22: =+Y22*AB22*R22 -> 0 | AD22: =+AC22-X22 -> 0 | AE22: =IFERROR(AD22/AC22,0) -> 0
C23: Day 4 | D23: Activity | J23: Rovaniemi: Small-Group Aurora Hunt by Minibus - Time: 7:00 pm - 10:00 pm - Meeting point: Lapland Royal Adventures Office - Includes: Pick-up/drop-off from central Rovaniemi, Knowledgeable, English-speaking guide, Dedicated Northern Lights chase by minibus, Cozy blankets, hot drinks and a snack | O23: x | P23: https://booknordics.com/finland/western-lapland/rovaniemi/aurora-quest-by-minibus | Q23: 89 | R23: 2 | S23: =+Q23*R23 -> 178 | T23: 0.2 | U23: =S23*(1-T23) -> 142.4 | V23: EUR | W23: 11.3 | X23: =U23*W23 -> 1609.12 | Y23: =Q23 -> 89 | Z23: =+Y23*R23 -> 178 | AA23: EUR | AB23: =IFERROR(VLOOKUP(AA23,Curr!$B$2:$C$13,2,FALSE),0) -> 11.3 | AC23: =+Y23*AB23*R23 -> 2011.4 | AD23: =+AC23-X23 -> 402.28 | AE23: =IFERROR(AD23/AC23,0) -> 0.2
S24: =+Q24*R24 -> 0 | T24: 0 | U24: =S24*(1-T24) -> 0 | V24: EUR | W24: =IFERROR(VLOOKUP(V24,[1]Curr!$B$2:$C$13,2,FALSE),0) -> 11.3 | X24: =U24*W24 -> 0 | Y24: =Q24 -> 0 | Z24: =+Y24*R24 -> 0 | AA24: EUR | AB24: =IFERROR(VLOOKUP(AA24,Curr!$B$2:$C$13,2,FALSE),0) -> 11.3 | AC24: =+Y24*AB24*R24 -> 0 | AD24: =+AC24-X24 -> 0 | AE24: =IFERROR(AD24/AC24,0) -> 0
C25: Day 5 | D25: Transfer | J25: Rovaniemi: Self transfer to Rovaniemi Bus Station | Q25: 0 | R25: 0 | S25: =+Q25*R25 -> 0 | T25: 0 | U25: =S25*(1-T25) -> 0 | V25: EUR | W25: =IFERROR(VLOOKUP(V25,[1]Curr!$B$2:$C$13,2,FALSE),0) -> 11.3 | X25: =U25*W25 -> 0 | Y25: =Q25 -> 0 | Z25: =+Y25*R25 -> 0 | AA25: EUR | AB25: =IFERROR(VLOOKUP(AA25,Curr!$B$2:$C$13,2,FALSE),0) -> 11.3 | AC25: =+Y25*AB25*R25 -> 0 | AD25: =+AC25-X25 -> 0 | AE25: =IFERROR(AD25/AC25,0) -> 0
C26: Day 5 | D26: Activity | J26: Rovaniemi: Arctic Route Coach Transfer to Tromsø - Time: 11:40 am - 7:30 pm - Includes: Tickets | O26: x | P26: https://bestarctic.com/the-arctic-route/arctic-winter-routes-explore-norway-sweden-and-finland/bus-between-tromso-norway-and-rovaniemi-finland/ | Q26: 1830 | R26: 2 | S26: =+Q26*R26 -> 3660 | T26: 0.2 | U26: =S26*(1-T26) -> 2928 | V26: NOK | W26: =IFERROR(VLOOKUP(V26,[1]Curr!$B$2:$C$13,2,FALSE),0) -> 1 | X26: =U26*W26 -> 2928 | Y26: =Q26/11.3/0.9 -> 179.941 | Z26: =+Y26*R26 -> 359.88201 | AA26: EUR | AB26: =IFERROR(VLOOKUP(AA26,Curr!$B$2:$C$13,2,FALSE),0) -> 11.3 | AC26: =+Y26*AB26*R26 -> 4066.6667 | AD26: =+AC26-X26 -> 1138.6667 | AE26: =IFERROR(AD26/AC26,0) -> 0.28
C27: Day 5 | D27: Transfer | J27: Tromsø: Self transfer to your accommodation | Q27: 0 | R27: 0 | S27: =+Q27*R27 -> 0 | T27: 0 | U27: =S27*(1-T27) -> 0 | V27: EUR | W27: =IFERROR(VLOOKUP(V27,[1]Curr!$B$2:$C$13,2,FALSE),0) -> 11.3 | X27: =U27*W27 -> 0 | Y27: =Q27 -> 0 | Z27: =+Y27*R27 -> 0 | AA27: EUR | AB27: =IFERROR(VLOOKUP(AA27,Curr!$B$2:$C$13,2,FALSE),0) -> 11.3 | AC27: =+Y27*AB27*R27 -> 0 | AD27: =+AC27-X27 -> 0 | AE27: =IFERROR(AD27/AC27,0) -> 0
C28: Day 5 | D28: Hotel | J28: Tromsø: Check in to your accommodation for a 2 night stay - Centrally Located 3/4-star Hotel - Standard Room - Breakfast included | Q28: 500 | R28: 1 | S28: =+Q28*R28 -> 500 | T28: 0 | U28: =S28*(1-T28) -> 500 | V28: EUR | W28: =IFERROR(VLOOKUP(V28,[1]Curr!$B$2:$C$13,2,FALSE),0) -> 11.3 | X28: =U28*W28 -> 5650 | Y28: =Q28/0.85 -> 588.23529 | Z28: =+Y28*R28 -> 588.23529 | AA28: EUR | AB28: =IFERROR(VLOOKUP(AA28,Curr!$B$2:$C$13,2,FALSE),0) -> 11.3 | AC28: =+Y28*AB28*R28 -> 6647.0588 | AD28: =+AC28-X28 -> 997.05882 | AE28: =IFERROR(AD28/AC28,0) -> 0.15
C29: Day 5 | D29: Leisure | J29: Tromsø: Spend time at leisure | Q29: 0 | R29: 0 | S29: =+Q29*R29 -> 0 | T29: 0 | U29: =S29*(1-T29) -> 0 | V29: EUR | W29: =IFERROR(VLOOKUP(V29,[1]Curr!$B$2:$C$13,2,FALSE),0) -> 11.3 | X29: =U29*W29 -> 0 | Y29: =Q29 -> 0 | Z29: =+Y29*R29 -> 0 | AA29: EUR | AB29: =IFERROR(VLOOKUP(AA29,Curr!$B$2:$C$13,2,FALSE),0) -> 11.3 | AC29: =+Y29*AB29*R29 -> 0 | AD29: =+AC29-X29 -> 0 | AE29: =IFERROR(AD29/AC29,0) -> 0
S30: =+Q30*R30 -> 0 | T30: 0 | U30: =S30*(1-T30) -> 0 | V30: EUR | W30: =IFERROR(VLOOKUP(V30,[1]Curr!$B$2:$C$13,2,FALSE),0) -> 11.3 | X30: =U30*W30 -> 0 | Y30: =Q30 -> 0 | Z30: =+Y30*R30 -> 0 | AA30: EUR | AB30: =IFERROR(VLOOKUP(AA30,Curr!$B$2:$C$13,2,FALSE),0) -> 11.3 | AC30: =+Y30*AB30*R30 -> 0 | AD30: =+AC30-X30 -> 0 | AE30: =IFERROR(AD30/AC30,0) -> 0
C31: Day 6 | D31: Activity | J31: Tromsø: Photo Tour to Arctic Landscapes and Fjords - Time: 10:00 am - 3:00 pm - Meeting point: Roald Amundsens plass 1A - Includes: Departure from central Tromsø. Drop-off to your hotel, Professional, English-speaking photo guides, Scenic fjord safari by comfortable minivan vehicle, Help with camera settings and nature photography, Usually a small-group experience with 4-8 guests, Soup or expedition food, coffee and waffles/cookies | O31: x | P31: https://booknordics.com/norway/northern-norway/tromso-region/tromso-fjord-photo-tour | Q31: 145 | R31: 2 | S31: =+Q31*R31 -> 290 | T31: 0.2 | U31: =S31*(1-T31) -> 232 | V31: EUR | W31: =IFERROR(VLOOKUP(V31,[1]Curr!$B$2:$C$13,2,FALSE),0) -> 11.3 | X31: =U31*W31 -> 2621.6 | Y31: =Q31 -> 145 | Z31: =+Y31*R31 -> 290 | AA31: EUR | AB31: =IFERROR(VLOOKUP(AA31,Curr!$B$2:$C$13,2,FALSE),0) -> 11.3 | AC31: =+Y31*AB31*R31 -> 3277 | AD31: =+AC31-X31 -> 655.4 | AE31: =IFERROR(AD31/AC31,0) -> 0.2
C32: Day 6 | D32: Leisure | J32: Tromsø: Spend time at leisure | Q32: 0 | R32: 0 | S32: =+Q32*R32 -> 0 | T32: 0 | U32: =S32*(1-T32) -> 0 | V32: EUR | W32: =IFERROR(VLOOKUP(V32,[1]Curr!$B$2:$C$13,2,FALSE),0) -> 11.3 | X32: =U32*W32 -> 0 | Y32: =Q32 -> 0 | Z32: =+Y32*R32 -> 0 | AA32: EUR | AB32: =IFERROR(VLOOKUP(AA32,Curr!$B$2:$C$13,2,FALSE),0) -> 11.3 | AC32: =+Y32*AB32*R32 -> 0 | AD32: =+AC32-X32 -> 0 | AE32: =IFERROR(AD32/AC32,0) -> 0
C33: Day 6 | D33: Activity | J33: Tromsø: Northern Lights Cruise with Silent Electric Ship - Time: 7:00 pm - 10:00 pm - Meeting point: Kaigata 6 - Includes: Departure from central Tromsø, 3-hour fjord cruise, Light meal (soup and bread) and water, English speaking guides, Warm indoor saloons, Free wifi, Toilets | O33: x | P33: https://booknordics.com/norway/northern-norway/tromso-region/northern-lights-cruise-electric-ship | Q33: 105 | R33: 2 | S33: =+Q33*R33 -> 210 | T33: 0.2 | U33: =S33*(1-T33) -> 168 | V33: EUR | W33: =IFERROR(VLOOKUP(V33,[1]Curr!$B$2:$C$13,2,FALSE),0) -> 11.3 | X33: =U33*W33 -> 1898.4 | Y33: =Q33 -> 105 | Z33: =+Y33*R33 -> 210 | AA33: EUR | AB33: =IFERROR(VLOOKUP(AA33,Curr!$B$2:$C$13,2,FALSE),0) -> 11.3 | AC33: =+Y33*AB33*R33 -> 2373 | AD33: =+AC33-X33 -> 474.6 | AE33: =IFERROR(AD33/AC33,0) -> 0.2
S34: =+Q34*R34 -> 0 | T34: 0 | U34: =S34*(1-T34) -> 0 | V34: EUR | W34: =IFERROR(VLOOKUP(V34,[1]Curr!$B$2:$C$13,2,FALSE),0) -> 11.3 | X34: =U34*W34 -> 0 | Y34: =Q34 -> 0 | Z34: =+Y34*R34 -> 0 | AA34: EUR | AB34: =IFERROR(VLOOKUP(AA34,Curr!$B$2:$C$13,2,FALSE),0) -> 11.3 | AC34: =+Y34*AB34*R34 -> 0 | AD34: =+AC34-X34 -> 0 | AE34: =IFERROR(AD34/AC34,0) -> 0
C35: Day 7 | D35: Transfer | J35: Tromsø: Self transfer to Tromsø Airport | Q35: 0 | R35: 0 | S35: =+Q35*R35 -> 0 | T35: 0 | U35: =S35*(1-T35) -> 0 | V35: EUR | W35: =IFERROR(VLOOKUP(V35,[1]Curr!$B$2:$C$13,2,FALSE),0) -> 11.3 | X35: =U35*W35 -> 0 | Y35: =Q35 -> 0 | Z35: =+Y35*R35 -> 0 | AA35: EUR | AB35: =IFERROR(VLOOKUP(AA35,Curr!$B$2:$C$13,2,FALSE),0) -> 11.3 | AC35: =+Y35*AB35*R35 -> 0 | AD35: =+AC35-X35 -> 0 | AE35: =IFERROR(AD35/AC35,0) -> 0
C36: Day 7 | D36: Departure | J36: Tromsø: Departure home | Q36: 0 | R36: 0 | S36: =+Q36*R36 -> 0 | T36: 0 | U36: =S36*(1-T36) -> 0 | V36: EUR | W36: =IFERROR(VLOOKUP(V36,[1]Curr!$B$2:$C$13,2,FALSE),0) -> 11.3 | X36: =U36*W36 -> 0 | Y36: =Q36 -> 0 | Z36: =+Y36*R36 -> 0 | AA36: EUR | AB36: =IFERROR(VLOOKUP(AA36,Curr!$B$2:$C$13,2,FALSE),0) -> 11.3 | AC36: =+Y36*AB36*R36 -> 0 | AD36: =+AC36-X36 -> 0 | AE36: =IFERROR(AD36/AC36,0) -> 0
S37: =+Q37*R37 -> 0 | T37: 0 | U37: =S37*(1-T37) -> 0 | V37: EUR | W37: =IFERROR(VLOOKUP(V37,[1]Curr!$B$2:$C$13,2,FALSE),0) -> 11.3 | X37: =U37*W37 -> 0 | Y37: =Q37 -> 0 | Z37: =+Y37*R37 -> 0 | AA37: EUR | AB37: =IFERROR(VLOOKUP(AA37,Curr!$B$2:$C$13,2,FALSE),0) -> 11.3 | AC37: =+Y37*AB37*R37 -> 0 | AD37: =+AC37-X37 -> 0 | AE37: =IFERROR(AD37/AC37,0) -> 0
S38: =+Q38*R38 -> 0 | T38: 0 | U38: =S38*(1-T38) -> 0 | V38: EUR | W38: =IFERROR(VLOOKUP(V38,[1]Curr!$B$2:$C$13,2,FALSE),0) -> 11.3 | X38: =U38*W38 -> 0 | Y38: =Q38 -> 0 | Z38: =+Y38*R38 -> 0 | AA38: EUR | AB38: =IFERROR(VLOOKUP(AA38,Curr!$B$2:$C$13,2,FALSE),0) -> 11.3 | AC38: =+Y38*AB38*R38 -> 0 | AD38: =+AC38-X38 -> 0 | AE38: =IFERROR(AD38/AC38,0) -> 0
C39: Day 1 | D39: Transfer package | J39: Helsinki: Private transfer to your accommodation | Q39: 80 | R39: 0 | S39: =+Q39*R39 -> 0 | T39: 0 | U39: =S39*(1-T39) -> 0 | V39: EUR | W39: =IFERROR(VLOOKUP(V39,[1]Curr!$B$2:$C$13,2,FALSE),0) -> 11.3 | X39: =U39*W39 -> 0 | Y39: =Q39/0.8 -> 100 | Z39: =+Y39*R39 -> 0 | AA39: EUR | AB39: =IFERROR(VLOOKUP(AA39,Curr!$B$2:$C$13,2,FALSE),0) -> 11.3 | AC39: =+Y39*AB39*R39 -> 0 | AD39: =+AC39-X39 -> 0 | AE39: =IFERROR(AD39/AC39,0) -> 0
C40: Day 2 | D40: Transfer package | J40: Helsinki: Private transfer to Helsinki Central Station | Q40: 80 | R40: 0 | S40: =+Q40*R40 -> 0 | T40: 0 | U40: =S40*(1-T40) -> 0 | V40: EUR | W40: =IFERROR(VLOOKUP(V40,[1]Curr!$B$2:$C$13,2,FALSE),0) -> 11.3 | X40: =U40*W40 -> 0 | Y40: =Q40/0.8 -> 100 | Z40: =+Y40*R40 -> 0 | AA40: EUR | AB40: =IFERROR(VLOOKUP(AA40,Curr!$B$2:$C$13,2,FALSE),0) -> 11.3 | AC40: =+Y40*AB40*R40 -> 0 | AD40: =+AC40-X40 -> 0 | AE40: =IFERROR(AD40/AC40,0) -> 0
C41: Day 3 | D41: Transfer package | J41: Rovaniemi: Private transfer to your accommodation | Q41: 40 | R41: 0 | S41: =+Q41*R41 -> 0 | T41: 0 | U41: =S41*(1-T41) -> 0 | V41: EUR | W41: =IFERROR(VLOOKUP(V41,[1]Curr!$B$2:$C$13,2,FALSE),0) -> 11.3 | X41: =U41*W41 -> 0 | Y41: =Q41/0.67 -> 59.701493 | Z41: =+Y41*R41 -> 0 | AA41: EUR | AB41: =IFERROR(VLOOKUP(AA41,Curr!$B$2:$C$13,2,FALSE),0) -> 11.3 | AC41: =+Y41*AB41*R41 -> 0 | AD41: =+AC41-X41 -> 0 | AE41: =IFERROR(AD41/AC41,0) -> 0
...

Sheet 1203
B1: Places: 1N Helsinki - 1N Santa Express - 2N Rovaniemi - 2N Tromsø - 1N Tromsø Igloo
B2: Dates: Winter
B3: Pax: 2
B4: Rooming: Double
B6: ID | C6: Day | D6: Type | E6: From date | F6: To date | G6: From time | H6: To time | I6: Supplier | J6: Travel element | K6: Manual booking? | L6: Status | M6: Comments | N6: Non-refundable | O6: Refundable | P6: URL | Q6: Gross P per unit | R6: Units | S6: Gross P | T6: Supp Comm | U6: Net P | V6: Supp curr | W6: X-rate | X6: Net P NOK | Y6: Sales P per unit | Z6: Price | AA6: Sales curr | AB6: X-rate | AC6: Sales P NOK tot | AD6: GP NOK | AE6: GP % | AF6: VAT25 | AG6: VAT15 | AH6: VAT12 | AI6: VAT0-D | AJ6: VAT0-I
C7: Day 1 | D7: Arrival | J7: Helsinki: Welcome to Finland | Q7: 0 | R7: 0 | S7: =+Q7*R7 -> 0 | T7: 0 | U7: =S7*(1-T7) -> 0 | V7: EUR | W7: =IFERROR(VLOOKUP(V7,[1]Curr!$B$2:$C$13,2,FALSE),0) -> 11.3 | X7: =U7*W7 -> 0 | Y7: =Q7 -> 0 | Z7: =+Y7*R7 -> 0 | AA7: EUR | AB7: =IFERROR(VLOOKUP(AA7,Curr!$B$2:$C$13,2,FALSE),0) -> 11.3 | AC7: =+Y7*AB7*R7 -> 0 | AD7: =+AC7-X7 -> 0 | AE7: =IFERROR(AD7/AC7,0) -> 0
C8: Day 1 | D8: Transfer | J8: Helsinki: Self transfer to your accommodation | Q8: 0 | R8: 0 | S8: =+Q8*R8 -> 0 | T8: 0 | U8: =S8*(1-T8) -> 0 | V8: EUR | W8: =IFERROR(VLOOKUP(V8,[1]Curr!$B$2:$C$13,2,FALSE),0) -> 11.3 | X8: =U8*W8 -> 0 | Y8: =Q8/0.8 -> 0 | Z8: =+Y8*R8 -> 0 | AA8: EUR | AB8: =IFERROR(VLOOKUP(AA8,Curr!$B$2:$C$13,2,FALSE),0) -> 11.3 | AC8: =+Y8*AB8*R8 -> 0 | AD8: =+AC8-X8 -> 0 | AE8: =IFERROR(AD8/AC8,0) -> 0
C9: Day 1 | D9: Hotel | J9: Helsinki: Check in to your accommodation for a 1 night stay - Centrally Located 3/4-star Hotel - Standard Room - Breakfast included | Q9: 150 | R9: 1 | S9: =+Q9*R9 -> 150 | T9: 0 | U9: =S9*(1-T9) -> 150 | V9: EUR | W9: =IFERROR(VLOOKUP(V9,[1]Curr!$B$2:$C$13,2,FALSE),0) -> 11.3 | X9: =U9*W9 -> 1695 | Y9: =Q9/0.85 -> 176.47059 | Z9: =+Y9*R9 -> 176.47059 | AA9: EUR | AB9: =IFERROR(VLOOKUP(AA9,Curr!$B$2:$C$13,2,FALSE),0) -> 11.3 | AC9: =+Y9*AB9*R9 -> 1994.1176 | AD9: =+AC9-X9 -> 299.11765 | AE9: =IFERROR(AD9/AC9,0) -> 0.15
C10: Day 1 | D10: Leisure | J10: Helsinki: Spend time at leisure | Q10: 0 | R10: 0 | S10: =+Q10*R10 -> 0 | T10: 0 | U10: =S10*(1-T10) -> 0 | V10: EUR | W10: =IFERROR(VLOOKUP(V10,[1]Curr!$B$2:$C$13,2,FALSE),0) -> 11.3 | X10: =U10*W10 -> 0 | Y10: =Q10 -> 0 | Z10: =+Y10*R10 -> 0 | AA10: EUR | AB10: =IFERROR(VLOOKUP(AA10,Curr!$B$2:$C$13,2,FALSE),0) -> 11.3 | AC10: =+Y10*AB10*R10 -> 0 | AD10: =+AC10-X10 -> 0 | AE10: =IFERROR(AD10/AC10,0) -> 0
S11: =+Q11*R11 -> 0 | T11: 0 | U11: =S11*(1-T11) -> 0 | V11: EUR | W11: =IFERROR(VLOOKUP(V11,[1]Curr!$B$2:$C$13,2,FALSE),0) -> 11.3 | X11: =U11*W11 -> 0 | Y11: =Q11 -> 0 | Z11: =+Y11*R11 -> 0 | AA11: EUR | AB11: =IFERROR(VLOOKUP(AA11,Curr!$B$2:$C$13,2,FALSE),0) -> 11.3 | AC11: =+Y11*AB11*R11 -> 0 | AD11: =+AC11-X11 -> 0 | AE11: =IFERROR(AD11/AC11,0) -> 0
C12: Day 2 | D12: Activity | J12: Helsinki: A Finntastic Walking Tour - Time: 10:30 am / 1:30 pm - 12:45 pm / 3:45 pm - Meeting point: Senate Square (Look for a blue and white umbrella) - End point: Helsinki Central Library Oodi - Notable Sights: Senate Square, Helsinki Cathedral, Kauppatori, Uspenski Cathedral, Esplanadi Park and more - Includes: Professional authorised Helsinki Guide, Liability Insurance | O12: x | P12: https://www.finntastictours.fi/# | Q12: 20 | R12: 2 | S12: =+Q12*R12 -> 40 | T12: 0 | U12: =S12*(1-T12) -> 40 | V12: EUR | W12: 11.3 | X12: =U12*W12 -> 452 | Y12: 35.087719 | Z12: =+Y12*R12 -> 70.175439 | AA12: EUR | AB12: =IFERROR(VLOOKUP(AA12,Curr!$B$2:$C$13,2,FALSE),0) -> 11.3 | AC12: =+Y12*AB12*R12 -> 792.98246 | AD12: =+AC12-X12 -> 340.98246 | AE12: =IFERROR(AD12/AC12,0) -> 0.43
C13: Day 2 | D13: Transfer | J13: Helsinki: Self transfer to Helsinki Central Station | Q13: 0 | R13: 0 | S13: =+Q13*R13 -> 0 | T13: 0 | U13: =S13*(1-T13) -> 0 | V13: EUR | W13: 11.3 | X13: =U13*W13 -> 0 | Y13: 0 | Z13: =+Y13*R13 -> 0 | AA13: EUR | AB13: =IFERROR(VLOOKUP(AA13,Curr!$B$2:$C$13,2,FALSE),0) -> 11.3 | AC13: =+Y13*AB13*R13 -> 0 | AD13: =+AC13-X13 -> 0 | AE13: =IFERROR(AD13/AC13,0) -> 0
C14: Day 2 | D14: Train | J14: Helsinki: Overnight Santa Claus Express Train to Rovaniemi - Time: 11:13 pm - 10:59 am - Includes: Upstairs Sleeper Cabin with Private Bathroom | N14: x | P14: https://www.vr.fi/en/santa-claus-express | Q14: 200 | R14: 1 | S14: =+Q14*R14 -> 200 | T14: 0 | U14: =S14*(1-T14) -> 200 | V14: EUR | W14: 11.3 | X14: =U14*W14 -> 2260 | Y14: =Q14/0.8 -> 250 | Z14: =+Y14*R14 -> 250 | AA14: EUR | AB14: =IFERROR(VLOOKUP(AA14,Curr!$B$2:$C$13,2,FALSE),0) -> 11.3 | AC14: =+Y14*AB14*R14 -> 2825 | AD14: =+AC14-X14 -> 565 | AE14: =IFERROR(AD14/AC14,0) -> 0.2
S15: =+Q15*R15 -> 0 | T15: 0 | U15: =S15*(1-T15) -> 0 | V15: EUR | W15: =IFERROR(VLOOKUP(V15,[1]Curr!$B$2:$C$13,2,FALSE),0) -> 11.3 | X15: =U15*W15 -> 0 | Y15: =Q15 -> 0 | Z15: =+Y15*R15 -> 0 | AA15: EUR | AB15: =IFERROR(VLOOKUP(AA15,Curr!$B$2:$C$13,2,FALSE),0) -> 11.3 | AC15: =+Y15*AB15*R15 -> 0 | AD15: =+AC15-X15 -> 0 | AE15: =IFERROR(AD15/AC15,0) -> 0
C16: Day 3 | D16: Transfer | J16: Rovaniemi: Self transfer to your accommodation | Q16: 0 | R16: 0 | S16: =+Q16*R16 -> 0 | T16: 0 | U16: =S16*(1-T16) -> 0 | V16: EUR | W16: =IFERROR(VLOOKUP(V16,[1]Curr!$B$2:$C$13,2,FALSE),0) -> 11.3 | X16: =U16*W16 -> 0 | Y16: =Q16/0.8 -> 0 | Z16: =+Y16*R16 -> 0 | AA16: EUR | AB16: =IFERROR(VLOOKUP(AA16,Curr!$B$2:$C$13,2,FALSE),0) -> 11.3 | AC16: =+Y16*AB16*R16 -> 0 | AD16: =+AC16-X16 -> 0 | AE16: =IFERROR(AD16/AC16,0) -> 0
C17: Day 3 | D17: Hotel | J17: Rovaniemi: Check in to your accommodation for a 2 night stay - Centrally Located 3/4-star Hotel - Standard Room - Breakfast included | Q17: 600 | R17: 1 | S17: =+Q17*R17 -> 600 | T17: 0 | U17: =S17*(1-T17) -> 600 | V17: EUR | W17: =IFERROR(VLOOKUP(V17,[1]Curr!$B$2:$C$13,2,FALSE),0) -> 11.3 | X17: =U17*W17 -> 6780 | Y17: =Q17/0.85 -> 705.88235 | Z17: =+Y17*R17 -> 705.88235 | AA17: EUR | AB17: =IFERROR(VLOOKUP(AA17,Curr!$B$2:$C$13,2,FALSE),0) -> 11.3 | AC17: =+Y17*AB17*R17 -> 7976.4706 | AD17: =+AC17-X17 -> 1196.4706 | AE17: =IFERROR(AD17/AC17,0) -> 0.15
C18: Day 3 | D18: Leisure | J18: Rovaniemi: Spend time at leisure | Q18: 0 | R18: 0 | S18: =+Q18*R18 -> 0 | T18: 0 | U18: =S18*(1-T18) -> 0 | V18: EUR | W18: =IFERROR(VLOOKUP(V18,[1]Curr!$B$2:$C$13,2,FALSE),0) -> 11.3 | X18: =U18*W18 -> 0 | Y18: =Q18 -> 0 | Z18: =+Y18*R18 -> 0 | AA18: EUR | AB18: =IFERROR(VLOOKUP(AA18,Curr!$B$2:$C$13,2,FALSE),0) -> 11.3 | AC18: =+Y18*AB18*R18 -> 0 | AD18: =+AC18-X18 -> 0 | AE18: =IFERROR(AD18/AC18,0) -> 0
C19: Day 3 | D19: Activity | J19: Rovaniemi: Northern Lights Unlimited Mileage Photo Tour - Time: 08:00 pm - 01:00 am - Meeting point: Book Lapland Office - Includes: Pick-up/drop-off in central Rovaniemi, Knowledgeable, English-speaking guides, Professional DSLR photography (unlimited), Meteorological observations, Thermal winter clothing, Hot drinks & snacks or cookies | O19: x | P19: https://booknordics.com/finland/western-lapland/rovaniemi/rovaniemi-northern-lights-family-tour-by-bus-with-photos | Q19: 109 | R19: 2 | S19: =+Q19*R19 -> 218 | T19: 0.2 | U19: =S19*(1-T19) -> 174.4 | V19: EUR | W19: =IFERROR(VLOOKUP(V19,[1]Curr!$B$2:$C$13,2,FALSE),0) -> 11.3 | X19: =U19*W19 -> 1970.72 | Y19: =Q19 -> 109 | Z19: =+Y19*R19 -> 218 | AA19: EUR | AB19: =IFERROR(VLOOKUP(AA19,Curr!$B$2:$C$13,2,FALSE),0) -> 11.3 | AC19: =+Y19*AB19*R19 -> 2463.4 | AD19: =+AC19-X19 -> 492.68 | AE19: =IFERROR(AD19/AC19,0) -> 0.2
S20: =+Q20*R20 -> 0 | T20: 0 | U20: =S20*(1-T20) -> 0 | V20: EUR | W20: =IFERROR(VLOOKUP(V20,[1]Curr!$B$2:$C$13,2,FALSE),0) -> 11.3 | X20: =U20*W20 -> 0 | Y20: =Q20 -> 0 | Z20: =+Y20*R20 -> 0 | AA20: EUR | AB20: =IFERROR(VLOOKUP(AA20,Curr!$B$2:$C$13,2,FALSE),0) -> 11.3 | AC20: =+Y20*AB20*R20 -> 0 | AD20: =+AC20-X20 -> 0 | AE20: =IFERROR(AD20/AC20,0) -> 0
C21: Day 4 | D21: Activity | J21: Rovaniemi: Arctic Circle Highlights Adventure Day - Time: 08:45 am - 2:45 pm - Meeting point: Arctic Circle Snowmobile Park office - Includes: Pick-up/drop-off in central Rovaniemi, Reindeer Farm visit with sleigh ride (2-3 pers), Reindeer sledge driver’s license reward, Alaskan Husky visit with sleigh ride (4 pers), Approx. 2 hours free time in Santa Claus Village, Winter clothes (overalls, boots and gloves), Traditional salmon soup or vegetarian option | O21: x | P21: https://booknordics.com/finland/western-lapland/rovaniemi/arctic-circle-highlights-family-day-by-minibus | Q21: 188 | R21: 2 | S21: =+Q21*R21 -> 376 | T21: 0.2 | U21: =S21*(1-T21) -> 300.8 | V21: EUR | W21: 11.3 | X21: =U21*W21 -> 3399.04 | Y21: 188 | Z21: =+Y21*R21 -> 376 | AA21: EUR | AB21: =IFERROR(VLOOKUP(AA21,Curr!$B$2:$C$13,2,FALSE),0) -> 11.3 | AC21: =+Y21*AB21*R21 -> 4248.8 | AD21: =+AC21-X21 -> 849.76 | AE21: =IFERROR(AD21/AC21,0) -> 0.2
C22: Day 4 | D22: Leisure | J22: Rovaniemi: Spend time at leisure | Q22: 0 | R22: 0 | S22: =+Q22*R22 -> 0 | T22: 0 | U22: =S22*(1-T22) -> 0 | V22: EUR | W22: 11.3 | X22: =U22*W22 -> 0 | Y22: 0 | Z22: =+Y22*R22 -> 0 | AA22: EUR | AB22: =IFERROR(VLOOKUP(AA22,Curr!$B$2:$C$13,2,FALSE),0) -> 11.3 | AC22: =+Y22*AB22*R22 -> 0 | AD22: =+AC22-X22 -> 0 | AE22: =IFERROR(AD22/AC22,0) -> 0
C23: Day 4 | D23: Activity | J23: Rovaniemi: Small-Group Aurora Hunt by Minibus - Time: 7:00 pm - 10:00 pm - Meeting point: Lapland Royal Adventures Office - Includes: Pick-up/drop-off from central Rovaniemi, Knowledgeable, English-speaking guide, Dedicated Northern Lights chase by minibus, Cozy blankets, hot drinks and a snack | O23: x | P23: https://booknordics.com/finland/western-lapland/rovaniemi/aurora-quest-by-minibus | Q23: 89 | R23: 2 | S23: =+Q23*R23 -> 178 | T23: 0.2 | U23: =S23*(1-T23) -> 142.4 | V23: EUR | W23: 11.3 | X23: =U23*W23 -> 1609.12 | Y23: 89 | Z23: =+Y23*R23 -> 178 | AA23: EUR | AB23: =IFERROR(VLOOKUP(AA23,Curr!$B$2:$C$13,2,FALSE),0) -> 11.3 | AC23: =+Y23*AB23*R23 -> 2011.4 | AD23: =+AC23-X23 -> 402.28 | AE23: =IFERROR(AD23/AC23,0) -> 0.2
S24: =+Q24*R24 -> 0 | T24: 0 | U24: =S24*(1-T24) -> 0 | V24: EUR | W24: =IFERROR(VLOOKUP(V24,[1]Curr!$B$2:$C$13,2,FALSE),0) -> 11.3 | X24: =U24*W24 -> 0 | Y24: =Q24 -> 0 | Z24: =+Y24*R24 -> 0 | AA24: EUR | AB24: =IFERROR(VLOOKUP(AA24,Curr!$B$2:$C$13,2,FALSE),0) -> 11.3 | AC24: =+Y24*AB24*R24 -> 0 | AD24: =+AC24-X24 -> 0 | AE24: =IFERROR(AD24/AC24,0) -> 0
C25: Day 5 | D25: Transfer | J25: Rovaniemi: Self transfer to Rovaniemi Bus Station | Q25: 0 | R25: 0 | S25: =+Q25*R25 -> 0 | T25: 0 | U25: =S25*(1-T25) -> 0 | V25: EUR | W25: =IFERROR(VLOOKUP(V25,[1]Curr!$B$2:$C$13,2,FALSE),0) -> 11.3 | X25: =U25*W25 -> 0 | Y25: =Q25 -> 0 | Z25: =+Y25*R25 -> 0 | AA25: EUR | AB25: =IFERROR(VLOOKUP(AA25,Curr!$B$2:$C$13,2,FALSE),0) -> 11.3 | AC25: =+Y25*AB25*R25 -> 0 | AD25: =+AC25-X25 -> 0 | AE25: =IFERROR(AD25/AC25,0) -> 0
C26: Day 5 | D26: Activity | J26: Rovaniemi: Arctic Route Coach Transfer to Tromsø - Time: 11:40 am - 7:30 pm - Includes: Tickets | O26: x | P26: https://bestarctic.com/the-arctic-route/arctic-winter-routes-explore-norway-sweden-and-finland/bus-between-tromso-norway-and-rovaniemi-finland/ | Q26: 1830 | R26: 2 | S26: =+Q26*R26 -> 3660 | T26: 0.2 | U26: =S26*(1-T26) -> 2928 | V26: NOK | W26: =IFERROR(VLOOKUP(V26,[1]Curr!$B$2:$C$13,2,FALSE),0) -> 1 | X26: =U26*W26 -> 2928 | Y26: =Q26/11.3/0.9 -> 179.941 | Z26: =+Y26*R26 -> 359.88201 | AA26: EUR | AB26: =IFERROR(VLOOKUP(AA26,Curr!$B$2:$C$13,2,FALSE),0) -> 11.3 | AC26: =+Y26*AB26*R26 -> 4066.6667 | AD26: =+AC26-X26 -> 1138.6667 | AE26: =IFERROR(AD26/AC26,0) -> 0.28
C27: Day 5 | D27: Transfer | J27: Tromsø: Self transfer to your accommodation | Q27: 0 | R27: 0 | S27: =+Q27*R27 -> 0 | T27: 0 | U27: =S27*(1-T27) -> 0 | V27: EUR | W27: =IFERROR(VLOOKUP(V27,[1]Curr!$B$2:$C$13,2,FALSE),0) -> 11.3 | X27: =U27*W27 -> 0 | Y27: =Q27 -> 0 | Z27: =+Y27*R27 -> 0 | AA27: EUR | AB27: =IFERROR(VLOOKUP(AA27,Curr!$B$2:$C$13,2,FALSE),0) -> 11.3 | AC27: =+Y27*AB27*R27 -> 0 | AD27: =+AC27-X27 -> 0 | AE27: =IFERROR(AD27/AC27,0) -> 0
C28: Day 5 | D28: Hotel | J28: Tromsø: Check in to your accommodation for a 2 night stay - Centrally Located 3/4-star Hotel - Standard Room - Breakfast included | Q28: 500 | R28: 1 | S28: =+Q28*R28 -> 500 | T28: 0 | U28: =S28*(1-T28) -> 500 | V28: EUR | W28: =IFERROR(VLOOKUP(V28,[1]Curr!$B$2:$C$13,2,FALSE),0) -> 11.3 | X28: =U28*W28 -> 5650 | Y28: =Q28/0.85 -> 588.23529 | Z28: =+Y28*R28 -> 588.23529 | AA28: EUR | AB28: =IFERROR(VLOOKUP(AA28,Curr!$B$2:$C$13,2,FALSE),0) -> 11.3 | AC28: =+Y28*AB28*R28 -> 6647.0588 | AD28: =+AC28-X28 -> 997.05882 | AE28: =IFERROR(AD28/AC28,0) -> 0.15
C29: Day 5 | D29: Leisure | J29: Tromsø: Spend time at leisure | Q29: 0 | R29: 0 | S29: =+Q29*R29 -> 0 | T29: 0 | U29: =S29*(1-T29) -> 0 | V29: EUR | W29: =IFERROR(VLOOKUP(V29,[1]Curr!$B$2:$C$13,2,FALSE),0) -> 11.3 | X29: =U29*W29 -> 0 | Y29: =Q29 -> 0 | Z29: =+Y29*R29 -> 0 | AA29: EUR | AB29: =IFERROR(VLOOKUP(AA29,Curr!$B$2:$C$13,2,FALSE),0) -> 11.3 | AC29: =+Y29*AB29*R29 -> 0 | AD29: =+AC29-X29 -> 0 | AE29: =IFERROR(AD29/AC29,0) -> 0
S30: =+Q30*R30 -> 0 | T30: 0 | U30: =S30*(1-T30) -> 0 | V30: EUR | W30: =IFERROR(VLOOKUP(V30,[1]Curr!$B$2:$C$13,2,FALSE),0) -> 11.3 | X30: =U30*W30 -> 0 | Y30: =Q30 -> 0 | Z30: =+Y30*R30 -> 0 | AA30: EUR | AB30: =IFERROR(VLOOKUP(AA30,Curr!$B$2:$C$13,2,FALSE),0) -> 11.3 | AC30: =+Y30*AB30*R30 -> 0 | AD30: =+AC30-X30 -> 0 | AE30: =IFERROR(AD30/AC30,0) -> 0
C31: Day 6 | D31: Activity | J31: Tromsø: Photo Tour to Arctic Landscapes and Fjords - Time: 10:00 am - 3:00 pm - Meeting point: Roald Amundsens plass 1A - Includes: Departure from central Tromsø. Drop-off to your hotel, Professional, English-speaking photo guides, Scenic fjord safari by comfortable minivan vehicle, Help with camera settings and nature photography, Usually a small-group experience with 4-8 guests, Soup or expedition food, coffee and waffles/cookies | O31: x | P31: https://booknordics.com/norway/northern-norway/tromso-region/tromso-fjord-photo-tour | Q31: 145 | R31: 2 | S31: =+Q31*R31 -> 290 | T31: 0.2 | U31: =S31*(1-T31) -> 232 | V31: EUR | W31: =IFERROR(VLOOKUP(V31,[1]Curr!$B$2:$C$13,2,FALSE),0) -> 11.3 | X31: =U31*W31 -> 2621.6 | Y31: =Q31 -> 145 | Z31: =+Y31*R31 -> 290 | AA31: EUR | AB31: =IFERROR(VLOOKUP(AA31,Curr!$B$2:$C$13,2,FALSE),0) -> 11.3 | AC31: =+Y31*AB31*R31 -> 3277 | AD31: =+AC31-X31 -> 655.4 | AE31: =IFERROR(AD31/AC31,0) -> 0.2
C32: Day 6 | D32: Leisure | J32: Tromsø: Spend time at leisure | Q32: 0 | R32: 0 | S32: =+Q32*R32 -> 0 | T32: 0 | U32: =S32*(1-T32) -> 0 | V32: EUR | W32: =IFERROR(VLOOKUP(V32,[1]Curr!$B$2:$C$13,2,FALSE),0) -> 11.3 | X32: =U32*W32 -> 0 | Y32: =Q32 -> 0 | Z32: =+Y32*R32 -> 0 | AA32: EUR | AB32: =IFERROR(VLOOKUP(AA32,Curr!$B$2:$C$13,2,FALSE),0) -> 11.3 | AC32: =+Y32*AB32*R32 -> 0 | AD32: =+AC32-X32 -> 0 | AE32: =IFERROR(AD32/AC32,0) -> 0
C33: Day 6 | D33: Activity | J33: Tromsø: Northern Lights Cruise with Silent Electric Ship - Time: 7:00 pm - 10:00 pm - Meeting point: Kaigata 6 - Includes: Departure from central Tromsø, 3-hour fjord cruise, Light meal (soup and bread) and water, English speaking guides, Warm indoor saloons, Free wifi, Toilets | O33: x | P33: https://booknordics.com/norway/northern-norway/tromso-region/northern-lights-cruise-electric-ship | Q33: 105 | R33: 2 | S33: =+Q33*R33 -> 210 | T33: 0.2 | U33: =S33*(1-T33) -> 168 | V33: EUR | W33: =IFERROR(VLOOKUP(V33,[1]Curr!$B$2:$C$13,2,FALSE),0) -> 11.3 | X33: =U33*W33 -> 1898.4 | Y33: =Q33 -> 105 | Z33: =+Y33*R33 -> 210 | AA33: EUR | AB33: =IFERROR(VLOOKUP(AA33,Curr!$B$2:$C$13,2,FALSE),0) -> 11.3 | AC33: =+Y33*AB33*R33 -> 2373 | AD33: =+AC33-X33 -> 474.6 | AE33: =IFERROR(AD33/AC33,0) -> 0.2
S34: =+Q34*R34 -> 0 | T34: 0 | U34: =S34*(1-T34) -> 0 | V34: EUR | W34: =IFERROR(VLOOKUP(V34,[1]Curr!$B$2:$C$13,2,FALSE),0) -> 11.3 | X34: =U34*W34 -> 0 | Y34: =Q34 -> 0 | Z34: =+Y34*R34 -> 0 | AA34: EUR | AB34: =IFERROR(VLOOKUP(AA34,Curr!$B$2:$C$13,2,FALSE),0) -> 11.3 | AC34: =+Y34*AB34*R34 -> 0 | AD34: =+AC34-X34 -> 0 | AE34: =IFERROR(AD34/AC34,0) -> 0
C35: Day 7 | D35: Transfer | J35: Tromsø: Self transfer to Steampier Adventure Hotel | Q35: 0 | R35: 0 | S35: =+Q35*R35 -> 0 | T35: 0 | U35: =S35*(1-T35) -> 0 | V35: EUR | W35: =IFERROR(VLOOKUP(V35,[1]Curr!$B$2:$C$13,2,FALSE),0) -> 11.3 | X35: =U35*W35 -> 0 | Y35: =Q35 -> 0 | Z35: =+Y35*R35 -> 0 | AA35: EUR | AB35: =IFERROR(VLOOKUP(AA35,Curr!$B$2:$C$13,2,FALSE),0) -> 11.3 | AC35: =+Y35*AB35*R35 -> 0 | AD35: =+AC35-X35 -> 0 | AE35: =IFERROR(AD35/AC35,0) -> 0
C36: Day 7 | D36: Hotel | J36: Steampier: Check in to your accommodation for a 1 night stay - Steampier Adventure Hotel - Aurora Hut - Brekfast included | P36: https://book.steampier.no/accommodation/room-details?channelid=f7a975e2-5254-4955-9e5d-9f61036705ac&roomid=08dd5be4-4d38-4cc8-0015-5d8b242d0000&roomconfig=a2&year=2026&month=2&day=3&staylength=1 | Q36: 3900 | R36: 1 | S36: =+Q36*R36 -> 3900 | T36: 0 | U36: =S36*(1-T36) -> 3900 | V36: NOK | W36: =IFERROR(VLOOKUP(V36,[1]Curr!$B$2:$C$13,2,FALSE),0) -> 1 | X36: =U36*W36 -> 3900 | Y36: =Q36/11.3/0.75 -> 460.17699 | Z36: =+Y36*R36 -> 460.17699 | AA36: EUR | AB36: =IFERROR(VLOOKUP(AA36,Curr!$B$2:$C$13,2,FALSE),0) -> 11.3 | AC36: =+Y36*AB36*R36 -> 5200 | AD36: =+AC36-X36 -> 1300 | AE36: =IFERROR(AD36/AC36,0) -> 0.25
C37: Day 7 | D37: Leisure | J37: Steampier: Spend time at leisure | Q37: 0 | R37: 0 | S37: =+Q37*R37 -> 0 | T37: 0 | U37: =S37*(1-T37) -> 0 | V37: EUR | W37: =IFERROR(VLOOKUP(V37,[1]Curr!$B$2:$C$13,2,FALSE),0) -> 11.3 | X37: =U37*W37 -> 0 | Y37: =Q37 -> 0 | Z37: =+Y37*R37 -> 0 | AA37: EUR | AB37: =IFERROR(VLOOKUP(AA37,Curr!$B$2:$C$13,2,FALSE),0) -> 11.3 | AC37: =+Y37*AB37*R37 -> 0 | AD37: =+AC37-X37 -> 0 | AE37: =IFERROR(AD37/AC37,0) -> 0
C38: Day 7 | D38: Activity | J38: Steampier: Northern Lights Minivan Tour - Time: 6:00 pm - Durration: 6 - 9 hrs - Meeting point: Steampier Reception - Includes: Professional guide & expert photographer, Comfortable minivan transport, Help setting up your camera/phone for your own photos, Hot drinks (coffee, tea, hot chocolate), Warm soup, Bonfire (when conditions allow), Low-resolution professional photos included, Thermal suits & winter boots for warmth | P38: https://book.steampier.no/extras?channelId=f7a975e2-5254-4955-9e5d-9f61036705ac | Q38: 2100 | R38: 2 | S38: =+Q38*R38 -> 4200 | T38: 0 | U38: =S38*(1-T38) -> 4200 | V38: NOK | W38: =IFERROR(VLOOKUP(V38,[1]Curr!$B$2:$C$13,2,FALSE),0) -> 1 | X38: =U38*W38 -> 4200 | Y38: =Q38/11.3/0.8 -> 232.30088 | Z38: =+Y38*R38 -> 464.60177 | AA38: EUR | AB38: =IFERROR(VLOOKUP(AA38,Curr!$B$2:$C$13,2,FALSE),0) -> 11.3 | AC38: =+Y38*AB38*R38 -> 5250 | AD38: =+AC38-X38 -> 1050 | AE38: =IFERROR(AD38/AC38,0) -> 0.2
S39: =+Q39*R39 -> 0 | T39: 0 | U39: =S39*(1-T39) -> 0 | V39: EUR | W39: =IFERROR(VLOOKUP(V39,[1]Curr!$B$2:$C$13,2,FALSE),0) -> 11.3 | X39: =U39*W39 -> 0 | Y39: =Q39 -> 0 | Z39: =+Y39*R39 -> 0 | AA39: EUR | AB39: =IFERROR(VLOOKUP(AA39,Curr!$B$2:$C$13,2,FALSE),0) -> 11.3 | AC39: =+Y39*AB39*R39 -> 0 | AD39: =+AC39-X39 -> 0 | AE39: =IFERROR(AD39/AC39,0) -> 0
C40: Day 8 | D40: Transfer | J40: Tromsø: Self transfer to Tromsø Airport | Q40: 0 | R40: 0 | S40: =+Q40*R40 -> 0 | T40: 0 | U40: =S40*(1-T40) -> 0 | V40: EUR | W40: =IFERROR(VLOOKUP(V40,[1]Curr!$B$2:$C$13,2,FALSE),0) -> 11.3 | X40: =U40*W40 -> 0 | Y40: =Q40 -> 0 | Z40: =+Y40*R40 -> 0 | AA40: EUR | AB40: =IFERROR(VLOOKUP(AA40,Curr!$B$2:$C$13,2,FALSE),0) -> 11.3 | AC40: =+Y40*AB40*R40 -> 0 | AD40: =+AC40-X40 -> 0 | AE40: =IFERROR(AD40/AC40,0) -> 0
C41: Day 8 | D41: Departure | J41: Tromsø: Departure home | Q41: 0 | R41: 0 | S41: =+Q41*R41 -> 0 | T41: 0 | U41: =S41*(1-T41) -> 0 | V41: EUR | W41: =IFERROR(VLOOKUP(V41,[1]Curr!$B$2:$C$13,2,FALSE),0) -> 11.3 | X41: =U41*W41 -> 0 | Y41: =Q41 -> 0 | Z41: =+Y41*R41 -> 0 | AA41: EUR | AB41: =IFERROR(VLOOKUP(AA41,Curr!$B$2:$C$13,2,FALSE),0) -> 11.3 | AC41: =+Y41*AB41*R41 -> 0 | AD41: =+AC41-X41 -> 0 | AE41: =IFERROR(AD41/AC41,0) -> 0
...

Sheet 1204
B1: Places: 3N Rovaniemi - 2N Tromsø - 1N Lyngen - 1N Tromsø
B2: Dates: Winter
B3: Pax: 2
B4: Rooming: Double
B6: ID | C6: Day | D6: Type | E6: From date | F6: To date | G6: From time | H6: To time | I6: Supplier | J6: Travel element | K6: Manual booking? | L6: Status | M6: Comments | N6: Non-refundable | O6: Refundable | P6: URL | Q6: Gross P per unit | R6: Units | S6: Gross P | T6: Supp Comm | U6: Net P | V6: Supp curr | W6: X-rate | X6: Net P NOK | Y6: Sales P per unit | Z6: Price | AA6: Sales curr | AB6: X-rate | AC6: Sales P NOK tot | AD6: GP NOK | AE6: GP % | AF6: VAT25 | AG6: VAT15 | AH6: VAT12 | AI6: VAT0-D | AJ6: VAT0-I
C7: Day 1 | D7: Arrival | J7: Rovaniemi: Welcome to Finland | Q7: 0 | R7: 0 | S7: =+Q7*R7 -> 0 | T7: 0 | U7: =S7*(1-T7) -> 0 | V7: EUR | W7: =IFERROR(VLOOKUP(V7,[1]Curr!$B$2:$C$13,2,FALSE),0) -> 11.3 | X7: =U7*W7 -> 0 | Y7: =Q7 -> 0 | Z7: =+Y7*R7 -> 0 | AA7: EUR | AB7: =IFERROR(VLOOKUP(AA7,Curr!$B$2:$C$13,2,FALSE),0) -> 11.3 | AC7: =+Y7*AB7*R7 -> 0 | AD7: =+AC7-X7 -> 0 | AE7: =IFERROR(AD7/AC7,0) -> 0
