Workbook

Sheet Curr
C1: NOK
B2: EUR | C2: 11
B3: SEK | C3: 1.02
B4: DKK | C4: 1.5
B5: ISK | C5: 0.075
B6: NOK | C6: 1
B7: USD | C7: 10.6

Sheet General
B2: Dates:
B3: Pax:
B4: Rooming:
B6: ID | C6: Day | D6: Type | E6: From date | F6: To date | G6: From time | H6: To time | I6: Supplier | J6: Travel element | K6: Manual booking? | L6: Status | M6: Comments | N6: Non-refundable | O6: Refundable | P6: URL | Q6: Gross P per unit | R6: Units | S6: Gross P | T6: Supp Comm | U6: Net P | V6: Supp curr | W6: X-rate | X6: Net P NOK | Y6: Sales P per unit | Z6: Price | AA6: Sales curr | AB6: X-rate2 | AC6: Sales P NOK tot | AD6: GP NOK | AE6: GP % | AF6: VAT25 | AG6: VAT15 | AH6: VAT12 | AI6: VAT0-D | AJ6: VAT0-I
B7: FI | D7: Arrival | J7: Helsinki: Welcome to Finland | Q7: 0 | R7: 0 | S7: =+Q7*R7 -> 0 | T7: 0 | U7: =S7*(1-T7) -> 0 | V7: EUR | W7: =IFERROR(VLOOKUP(V7,Curr!$B$2:$C$13,2,FALSE),0) -> 11 | X7: =U7*W7 -> 0 | Y7: =Q7 -> 0 | Z7: =+Y7*R7 -> 0 | AA7: EUR | AB7: =IFERROR(VLOOKUP(AA7,Curr!$B$2:$C$13,2,FALSE),0) -> 11 | AC7: =+Y7*AB7*R7 -> 0 | AD7: =+AC7-X7 -> 0 | AE7: =IFERROR(AD7/AC7,0) -> 0
B8: FI | D8: Departure | J8: Helsinki: Departure home | Q8: 0 | R8: 0 | S8: =+Q8*R8 -> 0 | T8: 0 | U8: =S8*(1-T8) -> 0 | V8: EUR | W8: =IFERROR(VLOOKUP(V8,Curr!$B$2:$C$13,2,FALSE),0) -> 11 | X8: =U8*W8 -> 0 | Y8: =Q8 -> 0 | Z8: =+Y8*R8 -> 0 | AA8: EUR | AB8: =IFERROR(VLOOKUP(AA8,Curr!$B$2:$C$13,2,FALSE),0) -> 11 | AC8: =+Y8*AB8*R8 -> 0 | AD8: =+AC8-X8 -> 0 | AE8: =IFERROR(AD8/AC8,0) -> 0
B9: FI | D9: Leisure | J9: Helsinki: Spend time at leisure | Q9: 0 | R9: 0 | S9: =+Q9*R9 -> 0 | T9: 0 | U9: =S9*(1-T9) -> 0 | V9: EUR | W9: =IFERROR(VLOOKUP(V9,Curr!$B$2:$C$13,2,FALSE),0) -> 11 | X9: =U9*W9 -> 0 | Y9: =Q9 -> 0 | Z9: =+Y9*R9 -> 0 | AA9: EUR | AB9: =IFERROR(VLOOKUP(AA9,Curr!$B$2:$C$13,2,FALSE),0) -> 11 | AC9: =+Y9*AB9*R9 -> 0 | AD9: =+AC9-X9 -> 0 | AE9: =IFERROR(AD9/AC9,0) -> 0
B10: FI | D10: Arrival | J10: Rovaniemi: Welcome to Finland | Q10: 0 | R10: 0 | S10: =+Q10*R10 -> 0 | T10: 0 | U10: =S10*(1-T10) -> 0 | V10: EUR | W10: =IFERROR(VLOOKUP(V10,Curr!$B$2:$C$13,2,FALSE),0) -> 11 | X10: =U10*W10 -> 0 | Y10: =Q10 -> 0 | Z10: =+Y10*R10 -> 0 | AA10: EUR | AB10: =IFERROR(VLOOKUP(AA10,Curr!$B$2:$C$13,2,FALSE),0) -> 11 | AC10: =+Y10*AB10*R10 -> 0 | AD10: =+AC10-X10 -> 0 | AE10: =IFERROR(AD10/AC10,0) -> 0
B11: FI | D11: Departure | J11: Rovaniemi: Departure home | Q11: 0 | R11: 0 | S11: =+Q11*R11 -> 0 | T11: 0 | U11: =S11*(1-T11) -> 0 | V11: EUR | W11: =IFERROR(VLOOKUP(V11,Curr!$B$2:$C$13,2,FALSE),0) -> 11 | X11: =U11*W11 -> 0 | Y11: =Q11 -> 0 | Z11: =+Y11*R11 -> 0 | AA11: EUR | AB11: =IFERROR(VLOOKUP(AA11,Curr!$B$2:$C$13,2,FALSE),0) -> 11 | AC11: =+Y11*AB11*R11 -> 0 | AD11: =+AC11-X11 -> 0 | AE11: =IFERROR(AD11/AC11,0) -> 0
B12: FI | D12: Leisure | J12: Rovaniemi: Spend time at leisure | Q12: 0 | R12: 0 | S12: =+Q12*R12 -> 0 | T12: 0 | U12: =S12*(1-T12) -> 0 | V12: EUR | W12: =IFERROR(VLOOKUP(V12,Curr!$B$2:$C$13,2,FALSE),0) -> 11 | X12: =U12*W12 -> 0 | Y12: =Q12 -> 0 | Z12: =+Y12*R12 -> 0 | AA12: EUR | AB12: =IFERROR(VLOOKUP(AA12,Curr!$B$2:$C$13,2,FALSE),0) -> 11 | AC12: =+Y12*AB12*R12 -> 0 | AD12: =+AC12-X12 -> 0 | AE12: =IFERROR(AD12/AC12,0) -> 0
B13: FI | D13: Arrival | J13: Turku: Welcome to Finland | Q13: 0 | R13: 0 | S13: =+Q13*R13 -> 0 | T13: 0 | U13: =S13*(1-T13) -> 0 | V13: EUR | W13: =IFERROR(VLOOKUP(V13,Curr!$B$2:$C$13,2,FALSE),0) -> 11 | X13: =U13*W13 -> 0 | Y13: =Q13 -> 0 | Z13: =+Y13*R13 -> 0 | AA13: EUR | AB13: =IFERROR(VLOOKUP(AA13,Curr!$B$2:$C$13,2,FALSE),0) -> 11 | AC13: =+Y13*AB13*R13 -> 0 | AD13: =+AC13-X13 -> 0 | AE13: =IFERROR(AD13/AC13,0) -> 0
B14: FI | D14: Departure | J14: Turku: Departure home | Q14: 0 | R14: 0 | S14: =+Q14*R14 -> 0 | T14: 0 | U14: =S14*(1-T14) -> 0 | V14: EUR | W14: =IFERROR(VLOOKUP(V14,Curr!$B$2:$C$13,2,FALSE),0) -> 11 | X14: =U14*W14 -> 0 | Y14: =Q14 -> 0 | Z14: =+Y14*R14 -> 0 | AA14: EUR | AB14: =IFERROR(VLOOKUP(AA14,Curr!$B$2:$C$13,2,FALSE),0) -> 11 | AC14: =+Y14*AB14*R14 -> 0 | AD14: =+AC14-X14 -> 0 | AE14: =IFERROR(AD14/AC14,0) -> 0
B15: FI | D15: Leisure | J15: Turku: Spend time at leisure | Q15: 0 | R15: 0 | S15: =+Q15*R15 -> 0 | T15: 0 | U15: =S15*(1-T15) -> 0 | V15: EUR | W15: =IFERROR(VLOOKUP(V15,Curr!$B$2:$C$13,2,FALSE),0) -> 11 | X15: =U15*W15 -> 0 | Y15: =Q15 -> 0 | Z15: =+Y15*R15 -> 0 | AA15: EUR | AB15: =IFERROR(VLOOKUP(AA15,Curr!$B$2:$C$13,2,FALSE),0) -> 11 | AC15: =+Y15*AB15*R15 -> 0 | AD15: =+AC15-X15 -> 0 | AE15: =IFERROR(AD15/AC15,0) -> 0
B16: FI | D16: Arrival | J16: Tampere: Welcome to Finland | Q16: 0 | R16: 0 | S16: =+Q16*R16 -> 0 | T16: 0 | U16: =S16*(1-T16) -> 0 | V16: EUR | W16: =IFERROR(VLOOKUP(V16,Curr!$B$2:$C$13,2,FALSE),0) -> 11 | X16: =U16*W16 -> 0 | Y16: =Q16 -> 0 | Z16: =+Y16*R16 -> 0 | AA16: EUR | AB16: =IFERROR(VLOOKUP(AA16,Curr!$B$2:$C$13,2,FALSE),0) -> 11 | AC16: =+Y16*AB16*R16 -> 0 | AD16: =+AC16-X16 -> 0 | AE16: =IFERROR(AD16/AC16,0) -> 0
B17: FI | D17: Departure | J17: Tampere: Departure home | Q17: 0 | R17: 0 | S17: =+Q17*R17 -> 0 | T17: 0 | U17: =S17*(1-T17) -> 0 | V17: EUR | W17: =IFERROR(VLOOKUP(V17,Curr!$B$2:$C$13,2,FALSE),0) -> 11 | X17: =U17*W17 -> 0 | Y17: =Q17 -> 0 | Z17: =+Y17*R17 -> 0 | AA17: EUR | AB17: =IFERROR(VLOOKUP(AA17,Curr!$B$2:$C$13,2,FALSE),0) -> 11 | AC17: =+Y17*AB17*R17 -> 0 | AD17: =+AC17-X17 -> 0 | AE17: =IFERROR(AD17/AC17,0) -> 0
B18: FI | D18: Leisure | J18: Tampere: Spend time at leisure | Q18: 0 | R18: 0 | S18: =+Q18*R18 -> 0 | T18: 0 | U18: =S18*(1-T18) -> 0 | V18: EUR | W18: =IFERROR(VLOOKUP(V18,Curr!$B$2:$C$13,2,FALSE),0) -> 11 | X18: =U18*W18 -> 0 | Y18: =Q18 -> 0 | Z18: =+Y18*R18 -> 0 | AA18: EUR | AB18: =IFERROR(VLOOKUP(AA18,Curr!$B$2:$C$13,2,FALSE),0) -> 11 | AC18: =+Y18*AB18*R18 -> 0 | AD18: =+AC18-X18 -> 0 | AE18: =IFERROR(AD18/AC18,0) -> 0
... B1254: DK | D1254: Leisure | J1254: Aakirkeby: Spend time at leisure | Q1254: 0 | R1254: 0 | S1254: =+Q1254*R1254 -> 0 | T1254: 0 | U1254: =S1254*(1-T1254) -> 0 | V1254: EUR | W1254: =IFERROR(VLOOKUP(V1254,Curr!$B$2:$C$13,2,FALSE),0) -> 11 | X1254: =U1254*W1254 -> 0 | Y1254: =Q1254 -> 0 | Z1254: =+Y1254*R1254 -> 0 | AA1254: EUR | AB1254: =IFERROR(VLOOKUP(AA1254,Curr!$B$2:$C$13,2,FALSE),0) -> 11 | AC1254: =+Y1254*AB1254*R1254 -> 0 | AD1254: =+AC1254-X1254 -> 0 | AE1254: =IFERROR(AD1254/AC1254,0) -> 0

Sheet Hotels
B2: Dates:
B3: Pax:
B4: Rooming:
B6: ID | C6: Day | D6: Type | E6: From date | F6: To date | G6: From time | H6: To time | I6: Supplier | J6: Travel element | K6: Manual booking? | L6: Status | M6: Comments | N6: Non-refundable | O6: Refundable | P6: URL | Q6: Gross P per unit | R6: Units | S6: Gross P | T6: Supp Comm | U6: Net P | V6: Supp curr | W6: X-rate | X6: Net P NOK | Y6: Sales P per unit | Z6: Price | AA6: Sales curr | AB6: X-rate2 | AC6: Sales P NOK tot | AD6: GP NOK | AE6: GP % | AF6: VAT25 | AG6: VAT15 | AH6: VAT12 | AI6: VAT0-D | AJ6: VAT0-I
B7: FI | D7: Hotel | J7: Helsinki: Check in to your accommodation for a X night stay - Hotel - Room - Bed - Breakfast included | Q7: 0 | R7: 0 | S7: =+Q7*R7 -> 0 | T7: 0 | U7: =S7*(1-T7) -> 0 | V7: EUR | W7: =IFERROR(VLOOKUP(V7,Curr!$B$2:$C$13,2,FALSE),0) -> 11 | X7: =U7*W7 -> 0 | Y7: =Q7/0.8 -> 0 | Z7: =+Y7*R7 -> 0 | AA7: EUR | AB7: =IFERROR(VLOOKUP(AA7,Curr!$B$2:$C$13,2,FALSE),0) -> 11 | AC7: =+Y7*AB7*R7 -> 0 | AD7: =+AC7-X7 -> 0 | AE7: =IFERROR(AD7/AC7,0) -> 0
B8: FI | D8: Hotel | J8: Helsinki: Check in to your accommodation for a X night stay - Hotel Arthur - Standard Room - Double/Twin Bed - Breakfast included | P8: https://www.ratehawk.com/hotel/finland/helsinki/mid7593355/hotel_arthur/?q=1443&dates=18.12.2026-19.12.2026&guests=1and14&meal_types=breakfast.halfBoard.fullBoard.allInclusive&payment=freecancellation&price=one&room=s-4c978903-d37c-5b78-8635-e8e17aeaccb6&serp_price=hotel_arthur.103.EUR.sr-019f85ad-99c9-75bd-97e1-20ea862313f2 | Q8: 110 | R8: 0 | S8: =+Q8*R8 -> 0 | T8: 0 | U8: =S8*(1-T8) -> 0 | V8: EUR | W8: =IFERROR(VLOOKUP(V8,Curr!$B$2:$C$13,2,FALSE),0) -> 11 | X8: =U8*W8 -> 0 | Y8: =Q8/0.8 -> 137.5 | Z8: =+Y8*R8 -> 0 | AA8: EUR | AB8: =IFERROR(VLOOKUP(AA8,Curr!$B$2:$C$13,2,FALSE),0) -> 11 | AC8: =+Y8*AB8*R8 -> 0 | AD8: =+AC8-X8 -> 0 | AE8: =IFERROR(AD8/AC8,0) -> 0
B9: FI | D9: Hotel | J9: Helsinki: Check in to your accommodation for a X night stay - Scandic Grand Marina Hotel - Standard Room - Double/Twin Bed - Breakfast included | P9: https://www.ratehawk.com/hotel/finland/helsinki/mid7594190/scandic_grand_marina/?dates=18.12.2026-19.12.2026&guests=1and14&meal_types=breakfast.halfBoard.fullBoard.allInclusive&payment=freecancellation&price=one&q=1443&room=s-ae0e9f27-be6c-50c5-a5fb-5c8d4489da01&serp_price=scandic_grand_marina.117.EUR.sr-019f85ad-9a17-74a4-af52-f491a6422915 | Q9: 130 | R9: 0 | S9: =+Q9*R9 -> 0 | T9: 0 | U9: =S9*(1-T9) -> 0 | V9: EUR | W9: =IFERROR(VLOOKUP(V9,Curr!$B$2:$C$13,2,FALSE),0) -> 11 | X9: =U9*W9 -> 0 | Y9: =Q9/0.8 -> 162.5 | Z9: =+Y9*R9 -> 0 | AA9: EUR | AB9: =IFERROR(VLOOKUP(AA9,Curr!$B$2:$C$13,2,FALSE),0) -> 11 | AC9: =+Y9*AB9*R9 -> 0 | AD9: =+AC9-X9 -> 0 | AE9: =IFERROR(AD9/AC9,0) -> 0
B10: FI | D10: Hotel | J10: Helsinki: Check in to your accommodation for a X night stay - Radisson Blu Royal - Standard Room - Double/Twin Bed - Breakfast included | P10: https://www.ratehawk.com/hotel/finland/helsinki/mid7593528/radisson_blu_royal_hotel_2/?q=1443&dates=18.12.2026-19.12.2026&guests=1and14&meal_types=breakfast.halfBoard.fullBoard.allInclusive&payment=freecancellation&price=one&room=s-6357a1f9-2246-5e2d-8197-57a7b4758b56&serp_price=radisson_blu_royal_hotel_2.127.EUR.sr-019f85ad-999d-737c-a93e-76852575a6d0 | Q10: 150 | R10: 0 | S10: =+Q10*R10 -> 0 | T10: 0 | U10: =S10*(1-T10) -> 0 | V10: EUR | W10: =IFERROR(VLOOKUP(V10,Curr!$B$2:$C$13,2,FALSE),0) -> 11 | X10: =U10*W10 -> 0 | Y10: =Q10/0.8 -> 187.5 | Z10: =+Y10*R10 -> 0 | AA10: EUR | AB10: =IFERROR(VLOOKUP(AA10,Curr!$B$2:$C$13,2,FALSE),0) -> 11 | AC10: =+Y10*AB10*R10 -> 0 | AD10: =+AC10-X10 -> 0 | AE10: =IFERROR(AD10/AC10,0) -> 0
B11: FI | D11: Hotel | J11: Helsinki: Check in to your accommodation for a X night stay - Lapland Hotels Bulevardi - Standard Room - Double/Twin Bed - Breakfast included | P11: https://www.ratehawk.com/hotel/finland/helsinki/mid8922586/lapland_hotels_bulevardi/?q=1443&dates=18.12.2026-19.12.2026&guests=1and14&meal_types=breakfast.halfBoard.fullBoard.allInclusive&payment=freecancellation&price=one&room=s-59505059-71d0-5e15-86cb-f22a7c7af008&serp_price=lapland_hotels_bulevardi.195.EUR.sr-019f85ad-95da-7247-993e-14193d9e981d&stars=5 | Q11: 220 | R11: 0 | S11: =+Q11*R11 -> 0 | T11: 0 | U11: =S11*(1-T11) -> 0 | V11: EUR | W11: =IFERROR(VLOOKUP(V11,Curr!$B$2:$C$13,2,FALSE),0) -> 11 | X11: =U11*W11 -> 0 | Y11: =Q11/0.8 -> 275 | Z11: =+Y11*R11 -> 0 | AA11: EUR | AB11: =IFERROR(VLOOKUP(AA11,Curr!$B$2:$C$13,2,FALSE),0) -> 11 | AC11: =+Y11*AB11*R11 -> 0 | AD11: =+AC11-X11 -> 0 | AE11: =IFERROR(AD11/AC11,0) -> 0
B12: FI | D12: Hotel | J12: Rovaniemi: Check in to your accommodation for a X night stay - Hotel - Room - Bed - Breakfast included | Q12: 0 | R12: 0 | S12: =+Q12*R12 -> 0 | T12: 0 | U12: =S12*(1-T12) -> 0 | V12: EUR | W12: =IFERROR(VLOOKUP(V12,Curr!$B$2:$C$13,2,FALSE),0) -> 11 | X12: =U12*W12 -> 0 | Y12: =Q12/0.8 -> 0 | Z12: =+Y12*R12 -> 0 | AA12: EUR | AB12: =IFERROR(VLOOKUP(AA12,Curr!$B$2:$C$13,2,FALSE),0) -> 11 | AC12: =+Y12*AB12*R12 -> 0 | AD12: =+AC12-X12 -> 0 | AE12: =IFERROR(AD12/AC12,0) -> 0
B13: FI | D13: Hotel | J13: Rovaniemi: Check in to your accommodation for a X night stay - Arctic City Hotel - Standard Room - Double/Twin Bed - Breakfast included | Q13: =166+166 -> 332 | R13: 0 | S13: =+Q13*R13 -> 0 | T13: 0 | U13: =S13*(1-T13) -> 0 | V13: EUR | W13: =IFERROR(VLOOKUP(V13,Curr!$B$2:$C$13,2,FALSE),0) -> 11 | X13: =U13*W13 -> 0 | Y13: =Q13/0.8 -> 415 | Z13: =+Y13*R13 -> 0 | AA13: EUR | AB13: =IFERROR(VLOOKUP(AA13,Curr!$B$2:$C$13,2,FALSE),0) -> 11 | AC13: =+Y13*AB13*R13 -> 0 | AD13: =+AC13-X13 -> 0 | AE13: =IFERROR(AD13/AC13,0) -> 0
B14: FI | D14: Hotel | J14: Rovaniemi: Check in to your accommodation for a X night stay - Arctic Light Hotel - Arctic Room -Double/Twin Bed - Breakfast included | Q14: =218+218 -> 436 | R14: 0 | S14: =+Q14*R14 -> 0 | T14: 0 | U14: =S14*(1-T14) -> 0 | V14: EUR | W14: =IFERROR(VLOOKUP(V14,Curr!$B$2:$C$13,2,FALSE),0) -> 11 | X14: =U14*W14 -> 0 | Y14: =Q14/0.8 -> 545 | Z14: =+Y14*R14 -> 0 | AA14: EUR | AB14: =IFERROR(VLOOKUP(AA14,Curr!$B$2:$C$13,2,FALSE),0) -> 11 | AC14: =+Y14*AB14*R14 -> 0 | AD14: =+AC14-X14 -> 0 | AE14: =IFERROR(AD14/AC14,0) -> 0
B15: FI | D15: Hotel | J15: Rovaniemi: Check in to your accommodation for a X night stay - Hotel - Room - Bed - Breakfast included | Q15: 0 | R15: 0 | S15: =+Q15*R15 -> 0 | T15: 0 | U15: =S15*(1-T15) -> 0 | V15: EUR | W15: =IFERROR(VLOOKUP(V15,Curr!$B$2:$C$13,2,FALSE),0) -> 11 | X15: =U15*W15 -> 0 | Y15: =Q15/0.8 -> 0 | Z15: =+Y15*R15 -> 0 | AA15: EUR | AB15: =IFERROR(VLOOKUP(AA15,Curr!$B$2:$C$13,2,FALSE),0) -> 11 | AC15: =+Y15*AB15*R15 -> 0 | AD15: =+AC15-X15 -> 0 | AE15: =IFERROR(AD15/AC15,0) -> 0
B16: FI | D16: Hotel | J16: Rovaniemi: Check in to your accommodation for a X night stay - Hotel - Room - Bed - Breakfast included | Q16: 0 | R16: 0 | S16: =+Q16*R16 -> 0 | T16: 0 | U16: =S16*(1-T16) -> 0 | V16: EUR | W16: =IFERROR(VLOOKUP(V16,Curr!$B$2:$C$13,2,FALSE),0) -> 11 | X16: =U16*W16 -> 0 | Y16: =Q16/0.8 -> 0 | Z16: =+Y16*R16 -> 0 | AA16: EUR | AB16: =IFERROR(VLOOKUP(AA16,Curr!$B$2:$C$13,2,FALSE),0) -> 11 | AC16: =+Y16*AB16*R16 -> 0 | AD16: =+AC16-X16 -> 0 | AE16: =IFERROR(AD16/AC16,0) -> 0
B17: FI | D17: Hotel | J17: Turku: Check in to your accommodation for a X night stay - Hotel - Room - Bed - Breakfast included | Q17: 0 | R17: 0 | S17: =+Q17*R17 -> 0 | T17: 0 | U17: =S17*(1-T17) -> 0 | V17: EUR | W17: =IFERROR(VLOOKUP(V17,Curr!$B$2:$C$13,2,FALSE),0) -> 11 | X17: =U17*W17 -> 0 | Y17: =Q17/0.8 -> 0 | Z17: =+Y17*R17 -> 0 | AA17: EUR | AB17: =IFERROR(VLOOKUP(AA17,Curr!$B$2:$C$13,2,FALSE),0) -> 11 | AC17: =+Y17*AB17*R17 -> 0 | AD17: =+AC17-X17 -> 0 | AE17: =IFERROR(AD17/AC17,0) -> 0
B18: FI | D18: Hotel | J18: Tampere: Check in to your accommodation for a X night stay - Hotel - Room - Bed - Breakfast included | Q18: 0 | R18: 0 | S18: =+Q18*R18 -> 0 | T18: 0 | U18: =S18*(1-T18) -> 0 | V18: EUR | W18: =IFERROR(VLOOKUP(V18,Curr!$B$2:$C$13,2,FALSE),0) -> 11 | X18: =U18*W18 -> 0 | Y18: =Q18/0.8 -> 0 | Z18: =+Y18*R18 -> 0 | AA18: EUR | AB18: =IFERROR(VLOOKUP(AA18,Curr!$B$2:$C$13,2,FALSE),0) -> 11 | AC18: =+Y18*AB18*R18 -> 0 | AD18: =+AC18-X18 -> 0 | AE18: =IFERROR(AD18/AC18,0) -> 0
B19: FI | D19: Hotel | J19: Porvoo: Check in to your accommodation for a X night stay - Hotel - Room - Bed - Breakfast included | Q19: 0 | R19: 0 | S19: =+Q19*R19 -> 0 | T19: 0 | U19: =S19*(1-T19) -> 0 | V19: EUR | W19: =IFERROR(VLOOKUP(V19,Curr!$B$2:$C$13,2,FALSE),0) -> 11 | X19: =U19*W19 -> 0 | Y19: =Q19/0.8 -> 0 | Z19: =+Y19*R19 -> 0 | AA19: EUR | AB19: =IFERROR(VLOOKUP(AA19,Curr!$B$2:$C$13,2,FALSE),0) -> 11 | AC19: =+Y19*AB19*R19 -> 0 | AD19: =+AC19-X19 -> 0 | AE19: =IFERROR(AD19/AC19,0) -> 0
B20: FI | D20: Hotel | J20: Savonlinna: Check in to your accommodation for a X night stay - Hotel - Room - Bed - Breakfast included | Q20: 0 | R20: 0 | S20: =+Q20*R20 -> 0 | T20: 0 | U20: =S20*(1-T20) -> 0 | V20: EUR | W20: =IFERROR(VLOOKUP(V20,Curr!$B$2:$C$13,2,FALSE),0) -> 11 | X20: =U20*W20 -> 0 | Y20: =Q20/0.8 -> 0 | Z20: =+Y20*R20 -> 0 | AA20: EUR | AB20: =IFERROR(VLOOKUP(AA20,Curr!$B$2:$C$13,2,FALSE),0) -> 11 | AC20: =+Y20*AB20*R20 -> 0 | AD20: =+AC20-X20 -> 0 | AE20: =IFERROR(AD20/AC20,0) -> 0
B21: FI | D21: Hotel | J21: Kuopio: Check in to your accommodation for a X night stay - Hotel - Room - Bed - Breakfast included | Q21: 0 | R21: 0 | S21: =+Q21*R21 -> 0 | T21: 0 | U21: =S21*(1-T21) -> 0 | V21: EUR | W21: =IFERROR(VLOOKUP(V21,Curr!$B$2:$C$13,2,FALSE),0) -> 11 | X21: =U21*W21 -> 0 | Y21: =Q21/0.8 -> 0 | Z21: =+Y21*R21 -> 0 | AA21: EUR | AB21: =IFERROR(VLOOKUP(AA21,Curr!$B$2:$C$13,2,FALSE),0) -> 11 | AC21: =+Y21*AB21*R21 -> 0 | AD21: =+AC21-X21 -> 0 | AE21: =IFERROR(AD21/AC21,0) -> 0
B22: FI | D22: Hotel | J22: Oulu: Check in to your accommodation for a X night stay - Hotel - Room - Bed - Breakfast included | Q22: 0 | R22: 0 | S22: =+Q22*R22 -> 0 | T22: 0 | U22: =S22*(1-T22) -> 0 | V22: EUR | W22: =IFERROR(VLOOKUP(V22,Curr!$B$2:$C$13,2,FALSE),0) -> 11 | X22: =U22*W22 -> 0 | Y22: =Q22/0.8 -> 0 | Z22: =+Y22*R22 -> 0 | AA22: EUR | AB22: =IFERROR(VLOOKUP(AA22,Curr!$B$2:$C$13,2,FALSE),0) -> 11 | AC22: =+Y22*AB22*R22 -> 0 | AD22: =+AC22-X22 -> 0 | AE22: =IFERROR(AD22/AC22,0) -> 0
B23: FI | D23: Hotel | J23: Jyväskylä: Check in to your accommodation for a X night stay - Hotel - Room - Bed - Breakfast included | Q23: 0 | R23: 0 | S23: =+Q23*R23 -> 0 | T23: 0 | U23: =S23*(1-T23) -> 0 | V23: EUR | W23: =IFERROR(VLOOKUP(V23,Curr!$B$2:$C$13,2,FALSE),0) -> 11 | X23: =U23*W23 -> 0 | Y23: =Q23/0.8 -> 0 | Z23: =+Y23*R23 -> 0 | AA23: EUR | AB23: =IFERROR(VLOOKUP(AA23,Curr!$B$2:$C$13,2,FALSE),0) -> 11 | AC23: =+Y23*AB23*R23 -> 0 | AD23: =+AC23-X23 -> 0 | AE23: =IFERROR(AD23/AC23,0) -> 0
B24: FI | D24: Hotel | J24: Vaasa: Check in to your accommodation for a X night stay - Hotel - Room - Bed - Breakfast included | Q24: 0 | R24: 0 | S24: =+Q24*R24 -> 0 | T24: 0 | U24: =S24*(1-T24) -> 0 | V24: EUR | W24: =IFERROR(VLOOKUP(V24,Curr!$B$2:$C$13,2,FALSE),0) -> 11 | X24: =U24*W24 -> 0 | Y24: =Q24/0.8 -> 0 | Z24: =+Y24*R24 -> 0 | AA24: EUR | AB24: =IFERROR(VLOOKUP(AA24,Curr!$B$2:$C$13,2,FALSE),0) -> 11 | AC24: =+Y24*AB24*R24 -> 0 | AD24: =+AC24-X24 -> 0 | AE24: =IFERROR(AD24/AC24,0) -> 0
B25: FI | D25: Hotel | J25: Mariehamn: Check in to your accommodation for a X night stay - Hotel - Room - Bed - Breakfast included | Q25: 0 | R25: 0 | S25: =+Q25*R25 -> 0 | T25: 0 | U25: =S25*(1-T25) -> 0 | V25: EUR | W25: =IFERROR(VLOOKUP(V25,Curr!$B$2:$C$13,2,FALSE),0) -> 11 | X25: =U25*W25 -> 0 | Y25: =Q25/0.8 -> 0 | Z25: =+Y25*R25 -> 0 | AA25: EUR | AB25: =IFERROR(VLOOKUP(AA25,Curr!$B$2:$C$13,2,FALSE),0) -> 11 | AC25: =+Y25*AB25*R25 -> 0 | AD25: =+AC25-X25 -> 0 | AE25: =IFERROR(AD25/AC25,0) -> 0
B26: FI | D26: Hotel | J26: Långnäs: Check in to your accommodation for a X night stay - Hotel - Room - Bed - Breakfast included | Q26: 0 | R26: 0 | S26: =+Q26*R26 -> 0 | T26: 0 | U26: =S26*(1-T26) -> 0 | V26: EUR | W26: =IFERROR(VLOOKUP(V26,Curr!$B$2:$C$13,2,FALSE),0) -> 11 | X26: =U26*W26 -> 0 | Y26: =Q26/0.8 -> 0 | Z26: =+Y26*R26 -> 0 | AA26: EUR | AB26: =IFERROR(VLOOKUP(AA26,Curr!$B$2:$C$13,2,FALSE),0) -> 11 | AC26: =+Y26*AB26*R26 -> 0 | AD26: =+AC26-X26 -> 0 | AE26: =IFERROR(AD26/AC26,0) -> 0
... B494: DK | D494: Hotel | J494: Aakirkeby: Check in to your accommodation for a X night stay - Hotel - Room - Bed - Breakfast included | Q494: 0 | R494: 0 | S494: =+Q494*R494 -> 0 | T494: 0 | U494: =S494*(1-T494) -> 0 | V494: EUR | W494: =IFERROR(VLOOKUP(V494,Curr!$B$2:$C$13,2,FALSE),0) -> 11 | X494: =U494*W494 -> 0 | Y494: =Q494/0.8 -> 0 | Z494: =+Y494*R494 -> 0 | AA494: EUR | AB494: =IFERROR(VLOOKUP(AA494,Curr!$B$2:$C$13,2,FALSE),0) -> 11 | AC494: =+Y494*AB494*R494 -> 0 | AD494: =+AC494-X494 -> 0 | AE494: =IFERROR(AD494/AC494,0) -> 0

Sheet Transfers
B2: Dates:
B3: Pax:
B4: Rooming:
B6: ID | C6: Day | D6: Type | E6: From date | F6: To date | G6: From time | H6: To time | I6: Supplier | J6: Travel element | K6: Manual booking? | L6: Status | M6: Comments | N6: Non-refundable | O6: Refundable | P6: URL | Q6: Gross P per unit | R6: Units | S6: Gross P | T6: Supp Comm | U6: Net P | V6: Supp curr | W6: X-rate | X6: Net P NOK | Y6: Sales P per unit | Z6: Price | AA6: Sales curr | AB6: X-rate2 | AC6: Sales P NOK tot | AD6: GP NOK | AE6: GP % | AF6: VAT25 | AG6: VAT15 | AH6: VAT12 | AI6: VAT0-D | AJ6: VAT0-I
B7: FI | D7: Transfer | J7: Helsinki: Self transfer to your accommodation | Q7: 0 | R7: 0 | S7: =+Q7*R7 -> 0 | T7: 0 | U7: =S7*(1-T7) -> 0 | V7: EUR | W7: =IFERROR(VLOOKUP(V7,Curr!$B$2:$C$13,2,FALSE),0) -> 11 | X7: =U7*W7 -> 0 | Y7: =Q7 -> 0 | Z7: =+Y7*R7 -> 0 | AA7: EUR | AB7: =IFERROR(VLOOKUP(AA7,Curr!$B$2:$C$13,2,FALSE),0) -> 11 | AC7: =+Y7*AB7*R7 -> 0 | AD7: =+AC7-X7 -> 0 | AE7: =IFERROR(AD7/AC7,0) -> 0
B8: FI | D8: Transfer | J8: Helsinki: Private transfer to your accommodation | Q8: 80 | R8: 1 | S8: =+Q8*R8 -> 80 | T8: 0 | U8: =S8*(1-T8) -> 80 | V8: EUR | W8: =IFERROR(VLOOKUP(V8,Curr!$B$2:$C$13,2,FALSE),0) -> 11 | X8: =U8*W8 -> 880 | Y8: =Q8/0.8 -> 100 | Z8: =+Y8*R8 -> 100 | AA8: EUR | AB8: =IFERROR(VLOOKUP(AA8,Curr!$B$2:$C$13,2,FALSE),0) -> 11 | AC8: =+Y8*AB8*R8 -> 1100 | AD8: =+AC8-X8 -> 220 | AE8: =IFERROR(AD8/AC8,0) -> 0.2
B9: FI | D9: Transfer | J9: Helsinki: Self transfer to Helsinki Airport | Q9: 0 | R9: 0 | S9: =+Q9*R9 -> 0 | T9: 0 | U9: =S9*(1-T9) -> 0 | V9: EUR | W9: =IFERROR(VLOOKUP(V9,Curr!$B$2:$C$13,2,FALSE),0) -> 11 | X9: =U9*W9 -> 0 | Y9: =Q9 -> 0 | Z9: =+Y9*R9 -> 0 | AA9: EUR | AB9: =IFERROR(VLOOKUP(AA9,Curr!$B$2:$C$13,2,FALSE),0) -> 11 | AC9: =+Y9*AB9*R9 -> 0 | AD9: =+AC9-X9 -> 0 | AE9: =IFERROR(AD9/AC9,0) -> 0
B10: FI | D10: Transfer | J10: Helsinki: Private transfer to Helsinki Airport | Q10: 80 | R10: 1 | S10: =+Q10*R10 -> 80 | T10: 0 | U10: =S10*(1-T10) -> 80 | V10: EUR | W10: =IFERROR(VLOOKUP(V10,Curr!$B$2:$C$13,2,FALSE),0) -> 11 | X10: =U10*W10 -> 880 | Y10: =Q10/0.8 -> 100 | Z10: =+Y10*R10 -> 100 | AA10: EUR | AB10: =IFERROR(VLOOKUP(AA10,Curr!$B$2:$C$13,2,FALSE),0) -> 11 | AC10: =+Y10*AB10*R10 -> 1100 | AD10: =+AC10-X10 -> 220 | AE10: =IFERROR(AD10/AC10,0) -> 0.2
B11: FI | D11: Transfer | J11: Helsinki: Self transfer to Helsinki Central Railway Station | Q11: 0 | R11: 0 | S11: =+Q11*R11 -> 0 | T11: 0 | U11: =S11*(1-T11) -> 0 | V11: EUR | W11: =IFERROR(VLOOKUP(V11,Curr!$B$2:$C$13,2,FALSE),0) -> 11 | X11: =U11*W11 -> 0 | Y11: =Q11 -> 0 | Z11: =+Y11*R11 -> 0 | AA11: EUR | AB11: =IFERROR(VLOOKUP(AA11,Curr!$B$2:$C$13,2,FALSE),0) -> 11 | AC11: =+Y11*AB11*R11 -> 0 | AD11: =+AC11-X11 -> 0 | AE11: =IFERROR(AD11/AC11,0) -> 0
B12: FI | D12: Transfer | J12: Helsinki: Private transfer to Helsinki Central Railway Station | Q12: 40 | R12: 1 | S12: =+Q12*R12 -> 40 | T12: 0 | U12: =S12*(1-T12) -> 40 | V12: EUR | W12: =IFERROR(VLOOKUP(V12,Curr!$B$2:$C$13,2,FALSE),0) -> 11 | X12: =U12*W12 -> 440 | Y12: =Q12/0.8 -> 50 | Z12: =+Y12*R12 -> 50 | AA12: EUR | AB12: =IFERROR(VLOOKUP(AA12,Curr!$B$2:$C$13,2,FALSE),0) -> 11 | AC12: =+Y12*AB12*R12 -> 550 | AD12: =+AC12-X12 -> 110 | AE12: =IFERROR(AD12/AC12,0) -> 0.2
B13: FI | D13: Transfer | J13: Helsinki: Self transfer to Kamppi Bus Station | Q13: 0 | R13: 0 | S13: =+Q13*R13 -> 0 | T13: 0 | U13: =S13*(1-T13) -> 0 | V13: EUR | W13: =IFERROR(VLOOKUP(V13,Curr!$B$2:$C$13,2,FALSE),0) -> 11 | X13: =U13*W13 -> 0 | Y13: =Q13 -> 0 | Z13: =+Y13*R13 -> 0 | AA13: EUR | AB13: =IFERROR(VLOOKUP(AA13,Curr!$B$2:$C$13,2,FALSE),0) -> 11 | AC13: =+Y13*AB13*R13 -> 0 | AD13: =+AC13-X13 -> 0 | AE13: =IFERROR(AD13/AC13,0) -> 0
B14: FI | D14: Transfer | J14: Helsinki: Private transfer to Kamppi Bus Station | Q14: 40 | R14: 1 | S14: =+Q14*R14 -> 40 | T14: 0 | U14: =S14*(1-T14) -> 40 | V14: EUR | W14: =IFERROR(VLOOKUP(V14,Curr!$B$2:$C$13,2,FALSE),0) -> 11 | X14: =U14*W14 -> 440 | Y14: =Q14/0.8 -> 50 | Z14: =+Y14*R14 -> 50 | AA14: EUR | AB14: =IFERROR(VLOOKUP(AA14,Curr!$B$2:$C$13,2,FALSE),0) -> 11 | AC14: =+Y14*AB14*R14 -> 550 | AD14: =+AC14-X14 -> 110 | AE14: =IFERROR(AD14/AC14,0) -> 0.2
B15: FI | D15: Transfer | J15: Helsinki: Self transfer to Helsinki ferry terminal | Q15: 0 | R15: 0 | S15: =+Q15*R15 -> 0 | T15: 0 | U15: =S15*(1-T15) -> 0 | V15: EUR | W15: =IFERROR(VLOOKUP(V15,Curr!$B$2:$C$13,2,FALSE),0) -> 11 | X15: =U15*W15 -> 0 | Y15: =Q15 -> 0 | Z15: =+Y15*R15 -> 0 | AA15: EUR | AB15: =IFERROR(VLOOKUP(AA15,Curr!$B$2:$C$13,2,FALSE),0) -> 11 | AC15: =+Y15*AB15*R15 -> 0 | AD15: =+AC15-X15 -> 0 | AE15: =IFERROR(AD15/AC15,0) -> 0
B16: FI | D16: Transfer | J16: Helsinki: Private transfer to Helsinki ferry terminal | Q16: 40 | R16: 1 | S16: =+Q16*R16 -> 40 | T16: 0 | U16: =S16*(1-T16) -> 40 | V16: EUR | W16: =IFERROR(VLOOKUP(V16,Curr!$B$2:$C$13,2,FALSE),0) -> 11 | X16: =U16*W16 -> 440 | Y16: =Q16/0.8 -> 50 | Z16: =+Y16*R16 -> 50 | AA16: EUR | AB16: =IFERROR(VLOOKUP(AA16,Curr!$B$2:$C$13,2,FALSE),0) -> 11 | AC16: =+Y16*AB16*R16 -> 550 | AD16: =+AC16-X16 -> 110 | AE16: =IFERROR(AD16/AC16,0) -> 0.2
B17: FI | D17: Transfer | J17: Helsinki: Self transfer to Helsinki cruise port | Q17: 0 | R17: 0 | S17: =+Q17*R17 -> 0 | T17: 0 | U17: =S17*(1-T17) -> 0 | V17: EUR | W17: =IFERROR(VLOOKUP(V17,Curr!$B$2:$C$13,2,FALSE),0) -> 11 | X17: =U17*W17 -> 0 | Y17: =Q17 -> 0 | Z17: =+Y17*R17 -> 0 | AA17: EUR | AB17: =IFERROR(VLOOKUP(AA17,Curr!$B$2:$C$13,2,FALSE),0) -> 11 | AC17: =+Y17*AB17*R17 -> 0 | AD17: =+AC17-X17 -> 0 | AE17: =IFERROR(AD17/AC17,0) -> 0
B18: FI | D18: Transfer | J18: Helsinki: Private transfer to Helsinki cruise port | Q18: 40 | R18: 1 | S18: =+Q18*R18 -> 40 | T18: 0 | U18: =S18*(1-T18) -> 40 | V18: EUR | W18: =IFERROR(VLOOKUP(V18,Curr!$B$2:$C$13,2,FALSE),0) -> 11 | X18: =U18*W18 -> 440 | Y18: =Q18/0.8 -> 50 | Z18: =+Y18*R18 -> 50 | AA18: EUR | AB18: =IFERROR(VLOOKUP(AA18,Curr!$B$2:$C$13,2,FALSE),0) -> 11 | AC18: =+Y18*AB18*R18 -> 550 | AD18: =+AC18-X18 -> 110 | AE18: =IFERROR(AD18/AC18,0) -> 0.2
B19: FI | D19: Transfer | J19: Rovaniemi: Self transfer to your accommodation | Q19: 0 | R19: 0 | S19: =+Q19*R19 -> 0 | T19: 0 | U19: =S19*(1-T19) -> 0 | V19: EUR | W19: =IFERROR(VLOOKUP(V19,Curr!$B$2:$C$13,2,FALSE),0) -> 11 | X19: =U19*W19 -> 0 | Y19: =Q19 -> 0 | Z19: =+Y19*R19 -> 0 | AA19: EUR | AB19: =IFERROR(VLOOKUP(AA19,Curr!$B$2:$C$13,2,FALSE),0) -> 11 | AC19: =+Y19*AB19*R19 -> 0 | AD19: =+AC19-X19 -> 0 | AE19: =IFERROR(AD19/AC19,0) -> 0
B20: FI | D20: Transfer | J20: Rovaniemi: Private transfer to your accommodation | Q20: 40 | R20: 1 | S20: =+Q20*R20 -> 40 | T20: 0 | U20: =S20*(1-T20) -> 40 | V20: EUR | W20: =IFERROR(VLOOKUP(V20,Curr!$B$2:$C$13,2,FALSE),0) -> 11 | X20: =U20*W20 -> 440 | Y20: =Q20/0.7 -> 57.142857 | Z20: =+Y20*R20 -> 57.142857 | AA20: EUR | AB20: =IFERROR(VLOOKUP(AA20,Curr!$B$2:$C$13,2,FALSE),0) -> 11 | AC20: =+Y20*AB20*R20 -> 628.57143 | AD20: =+AC20-X20 -> 188.57143 | AE20: =IFERROR(AD20/AC20,0) -> 0.3
B21: FI | D21: Transfer | J21: Rovaniemi: Self transfer to Rovaniemi Airport | Q21: 0 | R21: 0 | S21: =+Q21*R21 -> 0 | T21: 0 | U21: =S21*(1-T21) -> 0 | V21: EUR | W21: =IFERROR(VLOOKUP(V21,Curr!$B$2:$C$13,2,FALSE),0) -> 11 | X21: =U21*W21 -> 0 | Y21: =Q21 -> 0 | Z21: =+Y21*R21 -> 0 | AA21: EUR | AB21: =IFERROR(VLOOKUP(AA21,Curr!$B$2:$C$13,2,FALSE),0) -> 11 | AC21: =+Y21*AB21*R21 -> 0 | AD21: =+AC21-X21 -> 0 | AE21: =IFERROR(AD21/AC21,0) -> 0
B22: FI | D22: Transfer | J22: Rovaniemi: Private transfer to Rovaniemi Airport | Q22: 40 | R22: 1 | S22: =+Q22*R22 -> 40 | T22: 0 | U22: =S22*(1-T22) -> 40 | V22: EUR | W22: =IFERROR(VLOOKUP(V22,Curr!$B$2:$C$13,2,FALSE),0) -> 11 | X22: =U22*W22 -> 440 | Y22: =Q22/0.7 -> 57.142857 | Z22: =+Y22*R22 -> 57.142857 | AA22: EUR | AB22: =IFERROR(VLOOKUP(AA22,Curr!$B$2:$C$13,2,FALSE),0) -> 11 | AC22: =+Y22*AB22*R22 -> 628.57143 | AD22: =+AC22-X22 -> 188.57143 | AE22: =IFERROR(AD22/AC22,0) -> 0.3
B23: FI | D23: Transfer | J23: Rovaniemi: Self transfer to Rovaniemi railway station | Q23: 0 | R23: 0 | S23: =+Q23*R23 -> 0 | T23: 0 | U23: =S23*(1-T23) -> 0 | V23: EUR | W23: =IFERROR(VLOOKUP(V23,Curr!$B$2:$C$13,2,FALSE),0) -> 11 | X23: =U23*W23 -> 0 | Y23: =Q23 -> 0 | Z23: =+Y23*R23 -> 0 | AA23: EUR | AB23: =IFERROR(VLOOKUP(AA23,Curr!$B$2:$C$13,2,FALSE),0) -> 11 | AC23: =+Y23*AB23*R23 -> 0 | AD23: =+AC23-X23 -> 0 | AE23: =IFERROR(AD23/AC23,0) -> 0
B24: FI | D24: Transfer | J24: Rovaniemi: Private transfer to Rovaniemi railway station | Q24: 40 | R24: 1 | S24: =+Q24*R24 -> 40 | T24: 0 | U24: =S24*(1-T24) -> 40 | V24: EUR | W24: =IFERROR(VLOOKUP(V24,Curr!$B$2:$C$13,2,FALSE),0) -> 11 | X24: =U24*W24 -> 440 | Y24: =Q24/0.7 -> 57.142857 | Z24: =+Y24*R24 -> 57.142857 | AA24: EUR | AB24: =IFERROR(VLOOKUP(AA24,Curr!$B$2:$C$13,2,FALSE),0) -> 11 | AC24: =+Y24*AB24*R24 -> 628.57143 | AD24: =+AC24-X24 -> 188.57143 | AE24: =IFERROR(AD24/AC24,0) -> 0.3
B25: FI | D25: Transfer | J25: Rovaniemi: Self transfer to Rovaniemi Bus Station | Q25: 0 | R25: 0 | S25: =+Q25*R25 -> 0 | T25: 0 | U25: =S25*(1-T25) -> 0 | V25: EUR | W25: =IFERROR(VLOOKUP(V25,Curr!$B$2:$C$13,2,FALSE),0) -> 11 | X25: =U25*W25 -> 0 | Y25: =Q25 -> 0 | Z25: =+Y25*R25 -> 0 | AA25: EUR | AB25: =IFERROR(VLOOKUP(AA25,Curr!$B$2:$C$13,2,FALSE),0) -> 11 | AC25: =+Y25*AB25*R25 -> 0 | AD25: =+AC25-X25 -> 0 | AE25: =IFERROR(AD25/AC25,0) -> 0
B26: FI | D26: Transfer | J26: Rovaniemi: Private transfer to Rovaniemi Bus Station | Q26: 40 | R26: 1 | S26: =+Q26*R26 -> 40 | T26: 0 | U26: =S26*(1-T26) -> 40 | V26: EUR | W26: =IFERROR(VLOOKUP(V26,Curr!$B$2:$C$13,2,FALSE),0) -> 11 | X26: =U26*W26 -> 440 | Y26: =Q26/0.7 -> 57.142857 | Z26: =+Y26*R26 -> 57.142857 | AA26: EUR | AB26: =IFERROR(VLOOKUP(AA26,Curr!$B$2:$C$13,2,FALSE),0) -> 11 | AC26: =+Y26*AB26*R26 -> 628.57143 | AD26: =+AC26-X26 -> 188.57143 | AE26: =IFERROR(AD26/AC26,0) -> 0.3
B27: FI | D27: Transfer | J27: Turku: Self transfer to your accommodation | Q27: 0 | R27: 0 | S27: =+Q27*R27 -> 0 | T27: 0 | U27: =S27*(1-T27) -> 0 | V27: EUR | W27: =IFERROR(VLOOKUP(V27,Curr!$B$2:$C$13,2,FALSE),0) -> 11 | X27: =U27*W27 -> 0 | Y27: =Q27 -> 0 | Z27: =+Y27*R27 -> 0 | AA27: EUR | AB27: =IFERROR(VLOOKUP(AA27,Curr!$B$2:$C$13,2,FALSE),0) -> 11 | AC27: =+Y27*AB27*R27 -> 0 | AD27: =+AC27-X27 -> 0 | AE27: =IFERROR(AD27/AC27,0) -> 0
B28: FI | D28: Transfer | J28: Turku: Private transfer to your accommodation | Q28: 0 | R28: 0 | S28: =+Q28*R28 -> 0 | T28: 0 | U28: =S28*(1-T28) -> 0 | V28: EUR | W28: =IFERROR(VLOOKUP(V28,Curr!$B$2:$C$13,2,FALSE),0) -> 11 | X28: =U28*W28 -> 0 | Y28: =Q28 -> 0 | Z28: =+Y28*R28 -> 0 | AA28: EUR | AB28: =IFERROR(VLOOKUP(AA28,Curr!$B$2:$C$13,2,FALSE),0) -> 11 | AC28: =+Y28*AB28*R28 -> 0 | AD28: =+AC28-X28 -> 0 | AE28: =IFERROR(AD28/AC28,0) -> 0
B29: FI | D29: Transfer | J29: Turku: Self transfer to Turku Airport | Q29: 0 | R29: 0 | S29: =+Q29*R29 -> 0 | T29: 0 | U29: =S29*(1-T29) -> 0 | V29: EUR | W29: =IFERROR(VLOOKUP(V29,Curr!$B$2:$C$13,2,FALSE),0) -> 11 | X29: =U29*W29 -> 0 | Y29: =Q29 -> 0 | Z29: =+Y29*R29 -> 0 | AA29: EUR | AB29: =IFERROR(VLOOKUP(AA29,Curr!$B$2:$C$13,2,FALSE),0) -> 11 | AC29: =+Y29*AB29*R29 -> 0 | AD29: =+AC29-X29 -> 0 | AE29: =IFERROR(AD29/AC29,0) -> 0
B30: FI | D30: Transfer | J30: Turku: Private transfer to Turku Airport | Q30: 0 | R30: 0 | S30: =+Q30*R30 -> 0 | T30: 0 | U30: =S30*(1-T30) -> 0 | V30: EUR | W30: =IFERROR(VLOOKUP(V30,Curr!$B$2:$C$13,2,FALSE),0) -> 11 | X30: =U30*W30 -> 0 | Y30: =Q30 -> 0 | Z30: =+Y30*R30 -> 0 | AA30: EUR | AB30: =IFERROR(VLOOKUP(AA30,Curr!$B$2:$C$13,2,FALSE),0) -> 11 | AC30: =+Y30*AB30*R30 -> 0 | AD30: =+AC30-X30 -> 0 | AE30: =IFERROR(AD30/AC30,0) -> 0
B31: FI | D31: Transfer | J31: Turku: Self transfer to Turku railway station | Q31: 0 | R31: 0 | S31: =+Q31*R31 -> 0 | T31: 0 | U31: =S31*(1-T31) -> 0 | V31: EUR | W31: =IFERROR(VLOOKUP(V31,Curr!$B$2:$C$13,2,FALSE),0) -> 11 | X31: =U31*W31 -> 0 | Y31: =Q31 -> 0 | Z31: =+Y31*R31 -> 0 | AA31: EUR | AB31: =IFERROR(VLOOKUP(AA31,Curr!$B$2:$C$13,2,FALSE),0) -> 11 | AC31: =+Y31*AB31*R31 -> 0 | AD31: =+AC31-X31 -> 0 | AE31: =IFERROR(AD31/AC31,0) -> 0
B32: FI | D32: Transfer | J32: Turku: Private transfer to Turku railway station | Q32: 0 | R32: 0 | S32: =+Q32*R32 -> 0 | T32: 0 | U32: =S32*(1-T32) -> 0 | V32: EUR | W32: =IFERROR(VLOOKUP(V32,Curr!$B$2:$C$13,2,FALSE),0) -> 11 | X32: =U32*W32 -> 0 | Y32: =Q32 -> 0 | Z32: =+Y32*R32 -> 0 | AA32: EUR | AB32: =IFERROR(VLOOKUP(AA32,Curr!$B$2:$C$13,2,FALSE),0) -> 11 | AC32: =+Y32*AB32*R32 -> 0 | AD32: =+AC32-X32 -> 0 | AE32: =IFERROR(AD32/AC32,0) -> 0
B33: FI | D33: Transfer | J33: Turku: Self transfer to Turku Bus Station | Q33: 0 | R33: 0 | S33: =+Q33*R33 -> 0 | T33: 0 | U33: =S33*(1-T33) -> 0 | V33: EUR | W33: =IFERROR(VLOOKUP(V33,Curr!$B$2:$C$13,2,FALSE),0) -> 11 | X33: =U33*W33 -> 0 | Y33: =Q33 -> 0 | Z33: =+Y33*R33 -> 0 | AA33: EUR | AB33: =IFERROR(VLOOKUP(AA33,Curr!$B$2:$C$13,2,FALSE),0) -> 11 | AC33: =+Y33*AB33*R33 -> 0 | AD33: =+AC33-X33 -> 0 | AE33: =IFERROR(AD33/AC33,0) -> 0
B34: FI | D34: Transfer | J34: Turku: Private transfer to Turku Bus Station | Q34: 0 | R34: 0 | S34: =+Q34*R34 -> 0 | T34: 0 | U34: =S34*(1-T34) -> 0 | V34: EUR | W34: =IFERROR(VLOOKUP(V34,Curr!$B$2:$C$13,2,FALSE),0) -> 11 | X34: =U34*W34 -> 0 | Y34: =Q34 -> 0 | Z34: =+Y34*R34 -> 0 | AA34: EUR | AB34: =IFERROR(VLOOKUP(AA34,Curr!$B$2:$C$13,2,FALSE),0) -> 11 | AC34: =+Y34*AB34*R34 -> 0 | AD34: =+AC34-X34 -> 0 | AE34: =IFERROR(AD34/AC34,0) -> 0
B35: FI | D35: Transfer | J35: Turku: Self transfer to Port of Turku ferry terminal | Q35: 0 | R35: 0 | S35: =+Q35*R35 -> 0 | T35: 0 | U35: =S35*(1-T35) -> 0 | V35: EUR | W35: =IFERROR(VLOOKUP(V35,Curr!$B$2:$C$13,2,FALSE),0) -> 11 | X35: =U35*W35 -> 0 | Y35: =Q35 -> 0 | Z35: =+Y35*R35 -> 0 | AA35: EUR | AB35: =IFERROR(VLOOKUP(AA35,Curr!$B$2:$C$13,2,FALSE),0) -> 11 | AC35: =+Y35*AB35*R35 -> 0 | AD35: =+AC35-X35 -> 0 | AE35: =IFERROR(AD35/AC35,0) -> 0
B36: FI | D36: Transfer | J36: Turku: Private transfer to Port of Turku ferry terminal | Q36: 0 | R36: 0 | S36: =+Q36*R36 -> 0 | T36: 0 | U36: =S36*(1-T36) -> 0 | V36: EUR | W36: =IFERROR(VLOOKUP(V36,Curr!$B$2:$C$13,2,FALSE),0) -> 11 | X36: =U36*W36 -> 0 | Y36: =Q36 -> 0 | Z36: =+Y36*R36 -> 0 | AA36: EUR | AB36: =IFERROR(VLOOKUP(AA36,Curr!$B$2:$C$13,2,FALSE),0) -> 11 | AC36: =+Y36*AB36*R36 -> 0 | AD36: =+AC36-X36 -> 0 | AE36: =IFERROR(AD36/AC36,0) -> 0
B37: FI | D37: Transfer | J37: Turku: Self transfer to Turku cruise port | Q37: 0 | R37: 0 | S37: =+Q37*R37 -> 0 | T37: 0 | U37: =S37*(1-T37) -> 0 | V37: EUR | W37: =IFERROR(VLOOKUP(V37,Curr!$B$2:$C$13,2,FALSE),0) -> 11 | X37: =U37*W37 -> 0 | Y37: =Q37 -> 0 | Z37: =+Y37*R37 -> 0 | AA37: EUR | AB37: =IFERROR(VLOOKUP(AA37,Curr!$B$2:$C$13,2,FALSE),0) -> 11 | AC37: =+Y37*AB37*R37 -> 0 | AD37: =+AC37-X37 -> 0 | AE37: =IFERROR(AD37/AC37,0) -> 0
B38: FI | D38: Transfer | J38: Turku: Private transfer to Turku cruise port | Q38: 0 | R38: 0 | S38: =+Q38*R38 -> 0 | T38: 0 | U38: =S38*(1-T38) -> 0 | V38: EUR | W38: =IFERROR(VLOOKUP(V38,Curr!$B$2:$C$13,2,FALSE),0) -> 11 | X38: =U38*W38 -> 0 | Y38: =Q38 -> 0 | Z38: =+Y38*R38 -> 0 | AA38: EUR | AB38: =IFERROR(VLOOKUP(AA38,Curr!$B$2:$C$13,2,FALSE),0) -> 11 | AC38: =+Y38*AB38*R38 -> 0 | AD38: =+AC38-X38 -> 0 | AE38: =IFERROR(AD38/AC38,0) -> 0
... B287: FI | D287: Transfer | J287: Ivalo: Self transfer to Ivalo Bus Station | Q287: 0 | R287: 0 | S287: =+Q287*R287 -> 0 | T287: 0 | U287: =S287*(1-T287) -> 0 | V287: EUR | W287: =IFERROR(VLOOKUP(V287,Curr!$B$2:$C$13,2,FALSE),0) -> 11 | X287: =U287*W287 -> 0 | Y287: =Q287 -> 0 | Z287: =+Y287*R287 -> 0 | AA287: EUR | AB287: =IFERROR(VLOOKUP(AA287,Curr!$B$2:$C$13,2,FALSE),0) -> 11 | AC287: =+Y287*AB287*R287 -> 0 | AD287: =+AC287-X287 -> 0 | AE287: =IFERROR(AD287/AC287,0) -> 0
B288: FI | D288: Transfer | J288: Ivalo: Shuttle transfer to Kakslauttanen Arctic Resort | Q288: 49 | R288: 0 | S288: =+Q288*R288 -> 0 | T288: 0 | U288: =S288*(1-T288) -> 0 | V288: EUR | W288: =IFERROR(VLOOKUP(V288,Curr!$B$2:$C$13,2,FALSE),0) -> 11 | X288: =U288*W288 -> 0 | Y288: =Q288/0.8 -> 61.25 | Z288: =+Y288*R288 -> 0 | AA288: EUR | AB288: =IFERROR(VLOOKUP(AA288,Curr!$B$2:$C$13,2,FALSE),0) -> 11 | AC288: =+Y288*AB288*R288 -> 0 | AD288: =+AC288-X288 -> 0 | AE288: =IFERROR(AD288/AC288,0) -> 0
B289: FI | D289: Transfer | J289: Ivalo: Private transfer to Ivalo Bus Station | Q289: 0 | R289: 0 | S289: =+Q289*R289 -> 0 | T289: 0 | U289: =S289*(1-T289) -> 0 | V289: EUR | W289: =IFERROR(VLOOKUP(V289,Curr!$B$2:$C$13,2,FALSE),0) -> 11 | X289: =U289*W289 -> 0 | Y289: =Q289 -> 0 | Z289: =+Y289*R289 -> 0 | AA289: EUR | AB289: =IFERROR(VLOOKUP(AA289,Curr!$B$2:$C$13,2,FALSE),0) -> 11 | AC289: =+Y289*AB289*R289 -> 0 | AD289: =+AC289-X289 -> 0 | AE289: =IFERROR(AD289/AC289,0) -> 0
B290: FI | D290: Transfer | J290: Kemi: Self transfer to your accommodation | Q290: 0 | R290: 0 | S290: =+Q290*R290 -> 0 | T290: 0 | U290: =S290*(1-T290) -> 0 | V290: EUR | W290: =IFERROR(VLOOKUP(V290,Curr!$B$2:$C$13,2,FALSE),0) -> 11 | X290: =U290*W290 -> 0 | Y290: =Q290 -> 0 | Z290: =+Y290*R290 -> 0 | AA290: EUR | AB290: =IFERROR(VLOOKUP(AA290,Curr!$B$2:$C$13,2,FALSE),0) -> 11 | AC290: =+Y290*AB290*R290 -> 0 | AD290: =+AC290-X290 -> 0 | AE290: =IFERROR(AD290/AC290,0) -> 0
...

Sheet Transport
B2: Dates:
B3: Pax:
B4: Rooming:
B6: ID | C6: Day | D6: Type | E6: From date | F6: To date | G6: From time | H6: To time | I6: Supplier | J6: Travel element | K6: Manual booking? | L6: Status | M6: Comments | N6: Non-refundable | O6: Refundable | P6: URL | Q6: Gross P per unit | R6: Units | S6: Gross P | T6: Supp Comm | U6: Net P | V6: Supp curr | W6: X-rate | X6: Net P NOK | Y6: Sales P per unit | Z6: Price | AA6: Sales curr | AB6: X-rate2 | AC6: Sales P NOK tot | AD6: GP NOK | AE6: GP % | AF6: VAT25 | AG6: VAT15 | AH6: VAT12 | AI6: VAT0-D | AJ6: VAT0-I
B7: NO | D7: Activity | J7: Oslo: Norway in a Nutshell to Bergen - Time: TBD - Meeting point: Oslo Central Station - Route: Train transfer Oslo to Myrdal, Train tranfser Myrdal to Flåm, Fjord Cruise Flåm to Gudvangen, Coach Transfer Gudvangen to Voss, Train transfer Voss to Bergen - Includes: Tickets | P7: https://www.fjordtours.com/en | Q7: 3500 | R7: 0 | S7: =+Q7*R7 -> 0 | T7: 0.08 | U7: =S7*(1-T7) -> 0 | V7: NOK | W7: =IFERROR(VLOOKUP(V7,Curr!$B$2:$C$13,2,FALSE),0) -> 1 | X7: =U7*W7 -> 0 | Y7: =Q7/11/0.9 -> 353.53535 | Z7: =+Y7*R7 -> 0 | AA7: EUR | AB7: =IFERROR(VLOOKUP(AA7,Curr!$B$2:$C$13,2,FALSE),0) -> 11 | AC7: =+Y7*AB7*R7 -> 0 | AD7: =+AC7-X7 -> 0 | AE7: =IFERROR(AD7/AC7,0) -> 0
B8: NO | D8: Activity | J8: Oslo: Norway in a Nutshell to Flåm - Time: TBD - Meeting point: Oslo Central Station - Route: Train transfer Oslo to Myrdal, Train tranfser Myrdal to Flåm - Includes: Tickets | P8: https://www.fjordtours.com/en | Q8: 3500 | R8: 0 | S8: =+Q8*R8 -> 0 | T8: 0.08 | U8: =S8*(1-T8) -> 0 | V8: NOK | W8: =IFERROR(VLOOKUP(V8,Curr!$B$2:$C$13,2,FALSE),0) -> 1 | X8: =U8*W8 -> 0 | Y8: =Q8/11/0.9 -> 353.53535 | Z8: =+Y8*R8 -> 0 | AA8: EUR | AB8: =IFERROR(VLOOKUP(AA8,Curr!$B$2:$C$13,2,FALSE),0) -> 11 | AC8: =+Y8*AB8*R8 -> 0 | AD8: =+AC8-X8 -> 0 | AE8: =IFERROR(AD8/AC8,0) -> 0
B9: NO | D9: Activity | J9: Flåm: Norway in a Nutshell to Bergen - Time: TBD - Meeting point: Flåm Harbor - Route: Fjord Cruise Flåm to Gudvangen, Coach Transfer Gudvangen to Voss, Train transfer Voss to Bergen - Includes: Tickets | P9: https://www.fjordtours.com/en | Q9: 0 | R9: 0 | S9: =+Q9*R9 -> 0 | T9: 0 | U9: =S9*(1-T9) -> 0 | V9: NOK | W9: =IFERROR(VLOOKUP(V9,Curr!$B$2:$C$13,2,FALSE),0) -> 1 | X9: =U9*W9 -> 0 | Y9: =Q9 -> 0 | Z9: =+Y9*R9 -> 0 | AA9: EUR | AB9: =IFERROR(VLOOKUP(AA9,Curr!$B$2:$C$13,2,FALSE),0) -> 11 | AC9: =+Y9*AB9*R9 -> 0 | AD9: =+AC9-X9 -> 0 | AE9: =IFERROR(AD9/AC9,0) -> 0
B10: NO | D10: Activity | J10: Bergen: Norway in a Nutshell to Oslo - Time: TBD - Meeting point: Bergen Train Station - Route: Train transfer Bergen to Voss, Coach transfer Voss to Gudvangen, Fjord Cruise Gudvangen to Flåm, Train transfer Flåm to Myrdal, Train Transfer Myrdal to Oslo - Includes: Tickets | O10: x | P10: https://www.fjordtours.com/en | Q10: 3500 | R10: 0 | S10: =+Q10*R10 -> 0 | T10: 0.08 | U10: =S10*(1-T10) -> 0 | V10: NOK | W10: =IFERROR(VLOOKUP(V10,Curr!$B$2:$C$13,2,FALSE),0) -> 1 | X10: =U10*W10 -> 0 | Y10: =Q10/11/0.9 -> 353.53535 | Z10: =+Y10*R10 -> 0 | AA10: EUR | AB10: =IFERROR(VLOOKUP(AA10,Curr!$B$2:$C$13,2,FALSE),0) -> 11 | AC10: =+Y10*AB10*R10 -> 0 | AD10: =+AC10-X10 -> 0 | AE10: =IFERROR(AD10/AC10,0) -> 0
B11: NO | D11: Activity | J11: Bergen: Norway in a Nutshell to Flåm - Time: TBD - Meeting point: Bergen Train Station - Route: Train transfer Bergen to Voss, Coach transfer Voss to Gudvangen, Fjord Cruise Gudvangen to Flåm - Includes: Tickets | O11: x | P11: https://www.fjordtours.com/en | Q11: 3500 | R11: 0 | S11: =+Q11*R11 -> 0 | T11: 0.08 | U11: =S11*(1-T11) -> 0 | V11: NOK | W11: =IFERROR(VLOOKUP(V11,Curr!$B$2:$C$13,2,FALSE),0) -> 1 | X11: =U11*W11 -> 0 | Y11: =Q11/11/0.9 -> 353.53535 | Z11: =+Y11*R11 -> 0 | AA11: EUR | AB11: =IFERROR(VLOOKUP(AA11,Curr!$B$2:$C$13,2,FALSE),0) -> 11 | AC11: =+Y11*AB11*R11 -> 0 | AD11: =+AC11-X11 -> 0 | AE11: =IFERROR(AD11/AC11,0) -> 0
B12: NO | D12: Activity | J12: Flåm: Norway in a Nutshell to Oslo - Time: TBD - Meeting point: Flåm Train Station - Route: Train transfer Flåm to Myrdal, Train Transfer Myrdal to Oslo - Includes: Tickets | O12: x | P12: https://www.fjordtours.com/en | Q12: 0 | R12: 0 | S12: =+Q12*R12 -> 0 | T12: 0 | U12: =S12*(1-T12) -> 0 | V12: NOK | W12: =IFERROR(VLOOKUP(V12,Curr!$B$2:$C$13,2,FALSE),0) -> 1 | X12: =U12*W12 -> 0 | Y12: =Q12 -> 0 | Z12: =+Y12*R12 -> 0 | AA12: EUR | AB12: =IFERROR(VLOOKUP(AA12,Curr!$B$2:$C$13,2,FALSE),0) -> 11 | AC12: =+Y12*AB12*R12 -> 0 | AD12: =+AC12-X12 -> 0 | AE12: =IFERROR(AD12/AC12,0) -> 0
B13: NO | D13: Activity | J13: Bergen: Norway in a Nutshell Bergen to Bergen - Time: TBD - Route: Route: Train transfer Bergen to Voss, Coach transfer Voss to Gudvangen, Fjord Cruise Gudvangen to Flåm, Train transfer Flåm to Myrdal, Train Transfer Myrdal to Bergen - Includes: Tickets | P13: https://www.fjordtours.com/en | Q13: 3000 | R13: 0 | S13: =+Q13*R13 -> 0 | T13: 0.08 | U13: =S13*(1-T13) -> 0 | V13: NOK | W13: =IFERROR(VLOOKUP(V13,Curr!$B$2:$C$13,2,FALSE),0) -> 1 | X13: =U13*W13 -> 0 | Y13: =Q13/11/0.9 -> 303.0303 | Z13: =+Y13*R13 -> 0 | AA13: EUR | AB13: =IFERROR(VLOOKUP(AA13,Curr!$B$2:$C$13,2,FALSE),0) -> 11 | AC13: =+Y13*AB13*R13 -> 0 | AD13: =+AC13-X13 -> 0 | AE13: =IFERROR(AD13/AC13,0) -> 0
B14: FI | D14: Coach | J14: Helsinki: Coach transfer to Porvoo - Time: TBD - Includes: Tickets | Q14: 0 | R14: 0 | S14: =+Q14*R14 -> 0 | T14: 0 | U14: =S14*(1-T14) -> 0 | V14: EUR | W14: =IFERROR(VLOOKUP(V14,Curr!$B$2:$C$13,2,FALSE),0) -> 11 | X14: =U14*W14 -> 0 | Y14: =Q14/0.8 -> 0 | Z14: =+Y14*R14 -> 0 | AA14: EUR | AB14: =IFERROR(VLOOKUP(AA14,Curr!$B$2:$C$13,2,FALSE),0) -> 11 | AC14: =+Y14*AB14*R14 -> 0 | AD14: =+AC14-X14 -> 0 | AE14: =IFERROR(AD14/AC14,0) -> 0
B15: FI | D15: Coach | J15: Helsinki: Coach transfer to Hanko - Time: TBD - Includes: Tickets | Q15: 0 | R15: 0 | S15: =+Q15*R15 -> 0 | T15: 0 | U15: =S15*(1-T15) -> 0 | V15: EUR | W15: =IFERROR(VLOOKUP(V15,Curr!$B$2:$C$13,2,FALSE),0) -> 11 | X15: =U15*W15 -> 0 | Y15: =Q15/0.8 -> 0 | Z15: =+Y15*R15 -> 0 | AA15: EUR | AB15: =IFERROR(VLOOKUP(AA15,Curr!$B$2:$C$13,2,FALSE),0) -> 11 | AC15: =+Y15*AB15*R15 -> 0 | AD15: =+AC15-X15 -> 0 | AE15: =IFERROR(AD15/AC15,0) -> 0
B16: FI | D16: Coach | J16: Helsinki: Coach transfer to Turku - Time: TBD - Includes: Tickets | Q16: 0 | R16: 0 | S16: =+Q16*R16 -> 0 | T16: 0 | U16: =S16*(1-T16) -> 0 | V16: EUR | W16: =IFERROR(VLOOKUP(V16,Curr!$B$2:$C$13,2,FALSE),0) -> 11 | X16: =U16*W16 -> 0 | Y16: =Q16/0.8 -> 0 | Z16: =+Y16*R16 -> 0 | AA16: EUR | AB16: =IFERROR(VLOOKUP(AA16,Curr!$B$2:$C$13,2,FALSE),0) -> 11 | AC16: =+Y16*AB16*R16 -> 0 | AD16: =+AC16-X16 -> 0 | AE16: =IFERROR(AD16/AC16,0) -> 0
B17: FI | D17: Coach | J17: Helsinki: Coach transfer to Tampere - Time: TBD - Includes: Tickets | Q17: 0 | R17: 0 | S17: =+Q17*R17 -> 0 | T17: 0 | U17: =S17*(1-T17) -> 0 | V17: EUR | W17: =IFERROR(VLOOKUP(V17,Curr!$B$2:$C$13,2,FALSE),0) -> 11 | X17: =U17*W17 -> 0 | Y17: =Q17/0.8 -> 0 | Z17: =+Y17*R17 -> 0 | AA17: EUR | AB17: =IFERROR(VLOOKUP(AA17,Curr!$B$2:$C$13,2,FALSE),0) -> 11 | AC17: =+Y17*AB17*R17 -> 0 | AD17: =+AC17-X17 -> 0 | AE17: =IFERROR(AD17/AC17,0) -> 0
B18: FI | D18: Coach | J18: Helsinki: Coach transfer to Oulu - Time: TBD - Includes: Tickets | Q18: 0 | R18: 0 | S18: =+Q18*R18 -> 0 | T18: 0 | U18: =S18*(1-T18) -> 0 | V18: EUR | W18: =IFERROR(VLOOKUP(V18,Curr!$B$2:$C$13,2,FALSE),0) -> 11 | X18: =U18*W18 -> 0 | Y18: =Q18/0.8 -> 0 | Z18: =+Y18*R18 -> 0 | AA18: EUR | AB18: =IFERROR(VLOOKUP(AA18,Curr!$B$2:$C$13,2,FALSE),0) -> 11 | AC18: =+Y18*AB18*R18 -> 0 | AD18: =+AC18-X18 -> 0 | AE18: =IFERROR(AD18/AC18,0) -> 0
B19: FI | D19: Coach | J19: Helsinki: Coach transfer to Kuopio - Time: TBD - Includes: Tickets | Q19: 0 | R19: 0 | S19: =+Q19*R19 -> 0 | T19: 0 | U19: =S19*(1-T19) -> 0 | V19: EUR | W19: =IFERROR(VLOOKUP(V19,Curr!$B$2:$C$13,2,FALSE),0) -> 11 | X19: =U19*W19 -> 0 | Y19: =Q19/0.8 -> 0 | Z19: =+Y19*R19 -> 0 | AA19: EUR | AB19: =IFERROR(VLOOKUP(AA19,Curr!$B$2:$C$13,2,FALSE),0) -> 11 | AC19: =+Y19*AB19*R19 -> 0 | AD19: =+AC19-X19 -> 0 | AE19: =IFERROR(AD19/AC19,0) -> 0
B20: FI | D20: Coach | J20: Helsinki: Coach transfer to Lappeenranta - Time: TBD - Includes: Tickets | Q20: 0 | R20: 0 | S20: =+Q20*R20 -> 0 | T20: 0 | U20: =S20*(1-T20) -> 0 | V20: EUR | W20: =IFERROR(VLOOKUP(V20,Curr!$B$2:$C$13,2,FALSE),0) -> 11 | X20: =U20*W20 -> 0 | Y20: =Q20/0.8 -> 0 | Z20: =+Y20*R20 -> 0 | AA20: EUR | AB20: =IFERROR(VLOOKUP(AA20,Curr!$B$2:$C$13,2,FALSE),0) -> 11 | AC20: =+Y20*AB20*R20 -> 0 | AD20: =+AC20-X20 -> 0 | AE20: =IFERROR(AD20/AC20,0) -> 0
B21: FI | D21: Coach | J21: Helsinki: Coach transfer to Savonlinna - Time: TBD - Includes: Tickets | Q21: 0 | R21: 0 | S21: =+Q21*R21 -> 0 | T21: 0 | U21: =S21*(1-T21) -> 0 | V21: EUR | W21: =IFERROR(VLOOKUP(V21,Curr!$B$2:$C$13,2,FALSE),0) -> 11 | X21: =U21*W21 -> 0 | Y21: =Q21/0.8 -> 0 | Z21: =+Y21*R21 -> 0 | AA21: EUR | AB21: =IFERROR(VLOOKUP(AA21,Curr!$B$2:$C$13,2,FALSE),0) -> 11 | AC21: =+Y21*AB21*R21 -> 0 | AD21: =+AC21-X21 -> 0 | AE21: =IFERROR(AD21/AC21,0) -> 0
B22: FI | D22: Coach | J22: Rovaniemi: Coach transfer to Oulu - Time: TBD - Includes: Tickets | Q22: 0 | R22: 0 | S22: =+Q22*R22 -> 0 | T22: 0 | U22: =S22*(1-T22) -> 0 | V22: EUR | W22: =IFERROR(VLOOKUP(V22,Curr!$B$2:$C$13,2,FALSE),0) -> 11 | X22: =U22*W22 -> 0 | Y22: =Q22 -> 0 | Z22: =+Y22*R22 -> 0 | AA22: EUR | AB22: =IFERROR(VLOOKUP(AA22,Curr!$B$2:$C$13,2,FALSE),0) -> 11 | AC22: =+Y22*AB22*R22 -> 0 | AD22: =+AC22-X22 -> 0 | AE22: =IFERROR(AD22/AC22,0) -> 0
B23: FI | D23: Coach | J23: Rovaniemi: Coach transfer to Ranua - Time: TBD - Includes: Tickets | Q23: 0 | R23: 0 | S23: =+Q23*R23 -> 0 | T23: 0 | U23: =S23*(1-T23) -> 0 | V23: EUR | W23: =IFERROR(VLOOKUP(V23,Curr!$B$2:$C$13,2,FALSE),0) -> 11 | X23: =U23*W23 -> 0 | Y23: =Q23 -> 0 | Z23: =+Y23*R23 -> 0 | AA23: EUR | AB23: =IFERROR(VLOOKUP(AA23,Curr!$B$2:$C$13,2,FALSE),0) -> 11 | AC23: =+Y23*AB23*R23 -> 0 | AD23: =+AC23-X23 -> 0 | AE23: =IFERROR(AD23/AC23,0) -> 0
B24: FI | D24: Coach | J24: Rovaniemi: Coach transfer to Pyhä - Time: TBD - Includes: Tickets | Q24: 0 | R24: 0 | S24: =+Q24*R24 -> 0 | T24: 0 | U24: =S24*(1-T24) -> 0 | V24: EUR | W24: =IFERROR(VLOOKUP(V24,Curr!$B$2:$C$13,2,FALSE),0) -> 11 | X24: =U24*W24 -> 0 | Y24: =Q24 -> 0 | Z24: =+Y24*R24 -> 0 | AA24: EUR | AB24: =IFERROR(VLOOKUP(AA24,Curr!$B$2:$C$13,2,FALSE),0) -> 11 | AC24: =+Y24*AB24*R24 -> 0 | AD24: =+AC24-X24 -> 0 | AE24: =IFERROR(AD24/AC24,0) -> 0
B25: FI | D25: Coach | J25: Rovaniemi: Coach transfer to Luosto - Time: TBD - Includes: Tickets | Q25: 0 | R25: 0 | S25: =+Q25*R25 -> 0 | T25: 0 | U25: =S25*(1-T25) -> 0 | V25: EUR | W25: =IFERROR(VLOOKUP(V25,Curr!$B$2:$C$13,2,FALSE),0) -> 11 | X25: =U25*W25 -> 0 | Y25: =Q25 -> 0 | Z25: =+Y25*R25 -> 0 | AA25: EUR | AB25: =IFERROR(VLOOKUP(AA25,Curr!$B$2:$C$13,2,FALSE),0) -> 11 | AC25: =+Y25*AB25*R25 -> 0 | AD25: =+AC25-X25 -> 0 | AE25: =IFERROR(AD25/AC25,0) -> 0
B26: FI | D26: Coach | J26: Rovaniemi: Coach transfer to Kakslauttanen - Time: TBD - Includes: Tickets | Q26: 49 | R26: 0 | S26: =+Q26*R26 -> 0 | T26: 0 | U26: =S26*(1-T26) -> 0 | V26: EUR | W26: =IFERROR(VLOOKUP(V26,Curr!$B$2:$C$13,2,FALSE),0) -> 11 | X26: =U26*W26 -> 0 | Y26: =Q26/0.8 -> 61.25 | Z26: =+Y26*R26 -> 0 | AA26: EUR | AB26: =IFERROR(VLOOKUP(AA26,Curr!$B$2:$C$13,2,FALSE),0) -> 11 | AC26: =+Y26*AB26*R26 -> 0 | AD26: =+AC26-X26 -> 0 | AE26: =IFERROR(AD26/AC26,0) -> 0
B27: FI | D27: Coach | J27: Rovaniemi: Arctic Coach transfer on The Arctic Route to Levi - Time: TBD - Includes: Tickets | Q27: 0 | R27: 0 | S27: =+Q27*R27 -> 0 | T27: 0 | U27: =S27*(1-T27) -> 0 | V27: EUR | W27: =IFERROR(VLOOKUP(V27,Curr!$B$2:$C$13,2,FALSE),0) -> 11 | X27: =U27*W27 -> 0 | Y27: =Q27 -> 0 | Z27: =+Y27*R27 -> 0 | AA27: EUR | AB27: =IFERROR(VLOOKUP(AA27,Curr!$B$2:$C$13,2,FALSE),0) -> 11 | AC27: =+Y27*AB27*R27 -> 0 | AD27: =+AC27-X27 -> 0 | AE27: =IFERROR(AD27/AC27,0) -> 0
B28: FI | D28: Coach | J28: Rovaniemi: Overnight Arctic Coach transfer on the Aurora Express to Levi - Time: TBD - Includes: Tickets | Q28: 0 | R28: 0 | S28: =+Q28*R28 -> 0 | T28: 0 | U28: =S28*(1-T28) -> 0 | V28: EUR | W28: =IFERROR(VLOOKUP(V28,Curr!$B$2:$C$13,2,FALSE),0) -> 11 | X28: =U28*W28 -> 0 | Y28: =Q28 -> 0 | Z28: =+Y28*R28 -> 0 | AA28: EUR | AB28: =IFERROR(VLOOKUP(AA28,Curr!$B$2:$C$13,2,FALSE),0) -> 11 | AC28: =+Y28*AB28*R28 -> 0 | AD28: =+AC28-X28 -> 0 | AE28: =IFERROR(AD28/AC28,0) -> 0
B29: FI | D29: Coach | J29: Rovaniemi: Arctic Coach transfer on The Arctic Route to Kilpisjärvi - Time: TBD - Includes: Tickets | Q29: 0 | R29: 0 | S29: =+Q29*R29 -> 0 | T29: 0 | U29: =S29*(1-T29) -> 0 | V29: EUR | W29: =IFERROR(VLOOKUP(V29,Curr!$B$2:$C$13,2,FALSE),0) -> 11 | X29: =U29*W29 -> 0 | Y29: =Q29 -> 0 | Z29: =+Y29*R29 -> 0 | AA29: EUR | AB29: =IFERROR(VLOOKUP(AA29,Curr!$B$2:$C$13,2,FALSE),0) -> 11 | AC29: =+Y29*AB29*R29 -> 0 | AD29: =+AC29-X29 -> 0 | AE29: =IFERROR(AD29/AC29,0) -> 0
B30: FI | D30: Coach | J30: Rovaniemi: Overnight Arctic Coach transfer on the Aurora Express to Kilpisjärvi - Time: TBD - Includes: Tickets | Q30: 0 | R30: 0 | S30: =+Q30*R30 -> 0 | T30: 0 | U30: =S30*(1-T30) -> 0 | V30: EUR | W30: =IFERROR(VLOOKUP(V30,Curr!$B$2:$C$13,2,FALSE),0) -> 11 | X30: =U30*W30 -> 0 | Y30: =Q30 -> 0 | Z30: =+Y30*R30 -> 0 | AA30: EUR | AB30: =IFERROR(VLOOKUP(AA30,Curr!$B$2:$C$13,2,FALSE),0) -> 11 | AC30: =+Y30*AB30*R30 -> 0 | AD30: =+AC30-X30 -> 0 | AE30: =IFERROR(AD30/AC30,0) -> 0
B31: FI | D31: Coach | J31: Rovaniemi: Arctic Coach transfer on The Arctic Route to Tromsø - Time: TBD - Includes: Tickets | Q31: 0 | R31: 0 | S31: =+Q31*R31 -> 0 | T31: 0.2 | U31: =S31*(1-T31) -> 0 | V31: EUR | W31: =IFERROR(VLOOKUP(V31,Curr!$B$2:$C$13,2,FALSE),0) -> 11 | X31: =U31*W31 -> 0 | Y31: =Q31 -> 0 | Z31: =+Y31*R31 -> 0 | AA31: EUR | AB31: =IFERROR(VLOOKUP(AA31,Curr!$B$2:$C$13,2,FALSE),0) -> 11 | AC31: =+Y31*AB31*R31 -> 0 | AD31: =+AC31-X31 -> 0 | AE31: =IFERROR(AD31/AC31,0) -> 0
B32: FI | D32: Coach | J32: Rovaniemi: Overnight Arctic Coach transfer on the Aurora Express to Tromsø - Time: TBD - Includes: Tickets | Q32: 0 | R32: 0 | S32: =+Q32*R32 -> 0 | T32: 0.2 | U32: =S32*(1-T32) -> 0 | V32: EUR | W32: =IFERROR(VLOOKUP(V32,Curr!$B$2:$C$13,2,FALSE),0) -> 11 | X32: =U32*W32 -> 0 | Y32: =Q32 -> 0 | Z32: =+Y32*R32 -> 0 | AA32: EUR | AB32: =IFERROR(VLOOKUP(AA32,Curr!$B$2:$C$13,2,FALSE),0) -> 11 | AC32: =+Y32*AB32*R32 -> 0 | AD32: =+AC32-X32 -> 0 | AE32: =IFERROR(AD32/AC32,0) -> 0
B33: FI | D33: Coach | J33: Turku: Coach transfer to Helsinki - Time: TBD - Includes: Tickets | Q33: 0 | R33: 0 | S33: =+Q33*R33 -> 0 | T33: 0 | U33: =S33*(1-T33) -> 0 | V33: EUR | W33: =IFERROR(VLOOKUP(V33,Curr!$B$2:$C$13,2,FALSE),0) -> 11 | X33: =U33*W33 -> 0 | Y33: =Q33 -> 0 | Z33: =+Y33*R33 -> 0 | AA33: EUR | AB33: =IFERROR(VLOOKUP(AA33,Curr!$B$2:$C$13,2,FALSE),0) -> 11 | AC33: =+Y33*AB33*R33 -> 0 | AD33: =+AC33-X33 -> 0 | AE33: =IFERROR(AD33/AC33,0) -> 0
B34: FI | D34: Coach | J34: Turku: Coach transfer to Naantali - Time: TBD - Includes: Tickets | Q34: 0 | R34: 0 | S34: =+Q34*R34 -> 0 | T34: 0 | U34: =S34*(1-T34) -> 0 | V34: EUR | W34: =IFERROR(VLOOKUP(V34,Curr!$B$2:$C$13,2,FALSE),0) -> 11 | X34: =U34*W34 -> 0 | Y34: =Q34 -> 0 | Z34: =+Y34*R34 -> 0 | AA34: EUR | AB34: =IFERROR(VLOOKUP(AA34,Curr!$B$2:$C$13,2,FALSE),0) -> 11 | AC34: =+Y34*AB34*R34 -> 0 | AD34: =+AC34-X34 -> 0 | AE34: =IFERROR(AD34/AC34,0) -> 0
B35: FI | D35: Coach | J35: Tampere: Coach transfer to Helsinki - Time: TBD - Includes: Tickets | Q35: 0 | R35: 0 | S35: =+Q35*R35 -> 0 | T35: 0 | U35: =S35*(1-T35) -> 0 | V35: EUR | W35: =IFERROR(VLOOKUP(V35,Curr!$B$2:$C$13,2,FALSE),0) -> 11 | X35: =U35*W35 -> 0 | Y35: =Q35 -> 0 | Z35: =+Y35*R35 -> 0 | AA35: EUR | AB35: =IFERROR(VLOOKUP(AA35,Curr!$B$2:$C$13,2,FALSE),0) -> 11 | AC35: =+Y35*AB35*R35 -> 0 | AD35: =+AC35-X35 -> 0 | AE35: =IFERROR(AD35/AC35,0) -> 0
B36: FI | D36: Coach | J36: Porvoo: Coach transfer to Helsinki - Time: TBD - Includes: Tickets | Q36: 0 | R36: 0 | S36: =+Q36*R36 -> 0 | T36: 0 | U36: =S36*(1-T36) -> 0 | V36: EUR | W36: =IFERROR(VLOOKUP(V36,Curr!$B$2:$C$13,2,FALSE),0) -> 11 | X36: =U36*W36 -> 0 | Y36: =Q36 -> 0 | Z36: =+Y36*R36 -> 0 | AA36: EUR | AB36: =IFERROR(VLOOKUP(AA36,Curr!$B$2:$C$13,2,FALSE),0) -> 11 | AC36: =+Y36*AB36*R36 -> 0 | AD36: =+AC36-X36 -> 0 | AE36: =IFERROR(AD36/AC36,0) -> 0
B37: FI | D37: Coach | J37: Savonlinna: Coach transfer to Helsinki - Time: TBD - Includes: Tickets | Q37: 0 | R37: 0 | S37: =+Q37*R37 -> 0 | T37: 0 | U37: =S37*(1-T37) -> 0 | V37: EUR | W37: =IFERROR(VLOOKUP(V37,Curr!$B$2:$C$13,2,FALSE),0) -> 11 | X37: =U37*W37 -> 0 | Y37: =Q37 -> 0 | Z37: =+Y37*R37 -> 0 | AA37: EUR | AB37: =IFERROR(VLOOKUP(AA37,Curr!$B$2:$C$13,2,FALSE),0) -> 11 | AC37: =+Y37*AB37*R37 -> 0 | AD37: =+AC37-X37 -> 0 | AE37: =IFERROR(AD37/AC37,0) -> 0
B38: FI | D38: Coach | J38: Savonlinna: Coach transfer to Punkaharju - Time: TBD - Includes: Tickets | Q38: 0 | R38: 0 | S38: =+Q38*R38 -> 0 | T38: 0 | U38: =S38*(1-T38) -> 0 | V38: EUR | W38: =IFERROR(VLOOKUP(V38,Curr!$B$2:$C$13,2,FALSE),0) -> 11 | X38: =U38*W38 -> 0 | Y38: =Q38 -> 0 | Z38: =+Y38*R38 -> 0 | AA38: EUR | AB38: =IFERROR(VLOOKUP(AA38,Curr!$B$2:$C$13,2,FALSE),0) -> 11 | AC38: =+Y38*AB38*R38 -> 0 | AD38: =+AC38-X38 -> 0 | AE38: =IFERROR(AD38/AC38,0) -> 0
... B106: FI | D106: Coach | J106: Kakslauttanen: Coach transfer to Saariselkä - Time: TBD - Includes: Tickets | Q106: 0 | R106: 0 | S106: =+Q106*R106 -> 0 | T106: 0 | U106: =S106*(1-T106) -> 0 | V106: EUR | W106: =IFERROR(VLOOKUP(V106,Curr!$B$2:$C$13,2,FALSE),0) -> 11 | X106: =U106*W106 -> 0 | Y106: =Q106 -> 0 | Z106: =+Y106*R106 -> 0 | AA106: EUR | AB106: =IFERROR(VLOOKUP(AA106,Curr!$B$2:$C$13,2,FALSE),0) -> 11 | AC106: =+Y106*AB106*R106 -> 0 | AD106: =+AC106-X106 -> 0 | AE106: =IFERROR(AD106/AC106,0) -> 0
B107: FI | D107: Coach | J107: Kakslauttanen: Coach transfer to Rovaniemi - Time: TBD - Includes: Tickets | Q107: 49 | R107: 0 | S107: =+Q107*R107 -> 0 | T107: 0 | U107: =S107*(1-T107) -> 0 | V107: EUR | W107: =IFERROR(VLOOKUP(V107,Curr!$B$2:$C$13,2,FALSE),0) -> 11 | X107: =U107*W107 -> 0 | Y107: =Q107/0.8 -> 61.25 | Z107: =+Y107*R107 -> 0 | AA107: EUR | AB107: =IFERROR(VLOOKUP(AA107,Curr!$B$2:$C$13,2,FALSE),0) -> 11 | AC107: =+Y107*AB107*R107 -> 0 | AD107: =+AC107-X107 -> 0 | AE107: =IFERROR(AD107/AC107,0) -> 0
B108: NO | D108: Coach | J108: Oslo: Coach transfer to Kristiansand - Time: TBD - Includes: Tickets | Q108: 0 | R108: 0 | S108: =+Q108*R108 -> 0 | T108: 0 | U108: =S108*(1-T108) -> 0 | V108: EUR | W108: =IFERROR(VLOOKUP(V108,Curr!$B$2:$C$13,2,FALSE),0) -> 11 | X108: =U108*W108 -> 0 | Y108: =Q108 -> 0 | Z108: =+Y108*R108 -> 0 | AA108: EUR | AB108: =IFERROR(VLOOKUP(AA108,Curr!$B$2:$C$13,2,FALSE),0) -> 11 | AC108: =+Y108*AB108*R108 -> 0 | AD108: =+AC108-X108 -> 0 | AE108: =IFERROR(AD108/AC108,0) -> 0
B109: NO | D109: Coach | J109: Oslo: Coach transfer to Stavanger - Time: TBD - Includes: Tickets | Q109: 0 | R109: 0 | S109: =+Q109*R109 -> 0 | T109: 0 | U109: =S109*(1-T109) -> 0 | V109: EUR | W109: =IFERROR(VLOOKUP(V109,Curr!$B$2:$C$13,2,FALSE),0) -> 11 | X109: =U109*W109 -> 0 | Y109: =Q109 -> 0 | Z109: =+Y109*R109 -> 0 | AA109: EUR | AB109: =IFERROR(VLOOKUP(AA109,Curr!$B$2:$C$13,2,FALSE),0) -> 11 | AC109: =+Y109*AB109*R109 -> 0 | AD109: =+AC109-X109 -> 0 | AE109: =IFERROR(AD109/AC109,0) -> 0
...

Sheet Activities
B2: Dates:
B3: Pax:
B4: Rooming:
B6: ID | C6: Day | D6: Type | E6: From date | F6: To date | G6: From time | H6: To time | I6: Supplier | J6: Travel element | K6: Manual booking? | L6: Status | M6: Comments | N6: Non-refundable | O6: Refundable | P6: URL | Q6: Gross P per unit | R6: Units | S6: Gross P | T6: Supp Comm | U6: Net P | V6: Supp curr | W6: X-rate | X6: Net P NOK | Y6: Sales P per unit | Z6: Price | AA6: Sales curr | AB6: X-rate2 | AC6: Sales P NOK tot | AD6: GP NOK | AE6: GP % | AF6: VAT25 | AG6: VAT15 | AH6: VAT12 | AI6: VAT0-D | AJ6: VAT0-I
B7: DK | D7: Activity | J7: Copenhagen: City Walking & Harbour Ferry Tour with Changing of the Guard - Time: 9:00 am - 12:00 pm - Meeting point: Copenhagen Central Station, beneath the large clock beside 7-Eleven - Includes: Small-group walking tour with local host, harbour ferry ride and Changing of the Guard - Description: Discover Copenhagen on foot and from the water, passing historic landmarks, hidden corners, Kastellet and the Little Mermaid before finishing at Amalienborg Palace for the Changing of the Guard. | P7: =HYPERLINK("https://booknordics.com/denmark/eastern-denmark/copenhagen/walk-ferry-copenhagen-highlights-change-of-guards-finale","https://booknordics.com/denmark/eastern-denmark/copenhagen/walk-ferry-copenhagen-highlights-change-of-guards-finale") -> https://booknordics.com/denmark/eastern-denmark/copenhagen/walk-ferry-copenhagen-highlights-change-of-guards-finale | Q7: 55 | R7: 0 | S7: =+Q7*R7 -> 0 | T7: 0.2 | U7: =S7*(1-T7) -> 0 | V7: EUR | W7: =IFERROR(VLOOKUP(V7,Curr!$B$2:$C$13,2,FALSE),0) -> 11 | X7: =U7*W7 -> 0 | Y7: =Q7 -> 55 | Z7: =+Y7*R7 -> 0 | AA7: EUR | AB7: =IFERROR(VLOOKUP(AA7,Curr!$B$2:$C$13,2,FALSE),0) -> 11 | AC7: =+Y7*AB7*R7 -> 0 | AD7: =+AC7-X7 -> 0 | AE7: =IFERROR(AD7/AC7,0) -> 0
B8: DK | D8: Activity | J8: Copenhagen: Forest Tower & Forgotten Giants Day Tour - Time: 10:00 am - 3:30 pm - Meeting point: CPH Tours & Tickets, Colbjørnsensgade 15 - Includes: Central Copenhagen pickup and drop-off, air-conditioned minibus transportation, guided Forest Tower and Forgotten Giants visits and Forest Tower admission - Description: Walk through the treetops to the 45-metre Forest Tower for sweeping countryside views, then discover two enormous recycled-wood sculptures from Thomas Dambo’s celebrated Forgotten Giants project. | P8: =HYPERLINK("https://booknordics.com/denmark/eastern-denmark/copenhagen/forest-tower-and-forgotten-giants-a-day-tour-from-copenhagen","https://booknordics.com/denmark/eastern-denmark/copenhagen/forest-tower-and-forgotten-giants-a-day-tour-from-copenhagen") -> https://booknordics.com/denmark/eastern-denmark/copenhagen/forest-tower-and-forgotten-giants-a-day-tour-from-copenhagen | Q8: 110 | R8: 0 | S8: =+Q8*R8 -> 0 | T8: 0.2 | U8: =S8*(1-T8) -> 0 | V8: EUR | W8: =IFERROR(VLOOKUP(V8,Curr!$B$2:$C$13,2,FALSE),0) -> 11 | X8: =U8*W8 -> 0 | Y8: =Q8 -> 110 | Z8: =+Y8*R8 -> 0 | AA8: EUR | AB8: =IFERROR(VLOOKUP(AA8,Curr!$B$2:$C$13,2,FALSE),0) -> 11 | AC8: =+Y8*AB8*R8 -> 0 | AD8: =+AC8-X8 -> 0 | AE8: =IFERROR(AD8/AC8,0) -> 0
B9: FI | D9: Activity | J9: Helsinki: A Finntastic Walking Tour in Helsinki - Time: 10:30 am - 12:30 pm - Meeting point: Senate Square - Includes: Professional authorised Helsinki guide, liability insurance - Description: Explore Helsinki’s historic centre with a local guide, taking in Senate Square, Helsinki Cathedral, Market Square and Central Library Oodi while discovering Finnish history, culture and everyday life. | P9: https://www.finntastictours.fi/tours/ | Q9: 20 | R9: 0 | S9: =+Q9*R9 -> 0 | T9: 0 | U9: =S9*(1-T9) -> 0 | V9: EUR | W9: =IFERROR(VLOOKUP(V9,Curr!$B$2:$C$13,2,FALSE),0) -> 11 | X9: =U9*W9 -> 0 | Y9: =Q9/0.5 -> 40 | Z9: =+Y9*R9 -> 0 | AA9: EUR | AB9: =IFERROR(VLOOKUP(AA9,Curr!$B$2:$C$13,2,FALSE),0) -> 11 | AC9: =+Y9*AB9*R9 -> 0 | AD9: =+AC9-X9 -> 0 | AE9: =IFERROR(AD9/AC9,0) -> 0
